[META]
version=2.0
spawnOnBlockType=2
spawnSunlight=True
spawnDarkness=True
spawnWater=False
spawnLava=False
underFill=False
randomRotation=True
dig=True
tree=False
branch=False
needsFoundation=True
rarity=100
collisionPercentage=20
spawnElevationMin=0
spawnElevationMax=200
spawnInBiome=Custom
[DATA]
1,-2,-3:17.14
0,-2,-2:17.14
1,-2,-2:17.14
1,-1,-2:17.14
0,-2,-1:17.14
1,-2,-1:17.14
0,-1,-1:17.14
1,-1,-1:17.14
0,-2,0:17.14
1,-2,0:17.14
0,-1,0:17.14
1,-1,0:17.14
0,-2,1:17.14
1,-2,1:17.14
0,-1,1:17.14
1,-1,1:17.14
0,-2,2:17.14
1,-2,2:17.14
0,-1,2:17.14
1,-1,2:17.2
0,-2,3:17.14
1,-2,3:17.14
0,-1,3:17.14
1,-1,3:17.2
0,-2,4:17.14
1,-2,4:17.14
0,-1,4:17.14
1,-1,4:17.14
0,-2,5:17.14
1,-2,5:17.14
0,-1,5:17.14
1,-1,5:17.14
0,-2,6:17.14
1,-2,6:17.14
0,-1,6:17.14
1,-1,6:17.14
1,-2,7:17.14
0,-1,7:17.14
1,-1,7:17.14
1,-2,8:17.14
0,-1,8:17.14
1,-1,8:17.14
1,-2,9:17.14
0,-1,9:17.14
1,-1,9:17.14
0,-2,10:17.14
1,-2,10:17.14
0,-1,10:17.14
1,-1,10:17.14
0,-2,11:17.14
1,-2,11:17.14
2,-2,11:17.14
-1,-1,11:17.14
0,-1,11:17.14
1,-1,11:17.14
1,-4,12:18.13
3,-4,12:18.13
-1,-3,12:18.13
0,-3,12:18.13
1,-3,12:17.14
0,-2,12:17.14
1,-2,12:17.14
2,-2,12:17.14
3,-2,12:17.14
4,-2,12:17.14
-2,-1,12:17.14
-1,-1,12:17.14
0,-1,12:17.14
1,-1,12:17.14
2,-1,12:18.13
1,0,12:17.14
1,-6,13:18.13
2,-6,13:18.13
0,-5,13:18.13
1,-5,13:17.14
3,-5,13:18.13
-3,-4,13:18.13
-1,-4,13:18.13
1,-4,13:17.14
2,-4,13:18.13
3,-4,13:18.13
6,-4,13:18.5
-5,-3,13:18.5
-3,-3,13:18.13
0,-3,13:18.13
1,-3,13:18.13
4,-3,13:18.13
5,-3,13:18.5
7,-3,13:18.5
-3,-2,13:17.14
-2,-2,13:18.13
-1,-2,13:18.13
3,-2,13:18.13
5,-2,13:17.14
-3,-1,13:18.13
0,-1,13:17.14
1,-1,13:18.13
6,-1,13:18.5
-4,0,13:18.13
-2,0,13:17.14
-1,0,13:18.13
1,0,13:18.13
4,0,13:18.13
5,0,13:18.5
-2,1,13:18.13
1,1,13:17.14
2,1,13:18.13
-2,2,13:18.13
-1,2,13:18.13
2,3,13:18.5
-2,-2,14:18.5
2,-2,14:18.5
-2,-1,14:18.5
-1,-1,14:18.5
0,-1,14:17.14
-1,0,14:18.5
0,0,14:18.5
-1,1,14:18.5
0,1,14:18.5
