[META]
version=2.0
spawnOnBlockType=2
spawnSunlight=True
spawnDarkness=True
spawnWater=False
spawnLava=False
underFill=False
randomRotation=True
dig=True
tree=False
branch=False
needsFoundation=True
rarity=100
collisionPercentage=20
spawnElevationMin=0
spawnElevationMax=200
spawnInBiome=Custom
[DATA]
-2,0,-3:17.12
-2,0,-2:17.12
-1,1,-2:17.12
-2,0,-1:17.12
-1,1,-1:17.12
-2,0,0:17.12
-1,1,0:17.12
-2,0,1:17.12
-1,1,1:17.12
-2,0,2:17.12
0,1,2:17.12
-2,-1,3:17.12
0,1,3:17.12
-2,-1,4:17.12
-1,1,4:17.12
1,2,4:17.12
-3,-2,5:17.12
-1,-1,5:17.12
-2,2,5:17.12
1,2,5:17.12
-3,-6,6:18.4
-2,-6,6:18.4
0,-6,6:18.4
-1,-5,6:18.4
-3,-4,6:18.4
-1,-4,6:18.4
-3,-2,6:17.12
-1,-1,6:17.12
0,-1,6:18.4
-5,0,6:18.4
-4,0,6:18.4
2,0,6:18.4
-1,1,6:18.4
0,1,6:18.4
-4,2,6:18.4
-3,2,6:17.12
-1,2,6:18.4
3,2,6:18.4
2,3,6:17.12
-2,-6,7:18.4
-3,-5,7:18.4
-2,-4,7:18.4
1,-4,7:18.4
-5,-3,7:18.4
-4,-3,7:17.12
-2,-3,7:17.12
0,-3,7:18.4
2,-3,7:18.4
-6,-2,7:18.4
-5,-2,7:18.4
-3,-2,7:18.4
-2,-2,7:18.4
0,-2,7:18.4
4,-2,7:18.4
-3,-1,7:18.4
-2,-1,7:18.4
0,-1,7:17.12
1,-1,7:18.4
2,-1,7:18.4
-7,0,7:18.4
-5,0,7:18.4
-3,0,7:18.4
0,0,7:18.4
1,0,7:18.4
2,0,7:18.4
4,0,7:18.4
6,0,7:18.4
7,0,7:18.4
-5,1,7:18.4
-2,1,7:18.4
1,1,7:18.4
2,1,7:18.4
4,1,7:18.4
5,1,7:18.4
6,1,7:18.4
-3,2,7:18.4
-1,2,7:18.4
0,2,7:18.4
1,2,7:18.4
2,2,7:17.12
3,2,7:18.4
6,2,7:18.4
7,2,7:18.4
-9,3,7:18.4
-5,3,7:18.4
-4,3,7:17.12
-3,3,7:18.4
-2,3,7:18.4
0,3,7:18.4
4,3,7:18.4
6,3,7:18.4
-9,4,7:18.4
-4,4,7:18.4
-3,4,7:18.4
-2,4,7:18.4
-1,4,7:18.4
0,4,7:18.4
3,4,7:17.12
-7,5,7:18.4
-5,5,7:18.4
-4,5,7:18.4
-1,5,7:18.4
0,5,7:18.4
2,5,7:18.4
-5,6,7:18.4
3,6,7:18.4
4,6,7:18.4
5,6,7:18.4
2,7,7:18.4
3,-6,8:18.4
0,-5,8:18.4
1,-5,8:18.4
-5,-4,8:17.12
-2,-4,8:18.4
3,-4,8:18.4
4,-4,8:18.4
5,-4,8:18.4
-1,-3,8:17.12
0,-3,8:18.4
1,-3,8:18.4
3,-3,8:18.4
4,-3,8:18.4
5,-3,8:18.4
-4,-2,8:18.4
1,-2,8:18.4
2,-2,8:18.4
4,-2,8:18.4
-6,-1,8:18.4
-5,-1,8:18.4
-4,-1,8:18.4
-3,-1,8:18.4
-2,-1,8:18.4
0,-1,8:18.4
1,-1,8:17.12
2,-1,8:18.4
3,-1,8:18.4
7,-1,8:18.4
-5,0,8:18.4
-4,0,8:18.4
-2,0,8:18.4
-1,0,8:18.4
2,0,8:18.4
4,0,8:18.4
5,0,8:18.4
-9,1,8:18.4
-8,1,8:18.4
-4,1,8:18.4
0,1,8:18.4
1,1,8:18.4
3,1,8:17.12
4,1,8:18.4
6,1,8:18.4
8,1,8:18.4
-3,2,8:18.4
3,2,8:18.4
4,2,8:18.4
5,2,8:18.4
7,2,8:18.4
-9,3,8:18.4
-2,3,8:18.4
0,3,8:18.4
1,3,8:18.4
6,3,8:18.4
-7,4,8:18.4
-5,4,8:17.4
-3,4,8:18.4
-1,4,8:18.4
0,4,8:18.4
1,4,8:18.4
2,4,8:18.4
4,4,8:18.4
-6,5,8:18.4
-3,5,8:18.4
-1,5,8:18.4
0,5,8:18.4
1,5,8:18.4
2,5,8:18.4
3,5,8:18.4
4,5,8:17.12
5,5,8:18.4
7,5,8:18.4
-5,6,8:18.4
0,6,8:18.4
4,6,8:18.4
6,6,8:18.4
-7,7,8:18.4
-3,7,8:18.4
1,7,8:18.4
5,7,8:18.4
-4,8,8:18.4
3,8,8:18.4
-5,9,8:18.4
4,9,8:18.4
2,10,8:18.4
-5,-9,9:18.4
0,-9,9:18.4
-7,-8,9:18.4
-5,-8,9:18.4
-4,-8,9:18.4
-2,-8,9:18.4
3,-8,9:18.4
-9,-7,9:18.12
-7,-7,9:18.4
-5,-7,9:18.4
-4,-7,9:18.4
-1,-7,9:18.4
-5,-6,9:18.4
-4,-6,9:18.4
-3,-6,9:18.4
-1,-6,9:18.4
0,-6,9:18.4
1,-6,9:18.4
5,-6,9:18.4
-8,-5,9:18.4
-7,-5,9:18.4
-6,-5,9:17.12
-5,-5,9:18.4
-4,-5,9:18.4
-1,-5,9:18.4
0,-5,9:18.4
3,-5,9:18.4
-10,-4,9:18.12
-8,-4,9:18.4
-4,-4,9:18.4
-1,-4,9:18.4
0,-4,9:17.12
1,-4,9:18.4
2,-4,9:18.4
5,-4,9:18.4
-10,-3,9:18.4
-9,-3,9:18.4
-8,-3,9:18.4
-7,-3,9:18.4
-6,-3,9:18.4
-5,-3,9:18.4
-4,-3,9:18.4
-3,-3,9:18.4
1,-3,9:18.4
2,-3,9:18.4
4,-3,9:18.4
-5,-2,9:18.4
-4,-2,9:18.4
-3,-2,9:18.4
-1,-2,9:18.4
3,-2,9:18.4
-9,-1,9:18.4
-7,-1,9:18.4
-5,-1,9:18.4
-4,-1,9:18.4
-3,-1,9:18.4
-2,-1,9:18.4
1,-1,9:18.4
3,-1,9:18.4
-3,0,9:18.4
-1,0,9:18.4
0,0,9:18.4
-7,1,9:18.4
-1,1,9:18.4
0,1,9:18.4
1,1,9:18.4
3,1,9:18.4
4,1,9:18.4
-1,2,9:18.4
1,2,9:18.4
4,2,9:18.4
-5,3,9:18.4
-2,3,9:18.4
0,3,9:18.4
1,3,9:18.4
-4,4,9:18.4
2,4,9:18.4
-1,6,9:18.4
1,6,9:18.4
-3,-4,10:18.4
-2,-4,10:18.4
-1,-4,10:18.4
-2,-3,10:18.4
-1,-3,10:18.4
2,-3,10:18.4
-3,-2,10:18.4
-1,-2,10:18.4
0,-2,10:18.4
3,-2,10:18.4
-4,-1,10:18.4
-2,-1,10:18.4
-1,-1,10:18.4
0,-1,10:18.4
1,-1,10:18.4
2,-1,10:18.4
-4,0,10:18.4
-6,1,10:18.4
2,1,10:18.4
4,1,10:18.4
-5,2,10:18.4
-4,2,10:18.4
-3,2,10:18.4
-2,2,10:18.4
0,2,10:18.4
2,2,10:18.4
-6,3,10:18.4
-4,3,10:18.4
-2,3,10:18.4
1,3,10:18.4
4,3,10:18.4
-2,4,10:18.4
-4,5,10:18.4
-1,5,10:18.4
0,5,10:18.4
2,5,10:18.4
-2,6,10:18.4
-1,6,10:18.4
