[META]
version=2.0
spawnOnBlockType=2
spawnSunlight=True
spawnDarkness=True
spawnWater=False
spawnLava=False
underFill=False
randomRotation=True
dig=True
tree=False
branch=False
needsFoundation=True
rarity=100
collisionPercentage=20
spawnElevationMin=0
spawnElevationMax=200
spawnInBiome=Custom
[DATA]
0,0,0:17.14
1,-1,1:18.4
0,0,1:17.14
1,0,1:18.4
-1,-2,2:18.4
0,-2,2:18.4
0,-1,2:18.4
-2,0,2:18.4
0,0,2:17.14
-1,1,2:18.4
0,1,2:18.4
0,2,2:18.4
1,2,2:18.4
-1,-2,3:18.4
1,-2,3:18.4
-2,-1,3:18.4
0,-1,3:18.4
1,-1,3:18.4
0,0,3:17.14
2,0,3:18.4
-1,1,3:18.4
0,1,3:18.4
1,1,3:17.14
2,1,3:18.4
-1,2,3:18.4
1,2,3:18.4
1,-2,4:18.4
-1,-1,4:18.4
-1,0,4:18.4
0,0,4:17.14
2,0,4:18.4
-1,1,4:18.4
0,2,4:18.4
0,-2,5:18.4
-1,-1,5:18.4
0,-1,5:18.4
1,-1,5:18.4
-2,0,5:18.4
2,0,5:18.4
0,1,5:18.4
2,1,5:18.4
1,1,6:18.4
