[META]
version=2.0
spawnOnBlockType=2
spawnSunlight=True
spawnDarkness=True
spawnWater=False
spawnLava=False
underFill=False
randomRotation=True
dig=True
tree=False
branch=False
needsFoundation=True
rarity=100
collisionPercentage=20
spawnElevationMin=0
spawnElevationMax=200
spawnInBiome=Custom
[DATA]
-1,-1,-3:17.12
1,-1,-3:17.12
2,-3,-2:17.12
0,-2,-2:17.12
-1,-1,-2:17.12
1,-1,-2:17.12
0,0,-2:17.12
1,1,-2:17.12
0,-3,-1:17.12
2,-3,-1:17.12
0,-2,-1:17.12
1,-2,-1:17.12
-1,-1,-1:17.12
1,-1,-1:17.12
2,-1,-1:17.12
0,0,-1:17.12
1,0,-1:17.12
1,1,-1:17.12
0,-3,0:17.12
2,-3,0:17.12
0,-2,0:17.12
1,-2,0:17.12
-1,-1,0:17.12
0,-1,0:17.12
1,-1,0:17.12
2,-1,0:17.12
0,0,0:17.12
1,0,0:17.12
1,1,0:17.12
0,-2,1:17.12
1,-2,1:17.12
0,-1,1:17.12
1,-1,1:17.12
1,0,1:17.12
0,-2,2:17.12
1,-2,2:17.12
-1,-1,2:17.12
0,-1,2:17.12
1,-1,2:17.12
0,0,2:17.12
1,0,2:17.12
1,-2,3:17.12
-1,-1,3:17.12
0,-1,3:17.12
1,-1,3:17.12
-1,0,3:17.12
0,0,3:17.12
1,-2,4:17.12
0,-1,4:17.12
1,-1,4:17.12
-1,0,4:17.12
2,-3,5:17.12
1,-1,5:17.12
-1,0,5:17.12
2,-3,6:17.12
1,-1,6:17.12
-2,1,6:17.12
3,-4,7:17.12
2,0,7:17.12
-2,1,7:17.12
3,-4,8:17.12
-2,0,8:17.12
2,0,8:17.12
-3,2,8:17.12
4,-5,9:17.12
-3,-1,9:17.12
1,-1,9:17.12
3,1,9:17.12
-3,2,9:17.12
5,-6,10:17.12
-3,-2,10:17.12
1,-1,10:17.12
3,1,10:17.12
-4,3,10:17.12
6,-7,11:17.12
-4,-3,11:17.12
0,-2,11:17.12
4,2,11:17.12
-5,4,11:17.12
-3,4,11:17.12
5,-13,12:18.12
7,-13,12:18.12
9,-13,12:18.12
4,-12,12:18.12
7,-12,12:18.12
8,-12,12:18.12
9,-12,12:18.12
12,-12,12:18.12
3,-11,12:18.12
5,-11,12:18.12
12,-11,12:18.12
2,-10,12:18.12
8,-10,12:18.12
13,-10,12:18.12
7,-9,12:18.12
8,-9,12:17.12
9,-9,12:18.12
10,-9,12:18.12
12,-9,12:18.12
13,-9,12:18.12
2,-8,12:18.12
3,-8,12:18.12
5,-8,12:18.12
7,-8,12:17.12
8,-8,12:18.12
13,-8,12:18.12
-6,-7,12:18.12
-5,-7,12:18.12
5,-7,12:18.12
7,-7,12:18.12
8,-7,12:18.12
-6,-6,12:18.12
4,-6,12:18.12
6,-6,12:18.12
9,-6,12:18.12
11,-6,12:18.12
-8,-5,12:18.12
-7,-5,12:18.12
4,-5,12:18.12
5,-5,12:18.12
7,-5,12:18.12
8,-5,12:18.12
9,-5,12:18.12
11,-5,12:18.12
-9,-4,12:18.12
-5,-4,12:18.12
-4,-4,12:17.12
8,-4,12:18.12
9,-4,12:18.12
-9,-3,12:18.12
-7,-3,12:18.12
-5,-3,12:18.12
-2,-3,12:18.12
6,-3,12:18.12
8,-3,12:18.12
-6,-2,12:18.12
-5,-2,12:17.12
-4,-2,12:18.12
-3,-2,12:18.12
0,-2,12:17.12
-8,-1,12:18.12
-7,0,12:18.12
-5,0,12:18.12
-3,0,12:18.12
-1,0,12:18.12
0,0,12:18.12
-7,1,12:18.12
-5,1,12:18.12
-3,1,12:18.12
-2,1,12:18.12
-5,2,12:18.12
-4,2,12:18.12
0,2,12:18.12
4,2,12:17.12
-7,3,12:18.12
2,3,12:18.12
-7,4,12:18.12
-8,5,12:18.12
-7,5,12:18.12
-6,5,12:17.12
-4,5,12:18.12
-3,5,12:17.12
0,5,12:18.12
1,5,12:18.12
-5,6,12:18.12
-4,6,12:18.12
-3,6,12:18.12
-4,7,12:18.12
-3,7,12:18.12
-2,7,12:18.12
-1,7,12:18.12
2,7,12:18.12
-6,8,12:18.12
-5,8,12:18.12
0,8,12:18.12
-6,9,12:18.12
-2,9,12:18.12
-4,10,12:18.12
7,-14,13:18.12
12,-14,13:18.12
8,-13,13:18.12
9,-13,13:18.12
4,-12,13:18.12
6,-12,13:18.12
8,-12,13:18.12
9,-12,13:18.12
10,-12,13:18.12
9,-11,13:18.12
-5,-10,13:18.12
-4,-10,13:18.12
-3,-10,13:18.12
7,-10,13:18.12
8,-10,13:18.12
9,-10,13:17.12
-4,-9,13:18.12
-2,-9,13:18.12
4,-9,13:18.12
5,-9,13:18.12
8,-9,13:18.12
12,-9,13:18.12
10,-8,13:18.12
-8,-7,13:18.12
-5,-7,13:18.12
-4,-7,13:18.12
-2,-7,13:18.12
8,-7,13:18.12
9,-7,13:18.12
-9,-6,13:18.12
-8,-6,13:18.12
-7,-6,13:18.12
7,-6,13:18.12
11,-6,13:18.12
-9,-5,13:18.12
-7,-5,13:18.12
-6,-5,13:18.12
-5,-5,13:17.12
-3,-5,13:18.12
-2,-5,13:18.12
0,-5,13:18.12
7,-5,13:18.12
9,-5,13:18.12
10,-5,13:18.12
-6,-4,13:18.12
-4,-4,13:18.12
-9,-3,13:18.12
-5,-3,13:18.12
-4,-3,13:18.12
-3,-3,13:18.12
-1,-3,13:17.12
-11,-2,13:18.12
-10,-2,13:18.12
-9,-2,13:18.12
-8,-2,13:18.12
-7,-2,13:18.12
-6,-2,13:17.12
-5,-2,13:18.12
-4,-2,13:18.12
3,-2,13:18.12
4,-2,13:18.12
-7,-1,13:18.12
-6,-1,13:18.12
-2,-1,13:18.12
-1,-1,13:18.12
1,-1,13:17.12
3,-1,13:18.12
4,-1,13:18.12
7,-1,13:18.12
-11,0,13:18.12
-8,0,13:18.12
-6,0,13:18.12
-5,0,13:18.12
-3,0,13:18.12
6,0,13:18.12
8,0,13:18.12
9,0,13:18.12
-10,1,13:18.12
-7,1,13:18.12
-5,1,13:18.12
-4,1,13:18.12
-2,1,13:18.12
0,1,13:18.12
1,1,13:18.12
10,1,13:18.12
-8,2,13:18.12
-3,2,13:18.12
0,2,13:18.12
4,2,13:18.12
5,2,13:18.12
10,2,13:18.12
-8,3,13:18.12
-6,3,13:18.12
-5,3,13:18.12
0,3,13:18.12
1,3,13:18.12
5,3,13:17.12
7,3,13:18.12
8,3,13:18.12
10,3,13:18.12
-4,4,13:18.12
0,4,13:18.12
3,4,13:18.12
4,4,13:18.12
-7,5,13:18.12
0,5,13:18.12
2,5,13:18.12
5,5,13:18.12
6,5,13:18.12
7,5,13:18.12
8,5,13:18.12
10,5,13:18.12
-7,6,13:17.12
-6,6,13:18.12
-3,6,13:17.12
0,6,13:18.12
1,6,13:18.12
5,6,13:18.12
6,6,13:18.12
8,6,13:18.12
9,6,13:18.12
-2,7,13:18.12
2,7,13:18.12
3,7,13:18.12
5,7,13:18.12
-6,8,13:18.12
-3,8,13:18.12
-2,8,13:18.12
1,8,13:18.12
7,8,13:18.12
-5,9,13:18.12
-3,9,13:18.12
0,9,13:18.12
1,9,13:18.12
-6,10,13:18.12
-4,10,13:18.12
-2,10,13:18.12
11,-14,14:18.12
7,-13,14:18.12
11,-13,14:18.12
12,-13,14:18.12
5,-12,14:18.12
12,-12,14:18.12
13,-12,14:18.12
-3,-11,14:18.4
6,-11,14:18.12
8,-11,14:18.12
9,-11,14:18.12
10,-11,14:17.12
11,-11,14:18.12
13,-11,14:18.12
-6,-10,14:18.12
10,-10,14:18.12
14,-10,14:18.12
-7,-9,14:18.12
-3,-9,14:18.12
6,-8,14:18.12
10,-8,14:18.12
11,-8,14:18.12
8,-7,14:18.12
11,-7,14:18.12
-10,-6,14:18.12
-9,-6,14:18.12
-8,-6,14:18.12
-7,-6,14:18.12
-6,-6,14:18.12
-5,-6,14:17.12
-4,-6,14:18.12
8,-6,14:18.12
9,-6,14:18.12
10,-6,14:18.12
-7,-5,14:18.12
-6,-5,14:18.12
-3,-5,14:18.12
0,-5,14:18.12
-9,-4,14:18.12
-6,-4,14:18.12
0,-4,14:18.12
-12,-3,14:18.4
-8,-3,14:18.12
-6,-3,14:18.12
-5,-3,14:18.12
-1,-3,14:17.12
-8,-2,14:18.12
-6,-2,14:18.12
-5,-2,14:18.12
-4,-2,14:18.12
-3,-2,14:18.12
-12,-1,14:18.4
-11,-1,14:18.12
-8,-1,14:18.12
-7,-1,14:17.12
-6,-1,14:18.12
-5,-1,14:18.12
-4,-1,14:18.12
-2,-1,14:18.12
-12,0,14:18.4
-10,0,14:18.12
-9,0,14:18.12
-6,0,14:18.12
-4,0,14:18.12
-2,0,14:18.12
2,0,14:17.12
4,0,14:18.12
6,0,14:18.12
-12,1,14:18.4
-5,1,14:18.12
8,1,14:18.12
-11,2,14:18.12
-10,2,14:18.12
-4,2,14:18.12
-3,2,14:18.12
-2,2,14:18.12
4,2,14:18.12
11,2,14:18.4
-9,3,14:18.12
-8,3,14:18.12
-6,3,14:18.12
-5,3,14:18.12
-4,3,14:18.12
-2,3,14:18.12
0,3,14:18.12
1,3,14:18.12
7,3,14:18.12
8,3,14:18.12
10,3,14:18.12
-11,4,14:18.12
-8,4,14:18.12
-6,4,14:18.12
-5,4,14:18.12
-4,4,14:18.12
-2,4,14:18.12
0,4,14:18.12
1,4,14:18.12
2,4,14:18.12
6,4,14:17.12
9,4,14:18.12
10,4,14:18.12
-10,5,14:18.12
-8,5,14:18.12
-7,5,14:18.12
-2,5,14:18.12
2,5,14:18.12
9,5,14:18.12
11,5,14:18.4
-13,6,14:18.4
-9,6,14:18.12
-8,6,14:18.12
-5,6,14:18.12
-4,6,14:18.12
1,6,14:18.12
9,6,14:18.12
10,6,14:18.12
-13,7,14:18.4
-9,7,14:18.12
-8,7,14:17.12
-4,7,14:18.12
-3,7,14:18.12
-2,7,14:17.12
-1,7,14:18.12
0,7,14:18.12
1,7,14:18.12
9,7,14:18.12
-12,8,14:18.12
-10,8,14:18.12
-8,8,14:18.12
-7,8,14:18.12
-4,8,14:18.12
7,8,14:18.12
8,8,14:18.12
-13,9,14:18.4
-6,9,14:18.12
-5,9,14:18.12
-1,9,14:18.12
6,9,14:18.4
7,9,14:18.4
-10,10,14:18.12
1,10,14:18.12
-8,11,14:18.12
-2,11,14:18.12
5,-13,15:18.12
4,-12,15:18.12
8,-12,15:18.12
6,-11,15:18.12
-2,-10,15:18.12
2,-10,15:18.12
4,-10,15:18.12
5,-10,15:18.12
7,-10,15:18.12
11,-10,15:18.12
-2,-9,15:18.12
-1,-9,15:18.12
4,-9,15:18.12
6,-9,15:18.12
-4,-8,15:18.12
0,-8,15:18.12
1,-8,15:18.12
4,-8,15:18.12
7,-8,15:18.12
9,-8,15:18.12
10,-8,15:18.12
11,-8,15:18.12
-4,-7,15:18.12
0,-7,15:18.12
1,-7,15:18.12
4,-7,15:18.12
8,-7,15:18.12
9,-7,15:18.12
-8,-6,15:18.12
-5,-6,15:17.12
-3,-6,15:18.12
-2,-6,15:18.12
0,-6,15:18.12
4,-6,15:18.12
5,-6,15:18.12
6,-6,15:18.12
7,-6,15:18.12
8,-6,15:18.12
10,-6,15:18.12
-10,-5,15:18.12
-8,-5,15:18.12
-5,-5,15:18.12
-1,-5,15:18.12
0,-5,15:18.12
1,-5,15:18.12
2,-5,15:18.12
4,-5,15:18.12
-10,-4,15:18.12
-8,-4,15:18.12
-7,-4,15:18.12
-2,-4,15:17.12
-1,-4,15:18.12
0,-4,15:18.12
2,-4,15:18.12
5,-4,15:18.12
6,-4,15:18.12
-8,-3,15:18.12
-7,-3,15:18.12
-5,-3,15:18.12
0,-3,15:18.12
4,-3,15:18.12
6,-3,15:18.12
-5,-2,15:18.12
-4,-2,15:18.12
-2,-2,15:18.12
-1,-2,15:18.12
4,-2,15:18.12
-1,-1,15:18.12
5,-1,15:18.12
-3,0,15:18.12
1,0,15:18.12
2,0,15:17.12
-3,1,15:18.12
-2,1,15:18.12
-1,1,15:18.12
-10,2,15:18.12
2,2,15:18.12
5,2,15:18.12
-11,3,15:18.12
-8,3,15:18.12
-6,3,15:18.12
-4,3,15:18.12
-3,3,15:18.12
-1,3,15:18.12
2,3,15:18.12
4,3,15:18.12
6,3,15:18.12
-12,4,15:18.12
-7,4,15:18.12
-6,4,15:18.12
-5,4,15:18.12
-2,4,15:18.12
-10,5,15:18.12
-5,5,15:18.12
1,5,15:18.12
2,5,15:18.12
-11,6,15:18.12
-10,6,15:18.12
-9,6,15:18.12
-6,6,15:18.12
-11,7,15:18.12
-9,7,15:18.12
-8,7,15:17.12
-7,7,15:18.12
-6,7,15:18.12
-5,7,15:18.12
-4,7,15:18.12
-2,7,15:17.12
3,7,15:18.12
-10,8,15:18.12
-8,8,15:18.12
-6,8,15:18.12
-4,8,15:18.12
-2,8,15:18.12
0,8,15:18.12
-5,9,15:18.12
-2,9,15:18.12
-11,10,15:18.12
-8,10,15:18.12
-7,10,15:18.12
-4,10,15:18.12
-3,10,15:18.12
-10,11,15:18.12
-8,11,15:18.12
-6,11,15:18.12
-5,11,15:18.12
0,11,15:18.12
1,11,15:18.12
-9,12,15:18.4
-8,12,15:18.4
-3,12,15:18.4
-2,-9,16:18.12
-1,-9,16:18.12
-2,-8,16:18.12
0,-8,16:18.12
-5,-7,16:18.12
-3,-7,16:18.12
-1,-7,16:18.12
-3,-6,16:18.12
0,-6,16:18.12
-7,-5,16:18.12
-6,-5,16:18.12
-3,-5,16:18.12
0,-5,16:18.12
1,-5,16:18.12
2,-5,16:18.12
-6,-4,16:18.12
-3,-4,16:18.12
-1,-4,16:18.12
0,-4,16:18.12
4,-4,16:18.12
-2,-3,16:18.12
-1,-3,16:18.12
4,-3,16:18.12
-7,-2,16:18.12
-5,-2,16:18.12
-2,-2,16:18.12
2,-2,16:18.12
5,-2,16:18.12
7,-2,16:18.12
-6,-1,16:18.12
-2,-1,16:18.12
3,-1,16:18.12
5,-1,16:18.12
-7,0,16:18.12
-6,0,16:18.12
-5,0,16:18.12
-3,0,16:18.12
-2,0,16:18.12
-1,0,16:18.12
0,0,16:18.12
3,0,16:18.12
4,0,16:18.12
5,0,16:18.12
-10,1,16:18.12
-6,1,16:18.12
-3,1,16:18.12
-2,1,16:18.12
-1,1,16:18.12
0,1,16:18.12
2,1,16:18.12
4,1,16:18.12
7,1,16:18.12
-6,2,16:18.12
-3,2,16:18.12
-9,3,16:18.12
-6,3,16:18.12
-10,4,16:18.12
-9,4,16:18.12
-7,4,16:18.12
-4,4,16:18.12
-2,4,16:18.12
2,4,16:18.12
3,4,16:18.12
-8,5,16:18.12
-6,5,16:18.12
0,5,16:18.12
4,5,16:18.12
-8,6,16:18.12
-6,6,16:18.12
-4,6,16:18.12
-2,7,16:18.12
-4,-9,17:18.12
0,-7,17:18.12
1,-6,17:18.12
2,-6,17:18.12
3,-6,17:18.12
-6,-5,17:18.12
-1,-5,17:18.12
3,-5,17:18.12
-6,-4,17:18.12
-5,-4,17:18.12
1,-4,17:18.12
2,-4,17:18.12
-1,-3,17:18.12
3,-3,17:18.12
-7,-2,17:18.12
-6,-2,17:18.12
-4,-2,17:18.12
2,-2,17:18.12
-6,-1,17:18.12
-5,-1,17:18.12
-1,-1,17:18.12
4,-1,17:18.12
-3,0,17:18.12
0,0,17:18.12
1,0,17:18.12
3,0,17:18.12
5,0,17:18.12
-2,1,17:18.12
-1,1,17:18.12
0,1,17:18.12
1,2,17:18.12
2,2,17:18.12
3,2,17:18.12
1,3,17:18.12
2,3,17:18.12
-1,4,17:18.12
0,4,17:18.12
3,4,17:18.12
4,4,17:18.12
2,5,17:18.12
3,5,17:18.12
