[META]
version=2.0
spawnOnBlockType=2
spawnSunlight=True
spawnDarkness=True
spawnWater=False
spawnLava=False
underFill=False
randomRotation=True
dig=True
tree=False
branch=False
needsFoundation=True
rarity=100
collisionPercentage=20
spawnElevationMin=0
spawnElevationMax=200
spawnInBiome=Custom
[DATA]
-1,2,-3:17.14
-3,3,-3:17.14
-1,4,-3:17.14
-2,2,-2:17.14
-1,2,-2:17.14
-3,3,-2:17.14
-2,4,-2:17.14
-1,4,-2:17.14
-3,2,-1:17.14
-2,2,-1:17.14
-1,2,-1:17.14
-3,3,-1:17.14
-1,3,-1:17.14
-3,4,-1:17.14
-2,4,-1:17.14
-1,4,-1:17.14
-3,2,0:17.14
-2,2,0:17.14
-1,2,0:17.14
-3,3,0:17.14
-2,3,0:17.14
-1,3,0:17.14
-3,4,0:17.14
-2,4,0:17.14
-1,4,0:17.14
-3,2,1:17.14
-2,2,1:17.14
-1,2,1:17.14
-3,3,1:17.14
-2,3,1:17.14
-1,3,1:17.14
-3,4,1:17.14
-2,4,1:17.14
-1,4,1:17.14
-2,2,2:17.14
-1,2,2:17.14
-3,3,2:17.14
-2,3,2:17.14
-1,3,2:17.14
-3,4,2:17.14
-2,4,2:17.14
-1,4,2:17.14
-2,2,3:17.14
-1,2,3:17.14
-3,3,3:17.14
-2,3,3:17.14
-1,3,3:17.14
-3,4,3:17.14
-2,4,3:17.14
-1,4,3:17.14
-2,2,4:17.14
-1,2,4:17.14
-3,3,4:17.14
-2,3,4:17.14
-1,3,4:17.14
-3,4,4:17.14
-2,4,4:17.14
-1,4,4:17.14
-2,2,5:17.14
-3,3,5:17.14
-2,3,5:17.14
-1,3,5:17.14
-3,4,5:17.14
-2,4,5:17.14
-1,4,5:17.14
-3,2,6:17.14
-2,2,6:17.14
-3,3,6:17.14
-2,3,6:17.14
-1,3,6:17.14
-3,4,6:17.14
-2,4,6:17.14
-1,4,6:17.14
-3,2,7:17.14
-2,2,7:17.14
-3,3,7:17.14
-2,3,7:17.14
-1,3,7:17.14
-3,4,7:17.14
-2,4,7:17.14
-3,2,8:17.14
-2,2,8:17.14
-3,3,8:17.14
-2,3,8:17.14
-1,3,8:17.14
-2,4,8:17.14
-3,2,9:17.14
-2,2,9:17.14
-3,3,9:17.14
-2,3,9:17.14
-1,3,9:17.14
-3,4,9:17.14
-2,4,9:17.14
-3,2,10:17.14
-2,2,10:17.14
-3,3,10:17.14
-2,3,10:17.14
-1,3,10:17.14
-3,4,10:17.14
-2,4,10:17.14
-3,2,11:17.14
-2,2,11:17.14
-3,3,11:17.14
-2,3,11:17.14
-1,3,11:17.14
-2,4,11:17.14
-1,4,11:17.14
-3,2,12:17.14
-2,2,12:17.14
-3,3,12:17.14
-2,3,12:17.14
-1,3,12:17.14
-2,4,12:17.14
-1,4,12:17.14
-2,2,13:17.14
-1,2,13:17.14
-3,3,13:17.14
-2,3,13:17.14
-1,3,13:17.14
-2,4,13:17.14
-1,4,13:17.14
-2,2,14:17.14
-1,2,14:17.14
-3,3,14:17.14
-2,3,14:17.14
-1,3,14:17.14
-2,4,14:17.14
-1,4,14:17.14
-2,2,15:17.14
-1,2,15:17.14
-3,3,15:17.14
-2,3,15:17.14
-1,3,15:17.14
-2,4,15:17.14
-1,4,15:17.14
-2,2,16:17.14
-1,2,16:17.14
-3,3,16:17.14
-2,3,16:17.14
-1,3,16:17.14
-2,4,16:17.14
-1,4,16:17.14
-2,2,17:17.14
-3,3,17:17.14
-2,3,17:17.14
-1,3,17:17.14
-2,4,17:17.14
-2,2,18:17.14
-3,3,18:17.14
-2,3,18:17.14
-1,3,18:17.14
-2,4,18:17.14
-2,2,19:17.14
-3,3,19:17.14
-2,3,19:17.14
-1,3,19:17.14
-2,4,19:17.14
-2,2,20:17.14
-3,3,20:17.14
-2,3,20:17.14
-1,3,20:17.14
-2,4,20:17.14
-3,2,21:17.14
-2,2,21:17.14
-3,3,21:17.14
-2,3,21:17.14
-1,3,21:17.14
-3,4,21:17.14
-2,4,21:17.14
-3,2,22:17.14
-2,2,22:17.14
-3,3,22:17.14
-2,3,22:17.14
-1,3,22:17.14
-2,4,22:17.14
-3,2,23:17.14
-2,2,23:17.14
-3,3,23:17.14
-2,3,23:17.14
-1,3,23:17.14
-2,4,23:17.14
-3,2,24:17.14
-2,2,24:17.14
-3,3,24:17.14
-2,3,24:17.14
-1,3,24:17.14
-2,4,24:17.14
-2,1,25:17.14
-3,2,25:17.14
-2,2,25:17.14
-1,2,25:17.14
-4,3,25:17.14
-3,3,25:17.14
-2,3,25:17.14
-1,3,25:17.14
0,3,25:17.14
-3,4,25:17.14
-2,4,25:17.14
-3,7,25:17.14
-3,8,25:17.14
-3,9,25:17.14
-1,-1,26:17.14
-2,0,26:17.14
-1,0,26:17.14
-2,1,26:17.14
-5,2,26:17.14
-4,2,26:17.14
-3,2,26:17.14
-2,2,26:17.14
-1,2,26:17.14
0,2,26:17.14
1,2,26:17.14
2,2,26:17.14
-8,3,26:17.14
-6,3,26:17.14
-5,3,26:17.14
-4,3,26:17.14
-3,3,26:17.14
-2,3,26:17.14
-1,3,26:17.14
0,3,26:17.14
1,3,26:17.14
-3,4,26:17.14
-2,4,26:17.14
-3,5,26:17.14
-3,6,26:17.14
-4,7,26:18.13
-3,7,26:18.13
-6,8,26:18.13
-4,9,26:17.14
-3,9,26:18.13
-2,9,26:18.13
-6,10,26:18.13
-5,10,26:18.13
-3,10,26:18.13
-2,10,26:17.14
-1,10,26:18.13
0,10,26:18.13
-3,11,26:18.13
-1,11,26:18.13
-2,12,26:18.13
0,-4,27:18.13
1,-4,27:18.13
-2,-3,27:18.13
-1,-2,27:18.13
0,-2,27:17.14
0,-1,27:18.13
3,0,27:18.13
-10,2,27:18.13
3,2,27:17.14
5,2,27:18.13
-9,3,27:18.13
-7,3,27:17.14
-6,3,27:17.14
-2,3,27:17.14
3,3,27:18.13
4,3,27:18.13
-10,4,27:18.13
-9,4,27:17.14
-8,4,27:18.13
-1,4,27:17.14
-8,5,27:18.13
-3,8,27:18.13
-5,9,27:18.13
-2,9,27:18.13
-3,10,27:18.13
-4,11,27:18.13
-3,11,27:18.13
0,-4,28:18.13
0,-3,28:18.13
-2,-2,28:18.13
-1,-2,28:18.13
1,-2,28:18.13
-2,-1,28:18.13
1,-1,28:18.13
2,-1,28:18.13
1,0,28:18.13
5,0,28:18.13
-9,1,28:18.13
-6,1,28:18.13
-5,1,28:18.13
-7,2,28:17.14
-5,2,28:18.13
3,2,28:18.13
-6,3,28:18.13
-7,4,28:18.13
-1,4,28:17.14
0,4,28:17.14
-3,5,28:17.14
-2,5,28:17.14
-8,0,29:18.13
-7,0,29:18.13
0,1,29:18.13
0,2,29:18.13
-9,3,29:18.13
-7,3,29:18.13
-1,3,29:17.14
0,3,29:18.13
1,3,29:18.13
2,3,29:18.13
-7,4,29:18.13
-4,4,29:18.13
-3,4,29:18.13
-2,4,29:18.13
0,4,29:18.13
1,4,29:18.13
2,4,29:18.13
-6,5,29:18.13
-5,5,29:18.13
-4,5,29:18.13
1,5,29:17.14
-4,6,29:17.14
-2,6,29:18.13
1,6,29:18.13
-6,7,29:18.13
-5,7,29:18.13
-2,7,29:18.13
-5,8,29:18.13
1,1,30:18.13
0,2,30:18.13
1,2,30:18.13
2,2,30:18.13
-5,3,30:18.13
-4,3,30:18.13
-3,3,30:18.13
1,3,30:18.13
2,3,30:18.13
-6,4,30:18.13
1,4,30:18.13
2,4,30:18.13
-5,5,30:18.13
-1,5,30:18.13
1,5,30:18.13
-1,6,30:18.13
