[META]
version=2.0
spawnOnBlockType=2
spawnSunlight=True
spawnDarkness=True
spawnWater=False
spawnLava=False
underFill=False
randomRotation=True
dig=True
tree=False
branch=False
needsFoundation=True
rarity=100
collisionPercentage=20
spawnElevationMin=0
spawnElevationMax=200
spawnInBiome=Custom
[DATA]
0,-1,0:17.14
0,-1,1:17.14
0,-2,2:17.14
-1,0,2:17.14
1,0,2:17.14
-1,-3,3:17.14
1,-3,3:17.14
-2,-1,3:17.14
0,-1,3:17.14
2,-1,3:17.14
3,-1,3:17.14
-1,1,3:17.14
1,1,3:17.14
3,0,6:81.0
-1,-3,6:81.0
1,1,5:81.0
-1,1,5:81.0
3,0,5:81.0
2,-1,5:81.0
0,-1,5:81.0
-2,-1,5:81.13
1,-3,5:81.13
-1,-3,5:81.0
1,1,4:81.0
-1,1,4:81.0
3,0,4:81.0
2,-1,4:81.0
0,-1,4:81.0
-2,-1,4:81.0
1,-3,4:81.0
-1,-3,4:81.0
