[META]
version=2.0
spawnOnBlockType=2
spawnSunlight=True
spawnDarkness=True
spawnWater=False
spawnLava=False
underFill=False
randomRotation=True
dig=True
tree=False
branch=False
needsFoundation=True
rarity=100
collisionPercentage=20
spawnElevationMin=0
spawnElevationMax=200
spawnInBiome=Custom
[DATA]
-5,-4,-3:17.12
-7,-3,-3:17.12
-2,-3,-3:17.12
-9,-2,-3:17.12
2,0,-3:17.12
-11,1,-3:17.12
-10,3,-3:17.12
2,4,-3:17.12
-11,5,-3:17.12
0,5,-3:17.12
-10,7,-3:17.12
-1,7,-3:17.12
-8,8,-3:17.12
-5,9,-3:17.12
-2,9,-3:17.12
-5,-4,-2:17.12
-4,-4,-2:17.12
-7,-3,-2:17.12
-4,-3,-2:17.12
-2,-3,-2:17.12
-9,-2,-2:17.12
0,-2,-2:17.12
-10,-1,-2:17.12
1,-1,-2:17.12
2,0,-2:17.12
-11,1,-2:17.12
-11,2,-2:17.12
1,2,-2:17.12
-10,3,-2:17.12
-10,4,-2:17.12
2,4,-2:17.12
-11,5,-2:17.12
0,5,-2:17.12
0,6,-2:17.12
-10,7,-2:17.12
-9,7,-2:17.12
-1,7,-2:17.12
-8,8,-2:17.2
-7,8,-2:17.12
-2,8,-2:17.12
-5,9,-2:17.12
-3,9,-2:17.12
-2,9,-2:17.12
-6,-4,-1:17.12
-5,-4,-1:17.2
-4,-4,-1:17.2
-3,-4,-1:17.12
-8,-3,-1:17.2
-7,-3,-1:17.12
-6,-3,-1:17.12
-5,-3,-1:17.12
-4,-3,-1:17.12
-3,-3,-1:17.12
-2,-3,-1:17.2
0,-3,-1:17.12
-9,-2,-1:17.12
-8,-2,-1:17.12
-1,-2,-1:17.12
0,-2,-1:17.2
-10,-1,-1:17.2
1,-1,-1:17.12
-11,0,-1:17.12
-10,0,-1:17.12
1,0,-1:17.12
2,0,-1:17.2
-11,1,-1:17.2
-10,1,-1:17.12
1,1,-1:17.12
2,1,-1:17.2
-11,2,-1:17.2
-10,2,-1:17.12
1,2,-1:17.12
-10,3,-1:17.12
1,3,-1:17.12
2,3,-1:17.12
-10,4,-1:17.2
1,4,-1:17.12
2,4,-1:17.12
-11,5,-1:17.12
0,5,-1:17.12
-10,6,-1:17.2
0,6,-1:17.12
-10,7,-1:17.12
-9,7,-1:17.12
-1,7,-1:17.2
-9,8,-1:17.2
-8,8,-1:17.2
-7,8,-1:17.12
-2,8,-1:17.12
-6,9,-1:17.12
-5,9,-1:17.12
-4,9,-1:17.12
-3,9,-1:17.12
-2,9,-1:17.2
-7,-4,0:17.14
-6,-4,0:17.14
-5,-4,0:17.14
-4,-4,0:17.14
-3,-4,0:17.14
-9,-3,0:17.14
-8,-3,0:17.14
-7,-3,0:17.14
-6,-3,0:17.14
-5,-3,0:17.14
-4,-3,0:17.14
-3,-3,0:17.14
-2,-3,0:17.14
0,-3,0:17.14
-10,-2,0:17.14
-9,-2,0:17.14
-8,-2,0:17.14
-7,-2,0:17.14
-1,-2,0:17.14
0,-2,0:17.14
-10,-1,0:17.14
-9,-1,0:17.14
0,-1,0:17.14
1,-1,0:17.14
-11,0,0:17.14
-10,0,0:17.14
-9,0,0:17.14
1,0,0:17.14
2,0,0:17.14
-11,1,0:17.14
-10,1,0:17.14
1,1,0:17.14
2,1,0:17.14
-11,2,0:17.14
-10,2,0:17.14
1,2,0:17.14
-10,3,0:17.14
1,3,0:17.12
2,3,0:17.12
-10,4,0:17.14
1,4,0:17.14
2,4,0:17.12
-11,5,0:17.14
0,5,0:17.14
-10,6,0:17.14
0,6,0:17.14
-10,7,0:17.14
-9,7,0:17.14
-1,7,0:17.2
-9,8,0:17.14
-8,8,0:17.14
-7,8,0:17.14
-2,8,0:17.12
-6,9,0:17.14
-5,9,0:17.12
-4,9,0:17.12
-3,9,0:17.14
-2,9,0:17.14
-6,-4,1:17.14
-5,-4,1:17.14
-4,-4,1:17.14
-8,-3,1:17.14
-7,-3,1:17.14
-6,-3,1:17.14
-5,-3,1:17.14
-4,-3,1:17.14
-3,-3,1:17.14
-2,-3,1:17.14
-9,-2,1:17.14
-8,-2,1:17.14
-7,-2,1:17.14
-1,-2,1:17.14
0,-2,1:17.14
-10,-1,1:17.14
-9,-1,1:17.14
0,-1,1:17.14
1,-1,1:17.14
-10,0,1:17.14
1,0,1:17.14
-11,1,1:17.14
-10,1,1:17.14
1,1,1:17.14
-11,2,1:17.14
-10,2,1:17.14
1,2,1:17.14
-10,3,1:17.14
1,3,1:17.14
2,3,1:17.12
-10,4,1:17.14
0,4,1:17.14
1,4,1:17.12
-11,5,1:17.14
-1,5,1:17.14
0,5,1:17.14
-10,6,1:17.14
-1,6,1:17.14
0,6,1:17.14
-9,7,1:17.14
-1,7,1:17.14
-8,8,1:17.14
-7,8,1:17.14
-2,8,1:17.12
-6,9,1:17.14
-5,9,1:17.12
-4,9,1:17.12
-3,9,1:17.14
-5,-4,2:17.14
-4,-4,2:17.14
-6,-3,2:17.12
-5,-3,2:17.14
-4,-3,2:17.14
-3,-3,2:17.14
-8,-2,2:17.14
-7,-2,2:17.14
-2,-2,2:17.14
-9,-1,2:17.14
-1,-1,2:17.14
0,-1,2:17.14
-10,0,2:17.14
0,0,2:17.14
-10,1,2:17.14
1,1,2:17.14
-11,2,2:17.14
-10,2,2:17.14
1,2,2:17.12
-11,3,2:17.14
1,3,2:17.12
-10,4,2:17.14
-1,4,2:17.14
0,4,2:17.14
-11,5,2:17.14
-1,5,2:17.14
-10,6,2:17.14
-9,6,2:17.14
-1,6,2:17.14
-9,7,2:17.14
-2,7,2:17.14
-1,7,2:17.14
-8,8,2:17.14
-4,8,2:17.14
-3,8,2:17.14
-2,8,2:17.12
-7,9,2:17.14
-6,9,2:17.14
-5,9,2:17.12
-4,9,2:17.14
-5,-4,3:17.14
-4,-4,3:17.14
-6,-3,3:17.12
-5,-3,3:17.14
-4,-3,3:17.12
-8,-2,3:17.14
-7,-2,3:17.14
-6,-2,3:17.14
-3,-2,3:17.14
-9,-1,3:17.14
-8,-1,3:17.14
-2,-1,3:17.14
-10,0,3:17.14
-9,0,3:17.14
-1,0,3:17.14
-10,1,3:17.14
0,1,3:17.14
-10,2,3:17.14
1,2,3:17.12
-11,3,3:17.14
0,3,3:17.12
-11,4,3:17.14
-1,4,3:17.14
-11,5,3:17.14
-1,5,3:17.14
-10,6,3:17.14
-9,6,3:17.14
-8,6,3:17.14
-2,6,3:17.14
-8,7,3:17.14
-3,7,3:17.14
-2,7,3:17.14
-7,8,3:17.14
-6,8,3:17.14
-4,8,3:17.14
-3,8,3:17.14
-6,9,3:17.14
-5,9,3:17.12
-4,9,3:17.14
-5,-4,4:17.12
-5,-3,4:17.14
-4,-3,4:17.12
-7,-2,4:17.14
-6,-2,4:17.14
-3,-2,4:17.14
-9,-1,4:17.14
-8,-1,4:17.14
-2,-1,4:17.14
-9,0,4:17.14
-1,0,4:17.14
-10,1,4:17.14
-9,1,4:17.14
-8,1,4:17.14
0,1,4:17.14
-10,2,4:17.12
-9,2,4:17.14
1,2,4:17.12
-10,3,4:17.14
-1,3,4:17.14
0,3,4:17.12
-11,4,4:17.14
-1,4,4:17.14
-10,5,4:17.12
-1,5,4:17.14
-9,6,4:17.14
-8,6,4:17.14
-2,6,4:17.14
-7,7,4:17.14
-3,7,4:17.14
-2,7,4:17.14
-6,8,4:17.14
-4,8,4:17.14
-3,8,4:17.14
-5,9,4:17.12
-4,9,4:17.14
-5,-3,5:17.12
-7,-2,5:17.12
-6,-2,5:17.14
-4,-2,5:17.14
-3,-2,5:17.14
-8,-1,5:17.14
-3,-1,5:17.14
-9,0,5:17.12
-2,0,5:17.14
-1,0,5:17.14
-8,1,5:17.14
-1,1,5:17.14
-10,2,5:17.12
-9,2,5:17.14
0,2,5:17.12
-10,3,5:17.12
-1,3,5:17.14
-11,4,5:17.14
-10,4,5:17.14
-1,4,5:17.14
-10,5,5:17.12
-9,5,5:17.12
-2,5,5:17.14
-8,6,5:17.14
-2,6,5:17.14
-7,7,5:17.14
-6,7,5:17.12
-5,7,5:17.6
-3,7,5:17.14
-5,8,5:17.12
-4,8,5:17.14
-4,9,5:17.14
-5,-3,6:17.12
-7,-2,6:17.12
-6,-2,6:17.14
-4,-2,6:17.14
-7,-1,6:17.14
-3,-1,6:17.14
-9,0,6:17.12
-8,0,6:17.14
-2,0,6:17.14
-8,1,6:17.14
-1,1,6:17.14
-10,2,6:17.12
-9,2,6:17.14
0,2,6:17.12
-10,3,6:17.12
-1,3,6:17.14
-9,4,6:17.14
-2,4,6:17.14
-10,5,6:17.14
-9,5,6:17.12
-8,5,6:17.14
-2,5,6:17.14
-7,6,6:17.14
-3,6,6:17.14
-7,7,6:17.14
-6,7,6:17.12
-5,7,6:17.2
-4,7,6:17.14
-5,8,6:17.14
-4,8,6:17.14
-7,-2,7:17.14
-6,-2,7:17.14
-5,-2,7:17.14
-4,-2,7:17.14
-7,-1,7:17.14
-4,-1,7:17.14
-3,-1,7:17.14
-9,0,7:17.12
-8,0,7:17.14
-3,0,7:17.14
-9,1,7:17.14
-8,1,7:17.14
-2,1,7:17.14
-9,2,7:17.14
-1,2,7:17.14
-10,3,7:17.12
-2,3,7:17.14
-9,4,7:17.14
-2,4,7:17.14
-8,5,7:17.14
-7,5,7:17.14
-3,5,7:17.14
-7,6,7:17.14
-4,6,7:17.14
-6,7,7:17.14
-5,7,7:17.14
-5,-2,8:17.14
-7,-1,8:17.14
-6,-1,8:17.14
-4,-1,8:17.14
-8,0,8:17.14
-3,0,8:17.12
-9,1,8:17.14
-8,1,8:17.14
-3,1,8:17.14
-2,1,8:17.14
-9,2,8:17.14
-1,2,8:17.14
-9,3,8:17.12
-2,3,8:17.14
-9,4,8:17.14
-3,4,8:17.12
-8,5,8:17.14
-7,5,8:17.14
-6,5,8:17.14
-4,5,8:17.14
-6,6,8:17.14
-4,6,8:17.14
-5,7,8:17.14
-7,-1,9:17.14
-6,-1,9:17.14
-5,-1,9:17.14
-8,0,9:17.14
-7,0,9:17.12
-4,0,9:17.14
-3,0,9:17.12
-9,1,9:17.14
-8,1,9:17.14
-3,1,9:17.12
-9,2,9:17.14
-2,2,9:17.14
-9,3,9:17.14
-8,3,9:17.14
-3,3,9:17.14
-8,4,9:17.14
-4,4,9:17.14
-3,4,9:17.12
-7,5,9:17.12
-6,5,9:17.14
-4,5,9:17.14
-6,6,9:17.12
-5,6,9:17.14
-9,-5,10:18.13
-6,-1,10:17.14
-5,-1,10:17.12
-7,0,10:17.12
-6,0,10:17.12
-4,0,10:17.14
-8,1,10:17.14
-3,1,10:17.12
-9,2,10:17.14
-8,2,10:17.14
-2,2,10:17.14
-9,3,10:17.14
-8,3,10:17.14
-3,3,10:17.14
-8,4,10:17.14
-7,4,10:17.14
-4,4,10:17.14
-3,4,10:17.14
-7,5,10:17.14
-6,5,10:17.12
-4,5,10:17.14
-3,5,10:17.12
-5,6,10:17.14
-4,6,10:17.14
-3,9,10:18.13
-9,-5,11:18.13
-8,-4,11:18.13
-7,-3,11:18.13
-7,0,11:17.12
-6,0,11:17.12
-5,0,11:17.14
-8,1,11:17.12
-7,1,11:17.12
-6,1,11:17.12
-5,1,11:17.14
-4,1,11:17.14
-9,2,11:17.14
-8,2,11:17.14
-7,2,11:17.12
-6,2,11:17.14
-5,2,11:17.14
-4,2,11:17.14
-3,2,11:17.12
-9,3,11:17.14
-8,3,11:17.14
-7,3,11:17.14
-6,3,11:17.14
-5,3,11:17.14
-4,3,11:17.14
-3,3,11:17.14
-8,4,11:17.14
-7,4,11:17.14
-6,4,11:17.14
-5,4,11:17.14
-4,4,11:17.14
-3,4,11:17.14
-7,5,11:17.14
-6,5,11:17.14
-5,5,11:17.12
-4,5,11:17.14
-3,5,11:17.12
-5,6,11:17.12
-4,6,11:17.12
-3,6,11:17.12
-4,7,11:17.12
-1,8,11:18.13
-4,9,11:18.13
-9,-6,12:18.13
-10,-5,12:18.13
-8,-5,12:17.12
-6,-5,12:18.13
-8,-4,12:17.12
-9,-3,12:18.13
-7,-1,12:17.12
-7,0,12:17.12
-7,1,12:17.12
-6,1,12:17.12
-8,2,12:17.12
-7,2,12:17.12
-6,2,12:17.12
-5,2,12:17.12
-4,2,12:17.12
-3,2,12:17.12
-7,3,12:17.14
-6,3,12:17.14
-5,3,12:17.12
-4,3,12:17.12
-3,3,12:17.2
-6,4,12:17.14
-5,4,12:17.14
-4,4,12:17.14
-3,4,12:17.14
-4,5,12:17.12
-4,6,12:17.12
-3,7,12:18.13
-5,8,12:18.13
-3,8,12:17.12
-1,8,12:18.13
0,8,12:18.13
-4,9,12:18.13
-3,9,12:17.12
-1,9,12:18.13
-4,10,12:18.13
-3,10,12:18.13
-10,-6,13:18.13
-9,-6,13:18.13
-7,-5,13:18.13
-8,-4,13:18.13
-8,-3,13:17.12
-8,-2,13:17.12
-6,2,13:17.12
-5,2,13:17.12
-4,2,13:17.12
-3,2,13:17.12
-6,3,13:17.12
-5,3,13:17.12
-4,3,13:17.12
-3,3,13:17.12
-5,4,13:17.12
-4,4,13:17.14
-3,4,13:17.2
-4,5,13:17.12
-3,5,13:17.12
-3,7,13:18.13
-3,8,13:18.13
-5,9,13:18.13
-4,11,13:18.13
-3,11,13:18.13
-2,11,13:18.13
-1,11,13:18.13
0,11,13:18.13
-8,12,13:18.13
-8,13,13:18.13
-3,-6,14:18.13
-9,-5,14:18.13
-2,-5,14:18.13
-9,-4,14:18.13
-3,1,14:17.12
-5,2,14:17.12
-4,2,14:17.12
-2,2,14:17.12
-5,3,14:17.12
-4,3,14:17.12
-3,3,14:17.12
-5,4,14:17.12
-4,4,14:17.12
-3,4,14:17.2
-4,5,14:17.12
-3,5,14:17.12
-4,6,14:17.12
-4,9,14:18.13
-3,9,14:18.13
-3,10,14:18.13
-10,11,14:18.13
-6,11,14:18.13
-2,11,14:18.13
-9,12,14:18.13
0,12,14:18.13
1,12,14:18.5
2,12,14:18.13
-8,14,14:18.13
-7,14,14:18.5
-1,-7,15:18.13
-4,-4,15:18.13
-3,1,15:17.12
-2,1,15:17.12
-2,2,15:17.12
-4,3,15:17.12
-3,3,15:17.12
-4,4,15:17.12
-3,4,15:17.12
-5,5,15:17.12
-4,5,15:17.12
-3,5,15:17.12
-5,6,15:17.12
-4,6,15:17.12
-3,6,15:17.12
0,8,15:18.13
-7,9,15:18.13
0,9,15:18.13
1,9,15:18.13
2,10,15:18.13
-9,11,15:18.13
-8,11,15:17.12
0,11,15:17.12
1,11,15:18.13
-8,12,15:17.12
-7,12,15:18.13
-6,12,15:18.13
0,12,15:18.13
-7,13,15:18.13
-8,14,15:18.13
-2,-7,16:18.13
0,-6,16:18.13
-4,-5,16:18.13
-2,-5,16:17.12
0,-5,16:18.5
-3,-3,16:18.13
-2,-1,16:17.12
1,-1,16:18.13
-2,0,16:17.12
0,0,16:18.13
2,0,16:18.13
-2,1,16:18.13
0,1,16:18.13
1,1,16:17.12
-1,2,16:18.13
-4,3,16:17.12
-3,3,16:17.12
1,3,16:18.13
-4,4,16:17.12
-3,4,16:17.12
2,4,16:18.13
-4,5,16:17.12
-5,6,16:17.12
-4,6,16:17.12
-2,6,16:17.12
-1,6,16:17.12
-8,7,16:18.13
-6,7,16:17.12
-5,7,16:17.12
0,7,16:18.13
-9,8,16:18.13
-7,8,16:17.12
-6,8,16:17.12
-7,9,16:17.12
0,9,16:18.13
1,9,16:18.13
-7,10,16:17.12
-1,10,16:18.13
0,10,16:17.12
-2,11,16:18.13
-1,11,16:18.13
0,11,16:18.13
-8,12,16:18.13
1,12,16:18.13
1,13,16:18.13
-2,-5,17:18.13
-1,-5,17:18.13
-4,-4,17:18.13
-2,-4,17:18.13
-1,-4,17:17.12
-2,-3,17:18.13
-1,-3,17:17.12
-1,-2,17:17.12
0,-2,17:18.13
-2,-1,17:18.13
-2,0,17:18.13
-1,0,17:17.12
0,0,17:17.12
3,0,17:18.13
-2,1,17:18.13
-4,2,17:17.12
0,2,17:18.13
-4,3,17:17.12
-3,3,17:17.12
0,3,17:18.13
-4,4,17:17.12
-3,4,17:17.12
-8,6,17:18.13
0,6,17:18.13
1,6,17:18.13
-9,7,17:18.13
-1,7,17:17.12
0,7,17:18.13
-6,8,17:18.13
-2,8,17:18.13
0,8,17:17.12
1,8,17:18.13
2,8,17:18.13
-10,9,17:18.13
-9,9,17:18.13
-8,9,17:18.13
-7,9,17:18.13
-6,9,17:18.13
-1,9,17:18.13
0,9,17:17.12
2,9,17:18.13
3,9,17:18.13
-10,10,17:18.13
2,10,17:18.13
3,10,17:18.13
-8,11,17:18.13
-5,11,17:18.13
0,11,17:18.13
-7,12,17:18.13
0,12,17:18.13
-3,-7,18:18.13
-1,-7,18:18.13
0,-7,18:18.13
-4,-6,18:18.13
-3,-6,18:18.13
-1,-6,18:18.13
0,-6,18:18.13
1,-6,18:18.5
-2,-5,18:18.13
-1,-5,18:18.13
0,-5,18:18.13
0,-4,18:18.13
-2,-2,18:18.13
-5,2,18:17.12
-4,2,18:17.12
-3,2,18:17.12
-4,3,18:17.12
-3,3,18:17.12
-6,8,18:18.13
-1,8,18:18.13
0,8,18:18.13
1,8,18:18.13
-8,9,18:18.13
1,9,18:18.13
-1,-7,19:18.13
-1,-5,19:18.13
0,-5,19:18.13
-5,2,19:17.12
-4,2,19:17.12
-5,3,19:17.12
-4,3,19:17.12
-8,8,19:18.13
-8,9,19:18.13
-7,10,19:18.13
-3,-6,20:18.13
-2,-5,20:18.13
-3,-4,20:18.13
-5,1,20:17.12
-5,2,20:17.12
-4,2,20:17.12
-5,3,20:17.12
-4,3,20:17.12
-6,1,21:17.12
-5,1,21:17.12
-6,2,21:17.12
-5,2,21:17.12
-4,3,21:17.12
-3,4,21:17.12
0,8,21:18.13
0,9,21:18.13
1,9,21:18.5
-2,-6,22:18.5
-2,-5,22:18.5
-5,0,22:17.12
-4,0,22:17.12
-6,1,22:17.12
-5,1,22:17.12
-3,4,22:17.12
0,5,22:18.5
-1,9,22:18.13
0,9,22:18.13
1,9,22:18.13
-2,10,22:18.5
2,10,22:18.13
-4,-6,23:18.5
-4,-5,23:18.5
-1,-5,23:18.5
-3,-3,23:18.13
-2,-3,23:18.13
-6,-2,23:18.13
-1,-2,23:18.13
-6,-1,23:18.13
-3,-1,23:17.12
-2,-1,23:18.13
-4,0,23:17.12
-2,0,23:18.13
-1,0,23:18.13
-7,1,23:17.12
-1,1,23:18.13
-6,2,23:18.13
-2,2,23:18.13
-4,3,23:18.13
-5,4,23:18.13
-3,4,23:18.13
-2,4,23:18.13
-3,5,23:18.13
-2,5,23:17.12
-2,6,23:18.13
-1,6,23:18.13
1,6,23:18.13
-2,7,23:18.13
0,8,23:17.12
-2,9,23:18.5
0,9,23:17.12
0,10,23:18.5
1,10,23:18.5
2,10,23:18.5
0,11,23:18.5
-3,-6,24:18.5
-2,-6,24:18.5
-2,-5,24:18.5
-4,-4,24:18.5
-2,-4,24:18.5
-3,-3,24:18.13
-2,-3,24:18.13
0,-3,24:18.5
1,-3,24:18.5
-4,-2,24:18.13
-3,-2,24:18.13
-2,-2,24:17.12
1,-2,24:18.5
-8,-1,24:18.13
-2,-1,24:18.13
-1,-1,24:18.13
-10,1,24:18.13
-7,1,24:18.13
-8,2,24:18.13
-7,2,24:17.12
-5,2,24:18.13
-8,3,24:18.13
-6,3,24:18.13
1,4,24:18.13
2,5,24:18.5
-4,6,24:18.13
-1,6,24:17.12
0,6,24:18.13
1,6,24:18.13
2,6,24:18.5
-3,7,24:18.13
-1,7,24:17.12
-1,8,24:18.13
1,8,24:18.13
0,-4,25:18.5
-9,0,25:18.13
-8,0,25:18.13
-5,0,25:18.13
-10,1,25:18.13
-9,1,25:18.13
-4,1,25:18.13
-10,2,25:18.13
-9,2,25:18.13
-8,2,25:17.12
-7,2,25:18.13
-6,2,25:18.13
-4,2,25:18.13
-6,3,25:18.13
-4,3,25:18.13
-7,4,25:18.13
0,4,25:18.13
-7,5,25:18.13
-6,5,25:18.13
-1,6,25:18.13
-1,8,25:18.13
-2,-5,26:18.5
-2,-4,26:18.5
-3,-2,26:18.5
-9,0,26:18.5
-8,0,26:18.5
-6,0,26:18.13
-8,1,26:18.5
-8,3,26:18.5
-4,3,26:18.13
-6,1,27:18.5
-5,1,27:18.5
-9,2,27:18.5
-7,2,27:18.5
-6,2,27:18.5
