[META]
version=2.0
spawnOnBlockType=2
spawnSunlight=True
spawnDarkness=True
spawnWater=False
spawnLava=False
underFill=False
randomRotation=True
dig=True
tree=False
branch=False
needsFoundation=True
rarity=100
collisionPercentage=20
spawnElevationMin=0
spawnElevationMax=200
spawnInBiome=Custom
[DATA]
1,-5,-3:17.12
-1,-4,-3:17.12
-3,-2,-3:17.12
4,-1,-3:17.12
-2,0,-3:17.12
1,2,-3:17.12
1,-5,-2:17.2
-1,-4,-2:17.12
0,-4,-2:17.12
2,-4,-2:17.12
-2,-3,-2:17.12
3,-3,-2:17.12
-3,-2,-2:17.12
4,-2,-2:17.12
3,-1,-2:17.12
4,-1,-2:17.12
-2,0,-2:17.12
-1,0,-2:17.12
2,0,-2:17.12
2,1,-2:17.12
1,2,-2:17.2
1,-5,-1:17.2
-1,-4,-1:17.12
0,-4,-1:17.2
2,-4,-1:17.2
3,-4,-1:17.2
-2,-3,-1:17.12
3,-3,-1:17.12
-3,-2,-1:17.2
4,-2,-1:17.12
-3,-1,-1:17.12
3,-1,-1:17.12
4,-1,-1:17.12
-2,0,-1:17.2
-1,0,-1:17.2
2,0,-1:17.12
0,1,-1:17.12
2,1,-1:17.2
1,2,-1:17.2
1,-5,0:17.14
-1,-4,0:17.12
0,-4,0:17.14
2,-4,0:17.14
3,-4,0:17.14
-2,-3,0:17.14
3,-3,0:17.14
-3,-2,0:17.14
4,-2,0:17.14
-3,-1,0:17.14
3,-1,0:17.12
4,-1,0:17.12
-2,0,0:17.14
-1,0,0:17.14
2,0,0:17.14
0,1,0:17.14
2,1,0:17.14
1,2,0:17.14
1,-5,1:17.14
-1,-4,1:17.12
0,-4,1:17.14
2,-4,1:17.14
-2,-3,1:17.14
3,-3,1:17.14
-3,-2,1:17.14
4,-2,1:17.14
-2,-1,1:17.14
3,-1,1:17.12
-2,0,1:17.14
-1,0,1:17.14
2,0,1:17.14
0,1,1:17.14
2,1,1:17.14
1,2,1:17.14
1,-5,2:17.14
0,-4,2:17.12
1,-4,2:17.14
-1,-3,2:17.14
2,-3,2:17.14
3,-3,2:17.14
-2,-2,2:17.14
3,-2,2:17.14
4,-2,2:17.14
-2,-1,2:17.14
3,-1,2:17.12
-1,0,2:17.14
2,0,2:17.14
0,1,2:17.14
1,1,2:17.14
1,-4,3:17.14
-1,-3,3:17.14
0,-3,3:17.14
2,-3,3:17.12
-2,-2,3:17.12
3,-2,3:17.14
-1,-1,3:17.14
2,-1,3:17.14
-1,0,3:17.14
0,0,3:17.14
1,0,3:17.14
1,1,3:17.14
1,-4,4:17.14
-1,-3,4:17.14
0,-3,4:17.14
2,-3,4:17.12
-2,-2,4:17.12
3,-2,4:17.14
-1,-1,4:17.14
2,-1,4:17.14
0,0,4:17.14
1,0,4:17.14
1,1,4:17.14
0,-4,5:17.14
0,-3,5:17.14
1,-3,5:17.14
-2,-2,5:17.12
-1,-2,5:17.14
1,-2,5:17.14
2,-2,5:17.14
-1,-1,5:17.14
1,-1,5:17.12
0,0,5:17.14
1,0,5:17.14
0,-4,6:17.14
0,-3,6:17.14
1,-3,6:17.14
-3,-2,6:17.12
-2,-2,6:17.12
-1,-2,6:17.14
2,-2,6:17.14
-1,-1,6:17.14
1,-1,6:17.12
0,0,6:17.14
1,-4,7:17.12
0,-3,7:17.14
1,-3,7:17.12
-5,-2,7:17.12
-4,-2,7:17.12
-1,-2,7:17.14
0,-2,7:17.14
1,-2,7:17.14
0,-1,7:17.12
1,-1,7:17.12
2,-1,7:17.12
2,0,7:17.12
1,-9,8:18.5
1,-8,8:18.5
1,-6,8:17.12
1,-5,8:17.12
2,-5,8:17.12
-5,-4,8:17.12
1,-4,8:17.12
-5,-3,8:17.12
-1,-2,8:17.12
0,-2,8:17.12
-6,-1,8:17.12
0,-1,8:17.12
2,0,8:17.12
3,0,8:17.12
1,-8,9:18.5
-2,-7,9:18.13
-1,-7,9:18.5
0,-7,9:18.5
1,-7,9:17.12
2,-7,9:18.5
-4,-5,9:17.12
3,-5,9:17.12
-6,-4,9:17.12
-8,-2,9:18.13
0,-2,9:17.12
-9,-1,9:18.13
-1,-1,9:17.12
0,-1,9:17.12
-7,0,9:17.12
8,0,9:18.5
-9,1,9:18.5
-7,1,9:18.5
-6,1,9:18.5
3,1,9:17.12
6,1,9:18.5
8,1,9:18.5
4,2,9:17.12
7,2,9:18.5
4,3,9:17.12
-1,-9,10:18.5
4,-9,10:18.5
-1,-8,10:18.5
1,-8,10:17.12
2,-8,10:18.5
3,-8,10:18.5
-4,-7,10:18.13
1,-7,10:18.5
2,-7,10:18.5
3,-7,10:18.5
4,-7,10:18.5
6,-7,10:18.5
-8,-6,10:18.13
-3,-6,10:17.12
0,-6,10:18.5
2,-6,10:18.5
4,-6,10:17.12
-7,-5,10:18.13
-3,-5,10:18.13
-7,-4,10:17.12
-8,-2,10:18.13
-7,-2,10:18.13
-3,-2,10:18.13
-1,-2,10:18.5
-3,-1,10:18.13
-1,-1,10:17.12
-1,0,10:18.5
5,0,10:18.5
7,1,10:18.5
5,2,10:17.12
6,2,10:17.12
3,4,10:17.12
0,6,10:18.5
3,6,10:18.5
1,7,10:18.5
2,7,10:18.5
0,8,10:18.5
2,9,10:18.5
3,9,10:18.5
-2,-8,11:18.13
1,-8,11:18.5
3,-8,11:18.5
4,-8,11:18.5
5,-8,11:18.5
-4,-7,11:18.13
-3,-7,11:18.13
-2,-7,11:18.13
-1,-7,11:18.5
1,-7,11:18.5
2,-7,11:18.5
4,-7,11:17.12
6,-7,11:18.5
-5,-6,11:18.13
-4,-6,11:18.13
-3,-6,11:17.12
-2,-6,11:18.13
-1,-6,11:18.5
5,-6,11:18.5
-4,-5,11:18.13
-3,-5,11:18.13
-2,-5,11:18.13
-1,-5,11:18.5
3,-5,11:18.5
4,-5,11:18.5
5,-5,11:18.5
7,-5,11:18.5
-4,-4,11:18.13
-3,-4,11:18.13
-3,-2,11:18.13
-2,-2,11:18.5
-6,-1,11:18.5
-4,-1,11:18.13
-3,-1,11:18.5
-2,-1,11:18.5
7,-1,11:18.5
8,-1,11:18.5
-2,0,11:18.13
-1,0,11:17.12
0,0,11:18.13
5,0,11:18.5
7,0,11:18.5
-3,1,11:18.5
-1,1,11:18.5
5,1,11:18.5
7,1,11:17.12
8,1,11:18.5
9,1,11:18.5
-1,2,11:18.13
6,3,11:18.5
7,3,11:18.5
2,5,11:17.12
3,6,11:18.5
3,8,11:18.5
5,-9,12:18.5
0,-8,12:18.5
4,-8,12:18.5
-2,-7,12:18.13
-1,-7,12:18.5
3,-7,12:18.5
5,-7,12:18.5
-2,-6,12:18.13
3,-6,12:18.5
5,-6,12:18.5
-2,-5,12:18.13
2,-5,12:18.5
-4,-4,12:18.13
1,-3,12:18.5
2,-3,12:18.5
-3,-2,12:18.13
-1,-2,12:18.13
0,-2,12:18.13
2,-2,12:18.13
-4,-1,12:18.13
-3,-1,12:18.13
-2,-1,12:17.12
3,-1,12:18.5
-4,0,12:18.13
-2,0,12:18.13
-1,0,12:18.13
0,0,12:18.13
1,0,12:18.13
2,0,12:18.13
7,0,12:18.5
8,0,12:18.5
0,1,12:17.12
3,1,12:18.13
4,1,12:18.5
-2,2,12:18.5
-1,2,12:18.13
0,2,12:18.13
3,2,12:18.13
7,2,12:18.5
1,3,12:18.13
6,3,12:18.5
1,4,12:17.12
2,4,12:18.13
1,5,12:18.5
3,5,12:18.5
4,5,12:18.5
1,6,12:18.5
3,6,12:17.12
5,6,12:18.5
1,7,12:18.5
2,7,12:18.5
4,7,12:18.5
2,8,12:18.5
-2,-7,13:18.5
-4,-6,13:18.5
-2,-6,13:18.13
0,-6,13:18.5
3,-6,13:18.5
-4,-5,13:18.13
-3,-5,13:18.13
-2,-5,13:18.13
-1,-5,13:18.5
0,-5,13:18.5
-2,-4,13:18.5
-1,-4,13:18.5
-2,-3,13:18.5
-4,0,13:18.13
6,0,13:18.5
-4,2,13:18.5
-3,2,13:18.5
3,4,13:18.13
3,5,13:18.5
-2,-1,14:18.5
-1,-1,14:18.5
-3,0,14:18.13
2,5,14:18.5
