[META]
version=2.0
spawnOnBlockType=2
spawnSunlight=True
spawnDarkness=True
spawnWater=False
spawnLava=False
underFill=False
randomRotation=True
dig=True
tree=False
branch=False
needsFoundation=True
rarity=100
collisionPercentage=20
spawnElevationMin=0
spawnElevationMax=200
spawnInBiome=Custom
[DATA]
-2,2,0:17.12
-2,2,1:17.12
-2,2,2:17.12
-1,-3,3:18.4
-1,-2,3:18.4
0,-2,3:18.4
-1,-1,3:18.4
-2,1,3:17.12
-2,2,3:17.12
-2,3,3:17.12
-1,-3,4:18.4
-1,-2,4:18.4
0,-2,4:18.4
-3,-1,4:18.4
-1,-1,4:17.12
-1,0,4:17.12
-2,2,4:17.12
-5,4,4:18.4
-3,4,4:17.12
-5,5,4:18.4
-3,5,4:18.4
-2,5,4:18.4
-2,6,4:18.4
-1,6,4:18.4
0,-4,5:18.4
-2,-3,5:18.4
0,-3,5:18.4
-3,-2,5:18.4
-1,-2,5:17.12
0,-2,5:18.4
-3,-1,5:18.4
-2,-1,5:18.4
1,-1,5:18.4
0,0,5:18.4
-2,2,5:17.12
-5,4,5:18.4
-4,4,5:18.4
-3,4,5:17.12
0,4,5:18.4
-4,5,5:18.4
-3,5,5:18.4
-2,5,5:18.4
-1,5,5:18.4
-1,7,5:18.4
-1,-4,6:18.4
-3,-3,6:18.4
-1,-3,6:18.4
0,-3,6:18.4
-3,-2,6:18.4
-2,-2,6:18.4
-1,-2,6:17.12
0,-2,6:18.4
1,-2,6:18.4
-5,-1,6:18.4
-4,-1,6:18.4
-3,-1,6:18.4
-1,-1,6:18.4
1,-1,6:18.4
-2,0,6:18.4
0,0,6:18.4
-3,1,6:17.12
-5,2,6:18.4
-3,2,6:18.4
-1,2,6:17.12
-2,3,6:18.4
-5,4,6:18.4
-4,4,6:17.12
-3,4,6:18.4
-2,4,6:18.4
-3,5,6:18.4
-2,5,6:17.12
0,5,6:18.4
-4,6,6:18.4
-2,7,6:18.4
-1,-4,7:18.4
-2,-3,7:18.4
-4,-2,7:18.4
-6,-1,7:18.4
-5,-1,7:18.4
-4,-1,7:18.4
-2,-1,7:18.4
-1,-1,7:18.4
-5,0,7:18.4
-2,0,7:18.4
-4,1,7:17.12
-2,1,7:18.4
-3,2,7:18.4
-3,3,7:18.4
0,3,7:17.12
2,3,7:18.4
-2,4,7:18.4
2,4,7:18.4
-4,5,7:18.4
-2,5,7:18.4
-1,5,7:18.4
1,5,7:18.4
0,6,7:18.4
-2,-3,8:18.4
-5,-2,8:18.4
-2,-1,8:18.4
-5,0,8:18.4
-4,0,8:17.12
-6,1,8:18.4
-1,1,8:18.4
0,1,8:18.4
-2,2,8:18.4
-1,2,8:18.4
0,2,8:18.4
-4,3,8:18.4
-2,3,8:18.4
0,3,8:17.12
-5,4,8:18.4
-4,4,8:18.4
-3,4,8:18.4
-2,4,8:18.4
0,4,8:18.4
0,5,8:18.4
-3,-2,9:18.4
-2,-1,9:18.4
-4,0,9:18.4
-4,2,9:18.4
-3,2,9:18.4
1,2,9:18.4
-2,3,9:18.4
2,3,9:18.4
1,5,9:18.4
