[META]
version=2.0
spawnOnBlockType=2
spawnSunlight=True
spawnDarkness=True
spawnWater=False
spawnLava=False
underFill=False
randomRotation=True
dig=True
tree=False
branch=False
needsFoundation=True
rarity=100
collisionPercentage=20
spawnElevationMin=0
spawnElevationMax=200
spawnInBiome=Custom
[DATA]
1,0,0:17.12
1,1,0:17.12
-1,-3,1:18.12
1,-2,1:18.12
2,-2,1:18.12
2,-1,1:18.12
3,-1,1:18.12
-1,0,1:18.12
0,0,1:18.12
1,0,1:17.12
2,0,1:18.12
-1,1,1:18.12
1,1,1:18.12
-1,-3,2:18.12
0,-3,2:18.12
0,-2,2:18.12
2,-2,2:18.12
-2,-1,2:18.12
-1,-1,2:18.12
0,-1,2:17.12
0,0,2:18.12
1,0,2:18.12
2,0,2:17.12
1,1,2:18.12
2,-2,3:18.12
0,-1,3:18.12
-2,0,3:18.12
-1,0,3:18.12
2,0,3:18.12
-1,-2,4:18.12
0,-2,4:18.12
0,-1,4:18.12
-1,0,4:18.12
1,0,4:18.12
