[META]
version=2.0
spawnOnBlockType=2
spawnSunlight=True
spawnDarkness=True
spawnWater=False
spawnLava=False
underFill=False
randomRotation=True
dig=True
tree=False
branch=False
needsFoundation=True
rarity=100
collisionPercentage=20
spawnElevationMin=0
spawnElevationMax=200
spawnInBiome=Custom
[DATA]
2,-1,-3:17.14
2,-1,-2:17.14
3,-1,-2:17.14
2,-2,-1:17.14
2,-1,-1:17.14
3,-1,-1:17.14
2,-1,0:17.14
3,-1,0:17.14
1,-1,1:17.14
3,-1,1:17.14
1,-2,2:17.14
3,-1,2:17.14
1,-2,3:17.14
4,-1,3:17.14
0,-2,4:17.14
4,-1,4:17.14
7,3,4:18.14
0,-2,5:17.14
4,-1,5:17.14
6,2,5:18.14
6,3,5:18.14
7,3,5:18.14
8,3,5:18.14
10,3,5:18.14
9,4,5:18.14
-5,-6,6:18.6
0,-2,6:17.14
4,-1,6:17.14
8,1,6:18.14
7,2,6:18.14
1,3,6:18.14
6,3,6:18.14
7,3,6:18.14
9,3,6:18.14
2,4,6:18.14
9,4,6:18.14
8,6,6:18.14
-7,-9,7:18.14
-6,-9,7:18.14
-4,-9,7:18.14
-5,-8,7:18.14
-7,-7,7:18.14
-6,-7,7:18.14
0,-2,7:17.14
5,-2,7:17.14
3,-1,7:17.14
5,0,7:17.14
8,0,7:18.14
9,0,7:18.14
7,1,7:18.14
1,2,7:18.14
7,2,7:18.14
8,2,7:18.14
2,3,7:18.14
6,3,7:18.14
7,3,7:18.14
8,3,7:17.14
11,3,7:18.14
1,4,7:18.14
7,4,7:18.14
-1,5,7:18.14
1,5,7:18.14
8,5,7:18.14
1,6,7:18.14
3,6,7:18.14
8,6,7:18.14
-5,-10,8:18.14
-8,-9,8:18.14
-6,-9,8:18.14
-8,-7,8:18.14
-6,-7,8:18.14
-4,-7,8:18.14
-9,-6,8:18.14
-6,-6,8:18.14
-8,-5,8:18.14
-7,-5,8:18.14
-6,-5,8:18.14
-6,-4,8:18.14
-4,-2,8:18.14
-1,-2,8:17.14
0,-2,8:17.14
5,-2,8:17.14
-5,-1,8:18.14
-4,-1,8:18.14
3,-1,8:17.14
-6,0,8:18.14
-5,0,8:18.14
6,0,8:18.14
7,0,8:18.14
6,1,8:17.14
7,2,8:17.14
8,2,8:18.14
5,3,8:18.14
3,4,8:18.14
11,4,8:18.14
-2,5,8:18.14
1,5,8:18.14
3,5,8:18.14
6,5,8:18.14
8,5,8:18.14
-1,6,8:18.14
0,6,8:18.14
9,6,8:18.6
-5,-10,9:18.14
-2,-10,9:18.14
-6,-9,9:18.14
-3,-9,9:18.14
2,-8,9:18.14
3,-8,9:18.14
-8,-7,9:18.14
-6,-7,9:17.14
-5,-7,9:18.14
-6,-6,9:18.14
-5,-6,9:18.14
-6,-5,9:18.14
-5,-5,9:18.14
-4,-5,9:18.14
-6,-4,9:18.14
-5,-3,9:18.14
-2,-3,9:17.14
6,-3,9:17.14
-6,-2,9:18.14
-4,-2,9:18.14
0,-2,9:17.14
9,-2,9:18.14
10,-2,9:18.14
3,-1,9:17.14
11,0,9:18.14
-1,1,9:18.14
1,1,9:18.14
-1,2,9:18.14
3,2,9:18.14
6,2,9:18.14
-3,3,9:18.14
-2,3,9:18.14
8,3,9:18.14
10,3,9:18.14
-1,4,9:18.14
0,4,9:18.14
4,4,9:18.14
1,5,9:18.14
-1,6,9:18.14
1,6,9:18.14
3,6,9:18.14
-5,-11,10:18.14
-4,-11,10:18.14
-2,-11,10:18.14
-1,-11,10:18.14
-6,-10,10:18.14
-3,-10,10:18.14
5,-10,10:18.14
-3,-9,10:18.14
-2,-9,10:18.14
2,-9,10:18.14
5,-9,10:18.14
-4,-8,10:18.14
3,-8,10:18.14
4,-8,10:18.14
-7,-7,10:18.14
-6,-7,10:18.14
-4,-7,10:18.14
-3,-7,10:18.14
3,-7,10:18.14
4,-7,10:18.14
-9,-6,10:18.14
-7,-6,10:18.14
-5,-6,10:17.14
3,-6,10:18.14
-7,-5,10:18.14
-4,-5,10:17.14
-6,-4,10:18.14
-3,-4,10:17.14
1,-3,10:17.14
6,-3,10:17.14
-7,-2,10:18.14
0,-2,10:17.14
8,-2,10:18.14
9,-2,10:18.14
10,-2,10:18.14
-7,-1,10:18.14
-6,-1,10:18.14
5,-1,10:18.14
10,-1,10:18.14
-8,0,10:18.14
3,0,10:17.14
9,0,10:18.14
10,0,10:18.14
-5,1,10:18.14
-3,1,10:18.14
0,1,10:18.14
7,1,10:18.14
-2,2,10:18.14
0,2,10:18.14
6,2,10:18.14
8,2,10:18.14
-2,3,10:18.14
8,3,10:18.14
-2,4,10:18.14
-1,4,10:18.14
2,4,10:18.14
4,4,10:18.14
6,4,10:18.14
8,4,10:18.14
2,5,10:18.14
6,5,10:18.14
-1,6,10:18.14
0,6,10:18.14
0,7,10:18.14
-2,-11,11:18.14
-2,-10,11:18.14
-2,-9,11:18.14
-1,-9,11:18.14
0,-9,11:18.14
3,-9,11:18.14
6,-9,11:18.14
-8,-8,11:18.14
1,-8,11:18.14
3,-8,11:18.14
5,-8,11:18.14
-6,-7,11:18.14
-5,-7,11:18.14
-6,-6,11:18.14
-3,-6,11:18.14
6,-5,11:18.14
-6,-4,11:18.14
-5,-4,11:18.14
-4,-4,11:18.14
7,-4,11:18.14
-5,-3,11:18.14
-3,-3,11:18.14
1,-3,11:17.14
6,-3,11:17.14
7,-3,11:18.14
-6,-2,11:18.14
-5,-2,11:18.14
-2,-2,11:18.14
-1,-2,11:17.14
6,-2,11:18.14
-4,-1,11:18.14
-3,-1,11:18.14
-2,-1,11:18.14
-1,-1,11:18.14
5,-1,11:18.14
9,-1,11:18.14
11,-1,11:18.14
-8,0,11:18.14
-2,0,11:18.14
0,0,11:18.14
3,0,11:17.14
5,0,11:18.14
8,0,11:18.14
9,0,11:18.14
-5,1,11:18.14
-4,1,11:18.14
4,1,11:18.14
5,1,11:18.14
6,1,11:18.14
8,1,11:18.14
-3,2,11:18.14
-2,2,11:18.14
5,2,11:18.14
7,2,11:18.14
0,3,11:18.14
1,3,11:18.14
8,3,11:18.14
9,3,11:18.14
-2,4,11:18.14
-1,4,11:18.14
3,4,11:18.14
-1,5,11:18.14
3,5,11:18.14
5,5,11:18.14
5,6,11:18.14
7,6,11:18.14
-5,-11,12:18.14
3,-11,12:18.14
-4,-10,12:18.14
-3,-10,12:18.14
3,-10,12:18.14
-6,-9,12:18.14
-4,-9,12:18.14
-2,-9,12:18.14
0,-9,12:18.14
1,-9,12:18.14
2,-9,12:18.14
-4,-8,12:18.14
1,-8,12:18.14
5,-8,12:18.14
6,-8,12:18.14
-7,-7,12:18.14
0,-7,12:18.14
3,-7,12:18.14
6,-7,12:18.14
8,-7,12:18.14
-7,-6,12:18.14
-6,-6,12:18.14
-4,-6,12:18.14
3,-6,12:18.14
5,-6,12:18.14
6,-6,12:18.14
7,-6,12:18.14
9,-6,12:18.14
3,-5,12:18.14
-6,-4,12:18.14
1,-4,12:17.14
4,-4,12:18.14
5,-4,12:18.14
6,-4,12:18.14
7,-4,12:18.14
7,-3,12:17.14
-3,-2,12:18.14
-1,-2,12:17.14
8,-2,12:18.14
9,-2,12:18.14
-2,-1,12:18.14
6,-1,12:18.14
0,0,12:18.14
3,0,12:17.14
7,0,12:18.14
8,0,12:18.14
-7,1,12:18.14
-5,1,12:18.14
-2,1,12:18.14
4,1,12:18.14
5,1,12:18.14
6,1,12:18.14
-6,2,12:18.14
-5,2,12:18.14
-4,2,12:18.14
-3,2,12:18.14
-1,2,12:18.14
0,2,12:18.14
6,2,12:18.14
-2,3,12:18.14
0,3,12:18.14
3,3,12:18.14
-3,4,12:18.14
-2,4,12:18.14
4,4,12:18.14
9,4,12:18.14
1,5,12:18.14
4,6,12:18.14
6,6,12:18.14
7,6,12:18.14
3,-11,13:18.14
-5,-9,13:18.14
-2,-9,13:18.14
-6,-8,13:18.14
-5,-8,13:18.14
0,-8,13:18.14
-4,-7,13:18.14
-3,-7,13:18.14
0,-7,13:18.14
7,-7,13:18.14
-2,-6,13:18.14
-1,-6,13:18.14
0,-6,13:18.14
5,-6,13:18.14
6,-6,13:18.14
9,-6,13:18.14
-6,-5,13:18.14
-5,-5,13:18.14
4,-5,13:18.14
7,-5,13:18.14
1,-4,13:17.14
4,-4,13:18.14
5,-4,13:18.14
7,-4,13:17.14
9,-4,13:18.14
10,-4,13:18.14
-5,-3,13:18.14
6,-3,13:18.14
7,-3,13:17.14
10,-3,13:18.14
-6,-2,13:18.14
-1,-2,13:17.14
5,-2,13:18.14
7,-2,13:18.14
9,-2,13:18.14
-7,-1,13:18.14
-5,-1,13:18.14
-3,-1,13:18.14
6,-1,13:18.14
7,-1,13:18.14
0,0,13:18.14
4,0,13:17.14
7,0,13:18.14
-4,1,13:18.14
2,1,13:17.14
3,1,13:18.14
5,1,13:18.14
6,1,13:18.14
7,1,13:18.14
3,2,13:18.14
7,2,13:18.14
-5,3,13:18.14
-4,3,13:18.14
3,3,13:18.14
5,3,13:18.14
6,3,13:18.14
7,3,13:18.14
8,3,13:18.14
-1,4,13:18.14
3,4,13:18.14
5,4,13:18.14
6,4,13:18.14
7,4,13:18.14
8,4,13:18.14
5,5,13:18.14
7,5,13:18.14
9,5,13:18.6
4,6,13:18.14
5,6,13:18.14
6,7,13:18.14
-1,-10,14:18.14
-5,-9,14:18.14
-4,-9,14:18.14
5,-9,14:18.14
-1,-8,14:18.14
0,-8,14:18.14
3,-8,14:18.14
4,-8,14:18.14
-7,-7,14:18.14
-3,-7,14:18.14
-1,-7,14:18.14
1,-7,14:18.14
7,-7,14:18.14
-4,-6,14:18.14
2,-6,14:18.14
7,-6,14:18.14
-7,-5,14:18.14
-5,-5,14:18.14
-2,-5,14:18.14
0,-5,14:18.14
1,-5,14:17.14
6,-5,14:17.14
10,-5,14:18.14
-7,-4,14:18.14
2,-4,14:17.14
8,-4,14:18.14
9,-4,14:18.14
-7,-3,14:18.14
-2,-3,14:17.14
5,-3,14:18.14
7,-3,14:17.14
-5,-2,14:18.14
-2,-2,14:17.14
5,-2,14:18.14
8,-2,14:18.14
-6,-1,14:18.14
7,-1,14:18.14
-5,0,14:18.14
2,0,14:18.14
4,0,14:18.14
6,0,14:18.14
7,0,14:18.14
-5,1,14:18.14
-4,1,14:18.14
-3,1,14:18.14
2,1,14:17.14
3,1,14:18.14
5,1,14:17.14
6,1,14:18.14
0,2,14:18.14
2,2,14:18.14
6,2,14:18.14
0,3,14:18.14
4,3,14:18.14
8,3,14:18.14
4,4,14:18.14
5,4,14:18.14
3,5,14:18.6
4,5,14:18.6
6,5,14:18.6
8,6,14:18.6
6,7,14:18.6
7,7,14:18.6
-2,-10,15:18.14
0,-10,15:18.14
1,-10,15:18.14
-3,-9,15:18.14
-2,-9,15:18.14
1,-9,15:18.14
2,-9,15:18.14
4,-9,15:18.14
-5,-8,15:18.14
-3,-8,15:18.14
-1,-8,15:18.14
2,-8,15:18.14
3,-8,15:18.14
4,-8,15:18.14
-2,-7,15:18.14
-1,-7,15:18.14
4,-7,15:18.14
-2,-6,15:18.14
-1,-6,15:18.14
0,-6,15:18.14
3,-6,15:18.14
8,-6,15:18.14
-5,-5,15:18.14
-2,-5,15:18.14
-1,-5,15:18.14
0,-5,15:18.14
1,-5,15:17.14
6,-5,15:17.14
9,-5,15:18.14
-7,-4,15:18.14
-3,-4,15:17.14
2,-4,15:17.14
8,-4,15:18.14
9,-4,15:18.14
-5,-3,15:18.14
-2,-2,15:17.14
8,-2,15:17.14
11,-2,15:18.14
-5,-1,15:18.14
5,-1,15:18.6
6,-1,15:18.6
9,-1,15:18.14
10,-1,15:18.14
3,0,15:18.6
-5,1,15:18.14
0,1,15:18.14
2,1,15:17.14
-3,2,15:18.14
1,2,15:18.14
2,2,15:18.14
4,2,15:18.6
6,2,15:18.6
-2,3,15:18.14
-1,3,15:18.14
6,3,15:18.6
0,4,15:18.14
4,4,15:18.6
5,4,15:18.6
1,5,15:18.14
5,5,15:18.6
6,5,15:18.6
5,6,15:18.6
0,-10,16:18.14
3,-10,16:18.14
5,-10,16:18.14
-1,-9,16:18.14
0,-9,16:18.14
1,-9,16:18.14
3,-9,16:18.14
-4,-8,16:18.14
-1,-8,16:18.14
1,-8,16:18.14
3,-8,16:18.14
4,-8,16:18.14
-6,-7,16:18.14
-3,-7,16:18.14
-1,-7,16:17.14
0,-7,16:18.14
2,-7,16:18.14
-8,-6,16:18.14
-6,-6,16:18.14
-5,-6,16:18.14
-4,-6,16:18.14
-3,-6,16:18.14
-2,-6,16:18.14
-1,-6,16:18.14
0,-6,16:17.14
1,-6,16:18.14
5,-6,16:17.14
-6,-5,16:18.14
-5,-5,16:17.14
-4,-5,16:17.14
-3,-5,16:18.14
-2,-5,16:18.14
-1,-5,16:18.14
-8,-4,16:18.14
-4,-4,16:18.14
-3,-4,16:18.14
-2,-4,16:18.14
-1,-4,16:18.14
8,-4,16:18.14
-6,-3,16:18.14
-5,-3,16:18.14
3,-3,16:17.14
7,-3,16:18.14
10,-3,16:18.14
12,-3,16:18.14
-6,-2,16:18.14
-5,-2,16:18.14
-4,-2,16:18.14
8,-2,16:17.14
10,-2,16:18.14
-5,-1,16:18.14
-3,-1,16:17.14
9,-1,16:18.14
12,-1,16:18.14
-7,0,16:18.14
3,0,16:18.6
5,0,16:18.6
7,0,16:18.6
10,0,16:18.14
12,0,16:18.14
-8,1,16:18.14
-2,1,16:18.14
9,1,16:18.14
1,2,16:17.14
4,2,16:18.6
5,2,16:18.6
7,2,16:18.6
-7,3,16:18.14
-2,3,16:18.14
-1,3,16:18.14
0,3,16:18.14
5,3,16:18.6
7,3,16:18.6
-6,4,16:18.14
-4,4,16:18.14
0,4,16:18.14
6,4,16:18.6
6,5,16:18.6
2,-11,17:18.14
3,-11,17:18.14
3,-10,17:18.14
2,-9,17:18.14
4,-9,17:18.14
5,-9,17:18.14
0,-8,17:18.14
2,-8,17:18.14
3,-8,17:17.14
4,-8,17:18.14
6,-8,17:18.14
-6,-7,17:18.6
-4,-7,17:18.6
-3,-7,17:18.6
-1,-7,17:18.14
0,-7,17:18.14
2,-7,17:18.14
4,-7,17:17.14
6,-7,17:18.14
-5,-6,17:18.6
-5,-5,17:18.6
-3,-5,17:18.6
1,-5,17:18.14
-6,-4,17:18.6
-3,-4,17:18.6
-2,-4,17:18.6
-3,-3,17:18.6
3,-3,17:17.14
-4,-2,17:18.6
-7,-1,17:18.6
-6,-1,17:18.6
-5,-1,17:18.6
-3,-1,17:18.14
9,-1,17:17.14
-4,0,17:17.14
-2,0,17:18.14
-1,0,17:18.14
0,0,17:18.14
5,0,17:18.6
10,0,17:18.14
11,0,17:18.14
-7,1,17:18.6
-6,1,17:18.6
-5,1,17:17.14
-3,1,17:18.14
-2,1,17:18.14
6,1,17:18.6
8,1,17:18.14
-7,2,17:18.6
-5,2,17:18.6
-2,2,17:18.14
-1,2,17:18.14
1,2,17:18.14
5,2,17:18.6
-7,3,17:18.6
-5,3,17:18.6
-4,3,17:18.6
-3,3,17:18.14
-1,3,17:17.14
0,3,17:17.14
2,3,17:18.14
-3,4,17:18.14
-2,4,17:18.14
-2,5,17:18.14
-1,5,17:18.14
0,5,17:18.14
3,-11,18:18.6
3,-10,18:18.6
-1,-9,18:18.6
0,-9,18:18.6
1,-9,18:18.6
-2,-8,18:18.6
-1,-8,18:18.6
2,-8,18:18.6
3,-8,18:18.6
6,-8,18:18.6
-6,-7,18:18.6
-5,-7,18:18.6
-3,-7,18:18.6
-2,-7,18:18.6
-1,-7,18:18.14
1,-7,18:18.14
4,-6,18:18.14
-6,-5,18:18.6
-5,-5,18:18.6
0,-5,18:18.14
2,-5,18:18.14
4,-4,18:18.14
10,-4,18:18.14
3,-3,18:17.14
5,-3,18:18.14
6,-3,18:18.14
9,-3,18:18.14
6,-2,18:18.14
-6,-1,18:18.6
-3,-1,18:18.14
10,-1,18:17.14
11,-1,18:18.14
-5,0,18:18.6
-2,0,18:18.14
-1,0,18:18.14
12,0,18:18.14
-2,1,18:18.14
10,1,18:18.14
-5,2,18:18.6
-2,2,18:18.14
9,2,18:18.14
-7,3,18:18.6
-4,3,18:18.6
-3,3,18:18.14
1,3,18:18.14
-1,4,18:18.14
3,-10,19:18.6
4,-10,19:18.6
1,-8,19:18.6
3,-8,19:18.6
-2,-7,19:18.6
0,-7,19:18.14
4,-7,19:18.14
-5,-6,19:18.6
3,-6,19:18.14
-4,-5,19:18.6
1,-5,19:18.14
0,-4,19:18.14
1,-4,19:18.14
2,-4,19:17.14
4,-4,19:18.14
5,-4,19:18.14
4,-3,19:17.14
5,-3,19:18.14
9,-3,19:18.14
10,-3,19:18.14
11,-3,19:18.14
3,-2,19:18.14
11,-2,19:18.14
-5,-1,19:18.6
11,-1,19:18.14
12,-1,19:18.14
-4,0,19:18.6
-3,0,19:18.14
11,0,19:18.14
-4,1,19:18.6
-1,1,19:18.14
1,1,19:18.14
9,1,19:18.14
10,1,19:18.14
11,1,19:18.14
-1,2,19:18.14
0,2,19:18.14
-3,3,19:18.14
-1,3,19:18.14
-1,4,19:18.14
1,5,19:18.14
2,-9,20:18.6
4,-7,20:18.14
-1,-5,20:18.14
5,-5,20:18.14
6,-5,20:18.14
0,-4,20:18.14
2,-4,20:17.14
3,-4,20:18.14
4,-4,20:18.14
5,-4,20:18.14
2,-3,20:18.14
5,-3,20:17.14
7,-3,20:18.14
9,-3,20:18.14
1,-2,20:18.14
10,-2,20:18.14
12,-2,20:18.14
10,-1,20:18.14
6,0,20:18.14
-6,1,20:18.6
-4,1,20:18.6
12,1,20:18.14
-6,2,20:18.6
-1,3,20:18.14
-1,4,20:18.14
2,-7,21:18.14
0,-6,21:18.14
1,-6,21:18.14
2,-6,21:18.14
5,-6,21:18.14
6,-6,21:18.14
4,-5,21:18.14
5,-5,21:18.14
6,-5,21:18.14
7,-5,21:18.14
1,-4,21:18.14
2,-4,21:17.14
4,-4,21:18.14
5,-4,21:18.14
7,-4,21:18.14
-1,-3,21:18.14
1,-3,21:18.14
3,-3,21:18.14
4,-3,21:18.14
5,-3,21:17.14
1,-2,21:18.14
2,-2,21:18.14
5,-2,21:18.14
8,-2,21:18.14
2,-1,21:18.14
5,-1,21:18.14
6,-1,21:18.14
10,-1,21:18.14
11,-1,21:18.14
4,0,21:18.14
5,0,21:18.14
9,0,21:18.14
2,-7,22:18.6
2,-5,22:18.6
3,-5,22:18.6
4,-5,22:18.6
5,-5,22:18.6
7,-5,22:18.6
5,-4,22:18.6
7,-3,22:18.6
8,-3,22:18.6
2,-2,22:18.6
5,-2,22:18.6
5,-1,22:18.6
6,-1,22:18.6
5,0,22:18.6
4,-6,23:18.6
4,-5,23:18.6
4,-4,23:18.6
3,-1,23:18.6
5,-1,23:18.6
2,-5,24:18.6
3,-5,24:18.6
2,-4,24:18.6
