[META]
version=2.0
spawnOnBlockType=2
spawnSunlight=True
spawnDarkness=True
spawnWater=False
spawnLava=False
underFill=False
randomRotation=True
dig=True
tree=False
branch=False
needsFoundation=True
rarity=100
collisionPercentage=20
spawnElevationMin=0
spawnElevationMax=200
spawnInBiome=Custom
[DATA]
0,-2,-3:17.14
0,-1,-3:17.14
1,-1,-3:17.14
0,-2,-2:17.14
1,-2,-2:17.14
0,-1,-2:17.14
1,-1,-2:17.14
0,-2,-1:17.14
0,-1,-1:17.14
1,-1,-1:17.14
0,-2,0:17.14
1,-1,0:17.14
0,-2,1:17.14
1,-1,1:17.14
0,-3,2:17.14
-1,-1,2:17.14
2,-1,2:17.14
0,-3,3:17.14
-2,-1,3:17.14
2,-1,3:17.14
-1,-3,4:18.6
0,-3,4:17.14
-2,-2,4:18.6
-2,-1,4:17.14
2,-1,4:17.14
0,1,4:18.6
-1,2,4:18.6
0,2,4:18.6
1,2,4:18.6
0,3,4:18.6
-1,-5,5:18.6
0,-5,5:18.6
0,-4,5:18.6
1,-4,5:17.14
2,-4,5:18.6
-1,-3,5:17.14
1,-3,5:18.6
2,-3,5:18.6
-3,-2,5:18.6
-3,-1,5:18.6
-2,-1,5:18.6
-1,-1,5:18.6
0,-1,5:18.6
-5,0,5:18.6
-4,0,5:18.6
-3,0,5:17.14
2,0,5:17.14
-5,1,5:18.6
0,2,5:18.6
6,2,5:18.6
0,3,5:18.6
5,3,5:18.6
2,4,5:18.6
-2,-6,6:18.6
1,-5,6:18.6
4,-5,6:18.6
-4,-4,6:18.6
-3,-4,6:18.6
1,-4,6:17.14
3,-4,6:18.6
4,-4,6:18.6
-4,-3,6:18.6
-3,-3,6:18.6
-1,-3,6:17.14
1,-3,6:18.6
1,-2,6:18.6
-1,-1,6:18.6
0,-1,6:18.6
1,-1,6:18.6
-6,0,6:18.6
-4,0,6:18.6
-3,0,6:17.14
-1,0,6:18.6
2,0,6:17.14
0,1,6:18.6
1,1,6:17.14
-5,2,6:18.6
-4,2,6:18.6
-1,2,6:18.6
0,2,6:18.6
0,4,6:18.6
3,4,6:18.6
0,5,6:18.6
-2,-6,7:18.6
-3,-5,7:18.6
0,-5,7:18.6
-4,-4,7:18.6
-2,-4,7:18.6
-1,-4,7:18.6
1,-4,7:17.14
2,-4,7:18.6
3,-4,7:18.6
4,-4,7:18.6
5,-4,7:18.6
-1,-3,7:17.14
2,-3,7:18.6
5,-3,7:18.6
-3,-2,7:18.6
-2,-2,7:18.6
-1,-2,7:18.6
1,-2,7:18.6
2,-2,7:18.6
-5,-1,7:18.6
-3,-1,7:18.6
-1,-1,7:18.6
0,-1,7:18.6
1,-1,7:18.6
4,-1,7:18.6
-6,0,7:18.6
-4,0,7:18.6
-3,0,7:17.14
-2,0,7:18.6
-1,0,7:18.6
2,0,7:18.6
3,0,7:17.14
4,0,7:18.6
-5,1,7:18.6
-4,1,7:18.6
-3,1,7:18.6
-2,1,7:18.6
0,1,7:18.6
2,1,7:18.6
-5,2,7:18.6
-4,2,7:18.6
-3,2,7:18.6
0,2,7:17.14
1,2,7:18.6
2,2,7:18.6
4,2,7:18.6
5,2,7:18.6
7,2,7:18.6
-3,3,7:18.6
-2,3,7:18.6
-1,3,7:18.6
0,3,7:18.6
5,3,7:18.6
6,3,7:18.6
8,3,7:18.6
0,4,7:18.6
2,4,7:18.6
0,5,7:18.6
5,5,7:18.6
3,-7,8:18.6
-1,-6,8:18.6
-1,-5,8:18.6
0,-5,8:18.6
1,-5,8:18.6
2,-5,8:18.6
3,-5,8:18.6
5,-5,8:18.6
-3,-4,8:18.6
0,-4,8:18.6
1,-4,8:18.6
2,-4,8:17.14
4,-4,8:18.6
-3,-3,8:18.6
-2,-3,8:18.6
-1,-3,8:18.6
0,-3,8:18.6
0,-2,8:18.6
3,-2,8:18.6
-1,-1,8:18.6
5,-1,8:18.6
-2,0,8:18.6
-1,0,8:18.6
0,0,8:18.6
2,0,8:18.6
4,0,8:18.6
5,0,8:18.6
6,0,8:18.6
7,0,8:18.6
-2,1,8:18.6
4,1,8:17.14
-3,2,8:18.6
2,2,8:18.6
4,2,8:18.6
5,2,8:17.14
8,2,8:18.6
-4,3,8:18.6
-3,3,8:18.6
0,3,8:18.6
2,3,8:18.6
8,3,8:18.6
2,4,8:18.6
4,4,8:18.6
5,4,8:18.6
6,4,8:18.6
7,4,8:18.6
0,5,8:18.6
5,5,8:18.6
3,-6,9:18.6
0,-5,9:18.6
2,-5,9:18.6
-1,-4,9:18.6
1,-4,9:18.6
2,-4,9:18.6
4,-4,9:18.6
-3,-3,9:18.6
-1,-3,9:18.6
0,-3,9:18.6
2,-3,9:18.6
3,-3,9:18.6
-3,-2,9:18.6
-2,-2,9:18.6
2,-2,9:18.6
4,-2,9:18.6
-5,-1,9:18.6
-1,-1,9:18.6
5,-1,9:18.6
-1,0,9:18.6
0,0,9:18.6
2,0,9:18.6
3,0,9:18.6
-3,1,9:18.6
-1,1,9:18.6
5,1,9:18.6
7,1,9:18.6
-2,2,9:18.6
-1,2,9:18.6
0,2,9:18.6
2,2,9:18.6
3,2,9:18.6
6,2,9:18.6
8,2,9:18.6
0,3,9:18.6
2,3,9:18.6
3,3,9:18.6
7,3,9:18.6
-2,4,9:18.6
0,4,9:18.6
0,-6,10:18.6
1,-6,10:18.6
3,-6,10:18.6
-1,-4,10:18.6
0,-4,10:18.6
-1,-3,10:18.6
1,-3,10:18.6
3,-3,10:18.6
1,-2,10:18.6
2,-2,10:18.6
0,-1,10:18.6
4,-1,10:18.6
-4,0,10:18.6
1,0,10:18.6
3,0,10:18.6
4,0,10:18.6
5,0,10:18.6
7,0,10:18.6
-1,1,10:18.6
0,1,10:18.6
4,1,10:18.6
5,1,10:18.6
0,2,10:18.6
5,2,10:18.6
6,2,10:18.6
0,3,10:18.6
5,3,10:18.6
7,3,10:18.6
1,-5,11:18.6
3,-5,11:18.6
2,-4,11:18.6
3,-4,11:18.6
1,-3,11:18.6
3,-3,11:18.6
0,-1,11:18.6
2,-1,11:18.6
2,0,11:18.6
1,1,11:18.6
5,1,11:18.6
0,2,11:18.6
4,2,11:18.6
5,2,11:18.6
1,0,12:18.6
2,1,12:18.6
