[META]
version=2.0
spawnOnBlockType=2
spawnSunlight=True
spawnDarkness=True
spawnWater=False
spawnLava=False
underFill=False
randomRotation=True
dig=True
tree=False
branch=False
needsFoundation=True
rarity=100
collisionPercentage=20
spawnElevationMin=0
spawnElevationMax=200
spawnInBiome=Custom
[DATA]
5,-7,-3:17.13
5,-5,-3:17.13
5,-7,-2:17.13
4,-6,-2:17.13
6,-6,-2:17.13
5,-5,-2:17.13
5,-7,-1:17.13
4,-6,-1:17.13
6,-6,-1:17.13
4,-5,-1:17.13
5,-5,-1:17.13
5,-7,0:17.13
4,-6,0:17.13
5,-6,0:17.13
6,-6,0:17.13
4,-5,0:17.13
5,-5,0:17.13
4,-6,1:17.13
5,-6,1:17.13
4,-5,1:17.13
5,-5,1:17.13
5,-6,2:17.13
3,-5,2:17.13
4,-5,2:17.13
5,-5,2:17.13
6,-5,2:17.13
5,-4,2:17.13
3,-5,3:17.13
5,-5,3:17.13
6,-5,3:17.13
5,-4,3:17.13
6,-4,3:17.13
5,-10,4:18.12
7,-9,4:18.12
6,-8,4:18.12
11,-8,4:18.12
7,-6,4:17.13
2,-5,4:17.13
6,-4,4:17.13
13,1,4:18.4
7,-11,5:18.12
9,-10,5:18.12
4,-9,5:18.12
6,-9,5:18.12
7,-9,5:18.12
9,-9,5:18.12
10,-9,5:18.12
11,-9,5:18.12
5,-8,5:18.12
7,-8,5:18.12
9,-8,5:18.12
11,-8,5:18.12
12,-7,5:18.4
13,-7,5:18.4
8,-6,5:17.13
11,-6,5:18.12
2,-5,5:17.13
6,-4,5:17.13
7,-4,5:17.13
11,0,5:18.4
14,1,5:18.4
11,2,5:18.4
12,3,5:18.4
7,-12,6:18.12
1,-11,6:18.12
7,-11,6:18.12
2,-10,6:18.12
7,-10,6:18.12
12,-10,6:18.4
5,-9,6:18.12
8,-9,6:18.12
9,-9,6:18.12
14,-9,6:18.4
8,-8,6:18.12
12,-8,6:18.4
14,-8,6:18.4
9,-7,6:17.13
10,-7,6:17.13
6,-6,6:18.12
9,-6,6:18.12
10,-6,6:17.13
11,-6,6:18.12
1,-5,6:17.13
11,-5,6:18.12
14,-5,6:18.4
7,-4,6:17.13
12,-1,6:18.4
15,-1,6:18.4
10,1,6:18.12
12,1,6:18.4
13,1,6:18.4
15,1,6:18.4
10,2,6:18.12
11,2,6:18.4
11,3,6:18.4
2,-12,7:18.12
7,-12,7:18.12
4,-11,7:18.12
6,-11,7:18.12
7,-11,7:18.12
0,-10,7:18.12
2,-10,7:18.12
5,-10,7:18.12
8,-10,7:18.12
10,-10,7:18.12
11,-10,7:18.12
13,-10,7:18.4
3,-9,7:18.12
5,-9,7:18.12
7,-9,7:18.12
8,-9,7:18.12
9,-9,7:18.12
10,-9,7:18.12
13,-9,7:18.4
1,-8,7:18.12
11,-8,7:17.13
13,-8,7:18.4
4,-7,7:18.12
6,-7,7:18.12
12,-7,7:18.4
6,-6,7:18.12
10,-6,7:18.12
11,-6,7:18.12
1,-5,7:17.13
11,-5,7:17.13
12,-5,7:18.4
14,-5,7:18.4
7,-4,7:17.13
13,-4,7:18.4
7,-3,7:17.13
12,-2,7:18.4
13,-2,7:18.4
14,-2,7:18.4
11,-1,7:18.4
12,-1,7:18.4
14,-1,7:18.4
11,0,7:18.4
13,0,7:18.4
13,1,7:17.13
14,1,7:18.4
16,1,7:18.4
15,2,7:18.4
12,3,7:18.4
12,4,7:18.4
13,4,7:18.4
14,4,7:18.4
1,-13,8:18.12
2,-13,8:18.12
-1,-12,8:18.12
1,-12,8:18.12
-1,-11,8:18.12
2,-11,8:18.12
10,-11,8:18.12
12,-11,8:18.4
-2,-10,8:18.12
-1,-10,8:18.12
1,-10,8:18.12
2,-10,8:18.12
4,-10,8:18.12
11,-10,8:18.12
2,-9,8:18.12
6,-9,8:18.12
9,-9,8:18.12
3,-8,8:18.12
4,-8,8:18.12
9,-8,8:18.12
11,-7,8:18.12
12,-7,8:18.4
13,-7,8:18.4
14,-6,8:18.4
0,-5,8:17.13
10,-5,8:18.12
12,-5,8:18.4
13,-5,8:18.4
14,-5,8:18.4
2,-4,8:17.13
10,-4,8:18.12
12,-4,8:17.13
13,-4,8:18.4
8,-3,8:17.13
11,-3,8:18.12
12,-3,8:18.4
13,-3,8:18.4
15,-3,8:18.4
7,-2,8:18.12
8,-2,8:18.12
13,-2,8:18.4
12,-1,8:18.4
5,0,8:18.12
7,0,8:18.12
11,0,8:18.4
12,0,8:17.13
5,1,8:18.12
6,1,8:18.12
10,1,8:18.12
12,1,8:18.4
16,1,8:18.4
6,2,8:18.12
11,2,8:18.4
15,2,8:18.4
12,4,8:18.4
0,-12,9:18.12
-1,-11,9:18.12
8,-11,9:18.12
0,-10,9:18.12
2,-10,9:18.12
3,-10,9:18.12
5,-10,9:18.12
12,-10,9:18.4
3,-9,9:18.12
4,-9,9:18.12
5,-9,9:18.12
8,-9,9:18.12
1,-8,9:18.12
5,-8,9:18.12
6,-8,9:18.12
8,-8,9:18.12
12,-8,9:18.4
13,-8,9:18.4
-8,-7,9:18.4
-7,-7,9:18.4
2,-7,9:18.12
4,-7,9:18.12
6,-7,9:18.12
10,-7,9:18.12
11,-7,9:18.12
12,-7,9:18.4
-7,-6,9:18.4
11,-6,9:18.12
12,-6,9:18.4
-5,-5,9:17.13
-4,-5,9:17.13
-1,-5,9:17.13
0,-5,9:17.13
14,-5,9:18.4
2,-4,9:17.13
11,-4,9:18.4
12,-4,9:18.4
6,-2,9:18.12
8,-2,9:18.12
9,-2,9:17.13
10,-2,9:17.13
11,-2,9:18.4
12,-2,9:18.4
5,-1,9:18.12
7,-1,9:18.12
11,-1,9:17.13
4,0,9:18.12
9,0,9:18.12
4,1,9:18.12
6,1,9:18.12
8,1,9:18.12
13,1,9:18.4
14,1,9:18.4
13,3,9:18.4
2,-13,10:18.12
-2,-11,10:18.12
4,-11,10:18.12
7,-11,10:18.12
8,-11,10:18.12
-1,-10,10:18.12
1,-10,10:18.12
5,-10,10:18.12
6,-10,10:18.12
8,-10,10:18.12
-1,-9,10:18.12
3,-9,10:18.12
6,-9,10:18.12
0,-8,10:18.12
2,-8,10:18.12
6,-8,10:18.12
8,-8,10:18.12
11,-8,10:18.12
-7,-6,10:18.4
-5,-6,10:18.4
0,-6,10:17.13
5,-6,10:18.12
6,-6,10:18.12
11,-6,10:18.12
12,-6,10:18.4
14,-6,10:18.4
-6,-5,10:17.13
-3,-5,10:17.13
-2,-5,10:17.13
7,-5,10:18.12
9,-5,10:18.12
-9,-4,10:18.4
9,-4,10:18.12
12,-4,10:18.4
-4,-3,10:18.4
3,-3,10:17.13
9,-3,10:17.13
10,-3,10:18.12
11,-3,10:18.4
-6,-2,10:18.4
5,-2,10:18.12
6,-2,10:18.12
8,-2,10:18.12
9,-2,10:18.12
12,-2,10:18.4
6,-1,10:18.12
7,-1,10:18.12
8,-1,10:18.12
4,0,10:18.12
7,0,10:18.12
8,0,10:18.12
14,0,10:18.4
3,1,10:18.12
5,1,10:18.12
6,1,10:18.12
8,1,10:18.12
13,1,10:18.4
5,2,10:18.12
6,2,10:18.12
8,2,10:18.12
14,2,10:18.4
5,3,10:18.12
0,-12,11:18.12
2,-12,11:18.12
6,-12,11:18.12
4,-11,11:18.12
2,-10,11:18.12
3,-10,11:18.12
5,-10,11:18.12
7,-10,11:18.12
2,-9,11:18.12
4,-9,11:18.12
8,-9,11:18.12
-7,-8,11:18.4
3,-8,11:18.12
4,-8,11:18.12
6,-8,11:18.12
8,-8,11:18.12
6,-7,11:18.12
-7,-6,11:18.4
-6,-6,11:18.4
-3,-6,11:18.12
0,-6,11:17.13
7,-6,11:18.12
8,-6,11:18.12
-8,-5,11:17.13
-7,-5,11:17.13
-6,-5,11:18.4
-5,-5,11:18.4
-4,-5,11:18.4
-3,-5,11:18.12
0,-5,11:18.12
7,-5,11:18.12
8,-5,11:18.12
9,-5,11:18.12
10,-5,11:18.12
-9,-4,11:18.4
-7,-4,11:18.4
-5,-4,11:17.13
3,-4,11:18.12
4,-4,11:18.12
8,-4,11:17.13
11,-4,11:18.4
12,-4,11:18.4
13,-4,11:18.4
-7,-3,11:18.4
-5,-3,11:18.4
-4,-3,11:18.4
3,-3,11:17.13
7,-3,11:18.12
8,-3,11:18.12
9,-3,11:18.12
11,-3,11:18.4
13,-3,11:18.4
3,-2,11:18.12
-7,-1,11:18.4
9,-1,11:18.12
0,0,11:18.12
1,0,11:18.12
2,0,11:18.12
5,0,11:18.12
9,0,11:18.12
6,3,11:18.12
7,-12,12:18.12
1,-11,12:18.12
2,-10,12:18.12
0,-9,12:18.12
1,-9,12:18.12
5,-9,12:18.12
6,-9,12:18.12
-9,-8,12:18.4
0,-8,12:18.12
4,-8,12:18.12
7,-8,12:18.12
8,-8,12:18.12
-7,-7,12:18.4
-4,-7,12:18.4
0,-7,12:17.13
5,-7,12:18.12
8,-7,12:18.12
-9,-6,12:18.4
-8,-6,12:18.4
-7,-6,12:17.13
-5,-6,12:18.4
-2,-6,12:18.12
-1,-6,12:18.12
6,-6,12:18.12
7,-6,12:18.12
-5,-5,12:18.4
-4,-5,12:18.4
-2,-5,12:18.12
3,-5,12:18.12
8,-5,12:18.12
10,-5,12:18.12
11,-5,12:18.12
-4,-4,12:18.4
-3,-4,12:18.4
2,-4,12:18.12
4,-4,12:18.12
5,-4,12:18.12
6,-4,12:18.12
8,-4,12:17.13
10,-4,12:18.12
11,-4,12:18.4
-8,-3,12:18.4
-7,-3,12:18.4
-5,-3,12:17.13
-1,-3,12:18.4
2,-3,12:17.13
3,-3,12:17.13
4,-3,12:18.12
5,-3,12:18.12
7,-3,12:18.12
12,-3,12:18.4
-5,-2,12:18.4
1,-2,12:18.12
2,-2,12:17.13
3,-2,12:18.12
4,-2,12:18.12
6,-2,12:18.12
7,-2,12:18.12
8,-2,12:18.12
9,-2,12:18.12
4,-1,12:18.12
6,-1,12:18.12
7,-1,12:18.12
9,-1,12:18.12
-6,0,12:18.4
-1,0,12:18.4
1,0,12:18.12
6,0,12:18.12
8,0,12:18.12
6,2,12:18.12
5,-10,13:18.12
-2,-9,13:18.12
-1,-9,13:18.12
0,-9,13:18.12
4,-9,13:18.12
6,-9,13:18.12
-7,-8,13:18.4
-3,-8,13:18.12
-1,-8,13:18.12
0,-8,13:17.13
2,-8,13:18.12
-2,-7,13:18.12
0,-7,13:18.12
1,-7,13:18.12
6,-7,13:18.12
8,-7,13:18.12
-7,-6,13:18.4
-5,-6,13:18.4
-3,-6,13:18.12
-1,-6,13:17.13
5,-6,13:18.12
7,-6,13:18.12
8,-6,13:18.12
9,-6,13:18.12
10,-6,13:18.12
-7,-5,13:18.4
-6,-5,13:18.4
-5,-5,13:18.4
-2,-5,13:18.12
2,-5,13:18.12
5,-5,13:18.12
6,-5,13:18.12
8,-5,13:17.13
9,-5,13:18.12
10,-5,13:18.12
-5,-4,13:18.4
-4,-4,13:18.4
-2,-4,13:18.4
1,-4,13:17.13
3,-4,13:18.12
5,-4,13:18.12
8,-4,13:18.12
9,-4,13:18.12
10,-4,13:18.12
11,-4,13:18.4
-8,-3,13:18.4
-7,-3,13:18.4
-5,-3,13:17.13
-4,-3,13:18.4
-3,-3,13:18.4
-2,-3,13:18.4
0,-3,13:18.12
1,-3,13:18.12
4,-3,13:17.13
6,-3,13:18.12
8,-3,13:18.12
9,-3,13:17.13
10,-3,13:18.12
11,-3,13:18.4
-6,-2,13:18.4
-4,-2,13:18.4
-2,-2,13:18.4
1,-2,13:18.12
4,-2,13:18.12
5,-2,13:18.12
6,-2,13:18.12
7,-2,13:18.12
9,-2,13:18.12
1,-1,13:18.12
2,-1,13:17.13
3,-1,13:18.12
4,-1,13:18.12
9,-1,13:18.12
-6,0,13:18.4
-5,0,13:18.4
-2,0,13:18.4
-1,0,13:18.4
7,0,13:18.12
8,0,13:18.12
9,0,13:18.12
10,0,13:18.12
1,1,13:18.12
1,2,13:18.12
1,3,13:18.12
2,3,13:18.12
-1,-12,14:18.12
0,-12,14:18.12
0,-11,14:18.12
-2,-10,14:18.12
0,-10,14:18.12
3,-10,14:18.12
5,-10,14:18.12
-2,-9,14:18.12
-1,-9,14:18.12
0,-9,14:17.13
2,-9,14:18.12
3,-9,14:18.12
-7,-8,14:18.4
-3,-8,14:18.4
-1,-8,14:18.12
1,-8,14:18.12
-8,-7,14:18.4
-4,-7,14:18.4
-3,-7,14:18.4
-2,-7,14:18.12
0,-7,14:18.12
1,-7,14:18.12
7,-7,14:18.12
-9,-6,14:18.4
-7,-6,14:18.4
-5,-6,14:18.4
-4,-6,14:18.4
-3,-6,14:18.4
-2,-6,14:17.13
-1,-6,14:18.12
0,-6,14:18.12
5,-6,14:18.12
10,-6,14:18.12
-8,-5,14:18.4
-7,-5,14:18.4
-5,-5,14:18.4
-3,-5,14:18.4
0,-5,14:18.12
4,-5,14:18.12
5,-5,14:18.12
11,-5,14:18.12
-3,-4,14:18.4
-2,-4,14:18.4
-1,-4,14:18.4
0,-4,14:17.13
2,-4,14:18.12
3,-4,14:18.12
6,-4,14:18.12
9,-4,14:18.12
10,-4,14:18.12
1,-3,14:18.12
3,-3,14:18.12
4,-3,14:17.13
6,-3,14:18.12
7,-3,14:18.12
8,-3,14:18.12
9,-3,14:18.12
10,-3,14:18.12
12,-3,14:18.4
-5,-2,14:18.4
-2,-2,14:18.4
-1,-2,14:18.4
0,-2,14:18.12
1,-2,14:18.12
2,-2,14:18.12
6,-2,14:18.12
7,-2,14:18.12
8,-2,14:18.12
-7,-1,14:18.4
-5,-1,14:18.4
-4,-1,14:18.4
-2,-1,14:18.4
-1,-1,14:18.4
0,-1,14:18.12
3,-1,14:18.12
5,-1,14:18.12
-2,0,14:18.4
-1,0,14:18.4
1,0,14:17.13
2,0,14:18.12
5,0,14:18.12
0,1,14:18.12
-1,2,14:18.4
1,3,14:18.12
2,3,14:18.12
0,-12,15:18.4
-2,-11,15:18.4
0,-11,15:18.4
-3,-10,15:18.4
-2,-10,15:18.4
2,-10,15:18.12
-3,-9,15:18.4
-2,-9,15:18.4
-1,-9,15:18.4
0,-9,15:17.13
1,-9,15:18.4
2,-9,15:18.12
-7,-7,15:18.4
0,-7,15:18.4
8,-7,15:18.12
-4,-6,15:18.4
-3,-6,15:18.4
-1,-6,15:18.4
4,-6,15:18.12
8,-6,15:18.12
-7,-5,15:18.4
1,-5,15:18.12
3,-5,15:18.12
4,-5,15:18.12
6,-5,15:18.12
7,-5,15:18.12
9,-5,15:18.12
1,-4,15:18.12
3,-4,15:18.12
7,-4,15:18.12
8,-4,15:18.12
10,-4,15:18.4
-7,-3,15:18.4
0,-3,15:18.12
1,-3,15:18.12
2,-3,15:18.12
3,-3,15:18.12
4,-3,15:18.12
7,-3,15:18.12
11,-3,15:18.4
3,-2,15:18.12
5,-2,15:18.12
7,-2,15:18.12
-6,-1,15:18.4
-1,-1,15:18.4
0,-1,15:18.12
1,-1,15:18.12
4,-1,15:18.12
6,-1,15:18.12
-2,0,15:18.4
-1,0,15:18.4
1,0,15:18.12
3,0,15:18.12
4,0,15:18.12
2,1,15:18.12
4,1,15:18.12
1,2,15:18.12
1,-11,16:18.4
2,-11,16:18.12
2,-10,16:18.12
-2,-9,16:18.4
-1,-9,16:18.4
0,-9,16:18.4
-2,-8,16:18.4
-1,-7,16:18.4
-4,-6,16:18.4
-2,-6,16:18.4
-1,-6,16:18.4
0,-6,16:18.4
-2,-5,16:18.4
2,-5,16:18.12
0,-4,16:18.12
2,-4,16:18.12
-5,-3,16:18.4
0,-3,16:18.12
4,-3,16:18.12
6,-3,16:18.12
-5,-2,16:18.4
2,-2,16:18.12
-1,0,16:18.4
1,0,16:18.12
2,0,16:18.12
3,0,16:18.12
0,2,16:18.12
0,-11,17:18.4
0,-9,17:18.4
-3,-6,17:18.4
-2,-6,17:18.4
-1,-6,17:18.4
0,-4,17:18.4
1,-4,17:18.4
3,-4,17:18.4
4,-3,17:18.4
4,-2,17:18.4
2,-1,17:18.4
2,0,17:18.4
-1,-9,18:18.4
