[META]
version=2.0
spawnOnBlockType=2
spawnSunlight=True
spawnDarkness=True
spawnWater=False
spawnLava=False
underFill=False
randomRotation=True
dig=True
tree=False
branch=False
needsFoundation=True
rarity=100
collisionPercentage=20
spawnElevationMin=0
spawnElevationMax=200
spawnInBiome=Custom
[DATA]
-2,0,-3:17.13
-2,0,-2:17.13
-2,0,-1:17.13
-2,0,0:17.13
2,-4,1:18.4
-3,-3,1:18.4
-4,-2,1:18.4
-4,-1,1:18.4
-5,0,1:18.4
-1,0,1:17.13
-4,1,1:18.4
-3,1,1:17.13
-2,4,1:18.4
2,-5,2:18.4
-4,-4,2:18.4
2,-4,2:18.4
3,-4,2:18.4
4,-3,2:18.4
-5,-2,2:18.4
1,-2,2:18.4
3,-2,2:18.4
-5,0,2:18.4
-3,0,2:18.4
-1,0,2:17.13
-7,1,2:18.4
-3,1,2:17.13
-2,2,2:18.4
-3,3,2:18.4
-2,3,2:18.4
-1,4,2:18.4
0,4,2:18.4
-1,5,2:18.4
-2,6,2:18.4
0,-5,3:18.4
3,-5,3:18.4
-4,-4,3:18.4
-6,-3,3:18.4
-3,-3,3:18.4
0,-3,3:18.4
2,-3,3:18.4
5,-3,3:18.4
-6,-2,3:18.4
-5,-2,3:18.4
-5,-1,3:18.4
-4,-1,3:18.4
-2,-1,3:17.13
-1,-1,3:18.4
0,-1,3:17.13
-6,0,3:18.4
-1,0,3:18.4
-6,1,3:18.4
-4,1,3:17.13
-2,2,3:17.13
-1,3,3:18.4
-2,4,3:18.4
0,4,3:18.4
1,4,3:18.4
2,4,3:18.4
-2,5,3:18.4
-3,6,3:18.4
1,-6,4:18.4
-3,-5,4:18.4
-2,-5,4:18.4
2,-5,4:18.4
-5,-4,4:18.4
-3,-4,4:18.4
4,-4,4:18.4
-6,-3,4:18.4
-2,-3,4:18.4
0,-3,4:18.4
2,-3,4:17.13
3,-3,4:18.4
-5,-2,4:18.4
-3,-2,4:17.13
-2,-2,4:18.4
-1,-2,4:18.4
0,-2,4:18.4
1,-2,4:17.13
4,-2,4:18.4
-7,-1,4:18.4
-6,-1,4:18.4
-4,-1,4:18.4
-2,-1,4:18.4
0,-1,4:18.4
3,-1,4:18.4
-6,0,4:18.4
-3,0,4:18.4
1,0,4:18.4
2,0,4:18.4
3,0,4:18.4
-7,1,4:18.4
-6,1,4:18.4
-5,1,4:17.13
-4,1,4:18.4
-2,1,4:18.4
-1,1,4:18.4
-5,2,4:18.4
-2,2,4:18.4
-5,3,4:18.4
-2,3,4:17.13
2,3,4:18.4
-5,4,4:18.4
-2,4,4:18.4
-1,4,4:17.13
1,4,4:18.4
-1,5,4:18.4
0,5,4:18.4
-1,7,4:18.4
-3,-5,5:18.4
0,-5,5:18.4
-2,-4,5:18.4
-4,-3,5:18.4
-1,-3,5:18.4
0,-3,5:18.4
2,-3,5:18.4
2,-2,5:18.4
-5,-1,5:18.4
0,-1,5:18.4
-3,0,5:18.4
1,0,5:18.4
-6,1,5:18.4
-5,1,5:18.4
-4,1,5:18.4
-2,2,5:18.4
-1,2,5:18.4
-5,3,5:18.4
-4,3,5:18.4
-3,3,5:18.4
1,3,5:18.4
-4,4,5:18.4
-2,4,5:18.4
-1,4,5:18.4
0,4,5:18.4
-4,5,5:18.4
-1,6,5:18.4
1,6,5:18.4
1,-5,6:18.4
3,-5,6:18.4
-5,-3,6:18.4
0,-3,6:18.4
-4,-2,6:18.4
1,-2,6:18.4
-5,-1,6:18.4
-4,-1,6:18.4
2,-1,6:18.4
-3,0,6:18.4
-7,1,6:18.4
-5,1,6:18.4
-3,2,6:18.4
-1,3,6:18.4
-3,4,6:18.4
-1,5,6:18.4
1,6,6:18.4
-3,-2,7:18.4
2,-2,7:18.4
-4,0,7:18.4
-5,1,7:18.4
-4,1,7:18.4
-5,2,7:18.4
-2,5,7:18.4
-1,5,7:18.4
