[META]
version=2.0
spawnOnBlockType=2
spawnSunlight=True
spawnDarkness=True
spawnWater=False
spawnLava=False
underFill=False
randomRotation=True
dig=True
tree=False
branch=False
needsFoundation=True
rarity=100
collisionPercentage=20
spawnElevationMin=0
spawnElevationMax=200
spawnInBiome=Custom
[DATA]
1,2,-3:17.12
1,2,-2:17.12
0,3,-2:17.12
0,2,-1:17.12
1,2,-1:17.12
0,3,-1:17.12
1,3,-1:17.12
0,2,0:17.12
1,2,0:17.12
0,3,0:17.12
1,3,0:17.12
0,2,1:17.12
1,2,1:17.12
0,3,1:17.12
1,3,1:17.12
-1,1,2:17.12
0,2,2:17.12
1,2,2:17.12
2,4,2:17.12
-1,1,3:17.12
1,2,3:17.12
-1,3,3:17.12
2,4,3:17.12
-1,0,4:17.12
2,1,4:17.12
-1,3,4:17.12
2,4,4:17.12
-1,0,5:17.12
2,1,5:17.12
-1,4,5:17.12
2,4,5:17.12
-2,0,6:17.12
2,1,6:17.12
-1,4,6:17.12
3,4,6:17.12
-2,-1,7:17.12
3,0,7:17.12
-1,4,7:17.12
3,4,7:17.12
-3,-1,8:17.12
3,0,8:17.12
0,3,8:17.12
3,4,8:17.12
-1,5,8:17.12
-4,-2,9:17.12
-4,0,9:17.12
3,0,9:17.12
0,3,9:17.12
-1,5,9:17.12
4,5,9:17.12
-7,-6,10:18.5
-6,-5,10:18.5
-8,-4,10:18.5
-7,-4,10:18.5
-6,-4,10:17.12
-4,-4,10:18.5
-6,-3,10:18.5
-5,-3,10:17.12
-7,-2,10:18.5
-5,-2,10:18.5
3,-2,10:17.12
4,-1,10:17.12
-5,0,10:17.12
2,0,10:17.12
-5,1,10:18.5
1,3,10:17.12
-2,4,10:17.12
4,5,10:17.12
0,6,10:17.12
3,-7,11:18.5
5,-7,11:18.5
3,-6,11:18.5
4,-6,11:18.5
-7,-5,11:17.12
3,-5,11:18.5
4,-5,11:18.5
-4,-4,11:17.12
0,-4,11:18.5
1,-4,11:18.5
3,-4,11:17.12
4,-4,11:18.5
5,-4,11:18.5
1,-3,11:18.5
3,-3,11:17.12
4,-3,11:18.5
5,-3,11:18.5
6,-3,11:18.5
7,-3,11:18.5
2,-2,11:18.13
3,-2,11:18.13
5,-2,11:17.12
6,-2,11:18.5
1,-1,11:17.12
5,-1,11:18.13
8,-1,11:18.5
-8,0,11:18.5
-6,0,11:18.5
-5,0,11:18.5
5,0,11:18.13
6,0,11:18.5
-8,1,11:18.5
-7,1,11:17.12
-6,1,11:17.12
-5,1,11:18.5
5,1,11:18.5
-6,2,11:18.5
5,2,11:18.5
8,2,11:18.5
1,3,11:17.12
3,3,11:18.5
4,3,11:18.13
7,3,11:18.5
8,3,11:18.5
-2,4,11:17.12
0,4,11:18.5
-1,5,11:18.13
0,5,11:18.13
2,5,11:18.13
3,5,11:18.5
4,5,11:17.12
7,5,11:18.5
8,5,11:18.5
0,6,11:17.12
4,6,11:18.5
5,6,11:18.13
6,6,11:18.5
-2,7,11:18.5
-1,7,11:18.5
4,7,11:18.5
2,8,11:18.5
4,8,11:18.5
6,8,11:18.5
3,9,11:18.5
4,9,11:18.5
2,10,11:18.5
-4,-10,12:18.13
-3,-10,12:18.13
-1,-10,12:18.5
0,-9,12:18.5
-9,-8,12:18.5
-8,-8,12:18.5
-4,-8,12:18.5
-3,-8,12:18.5
-8,-7,12:18.5
-7,-7,12:18.5
-4,-7,12:18.5
1,-7,12:18.5
-7,-6,12:17.12
-4,-6,12:18.5
-3,-6,12:17.12
-1,-6,12:18.5
1,-6,12:18.5
2,-6,12:18.5
-6,-5,12:18.5
-5,-5,12:18.5
-4,-5,12:17.12
2,-5,12:18.5
0,-4,12:18.5
2,-4,12:18.5
-5,-3,12:18.5
-3,-3,12:18.5
-2,-3,12:18.5
0,-3,12:17.12
6,-3,12:17.12
0,-2,12:17.12
-9,-1,12:18.5
-8,-1,12:18.5
-5,-1,12:18.5
-8,0,12:18.5
-7,0,12:18.5
-10,1,12:18.5
-8,1,12:17.12
-7,1,12:18.5
-9,2,12:18.5
-8,2,12:18.5
-3,2,12:18.13
-7,3,12:18.5
1,3,12:17.12
-3,4,12:17.12
-5,5,12:18.5
-3,5,12:18.13
1,5,12:18.13
5,5,12:17.12
-3,6,12:18.13
0,6,12:17.12
1,7,12:18.5
0,8,12:18.5
1,8,12:18.5
-7,-8,13:18.5
-9,-7,13:18.5
-10,-6,13:18.5
-8,-6,13:17.12
-7,-6,13:18.5
-2,-6,13:18.5
-1,-6,13:18.5
0,-6,13:18.5
-1,-5,13:18.5
0,-5,13:18.5
8,-5,13:18.5
-9,-4,13:18.5
-4,-4,13:18.5
-3,-4,13:18.5
-2,-4,13:18.5
-1,-4,13:17.12
1,-4,13:18.5
5,-4,13:18.5
6,-4,13:17.12
-3,-3,13:18.5
-2,-3,13:18.5
-1,-3,13:18.5
6,-3,13:18.5
-3,-2,13:18.5
6,-2,13:18.5
-3,-1,13:18.5
0,-1,13:18.5
3,-1,13:18.5
4,-1,13:18.5
0,0,13:18.5
1,0,13:18.5
2,0,13:18.5
1,1,13:18.5
2,1,13:18.5
4,1,13:18.5
-4,2,13:18.5
-1,2,13:18.5
1,2,13:17.12
2,2,13:18.5
3,2,13:18.5
-4,3,13:18.5
0,3,13:18.5
2,3,13:18.5
6,3,13:18.5
-6,4,13:18.5
-4,4,13:17.12
-2,4,13:18.5
2,4,13:18.5
4,4,13:18.13
5,4,13:18.13
-2,5,13:18.5
3,5,13:18.13
5,5,13:17.12
7,5,13:18.5
0,7,13:17.12
4,7,13:18.5
5,7,13:18.5
6,7,13:18.5
-9,-8,14:18.5
-8,-8,14:18.5
-8,-7,14:18.5
-10,-6,14:18.5
-9,-6,14:18.5
-8,-6,14:17.12
-6,-6,14:18.5
-2,-6,14:18.5
-1,-6,14:18.5
-9,-5,14:18.5
-8,-5,14:18.5
-7,-5,14:18.5
-6,-5,14:18.5
1,-5,14:18.5
6,-5,14:18.5
-9,-4,14:18.5
-8,-4,14:18.5
-6,-4,14:18.5
-3,-4,14:18.5
-2,-4,14:18.13
-1,-4,14:17.12
1,-4,14:18.13
2,-4,14:18.13
3,-4,14:18.5
5,-4,14:18.5
6,-4,14:17.12
7,-4,14:18.5
8,-4,14:18.5
-6,-3,14:18.5
-4,-3,14:18.5
1,-3,14:18.13
2,-3,14:18.13
5,-3,14:18.5
-2,-2,14:18.13
0,-2,14:18.13
1,-2,14:18.13
4,-2,14:18.13
5,-2,14:18.13
6,-2,14:18.5
7,-2,14:18.5
-5,-1,14:18.5
-3,-1,14:18.13
-1,-1,14:18.13
5,-1,14:18.13
-5,0,14:18.5
-4,0,14:18.13
-3,0,14:18.13
0,0,14:18.13
2,0,14:18.13
3,0,14:18.13
5,0,14:18.13
8,0,14:18.5
-9,1,14:18.5
-8,1,14:18.5
-5,1,14:18.5
-4,1,14:18.13
-3,1,14:18.13
-2,1,14:18.13
0,1,14:18.13
2,1,14:18.13
3,1,14:18.13
4,1,14:18.13
-10,2,14:18.5
-9,2,14:18.5
-8,2,14:18.5
-4,2,14:18.13
-1,2,14:18.13
0,2,14:18.13
1,2,14:17.12
2,2,14:18.13
8,2,14:18.5
-8,3,14:18.5
-4,3,14:18.5
-2,3,14:18.13
-1,3,14:18.13
1,3,14:18.13
3,3,14:18.13
9,3,14:18.5
-6,4,14:18.5
-4,4,14:17.12
-3,4,14:18.13
-2,4,14:18.13
-1,4,14:18.13
1,4,14:18.13
-7,5,14:18.5
-6,5,14:18.5
-4,5,14:18.5
-2,5,14:18.13
-1,5,14:18.13
0,5,14:18.13
1,5,14:18.13
7,5,14:18.5
-5,6,14:18.5
-3,6,14:18.13
-2,6,14:18.13
-1,6,14:18.13
-2,7,14:18.5
-1,7,14:18.5
0,7,14:17.12
2,7,14:18.5
-1,8,14:18.5
0,8,14:18.5
-1,9,14:18.5
-3,-6,15:18.5
2,-6,15:18.5
-2,-5,15:18.5
-1,-5,15:18.5
-3,-4,15:18.5
1,-4,15:18.5
3,-4,15:18.5
-3,-3,15:18.5
0,-2,15:18.5
1,-2,15:18.5
-2,-1,15:18.5
-1,-1,15:18.5
-4,0,15:18.5
-2,0,15:18.5
-1,0,15:18.5
2,0,15:18.5
5,0,15:18.5
-2,1,15:18.5
3,1,15:18.5
-3,2,15:18.5
0,3,15:18.5
2,4,15:18.5
-2,5,15:18.5
0,5,15:18.5
