[META]
version=2.0
spawnOnBlockType=2
spawnSunlight=True
spawnDarkness=True
spawnWater=False
spawnLava=False
underFill=False
randomRotation=True
dig=True
tree=False
branch=False
needsFoundation=True
rarity=100
collisionPercentage=20
spawnElevationMin=0
spawnElevationMax=200
spawnInBiome=Custom
[DATA]
2,1,-3:17.12
1,0,-2:17.12
2,1,-2:17.12
1,0,-1:17.12
2,1,-1:17.12
1,0,0:17.12
2,1,0:17.12
1,0,1:17.12
2,1,1:17.12
0,0,2:17.12
3,1,2:17.12
1,2,2:17.12
0,0,3:17.12
3,1,3:17.12
1,2,3:17.12
0,0,4:17.12
3,0,4:17.12
3,2,4:17.12
0,3,4:17.12
1,-1,5:17.12
4,-1,5:17.12
-1,0,5:17.12
3,2,5:17.12
0,3,5:17.12
2,-6,6:18.5
3,-6,6:18.5
-1,-3,6:18.13
0,-2,6:18.13
1,-2,6:17.12
6,-2,6:18.5
-3,-1,6:17.12
0,-1,6:18.13
2,-1,6:18.13
4,-1,6:17.12
6,-1,6:18.5
-2,0,6:17.12
2,0,6:18.13
4,0,6:18.13
2,1,6:18.13
4,1,6:18.13
-2,2,6:18.13
-1,2,6:18.13
1,2,6:17.12
3,2,6:17.12
-3,3,6:18.13
-2,3,6:18.13
0,3,6:18.13
1,3,6:18.13
5,3,6:18.13
-3,4,6:18.13
-2,4,6:18.13
-1,4,6:17.12
0,4,6:18.13
2,4,6:18.13
4,4,6:18.13
0,5,6:18.5
-2,6,6:18.5
-1,6,6:18.5
2,-5,7:18.5
-2,-4,7:18.13
1,-4,7:18.13
1,-3,7:17.12
-4,-2,7:17.12
-3,-2,7:18.13
-2,-2,7:18.13
4,-2,7:17.12
-3,-1,7:18.13
-2,-1,7:18.13
-1,-1,7:18.13
0,-1,7:18.13
1,-1,7:18.13
2,-1,7:18.13
3,-1,7:18.13
-5,0,7:18.5
-3,0,7:18.13
0,0,7:18.13
1,0,7:18.13
2,0,7:18.13
3,0,7:18.13
4,0,7:18.13
5,0,7:18.13
6,0,7:18.13
-5,1,7:18.5
-4,1,7:18.5
1,1,7:17.12
4,1,7:18.13
0,2,7:18.13
4,2,7:17.12
5,2,7:18.13
-4,3,7:18.5
0,3,7:18.13
1,3,7:18.13
-2,4,7:17.12
1,4,7:18.13
4,5,7:18.5
-1,6,7:18.5
2,-5,8:18.5
3,-5,8:18.5
-2,-4,8:18.13
-1,-4,8:18.13
1,-4,8:18.13
3,-4,8:18.13
-3,-3,8:18.13
1,-3,8:18.13
3,-3,8:18.13
-2,-2,8:18.13
0,-2,8:18.13
1,-2,8:18.13
2,-2,8:18.13
5,-2,8:18.13
-4,-1,8:18.5
4,-1,8:18.13
6,-1,8:18.5
6,0,8:18.5
-1,1,8:18.13
2,1,8:18.13
4,1,8:18.13
1,2,8:18.13
3,2,8:18.13
5,2,8:18.13
-1,3,8:18.13
4,3,8:18.13
5,3,8:18.13
-1,4,8:18.13
1,4,8:18.13
-1,5,8:18.5
3,5,8:18.5
