[META]
version=2.0
spawnOnBlockType=2
spawnSunlight=True
spawnDarkness=True
spawnWater=False
spawnLava=False
underFill=False
randomRotation=True
dig=True
tree=False
branch=False
needsFoundation=True
rarity=100
collisionPercentage=20
spawnElevationMin=0
spawnElevationMax=200
spawnInBiome=Custom
[DATA]
0,-1,-3:17.14
-2,1,-3:17.14
1,1,-3:17.14
3,1,-3:17.14
-1,2,-3:17.14
0,-1,-2:17.14
3,-1,-2:17.14
-2,0,-2:17.14
-1,0,-2:17.14
0,0,-2:17.14
-2,1,-2:17.14
-1,1,-2:17.14
0,1,-2:17.14
1,1,-2:17.14
3,1,-2:17.14
-1,2,-2:17.14
2,2,-2:17.14
0,3,-2:17.14
-1,-1,-1:17.14
0,-1,-1:17.14
3,-1,-1:17.14
-2,0,-1:17.14
-1,0,-1:17.14
0,0,-1:17.14
1,0,-1:17.14
2,0,-1:17.14
-3,1,-1:17.14
-2,1,-1:17.14
-1,1,-1:17.14
0,1,-1:17.14
1,1,-1:17.14
2,1,-1:17.14
3,1,-1:17.14
-1,2,-1:17.14
1,2,-1:17.14
2,2,-1:17.14
-1,3,-1:17.14
0,3,-1:17.14
1,3,-1:17.14
0,4,-1:17.14
-1,-1,0:17.14
0,-1,0:17.14
3,-1,0:17.14
-2,0,0:17.14
-1,0,0:17.14
0,0,0:17.14
1,0,0:17.14
2,0,0:17.14
-3,1,0:17.14
-2,1,0:17.14
-1,1,0:17.14
0,1,0:17.14
1,1,0:17.14
2,1,0:17.14
3,1,0:17.14
-1,2,0:17.14
0,2,0:17.14
1,2,0:17.14
2,2,0:17.14
-1,3,0:17.14
0,3,0:17.14
1,3,0:17.14
0,4,0:17.14
0,-1,1:17.14
-1,0,1:17.14
0,0,1:17.14
1,0,1:17.14
-2,1,1:17.14
-1,1,1:17.14
0,1,1:17.14
1,1,1:17.14
2,1,1:17.14
-1,2,1:17.14
0,2,1:17.14
1,2,1:17.14
0,3,1:17.14
0,-1,2:17.14
-1,0,2:17.14
0,0,2:17.14
1,0,2:17.14
-1,1,2:17.14
0,1,2:17.14
1,1,2:17.14
2,1,2:17.14
-1,2,2:17.14
0,2,2:17.14
1,2,2:17.14
-1,0,3:17.14
0,0,3:17.14
1,0,3:17.14
-1,1,3:17.14
0,1,3:17.14
1,1,3:17.14
0,2,3:17.14
1,2,3:17.14
-1,0,4:17.14
0,0,4:17.14
-2,1,4:17.14
-1,1,4:17.14
0,1,4:17.14
1,1,4:17.14
0,2,4:17.14
0,0,5:17.14
-3,1,5:17.14
-2,1,5:17.14
-1,1,5:17.14
0,1,5:17.14
1,1,5:17.14
0,2,5:17.14
-4,0,6:17.14
0,0,6:17.14
1,0,6:17.14
-4,1,6:17.14
-1,1,6:17.14
0,1,6:17.14
1,1,6:17.14
0,2,6:17.14
1,2,6:17.14
0,3,6:17.14
-3,-1,7:17.14
1,-1,7:17.14
2,-1,7:17.14
1,0,7:17.14
-5,1,7:17.14
0,1,7:17.14
0,2,7:17.14
1,2,7:17.14
0,3,7:17.14
1,3,7:17.14
-4,4,7:18.4
4,-3,8:17.14
-3,-2,8:17.14
3,-2,8:17.14
2,-1,8:17.14
-6,1,8:17.14
-5,1,8:18.4
-4,1,8:18.4
0,1,8:17.14
-4,2,8:17.14
-4,3,8:18.4
-3,3,8:18.4
1,3,8:17.14
-5,4,8:18.4
-4,4,8:18.4
-5,-5,9:18.4
-4,-5,9:18.4
5,-5,9:17.14
-3,-4,9:18.4
4,-4,9:17.14
-3,-3,9:17.14
-1,0,9:17.14
1,0,9:17.14
-6,1,9:17.14
-4,1,9:18.4
-4,2,9:18.4
-3,2,9:18.4
-2,2,9:18.4
-4,3,9:17.14
-3,3,9:18.4
-2,3,9:18.4
-2,4,9:18.4
2,4,9:17.14
6,-6,10:17.14
-5,-5,10:18.4
-4,-4,10:17.14
-2,-4,10:18.12
3,-4,10:17.14
-2,-1,10:17.14
-7,0,10:17.14
1,0,10:17.14
-5,1,10:18.4
-1,1,10:17.14
-6,2,10:18.4
-4,2,10:18.4
-6,3,10:18.4
-5,3,10:18.4
-2,3,10:18.4
4,3,10:18.12
-6,4,10:17.14
-5,4,10:17.14
-4,4,10:18.4
-4,5,10:18.4
3,5,10:17.14
3,6,10:17.14
4,7,10:18.12
6,7,10:18.12
7,-8,11:18.12
8,-8,11:18.12
-4,-7,11:18.4
-3,-7,11:18.4
0,-7,11:18.12
6,-7,11:18.12
7,-7,11:17.14
-5,-6,11:18.4
4,-6,11:18.12
-6,-5,11:18.4
-5,-5,11:18.4
-4,-5,11:17.14
-2,-5,11:18.12
1,-5,11:18.12
2,-5,11:17.14
-4,-4,11:18.4
-2,-4,11:18.12
-1,-2,11:17.14
-2,-1,11:17.14
-7,0,11:17.14
1,0,11:17.14
-4,2,11:18.4
-1,2,11:17.14
-7,3,11:17.14
-3,3,11:18.4
0,3,11:18.4
1,3,11:18.4
3,3,11:18.12
6,3,11:18.12
7,3,11:18.12
-6,4,11:18.4
-5,4,11:17.14
1,4,11:18.4
4,4,11:17.14
-6,5,11:18.4
-5,5,11:18.4
-6,6,11:18.4
2,6,11:17.14
4,6,11:17.14
4,7,11:18.12
5,7,11:18.12
6,7,11:18.12
7,7,11:18.12
-2,8,11:18.4
0,8,11:18.4
1,8,11:18.4
5,9,11:18.4
6,-8,12:18.12
-3,-7,12:18.4
-1,-7,12:18.12
1,-7,12:18.12
2,-7,12:18.12
4,-7,12:18.12
7,-7,12:17.14
8,-7,12:18.12
1,-6,12:17.14
3,-6,12:18.12
8,-6,12:18.12
-6,-5,12:18.4
-5,-5,12:18.4
-4,-5,12:18.4
-2,-5,12:18.12
2,-5,12:18.12
3,-5,12:18.12
7,-5,12:18.12
1,-4,12:18.12
6,-4,12:18.4
-5,-3,12:18.4
5,-3,12:18.4
-9,-2,12:18.4
-7,-2,12:18.4
-6,-2,12:18.4
-1,-2,12:17.14
6,-2,12:18.4
-8,-1,12:17.14
-7,-1,12:18.4
-3,-1,12:17.14
2,0,12:17.14
6,0,12:18.4
7,0,12:18.4
-8,1,12:18.4
-7,1,12:18.4
0,1,12:18.4
-10,2,12:18.4
-9,2,12:18.4
-2,2,12:18.4
-1,2,12:17.14
3,2,12:18.12
6,2,12:18.12
7,2,12:18.12
-9,3,12:18.4
-8,3,12:17.14
-7,3,12:18.4
2,3,12:18.4
3,3,12:18.12
4,3,12:18.12
5,3,12:17.14
-7,4,12:18.4
-6,4,12:18.4
2,4,12:18.4
-9,5,12:18.4
-8,5,12:18.4
-6,5,12:17.14
-4,5,12:18.4
0,5,12:18.4
4,5,12:18.12
5,5,12:18.12
6,5,12:18.12
-6,6,12:18.4
-1,6,12:18.4
4,6,12:18.12
0,7,12:18.4
1,7,12:17.14
2,7,12:18.12
3,7,12:18.12
4,7,12:18.12
5,7,12:17.14
6,7,12:18.12
-2,8,12:18.4
0,8,12:17.14
1,8,12:18.4
2,8,12:18.4
5,8,12:18.4
-2,9,12:18.4
-1,9,12:18.4
0,9,12:18.4
5,9,12:18.4
0,10,12:18.4
6,-9,13:18.12
7,-9,13:18.12
0,-8,13:18.12
1,-8,13:18.12
2,-8,13:18.12
3,-8,13:18.12
5,-8,13:18.12
6,-8,13:18.12
8,-8,13:18.12
9,-8,13:18.12
1,-7,13:18.12
5,-7,13:18.12
7,-7,13:17.14
8,-7,13:18.12
9,-7,13:18.12
-1,-6,13:18.12
0,-6,13:18.12
1,-6,13:17.14
2,-6,13:18.12
3,-6,13:18.12
4,-6,13:18.12
5,-6,13:18.12
6,-6,13:18.12
9,-6,13:18.12
-5,-5,13:18.4
-3,-5,13:18.4
1,-5,13:18.12
3,-5,13:18.12
4,-5,13:18.12
5,-5,13:18.12
7,-5,13:18.12
0,-4,13:18.12
4,-4,13:18.12
5,-4,13:18.4
-5,-3,13:18.4
-2,-3,13:17.14
1,-3,13:18.12
5,-3,13:18.4
6,-3,13:18.4
-8,-2,13:18.4
-1,-2,13:18.12
0,-2,13:17.14
4,-2,13:18.4
5,-2,13:18.4
7,-2,13:18.4
8,-2,13:18.4
-9,-1,13:18.4
-8,-1,13:17.14
-7,-1,13:18.4
-3,-1,13:17.14
1,-1,13:18.12
3,-1,13:18.12
6,-1,13:18.4
7,-1,13:18.4
-8,0,13:18.4
-7,0,13:18.4
2,0,13:17.14
4,0,13:18.12
6,0,13:18.4
-8,1,13:18.4
-7,1,13:18.4
1,1,13:18.4
3,1,13:18.12
-10,2,13:18.4
-9,2,13:18.4
-7,2,13:18.4
-4,2,13:18.4
0,2,13:18.4
1,2,13:18.4
3,2,13:18.12
4,2,13:18.12
-10,3,13:18.4
-9,3,13:18.4
-8,3,13:17.14
-7,3,13:18.4
-6,3,13:18.4
-4,3,13:18.4
-3,3,13:18.4
-2,3,13:17.14
0,3,13:17.14
1,3,13:18.12
3,3,13:18.12
5,3,13:18.12
-8,4,13:18.4
-7,4,13:18.4
-2,4,13:18.4
0,4,13:18.4
1,4,13:18.12
2,4,13:18.12
5,4,13:18.12
-8,5,13:18.4
-6,5,13:17.14
-5,5,13:18.4
-4,5,13:18.4
-1,5,13:18.4
0,5,13:18.4
5,5,13:18.12
6,5,13:18.12
-6,6,13:18.4
-6,7,13:18.4
1,7,13:18.12
0,8,13:18.4
3,8,13:18.4
6,-9,14:18.12
7,-9,14:18.12
1,-8,14:18.12
1,-7,14:18.12
2,-7,14:18.12
3,-7,14:18.12
4,-7,14:18.12
5,-7,14:18.12
9,-7,14:18.12
3,-6,14:18.12
6,-6,14:18.12
1,-5,14:18.12
2,-5,14:18.12
3,-5,14:18.12
6,-5,14:18.12
7,-5,14:18.12
-5,-4,14:18.4
1,-4,14:18.12
2,-4,14:18.12
6,-4,14:18.4
-7,-3,14:18.4
0,-3,14:17.14
1,-3,14:18.12
2,-3,14:18.12
5,-3,14:18.4
6,-3,14:18.4
8,-3,14:18.4
-10,-2,14:18.4
-7,-2,14:18.4
-5,-2,14:18.4
-4,-2,14:17.14
-3,-2,14:18.4
3,-2,14:18.12
4,-2,14:18.12
-10,-1,14:18.4
-6,-1,14:18.4
-5,-1,14:18.4
2,-1,14:17.14
4,-1,14:18.12
6,-1,14:18.4
8,-1,14:18.4
-8,0,14:18.4
-4,0,14:18.4
-3,0,14:17.14
0,0,14:18.12
1,0,14:18.12
6,0,14:18.4
-9,1,14:18.4
-7,1,14:18.4
-2,1,14:18.12
2,1,14:18.12
3,1,14:17.14
4,1,14:18.12
-4,2,14:18.4
0,2,14:18.4
1,2,14:18.12
4,2,14:18.12
6,2,14:18.12
-9,3,14:18.4
-8,3,14:18.4
-7,3,14:18.4
-6,3,14:18.4
-4,3,14:18.4
-2,3,14:17.14
-1,3,14:18.12
0,3,14:17.14
3,3,14:18.12
6,3,14:18.12
-6,4,14:18.4
-5,4,14:18.4
-4,4,14:18.4
2,4,14:18.4
-4,6,14:18.4
2,6,14:18.12
6,6,14:18.12
-6,7,14:18.4
-1,7,14:18.4
4,7,14:18.12
-1,8,14:18.4
0,8,14:18.4
5,8,14:18.4
0,9,14:18.4
7,-8,15:18.12
8,-8,15:18.12
2,-7,15:18.12
6,-7,15:18.12
0,-6,15:18.12
2,-6,15:18.12
0,-5,15:18.12
2,-5,15:18.12
-4,-4,15:18.4
-2,-4,15:18.12
0,-4,15:18.12
1,-4,15:18.12
-2,-3,15:18.12
0,-3,15:17.14
1,-3,15:18.12
-8,-2,15:18.4
-4,-2,15:17.14
-2,-2,15:18.12
3,-2,15:18.12
6,-2,15:18.4
7,-2,15:18.4
-7,-1,15:18.4
-4,-1,15:18.4
0,-1,15:18.12
2,-1,15:17.14
3,-1,15:18.12
4,-1,15:18.12
5,-1,15:18.4
-3,0,15:18.4
-3,1,15:18.4
-2,1,15:18.12
1,1,15:18.12
3,1,15:17.14
-8,2,15:18.4
-4,2,15:18.4
1,2,15:18.12
2,2,15:18.12
3,2,15:18.12
5,2,15:18.12
-8,3,15:18.4
-5,3,15:18.4
-3,3,15:17.14
1,3,15:18.12
4,3,15:18.12
-3,4,15:18.4
0,4,15:18.12
1,4,15:17.14
2,4,15:18.12
3,4,15:18.12
-3,5,15:18.4
-2,5,15:18.4
1,5,15:18.12
0,6,15:18.4
2,-4,16:18.12
-6,-3,16:18.4
0,-3,16:18.12
-4,-2,16:18.4
0,-2,16:18.12
2,-2,16:18.12
2,-1,16:18.12
3,-1,16:18.12
4,-1,16:18.12
-3,0,16:18.4
1,0,16:18.12
3,0,16:18.12
-4,1,16:18.4
1,1,16:18.12
2,1,16:18.12
4,2,16:18.12
-4,3,16:18.4
-3,3,16:18.4
-1,3,16:18.12
0,3,16:18.12
0,4,16:18.12
1,4,16:18.12
-2,5,16:18.4
1,5,16:18.12
3,5,16:18.12
0,6,16:18.4
-4,-3,17:18.4
0,-3,17:18.12
1,-3,17:18.12
-3,-2,17:18.4
2,-1,17:18.12
3,-1,17:18.12
4,1,17:18.12
3,2,17:18.12
-2,3,17:18.12
1,4,17:18.12
