[META]
version=2.0
spawnOnBlockType=2
spawnSunlight=True
spawnDarkness=True
spawnWater=False
spawnLava=False
underFill=False
randomRotation=True
dig=True
tree=False
branch=False
needsFoundation=True
rarity=100
collisionPercentage=20
spawnElevationMin=0
spawnElevationMax=200
spawnInBiome=Custom
[DATA]
3,0,-3:17.14
1,-1,-2:17.14
3,0,-2:17.14
1,-1,-1:17.14
2,0,-1:17.14
3,0,-1:17.14
3,1,-1:17.14
1,-1,0:17.14
2,0,0:17.14
3,0,0:17.14
3,1,0:17.14
2,0,1:17.14
3,0,1:17.14
2,0,2:17.14
3,0,2:17.14
3,-1,3:17.14
2,0,3:17.14
3,-1,4:17.14
1,0,4:17.14
4,-4,5:18.12
6,-4,5:18.12
-1,-3,5:18.12
0,-3,5:18.12
-1,-2,5:18.12
1,-2,5:18.12
3,-2,5:17.14
-1,-1,5:17.14
0,0,5:17.14
3,-4,6:18.12
6,-4,6:18.12
7,-4,6:18.12
-2,-3,6:18.12
0,-3,6:18.12
1,-3,6:18.12
4,-3,6:17.14
5,-3,6:18.12
-3,-2,6:18.12
-1,-2,6:18.12
0,-2,6:17.14
1,-2,6:18.12
-3,-1,6:18.12
-2,-1,6:17.14
4,-1,6:17.14
5,-1,6:18.12
4,0,6:18.12
0,1,6:17.14
5,1,6:18.12
1,3,6:18.12
2,3,6:18.12
5,-6,7:18.4
0,-5,7:18.12
5,-5,7:18.12
6,-5,7:18.12
0,-4,7:18.12
1,-4,7:18.12
3,-4,7:18.12
5,-4,7:17.14
7,-4,7:18.12
-2,-3,7:18.12
-1,-3,7:18.12
0,-3,7:17.14
2,-3,7:18.12
4,-3,7:18.12
-3,-2,7:18.12
4,-2,7:18.12
5,-2,7:18.12
-5,-1,7:18.4
-3,-1,7:17.14
0,-1,7:18.12
1,-1,7:18.12
3,-1,7:18.12
4,-1,7:18.12
-5,0,7:18.4
0,0,7:18.12
2,0,7:18.12
4,0,7:17.14
-3,1,7:18.12
-1,1,7:18.12
0,1,7:18.12
-1,2,7:18.12
1,2,7:17.14
3,2,7:18.12
1,3,7:18.12
2,3,7:18.12
5,-6,8:18.4
6,-6,8:18.4
3,-4,8:18.12
5,-4,8:18.12
-2,-3,8:18.12
0,-3,8:18.12
4,-3,8:18.12
5,-3,8:18.12
-5,-2,8:18.4
-3,-2,8:18.12
-2,-2,8:18.12
-1,-2,8:18.12
4,-2,8:18.12
5,-2,8:18.12
-5,-1,8:18.4
-3,-1,8:17.14
-2,-1,8:18.12
-1,-1,8:18.12
1,-1,8:18.12
4,-1,8:18.12
-4,0,8:18.4
-1,0,8:18.12
4,0,8:17.14
6,0,8:18.12
-3,1,8:18.12
-1,1,8:18.12
1,1,8:18.12
2,1,8:18.12
3,1,8:18.12
4,1,8:18.12
-1,2,8:18.12
0,2,8:18.12
1,2,8:17.14
4,2,8:18.12
1,4,8:18.12
0,-3,9:18.4
1,-3,9:18.4
-1,-2,9:18.4
0,-2,9:18.4
1,-2,9:18.4
3,-2,9:18.4
4,-2,9:18.4
-1,-1,9:18.4
2,-1,9:18.4
3,-1,9:18.4
-4,0,9:18.4
1,0,9:18.4
1,1,9:18.4
2,1,9:18.4
4,1,9:18.4
6,1,9:18.4
-1,2,9:18.4
1,2,9:18.4
2,4,9:18.4
5,-1,10:18.4
-3,0,10:18.4
3,0,10:18.4
1,1,10:18.4
4,1,10:18.4
5,1,10:18.4
0,2,10:18.4
