[META]
version=2.0
spawnOnBlockType=2
spawnSunlight=True
spawnDarkness=True
spawnWater=False
spawnLava=False
underFill=False
randomRotation=True
dig=True
tree=False
branch=False
needsFoundation=True
rarity=100
collisionPercentage=20
spawnElevationMin=0
spawnElevationMax=200
spawnInBiome=Custom
[DATA]
-2,3,-3:17.13
-3,3,-2:17.13
-2,3,-2:17.13
-3,3,-1:17.13
-2,3,-1:17.13
-2,4,-1:17.13
-3,3,0:17.13
-2,3,0:17.13
-2,4,0:17.13
-2,3,1:17.13
-2,2,2:17.13
-2,2,3:17.13
-2,1,4:17.13
-2,-1,5:18.14
-3,0,5:18.14
-2,1,5:17.13
-3,-1,6:18.14
-2,-1,6:18.14
-2,0,6:18.14
-2,1,6:17.13
-1,1,6:18.14
-4,-2,7:18.14
-3,-2,7:18.14
-3,-1,7:18.14
-2,-1,7:18.14
-4,0,7:18.14
-3,0,7:17.13
-1,0,7:18.14
-5,1,7:18.14
-4,1,7:18.14
-2,1,7:18.14
-4,2,7:18.14
-3,2,7:18.14
-1,2,7:17.13
-3,-3,8:18.14
-3,-2,8:18.14
-5,-1,8:18.14
-3,-1,8:17.13
-2,-1,8:18.14
-1,-1,8:18.14
-3,0,8:18.14
-2,0,8:18.14
-2,1,8:18.14
-4,2,8:18.14
-2,2,8:18.14
-1,2,8:17.13
-3,3,8:18.14
-2,3,8:18.14
-1,3,8:18.14
0,3,8:18.14
-3,-3,9:18.14
-4,-1,9:18.14
-3,-1,9:18.14
-1,-1,9:18.14
0,1,9:18.14
-1,3,9:17.13
-3,4,9:18.14
-1,4,9:18.14
-2,1,10:18.14
-1,1,10:18.6
0,1,10:18.14
-4,2,10:18.14
-3,2,10:18.14
-2,2,10:18.14
0,2,10:18.14
1,2,10:18.14
-3,3,10:18.14
-2,3,10:18.14
-1,3,10:17.13
0,3,10:18.14
1,3,10:18.14
-3,4,10:18.14
-1,4,10:18.14
0,4,10:18.14
-2,5,10:18.14
-1,5,10:18.14
0,5,10:18.14
-2,6,10:18.14
-1,6,10:18.6
-4,1,11:18.6
0,1,11:18.6
-2,2,11:18.14
-1,2,11:18.6
-3,3,11:18.14
-2,3,11:18.14
-1,3,11:18.14
0,3,11:17.13
-3,4,11:18.6
-2,4,11:17.13
-1,4,11:18.14
0,4,11:18.14
1,4,11:18.14
-4,5,11:18.6
-1,5,11:18.14
-2,1,12:18.6
-2,2,12:18.14
-2,3,12:18.14
-1,3,12:18.14
0,3,12:18.14
-3,4,12:18.6
-2,4,12:18.14
-1,4,12:18.6
-2,6,12:18.14
-3,3,13:18.14
-2,3,13:18.6
-3,4,13:18.14
-2,4,13:18.14
-1,4,13:18.6
-3,5,13:18.14
