[META]
version=2.0
spawnOnBlockType=2
spawnSunlight=True
spawnDarkness=True
spawnWater=False
spawnLava=False
underFill=False
randomRotation=True
dig=True
tree=False
branch=False
needsFoundation=True
rarity=100
collisionPercentage=20
spawnElevationMin=0
spawnElevationMax=200
spawnInBiome=Custom
[DATA]
-2,2,0:17.0
-2,2,1:17.0
-2,2,2:17.0
-2,2,3:17.0
-2,2,4:17.0
-2,2,5:17.0
-2,2,6:17.0
-2,2,7:17.0
-2,2,8:17.0
-2,2,9:17.0
-2,2,10:17.0
-2,2,11:17.0
-2,2,12:17.0
-2,2,13:17.0
-2,2,14:17.0
-2,-1,15:18.6
-2,2,15:17.0
-3,-2,16:18.6
-2,2,16:17.0
-3,-3,17:18.6
-4,-2,17:18.6
-3,-2,17:18.6
-2,-2,17:18.6
-3,-1,17:17.4
-5,0,17:18.6
-3,0,17:18.6
-2,0,17:17.8
-3,1,17:18.6
-2,1,17:17.8
-2,2,17:17.0
-2,-3,18:18.6
-5,-2,18:18.6
-3,-2,18:18.6
-3,-1,18:18.6
-2,-1,18:18.6
-2,0,18:18.14
-3,1,18:18.6
-2,2,18:17.0
-1,2,18:18.14
-4,3,18:18.14
-3,3,18:18.14
-2,3,18:17.8
-3,4,18:18.14
-2,4,18:18.14
0,4,18:18.14
-1,5,18:18.6
-3,6,18:18.6
-2,6,18:18.6
-3,-2,19:18.6
-3,-1,19:18.6
-3,0,19:18.6
0,0,19:18.14
-2,1,19:18.14
-1,1,19:18.14
-3,2,19:18.14
-2,2,19:17.0
-3,3,19:18.14
-2,4,19:17.8
-1,4,19:18.14
-4,5,19:18.6
-2,5,19:18.6
-1,-1,20:18.14
-3,0,20:18.14
-1,0,20:18.14
-2,1,20:18.14
-1,1,20:17.8
0,1,20:18.14
1,1,20:18.14
-5,2,20:18.14
-2,2,20:17.0
-1,2,20:18.14
0,3,20:18.14
-4,4,20:18.14
-2,4,20:18.14
-1,4,20:18.14
-4,5,20:18.6
-3,5,20:18.6
0,5,20:18.6
-3,0,21:18.14
-2,0,21:18.14
-1,0,21:18.14
-3,2,21:17.4
-2,2,21:17.0
-1,2,21:18.14
-4,3,21:18.14
-2,3,21:18.14
-2,4,21:18.14
-3,-1,22:18.6
-1,-1,22:18.6
-4,0,22:18.6
-3,0,22:18.6
-2,0,22:18.6
0,0,22:18.6
-5,1,22:18.6
-4,1,22:18.6
-2,1,22:18.6
-1,1,22:18.6
0,1,22:18.6
-4,2,22:18.6
-2,2,22:17.0
-1,2,22:18.6
-1,3,22:17.8
-3,4,22:18.6
-1,-1,23:18.6
-3,0,23:18.6
-2,0,23:18.6
-1,0,23:18.6
-4,1,23:18.6
-2,1,23:17.8
-1,1,23:18.6
-3,2,23:18.6
-2,2,23:17.0
-3,3,23:18.6
-2,3,23:18.6
-2,-1,24:18.6
-1,-1,24:18.6
-2,1,24:18.6
-4,2,24:18.6
-2,2,24:17.0
-1,2,24:18.14
-2,3,24:18.6
-2,0,25:18.6
-3,1,25:18.6
0,1,25:18.14
-2,2,25:17.0
0,2,25:18.14
-2,3,25:18.14
-1,3,25:18.14
-3,4,25:18.14
-3,0,26:18.14
-2,0,26:18.14
-2,1,26:18.14
-4,2,26:18.14
-2,2,26:17.0
-1,2,26:18.14
0,2,26:18.14
-4,3,26:18.14
-3,3,26:18.14
-2,4,26:18.14
-1,0,27:18.6
-2,1,27:18.6
-3,2,27:18.6
-1,3,27:18.6
-3,1,28:18.6
-3,2,28:18.6
-2,2,28:18.6
-2,3,28:18.6
