[META]
version=2.0
spawnOnBlockType=2
spawnSunlight=True
spawnDarkness=True
spawnWater=False
spawnLava=False
underFill=False
randomRotation=True
dig=True
tree=False
branch=False
needsFoundation=True
rarity=100
collisionPercentage=20
spawnElevationMin=0
spawnElevationMax=200
spawnInBiome=Custom
[DATA]
0,0,-3:17.12
0,-1,-2:17.12
-2,0,-2:17.12
0,0,-2:17.12
0,1,-2:17.12
0,-1,-1:17.12
-2,0,-1:17.12
-1,0,-1:17.12
0,0,-1:17.12
0,1,-1:17.12
1,1,-1:17.12
0,2,-1:17.12
0,-1,0:17.12
-2,0,0:17.12
-1,0,0:17.12
0,0,0:17.12
0,1,0:17.12
1,1,0:17.12
0,2,0:17.12
-1,0,1:17.12
0,0,1:17.12
0,1,1:17.12
-3,3,1:18.12
-5,-3,2:18.12
-3,-3,2:18.12
-6,-2,2:18.12
-2,-1,2:17.12
-3,0,2:18.12
-1,0,2:17.12
0,0,2:17.12
-4,1,2:18.12
0,1,2:17.12
-3,3,2:18.12
-2,-6,3:18.12
-2,-5,3:18.12
-1,-5,3:18.12
-3,-4,3:18.12
0,-4,3:18.12
-5,-3,3:18.12
-4,-3,3:18.12
-3,-3,3:17.12
-1,-3,3:18.12
-5,-2,3:18.12
-3,-2,3:18.12
-2,-2,3:17.12
0,-2,3:18.12
-1,-1,3:18.12
0,-1,3:17.12
-2,0,3:18.12
-1,0,3:18.12
1,0,3:17.12
-1,1,3:17.12
1,1,3:18.12
-3,2,3:18.12
-1,2,3:17.12
-3,3,3:18.12
-3,4,3:18.12
-3,5,3:18.12
-1,6,3:18.12
-4,-5,4:18.12
-3,-5,4:18.12
-4,-3,4:18.12
0,-2,4:18.12
-1,-1,4:18.12
0,-1,4:17.12
1,-1,4:18.12
-1,0,4:18.12
1,0,4:18.12
0,1,4:18.12
1,1,4:17.12
2,1,4:18.12
-2,3,4:17.12
-1,3,4:18.12
0,3,4:18.12
0,5,4:18.12
-3,6,4:18.12
-2,6,4:18.12
-1,6,4:18.12
-3,-5,5:18.12
-1,-5,5:18.12
1,-3,5:18.12
-3,-2,5:18.12
2,-2,5:18.12
-5,-1,5:18.12
-2,-1,5:18.12
0,-1,5:17.12
2,-1,5:18.12
3,-1,5:18.12
-2,0,5:18.12
-1,0,5:18.12
1,1,5:17.12
4,1,5:18.12
-5,2,5:18.12
-4,2,5:18.12
-2,2,5:18.12
0,2,5:18.12
-3,3,5:18.12
-4,4,5:18.12
0,4,5:18.12
1,4,5:18.12
2,4,5:18.12
-3,5,5:18.12
-1,5,5:18.12
-2,6,5:18.12
4,-4,6:18.12
-4,-3,6:18.12
-3,-3,6:18.12
-2,-3,6:18.12
0,-3,6:18.12
1,-3,6:18.12
4,-3,6:18.12
-1,-2,6:18.12
0,-2,6:18.12
1,-2,6:17.12
-1,-1,6:17.12
0,-1,6:18.12
1,-1,6:18.12
2,-1,6:18.12
-1,0,6:18.12
0,0,6:18.12
1,0,6:18.12
2,0,6:18.12
-1,1,6:18.12
0,1,6:18.12
1,1,6:17.12
2,1,6:18.12
3,1,6:18.12
4,1,6:18.12
-4,2,6:18.12
-2,2,6:18.12
-1,2,6:18.12
0,2,6:18.12
4,2,6:18.12
0,5,6:18.12
2,-5,7:18.12
0,-4,7:18.12
-1,-3,7:18.12
1,-3,7:18.12
2,-3,7:18.12
5,-3,7:18.12
0,-2,7:18.12
1,-2,7:17.12
2,-2,7:18.12
5,-2,7:18.12
-3,-1,7:18.12
-1,-1,7:17.12
0,-1,7:18.12
1,-1,7:18.12
2,-1,7:18.12
3,-1,7:18.12
-4,0,7:18.12
-1,0,7:18.12
1,0,7:18.12
-2,1,7:18.12
2,1,7:17.12
3,1,7:18.12
-2,2,7:18.12
-1,2,7:18.12
0,2,7:17.12
-2,3,7:18.12
2,4,7:18.12
0,-4,8:18.12
-3,-3,8:18.12
-2,-3,8:18.12
0,-3,8:18.12
2,-3,8:18.12
3,-3,8:18.12
4,-3,8:18.12
5,-3,8:18.12
0,-2,8:18.12
1,-2,8:17.12
2,-2,8:18.12
5,-2,8:18.12
-4,-1,8:18.12
-3,-1,8:18.12
-1,-1,8:17.12
0,-1,8:18.12
1,-1,8:18.12
2,-1,8:18.12
3,-1,8:18.12
-4,0,8:18.12
0,0,8:18.12
2,0,8:18.12
-3,1,8:18.12
-1,1,8:18.12
0,1,8:18.12
1,1,8:18.12
2,1,8:17.12
0,2,8:17.12
2,2,8:18.12
3,2,8:18.12
-3,3,8:18.12
1,3,8:18.12
2,3,8:18.12
-1,5,8:18.12
-3,-3,9:18.4
-1,-3,9:18.4
-2,-2,9:17.12
-1,-2,9:18.4
0,-2,9:18.4
1,-2,9:18.4
2,-2,9:18.4
4,-2,9:18.4
-2,-1,9:18.4
1,-1,9:18.4
2,-1,9:18.4
-1,0,9:18.4
2,0,9:18.4
3,0,9:18.4
-2,1,9:18.4
2,1,9:17.12
4,1,9:18.4
5,1,9:18.4
-1,2,9:18.4
5,2,9:18.4
3,3,9:18.4
2,4,9:18.4
1,5,9:18.4
-2,-4,10:18.4
0,-4,10:18.4
2,-4,10:18.4
-3,-3,10:18.4
-1,-3,10:18.4
1,-3,10:18.4
3,-3,10:18.4
4,-3,10:18.4
-4,-2,10:18.4
-2,-2,10:17.12
1,-2,10:18.4
2,-2,10:18.4
3,-2,10:18.4
4,-2,10:18.4
0,-1,10:18.4
2,-1,10:18.4
-4,0,10:18.4
0,0,10:18.4
2,0,10:18.4
3,0,10:18.4
-1,1,10:18.4
0,1,10:18.4
1,1,10:18.4
5,1,10:18.4
-2,2,10:18.4
1,2,10:18.4
3,2,10:18.4
5,2,10:18.4
-4,3,10:18.4
2,3,10:18.4
-2,4,10:18.4
-1,4,10:18.4
4,4,10:18.4
0,5,10:18.4
1,5,10:18.4
-2,6,10:18.4
-2,-5,11:18.4
-2,-4,11:18.4
0,-4,11:18.4
-3,-3,11:18.4
1,-3,11:18.4
-3,-2,11:18.4
-1,-2,11:18.4
-2,-1,11:18.4
1,-1,11:18.4
3,-1,11:18.4
4,-1,11:18.4
5,-1,11:18.4
-2,0,11:18.4
3,0,11:18.4
5,0,11:18.4
-1,1,11:18.4
2,1,11:18.4
5,1,11:18.4
0,2,11:18.4
2,2,11:18.4
-3,3,11:18.4
1,3,11:18.4
-3,5,11:18.4
-2,5,11:18.4
-3,-5,12:18.4
-1,-5,12:18.4
-4,-4,12:18.4
-2,-3,12:18.4
0,-2,12:18.4
1,-2,12:18.4
3,-2,12:18.4
-4,-1,12:18.4
-2,-1,12:18.4
1,-1,12:18.4
-4,0,12:18.4
-2,0,12:18.4
2,0,12:18.4
-3,1,12:18.4
-1,1,12:18.4
2,1,12:18.4
5,1,12:18.4
-3,2,12:18.4
-2,2,12:18.4
-1,2,12:18.4
6,2,12:18.4
-3,3,12:18.4
0,3,12:18.4
2,3,12:18.4
3,4,12:18.4
4,4,12:18.4
-2,5,12:18.4
-1,5,12:18.4
-1,-5,13:18.4
-3,-4,13:18.4
-4,-3,13:18.4
-1,-3,13:18.4
-5,-2,13:18.4
0,-2,13:18.4
1,-2,13:18.4
1,-1,13:18.4
3,-1,13:18.4
1,0,13:18.4
-2,1,13:18.4
4,1,13:18.4
1,2,13:18.4
-2,3,13:18.4
1,3,13:18.4
-3,-4,14:18.4
0,-4,14:18.4
-3,-3,14:18.4
-2,-3,14:18.4
-2,-2,14:18.4
-2,-1,14:18.4
3,1,14:18.4
-2,-3,15:18.4
