[META]
version=2.0
spawnOnBlockType=2
spawnSunlight=True
spawnDarkness=True
spawnWater=False
spawnLava=False
underFill=False
randomRotation=True
dig=True
tree=False
branch=False
needsFoundation=True
rarity=100
collisionPercentage=20
spawnElevationMin=0
spawnElevationMax=200
spawnInBiome=Custom
[DATA]
0,0,0:17.0
0,0,1:17.0
0,0,2:17.0
0,0,3:17.0
1,0,3:18.14
2,0,3:18.14
2,1,3:18.14
-1,-2,4:18.14
0,-2,4:18.14
-1,-1,4:18.14
1,-1,4:17.4
2,-1,4:18.14
0,0,4:17.0
1,0,4:18.14
2,0,4:18.14
0,1,4:18.14
1,1,4:18.14
2,1,4:18.14
0,2,4:18.14
1,2,4:18.14
0,-2,5:18.14
1,-2,5:18.14
-2,-1,5:18.14
0,-1,5:18.14
-2,0,5:18.14
-1,0,5:17.4
0,0,5:17.0
2,0,5:18.14
-2,1,5:18.14
-1,1,5:18.14
2,1,5:18.14
-1,2,5:18.14
0,2,5:18.14
1,2,5:18.14
-1,0,6:18.6
0,0,6:17.0
2,0,6:18.14
0,2,6:18.6
0,-2,7:18.14
1,-2,7:18.14
0,-1,7:18.14
1,-1,7:18.14
0,0,7:17.0
1,0,7:18.14
-1,1,7:18.14
0,1,7:17.8
1,1,7:18.14
0,2,7:18.14
-1,-2,8:18.14
1,-2,8:18.6
-1,-1,8:17.4
1,-1,8:18.6
2,-1,8:18.6
-2,0,8:18.14
-1,0,8:18.14
0,0,8:17.0
1,0,8:17.4
2,0,8:18.6
-1,1,8:18.14
1,1,8:18.6
2,1,8:18.6
0,2,8:18.14
0,-2,9:18.14
-1,-1,9:18.14
0,-1,9:18.14
-1,0,9:18.14
0,0,9:17.0
1,0,9:18.14
2,0,9:18.14
0,1,9:18.14
0,-1,10:18.14
-1,0,10:18.14
0,0,10:18.14
1,0,10:18.14
0,1,10:18.14
0,0,11:18.14
0,0,12:18.6
