[META]
version=2.0
spawnOnBlockType=2
spawnSunlight=True
spawnDarkness=True
spawnWater=False
spawnLava=False
underFill=False
randomRotation=True
dig=True
tree=False
branch=False
needsFoundation=True
rarity=100
collisionPercentage=20
spawnElevationMin=0
spawnElevationMax=200
spawnInBiome=Custom
[DATA]
0,0,0:17.2
0,0,1:17.2
-1,-2,2:18.4
1,-1,2:18.12
0,0,2:17.2
1,0,2:18.12
0,1,2:18.12
1,1,2:18.12
2,1,2:18.12
-2,2,2:18.12
0,-3,3:18.4
-1,-2,3:18.12
-3,-1,3:18.12
-2,-1,3:18.12
1,-1,3:18.4
2,-1,3:18.4
3,-1,3:18.4
0,0,3:17.2
-3,1,3:18.12
0,1,3:18.4
1,1,3:18.4
2,1,3:18.4
0,-3,4:18.4
-2,-2,4:18.12
-1,-2,4:18.4
0,-2,4:18.4
1,-2,4:18.4
-2,-1,4:18.12
-1,-1,4:18.4
2,-1,4:18.4
-2,0,4:18.4
0,0,4:17.2
3,0,4:18.12
-2,1,4:18.12
1,1,4:18.4
-1,2,4:18.12
0,2,4:18.4
3,2,4:18.4
1,3,4:18.4
-1,-3,5:18.12
0,-3,5:18.4
-2,-2,5:18.12
2,-1,5:18.4
-2,0,5:18.4
-1,0,5:18.4
0,0,5:17.2
1,0,5:18.4
-1,1,5:18.12
1,1,5:18.4
0,2,5:18.4
0,3,5:18.4
-1,-3,6:18.4
0,-3,6:18.4
1,-3,6:18.4
2,-2,6:18.4
-2,-1,6:18.4
-1,-1,6:18.4
0,-1,6:18.4
1,-1,6:18.4
2,-1,6:18.4
-3,0,6:18.4
0,0,6:17.2
3,0,6:18.12
-2,1,6:18.12
0,1,6:18.4
1,1,6:18.4
0,2,6:18.12
-2,-2,7:18.12
-1,-2,7:18.4
2,-2,7:18.12
2,-1,7:18.4
-2,0,7:18.12
0,0,7:18.12
2,0,7:18.12
0,1,7:18.12
-1,2,7:18.4
2,2,7:18.12
-1,-2,8:18.4
0,-2,8:18.4
0,-1,8:18.12
1,-1,8:18.12
-2,0,8:18.4
2,0,8:18.12
-1,1,8:18.12
0,1,8:18.12
1,1,8:18.12
0,2,8:18.12
1,2,8:18.12
-1,-1,9:18.12
1,-1,9:18.12
-1,0,9:18.12
0,0,9:18.12
0,1,9:18.12
1,-1,10:18.4
0,0,10:18.12
0,1,10:18.4
0,0,11:18.4
