[META]
version=2.0
spawnOnBlockType=2
spawnSunlight=True
spawnDarkness=True
spawnWater=False
spawnLava=False
underFill=False
randomRotation=True
dig=True
tree=False
branch=False
needsFoundation=True
rarity=100
collisionPercentage=20
spawnElevationMin=0
spawnElevationMax=200
spawnInBiome=Custom
[DATA]
-2,2,0:17.13
-2,2,1:17.13
-1,-8,2:18.5
-1,-7,2:18.5
1,-7,2:18.5
-4,-6,2:18.5
1,-6,2:18.5
2,-6,2:18.5
-2,-5,2:18.5
-1,-5,2:17.13
0,-5,2:18.5
-1,-4,2:18.5
2,-4,2:18.5
-2,-3,2:18.5
-1,-3,2:18.5
0,-2,2:18.5
-2,2,2:17.13
-4,-8,3:18.5
-5,-7,3:18.5
-4,-6,3:18.5
-3,-6,3:18.5
-6,-5,3:18.5
-3,-5,3:17.13
-1,-5,3:18.5
-3,-4,3:18.13
-2,-4,3:17.13
-1,-4,3:18.13
0,-4,3:18.13
-9,-3,3:18.5
-8,-3,3:18.5
-5,-3,3:18.5
-4,-3,3:18.13
-3,-3,3:18.13
-2,-3,3:17.13
-1,-3,3:18.13
1,-3,3:18.13
-8,-2,3:18.5
-6,-2,3:18.13
-2,-2,3:18.13
1,-2,3:18.13
-10,-1,3:18.5
-9,-1,3:18.5
-6,-1,3:18.13
-4,-1,3:18.13
-3,-1,3:18.13
-2,-1,3:18.13
-1,-1,3:18.13
-10,0,3:18.5
-8,0,3:17.13
-6,0,3:18.13
-4,0,3:18.13
-10,1,3:18.5
-8,1,3:18.5
-7,1,3:17.13
-6,1,3:17.13
-4,1,3:18.13
-2,1,3:17.13
-10,2,3:18.5
-9,2,3:18.5
-8,2,3:18.5
-3,2,3:17.13
-2,2,3:17.13
-9,3,3:18.5
-7,3,3:18.5
-3,5,3:18.13
-2,5,3:18.13
-2,6,3:18.13
-2,7,3:18.5
0,7,3:18.5
-5,8,3:18.5
-4,8,3:18.5
-3,8,3:18.5
-2,8,3:17.13
0,8,3:18.5
-4,9,3:18.5
-1,9,3:18.5
0,9,3:18.5
1,9,3:18.5
0,10,3:18.5
-3,11,3:18.5
-2,-4,4:18.13
4,-4,4:18.13
1,-3,4:18.13
4,-3,4:18.13
5,-3,4:18.13
-4,-2,4:18.13
-3,-2,4:18.13
-2,-2,4:17.13
4,-2,4:17.13
5,-2,4:18.13
-6,-1,4:18.13
-4,-1,4:18.13
-3,-1,4:18.13
-2,-1,4:17.13
1,-1,4:18.13
3,-1,4:18.13
4,-1,4:18.13
-2,0,4:17.13
5,0,4:18.13
-6,1,4:18.13
-5,1,4:18.13
-3,1,4:18.13
-2,1,4:18.13
4,1,4:18.13
-7,2,4:18.5
-5,2,4:17.13
-4,2,4:17.13
-2,2,4:17.13
-7,3,4:18.5
-5,3,4:18.13
-4,3,4:18.13
-2,3,4:17.13
-7,4,4:18.5
-4,4,4:18.13
-2,4,4:18.13
-1,4,4:18.13
-2,5,4:18.13
0,5,4:18.13
-5,6,4:18.13
-4,6,4:18.13
-2,6,4:17.13
-1,6,4:18.13
-3,7,4:18.5
-2,7,4:17.13
0,7,4:18.5
1,7,4:18.5
0,8,4:18.5
-2,9,4:18.5
0,9,4:18.5
-3,10,4:18.5
-2,10,4:18.5
-1,10,4:18.5
0,-2,5:18.13
1,-2,5:18.13
2,-2,5:18.13
3,-2,5:17.13
4,-2,5:18.13
0,-1,5:18.13
1,0,5:18.13
-2,2,5:17.13
-4,3,5:18.13
-2,4,5:17.13
1,4,5:18.13
-4,5,5:18.13
-2,5,5:17.13
1,5,5:18.13
-5,6,5:18.13
-1,6,5:18.13
1,6,5:18.13
-2,7,5:18.5
2,-4,6:18.13
0,-2,6:18.13
1,-2,6:18.13
3,-2,6:18.13
0,-1,6:18.13
2,-1,6:17.13
3,-1,6:18.13
4,-1,6:18.13
-1,0,6:18.13
5,0,6:18.5
-1,1,6:17.13
0,1,6:18.13
2,1,6:18.13
4,1,6:18.13
-2,2,6:17.13
0,-3,7:18.13
2,-1,7:18.13
0,0,7:17.13
1,0,7:17.13
3,0,7:18.13
4,0,7:18.13
1,1,7:18.13
2,1,7:18.13
4,1,7:18.13
-2,2,7:17.13
1,2,7:18.13
-2,2,8:17.13
-7,3,8:18.5
-8,5,8:18.5
-7,5,8:18.5
-9,6,8:18.5
-8,6,8:18.5
-7,6,8:17.13
-5,6,8:18.13
-6,7,8:18.5
-8,8,8:18.5
-7,8,8:18.5
-8,9,8:18.5
-7,9,8:18.5
-5,2,9:18.13
-2,2,9:17.13
-7,3,9:18.5
-6,3,9:18.13
-3,3,9:17.13
-9,5,9:18.5
-8,5,9:18.5
-6,5,9:17.13
-6,6,9:18.13
-5,7,9:18.13
-4,7,9:18.13
-4,-7,10:18.5
-3,-7,10:18.5
1,-7,10:18.5
1,-6,10:18.5
2,-6,10:18.5
-8,-5,10:18.5
-7,-5,10:18.5
-6,-5,10:18.5
-5,-5,10:17.13
-3,-5,10:18.5
0,-5,10:18.5
1,-5,10:18.5
2,-5,10:18.5
-3,-4,10:18.13
-2,-4,10:18.13
0,-4,10:17.13
1,-4,10:18.13
2,-4,10:18.13
-7,-3,10:18.5
-5,-3,10:18.5
-4,-3,10:18.13
-2,-3,10:18.13
-1,-3,10:18.13
0,-3,10:17.13
2,-3,10:18.13
-6,-2,10:18.13
-4,-2,10:18.13
-1,-2,10:17.13
0,-2,10:18.13
1,-2,10:18.13
-1,-1,10:18.13
0,-1,10:18.13
-4,0,10:18.13
-3,0,10:18.13
-5,1,10:18.13
-4,1,10:18.13
-5,2,10:18.13
-4,2,10:18.13
-2,2,10:17.13
-6,3,10:18.13
-5,3,10:18.13
-4,3,10:17.13
-1,3,10:18.13
-7,4,10:18.5
-6,4,10:18.13
-5,4,10:17.13
-4,4,10:18.13
-1,4,10:18.13
-5,5,10:18.13
-4,5,10:18.13
-2,5,10:18.13
2,6,10:18.13
6,6,10:18.5
1,7,10:18.13
2,7,10:18.13
3,8,10:18.5
4,8,10:17.13
5,8,10:18.5
6,8,10:18.5
4,9,10:18.5
4,10,10:18.5
6,10,10:18.5
-2,-6,11:18.5
-6,-4,11:18.5
-4,-4,11:17.13
-1,-4,11:18.13
-6,-3,11:18.5
-4,-3,11:18.13
-3,-3,11:17.13
-6,-2,11:18.13
-4,-2,11:18.13
-3,-2,11:18.13
-2,-2,11:17.13
-1,-2,11:18.13
-4,0,11:18.13
-2,0,11:18.13
-2,1,11:17.13
-2,2,11:17.13
4,4,11:18.13
3,6,11:18.13
3,7,11:17.13
5,7,11:18.5
6,7,11:18.5
0,8,11:18.5
2,8,11:18.5
3,8,11:18.5
4,9,11:18.5
5,9,11:18.5
3,10,11:18.5
4,10,11:18.5
-2,-4,12:18.5
-4,-3,12:18.5
-2,-3,12:18.5
0,-3,12:18.5
-3,-2,12:18.13
1,-2,12:18.13
-5,-1,12:18.13
-4,-1,12:18.13
-3,-1,12:18.13
-2,-1,12:17.13
-3,0,12:18.13
-2,0,12:17.13
0,0,12:18.13
1,0,12:18.13
-2,1,12:18.13
-4,2,12:18.13
-2,2,12:17.13
0,2,12:18.13
-2,3,12:18.13
-1,3,12:18.13
4,4,12:18.5
4,6,12:18.5
0,7,12:18.13
3,7,12:17.13
4,7,12:18.5
6,7,12:18.5
0,8,12:18.5
1,8,12:18.5
2,8,12:18.5
-2,0,13:18.5
1,1,13:18.5
-5,2,13:18.5
-2,2,13:17.13
-1,2,13:18.5
1,2,13:18.5
-4,3,13:18.5
-2,3,13:18.5
-1,3,13:17.13
3,4,13:18.13
-1,5,13:18.13
0,5,13:18.13
0,6,13:18.13
1,6,13:18.13
2,6,13:17.13
4,6,13:18.5
3,7,13:18.13
5,7,13:18.5
2,8,13:18.5
2,9,13:18.5
1,1,14:18.13
-2,2,14:17.13
0,2,14:18.13
1,2,14:18.13
2,2,14:18.13
-2,3,14:18.13
0,3,14:18.13
2,3,14:18.13
-1,4,14:18.13
0,4,14:17.13
1,4,14:18.13
0,5,14:18.13
1,5,14:17.13
0,6,14:18.13
1,6,14:18.13
-1,7,14:18.13
0,7,14:18.13
1,7,14:18.13
-2,2,15:17.13
-2,2,16:17.13
-1,-2,17:18.13
-4,0,17:18.13
-4,1,17:18.13
-3,1,17:18.13
-2,1,17:18.13
-1,1,17:17.13
0,1,17:18.13
-3,2,17:18.13
-2,2,17:17.13
-1,2,17:18.13
0,3,17:18.13
-2,4,17:18.13
0,4,17:18.13
0,-4,18:18.13
1,-4,18:18.13
1,-3,18:18.13
-1,-2,18:18.13
2,-2,18:18.13
0,-1,18:18.13
1,-1,18:17.13
3,-1,18:18.13
-1,0,18:18.13
0,0,18:17.13
2,0,18:18.13
-2,2,18:17.13
2,2,18:18.13
-5,-5,19:18.5
-6,-4,19:18.13
-6,-3,19:18.13
-5,-3,19:18.13
-4,-3,19:18.13
-8,-2,19:18.13
-7,-2,19:18.13
-6,-2,19:17.13
-4,-2,19:18.13
-8,-1,19:18.13
-5,-1,19:18.13
-4,-1,19:18.13
-3,-1,19:18.13
-7,0,19:18.13
-6,0,19:18.13
0,0,19:18.13
-7,1,19:18.13
-5,1,19:18.13
-3,1,19:17.13
0,1,19:18.13
-5,2,19:18.13
-3,2,19:18.13
-2,2,19:17.13
-1,2,19:18.13
-5,3,19:18.13
-3,4,19:18.13
-6,-4,20:18.13
-6,-3,20:18.13
-5,-3,20:18.13
-4,-2,20:18.13
-3,-2,20:18.13
-2,-2,20:18.13
-5,-1,20:17.13
-3,-1,20:18.13
-7,0,20:18.13
-4,0,20:17.13
-2,2,20:17.13
-1,4,20:18.13
-2,5,20:18.13
-4,6,20:18.13
-2,6,20:18.13
0,6,20:18.13
-2,7,20:17.13
0,7,20:18.13
1,7,20:18.13
-3,8,20:18.5
-1,8,20:18.5
-2,9,20:18.5
-2,2,21:17.13
-3,3,21:18.13
-2,3,21:17.13
0,4,21:18.13
-2,5,21:18.13
0,5,21:18.13
-5,6,21:18.13
-2,6,21:17.13
0,6,21:18.13
1,6,21:18.13
-2,7,21:18.13
0,8,21:18.5
-2,1,22:18.13
-3,2,22:18.13
-2,2,22:17.13
-4,3,22:18.13
-4,4,22:18.13
-3,4,22:18.13
-2,4,22:17.13
-1,4,22:18.13
0,4,22:18.13
1,4,22:18.13
-5,5,22:18.13
-2,5,22:17.13
-4,6,22:18.13
-2,6,22:18.13
-2,2,23:17.13
-2,2,24:17.13
-2,-5,25:18.13
-4,-4,25:18.13
0,-4,25:18.13
-3,-3,25:18.13
-1,-3,25:18.13
-2,-2,25:17.13
0,-2,25:18.13
-2,-1,25:18.13
-1,-1,25:18.13
-1,0,25:18.13
0,0,25:18.13
-3,1,25:17.13
-2,1,25:18.13
-1,1,25:18.13
-3,2,25:18.13
-2,2,25:17.13
0,2,25:18.13
0,3,25:18.13
-2,4,25:18.13
0,4,25:18.13
-2,5,25:18.13
-3,-3,26:18.13
-2,-3,26:18.13
-4,-2,26:18.13
-3,-2,26:18.13
-2,-2,26:18.13
-6,-1,26:18.13
-3,-1,26:17.13
-5,0,26:18.13
-4,0,26:18.13
-3,0,26:17.13
-2,0,26:18.13
-4,1,26:18.13
-3,1,26:18.13
-5,2,26:18.13
-4,2,26:18.13
-3,2,26:18.13
-2,2,26:17.13
0,2,26:18.13
1,2,26:18.13
-2,3,26:18.13
0,3,26:18.13
1,3,26:18.13
-2,4,26:18.13
-3,-1,27:18.5
-2,-1,27:18.5
-2,0,27:18.5
-3,1,27:18.5
-1,1,27:18.5
1,1,27:18.5
-5,2,27:18.5
-3,2,27:18.5
-2,2,27:17.13
-1,2,27:18.5
1,2,27:18.5
-4,3,27:18.5
-3,3,27:18.5
1,3,27:18.5
-3,4,27:18.5
-2,5,27:18.5
