[META]
version=2.0
spawnOnBlockType=2
spawnSunlight=True
spawnDarkness=True
spawnWater=False
spawnLava=False
underFill=False
randomRotation=True
dig=True
tree=False
branch=False
needsFoundation=True
rarity=100
collisionPercentage=20
spawnElevationMin=0
spawnElevationMax=200
spawnInBiome=Custom
[DATA]
-4,-2,-3:17.13
0,-2,-3:17.13
-1,0,-3:17.13
-4,-2,-2:17.13
0,-2,-2:17.13
-2,-1,-2:17.13
-1,0,-2:17.13
-2,1,-2:17.13
-4,-2,-1:17.13
0,-2,-1:17.13
-3,-1,-1:17.13
-2,-1,-1:17.13
-1,-1,-1:17.13
-1,0,-1:17.13
-2,1,-1:17.13
0,1,-1:17.13
-4,-2,0:17.13
0,-2,0:17.13
-3,-1,0:17.13
-2,-1,0:17.13
-1,-1,0:17.13
-1,0,0:17.13
-2,1,0:17.13
0,1,0:17.13
3,-2,1:18.14
4,-2,1:18.14
-2,-1,1:17.13
-1,-1,1:17.13
4,-1,1:18.14
5,-1,1:18.6
-1,0,1:17.13
-5,5,1:18.14
-3,5,1:18.14
-2,6,1:18.14
-3,7,1:18.6
-6,-6,2:18.14
-4,-6,2:18.14
-5,-5,2:18.14
4,-4,2:18.14
3,-2,2:18.14
4,-2,2:18.14
-1,-1,2:17.13
4,-1,2:18.14
5,-1,2:18.6
-1,0,2:17.13
-5,5,2:18.14
-3,5,2:18.14
-5,6,2:18.6
-2,6,2:18.6
-3,7,2:18.6
-3,8,2:18.6
-5,-7,3:18.6
-4,-7,3:18.6
-6,-6,3:18.14
-5,-6,3:18.14
-4,-6,3:18.14
-6,-5,3:18.14
-5,-5,3:18.14
-4,-5,3:18.14
4,-4,3:18.14
3,-2,3:18.14
4,-2,3:18.14
-1,-1,3:17.13
4,-1,3:18.14
5,-1,3:18.6
-1,0,3:17.13
-4,4,3:18.14
-3,4,3:18.14
-5,5,3:18.14
-3,5,3:18.14
-5,6,3:18.6
-2,6,3:18.6
-3,7,3:18.6
-3,8,3:18.6
-5,-7,4:18.14
-4,-7,4:18.14
-6,-6,4:18.14
-5,-6,4:18.14
-4,-6,4:18.14
-6,-5,4:18.14
-5,-5,4:18.14
-4,-5,4:18.14
4,-4,4:18.14
-4,-3,4:18.14
0,-2,4:17.13
3,-2,4:18.14
4,-2,4:18.14
6,-2,4:18.6
-1,-1,4:17.13
3,-1,4:18.14
4,-1,4:18.14
5,-1,4:18.6
6,-1,4:18.6
-2,0,4:17.13
0,1,4:17.13
-4,4,4:18.14
-3,4,4:18.14
-5,5,4:18.14
-3,5,4:18.14
-5,6,4:18.6
-2,6,4:18.14
-1,6,4:18.14
-3,7,4:18.14
-3,8,4:18.6
-4,-7,5:18.6
-6,-6,5:18.14
-5,-6,5:18.6
-4,-6,5:18.14
-7,-5,5:18.14
-6,-5,5:18.14
-5,-5,5:17.13
-4,-5,5:18.14
-7,-4,5:18.14
4,-4,5:18.6
-5,-3,5:18.14
-4,-3,5:18.14
-2,-2,5:17.13
0,-2,5:17.13
3,-2,5:18.14
6,-2,5:18.6
-6,-1,5:18.14
3,-1,5:18.14
4,-1,5:18.6
5,-1,5:18.14
6,-1,5:18.14
-7,0,5:18.6
-2,0,5:17.13
3,0,5:18.14
4,0,5:18.6
5,0,5:18.6
-7,1,5:18.6
0,1,5:17.13
4,1,5:17.13
-1,2,5:17.13
-1,3,5:17.13
-3,4,5:18.14
-5,5,5:18.14
-3,5,5:18.14
-1,5,5:18.6
-5,6,5:18.6
-3,6,5:17.13
-1,6,5:18.14
-2,7,5:18.14
-3,8,5:18.14
-4,-7,6:18.14
-6,-6,6:18.14
-5,-6,6:18.14
-5,-5,6:18.14
-1,-5,6:18.14
-4,-4,6:17.13
4,-4,6:18.14
5,-4,6:18.6
-4,-3,6:18.14
-3,-3,6:17.13
0,-2,6:17.13
1,-2,6:17.13
3,-2,6:18.14
4,-2,6:17.13
5,-2,6:18.6
6,-2,6:18.6
-6,-1,6:18.14
4,-1,6:18.14
-7,0,6:18.6
-2,0,6:17.13
3,0,6:17.13
4,0,6:18.14
5,0,6:18.14
-7,1,6:18.6
0,1,6:17.13
-6,2,6:18.14
-1,4,6:17.13
-3,5,6:18.14
-2,5,6:17.13
-1,5,6:18.14
-5,6,6:18.14
-3,6,6:18.14
-3,7,6:18.14
-3,8,6:18.14
-2,8,6:18.14
-4,-5,7:18.14
-3,-5,7:18.14
-1,-5,7:18.14
-4,-4,7:18.14
4,-4,7:18.14
5,-4,7:18.14
5,-3,7:18.6
0,-2,7:17.13
3,-2,7:18.14
4,-2,7:18.6
5,-2,7:18.14
6,-2,7:18.14
-6,-1,7:18.14
2,-1,7:17.13
3,-1,7:17.13
4,-1,7:18.14
-7,0,7:18.6
-7,1,7:18.6
-6,1,7:18.14
-3,1,7:17.13
-6,2,7:18.14
1,2,7:17.13
-5,3,7:18.14
-3,4,7:18.14
-3,5,7:18.14
-3,6,7:18.14
-1,-6,8:18.6
-3,-5,8:18.14
-1,-5,8:18.14
1,-5,8:18.14
-3,-4,8:18.14
0,-4,8:18.14
-4,-3,8:18.14
-2,-3,8:18.14
-1,-3,8:17.13
1,-3,8:18.14
5,-3,8:18.14
3,-2,8:18.14
4,-2,8:18.14
-6,-1,8:18.14
-7,0,8:18.6
-6,0,8:18.14
-7,1,8:18.6
-6,1,8:18.14
-5,1,8:18.14
-3,1,8:17.13
-6,2,8:18.14
1,2,8:17.13
2,2,8:18.14
-5,3,8:18.14
0,3,8:18.14
2,3,8:18.14
3,3,8:18.14
-3,4,8:18.14
1,4,8:18.14
3,4,8:18.6
-3,5,8:18.14
-1,-6,9:18.6
-3,-5,9:18.6
-1,-5,9:18.6
1,-5,9:18.6
2,-5,9:18.6
-3,-4,9:18.6
0,-4,9:18.6
1,-4,9:18.6
-4,-3,9:18.6
-2,-3,9:18.6
-1,-3,9:17.13
1,-3,9:18.6
-7,-2,9:18.6
-6,-1,9:18.6
-4,-1,9:18.6
1,-1,9:18.6
-7,0,9:18.6
-6,0,9:18.6
-4,0,9:17.13
-7,1,9:18.6
-6,1,9:18.6
-5,1,9:18.6
-6,2,9:18.6
-3,2,9:17.13
1,2,9:17.13
2,2,9:18.6
-5,3,9:18.6
-1,3,9:18.6
0,3,9:18.6
2,3,9:18.6
3,3,9:18.6
-3,4,9:18.6
1,4,9:18.6
3,4,9:18.6
-3,5,9:18.6
2,5,9:18.6
1,6,9:18.6
-2,-6,10:18.6
-1,-6,10:18.6
0,-6,10:18.6
-3,-5,10:18.6
-1,-5,10:18.6
1,-5,10:18.6
2,-5,10:18.6
-3,-4,10:18.6
-1,-4,10:17.13
0,-4,10:18.6
1,-4,10:18.6
-4,-3,10:18.6
-2,-3,10:18.6
-1,-3,10:18.6
0,-3,10:18.6
1,-3,10:18.6
-7,-2,10:18.6
-6,-2,10:18.6
-3,-2,10:18.6
-6,-1,10:18.6
-4,-1,10:18.6
1,-1,10:18.6
-7,0,10:18.6
-6,0,10:18.6
-4,0,10:17.13
0,0,10:18.6
2,0,10:18.6
3,0,10:18.6
4,0,10:18.6
-7,1,10:18.6
-6,1,10:18.6
-5,1,10:18.6
-2,1,10:18.6
-1,1,10:18.6
0,1,10:18.6
2,1,10:17.13
4,1,10:18.6
-6,2,10:18.6
-3,2,10:17.13
1,2,10:18.6
2,2,10:18.6
-5,3,10:18.6
-1,3,10:18.6
0,3,10:18.6
1,3,10:17.13
2,3,10:18.6
3,3,10:18.6
-5,4,10:18.6
-3,4,10:18.6
1,4,10:18.6
2,4,10:18.6
3,4,10:18.6
-5,5,10:18.6
-3,5,10:18.6
2,5,10:18.6
1,6,10:18.6
2,6,10:18.6
0,-7,11:18.6
-2,-6,11:18.6
-1,-6,11:18.6
0,-6,11:18.6
-3,-5,11:18.6
-1,-5,11:18.6
1,-5,11:18.6
2,-5,11:18.6
-3,-4,11:18.6
-1,-4,11:17.13
0,-4,11:18.6
1,-4,11:18.6
-4,-3,11:18.6
-3,-3,11:18.6
-2,-3,11:18.6
-1,-3,11:18.6
0,-3,11:18.6
1,-3,11:18.6
-7,-2,11:18.6
-6,-2,11:18.6
-3,-2,11:18.6
-6,-1,11:18.6
-5,-1,11:17.13
-4,-1,11:18.6
-1,-1,11:18.6
1,-1,11:18.6
2,-1,11:18.6
-7,0,11:18.6
-6,0,11:18.6
-4,0,11:18.6
0,0,11:18.6
2,0,11:18.6
3,0,11:18.6
4,0,11:18.6
-7,1,11:18.6
-6,1,11:18.6
-5,1,11:18.6
-4,1,11:18.6
-2,1,11:18.6
-1,1,11:18.6
0,1,11:18.6
1,1,11:18.6
2,1,11:17.13
4,1,11:18.6
-6,2,11:18.6
-4,2,11:18.6
1,2,11:18.6
2,2,11:18.6
3,2,11:18.6
4,2,11:18.6
-5,3,11:18.6
-3,3,11:17.13
-1,3,11:18.6
0,3,11:18.6
1,3,11:17.13
2,3,11:18.6
3,3,11:18.6
-5,4,11:18.6
-3,4,11:18.6
0,4,11:18.6
1,4,11:18.6
2,4,11:18.6
3,4,11:18.6
-5,5,11:18.6
-3,5,11:18.6
2,5,11:18.6
1,6,11:18.6
2,6,11:18.6
0,-7,12:18.6
-2,-6,12:18.6
-1,-6,12:18.6
0,-6,12:18.14
-3,-5,12:18.14
-1,-5,12:18.14
1,-5,12:18.14
2,-5,12:18.14
-6,-4,12:18.6
-3,-4,12:18.14
-1,-4,12:17.13
0,-4,12:18.14
1,-4,12:18.14
-6,-3,12:18.6
-4,-3,12:18.14
-3,-3,12:18.14
-2,-3,12:18.14
-1,-3,12:18.14
0,-3,12:18.14
1,-3,12:18.14
-7,-2,12:18.6
-6,-2,12:18.6
-4,-2,12:18.14
-3,-2,12:18.14
-2,-2,12:18.6
-1,-2,12:18.6
-6,-1,12:18.14
-5,-1,12:17.13
-4,-1,12:18.14
-1,-1,12:18.6
1,-1,12:18.14
2,-1,12:18.14
-7,0,12:18.14
-6,0,12:18.14
-4,0,12:18.14
-2,0,12:18.6
0,0,12:18.6
2,0,12:18.14
3,0,12:18.14
4,0,12:18.6
-7,1,12:18.14
-6,1,12:18.6
-5,1,12:18.14
-4,1,12:18.14
-2,1,12:18.6
-1,1,12:18.6
0,1,12:18.6
1,1,12:18.14
2,1,12:17.13
4,1,12:18.6
-6,2,12:18.6
-4,2,12:18.14
0,2,12:18.6
1,2,12:18.14
2,2,12:18.14
3,2,12:18.14
4,2,12:18.6
-5,3,12:18.14
-3,3,12:17.13
-1,3,12:18.14
0,3,12:18.14
1,3,12:17.13
2,3,12:18.14
3,3,12:18.14
-5,4,12:18.14
-3,4,12:18.14
0,4,12:18.14
1,4,12:18.14
2,4,12:18.14
3,4,12:18.14
-5,5,12:18.6
-3,5,12:18.6
2,5,12:18.6
3,5,12:18.6
-4,6,12:18.6
1,6,12:18.6
2,6,12:18.6
0,-7,13:18.14
-2,-6,13:18.6
-1,-6,13:18.14
0,-6,13:18.6
2,-6,13:18.6
-3,-5,13:18.14
-1,-5,13:18.14
0,-5,13:17.13
1,-5,13:18.14
2,-5,13:18.14
-6,-4,13:18.6
-5,-4,13:18.14
-3,-4,13:18.14
-2,-4,13:17.13
-1,-4,13:18.14
0,-4,13:18.14
1,-4,13:18.14
-6,-3,13:18.6
-5,-3,13:18.14
-4,-3,13:18.14
-3,-3,13:18.14
-2,-3,13:18.14
-1,-3,13:18.14
0,-3,13:18.14
1,-3,13:18.14
-7,-2,13:18.6
-6,-2,13:18.6
-5,-2,13:17.13
-4,-2,13:18.14
-3,-2,13:18.14
-2,-2,13:18.6
-1,-2,13:18.6
3,-2,13:18.14
4,-2,13:18.6
-6,-1,13:18.14
-5,-1,13:18.14
-4,-1,13:18.14
-3,-1,13:18.6
-1,-1,13:18.6
1,-1,13:18.14
2,-1,13:18.14
-7,0,13:18.14
-6,0,13:17.13
-5,0,13:18.14
-4,0,13:18.14
-3,0,13:18.6
-2,0,13:18.6
0,0,13:18.6
2,0,13:18.14
3,0,13:17.13
4,0,13:18.6
-8,1,13:18.6
-6,1,13:18.6
-5,1,13:18.14
-4,1,13:18.14
-2,1,13:18.6
-1,1,13:18.6
0,1,13:18.6
1,1,13:18.14
2,1,13:18.14
4,1,13:18.14
-6,2,13:18.14
-4,2,13:18.14
-3,2,13:18.6
-2,2,13:18.6
0,2,13:18.6
1,2,13:18.14
2,2,13:18.14
3,2,13:18.14
4,2,13:18.6
-5,3,13:18.14
-3,3,13:17.13
-1,3,13:18.14
0,3,13:18.14
1,3,13:18.14
2,3,13:18.14
3,3,13:18.14
-6,4,13:18.6
-5,4,13:18.14
-3,4,13:18.14
0,4,13:18.14
1,4,13:17.13
2,4,13:18.14
3,4,13:18.14
-5,5,13:18.6
-3,5,13:18.6
-2,5,13:18.6
2,5,13:18.6
3,5,13:18.6
-4,6,13:18.6
1,6,13:18.14
2,6,13:18.14
0,-7,14:18.6
-2,-6,14:18.6
-1,-6,14:18.14
0,-6,14:18.14
1,-6,14:18.6
2,-6,14:18.14
-3,-5,14:18.14
-1,-5,14:18.14
0,-5,14:17.13
1,-5,14:18.14
2,-5,14:18.14
-6,-4,14:18.6
-5,-4,14:18.14
-3,-4,14:18.14
-2,-4,14:17.13
-1,-4,14:18.14
0,-4,14:18.14
1,-4,14:18.14
-7,-3,14:18.6
-6,-3,14:18.6
-5,-3,14:18.14
-4,-3,14:18.14
-3,-3,14:18.14
-2,-3,14:18.14
-1,-3,14:18.14
0,-3,14:18.14
1,-3,14:18.14
-7,-2,14:18.14
-6,-2,14:18.14
-5,-2,14:17.13
-4,-2,14:18.14
-3,-2,14:18.14
-2,-2,14:18.6
-1,-2,14:18.14
3,-2,14:18.14
4,-2,14:18.14
-6,-1,14:18.6
-5,-1,14:18.14
-4,-1,14:18.14
-3,-1,14:18.6
-1,-1,14:18.6
2,-1,14:18.14
4,-1,14:18.6
5,-1,14:18.6
-6,0,14:17.13
-5,0,14:18.14
-4,0,14:18.14
-3,0,14:18.6
-2,0,14:18.6
0,0,14:18.6
2,0,14:18.14
3,0,14:17.13
4,0,14:18.6
5,0,14:18.6
-8,1,14:18.6
-6,1,14:18.14
-5,1,14:18.14
-4,1,14:18.14
-2,1,14:18.6
-1,1,14:18.6
0,1,14:18.6
1,1,14:18.14
2,1,14:18.14
4,1,14:18.14
5,1,14:18.6
-6,2,14:18.14
-4,2,14:18.14
-3,2,14:18.6
-2,2,14:18.6
0,2,14:18.6
1,2,14:18.14
2,2,14:18.14
3,2,14:18.14
4,2,14:18.14
-5,3,14:18.14
-4,3,14:18.6
-3,3,14:18.14
-1,3,14:18.14
0,3,14:18.14
1,3,14:18.14
2,3,14:18.14
3,3,14:18.14
-6,4,14:18.6
-5,4,14:18.14
-4,4,14:17.13
-3,4,14:18.14
0,4,14:18.14
1,4,14:17.13
2,4,14:18.14
3,4,14:18.14
-5,5,14:18.6
-3,5,14:18.6
-2,5,14:18.6
2,5,14:18.14
3,5,14:18.6
-4,6,14:18.6
1,6,14:18.14
0,-7,15:18.14
-2,-6,15:18.14
0,-6,15:18.14
1,-6,15:18.6
-3,-5,15:18.14
-1,-5,15:18.14
0,-5,15:18.14
-6,-4,15:18.14
-5,-4,15:18.14
-2,-4,15:17.13
-1,-4,15:18.14
0,-4,15:18.14
1,-4,15:18.14
-7,-3,15:18.14
-6,-3,15:18.14
-5,-3,15:18.14
-4,-3,15:18.14
-2,-3,15:18.14
-1,-3,15:18.14
0,-3,15:18.14
-7,-2,15:18.14
-6,-2,15:18.14
-5,-2,15:17.13
-4,-2,15:18.14
-3,-2,15:18.14
-2,-2,15:18.6
-1,-2,15:18.14
3,-2,15:18.14
-6,-1,15:18.14
-5,-1,15:18.14
-3,-1,15:18.6
-1,-1,15:18.14
2,-1,15:18.14
4,-1,15:18.14
5,-1,15:18.14
-6,0,15:18.6
-5,0,15:18.14
-3,0,15:18.14
-1,0,15:18.14
0,0,15:18.14
1,0,15:18.6
3,0,15:18.14
4,0,15:18.14
5,0,15:18.14
-8,1,15:18.14
-2,1,15:18.14
-1,1,15:18.14
0,1,15:18.14
2,1,15:18.14
5,1,15:18.14
-4,2,15:18.14
-3,2,15:18.14
-2,2,15:18.14
0,2,15:18.6
1,2,15:18.14
3,2,15:18.14
4,2,15:18.14
5,2,15:18.14
-5,3,15:18.14
-4,3,15:18.14
-3,3,15:18.14
0,3,15:18.14
1,3,15:18.14
2,3,15:18.14
3,3,15:18.14
5,3,15:18.14
-6,4,15:18.6
-5,4,15:18.14
-4,4,15:17.13
-3,4,15:18.14
0,4,15:18.14
1,4,15:18.14
2,4,15:18.14
3,4,15:18.14
-5,5,15:18.6
-3,5,15:18.14
-2,5,15:18.6
1,5,15:18.14
2,5,15:18.14
3,5,15:18.14
-4,6,15:18.14
1,-6,16:18.14
-1,-5,16:18.14
0,-5,16:18.14
-2,-4,16:18.14
1,-4,16:18.14
-2,-3,16:18.14
-1,-3,16:18.14
0,-3,16:18.14
-5,-2,16:18.14
-3,-2,16:18.14
-2,-2,16:18.6
-1,-2,16:18.14
-6,-1,16:18.6
-3,-1,16:18.14
-1,-1,16:18.14
2,-1,16:18.14
4,-1,16:18.14
-6,0,16:18.14
-5,0,16:18.14
-3,0,16:18.14
-1,0,16:18.14
0,0,16:18.14
1,0,16:18.6
3,0,16:18.14
-2,1,16:18.6
-1,1,16:18.14
2,1,16:18.14
-4,2,16:18.14
-3,2,16:18.14
-2,2,16:18.14
0,2,16:18.6
1,2,16:18.14
3,2,16:18.14
5,2,16:18.14
-5,3,16:18.14
-4,3,16:18.14
-6,4,16:18.14
-5,4,16:18.14
-4,4,16:17.13
-3,4,16:18.14
0,4,16:18.14
1,4,16:18.14
-5,5,16:18.14
-2,5,16:18.14
-4,6,16:18.14
-5,-2,17:18.14
-6,-1,17:18.14
-1,-1,17:18.14
-1,0,17:18.14
-2,1,17:18.14
-1,1,17:18.14
3,2,17:18.14
4,2,17:18.14
-5,3,17:18.14
-4,3,17:18.14
4,3,17:18.14
-4,4,17:18.6
-4,5,17:18.6
-1,0,18:18.6
-4,5,18:18.14
