[META]
version=2.0
spawnOnBlockType=2
spawnSunlight=True
spawnDarkness=True
spawnWater=False
spawnLava=False
underFill=False
randomRotation=True
dig=True
tree=False
branch=False
needsFoundation=True
rarity=100
collisionPercentage=20
spawnElevationMin=0
spawnElevationMax=200
spawnInBiome=Custom
[DATA]
-1,1,0:17.1
-1,0,1:18.13
-3,1,1:18.13
-2,1,1:18.13
-1,1,1:17.1
0,1,1:18.13
-1,-2,2:18.13
0,-2,2:18.13
-2,-1,2:18.13
-1,-1,2:18.13
1,-1,2:18.13
-2,0,2:18.13
0,0,2:18.13
-3,1,2:18.13
-1,1,2:17.1
0,1,2:18.13
1,1,2:18.13
-2,2,2:18.5
-1,2,2:18.5
0,2,2:18.5
1,2,2:18.5
-2,3,2:18.13
-1,3,2:18.13
0,3,2:18.13
-1,-1,3:18.13
0,-1,3:18.13
-2,0,3:18.13
1,0,3:18.13
-3,1,3:18.13
-2,1,3:18.13
-1,1,3:17.1
0,1,3:18.13
-1,2,3:18.5
-2,3,3:18.13
-1,3,3:18.5
-1,-1,4:18.13
1,-1,4:18.13
-2,0,4:18.13
-1,0,4:18.13
1,0,4:18.13
-2,1,4:18.13
-1,1,4:17.1
0,1,4:18.13
1,1,4:18.13
-2,2,4:18.13
-1,2,4:18.13
0,2,4:18.5
0,3,4:18.5
-1,0,5:18.13
0,0,5:18.13
-2,1,5:18.13
-1,1,5:17.1
0,1,5:18.13
-2,2,5:18.13
0,2,5:18.13
1,2,5:18.5
-1,3,5:18.13
-1,0,6:18.5
-1,1,6:18.13
1,1,6:18.13
-1,2,6:18.13
-1,1,7:18.13
0,1,7:18.5
