[META]
version=2.0
spawnOnBlockType=2
spawnSunlight=True
spawnDarkness=True
spawnWater=False
spawnLava=False
underFill=False
randomRotation=True
dig=True
tree=False
branch=False
needsFoundation=True
rarity=100
collisionPercentage=20
spawnElevationMin=0
spawnElevationMax=200
spawnInBiome=Custom
[DATA]
-1,-1,-3:17.13
-2,1,-3:17.13
-1,-1,-2:17.13
-3,0,-2:17.13
-2,0,-2:17.13
-2,1,-2:17.13
-2,-1,-1:17.13
-1,-1,-1:17.13
-3,0,-1:17.13
-2,0,-1:17.13
-1,0,-1:17.13
-2,1,-1:17.13
-2,-1,0:17.13
-1,-1,0:17.13
-3,0,0:17.13
-2,0,0:17.13
-1,0,0:17.13
-2,1,0:17.13
-1,-1,1:17.13
-2,0,1:17.13
-1,0,1:17.13
-2,0,2:17.13
-1,0,2:17.13
-2,0,3:17.13
-1,0,3:17.13
-2,0,4:17.13
-2,0,5:17.13
-2,0,6:17.13
-2,0,7:17.13
-2,1,8:17.13
-2,1,9:17.13
-2,1,10:17.13
-2,1,11:17.13
-2,1,12:17.13
-2,1,13:17.13
-1,0,14:17.13
-2,1,14:17.13
-1,0,15:17.13
-1,0,16:17.13
-1,0,17:17.13
1,-2,18:18.14
2,-2,18:18.14
1,-1,18:18.14
-1,0,18:17.13
-3,4,18:18.14
-1,4,18:18.14
0,-4,19:18.14
3,-2,19:18.14
-1,-1,19:18.14
0,-1,19:17.13
1,-1,19:18.14
3,-1,19:18.14
-1,0,19:17.13
0,0,19:18.14
-1,1,19:17.13
0,3,19:18.14
-3,5,19:18.14
-2,5,19:18.14
-1,-3,20:18.14
1,-3,20:18.14
1,-2,20:17.13
0,-1,20:18.14
3,-1,20:18.14
-1,0,20:17.13
1,0,20:18.14
-2,1,20:18.14
-2,2,20:17.13
-3,3,20:18.14
-2,3,20:17.13
-3,4,20:18.14
-2,4,20:18.14
1,-4,21:18.14
0,-2,21:18.14
3,-2,21:18.14
-1,-1,21:18.14
1,-1,21:18.14
2,-1,21:18.14
-1,0,21:17.13
1,0,21:18.14
-2,1,21:18.14
-1,1,21:18.14
-2,3,21:18.14
-1,3,21:18.14
-3,-3,22:18.14
-1,-2,22:18.14
0,-2,22:18.14
1,-2,22:18.14
-1,-1,22:17.13
0,-1,22:18.6
1,-1,22:18.14
-3,0,22:18.14
-1,0,22:17.13
0,0,22:18.14
-4,1,22:18.14
-3,2,22:18.14
-1,2,22:18.14
1,2,22:18.6
2,2,22:18.6
-3,4,22:18.14
-1,-3,23:18.14
1,-3,23:18.14
-3,-2,23:18.14
-2,-2,23:18.14
-1,-2,23:17.13
0,-2,23:18.14
1,-2,23:18.14
-3,-1,23:18.14
-2,-1,23:18.14
-1,-1,23:18.14
0,-1,23:18.6
1,-1,23:18.14
-4,0,23:18.14
-3,0,23:18.14
-2,0,23:17.13
-1,0,23:17.13
0,0,23:18.6
2,0,23:18.6
-2,1,23:18.6
0,1,23:17.13
-2,2,23:18.14
0,2,23:18.6
1,2,23:18.6
0,3,23:18.6
1,3,23:18.6
-1,-4,24:18.14
0,-4,24:18.14
-2,-3,24:18.14
1,-3,24:18.14
-4,-2,24:18.14
-3,-2,24:18.14
-2,-2,24:18.14
-1,-2,24:18.14
0,-2,24:17.13
-1,-1,24:18.14
1,-1,24:18.14
-3,0,24:17.13
-2,0,24:18.14
-1,0,24:17.13
1,0,24:17.13
-3,1,24:18.14
-2,1,24:18.14
-1,1,24:18.14
1,1,24:18.6
-4,2,24:18.14
-3,2,24:18.14
-2,2,24:18.14
0,2,24:17.13
0,-3,25:18.14
-1,-2,25:18.14
0,-2,25:18.14
-5,-1,25:18.14
-2,-1,25:18.14
-1,-1,25:18.14
0,-1,25:18.14
-3,0,25:18.14
-2,0,25:18.14
-1,0,25:17.13
0,0,25:18.14
-3,1,25:18.14
-2,1,25:18.14
-1,1,25:18.14
0,2,25:18.6
1,2,25:18.6
-1,-2,26:18.14
0,-2,26:18.14
-2,-1,26:18.14
-1,-1,26:18.14
-4,0,26:18.14
0,0,26:18.14
-1,2,26:18.14
-2,0,27:18.14
-1,0,27:18.14
0,0,27:18.14
0,1,27:18.14
