[META]
version=2.0
spawnOnBlockType=2
spawnSunlight=True
spawnDarkness=True
spawnWater=False
spawnLava=False
underFill=False
randomRotation=True
dig=True
tree=False
branch=False
needsFoundation=True
rarity=100
collisionPercentage=20
spawnElevationMin=0
spawnElevationMax=200
spawnInBiome=Custom
[DATA]
-1,0,0:17.2
-2,-2,1:18.4
0,-1,1:18.4
-1,0,1:17.2
0,0,1:18.4
-1,-2,2:18.4
1,-2,2:18.4
-1,-1,2:18.4
1,-1,2:18.4
-1,0,2:17.2
0,0,2:18.4
-2,1,2:18.4
0,1,2:18.4
-2,2,2:18.12
0,2,2:18.12
1,2,2:18.4
-2,-3,3:18.4
-4,-2,3:18.4
-3,-2,3:18.4
-2,-2,3:18.4
0,-2,3:18.4
-1,-1,3:18.4
0,-1,3:18.4
2,-1,3:18.4
-3,0,3:18.4
-1,0,3:17.2
0,0,3:18.4
1,0,3:18.4
2,0,3:18.4
-1,1,3:18.4
1,1,3:18.4
-5,2,3:18.4
-4,2,3:18.4
-3,2,3:18.4
-1,3,3:18.4
-3,4,3:18.4
-1,4,3:18.4
-2,-4,4:18.4
0,-4,4:18.4
-4,-2,4:18.4
-2,-2,4:18.4
1,-2,4:18.4
2,-2,4:18.4
0,-1,4:18.4
2,-1,4:18.4
-4,0,4:18.4
-2,0,4:18.4
-1,0,4:17.2
0,0,4:18.4
-2,1,4:18.4
-1,1,4:18.4
-5,2,4:18.4
-3,2,4:18.4
0,3,4:18.4
0,4,4:18.4
-3,5,4:18.4
-1,-4,5:18.4
-3,-3,5:18.4
-3,-2,5:18.4
-1,-2,5:18.4
2,-2,5:18.4
-4,-1,5:18.4
-3,-1,5:18.4
2,-1,5:18.4
-3,0,5:18.4
-1,0,5:17.2
-5,1,5:18.4
-3,1,5:18.4
-2,1,5:18.4
-1,1,5:18.4
1,1,5:18.4
-3,2,5:18.4
-2,2,5:18.4
-1,2,5:18.4
-5,3,5:18.4
-1,4,5:18.4
0,4,5:18.4
-1,5,5:18.4
-1,-3,6:18.4
0,-3,6:18.4
-4,-2,6:18.4
1,-2,6:18.4
-4,-1,6:18.4
-3,-1,6:18.4
0,-1,6:18.4
1,-1,6:18.4
-3,0,6:18.4
-2,0,6:18.4
-1,0,6:17.2
-3,1,6:18.4
-1,1,6:18.4
0,1,6:18.4
-4,2,6:18.4
-2,2,6:18.4
-1,2,6:18.4
0,2,6:18.4
-4,3,6:18.4
-2,3,6:18.4
-3,4,6:18.4
-2,4,6:18.4
-1,-4,7:18.4
0,-4,7:18.4
-3,-2,7:18.4
-2,-2,7:18.4
-1,-2,7:18.4
1,-2,7:18.4
2,-2,7:18.4
-3,-1,7:18.4
-2,-1,7:18.4
0,-1,7:18.4
2,-1,7:18.4
-3,0,7:18.4
-1,0,7:17.2
0,0,7:18.4
1,0,7:18.4
2,0,7:18.4
-4,1,7:18.4
-1,1,7:18.4
0,1,7:18.4
-3,2,7:18.4
-2,2,7:18.4
-4,3,7:18.4
-3,3,7:18.4
-2,3,7:18.4
-1,3,7:18.4
-3,4,7:18.4
-2,4,7:18.4
-4,-4,8:18.4
-2,-4,8:18.4
0,-4,8:18.4
-1,-3,8:18.4
-4,-2,8:18.4
-3,-2,8:18.4
-2,-2,8:18.4
-3,-1,8:18.4
-2,-1,8:18.4
1,-1,8:18.4
2,-1,8:18.4
-2,0,8:18.4
-1,0,8:17.2
0,0,8:18.4
0,1,8:18.4
-4,2,8:18.4
-2,2,8:18.4
-5,3,8:18.4
1,3,8:18.4
-2,4,8:18.4
-1,4,8:18.4
-2,5,8:18.4
-1,-4,9:18.4
-2,-3,9:18.4
1,-3,9:18.4
-5,-2,9:18.4
-2,-1,9:18.4
0,-1,9:18.4
2,-1,9:18.4
-4,0,9:18.4
-3,0,9:18.4
-2,0,9:18.4
-1,0,9:17.2
0,0,9:18.4
2,0,9:18.4
-2,1,9:18.4
-1,1,9:18.4
-3,2,9:18.4
-1,2,9:18.4
0,2,9:18.4
1,2,9:18.4
-2,3,9:18.4
-1,3,9:18.4
1,3,9:18.4
-4,4,9:18.4
-3,4,9:18.4
-2,4,9:18.4
-3,5,9:18.4
-4,-3,10:18.4
-5,-2,10:18.4
-2,-2,10:18.4
1,-2,10:18.4
-3,-1,10:18.4
-2,-1,10:18.4
0,-1,10:18.4
-4,0,10:18.4
-2,0,10:18.4
-1,0,10:17.2
1,0,10:18.4
2,0,10:18.4
-3,1,10:18.4
-1,1,10:18.4
0,1,10:18.4
-4,2,10:18.4
-3,2,10:18.4
-2,2,10:18.4
-1,2,10:18.4
-2,3,10:18.4
-1,3,10:18.4
0,3,10:18.4
-2,4,10:18.4
0,4,10:18.4
-1,5,10:18.4
-2,-3,11:18.4
-1,-3,11:18.4
0,-3,11:18.4
1,-2,11:18.4
-3,-1,11:18.4
2,-1,11:18.4
-4,0,11:18.4
-1,0,11:17.2
-4,1,11:18.4
-3,1,11:18.4
1,1,11:18.4
-2,2,11:18.4
1,2,11:18.4
-3,3,11:18.4
-2,3,11:18.4
-2,4,11:18.4
0,4,11:18.4
0,-4,12:18.4
-1,-3,12:18.4
0,-3,12:18.4
-4,-2,12:18.4
-2,-2,12:18.4
-1,-2,12:18.4
1,-2,12:18.4
-4,-1,12:18.4
-3,-1,12:18.4
-1,-1,12:18.4
-4,0,12:18.4
-3,0,12:18.4
-1,0,12:17.2
0,0,12:18.4
-3,1,12:18.4
-3,2,12:18.4
-2,2,12:18.4
0,2,12:18.4
-2,-3,13:18.4
-3,-2,13:18.4
-1,-2,13:18.4
-3,-1,13:18.4
2,-1,13:18.4
-4,0,13:18.4
-3,0,13:18.4
-2,0,13:18.4
-1,0,13:17.2
0,0,13:18.4
2,0,13:18.4
-3,2,13:18.4
-2,2,13:18.4
-1,2,13:18.4
-1,-3,14:18.4
-2,-2,14:18.4
-1,-2,14:18.4
0,-2,14:18.4
-2,-1,14:18.4
-1,-1,14:18.4
0,-1,14:18.4
-4,0,14:18.4
-3,0,14:18.4
-1,0,14:17.2
-5,1,14:18.4
-3,1,14:18.4
-1,1,14:18.4
-1,3,14:18.4
-3,-3,15:18.12
-1,-3,15:18.4
1,-3,15:18.4
-3,-2,15:18.12
-2,-2,15:18.4
0,-2,15:18.4
-5,-1,15:18.12
0,-1,15:18.4
1,-1,15:18.4
-1,0,15:17.2
-1,1,15:18.4
-4,2,15:18.4
-3,2,15:18.4
-2,2,15:18.4
1,2,15:18.4
-3,-3,16:18.12
-4,-2,16:18.12
-3,-2,16:18.12
-4,0,16:18.12
-1,0,16:17.2
-1,1,16:18.4
1,1,16:18.4
-3,2,16:18.4
-1,2,16:18.4
-3,3,16:18.4
-1,-4,17:18.4
-4,-2,17:18.12
-3,-2,17:18.12
-1,-2,17:18.4
-4,-1,17:18.12
-3,-1,17:18.12
0,-1,17:18.4
1,-1,17:18.4
2,-1,17:18.4
-3,0,17:18.4
-1,0,17:17.2
0,0,17:18.4
-2,1,17:18.4
1,1,17:18.4
-2,2,17:18.4
0,2,17:18.4
-1,-2,18:18.4
1,-2,18:18.4
-4,-1,18:18.12
-2,0,18:18.4
2,0,18:18.4
1,1,18:18.4
-3,2,18:18.4
-1,-2,19:18.4
-3,-1,19:18.12
-2,-1,19:18.4
-1,-1,19:18.4
0,-1,19:18.4
1,-1,19:18.4
-2,0,19:18.4
0,0,19:18.4
-1,1,19:18.4
-1,-1,20:18.4
