[META]
version=2.0
spawnOnBlockType=2
spawnSunlight=True
spawnDarkness=True
spawnWater=False
spawnLava=False
underFill=False
randomRotation=True
dig=True
tree=False
branch=False
needsFoundation=True
rarity=100
collisionPercentage=20
spawnElevationMin=0
spawnElevationMax=200
spawnInBiome=Custom
[DATA]
-2,1,-3:17.12
-2,-1,-2:17.12
-3,0,-2:17.12
-3,1,-2:17.12
-2,1,-2:17.12
-2,-1,-1:17.12
-4,0,-1:17.12
-3,0,-1:17.12
-2,0,-1:17.12
-3,1,-1:17.12
-2,1,-1:17.12
-2,2,-1:17.12
-2,-1,0:17.12
-4,0,0:17.12
-3,0,0:17.12
-2,0,0:17.12
-3,1,0:17.12
-2,1,0:17.12
-2,2,0:17.12
-3,0,1:17.12
-2,0,1:17.12
-3,1,1:17.12
-2,1,1:17.12
-6,-2,2:18.12
-4,-2,2:18.12
-3,0,2:17.12
-2,0,2:17.12
-3,1,2:17.12
-2,1,2:17.12
-5,2,2:18.12
1,2,2:18.12
-5,3,2:18.12
-4,4,2:18.12
-1,-4,3:18.12
-6,-3,3:18.12
-3,-3,3:18.12
1,-2,3:18.12
-7,-1,3:18.12
1,-1,3:18.12
-4,1,3:18.12
-3,1,3:17.12
-2,1,3:17.12
0,1,3:18.12
-7,2,3:18.12
-1,2,3:18.12
1,2,3:18.12
-6,3,3:18.12
0,7,3:18.4
-1,8,3:18.4
-3,-5,4:18.12
-1,-5,4:18.12
-2,-4,4:18.12
-6,-3,4:18.12
-5,-3,4:18.12
-4,-3,4:18.12
-2,-3,4:18.12
1,-3,4:18.12
2,-3,4:18.12
-2,-2,4:18.12
1,-2,4:18.12
3,-2,4:18.4
-6,-1,4:18.12
-1,-1,4:18.12
1,-1,4:18.12
-5,0,4:18.12
-1,0,4:18.12
1,0,4:18.12
-2,1,4:17.12
-1,1,4:18.12
-7,2,4:18.12
-5,3,4:18.12
-2,3,4:18.12
1,3,4:18.12
-7,4,4:18.12
-4,4,4:18.12
-3,4,4:18.12
-3,5,4:18.12
-2,5,4:18.12
-1,5,4:18.12
-5,6,4:18.12
-1,6,4:18.12
-5,7,4:18.4
-2,7,4:18.4
1,7,4:18.4
-4,8,4:18.4
-1,8,4:18.4
0,8,4:18.4
1,8,4:18.4
-1,-6,5:18.4
-7,-5,5:18.4
-4,-4,5:18.12
-2,-4,5:18.12
0,-4,5:18.12
1,-4,5:18.12
-5,-3,5:18.12
-2,-3,5:18.12
0,-3,5:18.12
1,-3,5:18.12
2,-3,5:18.12
3,-3,5:18.12
-5,-2,5:18.12
-4,-2,5:18.12
-3,-2,5:18.12
-2,-2,5:18.12
1,-2,5:18.12
-7,-1,5:18.12
0,-1,5:18.12
2,-1,5:18.12
3,-1,5:18.4
-5,0,5:18.12
0,0,5:18.12
1,0,5:18.12
-4,1,5:18.12
-3,1,5:18.12
-2,1,5:17.12
0,1,5:18.12
-5,2,5:18.12
-3,2,5:18.12
-2,2,5:17.12
1,2,5:18.12
-6,3,5:18.12
-5,3,5:18.12
-2,3,5:18.12
2,3,5:18.12
-5,4,5:18.12
-4,4,5:18.12
-2,4,5:18.12
-1,4,5:18.12
0,4,5:18.12
1,4,5:18.12
-7,5,5:18.12
-6,5,5:18.12
-5,5,5:18.12
-3,5,5:18.12
-1,5,5:18.12
-5,6,5:18.12
-4,6,5:18.12
-1,6,5:18.12
-5,7,5:18.4
-3,7,5:18.4
-2,7,5:18.4
-1,8,5:18.4
2,8,5:18.4
-4,9,5:18.4
-3,9,5:18.4
-2,9,5:18.4
0,9,5:18.4
-6,-6,6:18.4
0,-6,6:18.4
-4,-5,6:18.4
-8,-4,6:18.4
-5,-4,6:18.12
-3,-4,6:18.12
-2,-4,6:18.12
-8,-3,6:18.4
-7,-3,6:18.12
0,-3,6:18.12
3,-3,6:18.12
-2,-2,6:18.12
-1,-2,6:18.12
-3,-1,6:18.12
-2,-1,6:18.12
-1,-1,6:18.12
-2,0,6:18.12
0,0,6:18.12
1,0,6:18.12
-4,1,6:18.12
-1,1,6:18.12
2,1,6:18.12
-5,2,6:18.12
-2,2,6:17.12
-1,2,6:18.12
-5,3,6:18.12
-2,3,6:18.12
-7,4,6:18.12
-5,4,6:18.12
-4,4,6:18.12
-2,4,6:18.12
-1,4,6:18.12
0,4,6:18.12
-7,5,6:18.12
-3,5,6:18.12
0,5,6:18.12
1,5,6:18.12
-6,6,6:18.12
-5,6,6:18.12
-4,6,6:18.12
-3,6,6:18.12
-2,6,6:18.12
-1,6,6:18.12
0,6,6:18.12
2,6,6:18.12
-4,7,6:18.4
-3,7,6:18.4
-2,7,6:18.4
-1,7,6:18.4
2,7,6:18.4
-3,8,6:18.4
-1,8,6:18.4
1,8,6:18.4
2,8,6:18.4
-5,9,6:18.4
-2,9,6:18.4
-1,10,6:18.4
-2,-6,7:18.4
-4,-5,7:18.4
-4,-4,7:18.4
0,-4,7:18.4
-6,-3,7:18.12
-1,-3,7:18.12
0,-3,7:18.12
-5,-2,7:18.12
-2,-2,7:18.12
0,-2,7:18.12
1,-2,7:18.12
-7,-1,7:18.12
-5,-1,7:18.12
-3,-1,7:18.12
-2,-1,7:18.12
-1,-1,7:18.12
-6,1,7:18.12
-5,1,7:18.12
-3,1,7:18.12
-2,1,7:18.12
-1,1,7:18.12
-7,2,7:18.12
-4,2,7:18.12
-2,2,7:17.12
2,2,7:18.12
-6,3,7:18.12
-5,3,7:18.12
-2,3,7:18.12
-1,3,7:18.12
-6,4,7:18.12
-5,4,7:18.12
-4,4,7:18.12
-3,4,7:18.12
-2,4,7:18.12
0,4,7:18.12
-5,5,7:18.12
-4,5,7:18.12
-3,5,7:18.12
-2,5,7:18.12
-7,6,7:18.4
-5,6,7:18.12
-4,6,7:18.12
-2,6,7:18.12
-1,6,7:18.12
-7,7,7:18.4
-5,7,7:18.4
-4,7,7:18.4
-3,7,7:18.4
-2,7,7:18.4
-1,7,7:18.4
-6,8,7:18.4
-4,8,7:18.4
-3,8,7:18.4
-2,8,7:18.4
0,8,7:18.4
-3,9,7:18.4
-2,9,7:18.4
-1,10,7:18.4
-2,-6,8:18.4
-2,-5,8:18.4
-5,-4,8:18.4
-2,-4,8:18.12
-6,-3,8:18.12
-4,-3,8:18.12
-3,-3,8:18.12
-6,-2,8:18.12
0,-2,8:18.12
-5,-1,8:18.12
-4,-1,8:18.12
-3,-1,8:18.12
-2,-1,8:18.12
-4,0,8:18.12
-3,0,8:18.12
-1,0,8:18.12
-6,1,8:18.12
-5,1,8:18.12
-4,1,8:18.12
-2,1,8:18.12
-4,2,8:18.12
-3,2,8:17.12
-2,2,8:17.12
-4,3,8:18.12
-3,3,8:18.12
-2,3,8:18.12
1,4,8:18.12
-6,5,8:18.12
1,6,8:18.12
-3,7,8:18.4
-2,7,8:18.4
-1,7,8:18.4
0,7,8:18.4
-4,8,8:18.4
-2,8,8:18.4
-1,8,8:18.4
0,8,8:18.4
1,8,8:18.4
-1,9,8:18.4
-2,-5,9:18.4
-3,-4,9:18.12
-5,-3,9:18.12
-5,-2,9:18.12
-2,-2,9:18.12
-4,-1,9:18.12
-3,0,9:18.12
-3,2,9:17.12
-3,3,9:17.12
-3,4,9:18.12
-5,5,9:18.12
-2,5,9:18.12
0,5,9:18.12
-6,6,9:18.12
-4,6,9:18.12
-3,6,9:18.12
-2,6,9:18.12
-3,7,9:18.4
-1,7,9:18.4
-4,8,9:18.4
-2,8,9:18.4
-1,8,9:18.4
-4,9,9:18.4
-3,-3,10:18.12
-4,-2,10:18.12
-5,3,10:18.4
-3,3,10:17.12
-6,4,10:18.4
-3,4,10:18.4
-6,5,10:18.4
-5,5,10:18.4
-3,6,10:18.4
-1,6,10:18.4
-4,7,10:18.4
-3,7,10:18.4
-4,8,10:18.4
-3,0,11:18.12
-1,2,11:18.4
-5,3,11:18.4
-4,3,11:18.4
-3,3,11:17.12
-6,4,11:18.4
-4,4,11:18.4
-6,5,11:18.4
-5,5,11:18.4
-4,5,11:18.4
-4,6,11:18.4
-4,0,12:18.12
-5,1,12:18.4
-3,1,12:18.12
-2,1,12:18.4
-6,2,12:18.12
-5,2,12:18.12
-7,3,12:18.4
-4,3,12:18.12
-3,3,12:17.12
-2,3,12:18.4
-7,4,12:18.4
-5,4,12:18.12
-3,4,12:18.4
-2,4,12:18.4
-5,5,12:18.4
-4,5,12:18.4
-2,5,12:18.4
-3,6,12:18.4
-5,7,12:18.4
-3,7,12:18.4
-3,0,13:18.4
-6,1,13:18.12
-3,1,13:18.4
-7,2,13:18.12
-6,2,13:18.12
-5,2,13:18.12
-3,2,13:18.4
-2,2,13:18.4
-4,3,13:18.12
-3,3,13:18.4
-2,3,13:18.4
-6,4,13:18.12
-4,4,13:18.12
-2,4,13:18.4
-7,5,13:18.4
-6,5,13:18.4
-5,5,13:18.4
-3,5,13:18.4
-5,6,13:18.4
-5,8,13:18.4
-6,1,14:18.12
-5,2,14:18.12
-4,2,14:18.12
-2,2,14:18.4
-4,3,14:18.12
-4,4,14:18.12
-2,4,14:18.4
-1,4,14:18.4
-8,5,14:18.4
-7,5,14:18.4
-6,5,14:18.4
-2,5,14:18.4
-6,6,14:18.4
-5,6,14:18.4
-6,7,14:18.4
-3,7,14:18.4
-5,1,15:18.12
-4,2,15:18.12
-2,2,15:18.4
-2,3,15:18.4
-5,4,15:18.12
-5,5,15:18.12
-3,2,16:18.4
