[META]
version=2.0
spawnOnBlockType=2
spawnSunlight=True
spawnDarkness=True
spawnWater=False
spawnLava=False
underFill=False
randomRotation=True
dig=True
tree=False
branch=False
needsFoundation=True
rarity=100
collisionPercentage=20
spawnElevationMin=0
spawnElevationMax=200
spawnInBiome=Custom
[DATA]
0,0,0:17.1
-1,-5,1:18.5
0,-5,1:18.5
0,-4,1:18.5
-4,-3,1:18.5
4,-3,1:18.5
-3,-2,1:18.5
-2,-2,1:18.5
-1,-2,1:18.5
0,-2,1:18.5
4,-2,1:18.5
-3,-1,1:18.5
2,-1,1:18.5
3,-1,1:18.5
5,-1,1:18.5
-5,0,1:18.5
-4,0,1:18.5
0,0,1:17.1
1,0,1:18.5
2,0,1:18.5
3,0,1:18.5
4,0,1:18.5
5,0,1:18.5
-2,1,1:18.5
0,1,1:18.5
3,1,1:18.5
4,1,1:18.5
-5,2,1:18.5
-4,2,1:18.5
-3,3,1:18.5
-1,5,1:18.5
0,5,1:18.5
0,-5,2:18.5
1,-5,2:18.5
-2,-4,2:18.5
0,-4,2:18.5
-4,-3,2:18.5
-2,-3,2:18.5
2,-3,2:18.5
-3,-2,2:18.5
0,-2,2:18.5
4,-2,2:18.5
5,-2,2:18.5
-5,-1,2:18.5
-4,-1,2:18.5
-2,-1,2:18.5
5,-1,2:18.5
-5,0,2:18.5
-3,0,2:18.5
-2,0,2:18.5
0,0,2:17.1
2,0,2:18.5
-4,1,2:18.5
-3,1,2:18.5
-2,3,2:18.5
1,3,2:18.5
4,3,2:18.5
-3,4,2:18.5
0,4,2:18.5
3,4,2:18.5
-2,5,2:18.5
-1,-4,3:18.5
0,-4,3:18.5
2,-4,3:18.5
-2,-3,3:18.5
-1,-2,3:18.5
-1,0,3:18.5
0,0,3:17.1
1,0,3:18.5
2,0,3:18.5
4,0,3:18.5
-1,1,3:18.5
1,1,3:18.5
4,1,3:18.5
0,2,3:18.5
2,2,3:18.5
-1,3,3:18.5
1,4,3:18.5
2,-4,4:18.5
-3,-3,4:18.5
-1,-3,4:18.5
0,-3,4:18.5
-2,-2,4:18.5
2,-1,4:18.5
4,-1,4:18.5
-2,0,4:18.5
0,0,4:17.1
1,0,4:18.5
3,0,4:18.5
0,1,4:18.5
4,1,4:18.5
-4,2,4:18.5
1,2,4:18.5
3,2,4:18.5
4,2,4:18.5
0,3,4:18.5
3,3,4:18.5
-2,4,4:18.5
0,4,4:18.5
-2,-4,5:18.5
-1,-4,5:18.5
0,-4,5:18.5
-3,-3,5:18.5
-2,-2,5:18.5
-1,-2,5:18.5
-2,-1,5:18.5
2,-1,5:18.5
3,-1,5:18.5
-2,0,5:18.5
-1,0,5:18.5
0,0,5:17.1
1,0,5:18.5
4,0,5:18.5
-3,1,5:18.5
-4,2,5:18.5
-3,2,5:18.5
3,2,5:18.5
0,3,5:18.5
1,3,5:18.5
-1,4,5:18.5
2,-4,6:18.5
0,-3,6:18.5
1,-3,6:18.5
2,-3,6:18.5
-3,-1,6:18.5
-1,-1,6:18.5
3,-1,6:18.5
-4,0,6:18.5
-3,0,6:18.5
-2,0,6:18.5
-1,0,6:18.5
0,0,6:17.1
4,0,6:18.5
0,1,6:18.5
1,1,6:18.5
-3,2,6:18.5
-2,2,6:18.5
3,2,6:18.5
-3,3,6:18.5
2,3,6:18.5
-2,4,6:18.5
0,4,6:18.5
-2,-2,7:18.5
2,-2,7:18.5
-3,0,7:18.5
-1,0,7:18.5
0,0,7:17.1
1,0,7:18.5
2,0,7:18.5
3,0,7:18.5
1,2,7:18.5
2,2,7:18.5
0,3,7:18.5
1,3,7:18.5
-1,-3,8:18.5
0,-2,8:18.5
-3,-1,8:18.5
0,-1,8:18.5
-3,0,8:18.5
-1,0,8:18.5
0,0,8:17.1
1,0,8:18.5
2,0,8:18.5
-2,1,8:18.5
-1,1,8:18.5
2,1,8:18.5
3,1,8:18.5
2,2,8:18.5
-1,3,8:18.5
-1,-3,9:18.5
-1,-2,9:18.5
-2,-1,9:18.5
-1,-1,9:18.5
0,-1,9:18.5
3,-1,9:18.5
-2,0,9:18.5
0,0,9:17.1
0,3,9:18.5
0,-3,10:18.5
1,-3,10:18.5
-3,-1,10:18.5
3,-1,10:18.5
-3,0,10:18.5
0,0,10:17.1
2,0,10:18.5
-2,2,10:18.5
0,2,10:18.5
0,3,10:18.5
1,3,10:18.5
1,-3,11:18.5
-1,-1,11:18.5
0,-1,11:18.5
3,-1,11:18.5
-3,0,11:18.5
-2,0,11:18.5
-1,0,11:18.5
0,0,11:17.1
1,0,11:18.5
2,0,11:18.5
-2,1,11:18.5
-1,1,11:18.5
-2,2,11:18.5
0,2,11:18.5
0,3,11:18.5
-1,-3,12:18.5
1,-2,12:18.5
-1,-1,12:18.5
2,-1,12:18.5
-3,0,12:18.5
-2,0,12:18.5
0,0,12:17.1
1,0,12:18.5
3,0,12:18.5
0,1,12:18.5
2,1,12:18.5
1,3,12:18.5
0,-2,13:18.13
0,-1,13:18.13
2,-1,13:18.13
-2,0,13:18.13
-1,0,13:18.13
0,0,13:17.1
2,0,13:18.13
-1,1,13:18.13
1,-1,14:18.13
-1,0,14:18.13
0,0,14:17.1
1,0,14:18.13
-1,-2,15:18.13
1,-2,15:18.13
-1,-1,15:18.13
-1,0,15:18.13
0,0,15:17.1
1,0,15:18.13
2,0,15:18.13
0,1,15:18.13
1,1,15:18.13
1,-1,16:18.13
-1,0,16:18.13
0,0,16:17.1
1,0,16:18.13
-2,1,16:18.13
0,2,16:18.13
0,-1,17:18.13
0,0,17:17.1
1,0,17:18.13
0,1,17:18.13
0,-1,18:18.13
0,0,18:17.1
1,0,18:18.13
-1,1,18:18.13
