[META]
version=2.0
spawnOnBlockType=2
spawnSunlight=True
spawnDarkness=True
spawnWater=False
spawnLava=False
underFill=False
randomRotation=True
dig=True
tree=False
branch=False
needsFoundation=True
rarity=100
collisionPercentage=20
spawnElevationMin=0
spawnElevationMax=200
spawnInBiome=Custom
[DATA]
-1,-1,0:17.0
-1,-1,1:17.0
-1,-1,2:17.12
-5,-7,3:18.4
-2,-7,3:18.4
-6,-6,3:18.4
-5,-6,3:18.4
-2,-6,3:18.4
-7,-5,3:18.4
-6,-5,3:18.4
-5,-5,3:18.4
-4,-5,3:18.4
-3,-5,3:18.4
-2,-5,3:18.4
-1,-5,3:18.12
0,-5,3:18.12
1,-5,3:18.12
-7,-4,3:18.4
-6,-4,3:18.4
-5,-4,3:18.4
-4,-4,3:18.4
-3,-4,3:18.4
-2,-4,3:18.12
-1,-4,3:18.12
0,-4,3:18.12
1,-4,3:18.12
2,-4,3:18.12
-6,-3,3:18.4
-5,-3,3:18.4
-4,-3,3:18.4
-3,-3,3:18.12
-2,-3,3:18.12
-1,-3,3:17.12
0,-3,3:18.12
1,-3,3:18.12
2,-3,3:18.4
-5,-2,3:18.4
-4,-2,3:18.4
-3,-2,3:18.4
-2,-2,3:18.4
-1,-2,3:17.12
0,-2,3:18.12
1,-2,3:18.4
-6,-1,3:18.4
-5,-1,3:18.4
-4,-1,3:18.4
-3,-1,3:18.4
-2,-1,3:18.4
-1,-1,3:17.12
0,-1,3:18.12
1,-1,3:18.4
-4,0,3:18.4
-4,1,3:18.4
-4,-6,4:18.4
-6,-5,4:18.4
-4,-5,4:18.4
-3,-5,4:18.4
-2,-5,4:18.4
-5,-4,4:18.4
-4,-4,4:18.4
-3,-4,4:18.4
-2,-4,4:18.4
0,-4,4:18.4
-5,-3,4:18.4
-4,-3,4:18.4
-3,-3,4:18.4
-2,-3,4:18.12
-1,-3,4:18.12
-5,-2,4:18.4
-4,-2,4:18.4
-3,-2,4:18.4
-2,-2,4:18.12
-1,-2,4:18.12
0,-2,4:18.12
2,-2,4:18.4
-3,-1,4:18.12
-2,-1,4:18.12
-1,-1,4:17.12
0,-1,4:18.4
2,-1,4:18.4
-3,0,4:18.4
-1,0,4:18.4
0,0,4:18.4
1,0,4:18.12
-2,1,4:18.12
0,-4,5:18.4
-1,-3,5:18.4
0,-3,5:18.4
1,-3,5:18.4
2,-3,5:18.4
0,-2,5:17.12
2,-2,5:18.4
-2,-1,5:18.12
-1,-1,5:17.12
0,-1,5:18.12
1,-1,5:18.4
-2,0,5:17.12
0,0,5:18.4
1,0,5:18.4
-4,1,5:18.12
-3,1,5:18.12
-2,1,5:18.12
0,1,5:18.12
1,1,5:18.4
2,1,5:18.4
3,1,5:18.4
4,1,5:18.4
-2,2,5:18.12
-1,2,5:18.12
0,2,5:18.4
1,2,5:18.4
2,2,5:18.4
5,2,5:18.4
0,3,5:18.4
1,3,5:18.4
2,3,5:18.4
3,3,5:18.4
4,3,5:18.4
5,3,5:18.4
1,4,5:18.4
2,4,5:18.4
3,4,5:18.4
1,5,5:18.12
2,5,5:18.4
3,-7,6:18.4
3,-6,6:18.4
4,-6,6:18.4
1,-5,6:18.4
2,-5,6:18.4
3,-5,6:18.4
4,-5,6:18.4
5,-5,6:18.4
-3,-4,6:18.12
0,-4,6:18.4
2,-4,6:18.4
3,-4,6:18.4
4,-4,6:18.4
5,-4,6:18.4
6,-4,6:18.4
7,-4,6:18.4
-4,-3,6:18.12
-3,-3,6:17.12
-2,-3,6:18.12
0,-3,6:18.12
1,-3,6:18.4
2,-3,6:18.12
3,-3,6:18.12
4,-3,6:18.4
5,-3,6:18.4
6,-3,6:18.4
7,-3,6:18.4
-3,-2,6:18.12
-2,-2,6:17.12
-1,-2,6:18.12
0,-2,6:18.12
1,-2,6:17.12
2,-2,6:18.12
3,-2,6:18.12
4,-2,6:18.4
5,-2,6:18.4
-3,-1,6:18.12
-2,-1,6:18.12
-1,-1,6:17.12
0,-1,6:17.12
1,-1,6:18.12
2,-1,6:18.12
3,-1,6:18.12
4,-1,6:18.4
5,-1,6:18.4
-3,0,6:18.4
-1,0,6:18.4
0,0,6:18.4
1,0,6:18.12
2,0,6:18.12
3,0,6:18.4
-2,1,6:18.4
-1,1,6:18.4
2,1,6:18.4
1,2,6:18.4
2,2,6:18.4
0,3,6:18.4
2,4,6:18.4
3,4,6:18.4
-4,-5,7:18.4
-3,-4,7:18.4
-2,-4,7:18.4
-1,-4,7:18.4
0,-4,7:18.4
3,-4,7:18.4
-6,-3,7:18.4
-5,-3,7:18.4
-4,-3,7:18.4
-3,-3,7:18.4
-2,-3,7:18.4
-1,-3,7:18.4
0,-3,7:18.12
1,-3,7:18.4
2,-3,7:18.4
-5,-2,7:18.4
-4,-2,7:18.4
-3,-2,7:18.12
-2,-2,7:18.12
-1,-2,7:18.12
0,-2,7:18.4
1,-2,7:18.4
2,-2,7:18.4
3,-2,7:18.4
4,-2,7:18.4
5,-2,7:18.4
6,-2,7:18.4
-3,-1,7:18.12
-2,-1,7:18.4
-1,-1,7:17.12
0,-1,7:18.4
1,-1,7:18.12
2,-1,7:18.4
3,-1,7:18.4
4,-1,7:18.4
-3,0,7:18.12
-2,0,7:18.4
-1,0,7:18.4
0,0,7:18.12
1,0,7:18.4
2,0,7:18.4
3,0,7:18.4
5,0,7:18.4
-3,1,7:18.4
-2,1,7:18.4
-1,1,7:18.12
0,1,7:18.4
-4,2,7:18.4
-3,2,7:18.4
-2,2,7:18.12
-1,2,7:18.4
0,2,7:17.12
1,2,7:18.12
-5,3,7:18.4
-4,3,7:18.4
-3,3,7:18.4
-2,3,7:18.4
0,3,7:18.12
-5,4,7:18.4
-3,4,7:18.4
-2,4,7:18.4
-1,4,7:18.4
0,4,7:18.12
1,4,7:18.12
2,4,7:18.4
-3,5,7:18.4
-3,6,7:18.4
-1,-3,8:18.12
-1,-2,8:18.12
1,-2,8:18.12
-2,-1,8:18.12
-1,-1,8:17.12
1,-1,8:18.4
-2,0,8:18.4
-1,0,8:17.12
0,0,8:18.12
1,0,8:18.12
2,0,8:18.12
-3,1,8:18.4
-2,1,8:18.12
-1,1,8:18.4
0,1,8:17.12
2,1,8:18.4
3,1,8:18.4
-2,2,8:18.12
0,2,8:18.4
1,2,8:18.4
2,2,8:18.4
-3,3,8:18.4
-2,3,8:18.4
-1,3,8:18.4
0,3,8:18.4
1,3,8:18.12
-1,4,8:18.4
0,4,8:18.4
-1,5,8:18.4
0,5,8:18.4
0,-7,9:18.4
0,-6,9:18.4
1,-6,9:18.4
2,-6,9:18.12
3,-6,9:18.4
4,-6,9:18.4
2,-5,9:18.12
3,-5,9:18.12
4,-5,9:18.12
0,-4,9:18.12
2,-4,9:17.12
3,-4,9:18.4
4,-4,9:18.12
-2,-3,9:18.12
0,-3,9:18.12
2,-3,9:18.12
3,-3,9:18.12
-2,-2,9:18.12
-1,-2,9:18.12
3,-2,9:18.12
-2,-1,9:18.12
-1,-1,9:17.12
0,-1,9:18.12
1,-1,9:18.12
-1,1,9:18.12
1,-5,10:18.12
2,-5,10:18.12
-1,-4,10:18.12
1,-4,10:18.12
-1,-3,10:18.12
1,-3,10:17.12
2,-3,10:18.12
-1,-2,10:18.12
0,-2,10:17.12
1,-2,10:18.12
2,-2,10:18.12
-1,-1,10:17.12
0,-1,10:18.4
1,-1,10:18.12
2,-1,10:18.12
3,-1,10:18.4
-1,0,10:18.4
1,0,10:18.4
3,0,10:18.4
-4,-3,11:18.12
-6,-1,11:18.4
-5,-1,11:18.12
-4,-1,11:17.12
-2,-1,11:18.12
-1,-1,11:17.12
-7,0,11:18.4
-6,0,11:18.4
-5,0,11:18.12
-4,0,11:18.12
-5,1,11:18.4
-4,1,11:18.12
-1,-5,12:18.4
0,-5,12:18.4
1,-5,12:18.4
-5,-4,12:18.4
-4,-4,12:18.4
-3,-4,12:18.4
-2,-4,12:18.4
0,-4,12:18.4
-3,-3,12:18.12
-2,-3,12:18.12
-1,-3,12:18.4
0,-3,12:18.4
2,-3,12:18.4
-6,-2,12:18.4
-4,-2,12:18.12
-3,-2,12:18.4
-2,-2,12:18.4
0,-2,12:18.4
1,-2,12:18.4
2,-2,12:18.4
-5,-1,12:18.12
-4,-1,12:18.4
-3,-1,12:17.12
-2,-1,12:17.12
-1,-1,12:17.12
0,-1,12:18.4
1,-1,12:18.4
-4,0,12:18.4
-3,0,12:18.12
-2,0,12:18.12
-4,1,12:18.4
-2,1,12:18.12
-3,2,12:18.4
1,-5,13:18.4
-3,-4,13:18.4
-2,-3,13:18.4
-1,-3,13:18.4
0,-3,13:18.4
1,-3,13:18.4
2,-3,13:18.4
-2,-2,13:18.4
2,-2,13:18.4
-3,-1,13:18.4
-2,-1,13:18.4
-1,-1,13:17.12
0,-1,13:18.4
-2,0,13:18.4
-1,0,13:18.4
0,0,13:18.4
-2,1,13:18.4
2,-2,14:18.4
4,-2,14:18.4
-1,-1,14:17.12
2,-1,14:18.4
3,-1,14:18.4
1,0,14:18.4
2,0,14:18.4
3,0,14:18.4
4,0,14:18.4
1,1,14:18.4
2,1,14:18.4
4,1,14:18.4
1,2,14:18.4
2,2,14:17.12
3,2,14:18.4
4,2,14:18.4
2,3,14:18.4
3,3,14:18.4
2,4,14:18.4
3,4,14:18.4
0,-2,15:18.4
-5,-1,15:18.4
-4,-1,15:18.4
-3,-1,15:18.4
-2,-1,15:18.4
-1,-1,15:17.12
1,-1,15:18.4
2,-1,15:18.4
-3,0,15:18.4
-2,0,15:18.4
-1,0,15:18.4
0,0,15:17.12
1,0,15:18.4
-4,1,15:18.4
-3,1,15:18.4
-2,1,15:18.4
-1,1,15:18.4
0,1,15:18.4
1,1,15:17.12
2,1,15:18.4
-4,2,15:18.4
-2,2,15:18.4
-1,2,15:18.4
0,2,15:18.4
1,2,15:18.4
3,2,15:18.4
-3,3,15:18.4
1,3,15:18.4
-2,4,15:18.4
0,-7,16:18.4
2,-7,16:18.4
2,-6,16:18.4
3,-6,16:18.4
-1,-5,16:18.4
0,-5,16:18.4
1,-5,16:18.4
2,-5,16:18.4
0,-4,16:18.4
1,-4,16:18.4
3,-4,16:18.4
-1,-3,16:18.4
0,-3,16:18.4
1,-3,16:18.4
2,-3,16:18.4
3,-3,16:18.4
-2,-2,16:18.4
-1,-2,16:18.4
0,-2,16:18.4
1,-2,16:18.4
3,-2,16:18.4
-3,-1,16:18.4
-2,-1,16:18.4
-1,-1,16:17.12
1,-1,16:18.4
2,-1,16:18.4
3,-1,16:18.4
0,0,16:18.4
-2,1,16:18.4
0,1,16:18.4
1,1,16:18.4
2,1,16:18.4
1,-6,17:18.4
-1,-4,17:18.4
0,-4,17:18.4
1,-4,17:18.4
2,-4,17:18.4
-2,-3,17:18.4
-1,-3,17:18.4
-3,-2,17:18.4
-1,-2,17:17.12
0,-2,17:18.4
-3,-1,17:18.4
-1,-1,17:17.12
0,-1,17:18.4
1,-1,17:18.4
1,0,17:18.4
-1,-3,18:18.12
-1,-2,18:18.12
1,-2,18:18.12
-3,-1,18:18.12
-2,-1,18:18.12
-1,-1,18:17.12
0,-1,18:18.12
-1,0,18:18.12
-3,1,18:18.12
-1,1,18:18.12
1,1,18:18.12
-1,2,18:18.12
1,2,18:18.12
-1,3,18:18.12
-1,-5,19:18.12
-1,-4,19:18.12
-3,-3,19:18.12
-2,-3,19:18.12
-2,-2,19:18.12
-1,-2,19:18.12
0,-2,19:18.12
-3,-1,19:18.12
-2,-1,19:17.12
-1,-1,19:17.12
-3,0,19:18.12
-2,0,19:18.12
0,0,19:18.12
-3,1,19:18.12
0,-4,20:18.12
0,-3,20:18.12
-1,-2,20:18.12
0,-2,20:17.12
-1,-1,20:17.12
0,0,20:18.12
-2,-4,21:18.12
-1,-4,21:18.12
-4,-3,21:18.12
-1,-3,21:18.12
-4,-2,21:18.12
-3,-2,21:18.12
-2,-2,21:18.12
-1,-2,21:18.12
0,-2,21:18.12
-4,-1,21:18.12
-3,-1,21:18.12
-2,-1,21:18.12
-1,-1,21:17.12
0,-1,21:18.12
-4,0,21:18.12
-3,0,21:18.12
-2,0,21:18.12
-1,0,21:17.12
0,0,21:18.12
1,0,21:18.12
-1,1,21:18.12
1,1,21:18.12
-2,-2,22:18.4
-1,-2,22:18.4
-2,-1,22:18.4
-1,-1,22:18.4
0,-1,22:18.4
-1,0,22:18.4
0,0,22:18.4
-2,-1,23:18.4
-1,-1,23:18.4
0,-1,23:18.4
-1,-1,24:18.4
