[META]
version=2.0
spawnOnBlockType=2
spawnSunlight=True
spawnDarkness=True
spawnWater=False
spawnLava=False
underFill=False
randomRotation=True
dig=True
tree=False
branch=False
needsFoundation=True
rarity=100
collisionPercentage=20
spawnElevationMin=0
spawnElevationMax=200
spawnInBiome=Custom
[DATA]
-1,0,0:17.14
-1,0,1:17.14
0,0,1:18.12
-3,-4,2:18.12
-2,-4,2:18.12
-2,-3,2:18.12
-1,-2,2:18.12
-1,0,2:17.14
0,1,2:18.12
-2,2,2:18.12
-3,-2,3:18.12
-2,-2,3:18.12
-2,-1,3:18.12
-1,-1,3:18.12
-3,0,3:18.12
-1,0,3:17.14
1,0,3:18.12
-3,1,3:18.12
-2,1,3:17.14
0,1,3:18.12
-2,2,3:17.14
-2,3,3:18.12
0,3,3:18.12
-2,4,3:18.12
-1,4,3:18.12
0,4,3:18.12
-2,-5,4:18.4
0,-5,4:18.4
-3,-4,4:18.12
-2,-3,4:18.12
0,-3,4:18.12
1,-3,4:18.12
-3,-2,4:18.12
-2,-2,4:18.12
-1,-2,4:18.12
-2,-1,4:18.12
-1,-1,4:18.12
0,-1,4:18.12
1,-1,4:18.12
-1,0,4:17.14
-3,1,4:18.12
-2,1,4:18.12
0,1,4:18.12
-1,2,4:18.12
0,2,4:18.12
1,2,4:18.12
-5,3,4:18.12
-3,4,4:18.12
-2,4,4:18.12
-4,-5,5:18.4
-3,-5,5:18.4
-2,-5,5:18.4
0,-4,5:18.12
-4,-3,5:18.12
-3,-3,5:18.12
-2,-3,5:17.14
0,-3,5:18.12
1,-3,5:18.12
-3,-2,5:18.12
-2,-2,5:17.14
-1,-2,5:18.12
2,-2,5:18.12
3,-2,5:18.12
-4,-1,5:18.12
-2,-1,5:17.14
-1,-1,5:18.12
2,-1,5:18.12
-2,0,5:18.12
-1,0,5:17.14
1,0,5:18.12
2,0,5:18.12
-4,1,5:18.12
-2,1,5:18.12
-1,1,5:18.12
-2,2,5:18.12
-1,2,5:18.12
0,2,5:18.12
-2,3,5:18.12
1,3,5:18.12
2,3,5:18.12
-2,4,5:18.12
-3,-5,6:18.4
-2,-5,6:18.4
1,-4,6:18.12
0,-3,6:18.12
-4,-2,6:18.12
-3,-2,6:18.12
0,-2,6:18.12
2,-2,6:18.12
-2,-1,6:18.12
0,-1,6:18.12
-1,0,6:17.14
0,0,6:17.14
1,0,6:17.14
2,0,6:18.12
4,0,6:18.12
-2,1,6:18.12
-1,1,6:18.12
1,1,6:18.12
2,1,6:18.12
-3,2,6:18.12
0,2,6:18.12
2,2,6:18.12
-4,-5,7:18.4
-2,-5,7:18.4
-2,-4,7:18.12
-1,-4,7:18.12
-4,-3,7:18.12
1,-2,7:18.12
-3,-1,7:18.12
2,-1,7:18.12
3,-1,7:18.12
-3,0,7:18.12
-1,0,7:17.14
0,0,7:18.12
0,1,7:18.12
1,3,7:18.12
-2,-4,8:18.12
-3,-3,8:18.12
-1,-2,8:18.12
1,-2,8:18.12
-1,-1,8:18.12
-1,0,8:17.14
-1,1,8:18.12
0,1,8:18.12
-1,2,8:18.12
-3,-2,9:18.12
-2,-1,9:18.12
-3,0,9:18.12
-1,0,9:17.14
0,0,9:18.12
2,0,9:18.12
-2,1,9:18.12
1,1,9:18.12
-1,2,9:18.12
-4,-1,10:18.12
-3,0,10:18.12
-1,0,10:17.14
1,0,10:18.12
-4,1,10:18.12
-1,1,10:18.12
0,1,10:18.12
1,1,10:18.12
-1,2,10:18.12
0,2,10:18.12
-2,-3,11:18.12
-1,-3,11:18.12
-2,-2,11:18.12
1,-2,11:18.12
-3,-1,11:18.12
-1,-1,11:18.12
-4,0,11:18.12
-3,0,11:18.12
-2,0,11:18.12
-1,0,11:17.14
2,1,11:18.12
-3,2,11:18.12
-1,2,11:18.12
-2,3,11:18.12
-1,3,11:18.12
0,3,11:18.12
-1,-3,12:18.12
0,-3,12:18.12
-3,-2,12:18.12
-4,0,12:18.12
-1,0,12:17.14
2,0,12:18.12
-1,2,12:18.12
-3,-2,13:18.12
-2,-1,13:18.12
-1,-1,13:18.12
-2,0,13:18.12
-1,0,13:18.12
1,0,13:18.12
-1,1,13:18.12
-1,2,13:18.12
0,2,13:18.12
-2,0,14:18.12
-1,0,14:18.12
-1,1,14:18.12
