[META]
version=2.0
spawnOnBlockType=2
spawnSunlight=True
spawnDarkness=True
spawnWater=False
spawnLava=False
underFill=False
randomRotation=True
dig=True
tree=False
branch=False
needsFoundation=True
rarity=100
collisionPercentage=20
spawnElevationMin=0
spawnElevationMax=200
spawnInBiome=Custom
[DATA]
2,-2,-3:17.12
1,0,-3:17.12
1,-3,-2:17.12
0,-2,-2:17.12
2,-2,-2:17.12
1,-1,-2:17.12
3,-1,-2:17.12
1,0,-2:17.12
1,-3,-1:17.12
2,-3,-1:17.12
0,-2,-1:17.12
1,-2,-1:17.12
2,-2,-1:17.12
1,-1,-1:17.12
2,-1,-1:17.12
3,-1,-1:17.12
1,0,-1:17.12
2,-3,0:17.12
0,-2,0:17.12
1,-2,0:17.12
2,-2,0:17.12
1,-1,0:17.12
2,-1,0:17.12
3,-1,0:17.12
1,0,0:17.12
1,-2,1:17.12
2,-2,1:17.12
1,-1,1:17.12
2,-1,1:17.12
5,-9,2:18.4
5,-7,2:18.12
4,-5,2:18.12
6,-5,2:18.12
8,-4,2:18.12
-5,-3,2:18.4
1,-2,2:17.12
2,-2,2:17.12
-5,-1,2:18.4
1,-1,2:17.12
2,-1,2:17.12
3,-1,2:18.12
-6,0,2:18.4
-6,1,2:18.4
-1,2,2:18.12
2,2,2:18.12
4,3,2:18.12
5,3,2:18.12
3,4,2:18.12
4,4,2:18.12
5,4,2:18.12
1,7,2:18.12
7,-9,3:18.4
5,-8,3:18.4
8,-7,3:18.4
1,-6,3:18.12
3,-6,3:18.12
5,-6,3:18.12
5,-5,3:18.12
8,-5,3:18.12
5,-3,3:18.12
-5,-2,3:18.4
1,-2,3:17.12
2,-2,3:17.12
4,-2,3:18.12
1,-1,3:17.12
2,-1,3:17.12
4,0,3:18.12
6,0,3:18.12
-5,1,3:18.4
-3,1,3:18.12
-1,1,3:18.12
6,4,3:18.12
-3,5,3:18.12
0,5,3:18.12
1,5,3:18.12
0,6,3:18.12
1,6,3:18.12
5,-10,4:18.4
5,-9,4:18.4
3,-7,4:18.12
7,-7,4:17.12
6,-6,4:17.12
4,-5,4:18.12
-6,-4,4:18.4
-4,-4,4:18.12
-2,-4,4:18.12
8,-4,4:18.12
-7,-3,4:18.4
9,-3,4:18.4
-5,-2,4:18.4
-3,-2,4:18.12
1,-2,4:17.12
2,-2,4:17.12
-4,-1,4:18.12
-1,-1,4:18.12
1,-1,4:17.12
3,-1,4:18.12
-7,0,4:18.4
-6,0,4:18.4
-2,0,4:18.12
-1,0,4:18.12
0,0,4:18.12
1,0,4:17.12
5,0,4:18.12
-9,1,4:18.4
6,1,4:18.12
-6,2,4:18.4
-4,2,4:18.12
-3,2,4:18.12
5,2,4:18.12
-3,3,4:18.12
-2,3,4:18.12
-1,3,4:18.12
4,3,4:18.12
1,4,4:17.12
3,4,4:18.12
1,5,4:17.12
3,5,4:18.12
4,7,4:18.12
4,-10,5:18.4
2,-9,5:18.4
3,-9,5:18.4
4,-9,5:18.4
3,-8,5:18.4
8,-8,5:18.4
0,-7,5:18.4
-4,-6,5:17.12
3,-6,5:18.12
9,-6,5:18.4
-7,-5,5:18.4
-3,-5,5:18.12
5,-5,5:17.12
7,-5,5:18.4
8,-5,5:18.4
-2,-4,5:18.12
0,-4,5:18.12
1,-4,5:18.12
4,-4,5:17.12
5,-4,5:18.12
-5,-3,5:18.4
2,-3,5:18.12
3,-3,5:17.12
0,-2,5:17.12
1,-2,5:17.12
6,-2,5:18.12
1,-1,5:17.12
5,-1,5:18.12
7,-1,5:18.4
-10,0,5:18.4
0,0,5:18.12
5,0,5:18.12
-5,1,5:18.4
0,1,5:18.12
1,1,5:17.12
-4,2,5:18.4
-3,2,5:18.12
1,2,5:17.12
4,2,5:18.12
6,2,5:18.12
-3,3,5:18.12
0,3,5:18.12
1,3,5:17.12
-6,4,5:18.4
-2,4,5:18.12
1,4,5:18.12
6,4,5:18.4
-3,5,5:18.4
0,5,5:18.4
3,5,5:18.4
4,5,5:18.4
-2,6,5:18.4
0,6,5:18.4
1,6,5:18.4
2,6,5:18.4
-1,7,5:18.4
0,7,5:18.4
3,7,5:18.4
0,8,5:18.4
2,8,5:18.4
4,-10,6:18.4
4,-8,6:18.4
5,-7,6:18.4
1,-6,6:18.12
2,-6,6:18.12
6,-6,6:18.12
-3,-5,6:17.12
-2,-5,6:18.12
3,-5,6:18.12
-2,-4,6:17.12
3,-4,6:18.12
-6,-3,6:18.4
-1,-3,6:17.12
6,-3,6:18.12
7,-3,6:18.4
-7,-2,6:18.4
-5,-2,6:18.4
1,-2,6:17.12
2,-2,6:18.12
6,-2,6:18.12
-3,-1,6:18.12
-2,-1,6:18.12
-1,-1,6:18.12
0,-1,6:18.12
1,-1,6:17.12
3,-1,6:18.12
-8,0,6:18.4
4,0,6:18.12
-10,1,6:18.4
-6,1,6:17.12
-4,1,6:18.4
-3,1,6:18.12
4,1,6:18.12
-5,2,6:18.4
-4,2,6:18.4
-1,2,6:18.12
1,2,6:18.12
-8,3,6:18.4
-5,3,6:18.4
2,3,6:18.12
3,3,6:18.12
-3,4,6:18.12
5,4,6:18.12
1,5,6:18.4
3,5,6:18.4
0,6,6:18.4
5,6,6:18.4
0,7,6:18.4
2,7,6:18.4
3,8,6:18.4
4,-10,7:18.4
8,-9,7:18.4
5,-8,7:18.4
6,-8,7:18.4
8,-8,7:18.4
-6,-6,7:18.4
-2,-6,7:18.12
5,-6,7:18.12
-5,-5,7:18.4
-4,-5,7:18.4
0,-5,7:18.12
4,-5,7:18.12
10,-5,7:18.4
-8,-4,7:18.4
-6,-4,7:18.4
0,-4,7:18.12
10,-4,7:18.4
-2,-3,7:18.12
-1,-3,7:18.12
-10,-2,7:18.4
-9,-2,7:18.4
-7,-2,7:18.4
-5,-2,7:18.4
0,-2,7:18.12
1,-2,7:17.12
5,-2,7:18.12
-9,-1,7:18.4
-6,-1,7:17.12
-5,-1,7:17.12
-4,-1,7:17.12
-3,-1,7:18.12
0,-1,7:17.12
1,-1,7:17.12
7,-1,7:18.4
8,-1,7:18.4
-9,0,7:18.4
-8,0,7:18.4
-4,0,7:17.12
-1,0,7:18.12
0,0,7:18.12
-5,1,7:17.12
0,1,7:18.12
-5,3,7:18.4
-4,3,7:18.4
-3,3,7:18.12
-2,3,7:18.12
1,3,7:18.12
-5,4,7:18.4
-4,4,7:18.4
-3,4,7:18.12
-2,4,7:18.12
6,4,7:18.4
-3,5,7:18.4
1,5,7:18.4
4,5,7:18.4
4,6,7:18.4
5,-8,8:18.4
6,-7,8:18.4
8,-7,8:18.4
-5,-6,8:18.4
0,-6,8:18.12
5,-6,8:18.12
-5,-5,8:18.4
-4,-5,8:18.4
0,-5,8:18.12
1,-5,8:18.12
5,-5,8:18.12
6,-5,8:18.12
-2,-4,8:18.12
1,-4,8:18.12
5,-4,8:18.12
-6,-3,8:18.4
-5,-3,8:18.4
1,-3,8:18.12
7,-3,8:18.4
-3,-2,8:18.12
-3,-1,8:17.12
-2,-1,8:17.12
-1,-1,8:17.12
1,-1,8:17.12
2,-1,8:17.12
6,-1,8:17.12
7,-1,8:17.12
0,0,8:18.12
-9,1,8:18.4
-8,1,8:18.4
-5,1,8:18.4
-4,1,8:18.4
-3,1,8:18.12
-1,1,8:18.12
1,1,8:18.12
2,1,8:18.12
-2,3,8:18.12
0,3,8:18.12
1,3,8:18.12
3,3,8:18.12
4,3,8:18.12
-5,4,8:18.4
4,4,8:18.12
5,4,8:18.12
2,5,8:18.4
6,5,8:18.4
3,6,8:18.4
-3,-8,9:18.4
-3,-7,9:18.4
-1,-7,9:18.4
4,-7,9:18.4
-3,-5,9:18.4
8,-5,9:18.4
-4,-4,9:18.4
-1,-4,9:18.4
0,-4,9:18.4
-8,-3,9:18.4
-10,-2,9:18.4
-3,-2,9:18.4
-1,-2,9:18.4
-8,-1,9:18.4
-5,-1,9:18.4
-4,-1,9:18.4
1,-1,9:17.12
3,-1,9:17.12
4,-1,9:17.12
5,-1,9:17.12
5,1,9:18.4
-1,2,9:18.4
1,2,9:18.4
7,3,9:18.4
-5,4,9:18.4
-4,4,9:18.4
2,4,9:18.4
5,4,9:18.4
5,6,9:18.4
1,-8,10:18.4
1,-7,10:18.4
-7,-5,10:18.4
-5,-5,10:18.4
4,-5,10:18.4
-2,-4,10:18.4
-1,-4,10:18.4
0,-4,10:18.4
7,-4,10:18.4
-5,-3,10:18.4
2,-3,10:18.4
6,-3,10:18.4
0,-2,10:17.12
-3,-1,10:18.4
1,-1,10:17.12
-2,0,10:18.4
-5,1,10:18.4
-4,1,10:18.4
2,1,10:18.4
-5,2,10:18.4
-2,2,10:18.4
3,2,10:18.4
-6,3,10:18.4
1,3,10:18.4
2,3,10:18.4
3,3,10:18.4
4,3,10:18.4
1,4,10:18.4
2,4,10:18.4
6,4,10:18.4
0,5,10:18.4
4,5,10:18.4
1,6,10:18.4
7,6,10:18.4
2,7,10:18.4
5,8,10:18.4
-1,-8,11:18.4
1,-8,11:18.4
-2,-7,11:18.4
-6,-6,11:18.4
-2,-6,11:17.12
-1,-6,11:18.4
-6,-5,11:18.4
-5,-5,11:17.12
-4,-5,11:17.12
-2,-5,11:17.12
2,-5,11:18.4
-5,-4,11:18.4
-3,-4,11:18.4
-2,-4,11:18.4
-1,-3,11:17.12
2,-3,11:18.4
0,-2,11:18.4
-5,-1,11:18.4
0,-1,11:18.4
1,-1,11:17.12
4,-1,11:18.4
-2,0,11:18.4
2,0,11:17.12
4,0,11:18.4
-8,1,11:18.4
2,1,11:18.4
9,3,11:18.4
4,4,11:18.4
4,5,11:18.4
0,6,11:18.4
2,8,11:18.4
0,-8,12:18.4
-3,-7,12:18.4
-4,-6,12:18.4
-2,-6,12:18.4
-3,-5,12:17.12
3,-5,12:18.4
-6,-4,12:18.4
-4,-4,12:18.4
-2,-4,12:17.12
-1,-4,12:18.4
0,-4,12:18.4
-5,-3,12:18.4
-3,-3,12:18.4
-2,-3,12:18.4
-3,-2,12:18.4
1,-2,12:17.12
-4,-1,12:18.4
0,-1,12:18.4
1,-1,12:17.12
-5,0,12:18.4
-2,0,12:18.4
-1,0,12:18.4
0,0,12:18.4
1,0,12:18.4
2,1,12:17.12
7,1,12:18.4
3,2,12:18.4
7,2,12:18.4
1,3,12:18.4
4,4,12:18.4
4,5,12:18.4
6,5,12:18.4
0,6,12:18.4
3,9,12:18.4
-6,-7,13:18.4
-6,-6,13:18.4
-7,-4,13:18.4
-4,-4,13:18.4
-2,-3,13:18.4
-1,-3,13:18.4
2,-3,13:17.12
-4,-2,13:18.4
-3,-2,13:18.4
3,-2,13:18.4
-2,-1,13:18.4
-1,-1,13:18.4
1,-1,13:17.12
2,0,13:18.4
5,0,13:18.4
2,1,13:18.4
3,1,13:18.4
4,1,13:18.4
6,1,13:18.4
1,2,13:18.4
2,2,13:18.4
3,2,13:17.12
2,3,13:18.4
3,3,13:17.12
4,3,13:18.4
5,3,13:18.4
9,3,13:18.4
-1,4,13:18.4
0,4,13:18.4
3,4,13:18.4
4,4,13:17.12
7,4,13:18.4
8,4,13:18.4
0,5,13:18.4
2,5,13:18.4
3,5,13:18.4
7,5,13:18.4
9,5,13:18.4
3,6,13:18.4
4,6,13:18.4
0,7,13:18.4
2,7,13:18.4
5,7,13:18.4
6,7,13:18.4
7,7,13:18.4
6,8,13:18.4
-4,-8,14:18.4
0,-8,14:18.4
0,-7,14:18.4
-4,-6,14:18.4
1,-6,14:18.4
-2,-5,14:18.4
3,-5,14:17.12
5,-5,14:18.4
-7,-4,14:18.4
-6,-4,14:18.4
-5,-4,14:18.4
-3,-4,14:18.4
-2,-4,14:18.4
0,-4,14:18.4
2,-4,14:17.12
-1,-3,14:18.4
1,-3,14:18.4
-5,-2,14:18.4
0,-2,14:17.12
1,-2,14:18.4
6,-2,14:18.4
-2,-1,14:18.4
0,-1,14:18.4
2,-1,14:17.12
6,-1,14:18.4
0,0,14:17.12
1,0,14:18.4
4,0,14:18.4
7,0,14:18.4
2,1,14:18.4
5,1,14:18.4
0,2,14:18.4
1,2,14:18.4
2,2,14:18.4
6,2,14:18.4
0,4,14:18.4
2,4,14:18.4
5,4,14:18.4
5,6,14:18.4
0,7,14:18.4
2,7,14:18.4
3,7,14:18.4
6,7,14:18.4
2,8,14:18.4
4,8,14:18.4
4,9,14:18.4
-1,-8,15:18.4
-2,-7,15:18.4
-3,-6,15:18.4
1,-6,15:18.4
2,-6,15:18.4
4,-6,15:18.4
-2,-5,15:18.4
-1,-5,15:18.4
-4,-4,15:18.4
1,-4,15:18.4
-3,-3,15:18.4
1,-3,15:18.4
2,-3,15:18.4
3,-3,15:18.4
-6,-2,15:18.4
-5,-2,15:18.4
-4,-2,15:18.4
-2,-2,15:18.4
0,-2,15:17.12
3,-2,15:18.4
4,-2,15:18.4
-2,-1,15:18.4
2,-1,15:17.12
3,-1,15:18.4
4,-1,15:18.4
-2,0,15:18.4
0,0,15:17.12
2,0,15:18.4
5,0,15:18.4
-4,1,15:18.4
-2,1,15:18.4
3,1,15:18.4
7,1,15:18.4
3,2,15:18.4
4,2,15:18.4
5,2,15:18.4
6,2,15:18.4
-1,3,15:18.4
0,3,15:18.4
1,3,15:18.4
4,3,15:18.4
7,4,15:18.4
7,6,15:18.4
8,6,15:18.4
3,8,15:18.4
4,8,15:18.4
-2,-7,16:18.4
-2,-6,16:18.4
-1,-6,16:18.4
-2,-5,16:18.4
-2,-4,16:18.4
-1,-4,16:18.4
0,-4,16:18.4
3,-4,16:18.4
6,-4,16:18.4
-5,-3,16:18.4
-2,-3,16:18.4
-1,-3,16:18.4
3,-3,16:18.4
5,-3,16:18.4
7,-3,16:18.4
-2,-2,16:18.4
-1,-2,16:17.12
2,-2,16:18.4
-5,-1,16:18.4
-3,-1,16:18.4
-2,-1,16:18.4
2,-1,16:17.12
3,-1,16:18.4
5,-1,16:18.4
6,-1,16:18.4
7,-1,16:18.4
-2,0,16:18.4
1,0,16:18.4
4,0,16:18.4
6,0,16:18.4
7,0,16:18.4
-2,1,16:18.4
0,1,16:17.12
2,1,16:18.4
4,1,16:18.4
7,1,16:18.4
-1,2,16:18.4
0,2,16:18.4
5,2,16:18.4
6,2,16:18.4
-1,3,16:18.4
2,3,16:18.4
3,3,16:18.4
6,3,16:18.4
0,4,16:18.4
1,4,16:18.4
2,4,16:18.4
6,4,16:18.4
1,5,16:18.4
8,5,16:18.4
3,6,16:18.4
6,6,16:18.4
-1,-7,17:18.4
-5,-6,17:18.4
-2,-6,17:18.4
1,-6,17:18.4
-5,-5,17:18.4
0,-5,17:18.4
2,-4,17:18.4
-5,-3,17:18.4
-4,-3,17:18.4
-1,-3,17:18.4
4,-3,17:18.4
6,-3,17:18.4
7,-3,17:18.4
-3,-2,17:18.4
-2,-2,17:17.12
2,-2,17:18.4
4,-2,17:18.4
5,-2,17:18.4
-7,-1,17:18.4
-2,-1,17:18.4
3,-1,17:18.4
7,-1,17:18.4
-3,0,17:18.4
-2,0,17:18.4
-1,0,17:18.4
3,0,17:17.12
7,0,17:18.4
-2,1,17:18.4
-1,1,17:17.12
7,1,17:18.4
-5,2,17:18.4
-1,2,17:18.4
5,2,17:18.4
-3,3,17:18.4
-2,3,17:18.4
6,3,17:18.4
0,4,17:18.4
2,4,17:18.4
3,4,17:18.4
4,4,17:18.4
2,6,17:18.4
2,7,17:18.4
-4,-7,18:18.4
-2,-7,18:18.4
-4,-6,18:18.4
-3,-6,18:18.4
0,-6,18:18.4
3,-6,18:18.4
-3,-5,18:18.4
-1,-5,18:18.4
0,-5,18:18.4
2,-5,18:18.4
3,-5,18:18.4
2,-4,18:18.4
5,-4,18:18.4
-2,-3,18:18.4
3,-3,18:18.4
6,-3,18:18.4
-2,-2,18:17.12
-1,-2,18:18.4
1,-2,18:18.4
2,-2,18:18.4
3,-2,18:18.4
5,-2,18:18.4
7,-2,18:18.4
-7,-1,18:18.4
-4,-1,18:18.4
-3,-1,18:18.4
-2,-1,18:18.4
-1,-1,18:18.4
2,-1,18:18.4
3,-1,18:18.4
4,-1,18:18.4
8,-1,18:18.4
-5,0,18:18.4
-4,0,18:18.4
-2,0,18:18.4
0,0,18:18.4
3,0,18:17.12
5,0,18:18.4
6,0,18:18.4
8,0,18:18.4
-5,1,18:18.4
-2,1,18:18.4
2,1,18:18.4
4,1,18:18.4
5,1,18:18.4
-2,2,18:18.4
-1,2,18:17.12
2,2,18:18.4
4,2,18:18.4
5,2,18:18.4
-3,3,18:18.4
-2,3,18:18.4
0,3,18:18.4
2,3,18:18.4
4,3,18:18.4
5,3,18:18.4
7,3,18:18.4
2,4,18:18.4
4,4,18:18.4
-2,-6,19:18.4
-1,-6,19:18.4
0,-6,19:18.4
-4,-5,19:18.4
-3,-5,19:18.4
1,-5,19:18.4
4,-5,19:18.4
-7,-4,19:18.4
2,-4,19:18.4
1,-3,19:18.4
5,-3,19:18.4
-6,-2,19:18.4
-3,-2,19:18.4
-2,-2,19:18.4
2,-2,19:18.4
3,-2,19:18.4
6,-2,19:18.4
-7,-1,19:18.4
-3,-1,19:18.4
-1,-1,19:18.4
1,-1,19:18.4
4,-1,19:18.4
5,-1,19:18.4
8,-1,19:18.4
-7,0,19:18.4
-3,0,19:18.4
-2,0,19:18.4
3,0,19:17.12
5,0,19:18.4
6,0,19:18.4
-5,1,19:18.4
0,1,19:18.4
6,1,19:18.4
7,1,19:18.4
-1,2,19:17.12
3,2,19:18.4
4,2,19:18.4
0,3,19:18.4
3,3,19:18.4
4,3,19:18.4
-2,-7,20:18.4
-2,-5,20:18.4
3,-5,20:18.4
2,-4,20:18.4
4,-4,20:18.4
6,-4,20:18.4
0,-2,20:18.4
1,-2,20:18.4
3,-2,20:18.4
-1,-1,20:18.4
0,-1,20:18.4
3,-1,20:18.4
-6,0,20:18.4
-4,0,20:18.4
-2,0,20:18.4
-1,0,20:18.4
0,0,20:18.4
5,0,20:18.4
-6,1,20:18.4
0,1,20:18.4
1,1,20:18.4
2,1,20:18.4
1,2,20:18.4
2,2,20:18.4
8,2,20:18.4
1,4,20:18.4
3,5,20:18.4
-3,-6,21:18.4
-2,-6,21:18.4
-2,-4,21:18.4
0,-4,21:18.4
-4,-3,21:18.4
0,-3,21:18.4
1,-3,21:18.4
3,-3,21:18.4
-4,-2,21:18.4
3,-2,21:18.4
2,0,21:18.4
3,0,21:18.4
0,1,21:18.4
3,1,21:18.4
4,1,21:18.4
6,1,21:18.4
0,3,21:18.4
3,5,21:18.4
4,5,21:18.4
-2,-5,22:18.4
0,-5,22:18.4
3,-4,22:18.4
-1,-3,22:18.4
4,-3,22:18.4
-1,-2,22:18.4
-2,-1,22:18.4
-4,0,22:18.4
-1,0,22:18.4
2,0,22:18.4
5,0,22:18.4
7,0,22:18.4
-1,1,22:18.4
0,1,22:18.4
3,1,22:18.4
5,1,22:18.4
3,2,22:18.4
-1,-3,23:18.4
-4,-2,23:18.4
-3,-2,23:18.4
-1,-2,23:18.4
0,-2,23:18.4
5,-2,23:18.4
6,-2,23:18.4
-3,0,23:18.4
0,0,23:18.4
3,0,23:18.4
5,3,23:18.4
4,1,24:18.4
