[META]
version=2.0
spawnOnBlockType=2
spawnSunlight=True
spawnDarkness=True
spawnWater=False
spawnLava=False
underFill=False
randomRotation=True
dig=True
tree=False
branch=False
needsFoundation=True
rarity=100
collisionPercentage=20
spawnElevationMin=0
spawnElevationMax=200
spawnInBiome=Custom
[DATA]
1,0,-3:17.13
1,0,-2:17.13
0,1,-2:17.13
1,-1,-1:17.13
1,0,-1:17.13
2,0,-1:17.13
0,1,-1:17.13
1,-1,0:17.13
1,0,0:17.13
2,0,0:17.13
0,1,0:17.13
1,0,1:17.13
0,-2,2:18.12
-1,-1,2:18.12
0,-1,2:18.12
1,-1,2:18.12
-1,0,2:18.12
1,0,2:17.13
-1,-4,3:18.12
1,-3,3:18.12
1,-2,3:18.12
2,-2,3:18.12
-2,-1,3:18.12
-1,-1,3:18.12
2,-1,3:18.12
1,0,3:17.13
-1,1,3:18.12
-2,2,3:18.12
-1,-5,4:18.12
-3,-4,4:18.12
-1,-4,4:18.12
-3,-3,4:18.12
-1,-3,4:18.12
0,-3,4:18.12
1,-2,4:18.12
-3,-1,4:18.12
0,-1,4:17.13
2,-1,4:18.12
-4,0,4:18.12
-2,0,4:18.12
1,0,4:17.13
2,0,4:18.12
-2,1,4:18.12
-1,1,4:18.12
1,1,4:18.12
2,1,4:18.12
4,1,4:18.12
-2,2,4:18.12
2,3,4:18.12
1,4,4:18.12
-1,-5,5:18.12
-4,-4,5:18.12
-2,-4,5:18.12
1,-4,5:18.12
2,-4,5:18.12
-5,-3,5:18.12
-2,-3,5:18.12
-1,-3,5:18.12
0,-2,5:18.12
1,-2,5:17.13
2,-2,5:18.12
-3,-1,5:18.12
-1,-1,5:17.13
-5,0,5:18.4
1,0,5:18.12
-5,1,5:18.4
-2,1,5:18.12
0,1,5:18.12
1,1,5:17.13
2,1,5:18.12
-1,2,5:18.12
1,2,5:18.12
2,2,5:18.12
-2,3,5:18.12
0,3,5:18.12
1,3,5:18.12
2,3,5:18.12
1,4,5:18.12
-1,-5,6:18.12
1,-5,6:18.12
-3,-4,6:18.12
-2,-4,6:18.12
0,-4,6:18.12
2,-4,6:18.12
-3,-3,6:18.12
1,-3,6:18.12
-4,-2,6:18.12
2,-2,6:18.12
3,-2,6:18.12
-3,-1,6:18.12
-2,-1,6:18.12
-1,-1,6:17.13
2,-1,6:18.12
-3,0,6:18.12
-2,0,6:18.12
0,0,6:18.12
3,0,6:18.12
-4,1,6:18.12
-3,1,6:18.12
-2,1,6:18.12
-1,1,6:18.12
1,1,6:17.13
2,1,6:18.12
4,1,6:18.12
5,1,6:18.12
-4,2,6:18.12
-3,2,6:18.12
1,2,6:18.12
2,2,6:18.12
3,2,6:18.12
-3,3,6:18.12
-2,-5,7:18.12
-1,-5,7:18.12
-3,-4,7:18.12
-1,-4,7:18.12
2,-3,7:18.12
3,-3,7:18.12
-3,-1,7:18.12
-2,-1,7:18.12
-1,-1,7:18.12
0,-1,7:18.12
2,-1,7:18.12
-2,0,7:18.12
2,0,7:18.12
3,0,7:18.12
-4,1,7:18.12
-3,1,7:18.12
-2,1,7:18.12
-1,1,7:18.12
0,1,7:18.12
1,1,7:17.13
2,1,7:18.12
-3,2,7:18.12
2,2,7:17.13
-2,3,7:18.12
-1,3,7:18.12
3,3,7:18.12
1,4,7:18.12
3,4,7:18.12
0,-4,8:18.12
-2,-3,8:18.12
1,-3,8:18.12
1,-2,8:18.12
0,-1,8:18.12
1,-1,8:18.12
3,-1,8:18.12
0,0,8:18.12
-2,1,8:18.12
0,1,8:18.12
4,1,8:18.12
0,2,8:18.12
1,2,8:18.12
2,3,8:18.12
-1,-3,9:18.4
-2,-1,9:18.4
0,-1,9:18.4
1,-1,9:18.4
4,-1,9:18.4
-2,1,9:18.4
0,1,9:18.4
1,1,9:18.12
2,1,9:18.12
-2,2,9:18.4
-1,2,9:18.4
0,2,9:18.4
-2,3,9:18.4
1,-2,10:18.4
-1,-1,10:18.4
0,-1,10:18.4
-1,1,10:18.4
