[META]
version=2.0
spawnOnBlockType=2
spawnSunlight=True
spawnDarkness=True
spawnWater=False
spawnLava=False
underFill=False
randomRotation=True
dig=True
tree=False
branch=False
needsFoundation=True
rarity=100
collisionPercentage=20
spawnElevationMin=0
spawnElevationMax=200
spawnInBiome=Custom
[DATA]
0,-1,-3:17.13
2,0,-3:17.13
-1,1,-3:17.13
0,-2,-2:17.13
0,-1,-2:17.13
-2,0,-2:17.13
1,0,-2:17.13
2,0,-2:17.13
-1,1,-2:17.13
2,1,-2:17.13
0,2,-2:17.13
0,-2,-1:17.13
0,-1,-1:17.13
-2,0,-1:17.13
-1,0,-1:17.13
0,0,-1:17.13
1,0,-1:17.13
2,0,-1:17.13
-1,1,-1:17.13
0,1,-1:17.13
2,1,-1:17.13
0,2,-1:17.13
0,-2,0:17.13
0,-1,0:17.13
-2,0,0:17.13
-1,0,0:17.13
0,0,0:17.13
1,0,0:17.13
2,0,0:17.13
-1,1,0:17.13
0,1,0:17.13
2,1,0:17.13
0,2,0:17.13
0,-1,1:17.13
-1,0,1:17.13
0,0,1:17.13
1,0,1:17.13
0,1,1:17.13
3,-4,2:18.12
-1,0,2:17.13
0,0,2:17.13
0,1,2:17.13
-7,5,2:18.12
-5,5,2:18.12
-8,6,2:18.12
-6,7,2:18.12
-2,7,2:18.12
3,-8,3:18.4
5,-7,3:18.4
2,-6,3:18.12
2,-5,3:18.12
3,-2,3:18.12
4,-2,3:18.12
0,0,3:17.13
-4,1,3:18.12
-3,1,3:18.12
0,1,3:17.13
-6,2,3:18.12
-3,2,3:18.12
4,2,3:18.12
-5,3,3:18.12
-5,4,3:18.12
-4,4,3:18.12
-3,4,3:18.12
6,4,3:18.12
-6,5,3:18.4
-5,5,3:18.12
-3,5,3:18.12
-3,6,3:18.12
-1,6,3:18.12
-2,7,3:18.4
3,-9,4:18.4
5,-8,4:18.4
3,-7,4:18.4
-1,-5,4:18.12
4,-5,4:18.12
4,-4,4:18.12
5,-4,4:18.12
1,-3,4:17.13
3,-3,4:18.12
1,-2,4:17.13
0,-1,4:17.13
0,0,4:17.13
0,1,4:17.13
-3,2,4:18.12
-4,3,4:18.12
7,3,4:18.4
-7,4,4:18.4
-4,4,4:18.12
-3,4,4:18.12
-2,4,4:18.12
1,4,4:18.12
4,4,4:18.12
6,4,4:18.12
-5,5,4:18.12
-3,5,4:18.12
6,5,4:18.12
7,5,4:18.4
-9,6,4:18.4
-7,6,4:18.4
-6,6,4:18.4
-5,6,4:17.13
-3,6,4:18.12
-1,6,4:18.12
6,6,4:18.4
-9,7,4:18.4
-7,7,4:18.4
4,7,4:18.4
-5,9,4:18.12
2,-7,5:18.4
0,-4,5:18.12
2,-4,5:17.13
3,-3,5:18.12
3,-2,5:18.12
-3,0,5:18.12
0,0,5:17.13
1,0,5:18.12
0,1,5:17.13
-4,2,5:18.12
-3,2,5:18.12
-1,2,5:17.13
0,2,5:18.12
3,2,5:18.12
-6,3,5:18.4
2,3,5:18.12
5,3,5:18.12
2,4,5:18.12
-4,5,5:17.13
-1,5,5:18.12
-7,6,5:18.4
-6,6,5:18.4
-9,7,5:18.4
5,7,5:18.4
6,7,5:18.4
-4,8,5:18.4
4,8,5:18.4
-4,9,5:18.4
5,-8,6:18.4
6,-8,6:18.4
2,-6,6:18.4
5,-6,6:18.4
1,-5,6:18.12
3,-5,6:17.13
7,-4,6:18.4
0,-2,6:18.12
1,-2,6:18.12
3,-2,6:18.12
4,-2,6:18.12
1,-1,6:18.12
5,-1,6:18.4
-5,0,6:18.12
0,0,6:17.13
1,0,6:18.12
-6,1,6:18.4
-1,1,6:18.12
0,1,6:17.13
-3,2,6:18.12
4,2,6:18.12
-3,3,6:18.12
-2,3,6:17.13
4,3,6:18.12
-7,4,6:18.4
-5,4,6:18.12
-3,4,6:17.13
-2,4,6:18.12
-1,4,6:18.12
1,4,6:18.12
3,4,6:18.12
5,4,6:18.4
0,5,6:18.12
2,5,6:18.12
7,5,6:18.4
-3,6,6:18.4
5,6,6:18.4
-5,7,6:18.4
-4,7,6:18.4
-7,8,6:18.4
-5,8,6:18.4
-4,8,6:18.4
-1,8,6:18.4
4,8,6:18.4
-5,9,6:18.4
3,-9,7:18.4
0,-7,7:18.4
1,-6,7:18.4
7,-6,7:18.4
2,-5,7:18.12
4,-5,7:18.12
2,-3,7:18.12
3,-3,7:18.12
-2,0,7:18.12
0,0,7:17.13
4,0,7:18.12
6,0,7:18.4
-1,1,7:18.12
1,1,7:18.12
2,1,7:18.12
3,1,7:18.12
5,1,7:18.4
0,2,7:18.12
1,2,7:17.13
5,2,7:18.4
-7,3,7:18.4
-3,3,7:18.12
0,3,7:18.12
2,3,7:18.12
4,3,7:18.12
-6,4,7:18.4
-5,4,7:18.4
-3,4,7:18.12
0,4,7:18.12
1,4,7:18.12
3,4,7:18.12
4,4,7:17.13
6,4,7:18.4
8,4,7:18.4
-1,5,7:18.12
0,5,7:18.12
4,5,7:18.12
-7,6,7:18.4
-6,6,7:18.4
-3,6,7:18.4
-1,6,7:18.4
0,6,7:18.4
1,6,7:18.4
3,6,7:18.4
4,7,7:18.4
-6,9,7:18.4
3,-9,8:18.4
3,-8,8:18.4
2,-5,8:18.12
5,-5,8:18.4
-2,-4,8:18.12
2,-3,8:18.12
4,-2,8:18.12
3,-1,8:18.12
-1,0,8:18.12
0,0,8:17.13
1,0,8:17.13
3,0,8:18.12
4,0,8:18.12
-3,1,8:18.12
-1,1,8:17.13
-2,2,8:18.12
2,2,8:18.12
4,2,8:18.12
0,3,8:18.12
1,3,8:18.12
2,3,8:17.13
3,3,8:17.13
6,3,8:18.4
-7,4,8:18.4
-6,4,8:18.4
-4,4,8:18.12
7,4,8:18.4
3,6,8:18.4
4,6,8:18.4
5,6,8:18.4
0,7,8:18.4
5,8,8:18.4
5,-7,9:18.4
1,-5,9:18.4
3,-5,9:18.4
4,-5,9:18.4
3,-3,9:18.4
-5,-2,9:18.4
-4,-2,9:18.4
-3,-2,9:18.4
-1,-1,9:17.13
0,0,9:17.13
1,0,9:17.13
-3,1,9:18.4
-5,2,9:18.4
-2,2,9:18.4
-1,2,9:17.13
0,2,9:18.4
-5,3,9:18.4
-3,3,9:18.4
-2,3,9:18.4
1,3,9:18.4
4,3,9:18.4
-3,4,9:18.4
-2,4,9:18.4
-1,4,9:18.4
1,4,9:18.4
3,4,9:18.4
1,5,9:18.4
2,5,9:18.4
-2,6,9:18.4
3,6,9:18.4
4,6,9:18.4
-3,7,9:18.4
4,8,9:18.4
0,-5,10:18.4
4,-5,10:18.4
-5,-4,10:18.4
-3,-4,10:18.4
3,-3,10:18.4
-6,-2,10:18.4
-3,-2,10:18.4
-4,-1,10:18.4
-1,-1,10:17.13
2,-1,10:18.4
0,0,10:17.13
2,0,10:17.13
-4,1,10:18.4
-3,1,10:18.4
3,1,10:18.4
-1,2,10:17.13
2,2,10:18.4
5,2,10:18.4
-4,3,10:18.4
-1,3,10:18.4
0,3,10:18.4
3,3,10:18.4
6,3,10:18.4
7,3,10:18.4
-4,4,10:18.4
-3,4,10:18.4
1,4,10:18.4
4,4,10:18.4
6,4,10:18.4
-2,5,10:18.4
2,5,10:18.4
2,6,10:18.4
3,6,10:18.4
-3,-6,11:18.4
0,-3,11:18.4
5,-3,11:18.4
-6,-2,11:18.4
-2,-2,11:17.13
1,-2,11:18.4
-5,-1,11:18.4
-2,-1,11:18.4
3,-1,11:18.4
5,-1,11:18.4
6,-1,11:18.4
0,0,11:17.13
2,0,11:17.13
2,1,11:18.4
-2,2,11:17.13
-3,3,11:18.4
5,3,11:18.4
-4,4,11:18.4
0,4,11:18.4
5,4,11:18.4
-4,5,11:18.4
-2,5,11:18.4
2,6,11:18.4
-2,-5,12:18.4
1,-5,12:18.4
-5,-4,12:18.4
-4,-4,12:18.4
2,-4,12:18.4
-6,-3,12:18.4
-5,-3,12:18.4
-2,-3,12:18.4
-2,-2,12:17.13
0,-2,12:18.4
-5,-1,12:18.4
-1,-1,12:18.4
0,-1,12:17.13
4,-1,12:18.4
-3,0,12:18.4
-2,0,12:18.4
-1,0,12:18.4
0,0,12:17.13
1,0,12:18.4
3,0,12:17.13
7,0,12:18.4
-5,1,12:18.4
-4,1,12:18.4
-3,1,12:18.4
0,1,12:18.4
3,1,12:18.4
-2,2,12:17.13
-1,2,12:18.4
3,2,12:18.4
4,2,12:18.4
5,2,12:18.4
-5,3,12:18.4
-3,3,12:18.4
0,3,12:18.4
1,3,12:18.4
2,3,12:18.4
3,3,12:18.4
4,3,12:18.4
-1,5,12:18.4
-3,7,12:18.4
4,-4,13:18.12
6,-4,13:18.4
-4,-3,13:18.12
-3,-3,13:17.13
4,-3,13:18.12
6,-3,13:18.4
-6,-2,13:18.4
-4,-2,13:18.12
-2,-2,13:18.12
0,-2,13:17.13
3,-2,13:18.12
4,-2,13:18.12
6,-1,13:18.4
0,0,13:17.13
3,0,13:17.13
7,0,13:18.4
8,0,13:18.4
-5,1,13:18.4
-2,1,13:18.12
1,1,13:18.12
4,1,13:18.12
3,2,13:18.12
5,2,13:18.4
7,2,13:18.4
-4,3,13:18.12
-2,3,13:17.13
-5,4,13:18.4
-4,4,13:18.12
0,4,13:18.12
-2,5,13:18.4
1,5,13:18.4
-5,6,13:18.4
-2,7,13:18.4
0,7,13:18.4
-2,-5,14:18.4
-2,-4,14:18.12
5,-4,14:18.4
-3,-3,14:17.13
0,-3,14:17.13
5,-3,14:18.4
-4,-2,14:18.12
-2,-2,14:18.12
1,-2,14:18.12
2,-2,14:18.12
3,-2,14:18.12
-4,-1,14:18.12
-3,-1,14:18.12
-2,-1,14:18.12
8,-1,14:18.4
9,-1,14:18.4
0,0,14:17.13
4,0,14:17.13
8,0,14:18.4
-2,1,14:18.12
-2,2,14:18.12
-1,2,14:18.12
4,3,14:18.12
-3,4,14:17.13
2,4,14:18.12
3,-5,15:18.12
5,-5,15:18.12
6,-5,15:18.4
2,-4,15:18.12
5,-4,15:18.12
8,-4,15:18.4
-5,-3,15:18.4
-4,-3,15:18.12
-2,-3,15:18.12
0,-3,15:17.13
1,-3,15:18.12
3,-3,15:18.12
5,-3,15:18.12
-3,-2,15:18.12
3,-2,15:18.12
9,-2,15:18.4
-3,-1,15:18.12
1,-1,15:17.13
4,-1,15:18.12
5,-1,15:17.13
-4,0,15:18.12
-1,0,15:18.12
0,0,15:17.13
3,0,15:18.12
5,0,15:17.13
9,0,15:18.4
-3,1,15:18.12
6,1,15:17.13
-4,2,15:18.12
-2,2,15:18.12
2,2,15:18.12
5,2,15:18.12
7,2,15:18.4
8,2,15:18.4
-1,3,15:18.12
2,3,15:18.12
6,3,15:18.4
7,3,15:18.4
-5,4,15:18.4
-3,4,15:18.12
-2,4,15:18.12
-4,5,15:18.12
-2,-4,16:18.12
0,-4,16:17.13
5,-4,16:18.12
-1,-3,16:18.12
-2,-2,16:18.12
-1,-2,16:18.12
1,-1,16:17.13
6,-1,16:18.4
-1,0,16:18.12
0,0,16:17.13
4,0,16:18.12
0,2,16:18.12
1,2,16:18.12
3,2,16:18.12
-5,3,16:18.4
-2,3,16:18.12
-1,3,16:18.12
0,3,16:18.12
2,3,16:18.4
4,3,16:18.12
5,3,16:18.12
-1,4,16:18.12
2,4,16:18.4
-2,6,16:18.4
-1,-5,17:18.12
-2,-4,17:18.12
1,-4,17:18.12
4,-4,17:18.12
6,-4,17:18.4
-2,-3,17:18.12
-1,-2,17:18.12
1,-2,17:17.13
3,-2,17:18.12
-3,-1,17:18.12
1,-1,17:18.12
3,-1,17:18.12
5,-1,17:18.12
8,-1,17:18.4
-3,0,17:18.12
0,0,17:17.13
4,0,17:18.12
6,0,17:18.4
7,0,17:18.4
0,1,17:18.12
4,1,17:18.12
8,1,17:18.4
-3,2,17:18.12
-2,2,17:18.12
-1,2,17:18.12
0,2,17:18.12
5,2,17:18.12
-1,4,17:18.12
3,4,17:18.4
-2,5,17:18.12
-1,5,17:18.12
0,5,17:18.12
-1,-6,18:18.12
2,-4,18:18.12
2,-3,18:18.12
1,-2,18:17.13
2,-2,18:18.12
3,-2,18:18.12
-3,-1,18:18.12
-2,-1,18:18.12
0,-1,18:18.12
1,0,18:18.12
5,0,18:18.12
6,0,18:18.4
0,1,18:17.13
3,1,18:18.12
-4,2,18:18.12
-2,2,18:18.12
-1,2,18:18.12
0,2,18:18.12
2,2,18:18.12
3,2,18:18.12
-1,4,18:18.4
2,4,18:18.4
3,4,18:18.4
-2,5,18:18.12
1,5,18:18.4
-1,6,18:18.4
-1,-5,19:18.12
1,-5,19:18.12
2,-5,19:18.12
-4,-4,19:18.12
-1,-4,19:18.12
2,-4,19:18.12
3,-3,19:18.12
-4,-2,19:18.12
-3,-2,19:18.12
-2,-2,19:18.12
-1,-2,19:18.12
1,-2,19:17.13
3,-2,19:18.12
-4,-1,19:18.12
-3,-1,19:18.12
-1,-1,19:18.12
0,-1,19:18.12
1,-1,19:18.12
0,0,19:18.12
2,0,19:18.12
0,1,19:17.13
1,1,19:17.13
5,1,19:18.12
-4,2,19:18.12
-3,2,19:18.12
1,2,19:18.12
5,5,19:18.4
-3,-6,20:18.12
-1,-5,20:18.12
1,-4,20:18.12
2,-3,20:18.4
3,-3,20:18.12
4,-3,20:18.12
-3,-2,20:18.12
-2,-2,20:18.12
1,-2,20:18.12
-5,-1,20:18.4
-4,-1,20:18.12
-1,-1,20:18.12
0,-1,20:18.12
3,-1,20:18.12
4,-1,20:18.12
5,-1,20:18.12
-5,0,20:18.4
-3,0,20:18.12
-1,0,20:18.12
0,0,20:18.12
1,0,20:18.12
2,0,20:18.12
5,0,20:18.12
6,0,20:18.4
-4,1,20:18.12
-3,1,20:18.12
-1,1,20:18.12
3,1,20:18.12
-4,2,20:18.12
1,2,20:18.12
3,2,20:18.12
5,2,20:18.12
-2,3,20:18.12
0,3,20:18.12
1,3,20:18.12
2,3,20:18.4
4,3,20:18.4
5,3,20:18.4
-5,4,20:18.4
-2,4,20:18.4
-1,4,20:18.12
0,4,20:18.12
1,4,20:18.4
2,4,20:18.4
4,4,20:18.4
-1,5,20:18.12
0,5,20:18.4
-1,6,20:18.4
0,-5,21:18.12
-3,-4,21:18.12
-2,-4,21:18.12
-1,-4,21:18.12
0,-3,21:18.12
-3,-2,21:18.12
0,-2,21:18.12
3,-2,21:18.12
4,-2,21:18.12
-2,-1,21:18.12
-1,-1,21:18.12
0,-1,21:18.12
1,-1,21:18.12
-3,0,21:18.12
3,0,21:18.12
-3,1,21:18.12
-1,1,21:18.12
0,1,21:18.12
1,1,21:18.12
-5,2,21:18.4
-4,2,21:18.12
-2,2,21:18.12
0,2,21:18.12
-1,3,21:18.12
2,3,21:18.4
-3,4,21:18.12
1,4,21:18.4
-2,5,21:18.12
-1,6,21:18.4
0,6,21:18.4
-1,-5,22:18.12
-4,-4,22:18.4
-1,-4,22:18.12
-1,-2,22:18.12
2,-2,22:18.12
-1,0,22:18.12
4,0,22:18.12
5,0,22:18.12
-2,1,22:18.12
-1,1,22:18.12
1,2,22:18.12
2,2,22:18.12
3,2,22:18.12
5,2,22:18.12
0,3,22:18.12
-1,4,22:18.12
0,4,22:18.12
1,5,22:18.4
2,6,22:18.4
0,-5,23:18.12
-2,-3,23:18.12
-1,-3,23:18.12
1,-3,23:18.12
5,-3,23:18.12
-2,-2,23:18.12
-2,-1,23:18.12
-1,-1,23:18.12
1,-1,23:18.12
2,-1,23:18.12
-2,0,23:18.12
-1,0,23:18.12
5,0,23:18.12
2,1,23:18.12
5,1,23:18.12
1,2,23:18.12
3,2,23:18.12
3,3,23:18.4
1,-4,24:18.12
-1,-3,24:18.12
0,-3,24:18.12
-2,-2,24:18.12
-1,-2,24:18.12
-1,-1,24:18.12
-1,0,24:18.12
3,1,24:18.12
1,2,24:18.12
2,2,24:18.12
-1,3,24:18.4
-1,4,24:18.4
2,4,24:18.4
2,-4,25:18.12
3,-3,25:18.12
-1,-2,25:18.12
3,-2,25:18.12
4,-1,25:18.12
2,-2,26:18.12
3,-2,26:18.12
4,-2,26:18.12
2,-1,26:18.12
2,-3,23:85.0
-1,2,22:85.0
2,-3,22:85.0
2,2,21:85.0
-1,2,21:85.0
2,-2,21:85.0
2,-3,21:85.0
-1,-3,21:85.0
2,2,20:85.0
0,2,20:85.0
-1,2,20:85.0
2,1,20:85.0
0,1,20:85.0
2,-2,20:85.0
0,-2,20:85.0
-1,-2,20:85.0
-1,-3,20:85.0
2,1,19:85.0
2,-2,19:85.0
0,-2,19:85.0
