[META]
version=2.0
spawnOnBlockType=2
spawnSunlight=True
spawnDarkness=True
spawnWater=False
spawnLava=False
underFill=False
randomRotation=True
dig=True
tree=False
branch=False
needsFoundation=True
rarity=100
collisionPercentage=20
spawnElevationMin=0
spawnElevationMax=200
spawnInBiome=Custom
[DATA]
-1,0,-3:17.13
0,-1,-2:17.13
-1,0,-2:17.13
0,-1,-1:17.13
-2,0,-1:17.13
-1,0,-1:17.13
0,0,-1:17.13
0,-1,0:17.13
-2,0,0:17.13
-1,0,0:17.13
0,0,0:17.13
0,-1,1:17.13
-1,0,1:17.13
0,0,1:17.13
-1,0,2:17.13
0,0,2:17.13
1,1,2:17.13
2,2,2:18.14
3,2,2:18.14
1,3,2:18.14
2,3,2:18.14
4,3,2:18.14
3,6,2:18.6
0,0,3:17.13
5,0,3:18.14
0,1,3:18.14
1,1,3:17.13
1,2,3:18.14
6,4,3:18.6
3,5,3:18.14
6,5,3:18.6
3,6,3:18.6
4,6,3:18.6
0,-4,4:18.14
0,-3,4:18.14
-3,-1,4:18.14
0,-1,4:17.13
3,0,4:18.14
5,0,4:18.14
-5,1,4:18.14
-2,1,4:18.14
-1,1,4:17.13
-4,2,4:18.14
-3,2,4:18.14
2,2,4:17.13
5,2,4:18.14
6,2,4:18.6
2,3,4:18.14
6,3,4:18.6
-1,4,4:18.14
0,4,4:18.14
6,4,4:18.6
7,4,4:18.6
2,5,4:18.14
5,5,4:18.14
1,6,4:18.14
3,6,4:18.6
-1,-7,5:18.6
0,-7,5:18.6
1,-7,5:18.6
3,-5,5:18.14
0,-4,5:18.14
1,-4,5:18.14
-2,-3,5:18.14
3,-3,5:18.14
0,-2,5:17.13
1,-2,5:18.14
-3,-1,5:18.14
2,-1,5:18.14
3,-1,5:18.14
4,-1,5:18.14
1,0,5:18.14
3,0,5:18.14
6,0,5:18.6
-5,1,5:18.14
-1,1,5:17.13
1,1,5:18.14
2,1,5:18.14
3,1,5:18.14
4,1,5:18.14
5,1,5:18.14
7,1,5:18.6
0,2,5:18.14
1,2,5:18.14
3,2,5:18.14
-3,3,5:18.14
0,3,5:18.14
1,3,5:18.14
3,3,5:17.13
5,3,5:18.14
7,3,5:18.6
-4,4,5:18.14
-1,4,5:18.14
0,4,5:18.14
1,4,5:18.14
0,5,5:18.14
5,5,5:18.14
6,5,5:18.6
5,6,5:18.6
6,6,5:18.6
0,-6,6:18.6
-2,-5,6:18.14
-1,-5,6:18.14
2,-5,6:18.14
0,-4,6:18.14
1,-4,6:18.14
-2,-3,6:18.14
1,-3,6:18.14
-5,-2,6:18.14
0,-2,6:17.13
2,-2,6:18.14
-2,-1,6:18.14
0,-1,6:18.14
2,-1,6:18.14
4,-1,6:18.14
-2,0,6:18.14
1,0,6:18.14
2,0,6:18.14
4,0,6:18.14
-5,1,6:18.14
-4,1,6:18.14
-3,1,6:18.14
-2,1,6:18.14
-1,1,6:18.14
0,1,6:18.14
1,1,6:18.14
3,1,6:18.14
-2,2,6:17.13
0,2,6:18.14
1,2,6:18.14
3,2,6:18.14
4,2,6:18.14
-5,3,6:18.14
1,3,6:18.14
5,3,6:18.14
6,3,6:18.6
7,3,6:18.6
-3,4,6:18.14
2,4,6:18.14
3,4,6:18.14
1,5,6:18.14
6,5,6:18.6
6,6,6:18.6
0,-7,7:18.6
-1,-4,7:18.14
1,-4,7:18.14
4,-4,7:18.14
0,-3,7:17.13
1,-3,7:18.14
-2,-2,7:18.14
-1,-2,7:18.14
0,-1,7:18.14
1,-1,7:18.14
3,-1,7:18.14
4,-1,7:18.14
-6,0,7:18.6
-5,0,7:18.14
-3,0,7:18.14
-2,0,7:18.14
0,0,7:18.14
2,0,7:18.14
3,0,7:18.14
-3,1,7:18.14
-2,1,7:18.14
1,1,7:18.14
3,1,7:18.14
-2,2,7:17.13
-6,3,7:18.6
-3,3,7:18.14
2,3,7:18.14
4,3,7:18.14
6,3,7:18.6
-3,4,7:18.14
1,4,7:18.14
6,4,7:18.6
5,5,7:18.14
2,6,7:18.6
3,6,7:18.6
0,-8,8:18.6
-3,-7,8:18.6
-2,-7,8:18.6
-1,-7,8:18.6
0,-7,8:18.6
2,-7,8:18.6
3,-7,8:18.6
-4,-6,8:18.6
-2,-6,8:18.6
0,-6,8:18.6
-3,-5,8:18.14
0,-5,8:18.14
4,-5,8:18.14
-3,-4,8:18.14
-2,-4,8:18.14
0,-4,8:17.13
3,-4,8:18.14
4,-4,8:18.14
-5,-3,8:18.14
-4,-3,8:18.14
0,-3,8:18.14
1,-3,8:18.14
4,-3,8:18.14
-4,-2,8:18.14
0,-2,8:18.14
2,-2,8:18.14
4,-2,8:18.14
-2,-1,8:18.14
-1,-1,8:18.14
0,-1,8:18.14
1,-1,8:18.14
2,-1,8:18.14
3,-1,8:18.14
-7,0,8:18.6
-6,0,8:18.6
-2,0,8:18.14
-1,0,8:18.14
1,0,8:18.14
2,0,8:18.14
-6,1,8:18.6
-5,1,8:18.14
-3,1,8:17.13
3,1,8:18.14
-7,2,8:18.6
-5,2,8:18.14
-2,2,8:18.14
-1,2,8:18.14
3,2,8:18.14
-2,3,8:17.13
-1,3,8:18.14
1,3,8:18.14
3,3,8:18.14
-2,4,8:18.14
1,4,8:18.14
-1,5,8:18.14
1,5,8:18.14
4,5,8:18.6
5,5,8:18.6
-1,-8,9:18.6
0,-7,9:18.6
3,-7,9:18.6
-1,-4,9:18.6
0,-4,9:18.6
1,-4,9:18.6
3,-4,9:18.6
4,-4,9:18.6
-3,-3,9:18.6
-2,-3,9:18.6
0,-3,9:18.6
3,-3,9:18.6
4,-3,9:18.6
-5,-2,9:18.6
-3,-2,9:18.6
-2,-2,9:18.6
-1,-2,9:18.6
1,-2,9:18.6
4,-2,9:18.6
0,-1,9:18.6
1,-1,9:18.6
4,-1,9:18.6
-2,0,9:18.6
-1,0,9:18.6
0,0,9:18.6
1,0,9:18.6
2,0,9:18.6
4,0,9:18.6
5,0,9:18.6
-6,1,9:18.6
-5,1,9:18.6
-2,1,9:18.6
1,1,9:18.6
3,1,9:18.6
-3,2,9:18.6
-2,2,9:18.6
0,2,9:18.6
1,2,9:18.6
0,3,9:18.6
1,3,9:18.6
4,3,9:18.6
2,4,9:18.6
3,4,9:18.6
-2,-7,10:18.14
0,-7,10:18.14
-3,-6,10:18.6
0,-5,10:18.6
-2,-4,10:18.6
-1,-4,10:18.6
1,-4,10:18.6
4,-4,10:18.6
-2,-3,10:18.6
0,-3,10:18.6
4,-3,10:18.6
-2,-2,10:18.6
-3,-1,10:18.6
-2,-1,10:18.6
1,-1,10:18.6
2,-1,10:18.6
-2,0,10:18.6
-1,0,10:18.6
0,0,10:18.6
0,1,10:18.6
-3,2,10:18.6
0,3,10:18.6
-1,4,10:18.6
1,4,10:18.6
0,-7,11:18.14
1,-4,11:18.6
-3,-3,11:18.6
2,-3,11:18.6
3,-3,11:18.6
-1,-1,11:18.6
1,-1,11:18.6
-4,0,11:18.6
2,0,11:18.6
-1,1,11:18.6
4,1,11:18.6
1,2,11:18.6
1,4,11:18.6
0,-3,12:18.6
2,-1,12:18.6
-2,0,12:18.6
1,0,12:18.6
2,1,12:18.6
4,1,12:18.6
3,2,12:18.6
1,2,13:18.6
