[META]
version=2.0
spawnOnBlockType=2
spawnSunlight=True
spawnDarkness=True
spawnWater=False
spawnLava=False
underFill=False
randomRotation=True
dig=True
tree=False
branch=False
needsFoundation=True
rarity=100
collisionPercentage=20
spawnElevationMin=0
spawnElevationMax=200
spawnInBiome=Custom
[DATA]
0,0,-3:17.13
1,-1,-2:17.13
0,0,-2:17.13
1,-1,-1:17.13
0,0,-1:17.13
0,1,-1:17.13
1,-1,0:17.13
0,0,0:17.13
0,1,0:17.13
-2,-1,1:18.14
0,0,1:17.13
1,0,1:18.14
0,1,1:18.14
0,2,1:18.14
-2,-3,2:18.14
-1,-3,2:18.14
0,-3,2:18.14
-1,-2,2:18.14
1,-2,2:18.14
-3,-1,2:18.14
-2,-1,2:18.14
-1,-1,2:18.14
0,-1,2:18.14
-3,0,2:18.14
-1,0,2:18.14
0,0,2:17.13
2,0,2:18.14
-3,1,2:18.14
-2,1,2:18.14
1,1,2:18.14
-1,2,2:18.14
-1,3,2:18.14
0,3,2:18.14
1,3,2:18.14
-4,-2,3:18.14
-3,-2,3:18.14
-1,-2,3:18.14
2,-2,3:18.14
-1,-1,3:17.13
0,-1,3:18.14
1,-1,3:18.14
-3,0,3:18.14
-2,0,3:18.14
1,0,3:18.14
2,0,3:18.14
3,0,3:18.14
-3,1,3:18.14
-2,1,3:18.14
0,1,3:17.13
1,1,3:18.14
2,1,3:18.14
-1,2,3:18.14
0,2,3:18.14
-1,3,3:18.14
0,3,3:18.14
1,3,3:18.14
2,3,3:18.14
-1,-4,4:18.14
-1,-3,4:18.14
1,-3,4:18.14
-3,-2,4:18.14
-2,-2,4:18.14
-1,-2,4:18.14
0,-2,4:18.14
1,-2,4:18.14
2,-2,4:18.14
-3,-1,4:18.14
-1,-1,4:17.13
1,-1,4:18.14
2,-1,4:18.14
3,-1,4:18.14
-2,0,4:18.14
1,0,4:18.14
-3,1,4:18.14
-2,1,4:18.14
-1,1,4:18.14
0,1,4:18.14
1,1,4:18.14
2,1,4:18.14
3,1,4:18.14
-3,2,4:18.14
-1,2,4:18.14
0,2,4:17.13
1,2,4:18.14
3,2,4:18.14
-2,3,4:18.14
-1,3,4:18.14
0,3,4:18.14
-1,4,4:18.14
0,4,4:18.14
-2,-4,5:18.14
-2,-3,5:18.14
-1,-2,5:18.14
0,-1,5:18.14
2,-1,5:18.14
-3,0,5:18.14
-1,0,5:18.14
-2,1,5:18.14
-1,2,5:18.14
0,2,5:18.14
1,2,5:18.14
-2,3,5:18.14
1,3,5:18.14
0,4,5:18.14
0,-1,6:18.14
1,-1,6:18.14
0,0,6:18.14
1,0,6:18.14
2,0,6:18.14
-1,1,6:18.14
0,1,6:18.14
1,1,6:18.14
2,1,6:18.14
2,2,6:18.14
-2,3,6:18.14
2,3,6:18.14
0,0,7:18.14
1,1,7:18.14
