[META]
version=2.0
spawnOnBlockType=2
spawnSunlight=True
spawnDarkness=True
spawnWater=False
spawnLava=False
underFill=False
randomRotation=True
dig=True
tree=False
branch=False
needsFoundation=True
rarity=100
collisionPercentage=20
spawnElevationMin=0
spawnElevationMax=200
spawnInBiome=Custom
[DATA]
-1,1,0:17.12
-1,1,1:17.12
1,-4,2:18.12
-5,-3,2:18.12
-4,-3,2:18.12
-1,-3,2:18.12
1,-3,2:18.12
3,-3,2:18.12
2,-2,2:18.12
5,-2,2:18.4
-6,-1,2:18.12
-5,-1,2:18.12
-4,-1,2:18.12
3,-1,2:18.12
4,-1,2:18.12
-2,0,2:18.12
-1,0,2:18.12
0,0,2:18.12
1,0,2:18.12
2,0,2:18.12
-5,1,2:18.12
-1,1,2:17.12
-5,4,2:18.12
-4,4,2:18.12
-5,5,2:18.12
0,5,2:18.12
-2,6,2:18.12
-2,7,2:18.12
-1,7,2:18.12
0,-7,3:18.12
1,-7,3:18.12
-1,-6,3:18.12
2,-6,3:18.12
-1,-5,3:18.12
-3,-4,3:18.12
-2,-4,3:18.12
1,-4,3:18.12
4,-4,3:18.4
-2,-3,3:18.12
-5,-2,3:18.12
-4,-2,3:18.12
-3,-2,3:18.12
-2,-2,3:18.12
-1,-2,3:18.12
4,-2,3:18.12
-7,-1,3:18.12
-2,-1,3:18.12
-1,-1,3:18.12
0,-1,3:18.12
1,-1,3:18.12
2,-1,3:18.12
-6,0,3:18.12
-3,0,3:18.12
-1,0,3:17.12
0,0,3:18.12
1,0,3:18.12
2,0,3:18.12
4,0,3:18.12
5,0,3:18.12
-7,1,3:18.12
-3,1,3:18.12
-2,1,3:18.12
-1,1,3:17.12
0,1,3:18.12
1,1,3:18.12
-3,2,3:18.12
-2,2,3:17.12
0,2,3:18.12
1,2,3:18.12
-7,3,3:18.12
-3,3,3:18.12
-1,3,3:18.12
2,3,3:18.12
-6,4,3:18.12
-3,4,3:18.12
-2,4,3:18.12
3,4,3:18.12
-2,5,3:18.12
-3,6,3:18.12
-2,6,3:18.12
0,6,3:18.12
1,6,3:18.12
-2,7,3:18.12
-1,7,3:18.12
2,-7,4:18.4
-3,-6,4:18.12
-2,-6,4:18.12
-1,-6,4:18.12
1,-6,4:18.12
-5,-5,4:18.12
-1,-5,4:18.12
0,-5,4:18.12
4,-5,4:18.4
-6,-4,4:18.12
-2,-4,4:18.12
1,-4,4:18.12
2,-4,4:18.12
3,-4,4:18.12
-5,-3,4:18.12
-3,-3,4:18.12
-2,-3,4:18.12
-1,-3,4:18.12
3,-3,4:18.12
4,-3,4:18.4
-5,-2,4:18.12
-3,-2,4:18.12
-2,-2,4:18.12
-1,-2,4:18.12
0,-2,4:18.12
1,-2,4:18.12
3,-2,4:18.12
5,-2,4:18.4
-5,-1,4:18.12
-4,-1,4:18.12
-2,-1,4:18.12
-1,-1,4:17.12
1,-1,4:18.12
2,-1,4:18.12
3,-1,4:18.12
-7,0,4:18.12
-3,0,4:18.12
-1,0,4:18.12
2,0,4:18.12
3,0,4:18.12
5,0,4:18.12
-8,1,4:18.12
-7,1,4:18.12
-5,1,4:18.12
-2,1,4:18.12
-1,1,4:17.12
0,1,4:18.12
2,1,4:18.12
6,1,4:18.4
-6,2,4:18.12
-3,2,4:18.12
-2,2,4:18.12
-1,2,4:18.12
0,2,4:17.12
1,2,4:18.12
5,2,4:18.12
-5,3,4:18.12
-3,3,4:17.12
-2,3,4:18.12
-1,3,4:18.12
1,3,4:18.12
2,3,4:18.12
4,3,4:18.12
-6,4,4:18.12
-5,4,4:18.12
-4,4,4:18.12
-1,4,4:18.12
1,4,4:18.12
2,4,4:18.12
-6,5,4:18.12
-5,5,4:18.12
-4,5,4:18.12
-2,5,4:18.12
-4,6,4:18.12
-2,7,4:18.12
1,7,4:18.12
-2,8,4:18.12
-3,-6,5:18.12
1,-6,5:18.12
3,-6,5:18.4
-2,-5,5:18.12
-1,-5,5:18.12
1,-5,5:18.12
3,-5,5:18.12
-7,-4,5:18.12
-5,-4,5:18.12
-4,-4,5:18.12
-3,-4,5:18.12
-2,-4,5:18.12
0,-4,5:18.12
-4,-3,5:18.12
-3,-3,5:18.12
-2,-3,5:18.12
-1,-3,5:18.12
0,-3,5:18.12
-8,-2,5:18.4
-7,-2,5:18.12
-6,-2,5:18.12
-5,-2,5:18.12
-4,-2,5:18.12
-2,-2,5:17.12
0,-2,5:18.12
1,-2,5:18.12
2,-2,5:18.12
-7,-1,5:18.12
-6,-1,5:18.12
-4,-1,5:18.12
-3,-1,5:18.12
-2,-1,5:18.12
-1,-1,5:18.12
0,-1,5:18.12
1,-1,5:18.12
2,-1,5:18.12
6,-1,5:18.4
-5,0,5:18.12
-4,0,5:18.12
-3,0,5:18.12
-1,0,5:18.12
0,0,5:18.12
1,0,5:18.12
3,0,5:18.12
-8,1,5:18.12
-7,1,5:18.12
-6,1,5:18.12
-5,1,5:18.12
-4,1,5:18.12
-3,1,5:18.12
-2,1,5:18.12
-1,1,5:17.12
0,1,5:18.12
1,1,5:18.12
2,1,5:18.12
3,1,5:18.12
-4,2,5:18.12
-3,2,5:18.12
-2,2,5:18.12
-1,2,5:18.12
0,2,5:18.12
1,2,5:18.12
2,2,5:18.12
-7,3,5:18.12
-4,3,5:18.12
-3,3,5:18.12
-2,3,5:18.12
-1,3,5:18.12
1,3,5:17.12
2,3,5:18.12
-5,4,5:18.12
-4,4,5:17.12
-3,4,5:18.12
-2,4,5:18.12
-1,4,5:18.12
0,4,5:18.12
1,4,5:18.12
2,4,5:18.12
4,4,5:18.12
-6,5,5:18.12
-4,5,5:18.12
-3,5,5:18.12
-2,5,5:18.12
-1,5,5:18.12
0,5,5:18.12
2,5,5:18.12
-3,6,5:18.12
-2,6,5:18.12
-1,6,5:18.12
0,6,5:18.12
1,6,5:18.12
2,6,5:18.12
3,6,5:18.12
4,6,5:18.12
-5,7,5:18.12
-4,7,5:18.12
-3,7,5:18.12
0,7,5:18.12
2,7,5:18.12
-2,8,5:18.12
-1,8,5:18.12
0,8,5:18.12
-2,9,5:18.4
-3,-6,6:18.12
-2,-6,6:18.12
-5,-5,6:18.12
-3,-5,6:18.12
-2,-5,6:18.12
-1,-5,6:18.12
1,-5,6:18.12
-5,-4,6:18.12
0,-4,6:18.12
-8,-3,6:18.4
-7,-3,6:18.12
-6,-3,6:18.12
-5,-3,6:18.12
-4,-3,6:18.12
-3,-3,6:17.12
-2,-3,6:18.12
-1,-3,6:18.12
0,-3,6:18.12
1,-3,6:18.12
-6,-2,6:18.12
-5,-2,6:18.12
-4,-2,6:18.12
-3,-2,6:18.12
-2,-2,6:18.12
-1,-2,6:18.12
0,-2,6:18.12
3,-2,6:18.12
-6,-1,6:18.12
-5,-1,6:18.12
-4,-1,6:18.12
-3,-1,6:18.12
-2,-1,6:18.12
0,-1,6:18.12
1,-1,6:18.12
3,-1,6:18.12
-5,0,6:18.12
-4,0,6:18.12
-3,0,6:18.12
-2,0,6:18.12
-1,0,6:18.12
0,0,6:18.12
1,0,6:18.12
2,0,6:18.12
3,0,6:18.12
5,0,6:18.12
-4,1,6:18.12
-3,1,6:18.12
-2,1,6:18.12
-1,1,6:17.12
0,1,6:18.12
1,1,6:18.12
2,1,6:18.12
3,1,6:18.12
-4,2,6:18.12
-3,2,6:18.12
-2,2,6:18.12
-1,2,6:18.12
0,2,6:18.12
1,2,6:18.12
2,2,6:18.12
3,2,6:18.12
4,2,6:18.12
-5,3,6:18.12
-2,3,6:18.12
-1,3,6:18.12
0,3,6:18.12
2,3,6:18.12
3,3,6:18.12
4,3,6:18.12
5,3,6:18.12
-6,4,6:18.12
-3,4,6:18.12
-2,4,6:18.12
-1,4,6:18.12
0,4,6:18.12
1,4,6:18.12
2,4,6:17.8
4,4,6:18.12
-7,5,6:18.12
-6,5,6:18.12
-5,5,6:18.12
-4,5,6:18.12
-1,5,6:18.12
0,5,6:18.12
2,5,6:18.12
3,5,6:18.12
-4,6,6:18.12
0,6,6:18.12
1,6,6:18.12
-5,7,6:18.12
-3,7,6:18.12
1,7,6:18.12
3,7,6:18.12
-3,8,6:18.12
-3,-6,7:18.12
1,-5,7:18.12
-8,-4,7:18.4
-3,-4,7:18.12
-1,-4,7:18.12
0,-4,7:18.12
-5,-3,7:18.12
-4,-3,7:18.12
-2,-3,7:18.12
-6,-2,7:18.12
-5,-2,7:18.12
-3,-2,7:18.12
-1,-2,7:18.12
0,-2,7:18.12
-7,-1,7:18.12
-5,-1,7:18.12
-4,-1,7:18.12
-3,-1,7:18.12
-2,-1,7:18.12
-1,-1,7:18.12
0,-1,7:18.12
1,-1,7:18.12
-6,0,7:18.12
-5,0,7:18.12
-4,0,7:18.12
-2,0,7:18.12
-1,0,7:18.12
1,0,7:18.12
-4,1,7:18.12
-2,1,7:18.12
-1,1,7:18.12
0,1,7:18.12
2,1,7:18.12
-6,2,7:18.12
-4,2,7:18.12
-3,2,7:18.12
-2,2,7:18.12
-1,2,7:18.12
0,2,7:18.12
-5,3,7:18.12
-3,3,7:18.12
-2,3,7:18.12
-1,3,7:18.12
0,3,7:18.12
2,3,7:18.12
-4,4,7:18.12
-3,4,7:18.12
-2,4,7:18.12
-1,4,7:18.12
0,4,7:18.12
-4,5,7:18.12
-3,5,7:18.12
2,5,7:18.12
-4,6,7:18.12
-2,6,7:18.12
1,6,7:18.12
-3,7,7:18.12
-2,7,7:18.12
1,7,7:18.12
3,7,7:18.12
-5,-5,8:18.12
-2,-5,8:18.12
-5,-4,8:18.12
-3,-4,8:18.12
-2,-4,8:18.12
-1,-3,8:18.12
-5,-2,8:18.12
-4,-2,8:18.12
-3,-2,8:18.12
-2,-2,8:18.12
-7,-1,8:18.12
-5,-1,8:18.12
-4,-1,8:18.12
-3,-1,8:18.12
-2,-1,8:18.12
-1,-1,8:18.12
0,-1,8:18.12
2,-1,8:18.12
-6,0,8:18.12
-5,0,8:18.12
-4,0,8:18.12
-3,0,8:18.12
-1,0,8:18.12
0,0,8:18.12
1,0,8:18.12
-5,1,8:18.12
-4,1,8:18.12
-3,1,8:18.12
-2,1,8:18.12
-1,1,8:18.12
0,1,8:18.12
1,1,8:18.12
-6,2,8:18.12
-4,2,8:18.12
-3,2,8:18.12
-2,2,8:18.12
-1,2,8:18.12
0,2,8:18.12
-6,3,8:18.12
-4,3,8:18.12
-2,3,8:18.12
-1,3,8:18.12
0,3,8:18.12
-5,4,8:18.12
-4,4,8:18.12
-3,4,8:18.12
-2,4,8:18.12
1,4,8:18.12
-4,5,8:18.12
2,5,8:18.12
-2,6,8:18.12
-1,6,8:18.12
-1,7,8:18.12
-3,-4,9:18.12
-2,-4,9:18.12
-1,-2,9:18.12
-3,-1,9:18.12
-2,-1,9:18.12
-1,-1,9:18.12
1,-1,9:18.12
-4,0,9:18.12
-3,0,9:18.12
-1,0,9:18.12
2,0,9:18.12
-4,1,9:18.12
-3,1,9:18.12
-2,1,9:18.12
-1,1,9:18.12
0,1,9:18.12
-6,2,9:18.12
-5,2,9:18.12
-4,2,9:18.12
-3,2,9:18.12
-2,2,9:18.12
-1,2,9:18.12
1,2,9:18.12
-7,3,9:18.12
-4,3,9:18.12
-2,3,9:18.12
0,3,9:18.12
2,3,9:18.12
3,3,9:18.12
-2,4,9:18.12
2,4,9:18.12
3,4,9:18.12
-4,5,9:18.12
-3,5,9:18.12
2,5,9:18.12
-1,-2,10:18.12
-4,-1,10:18.12
-3,-1,10:18.12
-2,-1,10:18.12
-1,-1,10:18.12
-6,0,10:18.12
-3,0,10:18.12
-6,1,10:18.12
-5,1,10:18.12
-4,1,10:18.12
-2,1,10:18.12
-1,1,10:18.12
2,1,10:18.12
-5,2,10:18.12
-4,2,10:18.12
-3,2,10:18.12
-1,3,10:18.12
0,3,10:18.12
1,3,10:18.12
-1,4,10:18.12
-2,-1,11:18.4
-1,-1,11:18.4
-2,0,11:18.4
-1,0,11:18.4
-2,1,11:18.4
-3,2,11:18.4
-2,2,11:18.4
0,2,11:18.4
-3,3,11:18.4
-1,3,11:18.4
-1,0,12:18.4
-3,1,12:18.4
-2,1,12:18.4
