[META]
version=2.0
spawnOnBlockType=2
spawnSunlight=True
spawnDarkness=True
spawnWater=False
spawnLava=False
underFill=False
randomRotation=True
dig=True
tree=False
branch=False
needsFoundation=True
rarity=100
collisionPercentage=20
spawnElevationMin=0
spawnElevationMax=200
spawnInBiome=Custom
[DATA]
1,-4,-3:17.14
2,-2,-3:17.14
1,-4,-2:17.14
2,-3,-2:17.14
2,-2,-2:17.14
1,-4,-1:17.14
2,-3,-1:17.14
3,-3,-1:17.14
2,-2,-1:17.14
1,-4,0:17.14
2,-3,0:17.14
3,-3,0:17.14
2,-2,0:17.14
2,-3,1:17.14
2,-3,2:17.14
2,-3,3:17.14
2,-3,4:17.14
2,-3,5:17.14
2,-3,6:17.14
2,-3,7:17.14
2,-3,8:17.14
2,-3,9:17.14
2,-3,10:17.14
2,-3,11:17.14
2,-3,12:17.14
2,-3,13:17.14
2,-3,14:17.14
0,-3,15:17.14
1,-3,15:17.14
2,-3,15:17.14
0,-6,16:18.12
3,-4,16:17.14
-1,-3,16:17.14
2,-3,16:17.14
0,-7,17:18.12
-1,-6,17:18.12
-1,-5,17:18.12
0,-5,17:18.12
4,-5,17:17.14
-3,-4,17:18.12
-2,-4,17:18.12
1,-4,17:17.14
2,-4,17:18.12
-1,-3,17:17.14
2,-3,17:17.14
1,-2,17:17.14
2,-1,17:18.12
2,1,17:18.12
3,1,17:18.12
-1,-7,18:18.12
-2,-6,18:18.12
5,-6,18:18.12
6,-6,18:18.12
-2,-5,18:18.12
0,-5,18:17.14
1,-5,18:18.12
2,-5,18:18.12
4,-5,18:17.14
6,-5,18:18.12
-3,-4,18:18.12
-2,-4,18:18.12
-1,-4,18:18.12
0,-4,18:18.12
3,-4,18:18.12
5,-4,18:18.12
-4,-3,18:18.12
-2,-3,18:17.14
0,-3,18:18.12
2,-3,18:17.14
3,-3,18:17.14
4,-3,18:18.12
-2,-1,18:18.12
1,-1,18:17.14
2,-1,18:18.12
-2,-7,19:18.12
-1,-7,19:18.12
7,-7,19:18.12
-2,-6,19:18.12
-1,-6,19:18.12
2,-6,19:18.12
5,-6,19:17.14
6,-6,19:18.12
7,-6,19:18.12
-2,-5,19:18.12
-1,-5,19:17.14
0,-5,19:18.12
-1,-4,19:18.12
0,-4,19:18.12
3,-4,19:18.12
-4,-3,19:18.12
-2,-3,19:17.14
-1,-3,19:18.12
0,-3,19:18.12
2,-3,19:17.14
4,-3,19:17.14
6,-3,19:18.12
-3,-2,19:18.12
-1,-2,19:18.12
2,-2,19:18.12
4,-2,19:18.12
5,-2,19:18.12
-3,-1,19:18.12
-2,-1,19:18.12
0,-1,19:17.14
4,-1,19:18.12
-1,0,19:18.12
0,0,19:18.12
1,0,19:18.12
2,0,19:17.14
-2,1,19:18.12
0,1,19:18.12
1,1,19:18.12
3,1,19:18.12
2,2,19:18.12
6,-8,20:18.12
-2,-7,20:18.12
0,-7,20:18.12
3,-7,20:18.12
5,-7,20:18.12
-2,-6,20:17.14
4,-6,20:18.12
5,-6,20:17.14
6,-6,20:18.12
7,-6,20:18.12
-3,-5,20:18.12
-2,-5,20:18.12
-1,-5,20:18.12
0,-5,20:18.12
1,-5,20:18.12
4,-5,20:18.12
5,-5,20:18.12
-1,-4,20:18.12
1,-4,20:18.12
2,-4,20:18.12
4,-4,20:18.12
5,-4,20:18.12
-3,-3,20:18.12
-2,-3,20:18.12
-1,-3,20:18.12
0,-3,20:18.12
2,-3,20:17.14
3,-3,20:18.12
4,-3,20:17.14
5,-3,20:18.12
6,-3,20:18.12
1,-2,20:18.12
4,-2,20:18.12
-3,-1,20:18.12
-2,-1,20:18.12
-1,-1,20:17.14
1,-1,20:18.12
4,-1,20:18.12
-2,0,20:18.12
0,0,20:18.12
2,0,20:17.14
3,0,20:18.12
-2,1,20:18.12
1,1,20:18.12
3,1,20:18.12
4,1,20:18.12
5,1,20:18.12
5,2,20:18.12
3,3,20:18.12
4,3,20:18.12
-3,-7,21:18.12
-2,-6,21:17.14
-1,-6,21:18.12
0,-6,21:18.12
6,-6,21:18.12
7,-6,21:18.12
-3,-5,21:18.12
-2,-5,21:18.12
-1,-5,21:18.12
0,-5,21:18.12
2,-5,21:18.12
4,-5,21:18.12
5,-5,21:18.12
6,-5,21:18.12
7,-5,21:18.12
-4,-4,21:18.12
0,-4,21:18.12
1,-4,21:18.12
3,-4,21:18.12
4,-4,21:18.12
6,-4,21:18.12
-5,-3,21:18.12
-3,-3,21:18.12
-2,-3,21:18.12
-1,-3,21:18.12
2,-3,21:17.14
3,-3,21:18.12
4,-3,21:18.12
5,-3,21:17.14
6,-3,21:18.12
7,-3,21:18.12
-6,-2,21:18.12
-2,-2,21:18.12
-1,-2,21:18.12
1,-2,21:18.12
5,-2,21:18.12
8,-2,21:18.12
-6,-1,21:18.12
-4,-1,21:18.12
-2,-1,21:18.12
-1,-1,21:17.14
0,-1,21:18.12
3,-1,21:18.12
-3,0,21:18.12
-2,0,21:18.12
2,0,21:18.12
3,0,21:18.12
5,0,21:18.12
-4,1,21:18.12
-2,1,21:18.12
-1,1,21:18.12
2,1,21:18.12
3,1,21:17.14
4,1,21:18.12
2,3,21:18.12
3,3,21:18.12
-4,-8,22:18.12
2,-7,22:18.12
6,-7,22:18.12
-4,-6,22:18.12
-3,-6,22:17.14
-2,-6,22:18.12
-1,-6,22:18.12
0,-6,22:18.12
5,-6,22:18.12
-5,-5,22:18.12
-4,-5,22:18.12
-1,-5,22:18.12
0,-5,22:18.12
1,-5,22:18.12
2,-5,22:18.12
3,-5,22:18.12
5,-5,22:18.12
6,-5,22:18.12
-4,-4,22:18.12
-1,-4,22:18.12
2,-4,22:18.12
3,-4,22:18.12
5,-4,22:18.12
6,-4,22:18.12
-3,-3,22:18.12
2,-3,22:17.14
4,-3,22:18.12
5,-3,22:17.14
7,-3,22:18.12
-5,-2,22:18.12
-2,-2,22:18.12
4,-2,22:18.12
5,-2,22:18.12
6,-2,22:18.12
7,-2,22:18.12
9,-2,22:18.12
-2,-1,22:18.12
-1,-1,22:18.12
2,-1,22:18.12
6,-1,22:18.12
-6,0,22:18.12
-3,0,22:18.12
-1,0,22:17.14
0,0,22:18.12
-4,1,22:18.12
1,1,22:18.12
2,1,22:18.12
3,1,22:17.14
4,1,22:18.12
5,1,22:18.12
7,1,22:18.12
-4,2,22:18.12
-3,2,22:18.12
-2,2,22:18.12
-1,2,22:18.12
3,2,22:18.12
3,3,22:18.12
4,3,22:18.12
5,3,22:18.12
2,4,22:18.12
-4,-7,23:18.12
-3,-7,23:18.12
-1,-7,23:18.12
-5,-6,23:18.12
-3,-6,23:17.14
-1,-6,23:18.12
2,-6,23:18.12
-4,-5,23:18.12
-3,-5,23:18.12
-2,-5,23:18.12
-1,-5,23:18.12
1,-5,23:18.12
3,-5,23:18.12
5,-5,23:18.12
7,-5,23:18.12
-6,-4,23:18.12
-5,-4,23:18.12
-4,-4,23:18.12
-3,-4,23:18.12
0,-4,23:18.12
1,-4,23:18.12
2,-4,23:18.12
3,-4,23:17.14
5,-4,23:18.12
6,-4,23:18.12
-7,-3,23:18.12
-6,-3,23:18.12
-5,-3,23:18.12
0,-3,23:18.12
1,-3,23:17.14
2,-3,23:18.12
3,-3,23:18.12
5,-3,23:18.12
6,-3,23:17.14
7,-3,23:18.12
-6,-2,23:18.12
-5,-2,23:18.12
-4,-2,23:18.12
-3,-2,23:18.12
-2,-2,23:18.12
-1,-2,23:18.12
2,-2,23:18.12
7,-2,23:18.12
-7,-1,23:18.4
-4,-1,23:18.12
-2,-1,23:18.12
0,-1,23:18.12
4,-1,23:18.12
5,-1,23:18.12
6,-1,23:18.12
7,-1,23:18.12
-5,0,23:18.12
-4,0,23:18.12
-3,0,23:18.12
-2,0,23:17.14
-1,0,23:18.12
0,0,23:18.12
2,0,23:18.12
3,0,23:18.12
6,0,23:18.12
7,0,23:18.12
8,0,23:18.12
-6,1,23:18.12
-4,1,23:18.12
0,1,23:18.12
1,1,23:18.12
2,1,23:18.12
3,1,23:18.12
4,1,23:17.14
5,1,23:18.12
6,1,23:18.12
7,1,23:18.12
-4,2,23:18.12
-2,2,23:18.12
0,2,23:18.12
2,2,23:17.14
6,2,23:18.4
3,3,23:18.12
4,3,23:18.12
3,5,23:18.4
2,6,23:18.4
-3,-7,24:18.12
0,-7,24:18.12
-3,-6,24:18.12
-2,-6,24:18.12
-1,-6,24:18.12
2,-6,24:18.12
3,-6,24:18.12
6,-6,24:18.12
-5,-5,24:18.12
1,-5,24:18.12
2,-5,24:18.12
3,-5,24:18.12
4,-5,24:17.14
5,-5,24:18.12
-4,-4,24:18.12
-2,-4,24:18.12
-1,-4,24:18.12
0,-4,24:17.14
2,-4,24:18.12
3,-4,24:18.12
4,-4,24:18.12
-5,-3,24:18.12
-3,-3,24:18.12
3,-3,24:18.4
4,-3,24:18.12
6,-3,24:18.12
7,-3,24:18.12
-6,-2,24:18.12
-4,-2,24:18.12
0,-2,24:18.12
1,-2,24:18.12
5,-2,24:18.12
6,-2,24:18.12
7,-2,24:18.12
-5,-1,24:18.12
-4,-1,24:18.12
-1,-1,24:18.12
4,-1,24:18.12
5,-1,24:18.12
-2,0,24:18.12
-1,0,24:18.12
1,0,24:18.12
2,0,24:18.12
5,0,24:18.12
9,0,24:18.12
-4,1,24:18.12
-1,1,24:18.12
0,1,24:18.12
1,1,24:18.12
2,1,24:18.12
4,1,24:18.12
-5,2,24:18.12
-2,2,24:18.12
-1,2,24:18.12
0,2,24:18.12
1,2,24:18.12
2,2,24:17.14
4,2,24:18.4
6,2,24:18.4
1,3,24:18.12
2,3,24:18.12
3,3,24:18.12
4,3,24:18.4
5,3,24:18.4
0,4,24:18.12
1,4,24:18.12
1,5,24:18.4
1,6,24:18.4
-2,-7,25:18.12
-2,-6,25:18.12
0,-6,25:18.12
1,-6,25:18.12
2,-6,25:18.12
4,-6,25:18.12
-4,-5,25:18.12
-3,-5,25:18.12
-2,-5,25:18.12
0,-5,25:18.12
2,-5,25:18.12
4,-5,25:17.14
5,-5,25:18.4
6,-5,25:18.12
-2,-4,25:18.12
-1,-4,25:18.12
0,-4,25:17.14
1,-4,25:18.12
2,-4,25:18.12
3,-4,25:18.12
4,-4,25:18.4
7,-4,25:18.12
-3,-3,25:18.12
-2,-3,25:18.12
-1,-3,25:18.12
0,-3,25:18.12
2,-3,25:18.12
3,-3,25:18.12
4,-3,25:18.12
6,-3,25:18.12
-6,-2,25:18.12
1,-2,25:18.12
2,-2,25:18.12
3,-2,25:18.4
7,-2,25:18.12
8,-2,25:18.12
-5,-1,25:18.12
-3,-1,25:18.12
2,-1,25:18.12
-5,0,25:18.12
-2,0,25:18.12
-1,0,25:18.12
1,0,25:18.12
2,0,25:18.12
-3,1,25:18.12
2,1,25:18.12
3,1,25:18.12
4,1,25:18.12
0,2,25:18.12
1,2,25:18.12
2,2,25:18.12
3,2,25:18.12
4,2,25:18.4
-1,3,25:18.12
1,3,25:18.12
2,3,25:18.12
1,4,25:18.12
2,4,25:18.12
0,5,25:18.4
3,5,25:18.4
1,6,25:18.4
3,-7,26:18.12
4,-7,26:18.12
3,-6,26:18.4
2,-5,26:18.4
3,-5,26:18.4
5,-5,26:18.12
1,-4,26:18.12
2,-4,26:18.12
3,-4,26:18.12
-1,-3,26:18.12
1,-3,26:18.12
2,-3,26:18.4
3,-3,26:18.12
-1,-2,26:18.12
0,-2,26:18.12
1,-2,26:18.12
2,-2,26:18.12
3,-2,26:18.12
-1,-1,26:18.12
0,-1,26:18.12
1,-1,26:18.12
2,-1,26:18.12
1,0,26:18.12
1,1,26:18.12
2,1,26:18.12
2,2,26:18.12
3,3,26:18.12
2,-6,27:18.4
0,-4,27:18.12
3,-4,27:18.4
0,-3,27:18.12
2,-3,27:18.4
5,-3,27:18.4
0,-2,27:18.12
4,-2,27:18.4
0,-1,27:18.12
3,-1,27:18.12
2,-4,28:18.4
3,-4,28:18.4
4,-4,28:18.4
1,-3,28:18.12
3,-3,28:18.4
2,-2,28:18.12
