[META]
version=2.0
spawnOnBlockType=2
spawnSunlight=True
spawnDarkness=True
spawnWater=False
spawnLava=False
underFill=False
randomRotation=True
dig=True
tree=False
branch=False
needsFoundation=True
rarity=100
collisionPercentage=20
spawnElevationMin=0
spawnElevationMax=200
spawnInBiome=Custom
[DATA]
-1,0,-3:17.12
1,2,-3:17.12
-1,0,-2:17.12
-2,1,-2:17.12
0,1,-2:17.12
1,2,-2:17.12
-1,0,-1:17.12
-2,1,-1:17.12
0,1,-1:17.12
1,2,-1:17.12
-1,0,0:17.12
0,0,0:17.12
-2,1,0:17.12
-1,1,0:17.12
0,1,0:17.12
1,2,0:17.12
0,0,1:17.12
-1,1,1:17.12
0,1,1:17.12
-1,1,2:17.12
0,1,2:17.12
-1,1,3:17.12
0,1,3:17.12
-2,1,4:17.12
0,1,4:17.12
-1,2,4:17.12
-4,4,4:18.12
-5,6,4:18.12
-4,6,4:18.12
-3,6,4:18.12
-2,-5,5:18.4
-3,-4,5:18.12
-2,-4,5:18.12
2,-2,5:18.12
3,-2,5:18.12
-4,-1,5:18.12
-4,0,5:18.12
-3,0,5:18.12
2,0,5:18.12
-4,1,5:18.12
-3,1,5:17.12
-2,1,5:18.12
0,1,5:17.12
1,1,5:18.12
-2,2,5:18.12
-1,2,5:17.12
0,2,5:18.12
0,3,5:18.12
-6,4,5:18.12
-5,4,5:18.12
-3,4,5:18.12
-5,5,5:18.12
-4,5,5:18.12
-2,5,5:18.12
-2,-6,6:18.4
-3,-4,6:18.4
0,-3,6:18.12
-5,-1,6:18.12
-4,-1,6:18.12
0,-1,6:18.12
1,-1,6:18.12
2,-1,6:18.12
-4,0,6:18.12
-1,0,6:18.12
0,0,6:18.12
3,0,6:18.12
4,0,6:18.12
-3,1,6:17.12
-2,1,6:18.12
1,1,6:17.12
-5,2,6:18.12
-2,2,6:18.12
-1,2,6:17.12
2,2,6:18.12
-3,3,6:18.12
-6,4,6:18.12
-4,4,6:18.12
-6,5,6:18.12
-4,5,6:18.12
-3,5,6:18.12
-2,5,6:18.12
-5,7,6:18.4
-4,7,6:18.4
-2,-5,7:18.4
0,-5,7:18.4
-3,-4,7:18.4
-2,-4,7:18.4
-2,-3,7:18.12
2,-3,7:18.12
-4,-2,7:18.12
-3,-2,7:18.12
-2,-2,7:18.12
1,-2,7:18.12
-5,-1,7:18.12
-4,-1,7:18.12
-2,-1,7:18.12
0,-1,7:18.12
1,-1,7:18.12
2,-1,7:18.12
3,-1,7:18.12
4,-1,7:18.12
-6,0,7:18.12
-4,0,7:17.12
0,0,7:18.12
1,0,7:18.12
2,0,7:18.12
3,0,7:18.12
-6,1,7:18.12
-4,1,7:18.12
-1,1,7:18.12
0,1,7:18.12
1,1,7:17.12
2,1,7:18.12
-4,2,7:18.12
-3,2,7:18.12
-1,2,7:17.12
0,2,7:18.12
1,2,7:18.12
2,2,7:18.12
-1,3,7:18.12
0,3,7:18.12
1,3,7:18.12
-5,4,7:18.12
-3,4,7:18.12
-2,4,7:18.12
0,4,7:18.12
-7,5,7:18.4
-5,5,7:18.12
-4,5,7:18.12
-6,6,7:18.4
-5,6,7:18.12
-4,6,7:18.12
-2,6,7:18.12
-4,7,7:18.12
-2,7,7:18.4
-2,-6,8:18.4
-4,-5,8:18.4
-3,-5,8:18.4
-1,-5,8:18.4
-1,-4,8:18.4
-4,-3,8:18.12
-2,-3,8:18.12
0,-3,8:18.12
-1,-2,8:18.12
-4,-1,8:18.12
-3,-1,8:18.12
-2,-1,8:18.12
2,-1,8:18.12
4,-1,8:18.12
-6,0,8:18.12
-4,0,8:17.12
-3,0,8:18.12
-2,0,8:18.12
2,0,8:18.12
3,0,8:18.12
-6,1,8:18.12
-4,1,8:18.12
0,1,8:18.12
1,1,8:17.12
3,1,8:18.12
-5,2,8:18.12
-4,2,8:18.12
-3,2,8:18.12
-1,2,8:18.12
0,2,8:18.12
2,2,8:18.12
-6,3,8:18.12
0,3,8:17.12
1,3,8:18.12
-6,4,8:18.12
-5,4,8:18.12
-4,4,8:18.12
-3,4,8:18.12
-6,5,8:18.12
-5,5,8:18.12
-4,5,8:18.12
-3,5,8:18.12
-2,5,8:18.12
-6,6,8:18.4
-5,6,8:18.12
-4,6,8:18.12
-5,7,8:18.12
-4,7,8:18.12
-3,7,8:18.12
-4,8,8:18.4
-3,8,8:18.4
-2,-5,9:18.4
-2,-4,9:18.4
-1,-4,9:18.4
0,-4,9:18.4
-2,-3,9:17.12
-4,-2,9:18.12
-3,-2,9:18.12
-2,-2,9:17.12
-1,-2,9:18.12
1,-2,9:18.4
2,-2,9:18.4
-5,-1,9:18.12
-3,-1,9:17.12
-1,-1,9:18.12
1,-1,9:18.4
-6,0,9:18.12
-4,0,9:17.12
3,0,9:18.12
-6,1,9:18.12
-4,1,9:18.12
-1,1,9:18.4
1,1,9:17.12
-5,2,9:18.12
-4,2,9:18.12
-1,2,9:18.4
0,2,9:18.12
1,2,9:18.12
2,2,9:18.12
-5,3,9:18.4
0,3,9:17.12
-7,4,9:18.4
-6,4,9:18.4
-5,4,9:18.4
-4,4,9:18.4
-3,4,9:18.4
-1,4,9:18.4
2,4,9:18.12
-5,5,9:18.4
-4,5,9:18.12
-4,6,9:18.4
-3,6,9:18.12
-4,7,9:18.12
-2,7,9:18.4
-4,8,9:18.4
-2,-5,10:18.4
-1,-5,10:18.4
0,-5,10:18.4
-2,-4,10:17.12
-1,-4,10:18.4
0,-4,10:18.4
2,-4,10:18.4
-4,-3,10:18.12
-3,-3,10:18.12
-1,-3,10:18.12
2,-3,10:18.12
-4,-2,10:18.12
-5,-1,10:18.12
-4,-1,10:18.12
-3,-1,10:18.12
-2,-1,10:18.12
-5,0,10:18.12
-2,0,10:18.12
1,0,10:17.12
-5,1,10:17.12
0,1,10:18.12
2,1,10:18.12
-4,2,10:18.12
0,2,10:18.12
2,2,10:17.12
-5,3,10:18.4
-3,3,10:18.12
-1,3,10:18.4
0,3,10:17.12
-6,4,10:18.4
-5,4,10:18.4
-2,4,10:18.4
-1,4,10:18.4
1,4,10:18.4
2,4,10:18.12
-4,5,10:18.4
-1,5,10:18.4
-2,7,10:18.4
-4,-7,11:18.4
-2,-7,11:18.4
-5,-6,11:18.4
-4,-6,11:18.4
-3,-6,11:18.4
-1,-6,11:18.4
2,-6,11:18.4
-1,-5,11:18.4
2,-5,11:18.4
-3,-4,11:18.4
-2,-4,11:17.12
2,-4,11:18.4
4,-4,11:18.4
0,-3,11:18.12
-3,-2,11:18.12
1,-2,11:18.12
-4,-1,11:18.12
-5,0,11:18.12
-4,0,11:18.12
1,0,11:17.12
2,0,11:18.12
-6,1,11:18.4
-5,1,11:17.12
2,1,11:18.12
4,1,11:18.12
-7,2,11:18.4
-5,2,11:18.12
1,2,11:18.12
2,2,11:17.12
4,2,11:18.12
-5,3,11:18.12
-3,3,11:18.4
0,3,11:17.12
1,3,11:18.12
4,3,11:18.12
-3,4,11:18.4
-1,4,11:17.12
0,4,11:18.4
1,4,11:18.12
2,4,11:18.12
-5,5,11:18.4
-3,5,11:18.4
-2,5,11:18.4
-1,5,11:18.4
0,5,11:18.4
-5,6,11:18.4
-3,6,11:18.4
-2,6,11:18.4
-1,6,11:18.4
0,6,11:18.4
-3,8,11:18.4
-3,-6,12:18.4
1,-6,12:18.4
2,-6,12:18.4
-3,-5,12:17.12
-2,-5,12:18.4
-1,-5,12:18.4
-4,-4,12:18.4
-2,-4,12:18.4
-1,-4,12:17.12
0,-4,12:17.12
1,-4,12:18.4
2,-4,12:18.4
-3,-3,12:18.4
0,-3,12:18.4
0,-2,12:18.4
3,-2,12:18.4
-6,-1,12:18.4
-6,0,12:18.4
-5,0,12:18.4
-4,0,12:18.12
1,0,12:17.12
-7,1,12:18.4
-6,1,12:18.4
-5,1,12:17.12
-4,1,12:18.12
-5,2,12:18.4
1,2,12:18.12
3,2,12:17.12
4,2,12:18.12
5,2,12:18.4
0,3,12:17.12
1,3,12:18.12
3,3,12:18.4
-1,4,12:18.4
0,4,12:18.4
2,4,12:18.4
4,4,12:18.4
-5,5,12:18.4
-4,5,12:18.4
-3,5,12:18.4
-2,5,12:17.12
3,5,12:18.4
-3,6,12:18.4
-2,6,12:18.4
-1,6,12:18.4
2,6,12:18.4
3,6,12:18.4
-4,8,12:18.4
-3,8,12:18.4
-2,8,12:18.4
-5,-6,13:18.4
0,-6,13:18.4
2,-6,13:18.4
-2,-5,13:18.4
0,-5,13:18.4
1,-5,13:17.12
2,-5,13:18.4
-2,-4,13:18.4
-1,-4,13:18.4
2,-4,13:18.4
4,-4,13:18.4
-2,-3,13:18.4
0,-3,13:18.4
2,-3,13:18.4
-4,-2,13:18.4
-1,-2,13:17.12
1,-2,13:18.4
3,-2,13:18.4
0,-1,13:17.12
2,-1,13:17.12
-4,0,13:17.12
2,0,13:18.4
-5,1,13:18.4
3,1,13:18.4
-6,2,13:18.4
-5,2,13:17.12
-4,2,13:18.4
-3,2,13:18.12
2,2,13:18.4
3,2,13:17.12
5,2,13:18.4
0,3,13:18.4
1,3,13:17.12
2,3,13:18.4
4,3,13:18.4
2,4,13:18.4
4,4,13:18.4
5,4,13:18.4
-4,5,13:18.4
-2,5,13:17.12
-1,5,13:18.4
0,5,13:18.4
3,5,13:18.4
4,5,13:18.4
5,5,13:18.4
-2,6,13:18.4
-1,6,13:18.4
0,6,13:18.4
-5,7,13:18.4
-2,7,13:18.4
2,7,13:18.4
-2,8,13:18.4
0,-7,14:18.4
-3,-6,14:18.4
1,-6,14:18.4
2,-6,14:18.4
3,-6,14:18.4
-4,-5,14:18.4
0,-5,14:18.4
1,-5,14:17.12
2,-5,14:18.4
0,-4,14:18.4
1,-4,14:18.4
3,-4,14:18.4
-4,-3,14:18.4
-3,-3,14:18.4
-2,-3,14:17.12
-1,-3,14:18.4
0,-3,14:18.4
1,-3,14:18.4
-4,-1,14:18.4
2,-1,14:17.12
4,-1,14:18.4
-4,0,14:17.12
2,0,14:18.4
-5,1,14:18.4
-4,1,14:18.4
3,1,14:18.4
-5,2,14:17.12
1,2,14:18.4
-7,3,14:18.4
1,3,14:17.12
2,3,14:18.4
3,3,14:18.4
4,3,14:17.12
5,3,14:18.4
-5,4,14:18.4
-2,4,14:18.4
3,4,14:18.4
-3,5,14:18.4
-1,5,14:18.4
0,5,14:18.4
1,5,14:18.4
3,5,14:18.4
-2,6,14:17.12
0,6,14:18.4
1,6,14:18.4
-1,7,14:18.4
0,7,14:18.4
4,7,14:18.4
-3,8,14:18.4
3,8,14:18.12
0,-7,15:18.4
-3,-5,15:18.4
-4,-4,15:18.4
-3,-4,15:18.4
-1,-4,15:18.4
3,-4,15:18.4
-5,-3,15:18.4
-4,-3,15:18.4
-3,-3,15:18.4
-2,-3,15:17.12
-1,-3,15:18.4
0,-3,15:18.4
-6,-2,15:18.4
-2,-2,15:18.4
-1,-2,15:18.4
0,-2,15:18.4
-4,-1,15:17.12
-3,-1,15:18.12
-2,-1,15:18.12
2,-1,15:17.12
3,-1,15:18.4
4,-1,15:18.4
-5,2,15:18.4
-4,2,15:18.4
3,2,15:18.4
4,2,15:18.4
6,2,15:18.4
-8,3,15:18.4
-6,3,15:17.12
-4,3,15:18.4
1,3,15:17.12
3,3,15:18.4
4,3,15:17.12
5,3,15:18.4
-6,4,15:18.4
-3,4,15:18.12
-2,4,15:18.12
1,4,15:18.4
4,4,15:18.4
-7,5,15:18.4
-6,5,15:18.4
-3,5,15:18.12
-2,5,15:18.4
0,5,15:18.4
1,5,15:18.4
2,5,15:18.4
3,5,15:18.4
5,5,15:18.4
-2,6,15:17.12
0,6,15:18.4
1,6,15:18.4
2,6,15:18.4
-3,7,15:18.4
-2,7,15:18.4
-1,7,15:18.4
0,7,15:18.4
2,7,15:18.4
3,7,15:18.4
4,7,15:18.4
-2,8,15:18.4
-1,8,15:18.4
1,8,15:18.4
2,8,15:18.12
3,8,15:18.12
0,-6,16:18.4
-3,-5,16:18.4
-1,-5,16:18.4
0,-5,16:18.4
-5,-3,16:18.4
-4,-3,16:18.4
1,-3,16:18.4
2,-3,16:18.4
3,-3,16:18.4
-3,-2,16:18.4
-1,-2,16:18.4
0,-2,16:18.4
1,-2,16:17.12
3,-2,16:18.4
-4,-1,16:18.4
-3,-1,16:18.12
-2,-1,16:18.12
1,-1,16:18.4
3,-1,16:18.12
-2,0,16:18.4
1,0,16:18.4
3,0,16:18.4
4,0,16:18.4
-6,1,16:18.4
-5,1,16:18.4
2,1,16:18.4
3,1,16:18.4
4,1,16:18.4
-7,2,16:18.4
-5,2,16:18.4
6,2,16:18.4
-8,3,16:18.4
-7,3,16:18.4
-6,3,16:17.12
-5,3,16:18.4
-4,3,16:18.4
-3,3,16:18.12
-2,3,16:18.12
1,3,16:17.12
2,3,16:18.4
3,3,16:18.4
4,3,16:17.12
-4,4,16:18.4
-3,4,16:18.12
-1,4,16:18.12
2,4,16:18.4
3,4,16:18.4
5,4,16:18.4
-6,5,16:18.4
-3,5,16:17.12
-2,5,16:18.12
0,5,16:18.4
3,5,16:18.4
4,5,16:18.4
-4,6,16:18.4
-2,6,16:17.12
2,6,16:18.4
3,6,16:18.4
4,6,16:18.4
-4,7,16:18.4
-3,7,16:18.4
-1,7,16:18.4
0,7,16:18.4
2,7,16:18.4
4,7,16:18.4
0,8,16:18.4
-2,-3,17:18.4
0,-3,17:18.4
1,-3,17:18.4
-1,-2,17:18.4
0,-2,17:18.4
1,-2,17:17.12
2,-2,17:18.4
-5,-1,17:18.4
-3,-1,17:18.4
-1,-1,17:18.12
0,-1,17:18.4
1,-1,17:18.12
3,-1,17:18.4
4,-1,17:18.4
-6,1,17:18.4
3,1,17:18.4
4,1,17:18.4
5,1,17:18.4
2,2,17:18.12
-3,3,17:18.12
0,3,17:18.12
1,3,17:17.12
3,3,17:18.4
4,3,17:17.12
5,3,17:18.4
6,3,17:18.4
-7,4,17:18.4
-5,4,17:18.4
2,4,17:18.4
5,4,17:18.4
-4,5,17:18.4
-3,5,17:17.12
-2,5,17:18.12
-1,5,17:18.12
0,5,17:18.4
4,5,17:18.4
-2,6,17:18.12
-1,6,17:18.12
2,6,17:18.4
4,6,17:18.4
-4,7,17:18.4
-3,7,17:18.4
-2,7,17:18.12
-1,7,17:18.4
0,7,17:18.4
3,7,17:18.4
-4,8,17:18.4
2,8,17:18.4
-3,9,17:18.4
-1,-4,18:18.4
3,-3,18:18.4
-1,-2,18:18.4
1,-2,18:18.4
2,-2,18:18.4
1,-1,18:18.12
3,-1,18:18.4
3,0,18:18.4
-5,2,18:18.4
1,2,18:18.12
2,2,18:18.4
4,2,18:18.4
-3,3,18:18.12
1,3,18:17.12
3,3,18:18.4
-3,4,18:18.12
-1,4,18:18.12
2,4,18:18.4
-1,5,18:18.4
0,5,18:18.12
1,5,18:18.12
2,5,18:18.4
-5,6,18:18.4
-2,6,18:18.4
-1,6,18:18.4
1,6,18:18.4
-2,7,18:18.4
-2,8,18:18.4
-1,8,18:18.4
-2,-2,19:18.4
-1,-2,19:18.4
0,-2,19:18.4
-2,-1,19:18.4
-1,-1,19:18.4
0,-1,19:18.12
1,-1,19:18.12
2,-1,19:18.12
3,2,19:18.12
-2,3,19:18.4
-1,3,19:18.12
1,3,19:17.12
4,3,19:18.4
-1,4,19:18.4
1,4,19:18.12
2,4,19:18.12
5,4,19:18.4
-3,5,19:18.12
-3,6,19:18.12
-2,6,19:18.4
-2,7,19:18.4
-2,1,20:18.4
-1,1,20:18.4
-3,2,20:18.4
-1,2,20:18.4
0,2,20:18.4
2,2,20:18.12
-1,3,20:18.12
-1,4,20:18.4
0,5,20:18.4
1,5,20:18.12
-1,2,21:18.4
1,2,21:18.12
-1,3,21:18.4
-1,4,21:18.4
-2,3,22:18.4
-1,4,22:18.4
