[META]
version=2.0
spawnOnBlockType=2
spawnSunlight=True
spawnDarkness=True
spawnWater=False
spawnLava=False
underFill=False
randomRotation=True
dig=True
tree=False
branch=False
needsFoundation=True
rarity=100
collisionPercentage=20
spawnElevationMin=0
spawnElevationMax=200
spawnInBiome=Custom
[DATA]
1,0,0:17.12
3,1,0:17.12
1,2,0:17.12
1,0,1:17.12
0,1,1:17.12
2,1,1:17.12
3,1,1:17.12
1,2,1:17.12
2,2,1:17.12
1,0,2:17.12
4,0,2:17.12
0,1,2:17.12
2,1,2:17.12
3,1,2:17.12
1,2,2:17.12
2,2,2:17.12
4,2,2:17.12
2,3,2:17.12
1,0,3:17.12
4,0,3:17.12
0,1,3:17.12
1,1,3:17.12
2,1,3:17.12
3,1,3:17.12
1,2,3:17.12
2,2,3:17.12
4,2,3:17.12
2,3,3:17.12
1,1,4:17.12
2,1,4:17.12
1,2,4:17.12
2,2,4:17.12
1,1,5:17.12
2,1,5:17.12
1,2,5:17.12
1,1,6:17.12
3,1,6:17.12
3,2,6:17.12
1,3,6:17.12
0,0,7:17.12
0,1,7:17.12
1,1,7:17.12
3,1,7:17.12
4,1,7:17.12
1,3,7:17.12
3,3,7:17.12
-1,-1,8:17.12
3,0,8:17.12
0,1,8:17.12
5,2,8:17.12
1,3,8:17.12
-2,-4,9:18.4
-1,-4,9:18.12
-2,-3,9:18.12
-1,-2,9:18.12
-1,-1,9:17.12
3,0,9:17.12
0,1,9:17.12
6,2,9:17.12
2,4,9:17.12
-3,-5,10:18.4
-1,-5,10:18.4
-2,-4,10:18.4
-2,-3,10:18.12
-4,-2,10:18.4
-1,-2,10:17.12
0,-2,10:18.12
-2,-1,10:18.12
0,0,10:17.12
3,0,10:17.12
6,1,10:18.12
5,2,10:18.12
6,2,10:17.12
2,4,10:17.12
3,-6,11:18.4
-2,-5,11:18.4
-5,-4,11:18.4
-2,-4,11:18.4
3,-4,11:18.12
-5,-3,11:18.4
-4,-3,11:18.4
-2,-3,11:18.12
-1,-3,11:18.12
0,-3,11:18.12
1,-3,11:18.12
-4,-2,11:18.4
-2,-2,11:18.12
-1,-2,11:17.12
0,-2,11:18.12
2,-1,11:17.12
7,-1,11:18.12
8,-1,11:18.12
0,0,11:17.12
8,1,11:18.12
6,2,11:17.12
7,2,11:18.12
6,3,11:18.12
7,3,11:18.12
2,4,11:17.12
7,4,11:18.12
0,5,11:18.12
2,5,11:18.12
6,5,11:18.12
7,5,11:18.12
5,-7,12:18.4
-3,-6,12:18.4
-2,-6,12:18.4
5,-6,12:18.4
-6,-5,12:18.4
-2,-5,12:18.4
0,-5,12:18.4
3,-5,12:18.4
4,-5,12:18.4
5,-5,12:18.4
-5,-4,12:18.4
-4,-4,12:18.4
-3,-4,12:18.4
-2,-4,12:18.4
-1,-4,12:18.12
0,-4,12:18.12
-6,-3,12:18.4
-5,-3,12:18.4
-4,-3,12:18.4
-2,-3,12:17.12
0,-3,12:18.12
1,-3,12:18.12
2,-3,12:17.12
-5,-2,12:18.4
-2,-2,12:18.4
-1,-2,12:18.12
0,-2,12:18.12
1,-2,12:18.12
2,-2,12:17.12
5,-2,12:18.12
-2,-1,12:18.4
-1,-1,12:18.12
2,-1,12:17.12
7,-1,12:18.12
8,-1,12:18.12
-2,0,12:18.4
0,0,12:17.12
3,0,12:18.12
4,0,12:18.12
3,1,12:18.12
6,1,12:17.12
6,2,12:18.12
7,2,12:18.12
8,2,12:18.12
9,2,12:18.12
0,3,12:18.12
4,3,12:18.12
5,3,12:18.12
6,3,12:18.12
7,3,12:17.12
1,4,12:18.12
2,4,12:18.12
5,4,12:18.12
6,4,12:18.12
7,4,12:18.12
8,4,12:18.12
9,4,12:18.12
1,5,12:18.12
3,5,12:17.12
7,5,12:18.12
0,6,12:18.4
2,6,12:18.12
8,6,12:18.12
-1,7,12:18.4
2,-8,13:18.4
3,-8,13:18.4
4,-8,13:18.4
3,-7,13:18.4
-6,-6,13:18.4
-5,-6,13:18.4
-3,-6,13:18.4
-2,-6,13:18.4
-1,-6,13:18.4
3,-6,13:18.4
4,-6,13:18.4
5,-6,13:18.4
-3,-5,13:18.4
-2,-5,13:18.4
3,-5,13:18.4
6,-5,13:18.4
-4,-4,13:18.4
0,-4,13:18.4
1,-4,13:18.4
3,-4,13:17.12
5,-4,13:18.4
-6,-3,13:18.4
-4,-3,13:18.4
-3,-3,13:18.4
-2,-3,13:17.12
1,-3,13:18.4
2,-3,13:18.4
3,-3,13:18.4
4,-3,13:18.4
5,-3,13:18.4
-6,-2,13:18.4
-4,-2,13:18.4
-2,-2,13:18.4
2,-2,13:18.4
6,-2,13:18.4
7,-2,13:18.4
-2,-1,13:18.4
2,-1,13:17.12
3,-1,13:17.12
4,-1,13:18.4
5,-1,13:18.4
6,-1,13:18.4
7,-1,13:18.4
8,-1,13:18.4
-3,0,13:18.4
-1,0,13:17.12
4,0,13:18.4
7,0,13:18.4
4,1,13:18.4
5,1,13:18.4
6,1,13:17.12
7,1,13:18.4
8,1,13:18.4
1,2,13:18.4
3,2,13:18.4
4,2,13:18.4
5,2,13:18.4
9,2,13:18.4
4,3,13:18.4
6,3,13:18.4
7,3,13:17.12
0,4,13:18.4
3,4,13:18.4
4,4,13:18.4
5,4,13:18.4
6,4,13:18.4
7,4,13:18.4
-1,5,13:18.4
2,5,13:17.12
3,5,13:17.12
4,5,13:18.4
-1,6,13:18.4
1,6,13:18.4
3,6,13:18.4
-1,7,13:18.4
-3,-8,14:18.4
2,-8,14:18.4
3,-8,14:18.4
-5,-7,14:18.4
1,-7,14:18.4
3,-7,14:18.4
-4,-6,14:18.4
-3,-6,14:18.4
-2,-6,14:18.4
-1,-6,14:18.4
0,-6,14:18.4
3,-6,14:18.4
5,-6,14:18.4
-6,-5,14:18.4
-5,-5,14:18.4
-4,-5,14:18.4
-2,-5,14:18.4
0,-5,14:18.4
3,-5,14:17.12
4,-5,14:18.4
5,-5,14:18.4
6,-5,14:18.4
-8,-4,14:18.4
-4,-4,14:18.4
-3,-4,14:17.12
-2,-4,14:18.4
-1,-4,14:18.4
0,-4,14:18.4
1,-4,14:18.4
2,-4,14:18.4
4,-4,14:18.4
6,-4,14:18.4
-7,-3,14:18.4
-5,-3,14:18.4
-4,-3,14:18.4
-3,-3,14:17.12
-2,-3,14:18.4
0,-3,14:18.4
1,-3,14:18.4
3,-3,14:18.4
-7,-2,14:18.4
-6,-2,14:18.4
-5,-2,14:18.4
-2,-2,14:18.4
0,-2,14:18.4
2,-2,14:17.12
3,-2,14:18.4
4,-2,14:17.12
6,-2,14:18.4
-6,-1,14:18.4
-5,-1,14:18.4
0,-1,14:18.4
6,-1,14:18.4
8,-1,14:18.4
-1,0,14:17.12
5,0,14:18.4
6,0,14:18.4
7,0,14:17.12
4,1,14:18.4
6,1,14:18.4
7,1,14:18.4
1,2,14:18.4
2,2,14:18.4
3,2,14:18.4
4,2,14:18.4
6,2,14:18.4
7,2,14:18.4
8,2,14:18.4
9,2,14:18.4
0,3,14:18.4
1,3,14:18.4
2,3,14:18.4
4,3,14:18.4
5,3,14:18.4
7,3,14:18.4
-2,4,14:18.4
-1,4,14:18.4
0,4,14:18.4
2,4,14:18.4
3,4,14:18.4
4,4,14:18.4
5,4,14:18.4
6,4,14:18.4
7,4,14:17.12
9,4,14:18.4
10,4,14:18.4
-2,5,14:18.4
-1,5,14:18.4
0,5,14:18.4
1,5,14:17.12
2,5,14:18.4
3,5,14:17.12
4,5,14:18.4
5,5,14:18.4
7,5,14:18.4
9,5,14:18.4
0,6,14:18.4
1,6,14:18.4
3,6,14:18.4
5,6,14:18.4
6,6,14:18.4
7,6,14:18.4
9,6,14:18.4
0,7,14:18.4
1,7,14:18.4
3,7,14:18.4
7,7,14:18.4
0,8,14:18.4
1,8,14:18.4
2,8,14:18.4
-1,-9,15:18.4
-4,-8,15:18.4
4,-8,15:18.4
-6,-7,15:18.4
-5,-7,15:18.4
-4,-7,15:18.4
-3,-7,15:18.4
2,-7,15:18.4
4,-7,15:18.4
5,-7,15:18.4
-8,-6,15:18.4
-7,-6,15:18.4
-5,-6,15:18.4
-3,-6,15:18.4
1,-6,15:18.4
2,-6,15:18.4
6,-6,15:18.4
-8,-5,15:18.4
-7,-5,15:18.4
-6,-5,15:18.4
-4,-5,15:18.4
-3,-5,15:17.12
-2,-5,15:18.4
1,-5,15:18.4
2,-5,15:18.4
3,-5,15:17.12
4,-5,15:18.4
5,-5,15:18.4
7,-5,15:18.4
-8,-4,15:18.4
-7,-4,15:18.4
-6,-4,15:18.4
-5,-4,15:17.12
-4,-4,15:18.4
-3,-4,15:18.4
-2,-4,15:18.4
-1,-4,15:18.4
1,-4,15:18.4
3,-4,15:18.4
5,-4,15:18.4
-8,-3,15:18.4
-7,-3,15:18.4
-4,-3,15:17.12
-3,-3,15:18.4
-2,-3,15:18.4
-1,-3,15:18.4
1,-3,15:18.4
3,-3,15:18.4
5,-3,15:17.12
-5,-2,15:18.4
-3,-2,15:18.4
-1,-2,15:18.4
2,-2,15:17.12
-4,-1,15:18.4
6,-1,15:18.4
7,-1,15:18.12
8,-1,15:18.12
-1,0,15:17.12
6,0,15:18.12
7,0,15:17.12
7,1,15:18.4
1,2,15:18.4
7,2,15:18.4
8,2,15:18.4
9,2,15:18.4
7,3,15:18.4
8,3,15:18.4
-2,4,15:18.4
1,4,15:18.4
2,4,15:18.4
4,4,15:18.4
5,4,15:18.4
7,4,15:17.12
9,4,15:18.4
-2,5,15:18.4
1,5,15:17.12
3,5,15:18.4
4,5,15:18.4
6,5,15:18.4
10,5,15:18.4
0,6,15:18.4
3,6,15:17.12
5,6,15:18.4
7,6,15:18.4
1,8,15:18.4
3,-9,16:18.4
5,-9,16:18.4
-7,-8,16:18.4
-3,-8,16:18.4
-2,-8,16:18.4
-1,-8,16:18.4
0,-8,16:18.4
4,-8,16:18.4
-5,-7,16:18.12
-4,-7,16:18.4
-3,-7,16:18.4
-2,-7,16:18.4
1,-7,16:18.4
3,-7,16:18.4
4,-7,16:18.4
7,-7,16:18.4
-9,-6,16:18.4
-8,-6,16:18.4
-7,-6,16:18.4
-5,-6,16:18.4
-3,-6,16:18.4
-2,-6,16:17.12
-1,-6,16:18.4
0,-6,16:18.4
3,-6,16:17.12
-9,-5,16:18.4
-8,-5,16:18.4
-6,-5,16:17.12
-4,-5,16:18.4
-3,-5,16:18.4
-2,-5,16:18.4
0,-5,16:18.4
3,-5,16:18.4
6,-5,16:18.4
8,-5,16:18.4
-4,-4,16:18.4
-3,-4,16:18.4
3,-4,16:18.4
5,-4,16:17.12
-8,-3,16:18.4
-5,-3,16:18.4
-4,-3,16:17.12
-3,-3,16:18.4
-2,-3,16:18.4
1,-3,16:18.4
4,-3,16:18.4
6,-3,16:18.4
7,-3,16:18.12
-5,-2,16:18.4
-4,-2,16:18.4
2,-2,16:17.12
7,-2,16:18.12
9,-2,16:18.12
-5,-1,16:18.4
-1,-1,16:17.12
7,-1,16:18.12
9,-1,16:18.12
7,0,16:17.12
6,1,16:18.4
7,1,16:18.12
8,1,16:18.12
9,1,16:18.12
7,2,16:18.4
8,3,16:18.4
3,4,16:18.4
7,4,16:18.4
8,4,16:18.4
0,5,16:18.4
1,5,16:17.12
2,5,16:18.4
6,5,16:17.12
-1,6,16:18.4
0,6,16:18.4
3,6,16:17.12
1,7,16:18.4
2,7,16:18.4
2,-10,17:18.4
3,-10,17:18.4
-7,-9,17:18.4
-6,-9,17:18.4
-2,-9,17:18.4
-1,-9,17:18.4
3,-9,17:18.4
4,-9,17:18.4
6,-9,17:18.4
-6,-8,17:18.4
-4,-8,17:18.4
3,-8,17:18.4
4,-8,17:18.4
5,-8,17:18.4
6,-8,17:18.4
7,-8,17:18.4
-7,-7,17:18.4
-2,-7,17:18.12
2,-7,17:17.12
3,-7,17:18.4
4,-7,17:17.12
6,-7,17:18.4
8,-7,17:18.4
-7,-6,17:18.4
-5,-6,17:18.12
-4,-6,17:18.4
-3,-6,17:18.4
-2,-6,17:17.12
-1,-6,17:18.4
2,-6,17:18.4
3,-6,17:17.12
4,-6,17:18.4
5,-6,17:18.4
7,-6,17:18.4
8,-6,17:18.4
-7,-5,17:17.12
-5,-5,17:18.4
-4,-5,17:18.4
3,-5,17:18.4
5,-5,17:18.4
6,-5,17:18.4
8,-5,17:18.4
9,-5,17:18.4
-8,-4,17:18.4
-7,-4,17:18.4
-6,-4,17:18.4
-5,-4,17:18.4
-3,-4,17:18.4
0,-4,17:18.4
3,-4,17:18.4
4,-4,17:18.4
5,-4,17:17.12
-6,-3,17:18.12
-5,-3,17:17.12
3,-3,17:17.12
7,-3,17:18.12
8,-3,17:18.12
-6,-2,17:18.4
-5,-2,17:18.12
6,-2,17:18.4
-7,-1,17:18.4
-5,-1,17:18.12
-1,-1,17:17.12
7,-1,17:17.12
10,-1,17:18.12
5,1,17:18.12
7,1,17:18.12
8,1,17:18.12
-2,2,17:18.12
-2,3,17:18.12
-1,3,17:18.12
6,3,17:18.4
8,3,17:18.4
-2,4,17:18.12
1,4,17:18.4
2,4,17:18.4
6,4,17:18.4
7,4,17:18.4
0,5,17:17.12
2,5,17:18.4
4,5,17:18.4
6,5,17:17.12
0,6,17:18.4
2,6,17:18.4
3,6,17:17.12
5,6,17:18.4
6,6,17:18.4
3,7,17:18.4
4,7,17:18.4
5,7,17:18.4
4,-10,18:18.4
-7,-9,18:18.4
-2,-9,18:18.12
4,-9,18:18.4
-9,-8,18:18.4
-8,-8,18:18.4
-7,-8,18:18.4
-6,-8,18:18.4
-1,-8,18:18.12
1,-8,18:17.12
4,-8,18:17.12
5,-8,18:18.4
6,-8,18:18.4
7,-8,18:18.4
-10,-7,18:18.4
-9,-7,18:18.4
-8,-7,18:18.4
-7,-7,18:18.4
-5,-7,18:18.4
-3,-7,18:18.12
-2,-7,18:18.12
-1,-7,18:18.12
0,-7,18:18.12
3,-7,18:18.4
4,-7,18:18.4
5,-7,18:18.4
6,-7,18:18.4
-10,-6,18:18.4
-9,-6,18:18.4
-7,-6,18:17.12
-6,-6,18:18.4
-5,-6,18:18.4
-4,-6,18:18.4
-3,-6,18:18.4
-2,-6,18:18.4
-1,-6,18:17.12
0,-6,18:18.12
5,-6,18:18.4
6,-6,18:18.4
8,-6,18:18.4
-10,-5,18:18.4
-7,-5,18:18.4
-6,-5,18:18.4
-5,-5,18:18.4
-4,-5,18:18.4
-3,-5,18:18.12
-2,-5,18:18.12
-1,-5,18:18.12
0,-5,18:18.4
4,-5,18:18.4
6,-5,18:17.12
7,-5,18:18.4
8,-5,18:18.4
9,-5,18:18.4
-7,-4,18:18.4
-4,-4,18:18.12
0,-4,18:18.4
3,-4,18:18.4
4,-4,18:18.4
5,-4,18:18.4
6,-4,18:18.4
7,-4,18:18.12
8,-4,18:18.12
-8,-3,18:18.4
-7,-3,18:18.4
-6,-3,18:18.4
-5,-3,18:17.12
3,-3,18:17.12
4,-3,18:18.4
5,-3,18:18.4
6,-3,18:18.4
7,-3,18:18.12
8,-3,18:18.12
9,-3,18:18.12
-8,-2,18:18.4
-6,-2,18:18.4
4,-2,18:18.12
6,-2,18:18.12
7,-2,18:18.4
10,-2,18:18.12
-4,-1,18:18.12
-2,-1,18:17.12
4,-1,18:18.12
6,-1,18:18.12
7,-1,18:17.12
-8,0,18:18.4
-7,0,18:18.4
-6,0,18:18.4
5,0,18:18.12
7,0,18:18.12
9,0,18:18.12
-4,1,18:18.12
6,1,18:18.12
7,1,18:18.12
6,2,18:18.12
7,2,18:18.12
-4,3,18:18.12
-2,3,18:18.12
-1,3,18:18.12
0,3,18:18.12
7,3,18:18.12
8,3,18:18.12
-1,4,18:17.12
0,4,18:18.12
4,4,18:18.12
6,4,18:18.12
7,4,18:18.12
0,5,18:17.12
1,5,18:18.4
4,5,18:18.4
5,5,18:18.4
6,5,18:17.12
7,5,18:18.4
3,6,18:18.4
5,6,18:18.4
6,6,18:18.4
7,6,18:18.4
3,7,18:17.12
4,7,18:18.4
7,7,18:18.4
2,9,18:18.4
3,9,18:18.4
-3,-10,19:18.12
5,-10,19:18.4
-7,-9,19:18.4
-4,-9,19:18.4
-3,-9,19:18.12
1,-9,19:18.4
2,-9,19:18.4
3,-9,19:18.4
4,-9,19:18.4
5,-9,19:18.4
6,-9,19:18.4
-9,-8,19:18.4
-5,-8,19:18.4
-4,-8,19:18.4
-2,-8,19:18.12
0,-8,19:18.12
1,-8,19:18.12
2,-8,19:18.4
3,-8,19:18.4
4,-8,19:17.12
5,-8,19:18.4
6,-8,19:18.4
7,-8,19:18.4
-9,-7,19:18.4
-5,-7,19:18.4
-3,-7,19:18.12
-1,-7,19:18.12
0,-7,19:18.12
1,-7,19:18.12
2,-7,19:18.12
3,-7,19:18.4
4,-7,19:18.4
6,-7,19:18.4
-7,-6,19:18.4
-4,-6,19:18.4
-2,-6,19:18.4
-1,-6,19:17.12
1,-6,19:18.12
2,-6,19:18.4
3,-6,19:18.4
4,-6,19:18.4
5,-6,19:18.4
6,-6,19:18.4
8,-6,19:18.4
-7,-5,19:18.4
-6,-5,19:18.4
-4,-5,19:18.4
-3,-5,19:18.12
-2,-5,19:18.12
-1,-5,19:18.12
3,-5,19:18.12
4,-5,19:18.12
5,-5,19:18.12
8,-5,19:18.4
-6,-4,19:18.4
-2,-4,19:18.12
3,-4,19:18.12
4,-4,19:18.12
5,-4,19:18.12
-8,-3,19:18.4
-6,-3,19:18.4
-4,-3,19:18.4
3,-3,19:17.12
4,-3,19:18.12
5,-3,19:18.4
-6,-2,19:17.12
-5,-2,19:18.4
-4,-2,19:18.4
-3,-2,19:18.4
4,-2,19:18.12
5,-2,19:18.4
8,-2,19:18.12
-9,-1,19:18.4
-6,-1,19:18.4
-5,-1,19:18.4
-3,-1,19:18.4
-2,-1,19:17.12
7,-1,19:18.12
8,-1,19:18.12
10,-1,19:18.12
-7,0,19:18.4
-4,0,19:18.4
-2,0,19:18.12
-1,0,19:18.12
-6,1,19:18.4
7,1,19:18.12
8,1,19:18.12
-4,2,19:18.4
1,2,19:18.12
6,2,19:18.12
7,2,19:18.12
-3,3,19:18.4
-2,3,19:17.12
-1,3,19:18.4
1,3,19:18.4
5,3,19:18.12
6,3,19:18.12
-5,4,19:18.4
-4,4,19:18.4
-3,4,19:18.4
0,4,19:18.4
4,4,19:18.12
5,4,19:18.12
6,4,19:18.12
7,4,19:17.12
8,4,19:18.12
-4,5,19:18.4
-2,5,19:18.4
-1,5,19:18.4
0,5,19:17.12
4,5,19:18.4
5,5,19:18.4
8,5,19:18.4
2,6,19:18.4
3,6,19:18.4
4,6,19:18.4
5,6,19:17.12
7,6,19:18.4
0,7,19:18.4
3,7,19:17.12
5,7,19:18.4
6,7,19:18.4
0,8,19:18.4
3,8,19:18.4
5,8,19:18.4
5,9,19:18.4
6,9,19:18.4
-3,-10,20:18.12
-1,-10,20:18.12
-3,-9,20:18.12
-1,-9,20:18.12
0,-9,20:18.12
1,-9,20:18.12
6,-9,20:18.4
-9,-8,20:18.4
-5,-8,20:18.4
-4,-8,20:18.4
-3,-8,20:18.12
-2,-8,20:18.12
0,-8,20:18.12
1,-8,20:18.12
4,-8,20:18.4
5,-8,20:18.4
7,-8,20:18.4
-5,-7,20:18.4
-4,-7,20:18.4
-3,-7,20:18.12
-2,-7,20:17.12
-1,-7,20:18.12
0,-7,20:18.12
1,-7,20:18.12
2,-7,20:18.12
3,-7,20:18.12
6,-7,20:18.4
7,-7,20:18.4
8,-7,20:18.4
-7,-6,20:18.4
-6,-6,20:18.4
-4,-6,20:18.4
0,-6,20:17.12
1,-6,20:18.12
2,-6,20:18.12
4,-6,20:18.12
5,-6,20:18.12
6,-6,20:18.4
7,-6,20:18.4
8,-6,20:18.4
-7,-5,20:18.4
-6,-5,20:18.4
-4,-5,20:18.4
-2,-5,20:18.12
-1,-5,20:18.12
0,-5,20:18.12
1,-5,20:18.12
2,-5,20:18.12
3,-5,20:18.12
4,-5,20:18.12
5,-5,20:18.12
6,-5,20:18.4
8,-5,20:18.4
-8,-4,20:18.4
-7,-4,20:18.4
-3,-4,20:18.12
-2,-4,20:18.12
-1,-4,20:18.12
4,-4,20:17.12
6,-4,20:18.12
-8,-3,20:18.4
-7,-3,20:18.4
-6,-3,20:18.4
-4,-3,20:18.4
4,-3,20:18.4
6,-3,20:18.12
7,-3,20:18.4
8,-3,20:18.4
-9,-2,20:18.4
-8,-2,20:18.4
-6,-2,20:17.12
-5,-2,20:18.4
-3,-2,20:18.4
-2,-2,20:17.12
3,-2,20:18.12
-9,-1,20:18.4
-8,-1,20:18.4
-7,-1,20:18.4
-6,-1,20:18.4
-3,-1,20:18.4
5,-1,20:18.12
6,-1,20:18.12
7,-1,20:18.12
8,-1,20:18.12
9,-1,20:18.12
-7,0,20:18.4
-6,0,20:18.4
-5,0,20:18.4
-3,0,20:18.4
-2,0,20:18.12
-1,0,20:18.12
7,0,20:18.12
9,0,20:18.12
-7,1,20:18.4
-6,1,20:18.4
-5,1,20:18.4
-4,1,20:18.4
-1,1,20:18.12
0,1,20:18.12
2,1,20:18.12
6,1,20:18.12
-5,2,20:18.4
-4,2,20:18.4
-3,2,20:18.4
-2,2,20:18.12
0,2,20:18.12
1,2,20:18.12
2,2,20:18.12
6,2,20:18.12
7,2,20:18.12
-4,3,20:18.4
-3,3,20:18.4
-2,3,20:17.12
-1,3,20:18.4
0,3,20:18.4
2,3,20:18.4
3,3,20:18.12
5,3,20:18.12
6,3,20:18.12
7,3,20:18.12
9,3,20:18.12
-5,4,20:18.4
-2,4,20:18.4
1,4,20:17.12
2,4,20:18.4
4,4,20:18.12
5,4,20:18.12
7,4,20:17.12
9,4,20:18.12
-2,5,20:18.4
-1,5,20:18.4
0,5,20:18.4
1,5,20:18.4
2,5,20:18.4
3,5,20:18.4
5,5,20:18.4
6,5,20:18.4
2,6,20:18.4
3,6,20:18.4
5,6,20:17.12
6,6,20:18.4
8,6,20:18.4
0,7,20:18.4
1,7,20:18.4
2,7,20:18.4
3,7,20:17.12
5,7,20:18.4
6,7,20:18.4
7,7,20:18.4
8,7,20:18.4
1,8,20:18.4
3,8,20:18.4
6,8,20:18.4
1,9,20:18.4
3,9,20:18.4
5,9,20:18.4
4,10,20:18.4
-2,-10,21:18.12
1,-10,21:18.12
2,-10,21:18.12
3,-10,21:18.4
4,-10,21:18.4
-4,-9,21:18.4
-1,-9,21:18.12
0,-9,21:18.12
-4,-8,21:18.4
-2,-8,21:18.12
-1,-8,21:18.12
0,-8,21:18.12
1,-8,21:18.12
3,-8,21:18.12
4,-8,21:18.12
6,-8,21:18.4
-7,-7,21:18.4
-4,-7,21:18.4
-3,-7,21:18.12
-2,-7,21:18.12
4,-7,21:18.12
-7,-6,21:18.4
-1,-6,21:18.12
0,-6,21:17.12
2,-6,21:18.4
4,-6,21:18.12
-7,-5,21:18.4
-4,-5,21:18.4
-2,-5,21:18.12
-1,-5,21:18.12
3,-5,21:18.12
4,-5,21:18.12
5,-5,21:18.4
6,-5,21:18.12
7,-5,21:18.4
-6,-4,21:18.4
-2,-4,21:18.12
0,-4,21:18.12
4,-4,21:17.12
5,-4,21:18.12
6,-4,21:18.12
7,-4,21:18.12
4,-3,21:18.12
-8,-2,21:18.4
-2,-2,21:17.12
6,-2,21:18.12
-6,-1,21:18.4
4,-1,21:18.12
7,-1,21:18.12
-3,0,21:18.4
2,0,21:18.12
7,0,21:18.12
-6,1,21:18.4
-5,1,21:18.4
-4,1,21:18.4
-2,1,21:18.4
-1,1,21:18.12
2,1,21:18.12
3,1,21:18.12
5,1,21:18.12
6,1,21:18.12
8,1,21:18.12
-2,2,21:18.4
-1,2,21:18.4
1,2,21:18.4
2,2,21:18.4
3,2,21:18.12
5,2,21:18.12
6,2,21:18.12
7,2,21:18.12
9,2,21:18.12
-4,3,21:18.4
-3,3,21:18.4
-1,3,21:18.4
0,3,21:18.4
2,3,21:18.4
3,3,21:18.12
4,3,21:18.12
5,3,21:18.12
6,3,21:18.12
8,3,21:18.12
1,4,21:17.12
3,4,21:18.4
5,4,21:18.4
6,4,21:18.4
7,4,21:17.12
8,4,21:18.4
10,4,21:18.4
-3,5,21:18.4
-2,5,21:18.4
0,5,21:18.4
1,5,21:18.4
5,5,21:18.4
6,5,21:18.4
7,5,21:18.4
8,5,21:18.4
10,5,21:18.4
-2,6,21:18.4
-1,6,21:18.4
3,6,21:18.4
5,6,21:18.4
6,6,21:18.4
7,6,21:18.4
8,6,21:18.4
0,7,21:18.4
1,7,21:18.4
3,7,21:18.4
4,7,21:18.4
5,7,21:18.4
3,8,21:18.4
6,8,21:18.4
2,10,21:18.4
4,10,21:18.4
1,-9,22:18.12
-3,-8,22:18.12
-2,-8,22:18.12
-1,-8,22:18.12
0,-8,22:18.12
1,-8,22:18.12
4,-8,22:18.12
5,-8,22:18.4
-4,-7,22:18.4
-3,-7,22:18.12
-2,-7,22:18.12
-1,-7,22:18.12
0,-7,22:18.12
1,-7,22:17.12
2,-7,22:18.12
3,-7,22:18.12
4,-7,22:18.12
-2,-6,22:18.12
0,-6,22:18.12
1,-6,22:18.12
5,-6,22:18.12
6,-6,22:18.12
-4,-5,22:18.4
-2,-5,22:18.12
1,-5,22:18.12
2,-5,22:18.12
4,-5,22:18.12
5,-5,22:18.12
6,-5,22:18.12
-6,-4,22:18.4
-4,-4,22:18.4
1,-4,22:18.12
2,-4,22:18.12
3,-4,22:18.12
4,-4,22:17.12
5,-4,22:18.12
6,-4,22:18.12
-5,-3,22:18.4
1,-3,22:18.12
3,-3,22:18.12
4,-3,22:18.12
6,-3,22:18.12
-7,-2,22:18.4
-6,-2,22:18.4
-3,-2,22:17.12
-2,-2,22:18.4
-1,-2,22:18.12
2,-2,22:18.12
4,-2,22:18.12
5,-2,22:18.12
6,-2,22:18.12
-5,-1,22:18.4
0,-1,22:18.12
1,-1,22:18.12
2,-1,22:18.12
3,-1,22:18.12
5,-1,22:18.12
-6,0,22:18.4
1,0,22:18.12
2,0,22:18.12
3,0,22:18.12
-4,1,22:18.4
-3,1,22:18.4
-2,1,22:18.4
-1,1,22:18.12
0,1,22:18.12
1,1,22:18.12
4,1,22:18.12
1,2,22:18.4
3,2,22:18.12
4,2,22:18.12
5,2,22:18.12
8,2,22:18.12
9,2,22:18.12
-2,3,22:18.4
-1,3,22:18.4
0,3,22:18.4
1,3,22:17.12
2,3,22:17.12
3,3,22:18.12
4,3,22:18.12
9,3,22:18.12
2,4,22:18.4
3,4,22:18.4
5,4,22:18.4
6,4,22:18.4
7,4,22:18.4
8,4,22:18.4
9,4,22:18.4
10,4,22:18.4
-1,5,22:18.4
1,5,22:18.4
3,5,22:18.4
5,5,22:18.4
3,6,22:18.4
4,6,22:18.4
5,6,22:18.4
6,6,22:18.4
7,6,22:18.4
3,7,22:18.4
6,7,22:18.4
7,7,22:18.4
1,8,22:18.4
2,8,22:18.4
3,8,22:18.4
5,8,22:18.4
3,9,22:18.4
4,9,22:18.4
1,-10,23:18.12
0,-9,23:18.12
-2,-8,23:18.4
-1,-8,23:18.4
0,-8,23:18.12
1,-8,23:18.12
3,-8,23:18.12
-3,-7,23:18.4
-2,-7,23:18.4
-1,-7,23:18.12
1,-7,23:18.12
2,-7,23:18.12
4,-7,23:18.12
-2,-6,23:18.4
-1,-6,23:18.12
0,-6,23:18.12
3,-6,23:18.12
4,-6,23:18.12
5,-6,23:18.12
1,-5,23:18.12
3,-5,23:18.12
4,-5,23:18.12
6,-5,23:18.12
-2,-4,23:18.4
1,-4,23:18.12
2,-4,23:18.12
3,-4,23:18.12
4,-4,23:18.12
-7,-3,23:18.4
-6,-3,23:18.4
-1,-3,23:18.12
0,-3,23:18.12
1,-3,23:18.12
6,-3,23:18.12
-7,-2,23:18.4
-6,-2,23:18.4
-3,-2,23:17.12
-2,-2,23:18.4
-1,-2,23:18.12
3,-2,23:18.12
4,-2,23:18.12
-6,-1,23:18.4
-1,-1,23:18.12
0,-1,23:18.12
1,-1,23:18.12
-2,0,23:18.4
-1,0,23:18.12
0,0,23:18.12
1,0,23:18.12
2,0,23:18.12
3,0,23:18.12
4,0,23:18.12
0,1,23:18.12
1,1,23:18.12
3,1,23:18.12
4,1,23:18.12
5,1,23:18.12
0,2,23:18.4
1,2,23:17.12
3,2,23:18.4
4,2,23:18.4
7,2,23:18.4
9,2,23:18.4
-2,3,23:18.4
0,3,23:18.4
1,3,23:18.4
3,3,23:17.12
4,3,23:18.4
6,3,23:18.4
8,3,23:18.4
-3,4,23:18.4
-2,4,23:18.4
-1,4,23:18.4
0,4,23:18.4
1,4,23:18.4
2,4,23:18.4
3,4,23:18.4
5,4,23:18.4
6,4,23:18.4
8,4,23:18.4
0,5,23:18.4
1,5,23:18.4
4,5,23:18.4
7,5,23:18.4
2,6,23:18.4
3,6,23:18.4
4,6,23:18.4
5,6,23:18.4
6,6,23:18.4
9,6,23:18.4
2,7,23:18.4
3,7,23:18.4
5,7,23:18.4
6,7,23:18.4
4,8,23:18.4
0,-9,24:18.4
1,-8,24:18.12
1,-7,24:18.12
2,-7,24:18.12
-1,-6,24:18.4
1,-6,24:18.12
3,-6,24:18.12
6,-6,24:18.12
-1,-5,24:18.4
2,-5,24:18.12
3,-5,24:18.12
6,-5,24:18.12
0,-4,24:18.12
1,-4,24:18.12
2,-4,24:18.12
5,-4,24:18.12
6,-4,24:18.12
-3,-3,24:18.4
4,-3,24:18.12
6,-3,24:18.12
-4,-2,24:18.4
-1,-2,24:18.4
0,-2,24:18.12
1,-2,24:18.12
2,-2,24:18.12
3,-2,24:18.12
5,-2,24:18.12
-3,-1,24:17.12
0,-1,24:18.12
2,-1,24:18.12
-4,0,24:18.4
-3,0,24:18.4
0,0,24:18.12
1,0,24:18.12
-3,1,24:18.4
-1,1,24:18.4
1,1,24:18.4
2,1,24:18.4
3,1,24:18.4
4,1,24:18.4
-1,2,24:18.4
1,2,24:18.4
2,2,24:18.4
3,2,24:18.4
4,2,24:18.4
5,2,24:18.4
0,3,24:18.4
1,3,24:18.4
3,3,24:18.4
4,3,24:18.4
6,3,24:18.4
1,4,24:18.4
2,4,24:18.4
3,4,24:18.4
7,4,24:18.4
8,4,24:18.4
1,5,24:18.4
3,5,24:18.4
6,5,24:18.4
2,6,24:18.4
3,6,24:18.4
1,-8,25:18.4
0,-7,25:18.4
1,-7,25:18.4
1,-6,25:18.4
-2,-5,25:18.4
3,-5,25:18.4
4,-5,25:18.4
5,-5,25:18.4
-2,-4,25:18.4
-1,-4,25:18.4
1,-4,25:18.4
4,-4,25:18.4
5,-4,25:18.4
-3,-3,25:18.4
-2,-3,25:18.4
-1,-3,25:18.4
0,-3,25:18.4
1,-3,25:18.4
2,-3,25:18.4
4,-3,25:18.4
-4,-2,25:18.4
-3,-2,25:18.4
-2,-2,25:18.4
-1,-2,25:18.4
0,-2,25:18.4
1,-2,25:18.4
2,-2,25:18.4
-4,-1,25:18.4
-3,-1,25:17.12
-2,-1,25:18.4
-1,-1,25:18.4
0,-1,25:18.4
1,-1,25:18.4
2,-1,25:18.4
-4,0,25:18.4
-3,0,25:18.4
-2,0,25:18.4
-1,0,25:18.4
0,0,25:18.4
3,0,25:18.4
-4,1,25:18.4
-3,1,25:18.4
-2,1,25:18.4
0,1,25:18.4
2,1,25:18.4
3,1,25:18.4
-5,2,25:18.4
-4,2,25:18.4
-3,2,25:18.4
-2,2,25:18.4
-1,2,25:18.4
3,2,25:18.4
5,2,25:18.4
1,3,25:18.4
2,3,25:18.4
1,4,25:18.4
3,4,25:18.4
5,4,25:18.4
2,5,25:18.4
3,5,25:18.4
5,5,25:18.4
-1,-5,26:18.4
-1,-4,26:18.4
0,-4,26:18.4
-4,-3,26:18.4
-3,-3,26:18.4
-1,-3,26:18.4
0,-3,26:18.4
1,-3,26:18.4
-3,-2,26:18.4
-1,-2,26:18.4
0,-2,26:18.4
1,-2,26:18.4
-3,-1,26:18.4
-2,-1,26:18.4
-1,-1,26:18.4
0,-1,26:18.4
-6,0,26:18.4
-5,0,26:18.4
-3,0,26:17.12
-1,0,26:18.4
0,0,26:18.4
-4,1,26:18.4
-4,2,26:18.4
1,2,26:18.4
-4,3,26:18.4
-3,3,26:18.4
-2,3,26:18.4
0,3,26:18.4
1,3,26:18.4
3,3,26:18.4
4,3,26:18.4
3,4,26:18.4
-3,-4,27:18.4
-2,-4,27:18.4
0,-4,27:18.4
-2,-3,27:18.4
-1,-3,27:18.4
0,-3,27:18.4
1,-3,27:18.4
-4,-2,27:18.4
-3,-2,27:18.4
-2,-2,27:18.4
-1,-2,27:18.4
-6,-1,27:18.4
-3,-1,27:18.4
-2,-1,27:18.4
-1,-1,27:18.4
1,-1,27:18.4
-6,0,27:18.4
-5,0,27:18.4
-4,0,27:18.4
-3,0,27:17.12
-2,0,27:18.4
-1,0,27:18.4
0,0,27:18.4
-3,1,27:18.4
-1,1,27:18.4
-5,2,27:18.4
-4,2,27:18.4
-3,2,27:18.4
-3,3,27:18.4
-2,-3,28:18.4
-1,-3,28:18.4
-2,-2,28:18.4
-5,-1,28:18.4
-3,-1,28:18.4
-2,-1,28:18.4
-1,-1,28:18.4
0,-1,28:18.4
-3,0,28:18.4
-1,0,28:18.4
-3,2,28:18.4
-2,2,28:18.4
-4,3,28:18.4
-3,3,28:18.4
-3,-2,29:18.4
-5,-1,29:18.4
-1,-1,29:18.4
-4,0,29:18.4
-3,0,29:18.4
-2,0,29:18.4
-4,1,29:18.4
-1,1,29:18.4
-4,2,29:18.4
-3,2,29:18.4
-1,2,29:18.4
-3,-1,30:18.4
-2,-1,30:18.4
-2,0,30:18.4
