[META]
version=2.0
spawnOnBlockType=2
spawnSunlight=True
spawnDarkness=True
spawnWater=False
spawnLava=False
underFill=False
randomRotation=True
dig=True
tree=False
branch=False
needsFoundation=True
rarity=100
collisionPercentage=20
spawnElevationMin=0
spawnElevationMax=200
spawnInBiome=Custom
[DATA]
1,0,0:17.12
1,0,1:17.12
0,1,1:17.12
2,1,1:17.12
1,-1,2:17.12
0,0,2:17.12
1,0,2:17.12
0,1,2:17.12
2,1,2:17.12
1,-1,3:17.12
0,0,3:17.12
1,0,3:17.12
0,1,3:17.12
2,1,3:17.12
0,0,4:17.12
1,0,4:17.12
0,0,5:17.12
1,0,5:17.12
1,2,5:18.12
2,2,5:18.12
-3,3,5:18.12
-2,3,5:18.12
-1,3,5:18.12
0,3,5:18.12
1,3,5:18.12
2,3,5:18.12
-1,4,5:18.12
0,0,6:17.12
1,0,6:17.12
-2,1,6:18.12
-1,1,6:18.12
0,1,6:17.12
3,1,6:18.12
0,2,6:18.12
3,2,6:18.12
-2,3,6:18.12
-1,3,6:18.12
1,3,6:18.12
3,3,6:18.12
-2,4,6:18.12
1,4,6:18.12
3,4,6:18.12
2,5,6:18.12
3,5,6:18.12
3,-3,7:18.12
3,-1,7:18.12
-3,0,7:18.12
0,0,7:17.12
1,0,7:18.12
-1,2,7:17.12
0,2,7:17.12
1,2,7:18.12
-5,3,7:18.12
-3,3,7:18.12
-2,3,7:18.12
-1,3,7:18.12
0,3,7:18.12
1,3,7:18.12
2,3,7:18.12
3,3,7:18.12
4,3,7:18.12
-5,4,7:18.12
-3,4,7:18.12
-1,4,7:18.12
0,4,7:18.12
1,4,7:18.12
3,4,7:18.12
-2,5,7:18.12
0,5,7:18.12
2,5,7:18.12
0,6,7:18.12
2,6,7:18.12
5,-4,8:18.12
2,-3,8:18.12
1,-2,8:18.12
2,-2,8:18.12
3,-2,8:18.12
4,-2,8:18.12
1,-1,8:17.12
-3,0,8:18.12
-2,0,8:18.12
0,0,8:17.12
1,0,8:18.12
2,0,8:18.12
3,0,8:18.12
5,0,8:18.12
-4,1,8:18.12
-3,1,8:18.12
-1,1,8:18.12
0,1,8:18.12
-4,2,8:18.12
-3,2,8:18.12
-1,2,8:18.12
0,2,8:18.12
1,2,8:18.12
4,2,8:18.12
-5,3,8:18.12
-4,3,8:18.12
-3,3,8:18.12
-2,3,8:17.12
-1,3,8:18.12
0,3,8:18.12
1,3,8:17.12
2,3,8:18.12
-4,4,8:18.12
-2,4,8:18.12
-1,4,8:18.12
0,4,8:18.12
3,4,8:18.12
4,4,8:18.12
-4,5,8:18.12
-3,5,8:18.12
-1,5,8:18.12
1,5,8:18.12
2,5,8:18.12
-3,6,8:18.12
1,6,8:18.12
2,6,8:18.12
2,-5,9:18.12
2,-4,9:18.12
0,-3,9:18.12
3,-3,9:18.12
-3,-2,9:18.12
-2,-2,9:18.12
2,-2,9:17.12
-4,-1,9:18.12
-1,-1,9:18.12
0,-1,9:18.12
4,-1,9:18.12
-3,0,9:18.12
-2,0,9:18.12
-1,0,9:17.12
0,0,9:17.12
1,0,9:18.12
3,0,9:18.12
5,0,9:18.12
-4,1,9:18.12
-3,1,9:18.12
-2,1,9:18.12
-1,1,9:18.12
0,1,9:18.12
3,1,9:18.12
4,1,9:18.12
-3,2,9:18.12
-2,2,9:18.12
-1,2,9:18.12
0,2,9:18.12
1,2,9:18.12
2,2,9:18.12
-5,3,9:18.12
0,3,9:18.12
1,3,9:18.12
2,3,9:18.12
-5,4,9:18.12
-4,5,9:18.12
-2,5,9:18.12
-1,5,9:18.12
0,5,9:18.12
1,5,9:18.12
0,6,9:18.12
2,-5,10:18.12
1,-4,10:18.12
3,-4,10:18.12
-3,-3,10:18.12
0,-3,10:18.12
2,-3,10:18.12
3,-3,10:18.12
-4,-2,10:18.12
2,-2,10:18.12
3,-2,10:17.12
6,-2,10:18.4
-4,-1,10:18.12
0,-1,10:18.12
1,-1,10:18.12
2,-1,10:18.12
4,-1,10:18.12
6,-1,10:18.4
-5,0,10:18.12
-4,0,10:18.12
-3,0,10:18.12
-2,0,10:17.12
-1,0,10:18.12
0,0,10:17.12
1,0,10:18.12
2,0,10:18.12
3,0,10:18.12
5,0,10:18.12
-3,1,10:18.12
-2,1,10:18.12
-1,1,10:18.12
0,1,10:18.12
2,1,10:18.12
3,1,10:18.12
-3,2,10:18.12
3,2,10:18.12
4,2,10:18.12
-3,3,10:18.12
-2,3,10:18.12
0,3,10:18.12
1,3,10:18.12
3,3,10:18.12
0,4,10:18.12
1,4,10:18.12
-2,5,10:18.12
0,5,10:18.12
1,5,10:18.12
3,-5,11:18.12
2,-4,11:18.12
5,-4,11:18.12
-4,-3,11:18.12
-3,-3,11:18.12
-2,-3,11:18.12
0,-3,11:18.12
2,-3,11:18.12
3,-3,11:18.12
5,-3,11:18.12
-3,-2,11:18.12
-2,-2,11:18.12
1,-2,11:18.12
3,-2,11:18.12
5,-2,11:18.12
-6,-1,11:18.4
-4,-1,11:18.12
-3,-1,11:18.12
-2,-1,11:18.12
3,-1,11:18.12
-6,0,11:18.4
-4,0,11:18.12
-3,0,11:17.12
-2,0,11:18.12
0,0,11:17.12
1,0,11:17.12
2,0,11:17.12
5,0,11:18.12
-5,1,11:18.12
-4,1,11:18.12
0,1,11:18.12
1,1,11:18.12
3,1,11:18.12
4,1,11:18.12
-5,2,11:18.12
-4,2,11:18.12
-2,2,11:18.12
-1,2,11:18.12
0,2,11:18.12
1,2,11:18.12
2,2,11:18.12
3,2,11:18.12
5,2,11:18.12
-2,3,11:18.12
-1,3,11:18.12
1,3,11:18.12
2,3,11:18.12
3,3,11:18.12
-2,4,11:18.12
1,4,11:18.12
-5,-5,12:18.4
3,-4,12:18.12
-3,-3,12:18.12
-2,-3,12:18.12
-1,-3,12:18.12
3,-3,12:18.12
4,-3,12:18.12
-3,-2,12:18.12
-1,-2,12:18.12
3,-2,12:18.12
4,-2,12:18.12
5,-2,12:18.12
-3,-1,12:18.12
1,-1,12:18.12
5,-1,12:18.12
-4,0,12:18.12
-3,0,12:18.12
-2,0,12:18.12
-1,0,12:18.12
0,0,12:17.12
1,0,12:18.12
2,0,12:18.12
3,0,12:18.12
4,0,12:18.12
-6,1,12:18.4
0,1,12:17.12
2,1,12:18.12
3,1,12:17.12
4,1,12:18.12
6,1,12:18.4
-5,2,12:18.12
-1,2,12:18.12
0,2,12:18.12
3,2,12:18.12
4,2,12:18.12
5,2,12:18.12
-4,3,12:18.12
-3,3,12:18.12
-2,3,12:18.12
-1,3,12:18.12
0,3,12:18.12
5,3,12:18.12
-3,4,12:18.12
-1,4,12:18.12
0,4,12:18.12
2,4,12:18.12
4,4,12:18.12
0,5,12:18.12
-4,-6,13:18.4
-2,-5,13:18.4
-5,-4,13:18.12
-1,-4,13:18.12
0,-4,13:18.12
-4,-3,13:18.12
-3,-3,13:18.12
0,-3,13:18.12
1,-3,13:18.12
2,-3,13:18.12
-6,-2,13:18.4
-3,-2,13:18.12
-2,-2,13:17.12
-1,-2,13:18.12
0,-2,13:18.12
3,-2,13:18.12
-5,-1,13:18.12
-3,-1,13:18.12
-1,-1,13:17.12
2,-1,13:18.12
3,-1,13:18.12
4,-1,13:18.12
5,-1,13:18.4
-5,0,13:18.12
-4,0,13:18.12
-3,0,13:18.12
0,0,13:17.12
-2,1,13:18.12
-1,1,13:18.12
0,1,13:18.12
1,1,13:18.12
2,1,13:18.12
5,1,13:18.4
6,1,13:18.4
-1,2,13:18.12
0,2,13:17.12
2,2,13:18.12
3,2,13:18.12
5,2,13:18.4
-4,3,13:18.12
-3,3,13:18.12
-2,3,13:18.12
-1,3,13:18.12
0,3,13:18.12
5,3,13:18.4
2,4,13:18.12
3,4,13:18.12
-1,5,13:18.4
1,5,13:18.4
-1,6,13:18.4
0,6,13:18.4
-3,-6,14:18.4
-2,-6,14:18.4
-4,-5,14:18.4
-3,-5,14:18.4
-2,-5,14:18.4
-1,-5,14:18.4
-5,-4,14:18.4
-4,-4,14:18.4
-3,-4,14:18.4
-2,-4,14:18.4
-1,-4,14:18.4
0,-4,14:18.4
1,-4,14:18.4
2,-4,14:18.4
-6,-3,14:18.4
-5,-3,14:18.4
-4,-3,14:18.4
-3,-3,14:17.12
-2,-3,14:18.4
-1,-3,14:18.4
0,-3,14:18.4
2,-3,14:18.4
-5,-2,14:18.4
-3,-2,14:18.4
-2,-2,14:18.4
-1,-2,14:18.4
0,-2,14:18.4
-4,-1,14:18.4
-3,-1,14:18.4
-2,-1,14:18.4
-1,-1,14:18.4
1,-1,14:18.4
2,-1,14:18.4
3,-1,14:18.4
5,-1,14:18.4
-4,0,14:18.4
-3,0,14:18.4
-2,0,14:18.4
-1,0,14:18.4
0,0,14:17.12
-4,1,14:18.4
-2,1,14:18.4
-1,1,14:18.4
0,1,14:18.4
1,1,14:18.4
3,1,14:18.4
4,1,14:18.4
-3,2,14:18.4
-2,2,14:18.4
-1,2,14:18.4
0,2,14:18.4
2,2,14:18.4
-3,3,14:18.4
-2,3,14:18.4
-1,3,14:17.12
0,3,14:18.4
1,3,14:18.4
2,3,14:18.4
5,3,14:18.4
-3,4,14:18.4
-2,4,14:18.4
0,4,14:18.4
1,4,14:18.4
-1,5,14:18.4
0,5,14:18.4
1,5,14:18.4
-2,6,14:18.4
-1,6,14:18.4
-1,-6,15:18.4
-1,-5,15:18.4
0,-5,15:18.4
1,-5,15:18.4
-5,-4,15:18.4
3,-4,15:18.4
-3,-3,15:18.4
-2,-3,15:18.4
-1,-3,15:18.4
0,-3,15:18.4
-6,-2,15:18.4
-4,-2,15:18.4
-3,-2,15:18.4
-2,-2,15:18.4
0,-2,15:17.12
-1,-1,15:18.4
0,-1,15:17.12
1,-1,15:18.4
3,-1,15:18.4
-4,0,15:18.4
-3,0,15:18.4
-2,0,15:18.4
0,0,15:17.12
3,0,15:18.4
4,0,15:18.4
-5,1,15:18.4
-2,1,15:18.4
-1,1,15:18.4
0,1,15:18.4
2,1,15:18.4
3,1,15:18.4
4,1,15:18.4
-3,2,15:18.4
-1,2,15:18.4
-5,3,15:18.4
-4,3,15:18.4
-3,3,15:18.4
-2,3,15:18.4
-1,3,15:18.4
2,3,15:18.4
-3,4,15:18.4
-5,5,15:18.4
-3,5,15:18.4
-2,5,15:18.4
-1,5,15:18.4
0,5,15:18.4
-1,-6,16:18.4
-5,-5,16:18.4
-4,-5,16:18.4
-1,-5,16:18.4
0,-5,16:18.4
-5,-4,16:18.4
-3,-4,16:18.4
-2,-4,16:18.4
-1,-4,16:18.4
0,-4,16:18.4
-5,-3,16:18.4
-4,-3,16:18.4
-3,-3,16:18.4
-2,-3,16:18.4
-1,-3,16:18.4
0,-3,16:17.12
1,-3,16:18.4
2,-3,16:18.4
-5,-2,16:18.4
-3,-2,16:18.4
-2,-2,16:18.4
0,-2,16:18.4
2,-2,16:18.4
3,-2,16:18.4
4,-2,16:18.4
-3,-1,16:18.4
-2,-1,16:18.4
0,-1,16:18.4
1,-1,16:18.4
3,-1,16:18.4
5,-1,16:18.4
-1,0,16:18.4
0,0,16:17.12
1,0,16:18.4
-3,1,16:18.4
-1,1,16:17.12
1,1,16:18.4
5,1,16:18.4
-6,2,16:18.4
-2,2,16:17.12
-1,2,16:18.4
0,2,16:18.4
1,2,16:18.4
4,2,16:18.4
-6,3,16:18.4
-4,3,16:18.4
-3,3,16:18.4
-2,3,16:18.4
-1,3,16:18.4
0,3,16:18.4
-6,4,16:18.4
-5,4,16:18.4
-2,4,16:18.4
-1,4,16:18.4
-3,5,16:18.4
-1,5,16:18.4
1,5,16:18.4
-3,6,16:18.4
-1,-6,17:18.4
-1,-5,17:18.4
0,-5,17:18.4
-4,-4,17:18.4
-2,-4,17:18.4
0,-4,17:18.4
3,-4,17:18.4
-4,-3,17:18.4
-3,-3,17:18.4
-2,-3,17:18.4
3,-3,17:18.4
-4,-2,17:18.4
-3,-2,17:18.4
3,-2,17:18.4
0,-1,17:18.4
2,-1,17:18.4
4,-1,17:18.4
-4,0,17:18.4
0,0,17:17.12
1,0,17:17.12
2,0,17:17.12
3,0,17:18.4
5,0,17:18.4
-2,1,17:18.4
3,1,17:18.4
-6,2,17:18.4
-5,2,17:18.4
-4,2,17:18.4
-1,2,17:18.4
0,2,17:18.4
1,2,17:18.4
-6,3,17:18.4
-5,3,17:18.4
-4,3,17:18.4
-3,3,17:17.12
-2,3,17:18.4
-1,3,17:18.4
0,3,17:18.4
-4,4,17:18.4
-3,4,17:18.4
-2,4,17:18.4
0,4,17:18.4
-5,5,17:18.4
-3,5,17:18.4
-1,5,17:18.4
-3,6,17:18.4
-1,-5,18:18.4
0,-5,18:18.4
0,-4,18:18.4
1,-4,18:18.4
-1,-3,18:18.4
0,-3,18:18.4
2,-3,18:18.4
0,-2,18:18.4
1,-2,18:18.4
2,-2,18:18.4
3,-2,18:18.4
0,-1,18:18.4
1,-1,18:18.4
3,-1,18:18.4
5,-1,18:18.4
6,-1,18:18.4
-3,0,18:18.4
0,0,18:17.12
1,0,18:18.4
3,0,18:17.12
4,0,18:18.4
5,0,18:18.4
6,0,18:18.4
-5,1,18:18.4
-2,1,18:18.4
-1,1,18:18.4
0,1,18:18.4
1,1,18:18.4
2,1,18:18.4
5,1,18:18.4
-6,2,18:18.4
-4,2,18:18.4
0,2,18:18.4
3,2,18:18.4
5,2,18:18.4
-5,3,18:18.4
-4,3,18:18.4
-3,3,18:18.4
-2,3,18:18.4
-1,3,18:18.4
0,3,18:18.4
2,3,18:18.4
4,3,18:18.4
-6,4,18:18.4
-1,4,18:18.4
0,4,18:18.4
2,4,18:18.4
-2,5,18:18.4
-1,5,18:18.4
0,5,18:18.4
-2,-4,19:18.4
0,-4,19:18.4
-1,-3,19:18.4
0,-3,19:18.4
2,-3,19:18.4
0,-2,19:18.4
1,-2,19:18.4
2,-2,19:18.4
5,-2,19:18.4
2,-1,19:18.4
3,-1,19:18.4
0,0,19:17.12
2,0,19:18.4
3,0,19:18.4
4,0,19:18.4
-3,1,19:18.4
-2,1,19:18.4
-1,1,19:18.4
0,1,19:17.12
2,1,19:18.4
3,1,19:18.4
-3,2,19:18.4
-2,2,19:18.4
-1,2,19:18.4
0,2,19:17.12
2,2,19:18.4
3,2,19:18.4
5,2,19:18.4
-3,3,19:18.4
-2,3,19:18.4
1,3,19:18.4
3,3,19:18.4
4,3,19:18.4
0,4,19:18.4
-5,5,19:18.4
-2,5,19:18.4
-1,-6,20:18.4
-2,-4,20:18.4
0,-4,20:18.4
3,-4,20:18.4
0,-3,20:18.4
2,-3,20:18.4
3,-3,20:18.4
-3,-2,20:18.4
0,-2,20:17.12
1,-2,20:18.4
2,-2,20:18.4
3,-2,20:18.4
-3,-1,20:18.4
-2,-1,20:18.4
0,-1,20:17.12
1,-1,20:18.4
2,-1,20:18.4
3,-1,20:18.4
4,-1,20:18.4
5,-1,20:18.4
-4,0,20:18.4
-3,0,20:18.4
-2,0,20:18.4
0,0,20:17.12
1,0,20:18.4
2,0,20:18.4
3,0,20:18.4
4,0,20:18.4
5,0,20:18.4
-3,1,20:18.4
-2,1,20:18.4
0,1,20:18.4
1,1,20:18.4
2,1,20:18.4
3,1,20:18.4
-3,2,20:18.4
-2,2,20:18.4
0,2,20:18.4
1,2,20:18.4
3,2,20:18.4
-3,3,20:18.4
-2,3,20:18.4
-1,3,20:18.4
0,3,20:17.12
1,3,20:18.4
2,3,20:18.4
-4,4,20:18.4
-3,4,20:18.4
0,4,20:18.4
-2,5,20:18.4
0,5,20:18.4
2,5,20:18.4
0,6,20:18.4
0,-6,21:18.4
-2,-5,21:18.4
0,-5,21:18.4
-1,-4,21:18.4
1,-4,21:18.4
2,-4,21:18.4
-3,-3,21:18.4
-2,-3,21:18.4
0,-3,21:17.12
1,-3,21:18.4
2,-3,21:18.4
-5,-2,21:18.4
-4,-2,21:18.4
-3,-2,21:18.4
-2,-2,21:18.4
1,-2,21:18.4
3,-2,21:18.4
4,-2,21:18.4
-4,-1,21:18.4
-3,-1,21:18.4
0,-1,21:18.4
2,-1,21:18.4
3,-1,21:18.4
6,-1,21:18.4
-4,0,21:18.4
-3,0,21:18.4
-2,0,21:18.4
0,0,21:17.12
1,0,21:17.12
2,0,21:17.12
3,0,21:18.4
4,0,21:18.4
5,0,21:18.4
-4,1,21:18.4
0,1,21:18.4
2,1,21:18.4
3,1,21:18.4
5,1,21:18.4
-5,2,21:18.4
-4,2,21:18.4
1,2,21:18.4
2,2,21:18.4
5,2,21:18.4
-1,3,21:18.4
0,4,21:18.4
0,5,21:18.4
0,-6,22:18.4
1,-6,22:18.4
-1,-4,22:18.4
0,-4,22:18.4
-4,-3,22:18.4
-3,-3,22:18.4
-2,-3,22:18.4
-1,-3,22:18.4
0,-3,22:18.4
2,-3,22:18.4
3,-3,22:18.4
4,-3,22:18.4
-5,-2,22:18.4
-3,-2,22:18.4
0,-2,22:18.4
2,-2,22:18.4
-4,-1,22:18.4
-1,-1,22:18.4
0,-1,22:18.4
2,-1,22:18.4
3,-1,22:18.4
5,-1,22:18.4
6,-1,22:18.4
-5,0,22:18.4
-3,0,22:18.4
-2,0,22:17.12
-1,0,22:17.12
0,0,22:17.12
1,0,22:18.4
2,0,22:18.4
3,0,22:17.12
4,0,22:18.4
-3,1,22:18.4
-2,1,22:18.4
-1,1,22:18.4
1,1,22:18.4
2,1,22:18.4
3,1,22:18.4
4,1,22:18.4
5,1,22:18.4
6,1,22:18.4
-5,2,22:18.4
-3,2,22:18.4
-1,2,22:18.4
0,2,22:18.4
1,2,22:18.4
2,2,22:18.4
3,2,22:18.4
4,2,22:18.4
-4,3,22:18.4
-3,3,22:18.4
-2,3,22:18.4
0,3,22:18.4
1,3,22:18.4
2,3,22:18.4
4,3,22:18.4
0,4,22:18.4
2,4,22:18.4
2,5,22:18.4
-2,-5,23:18.4
-1,-5,23:18.4
0,-5,23:18.4
1,-5,23:18.4
2,-5,23:18.4
1,-4,23:18.4
-4,-3,23:18.4
-3,-3,23:18.4
-2,-3,23:18.4
0,-3,23:18.4
1,-3,23:18.4
2,-3,23:18.4
3,-3,23:18.4
4,-3,23:18.4
-5,-2,23:18.4
-2,-2,23:18.4
0,-2,23:18.4
3,-2,23:18.4
5,-2,23:18.4
-3,-1,23:18.4
-2,-1,23:18.4
-1,-1,23:18.4
0,-1,23:18.4
1,-1,23:18.4
5,-1,23:18.4
6,-1,23:18.4
-6,0,23:18.4
-3,0,23:17.12
-1,0,23:18.4
0,0,23:17.12
2,0,23:18.4
-6,1,23:18.4
-4,1,23:18.4
-3,1,23:18.4
-2,1,23:18.4
-1,1,23:18.4
0,1,23:18.4
6,1,23:18.4
-4,2,23:18.4
-3,2,23:18.4
-1,2,23:18.4
0,2,23:18.4
1,2,23:18.4
2,2,23:18.4
3,2,23:18.4
5,2,23:18.4
-4,3,23:18.4
-3,3,23:18.4
-2,3,23:18.4
-1,3,23:18.4
0,3,23:18.4
1,3,23:18.4
3,3,23:18.4
4,3,23:18.4
3,4,23:18.4
4,4,23:18.4
0,-6,24:18.4
2,-6,24:18.4
0,-5,24:18.4
-1,-4,24:18.4
0,-4,24:18.4
4,-4,24:18.4
-2,-3,24:18.4
-1,-3,24:18.4
0,-3,24:18.4
4,-3,24:18.4
-3,-2,24:18.4
-1,-2,24:18.4
0,-2,24:17.12
2,-2,24:18.4
3,-2,24:18.4
4,-2,24:18.4
5,-2,24:18.4
-4,-1,24:18.4
0,-1,24:17.12
1,-1,24:18.4
-4,0,24:18.4
-3,0,24:18.4
-2,0,24:18.4
0,0,24:17.12
1,0,24:18.4
2,0,24:18.4
3,0,24:18.4
4,0,24:18.4
5,0,24:18.4
-5,1,24:18.4
-2,1,24:18.4
-1,1,24:18.4
0,1,24:18.4
1,1,24:17.12
2,1,24:18.4
3,1,24:18.4
-2,2,24:18.4
0,2,24:18.4
2,2,24:18.4
4,2,24:18.4
5,2,24:18.4
-2,3,24:18.4
2,3,24:18.4
4,3,24:18.4
3,4,24:18.4
1,5,24:18.4
2,5,24:18.4
3,5,24:18.4
-1,-5,25:18.4
1,-5,25:18.4
2,-5,25:18.4
3,-4,25:18.4
-2,-3,25:18.4
-1,-3,25:18.4
0,-3,25:18.4
1,-3,25:17.12
2,-3,25:18.4
-2,-2,25:18.4
-1,-2,25:18.4
0,-2,25:18.4
1,-2,25:18.4
3,-2,25:18.4
-4,-1,25:18.4
-1,-1,25:18.4
0,-1,25:18.4
1,-1,25:18.4
2,-1,25:18.4
3,-1,25:18.4
-5,0,25:18.4
-4,0,25:18.4
-3,0,25:18.4
-2,0,25:18.4
-1,0,25:18.4
0,0,25:17.12
1,0,25:18.4
2,0,25:18.4
4,0,25:18.4
-3,1,25:18.4
-1,1,25:18.4
0,1,25:18.4
1,1,25:18.4
-2,2,25:18.4
-1,2,25:18.4
0,2,25:18.4
1,2,25:18.4
2,2,25:17.12
3,2,25:18.4
4,2,25:18.4
5,2,25:18.4
3,3,25:18.4
4,3,25:18.4
2,4,25:18.4
3,4,25:18.4
4,4,25:18.4
2,5,25:18.4
2,-6,26:18.4
-1,-5,26:18.4
1,-4,26:18.4
-1,-3,26:18.4
0,-3,26:18.4
1,-3,26:18.4
-2,-2,26:18.4
1,-2,26:18.4
2,-2,26:18.4
4,-2,26:18.4
-3,-1,26:18.4
-4,0,26:18.4
-2,0,26:18.4
0,0,26:17.12
2,0,26:18.4
3,0,26:18.4
-4,1,26:18.4
-3,1,26:18.4
1,1,26:18.4
2,1,26:18.4
3,1,26:18.4
4,1,26:18.4
-2,2,26:18.4
-1,2,26:18.4
1,2,26:18.4
2,2,26:18.4
3,2,26:18.4
4,2,26:18.4
0,3,26:18.4
4,3,26:18.4
3,4,26:18.4
4,4,26:18.4
-1,-4,27:18.4
-1,-3,27:18.4
0,-3,27:18.4
1,-3,27:18.4
-1,-2,27:18.4
1,-2,27:18.4
2,-2,27:18.4
-3,-1,27:18.4
-2,-1,27:18.4
0,-1,27:18.4
3,-1,27:18.4
-3,0,27:18.4
-2,0,27:18.4
-1,0,27:18.4
0,0,27:17.12
2,0,27:18.4
3,0,27:18.4
-3,1,27:18.4
-2,1,27:18.4
0,1,27:18.4
1,1,27:18.4
2,1,27:18.4
-2,2,27:18.4
0,2,27:18.4
1,2,27:18.4
2,2,27:18.4
4,2,27:18.4
-1,3,27:18.4
2,3,27:18.4
3,4,27:18.4
-1,-3,28:18.4
0,-3,28:18.4
1,-3,28:18.4
1,-2,28:18.4
0,-1,28:18.4
1,-1,28:18.4
1,0,28:18.4
-2,1,28:18.4
-1,1,28:18.4
0,1,28:18.4
1,1,28:18.4
3,1,28:18.4
0,2,28:18.4
1,2,28:18.4
0,3,28:18.4
1,3,28:18.4
0,-2,29:18.4
-2,-1,29:18.4
-1,-1,29:18.4
0,0,29:18.4
1,2,29:18.4
-1,-1,30:18.4
0,0,30:18.4
-1,1,30:18.4
