[META]
version=2.0
spawnOnBlockType=2
spawnSunlight=True
spawnDarkness=True
spawnWater=False
spawnLava=False
underFill=False
randomRotation=True
dig=True
tree=False
branch=False
needsFoundation=True
rarity=100
collisionPercentage=20
spawnElevationMin=0
spawnElevationMax=200
spawnInBiome=Custom
[DATA]
0,0,0:17.14
0,0,1:17.14
-1,1,1:18.6
0,-2,2:18.14
2,-1,2:18.14
-2,0,2:18.6
0,0,2:17.14
2,0,2:18.14
0,1,2:18.14
1,1,2:18.14
-1,2,2:18.6
1,2,2:18.6
1,-2,3:18.6
-1,-1,3:18.6
0,-1,3:18.6
1,-1,3:18.6
2,-1,3:18.6
-2,0,3:18.6
-1,0,3:18.6
0,0,3:17.14
1,0,3:18.6
-1,1,3:18.6
0,1,3:18.6
2,1,3:18.6
0,2,3:18.6
1,2,3:18.6
-1,-2,4:18.14
0,-2,4:18.14
-2,-1,4:18.14
-1,-1,4:18.14
0,-1,4:18.14
2,-1,4:18.6
-2,0,4:18.14
0,0,4:17.14
1,0,4:18.6
2,0,4:18.6
-2,1,4:18.6
-1,1,4:18.14
0,1,4:18.14
1,1,4:18.14
2,1,4:18.6
0,2,4:18.14
0,-2,5:18.14
1,-2,5:18.14
-1,-1,5:18.14
0,-1,5:18.14
1,-1,5:18.14
-2,0,5:18.14
0,0,5:17.14
1,0,5:18.6
2,0,5:18.6
0,1,5:18.14
1,1,5:18.14
0,-2,6:18.14
0,-1,6:18.14
1,-1,6:18.14
2,-1,6:18.14
-1,0,6:18.14
0,0,6:18.14
2,0,6:18.14
-1,1,6:18.14
1,1,6:18.14
-1,-1,7:18.6
0,-1,7:18.14
-1,0,7:18.6
0,0,7:18.14
1,0,7:18.14
0,1,7:18.14
