[META]
version=2.0
spawnOnBlockType=2
spawnSunlight=True
spawnDarkness=True
spawnWater=False
spawnLava=False
underFill=False
randomRotation=True
dig=True
tree=False
branch=False
needsFoundation=True
rarity=100
collisionPercentage=20
spawnElevationMin=0
spawnElevationMax=200
spawnInBiome=Custom
[DATA]
0,-1,0:17.14
0,-1,1:17.14
0,-1,2:17.14
1,-1,2:18.6
0,0,2:18.6
1,0,2:18.6
1,-2,3:18.6
2,-2,3:18.6
-1,-1,3:18.6
0,-1,3:17.14
2,-1,3:18.6
-1,0,3:18.6
0,0,3:18.6
-2,1,3:18.6
-1,1,3:18.6
2,1,3:18.6
1,-3,4:18.6
-1,-2,4:18.6
0,-2,4:18.6
1,-2,4:18.6
3,-2,4:18.6
-2,-1,4:18.6
-1,-1,4:18.6
0,-1,4:17.14
1,-1,4:17.14
2,-1,4:18.6
3,-1,4:18.6
-1,0,4:18.6
0,0,4:18.6
1,0,4:18.6
-1,1,4:18.6
0,2,4:18.6
-1,-3,5:18.6
0,-3,5:18.6
-1,-2,5:18.6
0,-2,5:18.6
1,-2,5:18.6
-2,-1,5:18.6
-1,-1,5:18.6
0,-1,5:17.14
1,-1,5:18.6
3,-1,5:18.6
-3,0,5:18.6
-1,0,5:17.14
0,0,5:18.6
1,0,5:18.6
3,0,5:18.6
-3,1,5:18.6
-1,1,5:18.6
0,1,5:18.6
2,1,5:18.6
-2,2,5:18.6
-1,2,5:18.6
0,2,5:18.6
0,-4,6:18.6
-1,-3,6:18.6
1,-3,6:18.6
2,-3,6:18.6
-3,-2,6:18.6
-2,-2,6:18.6
-1,-2,6:18.6
0,-2,6:18.6
1,-2,6:18.6
2,-2,6:18.6
-3,-1,6:18.6
-2,-1,6:18.6
0,-1,6:17.14
1,-1,6:18.6
2,-1,6:18.6
-2,0,6:18.6
-1,0,6:18.6
1,0,6:18.6
2,0,6:18.6
-2,1,6:18.6
0,1,6:18.6
-1,-4,7:18.6
0,-4,7:18.6
2,-4,7:18.6
-3,-3,7:18.6
-2,-3,7:18.6
-1,-3,7:18.6
0,-3,7:18.6
1,-3,7:18.6
3,-3,7:18.6
-3,-2,7:18.6
-2,-2,7:18.6
-1,-2,7:17.14
0,-2,7:18.6
1,-2,7:18.6
2,-2,7:18.6
-3,-1,7:18.6
-2,-1,7:18.6
-1,-1,7:18.6
0,-1,7:17.14
1,-1,7:18.6
2,-1,7:18.6
-1,0,7:18.6
0,0,7:18.6
1,0,7:18.6
2,0,7:18.6
1,1,7:18.6
-2,-4,8:18.6
-1,-4,8:18.6
-1,-3,8:18.6
0,-3,8:18.6
-3,-2,8:18.6
-1,-2,8:18.6
1,-2,8:18.6
-2,-1,8:18.6
-1,-1,8:18.6
0,-1,8:17.14
1,-1,8:18.6
2,-1,8:18.6
-2,0,8:18.6
-1,0,8:18.6
0,0,8:18.6
2,0,8:18.6
3,0,8:18.14
2,1,8:18.6
1,2,8:18.6
0,-3,9:18.6
1,-3,9:18.6
2,-3,9:18.6
-2,-2,9:18.6
-1,-2,9:18.6
0,-2,9:18.6
1,-2,9:18.6
-2,-1,9:18.6
0,-1,9:17.14
1,-1,9:18.6
2,-1,9:18.6
-2,0,9:18.6
-1,0,9:18.6
0,0,9:17.14
1,0,9:18.6
-2,1,9:18.6
0,1,9:18.6
-1,2,9:18.6
0,2,9:18.6
1,2,9:18.6
3,2,9:18.14
0,-4,10:18.6
1,-4,10:18.6
0,-2,10:18.6
1,-2,10:17.14
2,-2,10:18.6
3,-2,10:18.6
-2,-1,10:18.6
0,-1,10:18.6
2,-1,10:18.6
3,-1,10:18.14
4,-1,10:18.14
0,0,10:18.6
1,0,10:18.6
2,0,10:18.6
3,0,10:18.14
-1,1,10:18.6
0,1,10:18.6
1,1,10:18.14
2,1,10:18.14
1,2,10:18.14
2,2,10:18.14
1,-4,11:18.6
1,-3,11:18.6
3,-3,11:18.6
-1,-2,11:18.6
0,-2,11:18.6
1,-2,11:17.14
3,-2,11:18.6
-1,-1,11:18.6
0,-1,11:18.6
1,-1,11:18.6
2,-1,11:18.6
3,-1,11:18.14
0,0,11:18.6
1,0,11:18.6
2,0,11:18.6
3,0,11:18.14
0,1,11:18.6
1,-3,12:18.6
2,-3,12:18.6
-1,-2,12:18.6
0,-2,12:18.6
1,-2,12:18.6
0,-1,12:18.6
1,-1,12:18.6
3,-1,12:18.6
0,0,12:18.6
1,0,12:18.6
1,1,12:18.14
0,-3,13:18.6
1,-3,13:18.6
0,-2,13:18.6
1,-2,13:18.6
2,-1,13:18.6
