[META]
version=2.0
spawnOnBlockType=2
spawnSunlight=True
spawnDarkness=True
spawnWater=False
spawnLava=False
underFill=False
randomRotation=True
dig=True
tree=False
branch=False
needsFoundation=True
rarity=100
collisionPercentage=20
spawnElevationMin=0
spawnElevationMax=200
spawnInBiome=Custom
[DATA]
-1,0,-3:17.12
-1,-1,-2:17.12
-2,0,-2:17.12
-1,0,-2:17.12
0,0,-2:17.12
-1,-1,-1:17.12
-2,0,-1:17.12
-1,0,-1:17.12
0,0,-1:17.12
-1,1,-1:17.12
-1,-1,0:17.12
-2,0,0:17.12
-1,0,0:17.12
0,0,0:17.12
-1,1,0:17.12
-2,0,1:17.12
-1,0,1:17.12
-1,0,2:17.12
-1,0,3:17.12
-1,0,4:17.12
-1,0,5:17.12
-1,0,6:17.12
-1,0,7:17.12
-1,1,7:17.12
-1,0,8:17.12
-1,2,8:17.12
0,2,8:18.12
1,2,8:18.12
0,3,8:18.12
-2,4,8:18.12
-1,4,8:18.12
-2,-2,9:18.12
-1,-1,9:18.12
0,-1,9:17.12
-2,0,9:18.12
-1,0,9:17.12
0,0,9:18.12
-4,1,9:18.12
-3,1,9:18.12
-2,1,9:18.12
-1,1,9:18.12
-4,2,9:18.12
-2,2,9:18.12
0,2,9:18.12
-2,3,9:18.12
-1,3,9:18.12
0,-4,10:18.4
0,-3,10:18.4
1,-3,10:18.4
3,-3,10:18.4
0,-2,10:18.4
1,-2,10:17.12
0,-1,10:18.4
-2,0,10:18.4
-1,0,10:17.12
0,0,10:18.4
1,0,10:18.4
2,0,10:18.4
-1,2,10:18.4
1,-3,11:18.4
2,-3,11:18.4
0,-2,11:18.4
-3,-1,11:18.4
-1,-1,11:18.4
1,-1,11:18.4
2,-1,11:18.4
3,-1,11:18.4
-3,0,11:18.4
-2,0,11:17.12
-1,0,11:17.12
1,0,11:18.4
-4,1,11:18.4
-3,1,11:17.12
-2,1,11:18.4
0,1,11:18.4
-4,2,11:18.4
-1,2,11:18.4
-1,-1,12:18.4
-3,0,12:18.4
-2,0,12:18.4
-1,0,12:17.12
0,0,12:18.12
1,0,12:18.4
-2,1,12:18.4
-2,2,12:18.4
0,-1,13:18.12
-2,0,13:18.12
-1,0,13:17.12
0,2,13:18.12
-1,-2,14:18.12
0,-2,14:18.12
-3,-1,14:18.12
-2,-1,14:18.12
-1,-1,14:18.12
0,-1,14:18.12
-3,0,14:18.12
-2,0,14:18.12
-1,0,14:17.12
1,0,14:18.12
-3,1,14:18.12
-2,1,14:18.12
-1,1,14:18.12
1,1,14:18.12
-2,2,14:18.12
-1,2,14:18.12
0,2,14:18.12
-3,0,15:18.12
-2,0,15:18.12
-1,0,15:18.12
-3,1,15:18.12
-1,1,15:18.12
0,1,15:18.12
1,1,15:18.12
-1,2,15:18.12
-1,-1,16:18.12
-1,0,16:18.12
-2,1,16:18.12
-1,1,16:18.12
