[META]
version=2.0
spawnOnBlockType=2
spawnSunlight=True
spawnDarkness=True
spawnWater=False
spawnLava=False
underFill=False
randomRotation=True
dig=True
tree=False
branch=False
needsFoundation=True
rarity=100
collisionPercentage=20
spawnElevationMin=0
spawnElevationMax=200
spawnInBiome=Custom
[DATA]
1,-3,-3:17.12
1,-1,-3:17.12
2,0,-3:17.12
1,-3,-2:17.12
0,-2,-2:17.12
2,-2,-2:17.12
0,-1,-2:17.12
1,-1,-2:17.12
3,-1,-2:17.12
0,0,-2:17.12
2,0,-2:17.12
1,-3,-1:17.12
0,-2,-1:17.12
2,-2,-1:17.12
-1,-1,-1:17.12
0,-1,-1:17.12
1,-1,-1:17.12
3,-1,-1:17.12
0,0,-1:17.12
1,0,-1:17.12
2,0,-1:17.12
1,1,-1:17.12
1,-3,0:17.12
0,-2,0:17.12
1,-2,0:17.12
2,-2,0:17.12
-1,-1,0:17.12
0,-1,0:17.12
1,-1,0:17.12
2,-1,0:17.12
3,-1,0:17.12
0,0,0:17.12
1,0,0:17.12
2,0,0:17.12
1,1,0:17.12
1,-2,1:17.12
2,-2,1:17.12
0,-1,1:17.12
1,-1,1:17.12
2,-1,1:17.12
0,0,1:17.12
1,0,1:17.12
1,-2,2:17.12
0,-1,2:17.12
1,-1,2:17.12
1,0,2:17.12
1,-1,3:17.12
1,-1,4:17.12
1,-1,5:17.12
1,-1,6:17.12
1,-1,7:17.12
1,-1,8:17.12
1,-1,9:17.12
1,-1,10:17.12
1,-1,11:17.12
1,-1,12:17.12
1,-1,13:17.12
1,-1,14:17.12
1,-1,15:17.12
9,-2,16:18.12
10,-2,16:18.12
1,-1,16:17.12
2,-1,16:17.12
9,-1,16:18.12
9,0,16:17.12
10,0,16:17.12
8,-4,17:18.12
9,-4,17:18.12
8,-3,17:18.12
11,-3,17:18.12
8,-2,17:18.12
1,-1,17:17.12
3,-1,17:17.12
7,-1,17:17.12
8,-1,17:17.12
9,-1,17:18.12
6,2,17:18.12
7,2,17:18.12
7,3,17:18.12
8,3,17:18.12
4,-4,18:18.4
10,-4,18:18.12
4,-3,18:18.4
8,-3,18:18.12
9,-3,18:18.12
11,-3,18:18.12
0,-2,18:17.12
3,-2,18:18.4
4,-2,18:18.4
7,-2,18:18.12
8,-2,18:18.12
9,-2,18:17.12
10,-2,18:18.12
11,-2,18:18.12
4,-1,18:17.12
5,-1,18:17.12
6,-1,18:17.12
9,-1,18:18.12
5,0,18:17.12
8,0,18:18.12
9,0,18:18.12
10,0,18:18.12
5,1,18:18.12
8,1,18:18.12
5,2,18:18.12
6,2,18:18.12
7,2,18:18.12
8,2,18:18.12
7,3,18:18.12
7,4,18:18.12
8,4,18:18.12
2,-4,19:18.4
4,-4,19:18.4
10,-4,19:18.12
2,-3,19:18.4
5,-3,19:18.4
10,-3,19:18.12
0,-2,19:17.12
4,-2,19:18.4
5,-2,19:17.12
9,-2,19:18.12
5,-1,19:18.4
7,-1,19:18.12
10,-1,19:18.12
9,0,19:18.12
6,1,19:17.12
7,1,19:18.12
5,2,19:18.12
6,2,19:18.12
7,2,19:17.12
8,2,19:18.12
6,3,19:18.12
7,3,19:18.12
7,4,19:18.12
8,4,19:18.12
5,-5,20:18.4
4,-4,20:18.4
2,-3,20:18.4
3,-3,20:18.4
4,-3,20:17.12
5,-3,20:18.4
9,-3,20:18.12
10,-3,20:18.12
0,-2,20:17.12
6,-2,20:18.4
9,-2,20:18.12
10,-2,20:18.12
3,-1,20:18.4
4,-1,20:18.4
8,0,20:18.12
5,2,20:18.12
7,2,20:18.12
9,2,20:18.12
5,3,20:18.12
6,3,20:18.12
7,4,20:18.12
8,4,20:18.12
4,-5,21:18.4
5,-5,21:18.4
4,-4,21:18.4
4,-3,21:18.4
5,-3,21:18.4
0,-2,21:17.12
4,-2,21:18.4
6,-2,21:18.4
1,-1,21:17.12
6,1,21:18.12
7,1,21:18.12
7,2,21:18.12
7,3,21:18.12
3,-4,22:18.4
-1,-3,22:17.12
4,-3,22:18.4
5,-3,22:18.4
-1,-2,22:18.12
-1,-1,22:17.12
-2,0,22:18.12
2,0,22:17.12
-2,-4,23:17.12
-2,-3,23:18.12
-2,-2,23:18.12
-1,-1,23:17.12
0,-1,23:18.12
-3,0,23:18.12
0,0,23:18.12
3,0,23:17.12
-1,1,23:18.12
0,1,23:18.12
7,1,23:18.12
7,2,23:18.12
8,2,23:18.12
6,3,23:18.12
-4,-5,24:17.12
-3,-5,24:17.12
-6,-4,24:18.4
-5,-3,24:18.12
-4,-3,24:18.12
-2,-3,24:18.12
-1,-3,24:18.12
0,-3,24:18.12
-2,-2,24:18.12
-1,-2,24:18.12
-2,-1,24:18.12
-1,-1,24:17.12
0,-1,24:18.12
-2,0,24:18.12
-1,0,24:18.12
-1,1,24:18.12
3,1,24:17.12
5,1,24:18.12
6,1,24:18.12
7,1,24:18.12
6,2,24:18.12
7,2,24:18.12
6,3,24:18.4
9,3,24:18.4
7,4,24:18.4
8,4,24:18.4
-1,-8,25:18.12
-1,-7,25:18.12
0,-7,25:18.12
-3,-6,25:17.12
-2,-6,25:18.12
-1,-6,25:18.12
-4,-5,25:18.12
3,-5,25:18.12
-5,-4,25:17.12
3,-4,25:18.12
-6,-3,25:18.4
-4,-3,25:18.12
-2,-3,25:18.12
3,-3,25:18.12
-6,-2,25:18.4
-5,-2,25:18.12
-3,-2,25:18.12
-1,-2,25:18.12
0,-2,25:18.12
-6,-1,25:18.4
-4,-1,25:18.12
-3,-1,25:18.12
-1,-1,25:18.12
0,-1,25:18.12
1,-1,25:18.12
-3,0,25:18.12
-2,0,25:17.12
-1,0,25:18.12
0,0,25:18.12
6,0,25:18.12
7,0,25:18.12
8,0,25:18.4
-2,1,25:18.12
-1,1,25:18.12
1,1,25:18.12
4,1,25:17.12
5,1,25:17.12
7,1,25:18.4
9,1,25:18.4
-1,2,25:18.12
2,2,25:17.12
3,2,25:18.12
4,2,25:18.12
5,2,25:18.12
7,2,25:17.12
9,2,25:18.4
0,3,25:18.12
2,3,25:18.12
3,3,25:18.12
4,3,25:18.12
5,3,25:18.12
6,3,25:18.4
7,3,25:18.4
6,4,25:18.4
7,4,25:18.4
-1,-9,26:18.4
-2,-8,26:18.12
-2,-7,26:17.12
-1,-7,26:18.12
-3,-6,26:18.12
-1,-6,26:18.12
0,-6,26:18.12
2,-6,26:18.12
-5,-5,26:18.12
3,-5,26:18.12
5,-5,26:18.12
-5,-4,26:18.12
-4,-4,26:18.12
1,-4,26:18.12
2,-4,26:18.12
3,-4,26:18.12
-6,-3,26:18.4
-5,-3,26:17.12
-4,-3,26:18.12
-3,-3,26:18.12
5,-3,26:18.12
-5,-2,26:18.12
-3,-2,26:18.12
3,-2,26:18.12
-4,-1,26:18.12
-3,-1,26:18.12
-2,-1,26:18.12
7,-1,26:18.12
-5,0,26:18.12
-4,0,26:18.12
-2,0,26:17.12
1,0,26:18.12
5,0,26:18.12
6,0,26:18.12
8,0,26:18.4
9,0,26:18.4
-3,1,26:18.12
0,1,26:18.12
1,1,26:18.12
5,1,26:18.12
6,1,26:17.12
7,1,26:18.4
8,1,26:18.4
-1,2,26:18.12
1,2,26:18.12
2,2,26:17.12
5,2,26:18.12
6,2,26:18.4
7,2,26:18.4
8,2,26:18.4
9,2,26:18.4
-1,3,26:18.12
0,3,26:18.12
2,3,26:18.12
3,3,26:18.12
5,3,26:18.12
7,3,26:18.4
3,4,26:18.4
8,4,26:18.4
2,5,26:18.4
-1,-9,27:18.4
-2,-8,27:18.12
0,-8,27:18.12
1,-8,27:18.12
-3,-7,27:18.12
-2,-7,27:18.12
-1,-7,27:17.12
0,-7,27:18.12
-1,-6,27:18.12
0,-6,27:18.12
1,-6,27:18.12
3,-6,27:18.12
4,-6,27:18.12
-4,-5,27:18.4
-2,-5,27:18.12
-1,-5,27:18.12
1,-5,27:18.4
2,-5,27:18.12
5,-5,27:18.12
-7,-4,27:18.4
-5,-4,27:18.4
0,-4,27:18.4
1,-4,27:18.12
3,-4,27:18.4
5,-4,27:18.12
-7,-3,27:18.4
-1,-3,27:18.4
0,-3,27:18.4
4,-3,27:18.12
-6,-2,27:18.4
-4,-2,27:18.4
-3,-2,27:18.12
0,-2,27:18.4
2,-2,27:18.12
7,-2,27:18.12
8,-2,27:18.4
-5,-1,27:18.4
-3,-1,27:18.12
6,-1,27:18.12
7,-1,27:18.12
8,-1,27:18.4
9,-1,27:18.4
-5,0,27:18.4
-4,0,27:18.4
-3,0,27:17.12
-2,0,27:18.12
-1,0,27:18.12
1,0,27:18.12
5,0,27:18.12
6,0,27:18.12
7,0,27:17.12
-5,1,27:18.4
-3,1,27:18.12
-2,1,27:18.12
-1,1,27:17.12
0,1,27:18.12
1,1,27:18.12
3,1,27:18.12
4,1,27:18.12
9,1,27:18.4
-4,2,27:18.4
-3,2,27:18.12
-2,2,27:18.12
0,2,27:18.12
1,2,27:17.12
2,2,27:18.12
3,2,27:18.12
6,2,27:18.4
7,2,27:18.4
-1,3,27:18.12
1,3,27:18.12
3,3,27:17.12
4,3,27:18.12
5,3,27:18.12
7,3,27:18.4
1,4,27:18.4
2,4,27:18.4
3,4,27:18.4
4,4,27:18.4
5,4,27:18.4
3,5,27:18.4
0,-9,28:18.4
-3,-8,28:18.12
-2,-7,28:18.12
-2,-6,28:18.12
1,-6,28:18.4
3,-6,28:18.12
-1,-5,28:18.4
1,-5,28:18.12
-6,-4,28:18.4
-5,-4,28:18.4
-4,-4,28:18.4
0,-4,28:18.4
1,-4,28:18.12
2,-4,28:18.4
3,-4,28:18.12
4,-4,28:18.12
-5,-3,28:18.4
-4,-3,28:18.4
3,-3,28:18.12
4,-3,28:18.12
5,-3,28:18.12
-4,-2,28:18.4
-3,-2,28:18.12
0,-2,28:18.4
6,-2,28:18.12
-5,-1,28:18.4
-4,-1,28:18.4
-3,-1,28:18.12
-2,-1,28:18.12
5,-1,28:18.12
9,-1,28:18.4
-5,0,28:18.4
-4,0,28:17.12
-3,0,28:18.12
-2,0,28:18.12
1,0,28:18.12
5,0,28:18.12
7,0,28:18.12
-6,1,28:18.4
-5,1,28:18.4
-4,1,28:18.4
-3,1,28:18.12
0,1,28:18.12
8,1,28:18.4
-4,2,28:18.4
-3,2,28:18.12
-1,2,28:18.12
1,2,28:18.12
2,2,28:18.12
4,2,28:18.12
5,2,28:18.12
-2,3,28:18.12
1,3,28:18.12
2,3,28:18.12
3,3,28:18.12
1,4,28:18.4
2,4,28:18.4
5,4,28:18.4
3,5,28:18.4
-2,-7,29:18.12
-1,-7,29:18.12
0,-7,29:18.12
-1,-6,29:18.12
0,-5,29:18.4
4,-5,29:18.12
1,-4,29:18.4
2,-4,29:18.12
3,-4,29:18.12
1,-3,29:18.4
2,-3,29:18.12
4,-3,29:18.12
1,-2,29:18.4
2,-2,29:18.4
6,-1,29:18.12
7,-1,29:18.12
-5,0,29:18.4
-4,0,29:18.4
-1,0,29:18.12
6,0,29:18.12
7,0,29:18.12
8,0,29:18.4
-6,1,29:18.4
-2,1,29:18.12
-1,1,29:18.12
0,1,29:18.12
1,1,29:18.12
2,1,29:18.12
6,1,29:18.4
7,1,29:18.4
1,2,29:18.12
4,2,29:18.12
1,3,29:18.12
3,3,29:18.12
3,4,29:18.4
0,-5,30:18.4
1,-5,30:18.4
1,-4,30:18.4
2,-4,30:18.4
1,-3,30:18.4
-4,-1,30:18.4
-4,0,30:18.4
-3,0,30:18.12
