[META]
version=2.0
spawnOnBlockType=2
spawnSunlight=True
spawnDarkness=True
spawnWater=False
spawnLava=False
underFill=False
randomRotation=True
dig=True
tree=False
branch=False
needsFoundation=True
rarity=100
collisionPercentage=20
spawnElevationMin=0
spawnElevationMax=200
spawnInBiome=Custom
[DATA]
-1,-1,-3:17.12
-1,-2,-2:17.12
-1,-1,-2:17.12
-3,0,-2:17.12
0,0,-2:17.12
-1,-2,-1:17.12
-2,-1,-1:17.12
-1,-1,-1:17.12
-3,0,-1:17.12
0,0,-1:17.12
-1,-2,0:17.12
-2,-1,0:17.12
-1,-1,0:17.12
0,-1,0:17.12
-3,0,0:17.12
0,0,0:17.12
-2,-1,1:17.12
-1,-1,1:17.12
-1,-1,2:17.12
-4,-5,3:18.13
-1,-5,3:18.13
-5,-4,3:18.13
-3,-4,3:18.13
-1,-4,3:18.13
-5,-3,3:18.13
-3,-3,3:18.13
-2,-3,3:18.13
0,-3,3:18.13
-5,-1,3:18.13
-4,-1,3:18.13
-1,-1,3:17.12
-6,0,3:18.13
-5,0,3:18.13
-4,0,3:18.13
-3,0,3:18.13
-2,0,3:18.13
1,0,3:18.13
-6,1,3:18.13
-4,1,3:18.13
-3,1,3:18.13
0,1,3:18.13
-4,-5,4:18.13
-2,-5,4:18.13
-1,-5,4:18.13
-6,-4,4:18.13
-4,-4,4:18.13
-3,-4,4:18.13
-1,-4,4:18.13
-5,-3,4:18.13
-4,-3,4:18.13
-3,-3,4:18.13
-2,-3,4:18.13
0,-3,4:18.13
-5,-2,4:18.13
-4,-2,4:17.12
-3,-2,4:18.13
-2,-2,4:18.13
-5,-1,4:18.13
-4,-1,4:18.13
-3,-1,4:17.12
-2,-1,4:17.12
-1,-1,4:17.12
-6,0,4:18.13
-5,0,4:18.13
-4,0,4:18.13
-2,0,4:18.13
1,0,4:18.13
-6,1,4:18.13
-4,1,4:18.13
-4,-6,5:18.13
-4,-5,5:18.13
-2,-5,5:18.13
-1,-5,5:18.13
-5,-4,5:18.13
-4,-4,5:18.13
-1,-4,5:18.13
-5,-3,5:17.12
-3,-3,5:18.13
-2,-3,5:18.13
0,-3,5:18.13
-1,-1,5:17.12
-6,0,5:18.13
-5,0,5:18.13
-4,0,5:17.12
1,0,5:18.13
2,0,5:18.13
4,0,5:18.5
-6,1,5:18.13
-5,1,5:17.12
1,1,5:18.13
1,2,5:18.13
3,2,5:18.13
1,3,5:18.13
2,3,5:18.13
-4,-6,6:18.13
-4,-5,6:18.13
-2,-5,6:18.13
-1,-5,6:18.13
-4,-4,6:18.13
-3,-4,6:18.13
-1,-4,6:18.13
-5,-3,6:18.13
-3,-3,6:18.13
-2,-3,6:18.13
0,-3,6:18.13
-2,-2,6:18.13
-1,-1,6:17.12
-4,0,6:18.13
0,0,6:17.12
2,0,6:18.13
-5,1,6:18.13
0,1,6:18.13
1,1,6:18.13
1,2,6:18.13
2,2,6:18.13
3,2,6:18.13
-4,-6,7:18.13
-4,-5,7:18.13
-3,-5,7:17.12
-2,-5,7:18.13
-1,-5,7:18.13
-4,-4,7:18.13
-3,-4,7:18.13
-2,-4,7:17.12
-1,-4,7:18.13
-3,-3,7:18.13
-2,-3,7:18.13
-1,-3,7:17.12
0,-3,7:18.13
-1,-2,7:17.12
-1,-1,7:17.12
2,0,7:18.13
3,0,7:18.13
1,1,7:18.13
2,1,7:17.12
3,1,7:17.12
4,1,7:18.5
2,2,7:17.12
3,2,7:18.13
1,3,7:18.13
0,-6,8:18.13
1,-6,8:18.13
-4,-5,8:18.13
-3,-5,8:18.13
0,-5,8:18.13
1,-5,8:18.13
2,-5,8:18.13
-3,-4,8:18.13
-2,-4,8:18.13
0,-4,8:18.13
3,-4,8:18.13
-5,-3,8:18.13
-4,-3,8:18.13
-1,-3,8:18.13
0,-3,8:18.13
2,-3,8:18.13
1,-2,8:18.13
2,-2,8:18.13
-1,-1,8:17.12
0,1,8:18.13
1,1,8:18.13
2,1,8:18.13
3,1,8:18.13
-1,2,8:18.13
1,2,8:18.13
2,2,8:18.13
-2,3,8:18.13
0,3,8:18.13
0,-6,9:18.13
1,-6,9:18.13
-4,-5,9:18.13
1,-5,9:18.13
2,-5,9:18.13
-3,-4,9:18.13
0,-4,9:18.13
1,-4,9:18.13
3,-4,9:18.13
-5,-3,9:18.13
0,-3,9:18.13
2,-3,9:18.13
4,-3,9:18.5
1,-2,9:18.13
2,-2,9:18.13
-1,-1,9:17.12
1,1,9:18.13
-1,2,9:18.13
1,2,9:18.13
-2,3,9:18.13
0,-6,10:18.13
1,-6,10:18.13
2,-6,10:18.13
-4,-5,10:18.13
0,-5,10:18.13
1,-5,10:18.13
2,-5,10:18.13
-3,-4,10:18.5
0,-4,10:18.13
3,-4,10:18.13
-5,-3,10:18.13
0,-3,10:18.13
2,-3,10:18.13
1,-2,10:18.13
2,-2,10:18.13
-1,-1,10:17.12
-3,1,10:18.5
0,1,10:18.13
1,1,10:18.13
-1,2,10:18.13
1,2,10:18.13
-2,3,10:18.13
0,3,10:18.13
-6,-6,11:18.13
-4,-6,11:18.13
0,-6,11:18.13
1,-6,11:18.13
-4,-5,11:18.13
0,-5,11:18.13
1,-5,11:18.13
2,-5,11:18.13
3,-5,11:18.13
-5,-4,11:18.13
0,-4,11:18.13
1,-4,11:18.13
3,-4,11:18.13
-5,-3,11:18.13
-4,-3,11:18.13
0,-3,11:18.13
2,-3,11:18.13
4,-3,11:18.13
1,-2,11:18.13
-1,-1,11:17.12
0,1,11:18.13
1,1,11:18.13
-1,2,11:18.13
1,2,11:18.13
-2,3,11:18.13
0,3,11:18.13
-6,-6,12:18.13
-4,-6,12:18.13
0,-6,12:18.13
1,-6,12:18.13
2,-6,12:18.13
-6,-5,12:18.13
-4,-5,12:18.13
0,-5,12:18.13
1,-5,12:18.13
2,-5,12:17.12
3,-5,12:18.13
-5,-4,12:18.13
-3,-4,12:18.13
0,-4,12:18.13
2,-4,12:17.12
3,-4,12:18.13
-5,-3,12:18.13
0,-3,12:18.13
1,-3,12:17.12
2,-3,12:18.13
3,-3,12:17.12
4,-3,12:18.5
0,-2,12:17.12
-1,-1,12:17.12
0,0,12:18.13
-3,1,12:18.13
0,1,12:18.13
1,1,12:18.13
-1,2,12:18.13
0,3,12:18.13
2,3,12:18.5
-4,4,12:18.13
0,4,12:18.13
-6,-6,13:18.13
-5,-6,13:18.13
-4,-6,13:18.5
1,-6,13:18.13
-6,-5,13:18.13
1,-5,13:18.13
-4,-4,13:18.13
-3,-4,13:18.13
2,-4,13:18.13
-5,-3,13:18.13
0,-3,13:18.13
2,-3,13:18.13
3,-3,13:18.5
-3,-2,13:18.13
0,-2,13:18.5
1,-2,13:18.13
-4,-1,13:18.13
-1,-1,13:17.12
-3,0,13:18.13
0,0,13:18.13
-3,1,13:18.13
1,1,13:18.13
-5,2,13:18.13
-4,2,13:18.13
-1,2,13:18.13
1,2,13:18.13
-3,3,13:18.13
-4,4,13:18.13
0,4,13:18.13
1,4,13:18.13
-6,-6,14:18.13
-5,-6,14:18.13
1,-6,14:18.13
-6,-5,14:18.13
-5,-5,14:17.4
1,-5,14:18.13
-5,-4,14:18.13
-3,-4,14:18.13
-5,-3,14:18.13
-4,-3,14:18.13
-3,-3,14:17.12
0,-3,14:18.13
2,-3,14:18.13
-3,-2,14:18.13
-2,-2,14:17.12
1,-2,14:18.13
-4,-1,14:18.13
-1,-1,14:17.12
-3,0,14:18.13
0,0,14:18.13
1,1,14:18.13
-5,2,14:18.13
-4,2,14:18.13
-1,2,14:18.13
1,2,14:18.13
-3,3,14:18.13
-2,3,14:18.13
0,3,14:18.13
-4,4,14:18.13
0,4,14:18.13
1,4,14:18.13
1,-6,15:18.13
2,-6,15:18.13
3,-6,15:18.13
-5,-5,15:18.13
1,-5,15:18.13
3,-5,15:18.13
-4,-4,15:18.13
2,-4,15:18.13
3,-4,15:18.13
-3,-3,15:18.13
0,-3,15:18.13
2,-3,15:18.13
-3,-2,15:18.13
1,-2,15:18.13
-4,-1,15:18.13
-1,-1,15:17.12
-3,0,15:18.5
-1,0,15:17.12
0,0,15:18.13
-1,1,15:17.12
0,1,15:18.13
1,1,15:18.5
-4,2,15:18.13
-3,2,15:17.12
-2,2,15:17.12
-1,2,15:18.13
0,2,15:17.12
-5,3,15:18.13
-4,3,15:17.12
-3,3,15:18.13
-2,3,15:18.13
1,3,15:17.12
-5,4,15:18.13
-4,4,15:18.13
0,4,15:18.13
1,4,15:18.5
1,-6,16:18.13
3,-6,16:18.13
1,-5,16:18.13
3,-5,16:18.13
2,-4,16:18.13
0,-3,16:18.13
2,-3,16:18.13
-3,-2,16:18.5
1,-2,16:18.13
-4,-1,16:18.13
-3,-1,16:17.4
-2,-1,16:17.4
-1,-1,16:17.12
0,0,16:18.13
-3,2,16:18.5
0,2,16:18.5
-4,3,16:18.5
1,3,16:18.5
1,-6,17:18.13
1,-5,17:18.13
2,-5,17:17.12
3,-5,17:18.13
-5,-4,17:18.13
-4,-4,17:18.13
1,-4,17:17.12
2,-4,17:18.13
3,-4,17:18.5
0,-3,17:18.13
1,-3,17:17.12
-5,-2,17:18.13
0,-2,17:17.12
-3,-1,17:18.5
-1,-1,17:17.12
-2,0,17:18.13
-3,1,17:18.13
0,1,17:18.13
-3,2,17:18.13
0,2,17:18.13
-3,3,17:18.13
-1,-5,18:18.13
-5,-4,18:18.13
-4,-4,18:18.5
0,-3,18:18.13
2,-3,18:18.13
-5,-2,18:18.13
-4,-2,18:18.13
-3,-2,18:18.13
1,-2,18:18.13
-1,-1,18:17.12
3,-1,18:18.13
-5,0,18:18.13
0,0,18:18.13
1,0,18:18.13
2,0,18:18.13
-3,1,18:18.13
-2,1,18:18.13
0,1,18:18.13
-5,2,18:18.13
-4,2,18:18.13
-3,2,18:18.13
-1,2,18:18.13
0,2,18:18.13
-3,3,18:18.13
-2,3,18:18.13
-1,3,18:18.13
-1,-5,19:18.13
-5,-4,19:18.13
-5,-3,19:18.13
1,-3,19:18.13
2,-3,19:18.13
-5,-2,19:18.13
-4,-2,19:18.13
-3,-2,19:18.5
1,-2,19:18.13
-1,-1,19:17.12
3,-1,19:18.13
-5,0,19:18.13
-4,0,19:18.13
-2,0,19:18.13
-1,0,19:17.12
0,0,19:18.13
-3,1,19:18.13
-2,1,19:18.13
-1,1,19:17.12
0,1,19:18.13
-5,2,19:18.13
-4,2,19:18.13
-3,2,19:18.13
-2,2,19:17.12
0,2,19:18.5
-3,3,19:18.13
-1,3,19:18.13
-4,-4,20:18.5
-2,-4,20:18.13
0,-4,20:18.13
-4,-3,20:17.12
-3,-3,20:17.12
0,-3,20:18.13
2,-3,20:18.13
-5,-2,20:18.13
-4,-2,20:18.13
-2,-2,20:17.12
1,-2,20:18.13
-1,-1,20:17.12
3,-1,20:18.13
-5,0,20:18.13
0,0,20:18.13
1,0,20:18.13
-2,1,20:18.13
-5,2,20:18.13
-4,2,20:18.13
-1,2,20:18.13
-3,3,20:18.13
-2,3,20:18.13
-1,-5,21:18.13
0,-4,21:18.13
-4,-3,21:18.5
-3,-3,21:18.5
0,-3,21:18.13
1,-3,21:18.13
2,-3,21:18.13
-2,-2,21:18.5
1,-2,21:18.13
3,-2,21:18.13
-1,-1,21:17.12
3,-1,21:18.13
-5,0,21:18.13
-4,0,21:18.5
0,0,21:18.13
1,0,21:18.13
2,0,21:18.13
-2,1,21:18.13
-5,2,21:18.13
-3,2,21:18.13
-1,2,21:18.13
-1,3,21:18.13
-1,-5,22:18.13
-2,-4,22:18.13
-1,-4,22:17.12
-1,-3,22:17.12
2,-3,22:18.13
-1,-2,22:17.12
2,-2,22:17.12
3,-2,22:18.13
-1,-1,22:17.12
0,-1,22:17.12
1,-1,22:17.12
2,-1,22:18.13
3,-1,22:18.5
-5,0,22:18.13
1,0,22:18.13
2,0,22:18.13
-2,1,22:18.13
-5,2,22:18.13
-4,2,22:18.13
-3,2,22:18.13
-1,2,22:18.13
-3,3,22:18.13
-2,3,22:18.13
-1,-4,23:18.13
1,-4,23:18.13
-1,-3,23:18.13
2,-3,23:18.13
-4,-2,23:18.13
-3,-2,23:18.5
2,-2,23:18.13
-4,-1,23:18.13
-1,-1,23:17.12
-5,0,23:18.13
-4,0,23:18.13
-3,0,23:18.13
-2,0,23:17.12
-4,1,23:17.12
-3,1,23:17.12
-2,1,23:18.13
-5,2,23:18.13
-3,2,23:18.13
-2,2,23:17.12
-1,2,23:18.5
-2,3,23:18.13
1,-4,24:18.13
0,-3,24:18.13
-4,-2,24:18.13
2,-2,24:18.13
-4,-1,24:18.13
-1,-1,24:17.12
-2,0,24:18.13
1,-3,25:17.12
2,-3,25:18.13
-4,-2,25:18.13
-3,-2,25:18.5
0,-2,25:17.12
2,-2,25:18.13
-4,-1,25:18.13
-1,-1,25:17.12
-4,0,25:18.13
-3,0,25:18.13
-2,0,25:18.13
2,-4,26:18.13
0,-3,26:18.13
1,-3,26:18.5
-4,-2,26:18.13
0,-2,26:18.5
1,-2,26:18.13
2,-2,26:18.13
-4,-1,26:18.13
-3,-1,26:17.12
-2,-1,26:17.12
-1,-1,26:17.12
-4,0,26:18.13
-3,0,26:18.13
-2,0,26:18.5
2,-4,27:18.13
2,-3,27:18.13
1,-2,27:18.13
-3,-1,27:18.5
-2,-1,27:18.5
-1,-1,27:17.12
1,-4,28:18.5
2,-4,28:18.13
0,-3,28:18.13
1,-3,28:17.12
2,-3,28:18.5
0,-2,28:17.12
1,-2,28:18.13
-1,-1,28:17.12
0,0,28:18.13
-2,1,28:18.13
0,1,28:18.13
-1,2,28:18.13
-3,-3,29:18.13
-2,-3,29:18.13
1,-3,29:18.5
-2,-2,29:18.13
0,-2,29:18.5
-4,-1,29:18.13
-1,-1,29:17.12
-1,0,29:17.12
0,0,29:18.13
-2,1,29:18.13
-1,1,29:17.12
0,1,29:18.5
-2,2,29:18.13
-1,2,29:18.5
-3,-3,30:18.13
-4,-2,30:18.13
-2,-2,30:18.13
-4,-1,30:18.13
-3,-1,30:18.13
-1,-1,30:17.12
-1,0,30:18.5
-1,1,30:18.5
-3,-3,31:18.13
-2,-3,31:18.13
-3,-2,31:17.12
-2,-2,31:18.5
-4,-1,31:18.13
-3,-1,31:18.13
-2,-1,31:17.12
-1,-1,31:17.12
-3,-2,32:18.5
-2,-1,32:18.5
-1,-1,32:17.12
-1,0,32:18.13
-1,-1,33:17.12
-1,0,33:18.13
1,0,33:18.13
0,1,33:18.13
0,-3,34:18.13
-3,-2,34:18.13
-2,-2,34:18.13
-1,-2,34:18.13
1,-2,34:18.13
-1,-1,34:17.12
0,-1,34:18.13
-3,0,34:18.5
-1,0,34:18.13
0,0,34:17.12
1,0,34:18.5
0,1,34:18.13
-1,-3,35:18.13
0,-3,35:18.13
-3,-2,35:18.13
-2,-2,35:18.13
-1,-2,35:18.13
1,-2,35:18.13
-2,-1,35:17.12
-1,-1,35:17.12
0,-1,35:18.13
-1,0,35:18.13
-1,-3,36:18.13
0,-3,36:18.13
-1,-2,36:18.13
0,-2,36:17.12
1,-2,36:18.5
-2,-1,36:18.5
-1,-1,36:17.12
0,-1,36:18.13
-1,-2,37:18.13
-2,-1,37:18.13
-1,-1,37:17.12
-1,-1,38:18.13
0,-1,38:18.5
-1,0,38:18.13
-1,-1,39:18.13
-1,-1,40:18.5
