[META]
version=2.0
spawnOnBlockType=2
spawnSunlight=True
spawnDarkness=True
spawnWater=False
spawnLava=False
underFill=False
randomRotation=True
dig=True
tree=False
branch=False
needsFoundation=True
rarity=100
collisionPercentage=20
spawnElevationMin=0
spawnElevationMax=200
spawnInBiome=Custom
[DATA]
0,0,0:17.0
0,0,1:17.0
-1,-1,2:18.13
-3,0,2:18.13
0,0,2:17.12
0,2,2:18.13
2,2,2:18.13
1,3,2:18.13
-1,-3,3:18.13
4,-3,3:18.13
0,-2,3:18.13
-3,-1,3:18.13
-1,-1,3:18.13
-3,0,3:18.13
0,0,3:17.12
2,1,3:18.13
-1,2,3:18.13
0,2,3:18.13
2,2,3:18.13
1,3,3:18.13
3,3,3:18.13
2,4,3:18.13
-1,-3,4:18.13
0,-3,4:18.13
4,-3,4:18.13
-4,-2,4:18.13
0,-2,4:18.13
-3,-1,4:18.13
-1,-1,4:18.13
-3,0,4:18.13
0,0,4:17.12
2,1,4:18.13
-1,2,4:18.13
0,2,4:18.13
2,2,4:18.13
-1,3,4:18.13
1,3,4:18.13
3,3,4:18.13
0,4,4:18.13
2,4,4:18.13
3,4,4:18.13
3,-4,5:18.13
-3,-3,5:18.13
-1,-3,5:18.13
0,-3,5:18.13
1,-3,5:18.13
4,-3,5:18.13
-4,-2,5:18.13
-3,-2,5:17.12
-2,-2,5:18.13
-1,-2,5:17.12
0,-2,5:18.13
-3,-1,5:18.13
-2,-1,5:17.12
-1,0,5:17.12
0,0,5:17.12
-3,1,5:18.13
2,1,5:18.13
3,1,5:18.13
-2,2,5:18.13
-1,2,5:18.13
2,2,5:18.13
3,2,5:18.13
1,3,5:18.13
0,4,5:18.13
1,4,5:18.13
2,4,5:18.13
3,4,5:18.13
3,-4,6:18.13
2,-3,6:18.13
4,-3,6:18.13
-1,-2,6:18.13
4,-2,6:18.13
-3,0,6:18.13
0,0,6:17.12
-3,1,6:18.13
0,1,6:17.12
2,1,6:18.13
-1,2,6:18.13
1,2,6:17.12
2,2,6:18.13
3,2,6:18.13
0,3,6:17.12
1,3,6:18.13
2,3,6:17.12
-1,4,6:18.13
0,4,6:18.13
2,4,6:18.13
3,4,6:18.5
0,-3,7:18.13
1,-3,7:18.13
2,-3,7:18.13
3,-3,7:17.12
4,-3,7:18.13
-1,-2,7:18.13
1,-2,7:18.13
2,-2,7:17.12
4,-2,7:18.5
-2,-1,7:18.13
1,-1,7:17.12
-3,0,7:18.13
0,0,7:17.12
0,1,7:18.13
2,1,7:18.13
-3,2,7:18.13
-1,2,7:18.13
0,2,7:18.13
1,2,7:18.13
0,-3,8:18.13
3,-3,8:18.13
-1,-2,8:18.13
3,-2,8:18.13
-2,-1,8:18.13
-3,0,8:18.13
-2,0,8:17.12
-1,0,8:17.12
0,0,8:17.12
0,1,8:18.13
3,1,8:18.13
-3,2,8:18.13
-2,2,8:18.13
-1,2,8:18.13
1,2,8:18.13
1,-2,9:18.13
2,-2,9:18.13
2,-1,9:17.12
-1,0,9:18.13
0,0,9:17.12
1,0,9:17.12
-3,1,9:18.13
0,1,9:18.13
2,1,9:18.13
3,1,9:18.13
-3,2,9:18.13
-2,2,9:18.13
1,2,9:18.13
3,2,9:18.13
1,-1,10:18.13
2,-1,10:18.5
-2,0,10:18.13
0,0,10:17.12
1,0,10:18.13
-3,1,10:18.13
0,1,10:18.13
3,1,10:18.13
-3,2,10:18.13
-2,2,10:18.13
0,2,10:18.13
3,2,10:18.13
1,3,10:18.13
0,-3,11:18.13
-1,-2,11:18.13
1,-2,11:18.13
1,-1,11:18.13
-2,0,11:18.13
0,0,11:17.12
-3,1,11:18.13
1,1,11:17.12
2,1,11:18.13
-2,2,11:18.13
-1,2,11:18.13
0,2,11:18.13
1,2,11:18.13
2,2,11:17.12
1,3,11:18.13
-1,-2,12:18.13
1,-2,12:18.13
-2,0,12:18.13
-1,0,12:17.12
0,0,12:17.12
-3,1,12:18.13
-2,1,12:17.12
0,1,12:18.13
1,1,12:18.13
-2,2,12:18.13
-1,2,12:18.13
0,2,12:18.13
2,2,12:18.13
0,-3,13:18.13
-1,-2,13:18.13
1,-1,13:18.13
-1,0,13:18.13
0,0,13:17.12
-2,1,13:18.13
0,1,13:18.13
0,2,13:18.13
0,-3,14:18.13
-1,-2,14:18.13
0,-2,14:17.12
1,-2,14:18.13
0,-1,14:17.12
1,-1,14:18.13
-2,0,14:18.13
-1,0,14:18.13
0,0,14:17.12
2,0,14:18.13
-2,1,14:18.13
2,1,14:18.13
-1,2,14:18.13
0,-2,15:18.13
-2,-1,15:18.13
0,-1,15:18.13
1,-1,15:18.13
2,-1,15:18.13
-2,0,15:18.13
-1,0,15:18.13
0,0,15:17.12
-1,1,15:17.12
0,1,15:18.13
1,1,15:18.13
0,2,15:18.13
0,-2,16:18.13
-2,-1,16:18.13
0,-1,16:18.13
1,-1,16:18.13
2,-1,16:18.13
-2,0,16:18.13
-1,0,16:18.13
0,0,16:17.12
1,0,16:17.12
2,0,16:18.5
-1,1,16:18.13
1,1,16:18.13
0,-2,17:18.13
-2,-1,17:18.13
-1,-1,17:17.12
0,-1,17:18.13
-2,0,17:18.13
-1,0,17:18.13
0,0,17:17.12
-1,-1,18:18.13
0,0,18:17.12
0,-1,19:18.13
-1,0,19:18.13
0,0,19:17.12
1,0,19:18.13
0,1,19:18.13
-1,0,20:18.13
0,0,20:18.13
0,0,21:18.13
