[META]
version=2.0
spawnOnBlockType=2
spawnSunlight=True
spawnDarkness=True
spawnWater=False
spawnLava=False
underFill=False
randomRotation=True
dig=True
tree=False
branch=False
needsFoundation=True
rarity=100
collisionPercentage=20
spawnElevationMin=0
spawnElevationMax=200
spawnInBiome=Custom
[DATA]
-1,-1,-3:17.13
-3,1,-3:17.13
0,1,-3:17.13
-1,-1,-2:17.13
-1,0,-2:17.13
-3,1,-2:17.13
-2,1,-2:17.13
0,1,-2:17.13
-1,-1,-1:17.13
-2,0,-1:17.13
-1,0,-1:17.13
-3,1,-1:17.13
-2,1,-1:17.13
-1,1,-1:17.13
0,1,-1:17.13
-1,-1,0:17.13
-2,0,0:17.13
-1,0,0:17.13
-3,1,0:17.13
-2,1,0:17.13
-1,1,0:17.13
0,1,0:17.13
-2,0,1:17.13
-1,0,1:17.13
-2,1,1:17.13
-1,1,1:17.13
-2,0,2:17.13
-1,0,2:17.13
-2,1,2:17.13
-1,1,2:17.13
-2,0,3:17.13
-2,1,3:17.13
-1,1,3:17.13
-2,-3,4:18.13
-2,-2,4:18.13
-1,-2,4:18.13
0,-1,4:18.13
-2,0,4:17.13
0,0,4:18.13
-5,1,4:18.13
-2,1,4:17.13
-1,1,4:17.13
0,1,4:18.13
1,1,4:18.13
-3,2,4:18.13
-2,2,4:18.13
-1,2,4:18.13
-2,3,4:18.13
-4,-4,5:18.13
-2,-4,5:18.13
-3,-3,5:18.13
2,-2,5:18.13
-6,-1,5:18.13
-4,-1,5:18.13
1,-1,5:18.13
-5,0,5:18.13
-4,0,5:18.13
-2,0,5:17.13
0,0,5:18.13
1,0,5:18.13
-2,1,5:17.13
-1,1,5:17.13
-5,2,5:18.13
0,2,5:18.13
2,2,5:18.13
-5,3,5:18.13
1,3,5:18.13
-3,4,5:18.13
-2,4,5:18.13
0,4,5:18.13
-3,-5,6:18.5
0,-5,6:18.5
-3,-4,6:18.13
1,-4,6:18.13
-6,-3,6:18.13
-4,-3,6:18.13
-3,-3,6:18.13
1,-3,6:18.13
-2,-2,6:18.13
1,-2,6:18.13
-5,-1,6:18.13
-4,-1,6:18.13
-2,-1,6:18.13
3,-1,6:18.13
-7,0,6:18.5
-5,0,6:18.13
-2,0,6:17.13
-7,1,6:18.5
-2,1,6:17.13
-1,1,6:17.13
0,2,6:18.13
3,2,6:18.13
1,3,6:18.13
2,3,6:18.13
-3,5,6:18.13
-2,5,6:18.13
-4,-5,7:18.13
-2,-5,7:18.13
-6,-4,7:18.13
-5,-3,7:18.13
-4,-3,7:18.13
-1,-3,7:18.13
-7,-2,7:18.5
-5,-2,7:18.13
-4,-2,7:17.13
-3,-2,7:18.13
-6,-1,7:18.13
-5,-1,7:18.13
-4,-1,7:18.13
-3,-1,7:17.13
0,-1,7:18.13
1,-1,7:18.13
-4,0,7:18.13
-3,0,7:18.13
-2,0,7:17.13
-5,1,7:18.13
-2,1,7:17.13
-1,1,7:17.13
-3,2,7:18.13
-2,2,7:18.13
0,2,7:18.13
-4,3,7:18.13
-3,3,7:18.13
-2,3,7:18.13
-1,3,7:18.13
-4,-4,8:18.13
-2,-4,8:18.13
-3,-3,8:18.13
-6,-2,8:18.13
-5,-2,8:18.13
-4,-2,8:18.13
-3,-2,8:18.13
-2,-2,8:18.13
-5,-1,8:18.13
-4,-1,8:18.13
-3,-1,8:18.13
-4,0,8:18.13
-3,0,8:18.13
-2,0,8:17.13
-1,0,8:18.13
0,0,8:18.13
-4,1,8:18.13
-2,1,8:17.13
-1,1,8:17.13
0,1,8:18.13
-3,2,8:18.13
-4,-4,9:18.5
0,-4,9:18.5
-5,-3,9:18.5
-3,-3,9:18.5
-2,-3,9:18.5
0,-3,9:18.5
-6,-2,9:18.5
-5,-2,9:18.5
1,-2,9:18.5
3,-2,9:18.5
-4,-1,9:18.5
-7,0,9:18.5
-4,0,9:18.5
-3,0,9:18.5
-2,0,9:17.13
-6,1,9:18.5
-4,1,9:18.5
-3,1,9:18.5
-2,1,9:17.13
-1,1,9:17.13
3,1,9:18.5
-7,2,9:18.5
-6,2,9:18.5
-5,2,9:18.5
-1,2,9:18.5
2,2,9:18.5
-3,3,9:18.5
-1,3,9:18.5
-2,4,9:18.5
0,4,9:18.5
1,4,9:18.5
-3,5,9:18.5
-2,5,9:18.5
0,5,9:18.5
-5,-4,10:18.5
2,-4,10:18.13
3,-4,10:18.13
-3,-3,10:18.13
-1,-3,10:18.13
0,-3,10:18.13
1,-3,10:18.5
3,-3,10:18.13
4,-3,10:18.13
-2,-2,10:18.13
-1,-2,10:18.13
1,-2,10:18.13
-4,-1,10:18.13
-3,-1,10:18.13
-2,-1,10:17.13
-1,-1,10:18.13
0,-1,10:18.13
1,-1,10:18.13
-7,0,10:18.13
-5,0,10:18.13
-4,0,10:17.13
-3,0,10:17.13
-2,0,10:17.13
-1,0,10:18.13
0,0,10:18.13
1,0,10:18.13
2,0,10:17.13
3,0,10:18.13
4,0,10:18.13
5,0,10:18.13
6,0,10:18.5
-7,1,10:18.13
-6,1,10:18.13
-4,1,10:18.13
-3,1,10:18.13
-2,1,10:17.13
-1,1,10:17.13
0,1,10:17.13
1,1,10:17.13
2,1,10:18.13
-6,2,10:18.13
-5,2,10:18.13
-2,2,10:17.13
-1,2,10:18.13
0,2,10:18.13
1,2,10:18.13
-6,3,10:18.13
-3,3,10:18.13
-2,3,10:17.13
-1,3,10:18.13
0,3,10:18.13
2,3,10:18.13
3,3,10:18.13
-3,4,10:18.13
-2,4,10:18.13
-1,4,10:17.13
0,4,10:18.13
1,4,10:18.13
2,4,10:18.5
-3,5,10:18.13
-2,5,10:18.13
-1,5,10:18.13
0,5,10:17.13
2,5,10:18.13
3,5,10:18.13
-4,6,10:18.5
0,6,10:18.13
3,6,10:18.13
-1,7,10:18.13
2,7,10:18.13
4,7,10:18.5
1,8,10:18.13
2,8,10:18.13
-1,9,10:18.13
0,9,10:18.13
2,9,10:18.5
-1,-2,11:18.13
-2,-1,11:18.13
-1,-1,11:18.13
0,-1,11:18.5
1,-1,11:18.13
2,-1,11:18.13
-3,0,11:18.5
-2,0,11:17.13
-1,0,11:18.13
0,0,11:18.13
1,0,11:18.13
2,0,11:18.13
3,0,11:18.13
-2,1,11:17.13
-1,1,11:18.13
0,1,11:18.13
1,1,11:18.13
2,1,11:18.13
-2,2,11:18.13
-1,2,11:18.13
0,2,11:18.5
-4,3,11:18.5
-3,3,11:18.13
-2,3,11:18.13
-1,3,11:18.13
0,3,11:18.13
-3,4,11:18.13
-2,4,11:18.13
0,4,11:18.13
-2,5,11:18.13
-1,5,11:18.13
0,5,11:18.5
1,5,11:18.13
-1,6,11:18.13
1,6,11:18.13
-2,7,11:18.13
-1,7,11:18.13
-3,-5,12:18.5
-2,-5,12:18.5
0,-5,12:18.5
-6,-3,12:18.5
-4,-3,12:18.5
-2,-3,12:18.5
-1,-3,12:18.5
-7,-2,12:18.5
-6,-2,12:18.5
-3,-2,12:18.5
-1,-2,12:18.5
3,-2,12:18.5
-7,-1,12:18.5
-5,-1,12:18.5
2,-1,12:18.5
-7,0,12:18.5
-4,0,12:18.5
-2,0,12:17.13
0,0,12:18.5
2,0,12:18.5
-6,1,12:18.5
-5,1,12:18.5
-4,1,12:18.5
-2,1,12:17.13
1,1,12:18.5
-3,2,12:18.5
2,2,12:18.5
-4,3,12:18.5
-4,5,12:18.5
-5,-8,13:18.13
-7,-7,13:18.5
-6,-7,13:18.13
-3,-6,13:18.5
-7,-5,13:18.13
-6,-5,13:18.5
-3,-5,13:18.5
-2,-5,13:18.5
-1,-5,13:18.5
-7,-4,13:17.13
-6,-4,13:18.13
-4,-4,13:18.13
-3,-4,13:18.13
-6,-3,13:17.13
-5,-3,13:18.5
-4,-3,13:18.13
2,-3,13:18.5
-7,-2,13:18.13
-6,-2,13:17.13
-3,-2,13:18.13
-2,-2,13:18.5
1,-2,13:18.5
2,-2,13:18.5
-9,-1,13:18.5
-7,-1,13:18.13
-6,-1,13:18.5
-5,-1,13:17.13
-2,-1,13:18.5
-8,0,13:18.13
-7,0,13:18.13
-5,0,13:18.13
-4,0,13:17.13
-3,0,13:17.13
-2,0,13:17.13
-4,1,13:18.5
-2,1,13:17.13
3,1,13:18.5
-7,2,13:18.5
-4,2,13:18.5
-1,2,13:18.5
3,2,13:18.5
-2,3,13:18.5
-3,4,13:18.5
-7,-5,14:18.13
-7,-3,14:18.13
-6,-3,14:18.13
-4,-3,14:18.13
-3,-3,14:18.13
-2,-3,14:18.13
-5,-2,14:18.13
-2,-2,14:18.13
-1,-2,14:18.13
-6,-1,14:18.13
-5,-1,14:18.13
-4,-1,14:18.13
-3,-1,14:18.5
-2,-1,14:18.13
-1,-1,14:18.5
-6,0,14:18.13
-5,0,14:18.13
-4,0,14:18.13
-3,0,14:18.13
-2,0,14:17.13
-1,0,14:18.13
-4,1,14:18.13
-3,1,14:18.5
-2,1,14:17.13
-2,2,14:18.13
-4,-5,15:18.5
-1,-5,15:18.5
-5,-4,15:18.5
0,-4,15:18.5
-2,-3,15:18.5
0,-3,15:18.5
2,-3,15:18.5
-4,-2,15:18.5
-2,-2,15:18.5
1,-2,15:18.5
-7,-1,15:18.5
-5,-1,15:18.5
-4,-1,15:18.5
1,-1,15:18.5
-5,0,15:18.5
-2,0,15:17.13
-1,0,15:18.5
1,0,15:18.5
-4,1,15:18.5
-2,1,15:17.13
1,1,15:18.5
2,2,15:18.5
-6,3,15:18.5
-2,3,15:18.5
-1,3,15:18.5
1,3,15:18.5
-5,4,15:18.5
-4,5,15:18.5
-1,5,15:18.5
0,5,15:18.5
-3,-5,16:18.5
-1,-5,16:18.5
-3,-4,16:18.5
-1,-4,16:18.5
-2,-3,16:18.5
-4,-2,16:18.5
-3,-2,16:18.5
0,-2,16:18.5
-4,0,16:18.5
-3,0,16:18.13
-2,0,16:17.13
-1,0,16:18.13
0,0,16:18.5
1,0,16:18.5
3,0,16:18.5
-5,1,16:18.5
-4,1,16:18.5
-2,1,16:17.13
-1,1,16:18.13
1,1,16:18.5
2,1,16:18.5
-5,2,16:18.5
-4,2,16:18.5
-3,2,16:18.13
-2,2,16:17.13
0,2,16:18.13
3,2,16:18.5
-6,3,16:18.5
-4,3,16:18.13
-2,3,16:17.13
-1,3,16:18.13
0,3,16:18.5
3,3,16:18.13
-5,4,16:18.5
-3,4,16:18.13
-2,4,16:18.13
-1,4,16:17.13
1,4,16:18.13
-3,5,16:18.5
-1,5,16:18.13
3,5,16:18.5
-3,-4,17:18.5
-6,-3,17:18.5
-4,-3,17:18.5
-1,-3,17:18.5
0,-3,17:18.5
1,-3,17:18.5
2,-3,17:18.5
-4,-2,17:18.5
-2,-2,17:18.5
-1,-2,17:18.5
0,-2,17:18.5
-7,-1,17:18.5
-6,-1,17:18.5
-5,-1,17:18.5
-2,-1,17:18.5
1,-1,17:18.5
-6,0,17:18.5
-5,0,17:18.5
-4,0,17:18.5
-3,0,17:18.13
-2,0,17:17.13
-1,0,17:18.13
0,0,17:18.5
3,0,17:18.5
-6,1,17:18.5
-4,1,17:18.13
-2,1,17:17.13
-1,1,17:18.13
0,1,17:18.13
3,1,17:18.5
-5,2,17:18.5
-2,2,17:18.13
-1,2,17:18.13
0,2,17:18.13
1,2,17:18.5
-3,3,17:18.13
-2,3,17:18.13
-1,3,17:18.13
0,3,17:18.13
1,3,17:18.13
-4,4,17:18.5
-2,4,17:18.5
-1,4,17:18.5
0,4,17:18.13
-4,5,17:18.5
0,5,17:18.13
-1,-5,18:18.13
0,-4,18:18.5
3,-4,18:18.13
-1,-3,18:18.13
4,-3,18:18.13
5,-3,18:18.13
-2,-2,18:18.13
-1,-2,18:18.13
1,-2,18:18.13
2,-2,18:18.13
4,-2,18:18.13
5,-2,18:18.5
0,-1,18:18.13
1,-1,18:17.13
2,-1,18:18.13
3,-1,18:18.5
-3,0,18:18.13
-2,0,18:17.13
-1,0,18:17.13
0,0,18:17.13
5,0,18:18.5
-2,1,18:17.13
0,1,18:18.13
2,1,18:18.5
3,1,18:18.13
-1,2,18:18.13
-1,3,18:18.13
2,3,18:18.5
0,-3,19:18.13
2,-3,19:18.13
-1,-2,19:18.13
1,-2,19:18.13
-3,-1,19:18.13
-2,-1,19:18.13
-1,-1,19:18.13
0,-1,19:18.13
1,-1,19:18.13
2,-1,19:18.13
-4,0,19:18.13
-2,0,19:17.13
0,0,19:18.13
1,0,19:18.13
3,0,19:18.13
-4,1,19:18.13
-2,1,19:17.13
-1,1,19:18.13
0,1,19:18.13
1,1,19:18.13
-3,-2,20:18.5
-2,-2,20:18.13
-1,-2,20:18.13
-4,-1,20:18.13
-2,-1,20:18.13
-1,-1,20:18.13
0,-1,20:18.13
-4,0,20:18.13
-3,0,20:18.13
-2,0,20:17.13
0,0,20:18.13
1,0,20:18.13
-4,1,20:18.5
-3,1,20:18.13
-2,1,20:18.13
-1,1,20:18.13
0,1,20:18.13
-3,2,20:18.13
0,2,20:18.13
2,3,20:18.5
0,4,20:18.5
-2,-5,21:18.5
0,-5,21:18.5
-4,-4,21:18.5
-2,-4,21:18.5
-1,-4,21:18.5
-3,-3,21:18.5
-3,-2,21:18.5
-2,-2,21:18.5
-1,-2,21:18.5
0,-2,21:18.5
1,-2,21:18.5
3,-2,21:18.5
-2,-1,21:18.5
-1,-1,21:18.5
1,-1,21:18.5
3,-1,21:18.5
-7,0,21:18.5
-6,0,21:18.5
-3,0,21:18.5
-2,0,21:17.13
-1,0,21:18.5
0,0,21:18.5
1,0,21:18.5
3,0,21:18.5
-6,1,21:18.5
-5,1,21:18.5
-4,1,21:18.5
-3,1,21:18.5
-2,1,21:18.5
-1,1,21:18.5
0,1,21:18.5
1,1,21:18.5
3,1,21:18.5
-6,2,21:18.5
-2,2,21:18.5
-1,4,21:18.5
1,4,21:18.5
-3,5,21:18.5
-6,-5,22:18.5
-4,-5,22:18.5
-2,-4,22:18.5
-7,-3,22:18.5
-6,-3,22:18.13
-5,-3,22:18.13
-4,-3,22:18.13
-3,-3,22:18.13
0,-3,22:18.5
-6,-2,22:18.13
-4,-2,22:17.13
-3,-2,22:18.13
-2,-2,22:18.5
-7,-1,22:18.5
-3,-1,22:17.13
0,-1,22:18.13
-3,0,22:18.13
-2,0,22:17.13
-5,1,22:18.13
-4,2,22:18.13
-1,-5,23:18.5
0,-5,23:18.5
-2,-3,23:18.5
0,-3,23:18.5
2,-3,23:18.5
-5,-2,23:18.5
3,-2,23:18.5
-3,-1,23:18.5
1,-1,23:18.5
3,-1,23:18.5
-6,0,23:18.5
-5,0,23:18.5
-4,0,23:18.13
-3,0,23:18.5
-2,0,23:17.13
0,0,23:18.5
-4,1,23:18.13
-2,1,23:18.5
3,1,23:18.5
-4,2,23:18.5
-3,2,23:18.13
2,2,23:18.5
-3,4,23:18.5
-4,5,23:18.5
-2,5,23:18.5
0,5,23:18.5
-1,-5,24:18.5
1,-4,24:18.5
-6,-3,24:18.5
-3,-3,24:18.5
-2,-3,24:18.5
-1,-3,24:18.5
0,-3,24:18.5
1,-3,24:18.5
-7,-2,24:18.5
-6,-2,24:18.5
-5,-2,24:18.5
-4,-2,24:18.5
-2,-2,24:18.5
0,-2,24:18.5
1,-2,24:18.5
-3,0,24:18.5
-2,0,24:17.13
-1,0,24:18.5
1,0,24:18.5
-6,1,24:18.5
1,1,24:18.5
-7,2,24:18.5
-6,2,24:18.5
-4,2,24:18.5
2,3,24:18.5
-3,5,24:18.5
-2,5,24:18.5
-3,-3,25:18.13
-2,-3,25:18.13
-5,-2,25:18.5
-3,-2,25:18.5
-1,-2,25:18.13
-3,-1,25:18.13
-1,-1,25:18.13
0,-1,25:18.13
-6,0,25:18.5
-4,0,25:18.13
-3,0,25:17.13
-2,0,25:17.13
-3,1,25:18.5
-2,1,25:18.13
-2,2,25:18.13
-1,-2,26:18.13
-2,0,26:17.13
-1,0,26:18.13
0,1,26:18.13
-2,-3,27:18.13
-5,-2,27:18.5
-2,-2,27:18.5
-1,-2,27:18.5
-4,-1,27:18.5
-2,-1,27:18.5
-6,0,27:18.13
-3,0,27:18.5
-2,0,27:17.13
-1,0,27:18.5
1,0,27:18.5
2,0,27:18.13
-2,1,27:18.5
-2,2,27:18.5
-1,2,27:18.5
-3,3,27:18.5
-1,-2,28:18.5
0,-2,28:18.13
-4,0,28:18.5
-2,0,28:17.13
-1,0,28:18.5
1,0,28:18.5
-2,1,28:18.13
-1,1,28:17.13
1,2,28:18.13
2,2,28:18.13
-2,3,28:18.5
1,3,28:18.13
-2,0,29:17.13
-4,-1,30:18.5
-2,-1,30:18.5
-2,0,30:17.13
-3,1,30:18.5
-2,1,30:18.13
-2,0,31:17.13
-2,1,31:18.13
0,1,31:18.5
-1,2,31:18.13
-3,-1,32:18.5
-1,-1,32:18.5
-2,0,32:18.13
-1,0,32:18.13
-2,0,33:18.13
