[META]
version=2.0
spawnOnBlockType=2
spawnSunlight=True
spawnDarkness=True
spawnWater=False
spawnLava=False
underFill=False
randomRotation=True
dig=True
tree=False
branch=False
needsFoundation=True
rarity=100
collisionPercentage=20
spawnElevationMin=0
spawnElevationMax=200
spawnInBiome=Custom
[DATA]
-1,-2,-3:17.12
1,0,-3:17.12
-3,1,-3:17.12
-1,1,-3:17.12
-2,3,-3:17.12
1,3,-3:17.12
-1,-2,-2:17.12
-1,-1,-2:17.12
-4,0,-2:17.12
1,0,-2:17.12
-3,1,-2:17.12
-1,1,-2:17.12
-4,2,-2:17.12
0,2,-2:17.12
-2,3,-2:17.12
1,3,-2:17.12
-1,-2,-1:17.12
-1,-1,-1:17.12
-4,0,-1:17.12
-1,0,-1:17.12
1,0,-1:17.12
-3,1,-1:17.12
-2,1,-1:17.12
-1,1,-1:17.12
-4,2,-1:17.12
-1,2,-1:17.12
0,2,-1:17.12
-2,3,-1:17.12
0,3,-1:17.12
1,3,-1:17.12
-1,-2,0:17.12
-2,-1,0:17.12
-1,-1,0:17.12
2,-1,0:17.12
-4,0,0:17.12
-1,0,0:17.12
0,0,0:17.12
1,0,0:17.12
-3,1,0:17.12
-2,1,0:17.12
-1,1,0:17.12
0,1,0:17.12
-4,2,0:17.12
-2,2,0:17.12
-1,2,0:17.12
0,2,0:17.12
-2,3,0:17.12
0,3,0:17.12
1,3,0:17.12
-1,-1,1:17.12
-1,0,1:17.12
0,0,1:17.12
1,0,1:17.12
-3,1,1:17.12
-2,1,1:17.12
-1,1,1:17.12
0,1,1:17.12
-1,2,1:17.12
0,2,1:17.12
-1,0,2:17.12
0,0,2:17.12
-2,1,2:17.12
-1,1,2:17.12
0,1,2:17.12
-1,0,3:17.12
0,0,3:17.12
-2,1,3:17.12
-1,1,3:17.12
0,1,3:17.12
-1,0,4:17.12
0,0,4:17.12
-1,1,4:17.12
0,1,4:17.12
-1,0,5:17.12
0,0,5:17.12
-1,1,5:17.12
0,1,5:17.12
-1,0,6:17.12
0,0,6:17.12
-1,1,6:17.12
0,1,6:17.12
-1,0,7:17.12
0,0,7:17.12
-1,1,7:17.12
0,1,7:17.12
-1,0,8:17.12
0,0,8:17.12
-1,1,8:17.12
0,1,8:17.12
-1,0,9:17.12
0,0,9:17.12
-1,1,9:17.12
0,1,9:17.12
-1,0,10:17.12
0,0,10:17.12
-1,1,10:17.12
0,1,10:17.12
-1,0,11:17.12
0,0,11:17.12
-1,1,11:17.12
0,1,11:17.12
-1,0,12:17.12
0,0,12:17.12
-1,1,12:17.12
0,1,12:17.12
-1,0,13:17.12
0,0,13:17.12
-1,1,13:17.12
0,1,13:17.12
-3,0,14:18.13
-1,0,14:17.12
0,0,14:17.12
-3,1,14:18.13
-2,1,14:17.12
-1,1,14:17.12
0,1,14:17.12
-2,2,14:18.13
-1,2,14:18.13
-1,0,15:17.12
0,0,15:17.12
-1,1,15:17.12
0,1,15:17.12
-1,0,16:17.12
0,0,16:17.12
-2,1,16:18.13
-1,1,16:17.12
0,1,16:17.12
-2,2,16:18.13
-1,2,16:17.12
0,2,16:18.13
-1,3,16:18.13
-1,0,17:17.12
0,0,17:17.12
-1,1,17:17.12
0,1,17:17.12
-2,-2,18:18.5
-1,-2,18:18.5
0,-2,18:18.5
-1,-1,18:17.12
0,-1,18:18.5
-1,0,18:17.12
0,0,18:17.12
-1,1,18:17.12
0,1,18:17.12
-1,0,19:17.12
0,0,19:17.12
-1,1,19:17.12
0,1,19:17.12
-1,0,20:17.12
0,0,20:17.12
-1,1,20:17.12
0,1,20:17.12
0,-2,21:18.13
1,-2,21:18.13
2,-2,21:18.13
0,-1,21:18.13
1,-1,21:17.12
2,-1,21:18.13
-1,0,21:17.12
0,0,21:17.12
1,0,21:18.13
2,0,21:18.13
-1,1,21:17.12
0,1,21:17.12
-1,0,22:17.12
0,0,22:17.12
-1,1,22:17.12
0,1,22:17.12
-3,-2,23:18.13
-2,-2,23:18.13
-1,-2,23:18.13
-3,-1,23:18.13
-1,-1,23:18.13
-2,0,23:18.13
-1,0,23:17.12
0,0,23:17.12
-1,1,23:17.12
0,1,23:17.12
-3,-4,24:18.13
-2,-4,24:18.13
-5,-3,24:18.13
-4,-3,24:18.13
-3,-3,24:18.13
-2,-3,24:17.12
-1,-3,24:18.13
-5,-2,24:18.13
-4,-2,24:18.13
-3,-2,24:17.12
-2,-2,24:18.13
-4,-1,24:17.12
-3,-1,24:18.13
-2,-1,24:17.12
-5,0,24:18.13
-4,0,24:18.13
-3,0,24:18.13
-1,0,24:17.12
0,0,24:17.12
-1,1,24:17.12
0,1,24:17.12
-5,-4,25:18.13
-3,-4,25:18.13
-4,-3,25:18.13
-3,-3,25:18.13
-2,-3,25:18.13
-5,-2,25:18.13
-2,-2,25:18.13
-4,-1,25:18.13
-3,-1,25:18.13
-2,-1,25:18.13
-1,0,25:17.12
0,0,25:17.12
-1,1,25:17.12
0,1,25:17.12
-1,0,26:17.12
0,0,26:17.12
-1,1,26:17.12
0,-2,27:18.13
0,-1,27:18.13
1,-1,27:17.12
2,-1,27:18.13
-1,0,27:17.12
0,0,27:17.12
1,0,27:18.13
-2,1,27:18.13
-1,1,27:17.12
-4,2,27:18.13
-3,2,27:18.13
-2,2,27:17.12
-1,2,27:18.13
-3,3,27:17.12
-2,3,27:18.13
-1,3,27:18.13
-4,4,27:18.5
-3,4,27:18.5
-2,4,27:18.5
2,-3,28:18.13
3,-3,28:18.5
1,-2,28:18.13
2,-2,28:17.12
1,-1,28:18.13
2,-1,28:18.13
3,-1,28:18.5
-1,0,28:17.12
0,0,28:17.12
-1,1,28:17.12
-3,-6,29:18.13
-4,-5,29:18.13
-3,-5,29:18.13
-7,-4,29:18.13
-4,-4,29:18.13
0,-4,29:18.13
-7,-3,29:18.13
-6,-3,29:18.13
-5,-3,29:18.13
-4,-3,29:18.13
-3,-3,29:18.13
-2,-3,29:18.13
1,-3,29:18.13
-4,-2,29:18.13
-3,-2,29:18.13
-2,-2,29:18.13
-1,-2,29:18.13
0,-2,29:18.13
1,-2,29:18.13
2,-2,29:18.5
-4,-1,29:18.13
-3,-1,29:18.13
-2,-1,29:18.13
2,-1,29:18.5
3,-1,29:18.5
-5,0,29:18.13
-4,0,29:18.13
-3,0,29:18.13
-2,0,29:18.13
-1,0,29:17.12
0,0,29:17.12
1,0,29:18.13
2,0,29:18.5
3,0,29:18.5
-1,1,29:17.12
1,1,29:18.13
3,1,29:18.5
0,2,29:18.13
1,2,29:18.13
3,2,29:18.5
-2,3,29:18.5
1,3,29:18.5
2,3,29:18.5
3,3,29:18.5
4,3,29:18.5
-2,4,29:18.5
-1,5,29:18.5
1,5,29:18.5
3,5,29:18.5
0,-7,30:18.5
0,-6,30:18.5
-3,-5,30:18.5
2,-5,30:18.5
3,-5,30:18.5
-1,-4,30:18.5
0,-4,30:18.5
1,-4,30:18.5
2,-4,30:18.5
3,-4,30:18.5
5,-4,30:18.5
-3,-3,30:18.5
-1,-3,30:18.5
0,-3,30:18.5
1,-3,30:18.5
2,-3,30:18.5
3,-3,30:18.5
4,-3,30:18.5
-3,-2,30:18.5
-2,-2,30:18.5
-1,-2,30:18.5
0,-2,30:18.5
1,-2,30:18.5
2,-2,30:18.5
4,-2,30:18.5
-3,-1,30:18.5
-2,-1,30:18.5
-1,-1,30:18.5
0,-1,30:18.5
1,-1,30:18.5
-4,0,30:18.5
-2,0,30:18.5
-1,0,30:17.12
0,0,30:17.12
1,0,30:18.5
2,0,30:18.5
-3,1,30:18.5
-1,1,30:17.12
4,1,30:18.5
-2,2,30:18.5
1,2,30:18.5
2,2,30:18.5
4,2,30:18.5
-2,3,30:18.5
0,4,30:18.5
1,4,30:18.5
3,4,30:18.5
1,5,30:18.5
2,5,30:18.5
-4,-4,31:18.5
0,-4,31:18.5
1,-4,31:18.5
2,-4,31:18.5
-3,-3,31:18.5
-2,-3,31:18.5
-1,-3,31:18.5
2,-3,31:18.5
-6,-2,31:18.5
-4,-2,31:18.5
-3,-2,31:18.5
-2,-2,31:18.5
-1,-2,31:18.5
0,-2,31:18.5
2,-2,31:18.5
3,-2,31:18.5
-6,-1,31:18.5
-4,-1,31:18.5
-1,-1,31:18.5
2,-1,31:18.5
-7,0,31:18.5
-6,0,31:18.5
-5,0,31:18.5
-4,0,31:18.5
-3,0,31:18.5
-1,0,31:17.12
0,0,31:17.12
1,0,31:18.5
-6,1,31:18.5
-4,1,31:18.5
-3,1,31:18.5
-1,1,31:17.12
0,1,31:18.5
-4,2,31:18.5
0,2,31:18.5
-1,3,31:18.5
-2,-3,32:18.5
-2,-2,32:17.12
-1,-2,32:18.5
-3,-1,32:18.5
-2,-1,32:18.5
-1,-1,32:17.12
0,-1,32:18.5
-2,0,32:18.5
-1,0,32:17.12
0,0,32:17.12
-1,1,32:17.12
0,2,32:17.12
1,2,32:18.13
2,2,32:18.13
0,3,32:18.13
1,3,32:17.12
2,3,32:18.13
3,3,32:18.5
-1,4,32:18.5
1,4,32:18.13
2,4,32:18.13
3,4,32:18.5
4,4,32:18.5
5,4,32:18.5
0,5,32:18.5
1,5,32:18.5
5,5,32:18.5
4,6,32:18.5
-2,-5,33:18.5
2,-4,33:18.5
-3,-3,33:18.5
-1,-3,33:18.5
0,-3,33:18.5
3,-3,33:18.5
-3,-2,33:18.5
-2,-2,33:18.5
0,-2,33:18.5
2,-2,33:18.5
3,-2,33:18.5
-5,-1,33:18.5
-3,-1,33:18.5
-2,-1,33:18.5
-1,-1,33:18.5
0,-1,33:18.5
1,-1,33:18.5
2,-1,33:18.5
-2,0,33:18.5
-1,0,33:17.12
0,0,33:17.12
3,0,33:18.5
-4,1,33:18.5
-1,1,33:17.12
1,1,33:18.5
3,1,33:18.5
5,1,33:18.5
6,1,33:18.5
-3,2,33:18.5
-1,2,33:18.5
0,2,33:18.5
2,2,33:18.5
3,2,33:18.5
4,2,33:18.5
6,2,33:18.5
-3,3,33:18.5
-2,3,33:18.5
-1,3,33:18.5
0,3,33:18.5
1,3,33:18.5
-3,4,33:18.5
-2,4,33:18.5
0,4,33:18.5
-2,5,33:18.5
2,5,33:18.5
-1,-3,34:18.5
-2,-2,34:18.5
0,-2,34:18.5
1,-1,34:18.5
-2,0,34:18.5
0,0,34:17.12
1,0,34:18.5
3,0,34:18.5
-2,1,34:18.5
-1,1,34:17.12
0,1,34:18.5
1,1,34:18.5
2,1,34:18.5
0,2,34:18.5
-3,3,34:18.5
-2,3,34:18.5
0,3,34:18.5
1,3,34:18.5
2,3,34:18.5
3,3,34:18.5
-3,4,34:18.5
0,4,34:18.5
3,4,34:18.5
-1,5,34:18.5
1,6,34:18.5
0,-3,35:18.5
-2,-1,35:18.5
-1,-1,35:18.5
0,-1,35:18.5
1,-1,35:18.5
3,-1,35:18.5
-3,0,35:18.5
0,0,35:17.12
1,0,35:18.5
2,0,35:18.5
-4,1,35:18.5
-3,1,35:18.5
-2,1,35:18.5
-1,1,35:17.12
0,1,35:18.5
-3,2,35:18.5
-1,2,35:18.5
0,2,35:18.5
1,2,35:18.5
2,2,35:18.5
5,2,35:18.5
-3,3,35:18.5
1,3,35:18.5
2,3,35:18.5
3,3,35:18.5
-1,4,35:18.5
0,4,35:18.5
2,4,35:18.5
2,5,35:18.5
-5,-2,36:18.5
-4,-2,36:18.5
-4,-1,36:18.5
-2,-1,36:18.5
0,-1,36:18.5
1,-1,36:18.5
-6,0,36:18.5
-3,0,36:18.5
-2,0,36:18.5
-1,0,36:18.5
0,0,36:17.12
2,0,36:18.5
-7,1,36:18.5
-5,1,36:18.5
-4,1,36:18.5
-3,1,36:18.5
-2,1,36:17.12
-1,1,36:17.12
2,1,36:18.5
-3,2,36:17.12
-2,2,36:18.5
-1,2,36:18.5
-4,3,36:18.5
-3,3,36:18.5
-2,3,36:18.5
-4,-3,37:18.5
-3,-3,37:18.5
1,-3,37:18.5
-5,-2,37:18.5
-4,-2,37:18.5
-3,-2,37:18.5
-1,-2,37:18.5
0,-2,37:18.5
1,-2,37:18.5
-5,-1,37:18.5
0,-1,37:18.5
1,-1,37:18.5
2,-1,37:18.5
-6,0,37:18.5
-5,0,37:18.5
-4,0,37:18.5
-3,0,37:18.5
-2,0,37:18.5
0,0,37:17.12
-6,1,37:18.5
-5,1,37:18.5
-3,1,37:18.5
-1,1,37:17.12
0,1,37:18.5
1,1,37:18.5
-4,2,37:18.5
-3,2,37:18.5
1,2,37:18.5
2,2,37:18.5
-7,3,37:18.5
-4,3,37:18.5
-2,3,37:18.5
1,3,37:18.5
-7,4,37:18.5
-5,4,37:18.5
-2,4,37:18.5
-6,5,37:18.5
-1,-1,38:18.5
0,-1,38:18.5
-3,0,38:18.5
-1,0,38:18.5
0,0,38:17.12
1,0,38:18.5
2,0,38:18.5
-3,1,38:18.5
-2,1,38:18.5
-1,1,38:17.12
-1,3,38:18.5
1,-4,39:18.5
0,-3,39:18.5
1,-3,39:18.5
-1,-2,39:18.5
1,-2,39:18.5
4,-2,39:18.5
-3,-1,39:18.5
-2,-1,39:18.5
-1,-1,39:18.5
1,-1,39:18.5
3,-1,39:18.5
-2,0,39:18.5
0,0,39:17.12
1,0,39:18.5
-4,1,39:18.5
-2,1,39:18.5
-1,1,39:17.12
-3,2,39:18.5
0,2,39:18.5
0,3,39:18.5
-1,4,39:18.5
-1,-2,40:18.5
-3,-1,40:18.5
-1,-1,40:18.5
1,-1,40:18.5
-3,0,40:18.5
0,0,40:17.12
2,0,40:18.5
-4,1,40:18.5
-1,1,40:17.12
1,1,40:18.5
-4,2,40:18.5
-2,2,40:18.5
0,3,40:18.5
0,-3,41:18.5
-2,-1,41:18.5
0,-1,41:18.5
1,-1,41:18.5
-2,0,41:18.5
-1,0,41:18.5
0,0,41:17.12
1,0,41:18.5
2,0,41:18.5
-1,1,41:17.12
0,1,41:18.5
1,1,41:18.5
0,2,41:18.5
0,3,41:18.5
-1,-3,42:18.5
0,-2,42:18.5
-1,-1,42:18.5
0,-1,42:18.5
2,-1,42:18.5
-3,0,42:18.5
-2,0,42:18.5
-1,0,42:18.13
-3,1,42:18.5
-1,1,42:17.12
0,1,42:18.13
-3,2,42:18.5
-2,2,42:18.5
-1,2,42:17.12
0,2,42:18.5
1,2,42:18.5
-2,3,42:18.5
-1,3,42:18.5
0,3,42:17.12
1,3,42:18.5
-1,4,42:18.5
0,4,42:18.5
1,4,42:18.5
0,-3,43:18.13
-1,-2,43:18.13
1,-2,43:18.13
-3,-1,43:18.5
-2,-1,43:18.5
0,-1,43:18.13
-1,0,43:18.13
1,0,43:18.13
-1,1,43:17.12
1,1,43:18.13
2,1,43:18.5
-2,2,43:18.5
1,2,43:18.5
-3,3,43:18.5
-2,3,43:18.5
-1,3,43:18.5
0,3,43:18.5
1,3,43:18.5
-1,4,43:18.5
-1,-2,44:18.13
0,-2,44:18.13
1,-2,44:18.13
-2,-1,44:18.13
0,-1,44:18.13
1,-1,44:18.13
-2,0,44:18.13
1,0,44:18.13
2,0,44:18.13
-3,1,44:18.13
-1,1,44:17.12
1,1,44:18.13
-4,2,44:18.13
-3,3,44:18.13
-2,4,44:18.13
-2,-2,45:18.5
-1,-2,45:18.5
0,-2,45:18.5
-1,-1,45:18.13
0,-1,45:18.5
-3,0,45:18.13
-1,0,45:18.13
0,0,45:18.5
2,0,45:18.13
-4,1,45:18.13
-3,1,45:18.13
-1,1,45:17.12
0,1,45:18.13
1,2,45:18.13
-2,3,45:18.13
1,3,45:18.13
-1,4,45:18.13
-2,0,46:18.5
-1,0,46:18.5
-2,1,46:18.5
-1,1,46:17.12
0,1,46:18.5
-2,2,46:18.5
-1,2,46:18.5
0,2,46:18.5
-1,0,47:18.5
0,0,47:18.5
-2,1,47:18.5
-1,1,47:17.12
0,1,47:18.5
-1,2,47:18.5
