[META]
version=2.0
spawnOnBlockType=2
spawnSunlight=True
spawnDarkness=True
spawnWater=False
spawnLava=False
underFill=False
randomRotation=True
dig=True
tree=False
branch=False
needsFoundation=True
rarity=100
collisionPercentage=20
spawnElevationMin=0
spawnElevationMax=200
spawnInBiome=Custom
[DATA]
0,0,0:17.12
0,0,1:17.12
0,0,2:17.12
0,-3,3:18.12
-1,0,3:17.12
0,0,3:17.12
0,2,3:18.4
0,3,3:18.4
1,4,3:18.4
0,-4,4:18.12
-2,-3,4:18.12
-1,-3,4:18.12
0,-3,4:18.12
1,-3,4:18.12
2,-3,4:18.12
-1,-2,4:18.12
0,-2,4:18.12
1,-2,4:18.12
2,-2,4:18.12
3,-2,4:18.12
-4,-1,4:18.12
-3,-1,4:18.12
0,-1,4:18.12
1,-1,4:17.12
3,-1,4:18.12
-2,0,4:17.12
0,0,4:17.12
-2,1,4:18.12
0,1,4:17.12
1,1,4:18.12
0,2,4:17.12
2,2,4:18.4
-1,3,4:18.4
0,3,4:18.4
1,3,4:18.4
2,3,4:18.4
-2,4,4:18.4
0,4,4:18.4
1,4,4:18.4
2,4,4:18.4
-1,-5,5:18.12
1,-5,5:18.12
-2,-4,5:18.12
-1,-4,5:18.12
1,-4,5:18.12
-2,-3,5:18.12
1,-3,5:18.12
2,-3,5:18.12
4,-3,5:18.12
5,-3,5:18.12
-3,-2,5:18.12
-2,-2,5:18.12
-1,-2,5:18.12
0,-2,5:18.12
1,-2,5:18.12
2,-2,5:17.12
3,-2,5:18.12
-5,-1,5:18.12
-3,-1,5:18.12
0,-1,5:17.12
1,-1,5:18.12
5,-1,5:18.12
-5,0,5:18.12
-4,0,5:18.12
-3,0,5:18.12
-2,0,5:17.12
-1,0,5:18.12
0,0,5:17.12
2,0,5:18.12
3,0,5:18.12
-3,1,5:18.12
-1,1,5:18.12
-1,2,5:18.4
0,2,5:18.4
-2,3,5:18.4
-1,3,5:18.4
0,3,5:17.12
1,3,5:18.4
-1,4,5:18.4
0,4,5:18.4
0,5,5:18.4
1,5,5:18.4
-2,-4,6:18.12
-1,-4,6:18.12
1,-4,6:18.12
3,-4,6:18.12
-1,-3,6:18.12
0,-3,6:18.12
1,-3,6:18.12
3,-3,6:18.12
-3,-2,6:18.12
0,-2,6:17.12
1,-2,6:18.12
3,-2,6:17.12
4,-2,6:18.12
5,-2,6:18.12
-3,-1,6:18.12
-2,-1,6:18.12
-1,-1,6:18.12
0,-1,6:18.12
1,-1,6:18.12
3,-1,6:18.12
4,-1,6:18.12
-4,0,6:18.12
-3,0,6:17.12
-2,0,6:18.12
-1,0,6:18.12
0,0,6:17.12
3,0,6:18.12
4,0,6:18.12
-5,1,6:18.12
-4,1,6:18.12
-3,1,6:18.12
-1,1,6:18.12
0,1,6:18.12
1,1,6:17.12
-3,2,6:18.12
-2,2,6:18.12
2,2,6:18.12
3,2,6:18.12
-2,3,6:18.12
-1,3,6:18.4
0,3,6:18.4
0,4,6:18.4
-1,5,6:18.4
0,5,6:18.4
0,-5,7:18.12
-2,-4,7:18.12
1,-4,7:18.12
-2,-3,7:18.12
-1,-3,7:18.12
0,-3,7:17.12
2,-3,7:18.12
3,-3,7:18.12
-4,-2,7:18.12
-3,-2,7:18.12
-1,-2,7:18.12
1,-2,7:18.12
2,-2,7:18.12
3,-2,7:18.12
5,-2,7:18.12
3,-1,7:18.12
-4,0,7:18.12
0,0,7:17.12
2,0,7:18.12
3,0,7:18.12
4,0,7:18.12
-4,1,7:18.12
-3,1,7:18.12
-1,1,7:17.12
0,1,7:18.12
-4,2,7:18.12
-2,2,7:18.12
0,2,7:18.12
1,2,7:17.12
2,2,7:18.12
3,2,7:18.12
-3,3,7:18.12
-2,3,7:18.12
0,3,7:18.4
2,3,7:18.12
1,4,7:18.4
0,-5,8:18.12
1,-5,8:18.12
-1,-4,8:18.12
0,-4,8:18.12
1,-4,8:18.12
2,-4,8:18.12
-1,-3,8:18.12
0,-3,8:17.12
2,-3,8:18.12
-1,-2,8:18.12
1,-2,8:18.12
2,-2,8:18.12
4,-2,8:18.12
-3,-1,8:18.12
-3,0,8:18.12
-2,0,8:18.12
0,0,8:17.12
-3,1,8:18.12
-2,1,8:18.12
-1,1,8:18.12
0,1,8:18.12
1,1,8:18.12
2,1,8:18.12
-4,2,8:18.12
-3,2,8:18.12
-2,2,8:17.12
0,2,8:18.12
1,2,8:18.12
2,2,8:17.12
3,2,8:18.12
4,2,8:18.12
-1,3,8:18.12
2,3,8:18.12
4,3,8:18.12
-2,4,8:18.12
1,4,8:18.12
2,4,8:18.12
3,4,8:18.12
-1,-4,9:18.12
0,-4,9:18.12
-1,-3,9:18.12
-1,-2,9:18.12
-1,-1,9:18.12
0,-1,9:18.12
1,-1,9:18.12
-1,0,9:18.12
0,0,9:17.12
1,0,9:18.12
-3,1,9:18.12
-1,1,9:18.12
1,1,9:18.12
2,1,9:18.12
-3,2,9:18.12
1,2,9:18.12
2,2,9:18.12
3,2,9:18.12
4,2,9:18.12
-3,3,9:18.12
-2,3,9:18.12
2,3,9:18.12
3,3,9:18.12
-2,4,9:18.12
2,4,9:18.12
0,-4,10:18.12
0,-3,10:18.12
-1,-2,10:18.12
0,-2,10:18.12
1,-2,10:18.12
-2,-1,10:18.12
-1,0,10:18.12
0,0,10:17.0
2,0,10:18.12
-2,1,10:18.12
2,1,10:18.12
-2,2,10:18.12
-1,2,10:18.12
1,2,10:18.12
2,2,10:18.12
-3,3,10:18.12
-1,3,10:18.12
1,3,10:18.12
2,3,10:18.12
-1,-2,11:18.12
0,-2,11:18.12
-2,0,11:18.12
0,0,11:17.0
1,0,11:18.12
2,0,11:18.12
-2,1,11:18.12
0,1,11:18.12
1,1,11:18.12
-1,2,11:18.12
0,-2,12:18.4
-2,-1,12:18.4
0,-1,12:18.4
-2,0,12:18.4
0,0,12:18.4
1,0,12:18.4
1,1,12:18.4
-1,2,12:18.4
0,0,13:18.4
