[META]
version=2.0
spawnOnBlockType=2
spawnSunlight=True
spawnDarkness=True
spawnWater=False
spawnLava=False
underFill=False
randomRotation=True
dig=True
tree=False
branch=False
needsFoundation=True
rarity=100
collisionPercentage=20
spawnElevationMin=0
spawnElevationMax=200
spawnInBiome=Custom
[DATA]
1,-3,-3:17.12
-2,-2,-3:17.12
2,-1,-3:17.12
-2,0,-3:17.12
2,1,-3:17.12
-1,-3,-2:17.12
1,-3,-2:17.12
-2,-2,-2:17.12
2,-1,-2:17.12
-2,0,-2:17.12
1,1,-2:17.12
2,1,-2:17.12
-1,-2,-1:17.12
1,-2,-1:17.12
1,-1,-1:17.12
-1,0,-1:17.12
2,0,-1:17.12
1,1,-1:17.12
-1,-2,0:17.12
1,-2,0:17.12
0,-1,0:17.12
1,-1,0:17.12
-1,0,0:17.12
0,0,0:17.12
1,0,0:17.12
2,0,0:17.12
1,1,0:17.12
0,-1,1:17.12
1,-1,1:17.12
0,0,1:17.12
1,0,1:17.12
0,-1,2:17.12
1,-1,2:17.12
0,0,2:17.12
-1,-6,3:18.12
1,-6,3:18.12
2,-6,3:18.12
-1,-5,3:18.12
2,-5,3:18.12
4,-5,3:18.12
-1,-4,3:18.12
1,-4,3:18.12
2,-4,3:18.12
-2,-3,3:18.12
-1,-3,3:18.12
1,-3,3:18.12
2,-3,3:18.12
6,-3,3:18.12
-4,-2,3:18.12
-3,-2,3:18.12
-2,-2,3:18.12
4,-2,3:18.12
6,-2,3:18.12
-2,-1,3:18.12
-1,-1,3:18.12
0,-1,3:17.12
1,-1,3:17.12
3,-1,3:18.12
4,-1,3:18.12
5,-1,3:18.12
6,-1,3:18.12
0,0,3:17.12
1,0,3:18.12
6,0,3:18.12
-3,1,3:18.12
-2,1,3:18.12
0,1,3:18.12
1,1,3:18.12
3,1,3:18.12
4,1,3:18.12
5,1,3:18.12
-2,2,3:18.12
1,2,3:18.12
2,2,3:18.12
4,2,3:18.12
-2,3,3:18.12
0,3,3:18.12
1,3,3:18.12
2,3,3:18.12
4,3,3:18.12
1,4,3:18.12
2,4,3:18.12
0,-4,4:18.12
-2,-3,4:18.12
-1,-3,4:18.12
0,-3,4:18.12
0,-2,4:18.12
1,-2,4:18.12
-2,-1,4:18.12
0,-1,4:17.12
1,-1,4:17.12
2,-1,4:18.12
3,-1,4:18.12
1,0,4:18.12
2,0,4:18.12
1,-6,5:18.4
2,-6,5:18.4
0,-5,5:18.12
2,-5,5:18.12
-1,-4,5:18.12
0,-4,5:18.12
1,-4,5:18.12
4,-4,5:18.12
5,-4,5:18.12
-1,-3,5:18.12
1,-3,5:18.12
4,-3,5:18.12
5,-3,5:18.12
6,-3,5:18.4
-3,-2,5:18.12
-1,-2,5:18.12
1,-2,5:18.12
2,-2,5:18.12
3,-2,5:18.12
4,-2,5:18.12
6,-2,5:18.4
-3,-1,5:18.12
0,-1,5:17.12
1,-1,5:17.12
3,-1,5:18.12
4,-1,5:18.12
5,-1,5:18.12
6,-1,5:18.4
-1,0,5:18.12
0,0,5:18.12
1,0,5:18.12
2,0,5:18.12
4,0,5:18.12
-4,1,5:18.12
3,1,5:18.12
0,2,5:18.12
1,2,5:18.12
4,2,5:18.12
5,2,5:18.12
-2,3,5:18.12
-1,3,5:18.12
0,3,5:18.12
1,3,5:18.12
3,3,5:18.12
4,3,5:18.12
0,4,5:18.12
2,4,5:18.12
3,4,5:18.12
-3,-4,6:18.12
-2,-2,6:18.12
4,-2,6:18.12
0,-1,6:17.12
1,-1,6:17.12
-2,1,6:18.12
3,1,6:18.12
-2,-6,7:18.4
2,-6,7:18.4
-3,-5,7:18.12
-2,-5,7:18.12
-1,-5,7:18.12
3,-5,7:18.12
-4,-4,7:18.12
-3,-4,7:18.12
-2,-4,7:18.12
0,-4,7:18.12
1,-4,7:18.12
2,-4,7:18.12
4,-4,7:18.12
-4,-3,7:18.12
-3,-3,7:18.12
-1,-3,7:18.12
0,-3,7:18.12
2,-3,7:18.12
3,-3,7:18.12
4,-3,7:18.12
5,-3,7:18.12
-5,-2,7:18.4
-2,-2,7:18.12
-1,-2,7:18.12
0,-2,7:18.12
1,-2,7:18.12
2,-2,7:18.12
-5,-1,7:18.4
-4,-1,7:18.12
-3,-1,7:18.12
-1,-1,7:18.12
0,-1,7:17.12
1,-1,7:18.12
2,-1,7:18.12
4,-1,7:18.12
-4,0,7:18.12
-3,0,7:18.12
-1,0,7:18.12
0,0,7:18.12
1,0,7:18.12
2,0,7:18.12
3,0,7:18.12
4,0,7:18.12
-4,1,7:18.12
-1,1,7:18.12
0,1,7:18.12
2,1,7:18.12
-4,2,7:18.12
-3,2,7:18.12
1,2,7:18.12
-2,3,7:18.12
0,3,7:18.12
-2,4,7:18.12
-1,4,7:18.12
1,4,7:18.12
-2,-4,8:18.12
3,-3,8:18.12
0,-1,8:17.12
1,1,8:18.12
2,1,8:18.12
-2,2,8:18.12
3,2,8:18.12
-1,3,8:18.12
-2,-6,9:18.12
-1,-6,9:18.12
1,-6,9:18.12
2,-5,9:18.12
1,-4,9:18.12
3,-4,9:18.12
-4,-3,9:18.12
3,-3,9:18.12
0,-2,9:18.12
-5,-1,9:18.12
-4,-1,9:18.12
0,-1,9:17.12
2,-1,9:18.12
4,-1,9:18.12
4,0,9:18.12
2,1,9:18.12
5,1,9:18.12
-4,2,9:18.12
0,2,9:18.12
1,2,9:18.12
2,2,9:18.12
3,2,9:18.12
0,4,9:18.12
1,4,9:18.12
2,4,9:18.12
4,-3,10:18.12
5,-3,10:18.4
0,-1,10:17.12
2,0,10:18.4
-3,2,10:18.4
-2,4,10:18.4
0,4,10:18.4
-2,-6,11:18.12
-1,-6,11:18.12
2,-6,11:18.12
0,-5,11:18.12
2,-5,11:18.12
-3,-4,11:18.12
-2,-4,11:18.12
0,-4,11:18.12
3,-4,11:18.12
-5,-3,11:18.12
-3,-3,11:18.12
-2,-3,11:18.12
0,-3,11:18.12
2,-3,11:18.12
-5,-2,11:18.12
-3,-2,11:18.12
-1,-2,11:18.12
0,-2,11:18.12
1,-2,11:18.12
2,-2,11:18.12
4,-2,11:18.12
-5,-1,11:18.12
-4,-1,11:18.12
-3,-1,11:18.12
-2,-1,11:18.12
0,-1,11:17.12
3,-1,11:18.12
-1,0,11:18.12
0,0,11:17.12
4,0,11:18.12
-5,1,11:18.12
-4,1,11:18.12
-3,1,11:18.12
-2,1,11:18.12
1,1,11:18.12
3,1,11:18.12
-3,2,11:18.12
0,2,11:18.12
1,2,11:18.12
-2,3,11:18.12
0,3,11:18.12
1,3,11:18.12
2,3,11:18.12
-2,4,11:18.12
0,4,11:18.12
1,4,11:18.12
1,-4,12:18.4
-3,-1,12:18.4
0,-1,12:17.12
0,0,12:17.12
-2,-5,13:18.12
-1,-4,13:18.12
3,-4,13:18.12
-3,-3,13:18.12
-1,-3,13:18.12
1,-3,13:18.12
-1,-2,13:18.12
-3,-1,13:18.12
0,-1,13:17.12
1,-1,13:18.12
4,-1,13:18.12
0,0,13:17.12
-4,1,13:18.4
0,2,13:18.12
1,2,13:18.12
0,-5,14:18.12
2,-5,14:18.12
-1,-4,14:18.12
-4,-3,14:18.12
-1,-3,14:18.12
3,-3,14:18.12
4,-3,14:18.12
-3,-2,14:18.12
0,-2,14:18.12
2,-2,14:18.12
3,-2,14:18.12
-4,-1,14:18.12
0,-1,14:17.12
1,-1,14:18.12
3,-1,14:18.12
4,-1,14:18.12
-3,0,14:18.12
0,0,14:17.12
2,0,14:18.12
3,0,14:18.12
-4,1,14:18.12
-2,1,14:18.12
2,1,14:18.12
4,1,14:18.12
-1,2,14:18.12
1,2,14:18.12
-1,3,14:18.12
0,3,14:18.12
0,-2,15:18.12
4,-2,15:18.4
-3,-1,15:18.12
0,-1,15:17.12
0,0,15:17.12
0,-4,16:18.12
1,-4,16:18.12
2,-3,16:18.12
-2,-2,16:18.12
-2,-1,16:18.12
0,-1,16:17.12
1,-1,16:18.12
-3,0,16:18.12
0,0,16:17.12
2,0,16:18.12
-1,-1,17:18.12
0,-1,17:17.12
3,-1,17:18.12
0,0,17:17.12
-1,-4,18:18.12
0,-4,18:18.12
-2,-3,18:18.12
0,-3,18:18.12
-2,-2,18:18.12
1,-2,18:18.12
2,-2,18:18.12
-3,-1,18:18.12
0,-1,18:17.12
1,-1,18:18.12
3,-1,18:18.12
-1,0,18:18.12
0,0,18:18.12
3,0,18:18.12
0,1,18:18.12
0,2,18:18.12
-1,-4,19:18.4
1,-4,19:18.4
2,-2,19:18.4
0,-1,19:17.12
-1,0,19:18.12
-1,1,19:18.12
-2,-2,20:18.12
-1,-2,20:18.12
0,-2,20:18.12
0,-1,20:17.12
1,-1,20:18.12
2,-1,20:18.12
-2,0,20:18.12
0,1,20:18.12
-1,-3,21:18.12
0,-3,21:18.4
-2,-1,21:18.12
0,-1,21:17.12
2,-1,21:18.12
1,1,21:18.12
1,-3,22:18.12
-1,-2,22:18.12
0,-1,22:17.12
0,1,22:18.12
0,-3,23:18.12
2,-2,23:18.12
-2,-1,23:18.12
0,-1,23:17.12
1,-1,23:18.12
-2,0,23:18.12
0,0,23:18.12
2,0,23:18.12
-1,-2,24:18.12
0,-1,24:18.12
1,-1,24:18.12
-1,0,24:18.12
-1,-1,25:18.12
0,-1,25:18.4
0,0,25:18.12
