[META]
version=2.0
spawnOnBlockType=2
spawnSunlight=True
spawnDarkness=True
spawnWater=False
spawnLava=False
underFill=False
randomRotation=True
dig=True
tree=False
branch=False
needsFoundation=True
rarity=100
collisionPercentage=20
spawnElevationMin=0
spawnElevationMax=200
spawnInBiome=Custom
[DATA]
1,-2,-3:17.13
3,-1,-3:17.13
0,0,-3:17.13
1,-2,-2:17.13
2,-2,-2:17.13
1,-1,-2:17.13
3,-1,-2:17.13
0,0,-2:17.13
1,-3,-1:17.13
1,-2,-1:17.13
2,-2,-1:17.13
1,-1,-1:17.13
2,-1,-1:17.13
3,-1,-1:17.13
0,0,-1:17.13
1,-3,0:17.13
1,-2,0:17.13
2,-2,0:17.13
1,-1,0:17.13
2,-1,0:17.13
3,-1,0:17.13
0,0,0:17.13
1,-2,1:17.13
2,-2,1:17.13
1,-1,1:17.13
2,-1,1:17.13
1,-2,2:17.13
2,-2,2:17.13
1,-1,2:17.13
2,-1,2:17.13
1,-2,3:17.13
2,-2,3:17.13
1,-1,3:17.13
2,-1,3:17.13
1,-2,4:17.13
2,-2,4:17.13
-2,-1,4:18.12
0,-1,4:18.12
1,-1,4:17.13
2,-1,4:17.13
-1,0,4:18.12
-2,-3,5:18.12
-1,-2,5:18.12
1,-2,5:17.13
2,-2,5:17.13
-2,-1,5:18.12
1,-1,5:17.13
2,-1,5:17.13
5,0,5:18.12
5,-4,6:18.12
3,-3,6:18.12
7,-3,6:18.12
-3,-2,6:18.12
-1,-2,6:18.12
1,-2,6:17.13
2,-2,6:17.13
8,-2,6:18.12
-4,-1,6:18.12
-1,-1,6:18.12
0,-1,6:17.13
1,-1,6:17.13
2,-1,6:17.13
4,-1,6:18.12
1,0,6:18.12
5,2,6:18.12
2,4,6:18.12
3,4,6:18.12
3,-4,7:18.12
8,-4,7:18.12
0,-3,7:18.12
2,-3,7:18.12
5,-3,7:18.12
8,-3,7:18.12
9,-3,7:18.12
-1,-2,7:18.12
1,-2,7:17.13
2,-2,7:17.13
5,-2,7:18.12
-3,-1,7:18.12
-1,-1,7:17.13
0,-1,7:17.13
1,-1,7:17.13
2,-1,7:17.13
-5,0,7:18.12
1,0,7:17.13
5,0,7:18.12
7,0,7:18.12
-3,1,7:18.12
-1,1,7:18.12
5,2,7:18.12
4,3,7:18.12
4,4,7:18.12
0,5,7:18.4
1,7,7:18.12
5,-6,8:18.12
-1,-4,8:18.12
8,-3,8:18.12
-6,-2,8:18.12
-1,-2,8:18.12
1,-2,8:17.13
2,-2,8:17.13
-4,-1,8:18.12
-3,-1,8:18.12
-2,-1,8:17.13
1,-1,8:17.13
2,-1,8:17.13
-3,0,8:18.12
5,0,8:18.12
6,0,8:18.12
-5,1,8:18.12
1,1,8:17.13
2,1,8:18.12
3,1,8:18.12
6,1,8:18.12
4,2,8:18.12
2,3,8:18.12
3,3,8:18.12
5,3,8:18.12
7,3,8:18.12
-7,4,8:18.12
-6,4,8:18.12
5,4,8:18.12
3,7,8:18.12
4,7,8:18.12
5,-6,9:18.12
3,-4,9:18.12
6,-4,9:18.12
-2,-3,9:18.12
-1,-3,9:18.12
0,-3,9:17.13
2,-3,9:18.12
3,-3,9:18.12
4,-3,9:18.12
5,-3,9:18.12
7,-3,9:18.12
8,-3,9:18.12
-3,-2,9:18.12
0,-2,9:18.12
2,-2,9:17.13
-4,-1,9:18.12
-2,-1,9:18.12
1,-1,9:17.13
2,-1,9:17.13
3,-1,9:18.12
5,-1,9:18.12
6,-1,9:18.12
8,-1,9:18.12
-7,0,9:18.12
-3,0,9:17.13
-2,0,9:18.12
-1,0,9:18.12
7,0,9:18.12
-4,1,9:18.12
4,1,9:18.12
5,1,9:18.12
7,1,9:18.12
8,1,9:18.12
-4,2,9:18.12
1,2,9:17.13
5,2,9:18.12
1,3,9:18.12
2,3,9:18.12
4,3,9:18.12
5,3,9:18.12
-6,4,9:18.12
3,4,9:18.12
5,4,9:18.12
-6,5,9:18.12
0,5,9:18.12
1,5,9:18.12
3,5,9:18.12
4,5,9:18.12
6,5,9:18.12
-4,6,9:18.12
0,6,9:18.12
2,6,9:18.12
4,6,9:18.12
-3,7,9:18.12
0,7,9:18.12
1,7,9:18.12
2,7,9:18.12
2,8,9:18.12
6,-6,10:18.12
4,-5,10:18.12
5,-5,10:18.12
-6,-4,10:18.12
-2,-4,10:18.12
0,-4,10:18.12
1,-4,10:18.12
6,-4,10:18.12
-6,-3,10:18.12
-3,-3,10:18.12
-2,-3,10:18.12
0,-3,10:17.13
2,-3,10:18.12
3,-3,10:18.12
5,-3,10:18.12
7,-3,10:18.12
8,-3,10:18.12
-3,-2,10:18.12
2,-2,10:18.12
3,-2,10:17.13
5,-2,10:18.12
6,-2,10:18.12
8,-2,10:18.12
-7,-1,10:18.12
-4,-1,10:18.12
-3,-1,10:18.12
1,-1,10:17.13
4,-1,10:18.12
6,-1,10:18.12
-7,0,10:18.12
-5,0,10:18.12
-4,0,10:17.13
-1,0,10:18.12
0,0,10:18.12
1,0,10:18.12
3,0,10:17.13
5,0,10:18.12
-5,1,10:18.12
-4,1,10:18.12
-6,2,10:18.12
1,2,10:17.13
2,2,10:18.12
-6,3,10:18.12
1,3,10:18.12
5,3,10:18.12
-4,4,10:18.12
1,4,10:18.12
2,4,10:18.12
3,4,10:18.12
4,4,10:18.12
5,4,10:18.12
-4,5,10:18.12
-1,5,10:18.12
0,5,10:18.12
1,5,10:18.12
2,5,10:18.12
-8,6,10:18.12
-5,6,10:18.12
0,6,10:18.12
4,6,10:18.12
-6,7,10:18.12
-4,8,10:18.12
-3,8,10:18.12
-6,-10,11:18.12
5,-9,11:18.12
3,-8,11:18.12
4,-7,11:18.12
0,-6,11:18.12
3,-6,11:18.12
5,-6,11:18.12
0,-5,11:18.12
2,-5,11:18.12
3,-5,11:18.12
5,-5,11:18.12
-2,-4,11:18.12
2,-4,11:18.12
-5,-3,11:18.12
0,-3,11:17.13
2,-3,11:18.12
4,-3,11:18.12
7,-3,11:18.12
-7,-2,11:18.12
2,-2,11:18.12
3,-2,11:17.13
4,-2,11:18.12
5,-2,11:18.12
2,-1,11:18.12
-7,0,11:18.12
-6,0,11:18.12
1,0,11:17.13
3,0,11:17.13
5,0,11:18.12
-6,1,11:18.12
-5,1,11:17.13
-2,1,11:18.12
3,1,11:18.12
4,1,11:18.12
7,1,11:18.12
-8,2,11:18.12
-4,2,11:18.12
-2,2,11:18.12
1,2,11:18.12
4,2,11:18.12
-9,3,11:18.12
-4,3,11:18.12
-3,3,11:18.12
-2,3,11:18.12
2,3,11:17.13
-6,4,11:18.12
-5,4,11:18.12
0,4,11:18.12
2,4,11:18.12
5,4,11:18.12
-9,5,11:18.12
-7,5,11:18.12
-3,5,11:18.12
-8,6,11:18.12
-6,6,11:18.12
-5,7,11:18.12
-3,7,11:18.12
1,7,11:18.12
3,7,11:18.12
-6,8,11:18.12
-5,8,11:18.12
-1,8,11:18.12
-5,-11,12:18.12
3,-11,12:18.12
-6,-10,12:18.12
-5,-10,12:18.12
3,-10,12:18.12
-4,-9,12:18.12
3,-9,12:18.12
-7,-8,12:18.12
-4,-8,12:18.12
1,-8,12:18.12
3,-8,12:18.12
6,-8,12:18.12
-6,-7,12:18.12
-5,-7,12:18.12
3,-7,12:18.12
-7,-6,12:18.12
3,-6,12:18.12
4,-6,12:18.12
6,-6,12:18.12
-6,-5,12:18.12
-2,-5,12:18.12
-1,-5,12:18.12
1,-5,12:18.12
4,-5,12:18.12
5,-5,12:18.12
6,-5,12:18.12
7,-5,12:18.12
-4,-4,12:18.12
-2,-4,12:18.12
0,-4,12:18.12
8,-4,12:18.4
-6,-3,12:18.12
-1,-3,12:17.13
0,-3,12:18.12
1,-3,12:18.12
4,-3,12:17.13
0,-1,12:18.12
2,-1,12:18.12
-9,0,12:18.12
-8,0,12:18.12
-5,0,12:18.12
-2,0,12:18.4
1,0,12:17.13
3,0,12:18.12
7,0,12:18.12
-9,1,12:18.12
-6,1,12:18.12
-5,1,12:17.13
1,1,12:18.12
4,1,12:17.13
5,1,12:18.12
7,1,12:18.12
-8,2,12:18.12
-7,2,12:18.12
-6,2,12:18.12
-5,2,12:18.12
-3,2,12:18.12
-2,2,12:18.12
2,2,12:18.12
4,2,12:18.12
6,2,12:18.12
-8,3,12:18.12
-5,3,12:18.12
2,3,12:18.12
-1,4,12:18.12
2,4,12:17.13
3,4,12:18.12
4,4,12:18.12
-7,5,12:18.12
-4,5,12:18.12
-1,5,12:18.12
0,5,12:18.12
1,5,12:18.12
3,5,12:18.12
-8,6,12:18.12
-4,6,12:18.12
-1,6,12:18.12
0,6,12:18.12
1,6,12:18.12
-6,7,12:18.12
-5,7,12:18.12
-1,7,12:18.12
3,7,12:18.12
-4,8,12:18.12
-2,8,12:18.12
-5,9,12:18.12
5,-11,13:18.12
-5,-10,13:18.12
-4,-10,13:18.12
1,-10,13:18.12
5,-10,13:18.12
-4,-9,13:18.12
-3,-9,13:18.12
0,-9,13:18.12
5,-9,13:18.12
6,-9,13:18.12
-7,-8,13:18.12
-4,-8,13:18.12
-3,-8,13:18.12
1,-8,13:18.12
6,-8,13:18.12
5,-7,13:18.12
-6,-6,13:18.12
-3,-6,13:18.12
6,-6,13:18.12
7,-6,13:18.12
-6,-5,13:18.12
3,-5,13:18.12
4,-5,13:18.12
-6,-4,13:18.12
-3,-4,13:18.12
2,-4,13:18.12
4,-4,13:18.12
5,-4,13:17.13
6,-4,13:18.12
-1,-3,13:17.13
0,-3,13:18.12
4,-3,13:17.13
5,-3,13:18.12
-7,-2,13:18.12
-1,-2,13:18.12
0,-2,13:18.12
4,-2,13:18.12
5,-2,13:18.12
6,-2,13:18.12
-5,-1,13:18.12
4,-1,13:18.12
-10,0,13:18.12
-5,0,13:18.12
-3,0,13:18.12
0,0,13:17.13
2,0,13:18.12
-10,1,13:18.12
-6,1,13:17.13
-3,1,13:18.12
2,1,13:18.12
4,1,13:17.13
-5,2,13:18.12
-1,2,13:18.12
-7,3,13:18.12
-1,3,13:18.12
1,3,13:18.12
2,3,13:18.12
4,3,13:18.12
6,3,13:18.12
-5,4,13:18.12
-1,4,13:18.12
1,4,13:18.12
1,5,13:17.13
-4,6,13:18.12
-3,6,13:18.12
-1,6,13:18.12
0,6,13:18.12
-1,8,13:18.12
1,8,13:18.12
2,8,13:18.12
3,8,13:18.4
-4,9,13:18.12
-4,-11,14:18.12
1,-11,14:18.12
2,-11,14:18.12
3,-11,14:18.12
4,-11,14:18.12
-6,-10,14:18.12
-6,-9,14:18.12
0,-9,14:18.12
1,-9,14:18.12
2,-9,14:18.12
-6,-8,14:18.12
-3,-8,14:18.12
2,-7,14:18.12
3,-7,14:18.12
4,-7,14:18.12
5,-7,14:18.12
7,-7,14:18.12
8,-6,14:18.12
-3,-5,14:18.12
2,-5,14:18.12
6,-5,14:17.13
7,-5,14:18.12
7,-4,14:18.12
-7,-3,14:18.12
-3,-3,14:18.12
-1,-3,14:17.13
4,-3,14:17.13
8,-3,14:18.4
-8,-2,14:18.12
-7,-2,14:18.12
3,-2,14:18.12
7,-2,14:18.12
-10,-1,14:18.12
-8,-1,14:18.12
-6,-1,14:18.12
-5,-1,14:18.12
-4,-1,14:18.12
-1,-1,14:18.12
4,-1,14:18.12
6,-1,14:18.12
-8,0,14:18.12
-7,0,14:17.13
0,0,14:17.13
3,0,14:18.12
6,0,14:18.12
-7,1,14:18.12
-6,1,14:17.13
0,1,14:17.13
4,1,14:17.13
0,2,14:17.13
4,2,14:18.12
-8,3,14:18.12
-5,3,14:18.12
-2,3,14:18.12
1,3,14:18.12
2,3,14:18.12
5,3,14:18.12
-8,4,14:18.12
1,4,14:18.12
-8,5,14:18.12
-7,5,14:18.12
-5,5,14:18.12
2,5,14:18.12
-4,6,14:18.12
-3,6,14:18.12
-2,6,14:18.12
1,6,14:17.13
4,6,14:18.12
-6,8,14:18.12
-4,8,14:18.12
-3,9,14:18.12
-4,-11,15:18.12
1,-11,15:18.12
-4,-10,15:18.12
-2,-10,15:18.12
6,-10,15:18.12
-7,-9,15:18.12
-6,-9,15:18.12
-4,-9,15:18.12
-3,-9,15:18.12
2,-9,15:18.12
4,-9,15:18.12
-5,-8,15:18.12
-3,-8,15:18.12
3,-8,15:18.12
5,-8,15:18.12
6,-8,15:18.12
-5,-6,15:18.12
-4,-6,15:18.12
0,-6,15:18.12
5,-6,15:17.13
7,-6,15:18.12
9,-6,15:18.12
-5,-5,15:18.12
-1,-5,15:18.12
0,-5,15:18.12
1,-5,15:18.12
4,-5,15:18.12
6,-5,15:17.13
-2,-4,15:18.12
-1,-4,15:17.13
1,-4,15:18.12
2,-4,15:18.12
6,-4,15:18.12
-8,-3,15:18.12
0,-3,15:18.12
1,-3,15:18.12
2,-3,15:18.12
5,-3,15:17.13
-8,-2,15:18.12
-6,-2,15:18.12
-10,-1,15:18.12
-8,-1,15:17.13
-1,-1,15:18.12
-7,0,15:18.12
-4,0,15:18.4
0,0,15:17.13
4,0,15:18.12
5,0,15:18.12
6,0,15:18.12
8,0,15:18.12
5,1,15:17.13
6,1,15:18.12
8,1,15:18.12
-7,2,15:17.13
-6,2,15:18.12
3,2,15:17.13
8,2,15:18.12
-1,3,15:17.13
1,3,15:18.12
2,3,15:18.12
3,3,15:18.12
4,3,15:18.12
6,3,15:18.12
8,3,15:18.12
-8,4,15:18.12
-7,4,15:18.12
1,4,15:18.12
2,4,15:18.12
7,4,15:18.12
-9,5,15:18.12
-8,5,15:18.12
-7,5,15:18.12
-5,5,15:18.12
-1,5,15:18.12
0,5,15:18.12
1,5,15:18.12
2,5,15:18.12
8,5,15:18.12
-4,6,15:18.12
1,6,15:17.13
3,6,15:18.12
4,6,15:18.12
-7,7,15:18.12
-6,7,15:18.12
-4,7,15:18.12
4,7,15:18.12
6,7,15:18.12
-6,8,15:18.12
0,8,15:18.12
-6,9,15:18.12
-5,9,15:18.12
-2,9,15:18.12
1,9,15:18.12
-4,-10,16:18.12
-4,-9,16:18.12
6,-9,16:18.12
-7,-8,16:18.12
-4,-8,16:18.12
7,-8,16:18.12
-6,-7,16:18.12
-4,-7,16:18.12
4,-7,16:17.13
-2,-6,16:18.12
-1,-6,16:18.12
5,-6,16:18.12
7,-6,16:17.13
-2,-5,16:18.12
4,-5,16:18.12
8,-5,16:18.12
9,-5,16:18.12
-1,-4,16:17.13
2,-4,16:18.12
5,-4,16:18.12
-10,-3,16:18.12
-3,-3,16:18.12
5,-3,16:17.13
-8,-2,16:18.12
6,-2,16:18.12
8,-2,16:18.12
-8,-1,16:17.13
-5,-1,16:18.12
-10,0,16:18.12
6,0,16:17.13
8,0,16:18.12
0,1,16:17.13
6,1,16:18.12
-8,2,16:18.12
-7,2,16:17.13
3,2,16:17.13
5,2,16:18.12
9,2,16:18.12
-10,3,16:18.12
-7,3,16:18.12
-6,3,16:18.12
0,3,16:18.12
4,3,16:18.12
6,3,16:18.12
-9,4,16:18.12
-8,4,16:18.12
-1,4,16:17.13
9,4,16:18.12
-10,5,16:18.12
5,5,16:18.12
6,5,16:18.12
8,5,16:18.12
-4,6,16:18.12
-2,6,16:18.12
3,6,16:18.12
7,6,16:18.12
-9,7,16:18.12
-6,7,16:18.12
-3,7,16:18.12
2,7,16:18.12
6,7,16:18.12
7,7,16:18.12
-8,8,16:18.12
3,8,16:18.12
7,8,16:18.12
-1,9,16:18.12
0,9,16:18.12
-3,12,16:18.12
-4,-10,17:18.12
-3,-10,17:18.12
-2,-10,17:18.12
2,-10,17:18.12
4,-10,17:18.12
2,-9,17:18.12
7,-9,17:18.12
-6,-8,17:18.12
-4,-8,17:18.12
3,-8,17:17.13
6,-8,17:18.12
9,-8,17:18.12
-5,-7,17:18.12
-4,-7,17:18.12
-2,-7,17:18.12
3,-7,17:18.12
5,-7,17:18.12
7,-7,17:18.12
-6,-6,17:18.12
-5,-6,17:18.12
0,-6,17:18.12
6,-6,17:18.12
7,-6,17:17.13
10,-6,17:18.12
-8,-5,17:18.12
-7,-5,17:18.12
-1,-5,17:17.13
0,-5,17:18.12
3,-5,17:18.12
6,-5,17:18.12
8,-5,17:18.12
9,-5,17:18.12
-10,-4,17:18.12
-9,-4,17:18.12
-5,-4,17:18.12
-1,-4,17:17.13
5,-4,17:18.12
6,-4,17:17.13
8,-4,17:18.12
-9,-3,17:18.12
-5,-3,17:18.12
-3,-3,17:18.12
-1,-3,17:18.12
6,-3,17:18.12
7,-3,17:18.12
-8,-2,17:17.13
-7,-2,17:18.12
6,-1,17:18.12
-10,0,17:18.12
3,0,17:18.12
5,0,17:18.12
6,0,17:17.13
9,0,17:18.12
-9,1,17:18.12
0,1,17:17.13
8,1,17:18.12
3,2,17:17.13
6,2,17:18.12
7,2,17:18.12
8,2,17:18.12
9,2,17:18.12
-10,3,17:18.12
-8,3,17:17.13
-7,3,17:18.12
-6,3,17:18.12
5,3,17:18.12
6,3,17:18.12
-11,4,17:18.12
-5,4,17:18.12
-1,4,17:17.13
0,4,17:18.12
5,4,17:18.12
6,4,17:18.12
8,4,17:18.12
9,4,17:18.12
-9,5,17:18.12
-7,5,17:18.12
-5,5,17:18.12
-4,5,17:18.12
6,5,17:18.12
-8,6,17:18.12
-3,6,17:18.12
5,6,17:18.12
9,6,17:18.12
-6,7,17:18.12
-5,7,17:18.12
-3,7,17:18.12
-2,7,17:18.12
1,7,17:18.12
-9,8,17:18.12
3,8,17:18.12
4,8,17:18.12
7,8,17:18.12
-6,9,17:18.12
-3,9,17:18.12
-1,9,17:18.12
7,9,17:18.12
-3,12,17:18.12
3,-11,18:18.12
1,-10,18:18.12
3,-10,18:18.12
-4,-9,18:18.12
3,-9,18:18.12
5,-9,18:18.12
6,-9,18:18.12
-5,-8,18:18.12
-2,-8,18:18.12
1,-8,18:18.12
2,-8,18:18.12
3,-8,18:17.13
8,-8,18:18.12
-5,-7,18:18.12
-3,-7,18:18.12
-5,-6,18:18.12
-3,-6,18:18.12
-1,-6,18:17.13
-3,-5,18:18.12
-10,-4,18:18.12
-9,-4,18:18.12
-7,-4,18:18.12
-4,-4,18:18.12
-2,-4,18:17.13
-1,-4,18:18.12
4,-4,18:18.12
6,-4,18:17.13
9,-4,18:18.12
-2,-3,18:18.12
-1,-3,18:18.12
5,-3,18:18.12
-11,-2,18:18.12
-8,-2,18:17.13
-7,-2,18:18.12
-5,-2,18:18.12
8,-2,18:18.4
-9,-1,18:18.12
-7,-1,18:18.12
5,-1,18:18.12
-9,0,18:18.12
-7,0,18:18.12
1,0,18:17.13
7,0,18:18.12
-7,1,18:18.12
3,1,18:18.12
9,1,18:18.12
-1,2,18:17.13
-9,3,18:18.12
-8,3,18:17.13
3,3,18:17.13
6,3,18:18.12
7,3,18:18.12
8,3,18:18.12
9,3,18:18.4
-8,4,18:18.12
-10,5,18:18.12
-6,5,18:18.12
-4,5,18:18.12
-2,5,18:17.13
3,5,18:18.12
6,5,18:18.12
-9,6,18:18.12
-8,6,18:18.12
-5,6,18:18.12
2,6,18:18.12
4,6,18:18.12
7,6,18:18.12
9,6,18:18.12
3,7,18:18.12
7,7,18:18.12
9,7,18:18.4
-8,8,18:18.12
6,8,18:18.12
8,8,18:18.12
-3,9,18:18.12
-3,11,18:18.12
-2,11,18:18.12
2,-11,19:18.12
3,-11,19:18.12
-1,-9,19:18.12
0,-9,19:18.12
2,-9,19:18.12
-2,-8,19:18.12
2,-8,19:18.12
5,-8,19:18.12
6,-8,19:18.12
-6,-7,19:18.12
-5,-7,19:18.12
-1,-7,19:17.13
0,-7,19:18.12
-6,-6,19:18.12
-4,-6,19:18.12
-2,-6,19:18.12
-1,-6,19:18.12
4,-6,19:18.12
-3,-5,19:18.12
9,-5,19:18.12
-6,-4,19:18.12
-2,-4,19:17.13
-1,-4,19:18.12
4,-4,19:18.12
6,-4,19:17.13
7,-4,19:18.12
-12,-3,19:18.12
-11,-3,19:18.12
-9,-3,19:17.13
-3,-3,19:18.12
3,-3,19:18.12
6,-3,19:18.12
-10,-2,19:18.12
-9,-2,19:18.12
-8,-2,19:18.12
-6,-2,19:18.12
-5,-2,19:18.12
6,-2,19:18.12
-6,-1,19:18.12
-5,-1,19:18.12
6,-1,19:18.12
-8,0,19:18.12
1,0,19:17.13
4,0,19:18.12
-8,1,19:18.12
5,1,19:18.12
8,1,19:18.12
-1,2,19:17.13
4,2,19:18.12
5,2,19:18.12
6,2,19:18.12
7,2,19:18.12
-11,3,19:18.12
-8,3,19:17.13
-7,3,19:18.12
3,3,19:17.13
6,3,19:18.12
-11,4,19:18.12
-7,4,19:18.12
-6,4,19:18.12
-5,4,19:18.12
-4,4,19:18.12
3,4,19:18.12
-6,5,19:18.12
-2,5,19:17.13
7,5,19:18.12
8,5,19:18.12
-9,6,19:18.12
-6,6,19:18.12
-1,6,19:18.12
0,6,19:18.12
2,6,19:18.12
3,6,19:18.12
4,6,19:18.12
6,6,19:18.12
-7,7,19:18.12
-4,7,19:18.12
-3,7,19:18.12
1,7,19:18.12
4,7,19:18.12
0,8,19:18.12
-7,9,19:18.12
-6,9,19:18.12
1,9,19:18.12
3,9,19:18.12
6,9,19:18.12
-1,10,19:18.12
0,-10,20:18.12
-2,-9,20:18.12
1,-9,20:18.12
4,-9,20:18.12
-4,-8,20:18.12
-5,-7,20:18.12
-3,-7,20:18.12
-2,-7,20:18.12
-1,-7,20:17.13
2,-7,20:18.12
3,-7,20:18.12
4,-7,20:18.12
5,-7,20:18.12
7,-7,20:18.12
8,-7,20:18.12
-9,-6,20:18.12
-3,-6,20:18.12
-2,-6,20:18.12
7,-6,20:18.12
8,-6,20:18.12
-9,-5,20:18.12
-3,-5,20:18.12
-1,-5,20:18.12
6,-5,20:18.12
-9,-4,20:18.12
-8,-4,20:18.12
-5,-4,20:18.12
-4,-4,20:18.12
-3,-4,20:18.12
-2,-4,20:17.13
-1,-4,20:18.12
0,-4,20:18.12
3,-4,20:18.12
6,-4,20:18.12
-11,-3,20:18.12
-10,-3,20:18.12
-9,-3,20:17.13
-8,-3,20:18.12
-6,-3,20:18.12
6,-3,20:18.12
8,-3,20:18.12
-7,-2,20:18.12
-6,-2,20:18.12
-4,-2,20:18.12
5,-2,20:18.12
7,-2,20:18.12
-11,-1,20:18.12
-6,-1,20:18.12
1,-1,20:17.13
5,-1,20:18.12
6,-1,20:18.12
-10,0,20:18.12
3,0,20:18.12
4,0,20:18.12
5,0,20:18.12
7,0,20:18.12
9,0,20:18.12
3,1,20:18.12
6,1,20:18.12
-10,2,20:18.12
-8,2,20:18.12
-6,2,20:18.12
-1,2,20:17.13
4,2,20:18.12
6,2,20:18.12
-10,3,20:18.12
-7,3,20:18.12
-5,3,20:18.12
3,3,20:17.13
5,3,20:18.12
6,3,20:18.12
-9,4,20:18.12
-8,4,20:18.12
-7,4,20:18.12
1,4,20:18.12
3,4,20:18.12
4,4,20:18.12
-9,5,20:18.12
-6,5,20:18.12
-3,5,20:18.12
1,5,20:18.12
3,5,20:18.12
-5,6,20:18.12
-2,6,20:18.12
-1,6,20:17.13
0,6,20:18.12
6,6,20:18.12
0,7,20:18.12
-6,8,20:18.12
-4,8,20:18.12
-2,8,20:18.12
1,8,20:18.12
3,8,20:18.12
-3,10,20:18.12
2,10,20:18.12
1,11,20:18.12
-2,-8,21:18.12
3,-8,21:18.12
1,-7,21:18.12
-3,-6,21:18.12
-2,-6,21:18.12
-1,-6,21:18.12
7,-6,21:18.12
-9,-5,21:18.12
-2,-5,21:17.13
1,-5,21:18.4
4,-5,21:18.12
8,-5,21:18.4
-10,-4,21:18.12
-7,-4,21:18.12
-6,-4,21:18.12
-5,-4,21:18.12
4,-4,21:18.4
6,-4,21:18.12
-11,-3,21:18.12
-9,-3,21:18.12
-8,-3,21:18.12
-7,-3,21:18.12
1,-3,21:18.12
6,-3,21:18.12
-8,-2,21:18.12
-5,-2,21:18.12
6,-2,21:18.12
1,-1,21:17.13
6,-1,21:18.12
6,0,21:18.12
-7,1,21:18.12
3,1,21:18.12
4,1,21:18.12
-8,2,21:18.12
-5,2,21:18.12
3,2,21:18.12
6,2,21:18.12
7,2,21:18.12
8,2,21:18.12
-8,3,21:18.12
-7,3,21:18.12
-2,3,21:17.13
4,3,21:17.13
6,3,21:18.12
-9,4,21:18.12
-8,4,21:18.12
-4,4,21:18.12
1,4,21:18.12
2,4,21:18.12
3,4,21:18.12
6,4,21:18.12
7,4,21:18.12
-6,5,21:18.12
0,5,21:18.12
5,5,21:18.12
6,5,21:18.12
-7,6,21:18.12
-4,6,21:18.12
-2,6,21:18.12
-1,6,21:17.13
0,6,21:18.12
5,6,21:18.12
-8,7,21:18.12
1,7,21:18.12
2,7,21:18.12
3,7,21:18.12
6,7,21:18.4
-1,8,21:18.12
1,8,21:18.12
2,8,21:18.12
3,10,21:18.4
0,-8,22:18.12
-1,-7,22:18.12
1,-7,22:18.4
-7,-6,22:18.12
-2,-5,22:17.13
-7,-4,22:18.12
-6,-4,22:18.12
-1,-4,22:18.12
6,-4,22:18.12
-10,-3,22:18.12
-9,-3,22:18.12
-8,-3,22:18.12
-7,-3,22:18.12
-6,-3,22:18.12
-1,-3,22:18.12
-7,-2,22:18.12
-6,-2,22:18.12
1,-2,22:17.13
5,-2,22:18.12
6,-2,22:18.12
-6,-1,22:18.12
3,-1,22:18.12
4,-1,22:18.12
5,0,22:18.12
-5,2,22:18.12
3,2,22:18.12
5,2,22:18.12
6,2,22:18.12
-8,3,22:18.12
-4,3,22:18.12
-2,3,22:17.13
4,3,22:17.13
-8,4,22:18.12
-4,4,22:18.12
-3,4,22:18.12
0,4,22:18.12
3,4,22:18.12
6,4,22:18.12
-5,5,22:18.12
-4,5,22:18.12
-3,5,22:18.12
0,5,22:18.12
3,5,22:18.12
5,5,22:18.12
-5,6,22:18.12
-1,6,22:17.13
0,6,22:18.12
2,6,22:18.12
-8,7,22:18.12
-3,7,22:18.12
0,7,22:18.12
1,7,22:18.12
4,7,22:18.12
-3,8,22:18.12
-1,8,22:18.12
1,8,22:18.12
4,8,22:18.12
-1,9,22:18.12
-6,-7,23:18.12
-8,-6,23:18.12
-6,-6,23:18.12
-3,-6,23:18.12
-2,-6,23:18.12
-4,-5,23:18.12
-2,-5,23:17.13
-9,-4,23:18.12
-6,-4,23:18.12
-3,-4,23:18.12
-9,-3,23:18.12
-7,-3,23:18.12
-5,-3,23:18.12
2,-3,23:18.12
-7,-2,23:18.12
-2,-2,23:18.12
1,-2,23:17.13
2,-2,23:18.12
6,-2,23:18.12
4,-1,23:18.12
-8,0,23:18.12
1,0,23:18.12
4,0,23:18.12
5,0,23:18.12
6,0,23:18.12
7,0,23:18.12
7,2,23:18.12
-2,3,23:17.13
1,3,23:18.12
2,3,23:18.12
6,3,23:18.12
-4,4,23:18.12
-1,4,23:18.12
1,4,23:18.12
5,4,23:17.13
7,4,23:18.12
8,4,23:18.12
-4,5,23:18.12
-1,5,23:18.12
0,5,23:18.12
1,5,23:18.12
2,5,23:18.12
4,5,23:18.12
7,5,23:18.12
-8,6,23:18.12
-7,6,23:18.12
-4,6,23:18.12
4,6,23:18.12
-3,7,23:18.12
5,7,23:18.12
3,8,23:18.12
-3,-7,24:18.12
-1,-7,24:18.12
-6,-6,24:18.12
-7,-5,24:18.12
-3,-5,24:17.13
1,-5,24:18.12
-6,-4,24:18.12
-3,-4,24:18.12
1,-4,24:18.12
3,-4,24:18.12
-8,-3,24:18.12
-5,-3,24:18.12
-1,-3,24:18.12
0,-3,24:18.12
1,-3,24:18.12
2,-3,24:18.12
-8,-2,24:18.12
-6,-2,24:18.12
-4,-2,24:18.12
-1,-2,24:18.12
0,-2,24:18.12
1,-2,24:17.13
2,-2,24:18.12
-7,-1,24:18.12
-4,-1,24:18.12
1,-1,24:18.12
7,-1,24:18.4
-6,1,24:18.12
-5,1,24:18.12
1,1,24:18.12
0,2,24:18.12
3,2,24:18.12
-3,3,24:17.13
3,3,24:18.12
5,3,24:18.12
8,3,24:18.12
-1,4,24:17.13
1,4,24:18.12
3,4,24:18.12
4,4,24:18.12
1,5,24:18.12
3,5,24:18.12
4,6,24:18.12
-3,7,24:18.12
-1,7,24:18.12
2,7,24:18.12
5,7,24:18.12
6,7,24:18.4
-6,-8,25:18.12
-5,-8,25:18.12
-1,-7,25:18.12
-9,-6,25:18.12
-8,-6,25:18.12
-7,-6,25:18.12
-9,-5,25:18.12
-3,-5,25:17.13
-8,-4,25:18.12
-6,-3,25:18.12
-5,-3,25:18.12
-4,-3,25:18.12
2,-3,25:17.13
6,-3,25:18.12
-8,-2,25:18.12
-5,-2,25:18.12
0,-2,25:18.12
-7,-1,25:18.12
-2,-1,25:18.12
-1,-1,25:18.12
3,-1,25:18.12
-9,0,25:18.12
-7,0,25:18.12
3,0,25:18.12
4,0,25:18.12
5,0,25:18.12
6,0,25:18.12
-5,1,25:18.12
1,1,25:18.12
3,1,25:18.12
-8,3,25:18.12
-3,3,25:17.13
0,3,25:18.12
5,3,25:18.12
-7,4,25:18.12
-2,4,25:18.12
-1,4,25:17.13
0,4,25:18.12
3,4,25:18.12
-7,5,25:18.12
1,5,25:18.12
5,5,25:18.12
4,6,25:18.12
-1,7,25:18.12
-4,-8,26:18.12
-6,-6,26:18.12
-9,-5,26:18.12
-3,-5,26:17.13
3,-5,26:18.12
4,-5,26:18.12
5,-5,26:18.12
-8,-4,26:18.12
-5,-4,26:18.12
-3,-4,26:18.12
-2,-4,26:18.12
-1,-4,26:18.12
4,-4,26:18.12
5,-4,26:18.12
6,-4,26:18.12
-4,-3,26:18.12
-2,-3,26:18.12
1,-3,26:18.12
2,-3,26:17.13
7,-3,26:18.12
-9,-2,26:18.12
4,-2,26:18.12
7,-2,26:18.4
2,-1,26:18.12
3,0,26:18.12
6,0,26:18.4
-3,1,26:18.12
2,1,26:18.12
4,1,26:18.12
5,1,26:18.12
-8,2,26:18.12
-6,2,26:18.12
-3,2,26:17.13
6,3,26:18.4
-6,4,26:18.12
-3,4,26:18.12
-1,4,26:18.12
0,4,26:17.13
2,4,26:18.12
5,4,26:18.12
2,5,26:18.12
-1,7,26:18.12
-1,-6,27:18.12
-3,-5,27:18.12
-2,-5,27:18.12
1,-5,27:18.12
4,-5,27:18.12
-4,-4,27:18.12
0,-4,27:18.12
0,-3,27:18.12
2,-3,27:17.13
3,-3,27:18.12
4,-3,27:18.12
-4,-2,27:18.12
-3,-2,27:18.12
2,-2,27:18.12
-5,-1,27:18.12
2,-1,27:18.12
3,-1,27:18.12
-8,0,27:18.12
-2,1,27:18.12
-7,2,27:18.12
-6,2,27:18.12
-3,2,27:17.13
5,2,27:18.12
-4,3,27:18.12
-3,3,27:18.12
-2,3,27:18.12
-1,3,27:18.12
1,3,27:18.12
0,4,27:18.12
2,4,27:18.12
0,5,27:18.12
-1,7,27:18.12
-3,-7,28:18.12
-5,-6,28:18.12
1,-6,28:18.12
3,-6,28:18.12
-6,-5,28:18.12
2,-5,28:18.12
4,-5,28:18.12
-6,-4,28:18.12
-2,-4,28:18.12
0,-4,28:18.12
1,-4,28:18.12
-1,-3,28:18.12
2,-3,28:17.13
-8,-1,28:18.12
4,-1,28:18.12
0,0,28:18.12
4,0,28:18.12
-1,1,28:18.12
1,1,28:18.12
2,1,28:18.12
4,1,28:18.12
6,1,28:18.12
-4,2,28:17.13
1,2,28:18.12
-5,3,28:18.12
3,3,28:18.12
-4,4,28:18.12
-2,4,28:18.12
0,4,28:18.12
-3,5,28:18.12
0,5,28:18.12
-1,6,28:18.12
0,6,28:18.12
-4,-5,29:18.12
0,-4,29:18.12
2,-4,29:18.12
3,-4,29:18.12
4,-4,29:18.12
1,-3,29:18.12
2,-3,29:17.13
-1,-2,29:18.12
2,0,29:18.12
3,0,29:18.12
-6,1,29:18.12
1,1,29:18.12
-6,2,29:18.12
-4,2,29:18.12
-3,3,29:18.12
-1,4,29:18.12
0,4,29:18.12
-1,5,29:18.12
0,-5,30:18.12
1,-3,30:18.12
3,-2,30:18.12
5,-2,30:18.4
1,-1,30:18.12
-6,0,30:18.12
-4,0,30:18.12
2,0,30:18.12
3,0,30:18.12
-6,1,30:18.12
4,1,30:18.12
-6,2,30:18.12
-5,2,30:18.12
1,2,30:18.12
4,2,30:18.12
-4,4,30:18.12
2,-3,31:18.12
3,-3,31:18.12
0,-2,31:18.12
1,-1,31:18.12
3,-1,31:18.12
-4,1,31:18.12
2,1,31:18.12
4,1,31:18.4
-4,2,31:18.12
-5,3,31:18.12
-3,3,31:18.4
1,-2,32:18.12
