[META]
version=2.0
spawnOnBlockType=2
spawnSunlight=True
spawnDarkness=True
spawnWater=False
spawnLava=False
underFill=False
randomRotation=True
dig=True
tree=False
branch=False
needsFoundation=True
rarity=100
collisionPercentage=20
spawnElevationMin=0
spawnElevationMax=200
spawnInBiome=Custom
[DATA]
0,0,0:17.13
0,0,1:17.13
0,0,2:17.13
1,-2,3:18.4
2,-2,3:18.4
-1,-1,3:17.13
2,-1,3:18.4
1,0,3:17.13
0,1,3:17.13
0,-3,4:18.4
1,-3,4:18.4
4,-3,4:18.4
2,-2,4:18.4
3,-2,4:18.4
-1,-1,4:17.13
0,-1,4:18.4
2,-1,4:17.13
3,-1,4:18.4
0,0,4:18.4
1,0,4:18.4
2,0,4:18.4
3,0,4:18.4
1,1,4:18.4
2,1,4:18.4
-2,2,4:18.4
-1,2,4:18.4
0,2,4:17.13
-2,3,4:18.4
-1,3,4:18.4
1,-5,5:18.4
-3,-3,5:18.4
-1,-3,5:18.4
2,-3,5:18.4
-3,-2,5:18.4
-1,-2,5:18.4
0,-2,5:18.4
1,-2,5:18.4
2,-2,5:18.4
3,-2,5:18.4
-3,-1,5:18.4
-2,-1,5:17.13
-1,-1,5:18.4
0,-1,5:18.4
2,-1,5:17.13
4,-1,5:18.4
5,-1,5:18.4
-3,0,5:18.4
-2,0,5:18.4
1,0,5:18.4
2,0,5:18.4
3,0,5:18.4
-2,1,5:18.4
-1,1,5:18.4
0,1,5:18.4
4,1,5:18.4
-3,2,5:18.4
-1,2,5:18.4
0,2,5:17.13
1,2,5:18.4
2,2,5:18.4
-3,3,5:18.4
1,-5,6:18.4
1,-4,6:18.4
3,-4,6:18.4
4,-4,6:18.4
-1,-3,6:18.4
3,-3,6:18.4
-4,-2,6:18.4
-2,-2,6:18.4
-1,-2,6:18.4
0,-2,6:18.4
1,-2,6:18.4
2,-2,6:17.13
3,-2,6:18.4
4,-2,6:18.4
-2,-1,6:17.13
-1,-1,6:18.4
0,-1,6:18.4
1,-1,6:18.4
3,-1,6:18.4
-4,0,6:18.4
-3,0,6:18.4
-2,0,6:18.4
-1,0,6:18.4
0,0,6:18.4
1,0,6:18.4
2,0,6:17.13
3,0,6:18.4
5,0,6:18.4
-3,1,6:18.4
-1,1,6:18.4
0,1,6:18.4
1,1,6:18.4
2,1,6:18.4
3,1,6:18.4
-3,2,6:18.4
-2,2,6:18.4
-1,2,6:17.13
0,2,6:18.4
4,2,6:18.4
-2,3,6:18.4
2,3,6:18.4
-1,5,6:18.4
-2,-5,7:18.4
-1,-5,7:18.4
2,-5,7:18.4
3,-5,7:18.4
-4,-4,7:18.4
-3,-4,7:18.4
-1,-4,7:18.4
0,-4,7:18.4
-2,-3,7:18.4
1,-3,7:18.4
5,-3,7:18.4
-3,-2,7:18.4
-2,-2,7:17.13
-1,-2,7:18.4
0,-2,7:18.4
1,-2,7:18.4
2,-2,7:17.13
4,-2,7:18.4
-4,-1,7:18.4
-2,-1,7:18.4
-1,-1,7:18.4
0,-1,7:18.4
1,-1,7:18.4
2,-1,7:18.4
5,-1,7:18.4
-3,0,7:18.4
-1,0,7:18.4
0,0,7:18.4
1,0,7:18.4
2,0,7:17.13
3,0,7:18.4
4,0,7:18.4
5,0,7:18.4
-3,1,7:18.4
-2,1,7:18.4
-1,1,7:18.4
0,1,7:18.4
1,1,7:18.4
2,1,7:18.4
3,1,7:18.4
-4,2,7:18.4
-3,2,7:18.4
-2,2,7:18.4
-1,2,7:17.13
0,2,7:18.4
1,2,7:18.4
2,2,7:18.4
4,2,7:18.4
-3,3,7:18.4
-1,3,7:18.4
0,3,7:18.4
1,3,7:18.4
2,3,7:18.4
3,3,7:18.4
-2,4,7:18.4
0,5,7:18.4
-4,-4,8:18.4
-3,-4,8:18.4
-2,-4,8:18.4
2,-4,8:18.4
3,-4,8:18.4
-4,-3,8:18.4
-2,-3,8:18.4
-1,-3,8:18.4
0,-3,8:18.4
1,-3,8:18.4
2,-3,8:17.13
3,-3,8:18.4
4,-3,8:18.4
-5,-2,8:18.4
-4,-2,8:18.4
-3,-2,8:18.4
-2,-2,8:17.13
-1,-2,8:18.4
1,-2,8:18.4
3,-2,8:18.4
-5,-1,8:18.4
-3,-1,8:18.4
-2,-1,8:18.4
-1,-1,8:18.4
0,-1,8:18.4
1,-1,8:18.4
2,-1,8:18.4
-4,0,8:18.4
-3,0,8:18.4
-2,0,8:18.4
-1,0,8:18.4
0,0,8:18.4
2,0,8:18.4
3,0,8:18.4
4,0,8:18.4
5,0,8:18.4
-3,1,8:18.4
-2,1,8:18.4
-1,1,8:18.4
0,1,8:18.4
2,1,8:18.4
3,1,8:17.13
5,1,8:18.4
-3,2,8:18.4
-2,2,8:17.13
-1,2,8:18.4
1,2,8:18.4
2,2,8:18.4
3,2,8:18.4
-1,3,8:18.4
0,3,8:17.13
2,3,8:18.4
-3,-5,9:18.4
-2,-4,9:18.4
-1,-4,9:18.4
-3,-3,9:18.4
-1,-3,9:17.13
0,-3,9:18.4
1,-3,9:18.4
2,-3,9:18.4
-4,-2,9:18.4
-3,-2,9:18.4
-2,-2,9:18.4
-1,-2,9:18.4
0,-2,9:18.4
1,-2,9:18.4
2,-2,9:18.4
3,-2,9:18.4
4,-2,9:18.4
-4,-1,9:18.4
-2,-1,9:18.4
0,-1,9:18.4
1,-1,9:18.4
3,-1,9:18.4
-4,0,9:18.4
-3,0,9:18.4
-2,0,9:18.4
-1,0,9:18.4
0,0,9:18.4
1,0,9:18.4
2,0,9:18.4
4,0,9:18.4
-3,1,9:18.4
-2,1,9:18.4
-1,1,9:18.4
0,1,9:18.4
1,1,9:18.4
3,1,9:17.13
4,1,9:18.4
-3,2,9:18.4
-2,2,9:17.13
-1,2,9:18.4
2,2,9:18.4
3,2,9:18.4
4,2,9:18.4
-2,3,9:18.4
-1,3,9:18.4
0,3,9:18.4
1,3,9:18.4
1,4,9:18.4
-1,-4,10:18.4
0,-4,10:18.4
1,-3,10:18.4
2,-3,10:18.4
-3,-2,10:18.4
-2,-2,10:18.4
-1,-2,10:18.4
2,-2,10:18.4
3,-2,10:18.4
-3,-1,10:18.4
-2,-1,10:18.4
-1,-1,10:18.4
0,-1,10:18.4
1,-1,10:18.4
4,-1,10:18.4
-3,0,10:18.4
-2,0,10:18.4
0,0,10:18.4
1,0,10:18.4
2,0,10:18.4
3,0,10:18.4
-3,1,10:18.4
-2,1,10:18.4
0,1,10:18.4
1,1,10:18.4
2,1,10:18.4
-1,2,10:18.4
0,2,10:18.4
0,3,10:18.4
2,3,10:18.4
-2,-3,11:18.4
-3,-2,11:18.4
-2,-2,11:18.4
2,-2,11:18.4
3,-2,11:18.4
-3,-1,11:18.4
-2,-1,11:18.4
-1,-1,11:18.4
1,-1,11:18.4
3,-1,11:18.4
-2,0,11:18.4
-1,0,11:18.4
0,0,11:18.4
1,0,11:18.4
-2,1,11:18.4
-1,1,11:18.4
1,2,11:18.4
0,3,11:18.4
1,3,11:18.4
2,3,11:18.4
-1,-2,12:18.4
0,-2,12:18.4
1,-2,12:18.4
-1,-1,12:18.4
1,0,12:18.4
2,0,12:18.4
3,0,12:18.4
-1,1,12:18.4
1,2,12:18.4
2,2,12:18.4
0,0,13:18.4
1,0,13:18.4
0,1,13:18.4
1,1,13:18.4
2,1,13:18.4
