[META]
version=2.0
spawnOnBlockType=2
spawnSunlight=True
spawnDarkness=True
spawnWater=False
spawnLava=False
underFill=False
randomRotation=True
dig=True
tree=False
branch=False
needsFoundation=True
rarity=100
collisionPercentage=20
spawnElevationMin=0
spawnElevationMax=200
spawnInBiome=Custom
[DATA]
0,-1,0:17.0
0,-1,1:17.0
0,-1,2:17.0
0,-1,3:17.0
0,-1,4:17.0
0,-1,5:17.0
0,-1,6:17.0
0,-1,7:17.0
0,-1,8:17.0
0,-1,9:17.0
0,-1,10:17.0
0,-1,11:17.0
0,-1,12:17.12
0,-1,13:17.12
0,-1,14:17.12
0,-1,15:17.12
0,-2,16:18.4
0,-1,16:17.12
1,-3,17:18.4
1,-2,17:18.4
2,-2,17:18.4
0,-1,17:17.12
2,-1,17:18.4
0,0,17:18.4
1,0,17:18.4
-1,1,17:18.12
0,-4,18:18.4
2,-4,18:18.4
-3,-3,18:18.4
-1,-3,18:18.12
0,-3,18:18.4
1,-3,18:18.4
3,-3,18:18.4
-2,-2,18:18.12
0,-2,18:18.4
1,-2,18:18.4
-1,-1,18:18.4
0,-1,18:17.12
1,-1,18:18.4
2,-1,18:18.4
-2,0,18:18.4
-1,0,18:18.12
1,0,18:18.4
-3,1,18:18.4
-2,1,18:18.12
-1,1,18:18.12
1,1,18:18.12
2,1,18:18.12
-2,2,18:18.12
-1,2,18:18.12
1,2,18:18.12
2,2,18:18.12
0,-6,19:18.12
2,-6,19:18.12
-1,-5,19:18.12
0,-5,19:18.12
1,-5,19:18.12
2,-5,19:18.12
-3,-4,19:18.12
-2,-4,19:18.12
-1,-4,19:18.12
0,-4,19:18.12
1,-4,19:18.12
2,-4,19:18.12
3,-4,19:18.12
5,-4,19:18.12
-3,-3,19:18.12
-1,-3,19:18.12
1,-3,19:18.12
2,-3,19:18.12
3,-3,19:18.12
-2,-2,19:18.12
-1,-2,19:18.12
1,-2,19:18.12
2,-2,19:18.12
3,-2,19:18.12
-2,-1,19:18.12
0,-1,19:17.12
1,-1,19:18.12
2,-1,19:18.12
3,-1,19:18.12
-3,0,19:18.12
-1,0,19:18.12
0,0,19:18.12
1,0,19:18.4
3,0,19:18.12
-5,1,19:18.4
-2,1,19:18.12
-1,1,19:18.12
0,1,19:18.12
2,1,19:18.12
-3,2,19:18.12
-2,2,19:18.12
-1,2,19:18.12
0,2,19:18.12
2,2,19:18.12
-2,3,19:18.12
1,3,19:18.12
-1,4,19:18.12
0,4,19:18.12
1,-5,20:18.12
3,-5,20:18.12
-2,-4,20:18.12
-1,-4,20:18.12
0,-4,20:18.12
3,-4,20:18.12
-4,-3,20:18.12
-2,-3,20:18.12
-1,-3,20:18.12
3,-3,20:18.12
-4,-2,20:18.12
-3,-2,20:18.12
1,-2,20:18.12
3,-2,20:18.12
4,-2,20:18.12
5,-2,20:18.12
-5,-1,20:18.4
-4,-1,20:18.12
-3,-1,20:18.12
0,-1,20:17.12
1,-1,20:18.12
6,-1,20:18.4
-5,0,20:18.4
-2,0,20:18.12
-1,0,20:18.12
0,0,20:18.12
2,0,20:18.12
3,0,20:18.12
4,0,20:18.12
-4,1,20:18.12
-1,1,20:18.12
0,1,20:18.12
1,1,20:18.12
-3,2,20:18.12
0,2,20:18.12
-1,-5,21:18.12
0,-5,21:18.12
2,-5,21:18.12
0,-4,21:18.12
1,-4,21:18.12
2,-4,21:18.12
3,-4,21:18.12
-2,-3,21:18.12
-1,-3,21:18.12
0,-3,21:18.12
2,-3,21:18.12
-3,-2,21:18.12
-2,-2,21:18.12
0,-2,21:18.12
1,-2,21:18.12
2,-2,21:18.12
4,-2,21:18.12
-2,-1,21:18.12
-1,-1,21:18.12
0,-1,21:17.12
1,-1,21:18.12
2,-1,21:18.12
3,-1,21:18.12
4,-1,21:18.12
2,0,21:18.12
1,1,21:18.12
3,1,21:18.12
0,2,21:18.12
0,3,21:18.12
0,-4,22:18.12
2,-4,22:18.12
-2,-3,22:18.12
3,-3,22:18.12
-1,-2,22:18.12
0,-2,22:17.12
1,-2,22:18.12
2,-2,22:18.12
3,-2,22:18.12
-2,-1,22:18.12
0,-1,22:17.12
1,-1,22:17.12
2,-1,22:18.12
1,0,22:18.12
0,1,22:18.12
1,-4,23:18.12
-1,-3,23:18.12
1,-3,23:18.12
-1,-2,23:18.12
1,-2,23:18.12
0,-1,23:17.12
0,0,23:17.12
1,0,23:18.12
-2,-4,24:18.12
0,-4,24:18.12
-1,-3,24:18.12
1,-3,24:18.12
2,-3,24:18.12
-2,-2,24:18.12
-1,-2,24:18.12
0,-2,24:18.12
2,-2,24:18.12
0,-1,24:17.12
-3,0,24:18.12
-2,0,24:18.12
-1,0,24:18.12
0,0,24:18.12
-1,1,24:18.12
2,1,24:18.12
-1,2,24:18.12
0,2,24:18.12
-1,-5,25:18.12
-3,-4,25:18.12
0,-4,25:18.12
-2,-3,25:18.12
-1,-3,25:18.12
0,-3,25:18.12
1,-3,25:18.4
-3,-2,25:18.12
-1,-2,25:18.12
0,-2,25:18.12
1,-2,25:18.12
2,-2,25:18.12
3,-2,25:18.12
-1,-1,25:17.12
0,-1,25:17.12
1,-1,25:18.12
3,-1,25:18.12
-3,0,25:18.12
-1,0,25:18.12
0,0,25:17.12
1,0,25:18.12
3,0,25:18.12
-1,1,25:18.12
0,1,25:18.12
1,1,25:18.12
-2,-4,26:18.12
2,-4,26:18.12
-3,-3,26:18.12
3,-3,26:18.12
-3,-2,26:18.12
-2,-2,26:18.12
-1,-2,26:18.12
0,-2,26:17.12
0,-1,26:17.12
-2,0,26:18.12
1,0,26:18.12
-2,1,26:18.12
-1,1,26:18.12
0,1,26:18.12
2,1,26:18.12
-1,2,26:18.12
0,2,26:18.12
1,2,26:18.12
-2,-4,27:18.12
-1,-4,27:18.12
-1,-3,27:18.12
0,-3,27:18.12
2,-3,27:18.12
-1,-2,27:18.12
3,-2,27:18.12
0,-1,27:17.12
1,-1,27:17.12
-2,0,27:18.12
-1,0,27:18.12
0,0,27:18.12
1,0,27:18.12
-2,1,27:18.12
-1,1,27:18.12
0,1,27:18.4
2,1,27:18.12
0,2,27:18.12
-1,-3,28:18.12
0,-3,28:18.12
-2,-2,28:18.12
0,-2,28:18.4
1,-2,28:18.12
-1,-1,28:18.12
0,-1,28:17.12
1,-1,28:18.12
2,-1,28:18.12
-3,0,28:18.12
0,0,28:18.12
1,0,28:18.12
1,1,28:18.12
0,1,29:18.4
