[META]
version=2.0
spawnOnBlockType=2
spawnSunlight=True
spawnDarkness=True
spawnWater=False
spawnLava=False
underFill=False
randomRotation=True
dig=True
tree=False
branch=False
needsFoundation=True
rarity=100
collisionPercentage=20
spawnElevationMin=0
spawnElevationMax=200
spawnInBiome=Custom
[DATA]
0,0,0:17.0
0,0,1:17.0
0,0,2:17.0
0,0,3:17.0
0,-3,4:18.4
-2,-2,4:18.4
-1,-2,4:18.4
0,-2,4:18.4
0,-1,4:18.4
1,-1,4:18.4
-2,0,4:18.4
0,0,4:17.0
2,0,4:18.4
3,0,4:18.4
1,1,4:18.4
2,1,4:18.4
-1,-3,5:18.4
0,-3,5:18.4
-1,-2,5:18.4
1,-2,5:18.4
-3,-1,5:18.4
-1,-1,5:18.4
2,-1,5:18.4
3,-1,5:18.4
-3,0,5:18.4
0,0,5:17.0
3,0,5:18.4
0,1,5:18.4
1,1,5:18.4
0,3,5:18.4
-1,-4,6:18.4
0,-4,6:18.4
-3,-3,6:18.4
1,-2,6:18.4
3,-2,6:18.4
-3,-1,6:18.4
-2,-1,6:18.4
4,-1,6:18.4
-4,0,6:18.4
0,0,6:17.0
3,0,6:18.4
4,0,6:18.4
1,1,6:18.4
-2,2,6:18.4
-1,2,6:18.4
1,2,6:18.4
3,2,6:18.4
0,4,6:18.4
1,4,6:18.4
0,-3,7:18.4
-4,-2,7:18.4
-1,-2,7:18.4
0,-2,7:18.4
3,-2,7:18.4
4,-2,7:18.4
-2,-1,7:18.4
1,-1,7:18.4
-4,0,7:18.4
-3,0,7:18.4
0,0,7:17.0
2,0,7:18.4
-4,1,7:18.4
2,1,7:18.4
4,1,7:18.4
-4,2,7:18.4
2,2,7:18.4
-2,4,7:18.4
-1,-4,8:18.4
0,-4,8:18.4
-2,-3,8:18.4
0,-3,8:18.4
3,-3,8:18.4
-2,-2,8:18.4
3,-2,8:18.4
4,-2,8:18.4
5,-2,8:18.4
1,-1,8:18.4
-5,0,8:18.4
-2,0,8:18.4
0,0,8:17.0
2,0,8:18.4
4,0,8:18.4
5,0,8:18.4
-4,1,8:18.4
2,1,8:18.4
5,1,8:18.4
0,2,8:18.4
1,2,8:18.4
2,2,8:18.4
-2,3,8:18.4
2,3,8:18.4
3,3,8:18.4
-1,4,8:18.4
0,5,8:18.4
-2,-5,9:18.4
-1,-5,9:18.4
1,-5,9:18.4
2,-4,9:18.4
1,-3,9:18.4
3,-3,9:18.4
-4,-2,9:18.4
3,-2,9:18.4
0,-1,9:18.4
1,-1,9:18.4
-5,0,9:18.4
-4,0,9:18.4
0,0,9:17.0
2,0,9:18.4
4,0,9:18.4
0,1,9:18.4
4,1,9:18.4
2,2,9:18.4
5,2,9:18.4
-4,3,9:18.4
0,3,9:18.4
1,3,9:18.4
2,3,9:18.4
3,3,9:18.4
0,5,9:18.4
1,5,9:18.4
2,5,9:18.4
0,-5,10:18.4
2,-5,10:18.4
-3,-4,10:18.4
1,-4,10:18.4
2,-4,10:18.4
-2,-3,10:18.4
-1,-3,10:18.4
0,-2,10:18.4
1,-2,10:18.4
4,-2,10:18.4
5,-2,10:18.4
-5,-1,10:18.4
-4,-1,10:18.4
-5,0,10:18.4
-2,0,10:18.4
0,0,10:17.0
1,0,10:18.4
4,0,10:18.4
5,0,10:18.4
-5,1,10:18.4
2,1,10:18.4
-3,3,10:18.4
2,3,10:18.4
0,4,10:18.4
-2,5,10:18.4
0,5,10:18.4
-2,-5,11:18.4
-1,-5,11:18.4
2,-5,11:18.4
0,-4,11:18.4
2,-4,11:18.4
-3,-3,11:18.12
-2,-3,11:18.4
0,-3,11:18.12
3,-3,11:18.4
-5,-2,11:18.4
-3,-2,11:18.4
-2,-2,11:18.4
0,-2,11:18.12
2,-2,11:18.12
-5,-1,11:18.4
-3,-1,11:18.4
-1,-1,11:18.12
0,-1,11:18.4
1,-1,11:18.12
2,-1,11:18.4
4,-1,11:18.4
-5,0,11:18.4
-4,0,11:18.4
-3,0,11:18.12
-2,0,11:18.12
0,0,11:17.0
3,0,11:18.12
-1,1,11:18.12
0,1,11:18.12
4,1,11:18.12
-5,2,11:18.4
-4,2,11:18.4
-3,2,11:18.12
-2,2,11:18.12
1,2,11:18.12
3,2,11:18.4
-3,3,11:18.12
0,3,11:18.12
1,3,11:18.12
-2,4,11:18.4
0,4,11:18.12
1,4,11:18.4
2,4,11:18.4
-2,5,11:18.4
0,5,11:18.4
1,5,11:18.4
-3,-3,12:18.4
-2,-3,12:18.4
1,-3,12:18.4
2,-3,12:18.4
3,-3,12:18.4
1,-2,12:18.4
0,-1,12:18.4
1,-1,12:18.4
-3,0,12:18.4
-2,0,12:18.4
0,0,12:17.0
4,0,12:18.4
0,1,12:18.4
1,1,12:18.4
-2,3,12:18.4
0,3,12:18.4
3,3,12:18.4
-2,-4,13:18.4
-3,-3,13:18.4
-2,-3,13:18.4
-1,-3,13:18.4
0,-3,13:18.4
1,-3,13:18.4
3,-3,13:18.4
-4,-2,13:18.4
-3,-2,13:18.4
-1,-2,13:18.4
1,-2,13:18.4
-2,-1,13:18.4
-1,-1,13:18.4
4,-1,13:18.4
-3,0,13:18.4
-1,0,13:18.4
0,0,13:17.0
1,0,13:18.4
4,0,13:18.4
-4,2,13:18.4
0,3,13:18.4
1,3,13:18.4
-2,4,13:18.4
0,4,13:18.4
0,-4,14:18.4
2,-4,14:18.4
-1,-3,14:18.4
-4,-2,14:18.4
-1,-2,14:18.4
3,-2,14:18.4
4,-2,14:18.4
-3,-1,14:18.4
0,-1,14:18.4
2,-1,14:18.4
3,-1,14:18.4
-4,0,14:18.4
0,0,14:17.0
1,0,14:18.4
3,0,14:18.4
4,0,14:18.4
-3,1,14:18.4
2,1,14:18.4
3,1,14:18.4
-4,2,14:18.4
-2,2,14:18.4
2,2,14:18.4
4,2,14:18.4
-1,3,14:18.4
1,3,14:18.4
-1,4,14:18.4
0,4,14:18.4
0,-3,15:18.4
1,-2,15:18.4
2,-2,15:18.4
-3,-1,15:18.4
0,-1,15:18.4
3,-1,15:18.4
4,-1,15:18.4
-4,0,15:18.4
-3,0,15:18.4
0,0,15:17.0
-1,1,15:18.4
0,1,15:18.4
4,1,15:18.4
-3,2,15:18.4
-1,2,15:18.4
1,2,15:18.4
4,2,15:18.4
2,3,15:18.4
3,3,15:18.4
0,4,15:18.4
1,4,15:18.4
0,-3,16:18.4
1,-3,16:18.4
2,-2,16:18.4
-2,-1,16:18.4
-2,0,16:18.4
0,0,16:17.0
1,0,16:18.4
-3,1,16:18.4
2,1,16:18.4
0,-3,17:18.12
-1,-2,17:18.12
2,-1,17:18.12
3,-1,17:18.12
-2,0,17:18.12
-1,0,17:18.12
0,0,17:17.0
3,0,17:18.12
-3,1,17:18.12
0,1,17:18.12
1,1,17:18.12
3,1,17:18.12
0,2,17:18.12
0,3,17:18.12
1,3,17:18.12
-1,-3,18:18.12
0,-3,18:18.12
-2,-2,18:18.12
0,-2,18:18.12
-2,-1,18:18.12
1,-1,18:18.12
2,-1,18:18.12
-3,0,18:18.12
0,0,18:17.0
1,0,18:18.12
3,0,18:18.12
-1,1,18:18.12
0,1,18:18.12
3,1,18:18.12
0,2,18:18.12
0,3,18:18.12
-1,-3,19:18.12
-3,-1,19:18.12
2,-1,19:18.12
-3,0,19:18.12
-2,0,19:18.12
0,0,19:17.0
-3,1,19:18.12
-2,1,19:18.12
-1,1,19:18.12
0,1,19:18.12
-1,2,19:18.12
0,3,19:18.12
-2,-1,20:18.12
-1,-1,20:18.12
0,-1,20:18.12
0,0,20:17.0
1,0,20:18.12
2,0,20:18.12
-2,1,20:18.12
0,2,20:18.12
-1,-2,21:18.12
-2,0,21:18.12
0,0,21:17.12
2,0,21:18.12
1,2,21:18.12
1,-2,22:18.12
0,0,22:17.12
0,2,22:18.12
2,-1,23:18.12
-2,0,23:18.12
0,0,23:17.12
1,0,23:18.12
-2,1,23:18.12
0,1,23:18.12
2,1,23:18.12
-1,-1,24:18.12
1,0,24:18.12
-1,1,24:18.12
-1,0,25:18.12
0,1,25:18.12
