[META]
version=2.0
spawnOnBlockType=2
spawnSunlight=True
spawnDarkness=True
spawnWater=False
spawnLava=False
underFill=False
randomRotation=True
dig=True
tree=False
branch=False
needsFoundation=True
rarity=100
collisionPercentage=20
spawnElevationMin=0
spawnElevationMax=200
spawnInBiome=Custom
[DATA]
0,0,0:17.0
0,0,1:17.0
0,0,2:17.0
-1,-1,3:18.12
1,-1,3:18.12
-2,0,3:18.4
-1,0,3:18.12
0,0,3:17.0
1,0,3:18.12
1,1,3:18.12
-1,2,3:18.12
1,2,3:18.12
-1,-3,4:18.4
0,-3,4:18.4
0,-2,4:18.4
2,-2,4:18.4
-1,-1,4:18.4
0,-1,4:18.4
-3,0,4:18.4
-2,0,4:18.4
0,0,4:17.0
1,0,4:18.4
2,0,4:18.4
-1,1,4:18.4
2,1,4:18.4
3,1,4:18.4
0,2,4:18.4
-1,-3,5:18.12
0,-3,5:18.12
-2,-1,5:18.12
0,-1,5:18.12
2,-1,5:18.12
0,0,5:17.0
1,0,5:18.12
2,0,5:18.12
3,0,5:18.12
0,1,5:18.12
0,2,5:18.12
1,3,5:18.12
0,-3,6:18.4
0,-2,6:18.4
-3,-1,6:18.4
0,-1,6:18.4
-3,0,6:18.4
-2,0,6:18.4
0,0,6:17.0
1,1,6:18.4
2,1,6:18.4
-2,2,6:18.4
0,2,6:18.4
2,2,6:18.4
0,3,6:18.4
-2,-1,7:18.12
1,-1,7:18.12
0,0,7:17.0
2,0,7:18.12
0,-2,8:18.12
1,-2,8:18.12
-1,-1,8:18.12
-2,0,8:18.12
-1,0,8:18.12
0,0,8:17.0
1,1,8:18.12
1,-1,9:18.4
0,0,9:17.0
1,0,9:18.12
1,1,9:18.4
-1,-1,10:18.12
-1,0,10:18.12
0,0,10:17.0
1,0,10:18.12
0,1,10:18.12
1,1,10:18.12
0,-1,11:18.12
-1,0,11:18.12
1,1,11:18.12
0,-1,12:18.12
