[META]
version=2.0
spawnOnBlockType=2
spawnSunlight=True
spawnDarkness=True
spawnWater=False
spawnLava=False
underFill=False
randomRotation=True
dig=True
tree=False
branch=False
needsFoundation=True
rarity=100
collisionPercentage=20
spawnElevationMin=0
spawnElevationMax=200
spawnInBiome=Custom
[DATA]
-2,0,-3:17.13
-1,-1,-2:17.13
-2,0,-2:17.13
-3,1,-2:17.13
-1,1,-2:17.13
-1,-1,-1:17.13
-2,0,-1:17.13
-1,0,-1:17.13
-3,1,-1:17.13
-2,1,-1:17.13
-1,1,-1:17.13
0,1,-1:17.13
-1,-1,0:17.13
-2,0,0:17.13
-1,0,0:17.13
-3,1,0:17.13
-2,1,0:17.13
-1,1,0:17.13
0,1,0:17.13
-2,0,1:17.13
-1,0,1:17.13
-2,1,1:17.13
-1,1,1:17.13
-2,0,2:17.13
-1,0,2:17.13
-2,1,2:17.13
-1,1,2:17.13
-2,0,3:17.13
-2,1,3:17.13
-1,1,3:17.13
-2,0,4:17.13
-2,1,4:17.13
-1,1,4:17.13
-2,0,5:17.13
-2,1,5:17.13
-1,1,5:17.13
-2,0,6:17.13
-2,1,6:17.13
-1,1,6:17.13
-4,-5,7:18.4
-2,-5,7:18.4
-6,-4,7:18.12
-5,-3,7:18.12
-4,-3,7:18.12
-1,-3,7:18.12
-7,-2,7:18.4
-5,-2,7:18.12
-4,-2,7:17.13
-3,-2,7:18.12
-6,-1,7:18.12
-5,-1,7:18.12
-4,-1,7:18.12
-3,-1,7:17.13
0,-1,7:18.12
1,-1,7:18.12
-4,0,7:18.12
-3,0,7:18.12
-2,0,7:17.13
-5,1,7:18.12
-2,1,7:17.13
-1,1,7:17.13
-3,2,7:18.12
-2,2,7:18.12
0,2,7:18.12
-4,3,7:18.12
-3,3,7:18.12
-2,3,7:18.12
-1,3,7:18.12
-4,-4,8:18.12
-2,-4,8:18.12
-3,-3,8:18.12
-6,-2,8:18.12
-5,-2,8:18.12
-4,-2,8:18.12
-3,-2,8:18.12
-2,-2,8:18.12
-5,-1,8:18.12
-4,-1,8:18.12
-3,-1,8:18.12
-4,0,8:18.12
-3,0,8:18.12
-2,0,8:17.13
-1,0,8:18.12
0,0,8:18.12
-4,1,8:18.12
-2,1,8:17.13
-1,1,8:17.13
0,1,8:18.12
-3,2,8:18.12
-2,0,9:17.13
-2,1,9:17.13
-1,1,9:17.13
-5,-4,10:18.4
2,-4,10:18.4
3,-4,10:18.4
-3,-3,10:18.4
-1,-3,10:18.4
0,-3,10:18.4
1,-3,10:18.4
3,-3,10:18.4
4,-3,10:18.4
5,-3,10:18.4
-2,-2,10:18.4
-1,-2,10:18.4
1,-2,10:18.4
-4,-1,10:18.4
-3,-1,10:18.4
-2,-1,10:17.13
-1,-1,10:18.4
0,-1,10:18.4
1,-1,10:18.4
-7,0,10:18.4
-5,0,10:18.4
-4,0,10:17.13
-3,0,10:17.13
-2,0,10:17.13
-1,0,10:18.4
0,0,10:18.4
1,0,10:18.4
2,0,10:17.13
3,0,10:18.4
4,0,10:18.4
5,0,10:18.4
6,0,10:18.4
-7,1,10:18.4
-6,1,10:18.4
-4,1,10:18.4
-3,1,10:18.4
-2,1,10:17.13
-1,1,10:17.13
0,1,10:17.13
1,1,10:17.13
2,1,10:18.4
-6,2,10:18.4
-5,2,10:18.4
-2,2,10:17.13
-1,2,10:18.4
0,2,10:18.4
1,2,10:18.4
-6,3,10:18.4
-3,3,10:18.4
-2,3,10:17.13
-1,3,10:18.4
0,3,10:18.4
2,3,10:18.4
3,3,10:18.4
-3,4,10:18.4
-2,4,10:18.4
-1,4,10:17.13
0,4,10:18.4
1,4,10:18.4
2,4,10:18.4
-3,5,10:18.4
-2,5,10:18.4
-1,5,10:18.4
0,5,10:17.13
2,5,10:18.4
3,5,10:18.4
-4,6,10:18.4
0,6,10:18.4
3,6,10:18.4
-1,7,10:18.4
2,7,10:18.4
4,7,10:18.4
1,8,10:18.4
2,8,10:18.4
-1,9,10:18.4
0,9,10:18.4
2,9,10:18.4
-1,-2,11:18.4
-2,-1,11:18.4
-1,-1,11:18.4
0,-1,11:18.4
1,-1,11:18.4
2,-1,11:18.4
-3,0,11:18.4
-2,0,11:17.13
-1,0,11:18.4
0,0,11:18.4
1,0,11:18.4
2,0,11:18.4
3,0,11:18.4
-2,1,11:17.13
-1,1,11:18.4
0,1,11:18.4
1,1,11:18.4
2,1,11:18.4
-2,2,11:18.4
-1,2,11:18.4
0,2,11:18.4
-4,3,11:18.4
-3,3,11:18.4
-2,3,11:18.4
-1,3,11:18.4
0,3,11:18.4
-3,4,11:18.4
-2,4,11:18.4
0,4,11:18.4
-2,5,11:18.4
-1,5,11:18.4
0,5,11:18.4
1,5,11:18.4
-1,6,11:18.4
1,6,11:18.4
-2,7,11:18.4
-1,7,11:18.4
-2,0,12:17.13
-2,1,12:17.13
-5,-8,13:18.4
-7,-7,13:18.4
-6,-7,13:18.4
-3,-6,13:18.4
-7,-5,13:18.4
-6,-5,13:18.4
-7,-4,13:17.13
-6,-4,13:18.4
-4,-4,13:18.4
-3,-4,13:18.4
-6,-3,13:17.13
-4,-3,13:18.4
-7,-2,13:18.4
-6,-2,13:17.13
-3,-2,13:18.4
-9,-1,13:18.4
-7,-1,13:18.4
-5,-1,13:17.13
-8,0,13:18.4
-7,0,13:18.4
-5,0,13:18.4
-4,0,13:17.13
-3,0,13:17.13
-2,0,13:17.13
-2,1,13:17.13
-7,-5,14:18.4
-7,-3,14:18.4
-6,-3,14:18.4
-4,-3,14:18.4
-3,-3,14:18.4
-2,-3,14:18.4
-5,-2,14:18.4
-2,-2,14:18.4
-1,-2,14:18.4
-6,-1,14:18.4
-5,-1,14:18.4
-4,-1,14:18.4
-3,-1,14:18.4
-2,-1,14:18.4
-1,-1,14:18.4
-6,0,14:18.4
-5,0,14:18.4
-4,0,14:18.4
-3,0,14:18.4
-2,0,14:17.13
-1,0,14:18.4
-4,1,14:18.4
-3,1,14:18.4
-2,1,14:17.13
-2,2,14:18.4
-2,0,15:17.13
-2,1,15:17.13
-3,0,16:18.4
-2,0,16:17.13
-1,0,16:18.4
-2,1,16:17.13
-1,1,16:18.4
1,1,16:18.4
-3,2,16:18.4
-2,2,16:17.13
0,2,16:18.4
3,2,16:18.4
-4,3,16:18.4
-2,3,16:17.13
-1,3,16:18.4
3,3,16:18.4
-5,4,16:18.4
-3,4,16:18.4
-2,4,16:18.4
-1,4,16:17.13
1,4,16:18.4
-3,5,16:18.4
-1,5,16:18.4
3,5,16:18.4
-1,7,16:18.4
1,7,16:18.4
-3,8,16:18.4
-4,0,17:18.4
-3,0,17:18.4
-2,0,17:17.13
-1,0,17:18.4
-4,1,17:18.4
-2,1,17:17.13
-1,1,17:18.4
0,1,17:18.4
-2,2,17:18.4
-1,2,17:18.4
0,2,17:18.4
-3,3,17:18.4
-2,3,17:18.4
-1,3,17:18.4
0,3,17:18.4
1,3,17:18.4
0,4,17:18.4
0,5,17:18.4
-1,-5,18:18.12
0,-4,18:18.12
3,-4,18:18.4
-1,-3,18:18.12
4,-3,18:18.4
5,-3,18:18.4
-2,-2,18:18.12
-1,-2,18:18.12
1,-2,18:18.12
2,-2,18:18.12
4,-2,18:18.4
5,-2,18:18.4
0,-1,18:18.12
1,-1,18:17.13
2,-1,18:18.12
3,-1,18:18.4
-3,0,18:18.12
-2,0,18:17.13
-1,0,18:17.13
0,0,18:17.13
5,0,18:18.4
-2,1,18:17.13
0,1,18:18.12
2,1,18:18.12
3,1,18:18.4
-1,2,18:18.12
-1,3,18:18.12
2,3,18:18.12
0,-3,19:18.4
2,-3,19:18.4
-1,-2,19:18.4
1,-2,19:18.4
-3,-1,19:18.4
-2,-1,19:18.4
-1,-1,19:18.4
0,-1,19:18.4
1,-1,19:18.4
2,-1,19:18.4
-4,0,19:18.4
-2,0,19:17.13
0,0,19:18.4
1,0,19:18.4
3,0,19:18.4
-4,1,19:18.4
-2,1,19:17.13
-1,1,19:18.4
0,1,19:18.4
1,1,19:18.4
-3,-2,20:18.4
-2,-2,20:18.4
-1,-2,20:18.4
-4,-1,20:18.4
-2,-1,20:18.4
-1,-1,20:18.4
0,-1,20:18.4
-4,0,20:18.4
-3,0,20:18.4
-2,0,20:17.13
0,0,20:18.4
1,0,20:18.4
-4,1,20:18.4
-3,1,20:18.4
-2,1,20:18.4
-1,1,20:18.4
0,1,20:18.4
-3,2,20:18.4
0,2,20:18.4
2,3,20:18.4
0,4,20:18.4
-2,0,21:17.13
-6,-5,22:18.12
-4,-5,22:18.12
-2,-4,22:18.12
-7,-3,22:18.12
-6,-3,22:18.12
-5,-3,22:18.4
-4,-3,22:18.4
-3,-3,22:18.12
0,-3,22:18.12
-6,-2,22:18.12
-4,-2,22:17.13
-3,-2,22:18.12
-2,-2,22:18.12
-7,-1,22:18.12
-3,-1,22:17.13
0,-1,22:18.12
-3,0,22:18.12
-2,0,22:17.13
-5,1,22:18.12
-4,2,22:18.12
-4,0,23:18.4
-2,0,23:17.13
0,0,23:18.4
-4,1,23:18.4
-2,1,23:18.4
-3,2,23:18.4
-2,0,24:17.13
-3,-3,25:18.4
-2,-3,25:18.4
-5,-2,25:18.4
-3,-2,25:18.4
-1,-2,25:18.4
-3,-1,25:18.4
-1,-1,25:18.4
0,-1,25:18.4
-6,0,25:18.4
-4,0,25:18.4
-3,0,25:17.13
-2,0,25:17.13
-3,1,25:18.4
-2,1,25:18.4
-2,2,25:18.4
-1,-2,26:18.4
-2,0,26:17.13
-1,0,26:18.4
0,1,26:18.4
-2,0,27:17.13
-1,-2,28:18.12
0,-2,28:18.12
-4,0,28:18.12
-2,0,28:17.13
-1,0,28:18.12
1,0,28:18.12
-2,1,28:18.12
-1,1,28:17.13
1,2,28:18.12
2,2,28:18.12
-2,3,28:18.12
1,3,28:18.12
-2,0,29:17.13
-4,-1,30:18.12
-2,-1,30:18.12
-2,0,30:17.13
-3,1,30:18.4
-2,1,30:18.12
-2,0,31:17.13
-2,1,31:18.12
0,1,31:18.12
-1,2,31:18.12
-3,-1,32:18.12
-1,-1,32:18.4
-2,0,32:18.12
-1,0,32:18.4
-2,0,33:18.12
