[META]
version=2.0
spawnOnBlockType=2
spawnSunlight=True
spawnDarkness=True
spawnWater=False
spawnLava=False
underFill=False
randomRotation=True
dig=True
tree=False
branch=False
needsFoundation=True
rarity=100
collisionPercentage=20
spawnElevationMin=0
spawnElevationMax=200
spawnInBiome=Custom
[DATA]
-4,0,-3:17.13
-2,0,-3:17.13
-2,2,-3:17.13
-4,3,-3:17.13
-4,0,-2:17.13
-2,0,-2:17.13
-3,2,-2:17.13
-2,2,-2:17.13
-4,3,-2:17.13
-2,3,-2:17.13
-4,0,-1:17.13
-2,0,-1:17.13
-3,1,-1:17.13
-1,1,-1:17.13
-4,2,-1:17.13
-3,2,-1:17.13
-2,2,-1:17.13
-5,3,-1:17.13
-4,3,-1:17.13
-2,3,-1:17.13
-1,3,-1:17.13
-4,0,0:17.13
-2,0,0:17.13
-3,1,0:17.13
-2,1,0:17.13
-1,1,0:17.13
-4,2,0:17.13
-3,2,0:17.13
-2,2,0:17.13
-5,3,0:17.13
-4,3,0:17.13
-2,3,0:17.13
-1,3,0:17.13
-2,0,1:17.13
-3,1,1:17.13
-2,1,1:17.13
-3,2,1:17.13
-2,2,1:17.13
-3,1,2:17.13
-2,1,2:17.13
-3,2,2:17.13
-2,2,2:17.13
-3,1,3:17.13
-2,1,3:17.13
-3,2,3:17.13
-2,2,3:17.13
-3,1,4:17.13
-2,1,4:17.13
-3,2,4:17.13
-2,2,4:17.13
-3,1,5:17.13
-2,1,5:17.13
-3,2,5:17.13
-2,2,5:17.13
-3,1,6:17.13
-2,1,6:17.13
-3,2,6:17.13
-2,2,6:17.13
-3,1,7:17.13
-2,1,7:17.13
-3,2,7:17.13
-2,2,7:17.13
-3,1,8:17.13
-2,1,8:17.13
-3,2,8:17.13
-2,2,8:17.13
-3,1,9:17.13
-2,1,9:17.13
-3,2,9:17.13
-2,2,9:17.13
-3,1,10:17.13
-2,1,10:17.13
-3,2,10:17.13
-2,2,10:17.13
-7,-1,11:18.4
-4,-1,11:18.4
-9,0,11:18.4
-8,0,11:18.4
-7,0,11:18.4
-6,0,11:18.4
-10,1,11:18.4
-4,1,11:18.4
-3,1,11:17.13
-2,1,11:17.13
-9,2,11:18.4
-8,2,11:18.4
-7,2,11:18.4
-4,2,11:17.13
-3,2,11:17.13
-2,2,11:17.13
-8,3,11:18.4
-6,3,11:17.13
-5,3,11:17.13
-4,3,11:18.4
-3,3,11:18.4
-6,4,11:18.4
-3,5,11:18.4
-2,5,11:18.4
-6,6,11:18.4
-4,6,11:18.4
-4,7,11:18.4
-6,-9,12:18.4
-5,-9,12:18.4
-4,-9,12:18.4
-3,-9,12:18.4
-5,-8,12:18.4
-2,-8,12:18.4
-7,-7,12:18.4
-6,-7,12:18.4
-4,-7,12:18.4
-2,-7,12:18.4
0,-7,12:18.4
1,-7,12:18.4
-6,-6,12:18.4
-5,-6,12:18.4
-4,-6,12:18.4
-1,-6,12:18.4
-6,-5,12:18.4
-5,-5,12:17.13
-4,-5,12:18.4
-3,-5,12:18.4
-2,-5,12:18.4
1,-5,12:18.4
-8,-4,12:18.4
-7,-4,12:18.4
-5,-4,12:17.13
-3,-4,12:18.4
-1,-4,12:18.4
3,-4,12:18.4
-9,-3,12:18.4
-5,-3,12:18.4
-4,-3,12:17.13
-3,-3,12:18.4
-2,-3,12:18.4
-1,-3,12:17.13
0,-3,12:18.4
1,-3,12:18.4
3,-3,12:18.4
-6,-2,12:18.4
-5,-2,12:18.4
-4,-2,12:17.13
-2,-2,12:17.13
-1,-2,12:18.4
1,-2,12:18.4
3,-2,12:18.4
-7,-1,12:18.4
-6,-1,12:18.4
-5,-1,12:18.4
-4,-1,12:18.4
-3,-1,12:17.13
-2,-1,12:18.4
-1,-1,12:18.4
3,-1,12:18.4
-3,0,12:17.13
-1,0,12:18.4
-3,1,12:17.13
-2,1,12:17.13
-1,1,12:18.4
-3,2,12:17.13
-2,2,12:17.13
-1,-3,13:18.4
-2,-2,13:18.4
-1,-2,13:18.4
-5,-1,13:18.4
0,-1,13:18.4
1,-1,13:18.4
-5,0,13:18.4
-4,0,13:18.4
-3,0,13:18.4
-7,1,13:18.4
-5,1,13:18.4
-4,1,13:18.4
-3,1,13:17.13
-2,1,13:17.13
0,1,13:18.4
-5,2,13:18.4
-3,2,13:17.13
-2,2,13:17.13
-6,3,13:18.4
-3,3,13:18.4
-1,4,13:18.4
-3,1,14:17.13
-2,1,14:17.13
-3,2,14:17.13
-2,2,14:17.13
-7,-4,15:18.4
0,-4,15:18.4
1,-4,15:18.4
-7,-3,15:18.4
-6,-3,15:18.4
-5,-3,15:18.4
1,-3,15:18.4
2,-3,15:18.4
3,-3,15:18.4
4,-3,15:18.4
-6,-2,15:18.4
-5,-2,15:18.4
-2,-2,15:18.4
0,-2,15:18.4
3,-2,15:18.4
-5,-1,15:18.4
-2,-1,15:18.4
5,-1,15:18.4
-9,0,15:18.4
-8,0,15:18.4
-5,0,15:17.13
-4,0,15:18.4
-3,0,15:18.4
-2,0,15:18.4
-1,0,15:18.4
1,0,15:17.13
2,0,15:18.4
3,0,15:18.4
4,0,15:18.4
5,0,15:18.4
-7,1,15:18.4
-4,1,15:17.13
-3,1,15:17.13
-2,1,15:17.13
-1,1,15:17.13
0,1,15:17.13
1,1,15:18.4
2,1,15:18.4
3,1,15:18.4
-8,2,15:18.4
-3,2,15:17.13
-2,2,15:17.13
0,2,15:18.4
1,2,15:18.4
2,2,15:18.4
3,2,15:18.4
5,2,15:18.4
-6,3,15:18.4
-4,3,15:18.4
-2,3,15:18.4
0,3,15:18.4
2,3,15:18.4
4,3,15:18.4
-6,4,15:18.4
-3,4,15:18.4
-1,4,15:18.4
-5,-3,16:18.4
-3,-3,16:18.4
-2,-3,16:18.4
-4,-2,16:18.4
0,-2,16:18.4
-5,-1,16:18.4
-4,0,16:18.4
-7,1,16:18.4
-6,1,16:18.4
-5,1,16:18.4
-4,1,16:18.4
-3,1,16:17.13
-2,1,16:17.13
-1,1,16:18.4
0,1,16:18.4
1,1,16:18.4
-3,2,16:17.13
-2,2,16:17.13
-7,3,16:18.4
-3,3,16:18.4
-6,4,16:18.4
-3,4,16:18.4
0,4,16:18.4
-3,5,16:18.4
-2,5,16:18.4
-1,5,16:18.4
-3,1,17:17.13
-2,1,17:18.4
-1,1,17:18.4
1,1,17:18.4
-3,2,17:17.13
-2,2,17:17.13
-4,3,17:18.4
-2,3,17:17.13
-1,3,17:18.4
2,3,17:18.4
-5,4,17:18.4
-2,4,17:17.13
-1,4,17:18.4
2,4,17:18.4
-6,5,17:18.4
-5,5,17:18.4
-1,5,17:17.13
0,5,17:17.13
2,5,17:18.4
-5,6,17:18.4
-3,6,17:18.4
-1,6,17:17.13
1,6,17:17.13
2,6,17:18.4
3,6,17:18.4
4,6,17:18.4
5,6,17:18.4
-7,7,17:18.4
-3,7,17:18.4
-2,7,17:17.13
0,7,17:18.4
1,7,17:18.4
2,7,17:17.13
3,7,17:18.4
4,7,17:18.4
5,7,17:18.4
-4,8,17:18.4
-3,8,17:17.13
-1,8,17:18.4
0,8,17:18.4
2,8,17:18.4
-7,9,17:18.4
-1,9,17:18.4
1,9,17:18.4
2,9,17:18.4
-7,10,17:18.4
-5,10,17:18.4
-3,10,17:18.4
0,10,17:18.4
1,10,17:18.4
-4,11,17:18.4
0,11,17:18.4
2,11,17:18.4
3,11,17:18.4
-2,12,17:18.4
-1,12,17:18.4
-6,-3,18:18.4
-4,-3,18:18.4
-7,-2,18:18.4
-5,-2,18:18.4
-4,-2,18:18.4
-7,-1,18:18.4
-6,-1,18:18.4
-5,-1,18:18.4
-10,0,18:18.4
-7,0,18:18.4
-6,0,18:17.13
-4,0,18:18.4
-3,0,18:18.4
-10,1,18:18.4
-6,1,18:18.4
-5,1,18:17.13
-4,1,18:17.13
-3,1,18:17.13
-10,2,18:18.4
-5,2,18:18.4
-4,2,18:18.4
-3,2,18:17.13
-2,2,18:17.13
-3,-2,19:18.4
-7,-1,19:18.4
-6,-1,19:18.4
-2,-1,19:18.4
-1,-1,19:18.4
-6,0,19:18.4
-5,0,19:18.4
-3,0,19:18.4
-2,0,19:18.4
-3,1,19:17.13
1,1,19:18.4
-4,2,19:18.4
-3,2,19:17.13
-2,2,19:17.13
1,2,19:18.4
-7,3,19:18.4
-5,3,19:18.4
-3,3,19:18.4
-1,3,19:18.4
-4,4,19:18.4
-5,5,19:18.4
-3,5,19:18.4
-1,5,19:18.4
-3,1,20:17.13
-3,2,20:17.13
-2,2,20:17.13
-1,-5,21:18.4
1,-5,21:18.4
-2,-4,21:18.12
-1,-4,21:18.4
0,-4,21:18.4
-4,-3,21:18.12
3,-3,21:18.4
-7,-2,21:18.12
-5,-2,21:18.12
-4,-2,21:18.12
-3,-2,21:18.12
-1,-2,21:18.12
0,-2,21:18.12
-5,-1,21:18.12
-4,-1,21:18.12
-2,-1,21:18.12
-1,-1,21:18.12
2,-1,21:18.12
-11,0,21:18.4
-9,0,21:18.12
-7,0,21:18.12
-6,0,21:18.12
-4,0,21:18.12
-2,0,21:18.12
0,0,21:18.12
-10,1,21:18.12
-6,1,21:18.12
-5,1,21:18.12
-4,1,21:18.12
-3,1,21:17.13
-2,1,21:18.12
-1,1,21:18.12
0,1,21:18.12
1,1,21:18.12
2,1,21:18.12
3,1,21:18.12
-11,2,21:18.4
-10,2,21:18.12
-9,2,21:18.12
-8,2,21:18.12
-7,2,21:18.12
-5,2,21:18.12
-3,2,21:17.13
-2,2,21:17.13
1,2,21:18.12
-11,3,21:18.4
-7,3,21:18.12
-5,3,21:18.12
-3,3,21:18.12
-2,3,21:18.12
-1,3,21:18.12
-5,4,21:18.12
-3,4,21:18.12
-6,5,21:18.12
-3,5,21:18.12
-2,5,21:18.12
0,5,21:18.12
1,5,21:18.12
2,5,21:18.12
4,5,21:18.12
-5,6,21:18.12
-2,6,21:18.12
4,6,21:18.12
-2,7,21:18.12
3,7,21:18.12
4,7,21:18.12
-2,8,21:18.12
0,8,21:18.12
1,8,21:18.12
3,8,21:18.12
0,9,21:18.12
-1,-3,22:18.12
0,-2,22:18.12
-4,-1,22:18.12
0,-1,22:18.12
-7,1,22:18.12
-5,1,22:18.12
-3,1,22:17.13
-1,1,22:18.12
-4,2,22:18.12
-3,2,22:17.13
-2,2,22:17.13
0,2,22:18.12
-3,3,22:18.12
1,3,22:18.12
-3,4,22:18.12
0,4,22:18.12
-5,5,22:18.12
-4,5,22:18.12
-3,5,22:18.12
2,-4,23:18.4
2,-3,23:18.4
5,-3,23:18.4
-1,-2,23:18.4
0,-2,23:18.4
3,-2,23:18.4
-2,-1,23:18.4
-1,-1,23:18.4
1,-1,23:18.4
4,-1,23:18.4
5,-1,23:18.4
6,-1,23:18.4
-2,0,23:18.4
-1,0,23:18.4
0,0,23:18.4
1,0,23:18.4
2,0,23:17.13
5,0,23:18.4
6,0,23:18.4
-3,1,23:17.13
-2,1,23:18.4
-1,1,23:18.4
0,1,23:17.13
1,1,23:17.13
2,1,23:18.4
5,1,23:18.4
-3,2,23:17.13
-2,2,23:17.13
-1,2,23:17.13
0,2,23:18.4
1,2,23:18.4
2,2,23:18.4
3,2,23:18.4
6,2,23:18.4
2,3,23:18.4
3,3,23:18.4
-2,4,23:18.4
2,4,23:18.4
1,5,23:18.4
2,5,23:18.4
-3,-2,24:18.4
-1,-2,24:18.4
1,-2,24:18.4
-3,-1,24:18.4
-1,-1,24:18.4
0,-1,24:18.4
-3,0,24:18.4
2,0,24:18.4
3,0,24:18.4
-6,1,24:18.4
-4,1,24:18.4
-3,1,24:17.13
-2,1,24:18.4
-1,1,24:18.4
1,1,24:18.4
-4,2,24:18.4
-3,2,24:17.13
-2,2,24:17.13
-1,2,24:18.4
1,2,24:18.4
3,2,24:18.4
5,2,24:18.4
-7,3,24:18.4
-6,3,24:18.4
-3,3,24:18.4
-2,3,24:18.4
-1,3,24:18.4
1,3,24:18.4
-6,4,24:18.4
-5,4,24:18.4
-3,4,24:18.4
-2,4,24:18.4
-1,4,24:18.4
1,4,24:18.4
2,4,24:18.4
3,4,24:18.4
-3,5,24:18.4
-2,5,24:18.4
1,5,24:18.4
2,5,24:18.4
-2,6,24:18.4
-1,6,24:18.4
2,6,24:18.4
-2,7,24:18.4
-3,8,24:18.4
-3,1,25:17.13
-3,2,25:17.13
-2,2,25:17.13
-3,1,26:17.13
-3,2,26:17.13
-2,2,26:17.13
0,2,26:18.4
2,2,26:18.4
-2,3,26:17.13
-1,3,26:18.4
0,3,26:18.4
2,3,26:18.4
-4,4,26:18.4
-2,4,26:17.13
3,4,26:18.4
4,4,26:18.4
-4,5,26:18.4
-1,5,26:17.13
0,5,26:18.4
1,5,26:18.4
2,5,26:18.4
4,5,26:18.4
-2,6,26:18.4
-1,6,26:18.4
0,6,26:17.13
2,6,26:18.4
3,6,26:18.4
4,6,26:18.4
-4,8,26:18.4
-1,8,26:18.4
1,8,26:18.4
0,9,26:18.4
3,9,26:18.4
-1,-7,27:18.4
1,-7,27:18.4
-4,-6,27:18.4
-1,-6,27:18.4
-5,-5,27:18.4
-1,-5,27:18.4
2,-5,27:18.4
3,-5,27:18.4
-9,-4,27:18.4
-7,-4,27:18.4
-5,-4,27:18.4
-3,-4,27:18.4
0,-4,27:18.4
3,-4,27:18.4
-8,-3,27:18.4
-4,-3,27:18.4
-3,-3,27:18.4
-2,-3,27:18.4
-1,-3,27:17.13
3,-3,27:18.4
-11,-2,27:18.4
-10,-2,27:18.4
-9,-2,27:18.4
-6,-2,27:18.4
-4,-2,27:18.4
-3,-2,27:18.4
-2,-2,27:17.13
-9,-1,27:18.4
-7,-1,27:18.4
-3,-1,27:17.13
-1,-1,27:18.4
-10,0,27:18.4
-9,0,27:18.4
-7,0,27:17.13
-6,0,27:18.4
-3,0,27:17.13
-1,0,27:18.4
-11,1,27:18.4
-7,1,27:18.4
-6,1,27:17.13
-5,1,27:18.4
-3,1,27:17.13
0,1,27:18.4
-11,2,27:18.4
-5,2,27:17.13
-4,2,27:17.13
-3,2,27:17.13
-9,3,27:18.4
-8,3,27:18.4
-9,4,27:18.4
-7,4,27:18.4
-6,4,27:18.4
-5,4,27:18.4
-4,-6,28:18.4
-7,-4,28:18.4
-7,-3,28:18.4
-3,-3,28:18.4
-2,-3,28:18.4
0,-3,28:18.4
-7,-2,28:18.4
-6,-2,28:18.4
-4,-2,28:18.4
-3,-2,28:18.4
-1,-2,28:18.4
1,-2,28:18.4
-7,-1,28:18.4
-3,-1,28:18.4
-2,-1,28:18.4
0,-1,28:18.4
-7,0,28:18.4
-6,0,28:18.4
-5,0,28:18.4
-2,0,28:18.4
-1,0,28:18.4
0,0,28:18.4
-5,1,28:18.4
-3,1,28:17.13
-1,1,28:18.4
-5,2,28:18.4
-4,2,28:18.4
-3,2,28:17.13
-1,2,28:18.4
-3,3,28:18.4
-2,3,28:18.4
0,3,28:18.4
1,3,28:18.4
-5,4,28:18.4
-3,4,28:18.4
-5,5,28:18.4
-4,6,28:18.4
-3,1,29:17.13
-3,2,29:17.13
-8,-4,30:18.4
-6,-4,30:18.4
-5,-4,30:18.4
-4,-3,30:18.4
-9,-2,30:18.4
-8,-2,30:18.4
-6,-2,30:18.4
-8,-1,30:18.4
-6,-1,30:18.4
-5,-1,30:18.4
-6,0,30:17.13
-7,1,30:18.4
-5,1,30:17.13
-4,1,30:17.13
-3,1,30:17.13
-6,2,30:18.4
-3,2,30:17.13
-6,3,30:18.4
-5,3,30:18.4
-7,4,30:18.4
-6,4,30:18.4
-2,-2,31:18.4
-5,-1,31:18.4
-4,-1,31:18.4
-3,-1,31:18.4
-2,-1,31:18.4
-1,-1,31:18.4
-2,0,31:18.4
-4,1,31:18.4
-3,1,31:17.13
-2,1,31:18.4
-1,1,31:18.4
-6,2,31:18.4
-3,2,31:17.13
-2,2,31:18.4
-2,3,31:18.4
1,3,31:18.4
-4,4,31:18.4
-2,4,31:18.4
-2,5,31:18.4
-4,6,31:18.4
-1,6,31:18.4
-1,-3,32:18.4
-5,-2,32:18.4
0,-2,32:18.4
-5,-1,32:18.4
-2,-1,32:18.4
-1,-1,32:18.4
1,-1,32:18.4
2,-1,32:18.4
-6,0,32:18.4
-4,0,32:18.4
-1,0,32:18.4
0,0,32:17.13
2,0,32:18.4
-5,1,32:18.4
-3,1,32:17.13
-2,1,32:17.13
-1,1,32:17.13
0,1,32:18.4
-6,2,32:18.4
-5,2,32:18.4
-3,2,32:17.13
-2,2,32:18.4
-1,2,32:18.4
1,2,32:18.4
2,2,32:18.4
-1,3,32:18.4
0,3,32:18.4
-5,4,32:18.4
-3,4,32:18.4
-2,4,32:18.4
-4,5,32:18.4
-1,5,32:18.4
0,5,32:18.4
-3,1,33:17.13
-3,2,33:17.13
-5,-3,34:18.4
-4,-3,34:18.4
-3,-3,34:18.4
-3,-2,34:18.4
-4,-1,34:18.4
-2,-1,34:18.4
0,-1,34:18.4
1,-1,34:18.4
-6,0,34:18.4
-1,0,34:18.4
1,0,34:18.4
-5,1,34:18.4
-4,1,34:18.4
-3,1,34:17.13
-2,1,34:18.4
-4,2,34:18.4
-3,2,34:17.13
0,2,34:18.4
-6,3,34:18.4
-5,3,34:18.4
-3,3,34:18.4
-2,3,34:18.4
-5,4,34:18.4
-1,4,34:18.4
-1,0,35:18.4
-4,1,35:18.4
-3,1,35:17.13
-2,1,35:18.4
-7,2,35:18.4
-3,2,35:17.13
-1,2,35:18.4
1,2,35:18.4
-3,3,35:17.13
-4,4,35:18.4
-3,4,35:17.13
-2,4,35:18.4
0,4,35:18.4
-6,5,35:18.4
0,5,35:18.4
-1,6,35:18.4
1,6,35:18.4
-3,7,35:18.4
-1,7,35:18.4
0,7,35:18.4
-1,8,35:18.4
-3,1,36:17.13
-4,-3,37:18.4
-2,-3,37:18.4
-5,-2,37:18.4
-1,-2,37:18.4
-6,-1,37:18.4
-3,-1,37:18.4
0,-1,37:18.4
-7,0,37:18.4
-1,0,37:18.4
0,0,37:18.4
-5,1,37:18.4
-4,1,37:18.4
-3,1,37:17.13
-2,1,37:18.4
0,1,37:18.4
1,1,37:18.4
-5,2,37:18.4
-3,2,37:18.4
1,2,37:18.4
-3,3,37:18.4
-1,3,37:18.4
-4,4,37:18.4
-2,4,37:18.4
-2,5,37:18.4
-5,-3,38:18.4
-4,-3,38:18.4
-7,-2,38:18.4
-6,-2,38:18.4
-2,-2,38:18.4
-8,-1,38:18.4
-6,-1,38:18.4
-9,0,38:18.4
-8,0,38:18.4
-6,0,38:18.4
-5,0,38:18.4
-7,1,38:18.4
-6,1,38:17.13
-5,1,38:17.13
-4,1,38:17.13
-3,1,38:17.13
-1,1,38:18.4
-9,2,38:18.4
-7,2,38:18.4
-5,2,38:18.4
-4,2,38:18.4
-1,2,38:18.4
-2,3,38:18.4
-7,4,38:18.4
-6,4,38:18.4
-5,4,38:18.4
-2,4,38:18.4
-3,1,39:17.13
-4,-4,40:18.4
-2,-4,40:18.4
-1,-4,40:18.4
-5,-3,40:18.4
-6,-2,40:18.4
-1,-1,40:17.13
-3,0,40:18.4
-2,0,40:17.13
0,0,40:18.4
-6,1,40:18.4
-3,1,40:17.13
-2,1,40:18.4
-1,1,40:18.4
0,1,40:18.4
2,1,40:18.4
-2,2,40:18.4
0,2,40:18.4
-1,3,40:18.4
-3,1,41:17.13
-4,-3,42:18.12
-3,-3,42:18.12
-6,-2,42:18.12
-4,-2,42:18.12
-1,-2,42:18.12
-6,-1,42:18.12
-5,-1,42:18.12
-3,-1,42:18.12
-6,0,42:18.12
-3,0,42:18.12
-2,0,42:18.12
1,0,42:18.12
-6,1,42:18.12
-4,1,42:18.12
-3,1,42:17.13
-2,1,42:18.12
0,1,42:18.12
-5,2,42:18.12
-4,2,42:18.12
-1,2,42:18.12
-7,3,42:18.12
1,3,42:18.12
-5,4,42:18.12
-4,4,42:18.12
0,4,42:18.12
-3,5,42:18.12
-1,5,42:18.12
-4,-2,43:18.12
-3,-2,43:18.12
-3,-1,43:18.12
-1,-1,43:18.12
-3,0,43:18.12
-2,0,43:18.12
-5,1,43:18.12
-3,1,43:17.13
-1,1,43:18.12
-6,2,43:18.12
-1,2,43:18.12
-5,3,43:18.12
-3,3,43:18.12
-1,3,43:18.12
-3,4,43:18.12
-4,-2,44:18.12
-2,-2,44:18.12
-4,0,44:18.12
0,0,44:18.12
-3,1,44:17.13
-3,3,44:18.12
-3,4,44:18.12
-3,1,45:17.13
-5,0,46:18.12
-3,0,46:18.12
-4,1,46:18.12
-3,1,46:17.13
-2,1,46:18.12
-1,2,46:18.12
-3,0,47:18.4
-3,1,47:17.13
-1,1,47:18.4
-4,3,47:18.4
-3,3,47:18.4
-2,3,47:18.4
-3,1,48:17.13
-5,0,49:18.4
-4,0,49:18.4
-5,1,49:18.4
-3,1,49:17.13
-1,1,49:18.4
-4,2,49:18.4
-3,3,49:18.4
-4,-1,50:18.4
-3,-1,50:18.4
-1,0,50:18.4
-3,1,50:17.13
-5,2,50:18.4
-2,3,50:18.4
-3,1,51:17.13
-3,0,52:18.4
-2,0,52:18.4
-3,1,52:17.13
-3,2,52:18.4
-3,1,53:17.13
-2,1,53:18.4
-4,2,53:18.4
-4,1,54:18.4
-3,1,54:17.13
-4,2,54:18.4
