[META]
version=2.0
spawnOnBlockType=2
spawnSunlight=True
spawnDarkness=True
spawnWater=False
spawnLava=False
underFill=False
randomRotation=True
dig=True
tree=False
branch=False
needsFoundation=True
rarity=100
collisionPercentage=20
spawnElevationMin=0
spawnElevationMax=200
spawnInBiome=Custom
[DATA]
-1,-1,-3:17.13
1,0,-3:17.13
-1,1,-3:17.13
-1,-1,-2:17.13
0,-1,-2:17.13
0,0,-2:17.13
1,0,-2:17.13
-1,1,-2:17.13
-2,-2,-1:17.13
-1,-1,-1:17.13
0,-1,-1:17.13
-1,0,-1:17.13
0,0,-1:17.13
1,0,-1:17.13
-1,1,-1:17.13
-2,-2,0:17.13
-1,-1,0:17.13
0,-1,0:17.13
-1,0,0:17.13
0,0,0:17.13
1,0,0:17.13
-1,1,0:17.13
-1,-1,1:17.13
0,-1,1:17.13
-1,0,1:17.13
0,0,1:17.13
-1,-1,2:17.13
-1,0,2:17.13
0,0,2:17.13
-1,-1,3:17.13
-1,0,3:17.13
0,0,3:17.13
-1,-1,4:17.13
-1,0,4:17.13
0,0,4:17.13
-1,-1,5:17.13
-1,0,5:17.13
0,0,5:17.13
-1,-1,6:17.13
-1,0,6:17.13
0,0,6:17.13
-1,-1,7:17.13
-1,0,7:17.13
0,0,7:17.13
-1,-1,8:17.13
-1,0,8:17.13
0,0,8:17.13
-1,-1,9:17.13
-1,0,9:17.13
0,0,9:17.13
-1,-1,10:17.13
-1,0,10:17.13
0,0,10:17.13
-1,-1,11:17.13
-1,0,11:17.13
-1,-1,12:17.13
-1,0,12:17.13
-1,-1,13:17.13
-1,0,13:17.13
0,-4,14:18.5
-1,-3,14:18.5
-4,-2,14:18.5
-1,-2,14:18.5
-4,-1,14:18.5
-3,-1,14:18.5
-2,-1,14:17.13
-1,-1,14:17.13
2,-1,14:18.5
-2,0,14:18.5
-1,0,14:17.13
-1,1,14:18.5
0,1,14:18.5
-2,2,14:18.5
0,2,14:18.5
-4,-3,15:18.5
-3,-2,15:17.13
-2,-2,15:18.5
-1,-2,15:18.5
-2,-1,15:18.5
-1,-1,15:17.13
0,-1,15:18.5
-2,0,15:18.5
-1,0,15:17.13
0,0,15:18.5
-2,1,15:18.5
-1,1,15:18.5
0,1,15:18.5
-3,-5,16:18.5
-3,-4,16:18.5
-1,-4,16:18.5
-3,-3,16:18.5
-2,-3,16:18.5
0,-3,16:18.5
-6,-2,16:18.5
-5,-2,16:18.5
-3,-2,16:17.13
-1,-2,16:18.5
0,-2,16:18.5
-1,-1,16:17.13
0,-1,16:18.5
-5,0,16:18.5
-3,0,16:18.5
-1,0,16:17.13
-4,1,16:18.5
-3,1,16:18.5
-4,-4,17:18.5
-4,-3,17:17.13
-3,-3,17:18.5
-4,-2,17:18.5
-1,-1,17:17.13
0,-1,17:18.5
-5,0,17:18.5
-1,0,17:17.13
-2,1,17:17.13
1,1,17:18.5
-3,2,17:18.5
-2,2,17:18.5
-1,2,17:18.5
-4,3,17:18.5
-3,3,17:18.5
-1,3,17:18.5
-4,-6,18:18.5
-6,-5,18:18.5
-4,-5,18:18.5
-3,-5,18:18.5
-2,-5,18:18.5
-4,-4,18:18.5
-6,-3,18:18.5
-4,-3,18:17.13
-3,-3,18:18.5
-4,-2,18:18.5
-1,-2,18:18.5
-4,-1,18:18.5
-2,-1,18:18.5
-1,-1,18:17.13
-5,0,18:18.5
-4,0,18:18.5
-2,0,18:18.5
-1,0,18:17.13
0,0,18:18.5
-1,1,18:18.5
0,1,18:18.5
-2,2,18:17.13
-4,-4,19:18.5
-5,-3,19:18.5
-4,-3,19:17.13
-1,-3,19:18.5
1,-3,19:18.5
-4,-2,19:18.5
-2,-2,19:18.5
0,-2,19:18.5
-3,-1,19:18.5
-2,-1,19:18.5
-1,-1,19:17.13
0,-1,19:18.5
3,-1,19:18.5
-2,0,19:18.5
-1,0,19:17.13
0,0,19:17.13
3,0,19:18.5
-3,1,19:18.5
-1,1,19:18.5
0,1,19:18.5
1,1,19:18.5
-5,2,19:18.5
-3,2,19:18.5
-2,2,19:17.13
-1,2,19:18.5
0,2,19:18.5
1,2,19:18.5
-2,3,19:18.5
0,3,19:18.5
-4,4,19:18.5
-2,5,19:18.5
-3,-6,20:18.5
-6,-5,20:18.5
-3,-5,20:18.5
-2,-5,20:18.5
-5,-4,20:18.5
-3,-4,20:18.5
-6,-3,20:18.5
-4,-3,20:17.13
-3,-3,20:18.5
-2,-3,20:18.5
-5,-2,20:18.5
-4,-2,20:18.5
-3,-2,20:18.5
2,-2,20:18.5
-5,-1,20:18.5
-2,-1,20:18.5
-1,-1,20:17.13
0,-1,20:18.5
-3,0,20:18.5
-1,0,20:17.13
0,0,20:18.5
1,0,20:18.5
-2,1,20:18.5
1,1,20:17.13
2,1,20:18.5
3,1,20:18.5
-3,2,20:17.13
-2,2,20:18.5
1,2,20:18.5
0,3,20:18.5
3,3,20:18.5
0,-2,21:18.5
-3,-1,21:18.5
-2,-1,21:18.5
-1,-1,21:17.13
-1,0,21:18.5
-2,1,21:18.5
-1,1,21:18.5
2,1,21:17.13
-6,2,21:18.5
-5,2,21:18.5
-3,2,21:17.13
-2,2,21:18.5
0,2,21:18.5
-5,3,21:18.5
-4,3,21:18.5
-3,3,21:18.5
-2,3,21:18.5
-1,3,21:18.5
-4,4,21:18.5
-3,4,21:18.5
-4,5,21:18.5
-1,-6,22:18.13
-1,-5,22:18.13
1,-5,22:18.13
-5,-4,22:18.13
-4,-4,22:18.13
-3,-4,22:18.13
-2,-4,22:18.13
-1,-4,22:18.13
3,-4,22:18.13
-6,-3,22:18.13
-5,-3,22:18.13
3,-3,22:18.13
-4,-2,22:18.13
-3,-2,22:18.13
-1,-2,22:18.13
0,-2,22:18.13
1,-2,22:18.5
2,-2,22:18.13
3,-2,22:18.13
4,-2,22:18.13
-5,-1,22:18.13
-4,-1,22:18.13
-2,-1,22:18.13
-1,-1,22:17.13
1,-1,22:18.13
2,-1,22:18.13
3,-1,22:18.13
-6,0,22:18.13
-2,0,22:18.13
-6,1,22:18.13
-3,1,22:18.13
-2,1,22:18.13
-1,1,22:18.13
0,1,22:18.13
1,1,22:18.5
2,1,22:17.13
3,1,22:18.5
4,1,22:18.5
-3,2,22:17.13
1,2,22:18.13
3,2,22:18.5
5,2,22:18.5
-4,3,22:18.13
-1,3,22:18.13
2,3,22:18.13
3,3,22:18.5
-1,4,22:18.13
0,4,22:18.13
3,4,22:18.5
-1,-2,23:18.5
0,-2,23:17.13
1,-2,23:18.5
-1,-1,23:17.13
0,-1,23:18.5
1,-1,23:18.5
-2,0,23:18.5
-1,0,23:18.5
-1,-6,24:18.13
0,-6,24:18.13
-4,-5,24:18.13
-2,-5,24:18.13
-1,-5,24:18.13
-4,-4,24:18.13
-3,-4,24:18.13
-1,-4,24:18.13
0,-4,24:18.13
2,-4,24:18.13
3,-4,24:18.13
-2,-3,24:18.13
-1,-3,24:18.13
1,-3,24:17.13
3,-3,24:18.13
-5,-2,24:18.13
-1,-2,24:18.13
3,-2,24:18.13
4,-2,24:18.13
-6,-1,24:18.13
-4,-1,24:18.13
-3,-1,24:18.13
-1,-1,24:17.13
1,-1,24:18.13
2,-1,24:18.13
3,-1,24:18.13
4,-1,24:18.13
1,0,24:18.13
2,0,24:18.13
3,0,24:18.13
-5,1,24:18.13
-1,1,24:18.13
2,1,24:18.13
-5,2,24:18.13
-2,2,24:18.13
-1,2,24:18.13
3,2,24:18.13
-3,3,24:18.13
-2,3,24:18.13
0,-4,25:18.5
1,-4,25:18.13
2,-4,25:18.13
0,-3,25:18.5
1,-3,25:17.13
-2,-2,25:18.5
-1,-2,25:18.5
-2,-1,25:18.5
-1,-1,25:17.13
0,-1,25:18.5
-2,-6,26:18.5
-3,-5,26:18.5
1,-5,26:18.13
-1,-4,26:18.5
-1,-3,26:18.5
-5,-2,26:18.13
-4,-2,26:18.5
-3,-2,26:18.5
-1,-2,26:18.5
3,-2,26:18.5
4,-2,26:18.5
-5,-1,26:18.13
-4,-1,26:18.5
-2,-1,26:18.5
-1,-1,26:17.13
0,-1,26:18.5
1,-1,26:18.5
2,-1,26:18.5
3,-1,26:18.5
-5,0,26:18.13
0,0,26:18.5
-5,1,26:18.5
-3,1,26:18.5
0,1,26:18.5
1,1,26:18.5
2,1,26:18.5
4,1,26:18.5
-4,2,26:18.5
-3,2,26:18.5
-2,2,26:18.5
-1,2,26:18.5
0,2,26:18.5
1,2,26:18.5
-4,3,26:18.5
2,3,26:18.5
-3,4,26:18.5
0,4,26:18.5
-2,-2,27:18.5
-1,-2,27:18.5
0,-2,27:18.5
-2,-1,27:18.5
-1,-1,27:17.13
0,-1,27:18.5
-1,0,27:18.5
0,0,27:18.5
-1,-6,28:18.13
-3,-5,28:18.5
-2,-5,28:18.5
-1,-5,28:18.13
-4,-4,28:18.13
0,-4,28:18.13
1,-4,28:18.13
-6,-3,28:18.13
-5,-3,28:18.13
-3,-3,28:18.5
-1,-3,28:18.5
1,-3,28:18.5
2,-3,28:18.13
-6,-2,28:18.13
1,-2,28:18.5
-5,-1,28:18.13
-3,-1,28:18.5
-2,-1,28:18.5
-1,-1,28:17.13
0,-1,28:17.13
2,-1,28:18.5
3,-1,28:18.13
-4,0,28:18.5
-1,0,28:18.5
1,0,28:18.5
3,0,28:18.13
-4,1,28:18.5
2,1,28:18.5
-4,2,28:18.5
-2,2,28:18.5
-1,2,28:18.5
2,2,28:18.5
3,2,28:18.5
-2,3,28:18.5
0,3,28:18.13
1,3,28:18.13
-3,4,28:18.5
1,4,28:18.13
-2,-3,29:18.5
-1,-3,29:18.5
0,-3,29:18.13
-1,-2,29:17.13
0,-2,29:18.5
-1,-1,29:17.13
0,-1,29:18.5
-3,-6,30:18.5
-1,-6,30:18.5
0,-6,30:18.5
-1,-5,30:18.5
2,-5,30:18.13
0,-4,30:18.13
3,-4,30:18.5
-3,-3,30:18.5
-1,-3,30:18.5
1,-3,30:18.13
4,-3,30:18.5
-2,-2,30:18.5
-1,-2,30:18.5
3,-2,30:18.5
-6,-1,30:18.5
-3,-1,30:18.5
-2,-1,30:17.13
-1,-1,30:17.13
0,-1,30:18.5
2,-1,30:18.5
3,-1,30:18.5
4,-1,30:18.5
-1,0,30:18.5
0,0,30:18.5
3,0,30:18.5
-4,1,30:18.5
-3,1,30:18.5
-1,1,30:18.5
0,1,30:18.5
1,1,30:18.5
4,1,30:18.5
-5,2,30:18.5
-4,2,30:18.5
-1,2,30:18.5
-4,3,30:18.5
0,3,30:18.5
1,3,30:18.5
-2,4,30:18.5
-1,4,30:18.5
-3,-6,31:18.5
0,-6,31:18.5
-3,-5,31:18.5
-2,-5,31:18.5
0,-5,31:18.13
-3,-4,31:18.5
-2,-4,31:18.5
-1,-4,31:18.5
2,-4,31:18.13
-5,-3,31:18.5
-6,-2,31:18.5
0,-2,31:18.5
2,-2,31:18.5
4,-2,31:18.5
-5,-1,31:18.5
-4,-1,31:18.5
-3,-1,31:18.5
-2,-1,31:18.5
-1,-1,31:17.13
0,-1,31:17.13
1,-1,31:18.5
3,-1,31:18.5
4,-1,31:18.5
-3,0,31:18.5
-2,0,31:18.5
2,0,31:18.5
3,0,31:18.5
-6,1,31:18.5
-4,2,31:18.5
0,2,31:18.5
2,2,31:18.5
-3,3,31:18.5
0,3,31:18.5
1,3,31:18.5
-3,4,31:18.5
-1,4,31:18.5
-2,-2,32:18.5
-1,-2,32:18.5
0,-2,32:18.5
-2,-1,32:18.5
-1,-1,32:17.13
0,-1,32:18.5
-1,-5,33:18.5
-4,-4,33:18.5
-2,-4,33:18.5
1,-4,33:18.5
2,-4,33:18.5
-1,-3,33:18.5
-3,-2,33:18.5
-1,-2,33:18.5
0,-2,33:18.5
3,-2,33:18.5
-3,-1,33:18.5
-2,-1,33:17.13
-1,-1,33:17.13
1,-1,33:18.5
2,-1,33:18.5
3,-1,33:18.5
-3,0,33:18.5
0,0,33:18.5
3,0,33:18.5
-3,1,33:18.5
-1,1,33:18.5
0,1,33:18.5
1,1,33:18.5
-3,2,33:18.5
-2,2,33:18.5
-1,2,33:18.5
-2,3,33:18.5
-1,3,33:18.5
1,3,33:18.5
-2,-3,34:18.5
-1,-3,34:18.5
-1,-2,34:17.13
-2,-1,34:18.5
-1,-1,34:17.13
0,-1,34:18.5
-2,0,34:18.5
-1,0,34:17.13
0,0,34:18.5
-1,1,34:18.5
0,1,34:18.5
-2,-4,35:18.13
-1,-4,35:18.13
0,-4,35:18.13
-3,-3,35:18.13
-1,-3,35:18.13
0,-3,35:18.13
-1,-2,35:18.13
-1,-1,35:17.13
0,-1,35:18.13
-3,0,35:18.13
-2,0,35:18.13
-1,0,35:18.13
0,0,35:18.13
-2,1,35:18.13
0,1,35:18.13
1,1,35:18.13
-1,2,35:18.13
0,2,35:18.13
-1,-2,36:18.5
-2,-1,36:18.5
-1,-1,36:17.13
-2,0,36:18.5
0,0,36:18.5
0,-2,37:18.13
-3,-1,37:18.13
-2,-1,37:18.13
-1,-1,37:17.13
0,-1,37:18.13
1,-1,37:18.13
-3,0,37:18.13
-2,1,37:18.13
-2,-2,38:18.5
-1,-1,38:17.13
0,-1,38:18.5
-1,-2,39:18.13
-2,-1,39:18.13
-1,-1,39:17.13
0,-1,39:18.13
-1,0,39:18.13
