[META]
version=2.0
spawnOnBlockType=2
spawnSunlight=True
spawnDarkness=True
spawnWater=False
spawnLava=False
underFill=False
randomRotation=True
dig=True
tree=False
branch=False
needsFoundation=True
rarity=100
collisionPercentage=20
spawnElevationMin=0
spawnElevationMax=200
spawnInBiome=Custom
[DATA]
0,0,-3:17.13
0,0,-2:17.13
1,0,-2:17.13
0,0,-1:17.13
1,0,-1:17.13
0,1,-1:17.13
0,0,0:17.13
1,0,0:17.13
0,1,0:17.13
0,0,1:17.13
0,1,1:17.13
-1,-5,2:18.5
0,-5,2:18.5
1,-5,2:18.5
-1,-4,2:18.13
2,-4,2:18.13
-1,-2,2:18.13
0,-2,2:18.13
1,-2,2:18.13
2,-2,2:18.13
3,-2,2:18.13
-4,-1,2:18.13
-2,-1,2:18.13
5,-1,2:18.13
-3,0,2:18.13
-2,0,2:18.13
0,0,2:17.13
2,0,2:18.13
4,0,2:18.13
5,0,2:18.13
-4,1,2:18.13
-3,1,2:18.13
0,1,2:17.13
3,1,2:18.13
5,1,2:18.13
-3,2,2:18.13
-2,2,2:18.13
2,2,2:18.13
4,2,2:18.13
-4,3,2:18.13
-1,3,2:18.13
2,3,2:18.13
4,3,2:18.13
0,4,2:18.13
1,4,2:18.13
2,4,2:18.13
3,4,2:18.13
-2,5,2:18.13
1,5,2:18.13
-1,-5,3:18.5
-3,-4,3:18.13
0,-4,3:18.13
3,-4,3:18.13
-4,-3,3:18.13
-3,-3,3:18.13
-2,-3,3:18.13
2,-3,3:18.13
-2,-2,3:18.13
4,-2,3:18.13
5,-2,3:18.13
-4,-1,3:18.13
0,-1,3:18.13
2,-1,3:18.13
4,-1,3:18.13
-4,0,3:18.13
-3,0,3:18.13
-2,0,3:18.13
-1,0,3:18.13
0,0,3:17.13
1,0,3:18.13
2,0,3:18.13
3,0,3:18.13
5,0,3:18.13
-4,1,3:18.13
-3,1,3:18.13
-2,1,3:18.13
0,1,3:17.13
1,1,3:18.13
2,1,3:18.13
-5,2,3:18.5
-3,2,3:18.13
-2,2,3:18.13
0,2,3:18.13
3,2,3:18.13
4,2,3:18.13
-3,3,3:18.13
-1,3,3:18.13
0,3,3:18.13
2,3,3:18.13
3,3,3:18.13
-3,4,3:18.13
-1,4,3:18.13
0,4,3:18.13
1,4,3:18.13
-2,5,3:18.13
2,5,3:18.13
0,0,4:17.13
0,1,4:17.13
-1,-4,5:18.13
0,-4,5:18.13
2,-4,5:18.13
1,-3,5:18.13
-4,-2,5:18.13
0,-2,5:18.13
1,-2,5:18.13
2,-2,5:18.13
4,-2,5:18.13
-3,-1,5:18.13
-2,-1,5:18.13
0,-1,5:18.13
1,-1,5:18.13
2,-1,5:18.13
-4,0,5:18.13
-3,0,5:18.13
-1,0,5:18.13
0,0,5:17.13
1,0,5:18.13
2,0,5:18.13
-4,1,5:18.13
0,1,5:17.13
3,1,5:18.13
-4,2,5:18.13
0,2,5:18.13
-3,3,5:18.13
-1,3,5:18.13
0,3,5:18.13
1,3,5:18.13
2,3,5:18.13
3,3,5:18.13
1,4,5:18.13
-1,-4,6:18.13
0,-4,6:18.13
-3,-3,6:18.13
-1,-3,6:18.13
0,-3,6:18.13
1,-3,6:18.13
-3,-2,6:18.13
-2,-2,6:18.13
0,-2,6:18.13
3,-2,6:18.13
-4,-1,6:18.13
3,-1,6:18.13
-4,0,6:18.13
-2,0,6:18.13
-1,0,6:18.13
0,0,6:17.13
1,0,6:18.13
3,0,6:18.13
-3,1,6:18.13
-2,1,6:18.13
0,1,6:17.13
0,2,6:18.13
2,2,6:18.13
3,2,6:18.13
4,2,6:18.13
2,3,6:18.13
-2,4,6:18.13
-1,4,6:18.13
0,4,6:18.13
0,0,7:17.13
1,-3,8:18.13
0,-2,8:18.13
2,-2,8:18.13
-1,-1,8:18.13
1,-1,8:18.13
-3,0,8:18.13
0,0,8:17.13
1,0,8:18.13
3,0,8:18.13
-1,1,8:18.13
0,1,8:18.13
-2,2,8:18.13
0,2,8:18.13
1,2,8:18.13
2,2,8:18.13
1,3,8:18.13
-1,-3,9:18.5
0,-3,9:18.5
1,-3,9:18.5
0,-2,9:18.5
2,-2,9:18.5
0,-1,9:18.5
1,-1,9:18.5
0,0,9:17.13
-1,1,9:18.5
0,1,9:18.5
1,1,9:18.5
-2,2,9:18.5
1,2,9:18.5
-1,3,9:18.5
0,3,9:18.5
1,3,9:18.5
0,0,10:17.13
0,-2,11:18.5
1,-2,11:18.5
0,-1,11:18.5
-2,0,11:18.5
0,0,11:17.13
1,0,11:18.5
0,1,11:18.5
-1,2,11:18.5
-1,-2,12:18.5
1,-2,12:18.5
0,-1,12:18.5
1,-1,12:18.5
-2,0,12:18.5
-1,0,12:18.5
0,0,12:17.13
1,0,12:18.5
0,1,12:18.5
1,1,12:18.5
-1,2,12:18.5
0,0,13:17.13
0,-2,14:18.13
0,0,14:17.13
1,0,14:18.13
-2,1,14:18.13
0,1,14:18.13
1,1,14:18.13
-1,2,14:18.13
0,2,14:18.13
-1,-1,15:18.13
1,-1,15:18.13
0,0,15:17.13
0,1,15:18.5
0,-1,16:18.13
-1,0,16:18.13
0,0,16:17.13
1,0,16:18.13
-1,1,16:18.13
1,1,16:18.13
0,0,17:18.13
0,0,18:18.13
