[META]
version=2.0
spawnOnBlockType=2
spawnSunlight=True
spawnDarkness=True
spawnWater=False
spawnLava=False
underFill=False
randomRotation=True
dig=True
tree=False
branch=False
needsFoundation=True
rarity=100
collisionPercentage=20
spawnElevationMin=0
spawnElevationMax=200
spawnInBiome=Custom
[DATA]
-3,-3,-3:17.15
1,-3,-3:17.15
-1,-2,-3:17.15
2,-1,-3:17.15
1,0,-3:17.15
-2,2,-3:17.15
-3,-3,-2:17.15
1,-3,-2:17.15
-2,-2,-2:17.15
-1,-2,-2:17.15
1,-2,-2:17.15
2,-1,-2:17.15
-1,1,-2:17.15
1,1,-2:17.15
-2,2,-2:17.15
-2,-2,-1:17.15
1,-2,-1:17.15
-1,1,-1:17.15
1,1,-1:17.15
-2,-2,0:17.15
1,-2,0:17.15
-2,-1,0:17.15
-1,-1,0:17.15
0,-1,0:17.15
1,-1,0:17.15
-1,0,0:17.15
0,0,0:17.15
-1,1,0:17.15
1,1,0:17.15
-1,-1,1:17.15
0,-1,1:17.15
1,-1,1:17.15
-1,0,1:17.15
0,0,1:17.15
-1,-1,2:17.15
0,-1,2:17.15
-1,0,2:17.15
0,0,2:17.15
-1,-1,3:17.15
0,-1,3:17.15
-1,0,3:17.15
0,0,3:17.15
-1,-1,4:17.15
0,-1,4:17.15
-1,0,4:17.15
0,0,4:17.15
-1,-1,5:17.15
0,-1,5:17.15
-1,0,5:17.15
0,0,5:17.15
-1,-1,6:17.15
0,-1,6:17.15
-1,0,6:17.15
0,0,6:17.15
-1,-1,7:17.15
0,-1,7:17.15
-1,0,7:17.15
0,0,7:17.15
-1,-1,8:17.15
0,-1,8:17.15
-1,0,8:17.15
0,0,8:17.15
-1,-1,9:17.15
0,-1,9:17.15
-1,0,9:17.15
0,0,9:17.15
-1,-1,10:17.15
0,-1,10:17.15
-1,0,10:17.15
0,0,10:17.15
-1,-1,11:17.15
0,-1,11:17.15
-1,0,11:17.15
0,0,11:17.15
-1,-1,12:17.15
0,-1,12:17.15
-1,0,12:17.15
0,0,12:17.15
-1,-1,13:17.15
0,-1,13:17.15
-1,0,13:17.15
0,0,13:17.15
-1,-1,14:17.15
0,-1,14:17.15
-1,0,14:17.15
0,0,14:17.15
-1,-1,15:17.15
0,-1,15:17.15
-1,0,15:17.15
0,0,15:17.15
-1,-1,16:17.15
0,-1,16:17.15
-1,0,16:17.15
0,0,16:17.15
-1,-1,17:17.15
0,-1,17:17.15
-1,0,17:17.15
0,0,17:17.15
3,-9,18:18.4
4,-8,18:18.4
3,-7,18:18.4
-1,-3,18:18.4
8,-3,18:18.4
-1,-1,18:17.15
0,-1,18:17.15
-1,0,18:17.15
0,0,18:17.15
4,-10,19:18.4
6,-8,19:18.4
3,-7,19:18.4
2,-6,19:18.4
6,-6,19:18.4
-3,-4,19:18.4
6,-4,19:18.4
8,-4,19:18.4
10,-4,19:18.4
-2,-3,19:18.4
8,-3,19:18.4
0,-2,19:18.4
-3,-1,19:18.4
-1,-1,19:17.15
0,-1,19:17.15
-1,0,19:17.15
7,-9,20:18.4
6,-8,20:18.4
7,-8,20:18.4
-1,-6,20:18.4
-2,-5,20:18.4
0,-5,20:18.4
5,-4,20:18.4
11,-4,20:18.4
-2,-3,20:18.4
5,-3,20:18.4
7,-3,20:18.4
8,-3,20:18.4
11,-3,20:18.4
-1,-2,20:17.15
1,-2,20:18.4
-7,-1,20:18.4
-1,-1,20:17.15
0,-1,20:17.15
1,-1,20:18.4
8,-1,20:18.4
-1,0,20:17.15
0,0,20:18.4
4,-10,21:18.4
5,-9,21:18.4
6,-9,21:18.4
1,-8,21:18.4
3,-8,21:18.4
4,-8,21:17.15
6,-8,21:18.4
2,-7,21:18.4
4,-7,21:17.15
7,-7,21:18.4
8,-7,21:18.4
9,-7,21:18.4
5,-6,21:18.4
10,-6,21:18.4
1,-5,21:18.4
8,-5,21:18.4
-1,-4,21:18.4
2,-4,21:18.4
5,-4,21:18.4
7,-4,21:18.4
8,-4,21:17.15
10,-4,21:18.4
-4,-3,21:18.4
-3,-3,21:18.4
-2,-3,21:18.4
-1,-3,21:17.15
1,-3,21:18.4
7,-3,21:18.4
11,-3,21:18.4
-7,-2,21:18.4
-1,-2,21:18.4
6,-2,21:18.4
8,-2,21:18.4
-9,-1,21:18.4
-8,-1,21:18.4
-1,-1,21:17.15
0,-1,21:17.15
-1,0,21:17.15
5,-11,22:18.4
4,-10,22:18.4
6,-9,22:18.4
6,-8,22:18.4
4,-6,22:17.15
6,-6,22:18.4
8,-6,22:18.4
9,-6,22:18.4
-8,-5,22:18.4
5,-5,22:18.4
-8,-4,22:18.4
2,-4,22:18.4
6,-4,22:17.15
7,-4,22:17.15
11,-4,22:18.4
-11,-3,22:18.4
6,-3,22:18.4
-10,-2,22:18.4
-1,-1,22:17.15
0,-1,22:17.15
8,-1,22:18.4
9,-1,22:18.4
-8,0,22:18.4
-2,0,22:18.4
-1,0,22:17.15
0,0,22:18.4
5,-8,23:18.4
2,-7,23:18.4
3,-7,23:18.4
2,-6,23:18.4
7,-6,23:18.4
9,-6,23:18.4
-8,-5,23:18.4
-7,-5,23:18.4
-3,-5,23:18.4
5,-5,23:17.15
-8,-4,23:18.4
9,-4,23:18.4
-7,-3,23:18.4
-5,-3,23:18.4
-3,-3,23:18.4
-1,-3,23:18.4
0,-3,23:18.4
6,-3,23:18.4
7,-3,23:18.4
-11,-2,23:18.4
-9,-2,23:18.4
-8,-2,23:17.15
1,-2,23:17.15
6,-2,23:18.4
9,-2,23:18.4
-6,-1,23:18.4
-1,-1,23:17.15
0,-1,23:17.15
1,-1,23:18.4
-10,0,23:18.4
-7,0,23:18.4
-2,0,23:17.15
-1,0,23:17.15
-9,1,23:18.4
-1,1,23:17.15
-8,3,23:18.4
-7,3,23:18.4
-1,5,23:18.4
1,5,23:18.4
-2,7,23:18.4
1,7,23:18.4
4,-8,24:18.4
5,-8,24:18.4
4,-7,24:18.4
-8,-4,24:18.4
4,-4,24:17.15
7,-4,24:18.4
3,-3,24:17.15
9,-3,24:18.4
2,-2,24:17.15
-7,-1,24:17.15
-1,-1,24:17.15
0,-1,24:17.15
3,-1,24:18.4
-6,0,24:17.15
-3,0,24:17.15
-1,0,24:17.15
3,0,24:18.4
4,0,24:18.4
-1,2,24:18.4
0,2,24:17.15
4,2,24:18.4
-7,3,24:18.4
-2,3,24:18.4
0,3,24:18.4
2,3,24:18.4
-8,4,24:18.4
-7,4,24:18.4
3,4,24:18.4
-1,5,24:18.4
0,5,24:18.4
0,6,24:18.4
-1,7,24:18.4
-10,-4,25:18.4
-8,-4,25:18.4
2,-3,25:17.15
-2,-2,25:17.15
-8,-1,25:18.4
-1,-1,25:17.15
0,-1,25:17.15
3,-1,25:17.15
-6,0,25:18.4
-1,0,25:17.15
4,0,25:18.4
-5,1,25:17.15
-4,1,25:17.15
4,1,25:18.4
5,1,25:18.4
-6,2,25:17.15
0,2,25:18.4
3,2,25:18.4
-10,3,25:18.4
0,3,25:18.4
1,3,25:17.15
3,3,25:18.4
5,3,25:18.4
0,4,25:17.15
2,4,25:18.4
-5,5,25:18.4
-3,5,25:18.4
0,5,25:17.15
1,5,25:18.4
2,5,25:18.4
3,5,25:18.4
-3,6,25:18.4
-2,6,25:18.4
0,6,25:18.4
2,7,25:18.4
1,-4,26:17.15
2,-3,26:18.4
4,-3,26:18.4
-8,-2,26:18.4
-2,-2,26:17.15
4,-2,26:18.4
-1,-1,26:17.15
3,-1,26:17.15
-7,0,26:18.4
-1,0,26:17.15
4,0,26:18.4
5,0,26:18.4
-8,1,26:18.4
-6,1,26:18.4
-2,1,26:17.15
-4,2,26:18.4
1,2,26:18.4
2,2,26:18.4
6,2,26:18.4
-9,3,26:18.4
-7,3,26:17.15
-6,3,26:18.4
0,3,26:18.4
2,3,26:18.4
5,3,26:18.4
-10,4,26:18.4
-2,4,26:18.4
2,4,26:17.15
-8,5,26:18.4
-7,5,26:18.4
-3,5,26:18.4
5,5,26:18.4
3,6,26:18.4
-5,-8,27:18.4
-4,-8,27:18.4
4,-5,27:18.4
5,-4,27:18.4
6,-4,27:18.4
-2,-3,27:17.15
3,-2,27:18.4
4,-2,27:17.15
-1,-1,27:17.15
0,-1,27:18.4
3,-1,27:18.4
-7,0,27:18.4
-1,0,27:17.15
2,0,27:18.4
3,0,27:17.15
4,0,27:18.4
6,0,27:18.4
-7,1,27:18.4
1,1,27:18.4
2,1,27:18.4
3,1,27:18.4
4,1,27:18.4
5,1,27:18.4
-2,2,27:17.15
1,2,27:18.4
3,2,27:18.4
6,2,27:18.4
-7,3,27:18.4
1,3,27:18.4
2,3,27:18.4
3,3,27:17.15
4,3,27:18.4
6,3,27:18.4
5,4,27:18.4
-7,5,27:18.4
-1,5,27:18.4
1,5,27:18.4
2,5,27:18.4
4,5,27:18.4
4,6,27:18.4
-6,-10,28:18.4
-7,-8,28:18.4
-5,-7,28:18.4
4,-7,28:18.4
-4,-6,28:18.4
4,-6,28:18.4
-2,-5,28:17.15
-2,-4,28:17.15
4,-4,28:18.4
5,-4,28:18.4
1,-3,28:18.4
3,-3,28:17.15
6,-3,28:18.4
-6,-2,28:18.4
4,-2,28:18.4
5,-2,28:17.15
-6,-1,28:17.15
-1,-1,28:17.15
5,-1,28:18.4
6,-1,28:18.4
7,-1,28:18.4
-1,0,28:17.15
3,0,28:18.4
5,0,28:18.4
6,0,28:18.4
-7,1,28:18.4
3,1,28:18.4
-1,3,28:17.15
1,4,28:18.4
-7,5,28:18.4
-1,5,28:18.4
0,5,28:18.4
2,5,28:18.4
4,6,28:18.4
-6,-11,29:18.4
-6,-10,29:18.4
-8,-9,29:18.4
-5,-9,29:18.4
-4,-9,29:18.4
-3,-9,29:18.4
-8,-8,29:18.4
-4,-8,29:18.4
-2,-8,29:18.4
3,-7,29:18.4
-7,-6,29:18.4
-3,-6,29:17.15
2,-6,29:18.4
-6,-5,29:18.4
-5,-5,29:18.4
-4,-5,29:18.4
-3,-5,29:17.15
1,-5,29:18.4
7,-5,29:18.4
1,-4,29:18.4
2,-4,29:18.4
3,-4,29:18.4
4,-4,29:17.15
5,-4,29:18.4
7,-4,29:18.4
5,-3,29:18.4
6,-3,29:18.4
-7,-2,29:17.15
2,-2,29:18.4
3,-2,29:18.4
5,-2,29:17.15
6,-2,29:18.4
-1,-1,29:17.15
1,-1,29:18.4
4,-1,29:18.4
6,-1,29:18.4
8,-1,29:18.4
-5,0,29:17.15
-4,0,29:17.15
-2,0,29:17.15
-1,0,29:17.15
7,0,29:18.4
-6,1,29:17.15
5,1,29:18.4
1,2,29:18.4
-7,3,29:18.4
-1,3,29:17.15
1,3,29:18.4
5,3,29:18.4
-6,4,29:18.4
2,4,29:18.4
-5,-11,30:18.4
-4,-9,30:18.4
-2,-9,30:18.4
-7,-8,30:18.4
-6,-8,30:18.4
-5,-8,30:17.15
-3,-8,30:18.4
-2,-8,30:18.4
-8,-7,30:18.4
-7,-7,30:18.4
-6,-7,30:18.4
-4,-7,30:17.15
-8,-6,30:18.4
-7,-6,30:18.4
-3,-6,30:18.4
-7,-5,30:18.4
-6,-5,30:18.4
-5,-5,30:18.4
6,-5,30:18.4
-7,-4,30:18.4
3,-4,30:18.4
5,-4,30:18.4
-7,-3,30:17.15
-6,-3,30:18.4
1,-3,30:18.4
6,-3,30:18.4
7,-3,30:18.4
-10,-2,30:18.4
5,-2,30:18.4
-8,-1,30:17.15
-7,-1,30:18.4
-1,-1,30:17.15
0,-1,30:17.15
3,-1,30:18.4
4,-1,30:18.4
7,-1,30:18.4
-3,0,30:17.15
-1,0,30:17.15
4,0,30:18.4
5,0,30:18.4
3,1,30:18.4
4,1,30:18.4
6,1,30:18.4
3,3,30:18.4
0,4,30:17.15
-2,6,30:18.4
3,6,30:18.4
4,6,30:18.4
-6,-10,31:18.4
-4,-10,31:18.4
-8,-9,31:18.4
-5,-9,31:18.4
-5,-8,31:18.4
-2,-8,31:18.4
-8,-7,31:18.4
-7,-6,31:18.4
-3,-6,31:18.4
2,-6,31:18.4
-7,-5,31:18.4
-6,-5,31:18.4
-8,-4,31:18.4
-4,-4,31:18.4
3,-4,31:18.4
4,-4,31:18.4
5,-4,31:18.4
6,-4,31:18.4
-10,-3,31:18.4
-8,-3,31:18.4
-7,-3,31:17.15
1,-3,31:18.4
2,-3,31:18.4
5,-3,31:18.4
-6,-2,31:18.4
-5,-2,31:18.4
3,-2,31:18.4
4,-2,31:18.4
5,-2,31:18.4
-9,-1,31:18.4
-8,-1,31:18.4
-7,-1,31:18.4
-6,-1,31:18.4
-1,-1,31:17.15
1,-1,31:17.15
6,-1,31:18.4
7,-1,31:18.4
-7,0,31:18.4
-6,0,31:18.4
-1,0,31:17.15
3,0,31:18.4
4,0,31:18.4
-3,1,31:17.15
0,4,31:17.15
-3,5,31:18.4
5,5,31:18.4
-3,6,31:18.4
-2,6,31:18.4
1,7,31:18.4
3,7,31:18.4
-1,8,31:18.4
0,8,31:18.4
-6,-10,32:18.4
-3,-9,32:18.4
-6,-8,32:18.4
-5,-8,32:18.4
-3,-8,32:18.4
-7,-7,32:18.4
-6,-7,32:18.4
-4,-7,32:18.4
-6,-6,32:18.4
-9,-5,32:18.4
1,-5,32:18.4
4,-5,32:18.4
-10,-4,32:18.4
4,-4,32:18.4
-10,-3,32:18.4
-5,-3,32:18.4
0,-3,32:18.4
4,-3,32:18.4
-7,-2,32:18.4
1,-2,32:17.15
5,-2,32:18.4
-1,-1,32:17.15
2,-1,32:18.4
3,-1,32:18.4
-8,0,32:18.4
-1,0,32:17.15
2,0,32:17.15
3,0,32:18.4
-4,1,32:17.15
-1,4,32:17.15
-2,5,32:18.4
1,5,32:17.15
2,6,32:17.15
1,7,32:18.4
0,8,32:18.4
5,8,32:18.4
1,9,32:18.4
-5,-8,33:18.4
-5,-7,33:18.4
2,-6,33:18.4
-8,-5,33:18.4
-9,-4,33:18.4
2,-4,33:18.4
4,-4,33:18.4
-6,-3,33:18.4
0,-3,33:18.4
2,-3,33:17.15
5,-3,33:18.4
-2,-2,33:17.15
3,-2,33:18.4
-9,-1,33:18.4
-1,-1,33:17.15
1,-1,33:18.4
5,-1,33:18.4
-6,0,33:18.4
0,0,33:18.4
1,0,33:18.4
2,0,33:18.4
3,0,33:17.15
6,0,33:18.4
-6,1,33:18.4
-5,1,33:18.4
0,1,33:17.15
-4,2,33:17.15
-2,3,33:18.4
-2,4,33:18.4
2,4,33:18.4
3,4,33:18.4
-4,5,33:18.4
-3,5,33:18.4
-2,5,33:17.15
1,5,33:18.4
2,5,33:18.4
3,5,33:18.4
-4,6,33:18.4
-2,6,33:17.15
0,6,33:18.4
-4,7,33:18.4
-2,7,33:18.4
3,7,33:17.15
4,7,33:18.4
-1,8,33:18.4
6,8,33:18.4
3,9,33:18.4
2,10,33:18.4
4,10,33:18.4
2,-5,34:18.4
4,-5,34:18.4
2,-3,34:17.15
3,-3,34:18.4
5,-3,34:18.4
-3,-2,34:17.15
1,-2,34:18.4
4,-2,34:18.4
5,-2,34:18.4
-8,-1,34:18.4
-7,-1,34:18.4
-1,-1,34:17.15
2,-1,34:18.4
-8,0,34:18.4
-4,0,34:18.4
1,0,34:18.4
2,0,34:18.4
3,0,34:17.15
4,0,34:18.4
5,0,34:18.4
-8,2,34:18.4
-5,2,34:17.15
-4,2,34:18.4
1,2,34:17.15
-4,3,34:18.4
-3,3,34:17.15
4,3,34:18.4
-5,4,34:18.4
-3,4,34:18.4
-5,5,34:18.4
-2,5,34:18.4
-4,6,34:18.4
-3,6,34:18.4
-2,6,34:18.4
-1,6,34:18.4
4,6,34:18.4
-4,7,34:18.4
-4,8,34:18.4
-3,8,34:18.4
3,10,34:18.4
-3,-4,35:18.4
-3,-3,35:17.15
0,-3,35:18.4
3,-3,35:18.4
-1,-2,35:18.4
2,-2,35:18.4
-7,-1,35:18.4
-1,-1,35:17.15
-5,0,35:18.4
-3,0,35:18.4
-2,0,35:17.15
2,0,35:18.4
6,0,35:18.4
-6,1,35:17.15
-4,1,35:18.4
0,1,35:18.4
3,1,35:18.4
-1,2,35:18.4
0,2,35:18.4
1,2,35:17.15
3,2,35:18.4
-6,3,35:18.4
-3,3,35:18.4
1,3,35:18.4
2,3,35:18.4
-7,4,35:18.4
-3,4,35:17.15
-2,4,35:18.4
-1,4,35:18.4
0,4,35:18.4
1,5,35:18.4
-2,7,35:18.4
2,7,35:18.4
1,8,35:18.4
-4,-6,36:18.4
-3,-4,36:18.4
-1,-4,36:18.4
2,-4,36:18.4
3,-4,36:18.4
-4,-3,36:17.15
0,-3,36:18.4
2,-3,36:18.4
2,-2,36:18.4
3,-2,36:18.4
-7,-1,36:18.4
-3,-1,36:18.4
0,-1,36:17.15
3,-1,36:18.4
-2,0,36:17.15
1,0,36:18.4
-8,1,36:18.4
-6,1,36:17.15
-5,1,36:18.4
2,1,36:17.15
-4,2,36:18.4
-3,2,36:18.4
0,2,36:17.15
2,2,36:18.4
-7,3,36:18.4
-6,3,36:18.4
-4,3,36:18.4
-2,3,36:18.4
0,3,36:18.4
-7,4,36:18.4
-6,4,36:18.4
-5,4,36:18.4
-3,4,36:17.15
0,4,36:18.4
-5,5,36:18.4
-2,5,36:18.4
-2,6,36:18.4
-1,6,36:18.4
0,6,36:18.4
-3,7,36:18.4
-5,-7,37:18.4
0,-5,37:18.4
-6,-4,37:18.4
-4,-4,37:17.15
0,-3,37:18.4
2,-3,37:18.4
0,-2,37:18.4
1,-2,37:18.4
2,-2,37:18.4
0,-1,37:17.15
-6,0,37:18.4
-1,0,37:18.4
2,0,37:18.4
3,0,37:18.4
-5,1,37:18.4
-2,1,37:17.15
0,1,37:18.4
-7,2,37:18.4
-5,2,37:18.4
-1,2,37:18.4
3,2,37:18.4
-6,3,37:18.4
-1,3,37:18.4
0,3,37:17.15
2,3,37:18.4
-2,4,37:18.4
-1,4,37:18.4
0,4,37:18.4
-5,5,37:18.4
-3,7,37:18.4
-6,-6,38:18.4
-4,-6,38:18.4
-3,-6,38:18.4
-4,-4,38:17.15
-2,-4,38:18.4
-5,-3,38:18.4
-1,-3,38:18.4
2,-3,38:18.4
-6,-2,38:18.4
-4,-2,38:18.4
-1,-2,38:18.4
0,-2,38:17.15
3,-2,38:18.4
-3,-1,38:18.4
3,-1,38:18.4
-4,0,38:18.4
-1,0,38:18.4
2,0,38:18.4
-5,1,38:18.4
-3,1,38:18.4
-2,1,38:17.15
-1,1,38:18.4
2,1,38:18.4
-5,2,38:18.4
-3,2,38:18.4
-2,2,38:18.4
-1,2,38:18.4
-8,3,38:18.4
-4,3,38:18.4
3,3,38:18.4
-4,4,38:18.4
-2,4,38:18.4
-1,4,38:18.4
-1,5,38:18.4
-3,6,38:18.4
-7,-5,39:18.4
-6,-5,39:18.4
-4,-5,39:18.4
-2,-5,39:18.4
-4,-4,39:18.4
0,-4,39:18.4
-3,-2,39:18.4
-2,-2,39:18.4
-1,-2,39:18.4
3,-2,39:18.4
-4,-1,39:18.4
-2,-1,39:18.4
0,-1,39:18.4
-6,0,39:18.4
-3,1,39:18.4
-2,1,39:18.4
-1,1,39:18.4
-6,2,39:18.4
-4,2,39:18.4
0,2,39:18.4
-3,3,39:18.4
-1,3,39:18.4
-2,4,39:18.4
-1,4,39:18.4
-1,5,39:18.4
-6,-5,40:18.4
-6,-4,40:18.4
0,-4,40:18.4
2,-4,40:18.4
-5,-3,40:18.4
0,-3,40:18.4
-1,-2,40:18.4
0,-2,40:18.4
-2,-1,40:18.4
-2,1,40:18.4
0,3,40:18.4
-4,-4,41:18.4
-1,-2,41:18.4
0,-2,41:18.4
-3,1,41:18.4
