[META]
version=2.0
spawnOnBlockType=2
spawnSunlight=True
spawnDarkness=True
spawnWater=False
spawnLava=False
underFill=False
randomRotation=True
dig=True
tree=False
branch=False
needsFoundation=True
rarity=100
collisionPercentage=20
spawnElevationMin=0
spawnElevationMax=200
spawnInBiome=Custom
[DATA]
1,-4,-3:17.15
-1,-3,-3:17.15
3,-2,-3:17.15
0,-1,-3:17.15
1,0,-3:17.15
3,1,-3:17.15
-1,-3,-2:17.15
1,-3,-2:17.15
0,-2,-2:17.15
2,-2,-2:17.15
0,-1,-2:17.15
1,-1,-2:17.15
2,0,-2:17.15
3,1,-2:17.15
1,-3,-1:17.15
0,-2,-1:17.15
2,-2,-1:17.15
1,-1,-1:17.15
2,0,-1:17.15
1,-3,0:17.15
0,-2,0:17.15
1,-2,0:17.15
2,-2,0:17.15
1,-1,0:17.15
2,0,0:17.15
1,-2,1:17.15
2,-2,1:17.15
1,-1,1:17.15
1,-2,2:17.15
1,-1,2:17.15
1,-2,3:17.15
1,-1,3:17.15
1,-2,4:17.15
1,-1,4:17.15
1,-2,5:17.15
1,-2,6:17.15
-3,-3,7:18.12
-2,-3,7:18.12
3,-3,7:18.12
1,-2,7:17.15
-1,-5,8:18.12
-3,-4,8:18.12
-1,-4,8:18.12
1,-4,8:18.12
3,-4,8:18.12
-2,-3,8:18.12
0,-3,8:18.12
2,-3,8:17.15
3,-3,8:18.12
5,-3,8:18.12
-2,-2,8:18.12
0,-2,8:17.15
1,-2,8:17.15
-5,-4,9:18.4
0,-4,9:18.12
1,-4,9:18.12
3,-4,9:18.12
6,-4,9:18.4
-4,-3,9:18.4
-1,-3,9:17.15
0,-3,9:18.12
1,-3,9:18.12
3,-3,9:17.15
-1,-2,9:18.12
1,-2,9:17.15
3,-2,9:18.12
-2,-1,9:18.12
-1,-1,9:17.15
-1,0,9:18.12
0,2,9:18.12
-2,-6,10:18.4
4,-6,10:18.4
5,-6,10:18.4
5,-5,10:18.12
-3,-4,10:18.12
-2,-4,10:18.12
0,-4,10:18.12
1,-4,10:18.12
2,-4,10:18.12
3,-4,10:17.15
4,-4,10:18.12
-2,-3,10:17.15
-1,-3,10:18.12
0,-3,10:18.12
2,-3,10:18.12
3,-3,10:18.12
-5,-2,10:18.4
-1,-2,10:18.12
1,-2,10:17.15
3,-2,10:18.12
0,-1,10:18.12
2,-1,10:17.15
-2,0,10:17.15
0,0,10:18.12
2,0,10:18.12
-1,1,10:18.12
2,2,10:18.12
0,-5,11:18.12
6,-5,11:18.4
-5,-3,11:18.4
4,-3,11:18.12
-3,-2,11:18.12
0,-2,11:18.12
1,-2,11:17.15
2,-2,11:18.12
-1,-1,11:18.12
3,-1,11:17.15
-2,0,11:17.15
-1,0,11:18.12
-2,1,11:18.12
-1,2,11:18.12
-3,3,11:18.12
1,3,11:18.12
0,-5,12:18.4
-4,-4,12:18.4
-2,-4,12:18.4
-1,-4,12:18.4
0,-4,12:18.4
-2,-3,12:18.4
-1,-3,12:18.4
1,-3,12:17.15
2,-3,12:18.4
3,-3,12:18.4
-2,-2,12:18.4
1,-2,12:18.4
3,-2,12:18.4
4,-2,12:18.4
0,-1,12:17.15
2,-1,12:18.4
-1,0,12:18.4
1,0,12:18.4
3,0,12:17.15
-2,1,12:18.4
-1,1,12:17.15
1,1,12:18.4
3,1,12:18.4
-4,2,12:18.4
-3,2,12:18.4
2,2,12:18.4
-1,3,12:18.4
3,3,12:18.4
0,4,12:18.4
1,-5,13:18.4
2,-5,13:18.4
1,-4,13:18.4
2,-4,13:18.4
3,-4,13:18.4
-2,-3,13:18.4
-1,-3,13:18.4
0,-3,13:18.4
2,-3,13:17.15
3,-3,13:18.4
4,-3,13:18.4
1,-2,13:18.4
2,-2,13:18.4
4,-2,13:18.4
0,-1,13:17.15
1,-1,13:18.4
3,-1,13:18.4
4,-1,13:17.15
5,-1,13:18.4
-4,0,13:18.4
2,0,13:18.4
3,0,13:18.4
-4,1,13:18.4
0,1,13:18.4
1,1,13:18.4
3,1,13:17.15
4,1,13:18.4
5,1,13:18.4
-1,2,13:18.4
4,3,13:18.4
1,-6,14:18.4
4,-6,14:18.4
1,-5,14:18.4
-2,-4,14:18.4
-1,-4,14:18.4
2,-4,14:17.15
3,-4,14:18.4
-3,-3,14:18.4
1,-3,14:18.4
2,-3,14:18.4
-3,-2,14:18.4
-2,-2,14:18.4
2,-2,14:18.4
4,-2,14:18.4
5,-2,14:18.4
-2,-1,14:18.4
-1,-1,14:17.15
3,-1,14:18.4
5,-1,14:18.4
-3,0,14:18.4
-1,0,14:18.4
0,0,14:18.4
1,0,14:17.15
2,0,14:18.4
3,0,14:18.4
4,0,14:18.4
-3,1,14:18.4
-2,1,14:18.4
-1,1,14:18.4
0,1,14:18.4
1,1,14:18.4
5,1,14:18.4
-1,2,14:18.4
0,2,14:18.4
3,2,14:18.4
1,3,14:18.4
3,4,14:18.4
2,-6,15:18.4
4,-5,15:18.4
5,-5,15:18.4
0,-4,15:18.4
2,-4,15:17.15
3,-4,15:18.4
4,-4,15:18.4
0,-3,15:18.4
1,-3,15:18.4
2,-3,15:18.4
4,-3,15:18.4
0,-2,15:18.4
1,-2,15:18.4
2,-2,15:18.4
-4,-1,15:18.4
1,-1,15:18.4
-1,0,15:18.4
0,0,15:18.4
1,0,15:17.15
2,0,15:18.4
4,0,15:18.4
0,1,15:18.4
1,1,15:18.4
3,1,15:18.4
-1,2,15:18.4
0,2,15:18.4
1,2,15:18.4
0,3,15:18.4
1,3,15:18.4
2,3,15:18.4
3,3,15:18.4
2,-4,16:18.4
4,-4,16:18.4
-3,-2,16:18.4
1,-2,16:18.4
-2,-1,16:18.4
0,-1,16:18.4
0,0,16:18.4
4,0,16:18.4
1,1,16:18.4
2,1,16:18.4
4,1,16:18.4
-1,-2,17:18.4
0,-2,17:18.4
-1,0,17:18.4
0,0,17:18.4
2,0,17:18.4
-1,2,17:18.4
1,-4,18:18.4
2,-4,18:18.4
2,-3,18:18.4
