[META]
version=2.0
spawnOnBlockType=2
spawnSunlight=True
spawnDarkness=True
spawnWater=False
spawnLava=False
underFill=False
randomRotation=True
dig=True
tree=False
branch=False
needsFoundation=True
rarity=100
collisionPercentage=20
spawnElevationMin=0
spawnElevationMax=200
spawnInBiome=Custom
[DATA]
0,0,0:17.14
0,0,1:17.14
0,0,2:17.14
0,0,3:17.14
0,0,4:17.14
1,0,4:17.14
4,0,4:18.4
2,1,4:18.4
3,1,4:18.4
-1,-1,5:17.14
5,-1,5:18.4
1,0,5:17.14
-1,1,5:17.14
2,1,5:18.4
4,2,5:18.4
3,3,5:18.4
6,-3,6:18.12
-1,-1,6:17.14
1,-1,6:18.4
2,-1,6:17.14
3,0,6:17.14
-1,1,6:17.14
3,1,6:18.4
6,1,6:18.4
3,-6,7:18.12
3,-4,7:18.12
-2,-2,7:17.14
3,-2,7:17.14
0,-1,7:17.14
3,-1,7:18.4
5,-1,7:18.4
0,0,7:18.4
2,0,7:18.4
5,0,7:18.4
-1,1,7:17.14
3,1,7:17.14
1,2,7:18.4
3,2,7:18.4
6,2,7:18.4
3,3,7:18.4
2,4,7:18.4
5,-7,8:18.12
6,-6,8:18.12
-2,-5,8:18.12
-1,-5,8:18.12
4,-5,8:18.12
-5,-4,8:18.12
-1,-4,8:18.12
4,-4,8:18.12
-6,-3,8:18.4
-5,-3,8:18.12
-3,-3,8:17.14
4,-3,8:17.14
8,-3,8:18.12
-4,-2,8:18.12
4,-2,8:18.4
6,-2,8:18.12
0,-1,8:17.14
1,-1,8:18.4
4,-1,8:17.14
-2,0,8:18.12
5,0,8:18.12
-1,1,8:18.12
0,1,8:18.4
2,1,8:18.12
6,1,8:18.4
-2,2,8:17.14
0,2,8:17.14
1,2,8:18.12
2,2,8:18.4
6,2,8:18.4
-4,3,8:18.12
4,4,8:18.4
3,-7,9:18.12
6,-7,9:18.12
-1,-6,9:18.12
5,-6,9:18.12
-5,-5,9:18.12
2,-5,9:18.12
3,-5,9:18.12
5,-5,9:18.12
6,-5,9:18.12
-4,-4,9:17.14
-1,-4,9:18.12
5,-4,9:17.14
6,-4,9:18.12
7,-4,9:18.12
-6,-3,9:18.4
-5,-3,9:18.12
-3,-3,9:18.12
-2,-3,9:17.14
-1,-3,9:18.12
4,-3,9:18.12
5,-3,9:18.12
-7,-2,9:18.4
-4,-2,9:18.12
1,-2,9:18.12
3,-2,9:18.12
4,-2,9:18.12
8,-2,9:18.12
3,-1,9:18.4
4,-1,9:17.14
5,-1,9:18.12
0,0,9:17.14
1,0,9:18.12
6,0,9:18.12
-3,1,9:18.12
3,1,9:18.12
4,1,9:18.4
5,1,9:18.4
-3,2,9:17.14
0,2,9:18.12
6,2,9:18.12
-1,3,9:18.12
1,3,9:17.14
2,3,9:18.12
2,4,9:18.12
4,4,9:18.12
3,-8,10:18.4
5,-7,10:18.12
-1,-6,10:18.12
2,-6,10:18.12
-4,-5,10:18.12
1,-5,10:18.12
2,-5,10:18.12
3,-5,10:18.12
4,-5,10:17.14
6,-5,10:18.12
8,-5,10:18.12
-4,-4,10:17.14
-3,-4,10:18.12
-2,-4,10:18.12
0,-4,10:18.12
3,-4,10:18.12
5,-4,10:18.12
6,-4,10:17.14
8,-4,10:18.12
-7,-3,10:18.4
-6,-3,10:18.4
-5,-3,10:17.14
-2,-3,10:18.12
-1,-3,10:17.14
0,-3,10:18.12
1,-3,10:18.12
4,-3,10:18.12
6,-3,10:18.12
3,-2,10:17.14
4,-2,10:18.12
5,-2,10:17.14
6,-2,10:18.12
1,-1,10:18.12
2,-1,10:18.12
-2,0,10:18.12
-1,0,10:17.14
1,0,10:17.14
2,0,10:18.12
4,0,10:17.14
5,0,10:18.12
1,1,10:18.12
2,1,10:18.12
-3,2,10:17.14
-1,2,10:18.12
0,2,10:18.12
1,2,10:18.12
2,2,10:18.12
3,2,10:18.12
4,2,10:18.12
-3,3,10:18.12
1,3,10:17.14
2,3,10:18.12
5,3,10:18.12
-6,4,10:18.12
-2,4,10:18.12
-5,5,10:18.12
-1,-7,11:18.4
1,-7,11:18.12
-4,-6,11:18.4
-3,-6,11:18.4
-2,-6,11:18.4
-1,-6,11:18.12
0,-6,11:18.12
6,-6,11:18.12
-3,-5,11:17.14
-1,-5,11:18.12
2,-5,11:18.12
3,-5,11:17.14
-4,-4,11:18.12
-1,-4,11:17.14
1,-4,11:18.12
3,-4,11:18.12
5,-4,11:18.12
6,-4,11:18.12
-7,-3,11:18.4
-5,-3,11:17.14
-4,-3,11:18.12
-3,-3,11:18.12
-1,-3,11:18.12
3,-3,11:18.12
4,-3,11:18.12
5,-3,11:18.12
-6,-2,11:18.12
-2,-2,11:18.12
0,-2,11:18.12
2,-2,11:18.12
4,-2,11:18.12
5,-2,11:18.12
6,-2,11:17.14
9,-2,11:18.12
-1,-1,11:18.12
0,-1,11:18.12
3,-1,11:18.12
5,-1,11:18.12
6,-1,11:18.12
7,-1,11:18.12
9,-1,11:18.12
-5,0,11:18.12
-1,0,11:18.12
1,0,11:17.14
4,0,11:17.14
5,0,11:18.12
-4,1,11:17.14
-2,1,11:18.12
-1,1,11:17.14
3,1,11:18.12
-5,2,11:18.12
-4,2,11:18.12
-2,2,11:18.12
0,2,11:18.12
1,2,11:18.12
2,2,11:17.14
3,2,11:18.12
4,2,11:18.12
6,2,11:18.12
-5,3,11:18.12
-4,3,11:18.12
-3,3,11:17.14
-2,3,11:18.12
1,3,11:18.12
4,3,11:18.12
-4,4,11:18.12
-2,4,11:18.12
0,4,11:17.14
4,4,11:18.12
-3,6,11:18.12
0,-7,12:18.12
-3,-5,12:18.12
5,-5,12:18.12
-4,-4,12:18.12
1,-4,12:18.12
5,-4,12:18.12
2,-3,12:18.12
6,-3,12:18.12
-3,-2,12:18.12
6,-2,12:18.12
-1,-1,12:18.12
6,-1,12:18.12
-6,0,12:18.12
-5,0,12:18.12
-2,0,12:18.12
7,0,12:18.12
-3,1,12:18.12
-1,1,12:18.12
0,1,12:18.12
2,1,12:18.12
3,1,12:18.12
-3,2,12:18.12
5,2,12:18.12
-6,3,12:18.12
-3,3,12:18.12
-1,3,12:18.12
0,3,12:18.12
4,3,12:18.12
5,3,12:18.12
-2,4,12:18.12
-1,4,12:18.12
0,4,12:18.12
-3,5,12:18.12
-3,-5,13:18.4
-1,-5,13:18.12
-5,-4,13:18.12
7,-4,13:18.12
8,-4,13:18.12
-6,-3,13:18.4
-3,-3,13:18.12
5,-3,13:18.12
-3,-2,13:18.12
8,-2,13:18.12
4,-1,13:18.12
2,0,13:18.12
4,0,13:18.12
-3,1,13:18.12
-1,1,13:18.12
0,1,13:18.12
-4,2,13:18.12
4,2,13:18.12
6,2,13:18.12
2,3,13:18.12
-5,4,13:18.12
-3,4,13:18.12
-2,4,13:18.12
-2,5,13:18.12
-1,5,13:18.12
3,-6,14:18.12
-1,-5,14:18.12
4,-5,14:18.12
-6,-4,14:18.4
-5,-4,14:18.12
-1,-4,14:18.12
-4,-3,14:18.12
5,-2,14:18.12
7,-1,14:18.12
4,0,14:18.12
-1,2,14:18.12
2,2,14:18.12
3,2,14:18.12
-4,3,14:18.12
-3,3,14:18.12
-2,3,14:18.12
1,3,14:18.12
-3,4,14:18.12
