[META]
version=2.0
spawnOnBlockType=2
spawnSunlight=True
spawnDarkness=True
spawnWater=False
spawnLava=False
underFill=False
randomRotation=True
dig=True
tree=False
branch=False
needsFoundation=True
rarity=100
collisionPercentage=20
spawnElevationMin=0
spawnElevationMax=200
spawnInBiome=Custom
[DATA]
-1,0,0:17.14
-1,0,1:17.14
-1,0,2:17.14
-1,0,3:17.14
0,0,3:18.4
-1,1,3:18.4
0,1,3:18.4
0,2,3:18.4
-2,-2,4:18.4
0,-1,4:18.4
-4,0,4:18.4
-3,0,4:18.4
-2,0,4:18.4
-1,0,4:17.14
0,0,4:18.4
0,1,4:18.4
1,1,4:18.4
0,-4,5:18.4
-4,-2,5:18.4
0,-2,5:18.4
1,-2,5:18.4
-3,-1,5:18.4
-1,-1,5:17.14
0,0,5:18.4
3,0,5:18.4
-3,1,5:18.4
-2,1,5:18.4
-1,1,5:17.14
0,2,5:18.4
1,2,5:18.4
2,2,5:18.4
-1,4,5:18.4
-1,-4,6:18.4
0,-4,6:18.4
1,-4,6:18.4
-2,-3,6:18.4
-1,-3,6:18.4
-2,-2,6:18.4
-1,-2,6:18.4
0,-2,6:17.14
2,-2,6:18.4
-1,-1,6:18.4
0,-1,6:18.4
1,-1,6:18.4
3,-1,6:18.4
-4,0,6:18.4
-2,0,6:17.14
0,0,6:18.4
1,0,6:18.4
-5,1,6:18.4
-2,1,6:18.4
0,1,6:17.14
-2,2,6:18.4
-1,2,6:18.4
2,2,6:18.4
-2,3,6:18.4
0,3,6:18.4
-2,-3,7:18.4
0,-3,7:18.4
-2,-2,7:18.4
-1,-2,7:18.4
0,-2,7:17.14
1,-2,7:18.4
2,-2,7:18.4
-5,-1,7:18.4
-2,-1,7:18.4
-4,0,7:18.4
-3,0,7:17.14
0,0,7:18.4
2,0,7:18.4
4,0,7:18.4
-2,1,7:18.4
-1,1,7:18.4
0,1,7:18.4
1,1,7:17.14
3,1,7:18.4
-1,2,7:17.14
0,2,7:18.4
1,2,7:18.4
2,2,7:18.4
3,2,7:18.4
4,2,7:18.4
-1,3,7:18.4
3,3,7:18.4
-1,4,7:18.4
1,4,7:18.4
0,-5,8:18.4
-4,-2,8:18.4
-4,-1,8:18.4
-1,-1,8:18.4
0,-1,8:18.4
1,-1,8:18.4
0,0,8:18.4
2,0,8:18.4
-2,1,8:18.4
-1,1,8:18.4
0,1,8:18.4
1,1,8:18.4
3,1,8:18.4
0,2,8:18.4
1,2,8:18.4
0,3,8:18.4
0,-1,9:18.4
1,-1,9:18.4
2,-1,9:18.4
-2,0,9:18.4
3,0,9:18.4
2,1,9:18.4
1,-2,10:18.4
1,0,10:18.4
0,1,10:18.4
1,2,10:18.4
