[META]
version=2.0
spawnOnBlockType=2
spawnSunlight=True
spawnDarkness=True
spawnWater=False
spawnLava=False
underFill=False
randomRotation=True
dig=True
tree=False
branch=False
needsFoundation=True
rarity=100
collisionPercentage=20
spawnElevationMin=0
spawnElevationMax=200
spawnInBiome=Custom
[DATA]
-1,0,0:17.13
-1,0,1:17.13
1,-3,2:18.12
-2,0,2:17.13
0,0,2:17.13
2,1,2:18.12
-2,2,2:18.12
-1,-4,3:18.12
-2,-3,3:18.12
0,-2,3:18.12
-2,-1,3:17.13
1,-1,3:17.13
-2,0,3:18.12
1,0,3:18.12
-2,1,3:18.12
1,1,3:17.13
-1,2,3:18.12
-3,3,3:18.12
-2,-3,4:18.12
-1,-3,4:18.12
-4,-2,4:18.12
-4,-1,4:18.12
0,-1,4:18.12
2,-1,4:18.12
-2,1,4:18.12
0,1,4:18.12
-3,2,4:18.12
0,2,4:18.12
1,2,4:17.13
-1,3,4:18.12
2,3,4:18.12
-1,4,4:18.12
-3,-3,5:18.12
-1,-2,5:18.12
0,-2,5:18.12
1,-2,5:18.12
-4,-1,5:18.12
-4,0,5:18.12
-2,0,5:18.12
0,0,5:18.12
1,0,5:18.12
-1,1,5:18.12
0,1,5:18.12
4,1,5:18.12
-1,2,5:18.12
0,2,5:18.12
1,3,5:18.12
0,-3,6:18.12
-2,-2,6:18.12
-1,-2,6:18.12
-3,-1,6:18.12
-1,-1,6:18.12
0,-1,6:18.12
2,1,6:18.12
-2,2,6:18.12
-1,2,6:18.12
0,2,6:18.12
0,3,6:18.12
-1,2,4:85.0
2,1,4:85.0
-2,-1,4:85.0
0,-2,4:85.0
-2,2,3:85.0
0,1,3:85.0
-3,1,3:85.0
0,-1,3:85.0
-2,1,2:85.0
