[META]
version=2.0
spawnOnBlockType=2
spawnSunlight=True
spawnDarkness=True
spawnWater=False
spawnLava=False
underFill=False
randomRotation=True
dig=True
tree=False
branch=False
needsFoundation=True
rarity=100
collisionPercentage=20
spawnElevationMin=0
spawnElevationMax=200
spawnInBiome=Custom
[DATA]
0,-5,-3:17.12
2,-5,-3:17.12
-1,-3,-3:17.12
1,-3,-3:17.12
4,-2,-3:17.12
0,-1,-3:17.12
2,-1,-3:17.12
1,-5,-2:17.12
-1,-3,-2:17.12
1,-3,-2:17.12
3,-2,-2:17.12
4,-2,-2:17.12
0,-1,-2:17.12
1,-4,-1:17.12
1,-3,-1:17.12
2,-3,-1:17.12
0,-2,-1:17.12
3,-2,-1:17.12
1,-4,0:17.12
1,-3,0:17.12
2,-3,0:17.12
0,-2,0:17.12
1,-2,0:17.12
3,-2,0:17.12
2,-3,1:17.12
1,-2,1:17.12
2,-3,2:17.12
1,-2,2:17.12
2,-3,3:17.12
1,-2,3:17.12
-3,-5,4:18.12
2,-3,4:17.12
1,-2,4:17.12
2,-2,4:18.12
-2,-7,5:18.12
3,-5,5:18.12
4,-5,5:18.12
-2,-4,5:18.12
2,-4,5:17.12
1,-3,5:18.12
2,-3,5:17.12
1,-2,5:17.12
3,-2,5:17.12
0,-9,6:18.4
3,-9,6:18.4
5,-7,6:18.12
1,-5,6:17.12
5,-5,6:18.12
-2,-3,6:18.12
-1,-3,6:18.12
2,-3,6:17.12
0,-2,6:17.12
4,-2,6:17.12
1,-1,6:18.12
-5,3,6:18.4
-5,4,6:18.4
0,-9,7:18.4
8,-7,7:18.12
-3,-6,7:18.12
1,-6,7:18.12
4,-6,7:18.12
9,-6,7:18.12
1,-5,7:18.12
1,-4,7:18.12
2,-3,7:17.12
5,-3,7:17.12
0,-2,7:17.12
2,-2,7:17.12
11,-2,7:18.4
4,-1,7:17.12
-6,2,7:18.12
-6,3,7:18.4
1,-9,8:18.12
8,-8,8:18.12
0,-5,8:18.12
8,-5,8:18.12
-2,-4,8:18.12
2,-3,8:17.12
6,-3,8:17.12
10,-3,8:18.12
13,-3,8:18.4
-1,-2,8:17.12
2,-1,8:17.12
4,-1,8:17.12
9,-1,8:18.12
-10,2,8:18.4
-7,3,8:18.4
2,3,8:18.12
-6,4,8:18.4
3,4,8:18.12
1,-12,9:18.4
0,-9,9:18.12
1,-9,9:18.12
0,-7,9:18.12
1,-5,9:18.4
2,-5,9:18.4
7,-5,9:18.12
10,-5,9:18.12
1,-4,9:17.12
7,-4,9:17.12
-6,-3,9:18.12
-3,-3,9:17.12
1,-3,9:18.4
2,-3,9:17.12
3,-3,9:17.12
7,-3,9:18.12
9,-3,9:18.12
-2,-2,9:17.12
-10,-1,9:18.4
-9,-1,9:18.4
-3,-1,9:17.12
5,-1,9:17.12
2,0,9:17.12
3,0,9:18.12
-6,1,9:18.12
-7,2,9:17.12
-4,3,9:18.4
1,3,9:18.12
4,3,9:18.12
-8,4,9:18.4
-7,4,9:18.4
-5,5,9:18.4
5,5,9:18.4
-7,6,9:18.4
2,6,9:18.4
-1,-10,10:18.4
-1,-9,10:18.12
1,-9,10:18.12
2,-9,10:18.12
-2,-8,10:18.12
5,-8,10:18.12
7,-8,10:18.12
1,-7,10:18.12
9,-7,10:18.12
-2,-6,10:18.12
12,-6,10:18.4
-4,-5,10:18.12
1,-5,10:17.12
7,-5,10:17.12
-9,-4,10:18.4
-8,-4,10:18.4
-7,-4,10:18.4
-3,-4,10:17.12
1,-4,10:18.4
4,-4,10:17.12
5,-4,10:18.12
-6,-3,10:18.12
2,-3,10:17.12
8,-3,10:17.12
9,-3,10:17.12
-4,-1,10:17.12
5,-1,10:17.12
10,-1,10:18.12
-5,0,10:17.12
1,0,10:17.12
3,0,10:18.12
7,0,10:18.12
10,0,10:18.12
-7,1,10:18.4
-6,1,10:17.12
3,1,10:17.12
-6,2,10:18.12
2,2,10:18.12
3,2,10:17.12
5,2,10:18.12
6,2,10:18.12
4,3,10:18.12
-2,4,10:18.12
-1,-11,11:18.4
2,-11,11:18.4
6,-10,11:18.4
8,-10,11:18.4
9,-10,11:18.4
-3,-9,11:18.12
-1,-9,11:18.12
5,-9,11:18.12
-4,-8,11:18.4
8,-8,11:18.12
-7,-7,11:18.4
-6,-7,11:18.4
-5,-7,11:18.4
-2,-7,11:18.12
0,-7,11:17.12
3,-7,11:18.12
5,-7,11:18.12
-3,-6,11:18.12
-2,-6,11:18.12
1,-6,11:17.12
7,-6,11:18.12
8,-6,11:17.12
11,-6,11:18.4
-4,-5,11:17.12
4,-5,11:17.12
-7,-4,11:18.4
-5,-4,11:18.12
-7,-3,11:18.4
2,-3,11:17.12
8,-3,11:18.12
9,-3,11:18.12
10,-3,11:17.12
12,-3,11:18.4
6,-2,11:17.12
8,-2,11:18.12
9,-2,11:18.12
11,-2,11:18.4
13,-2,11:18.4
5,-1,11:18.12
7,-1,11:18.12
8,-1,11:18.12
9,-1,11:18.12
10,-1,11:18.12
-5,0,11:18.12
4,0,11:18.12
6,0,11:17.12
9,0,11:18.12
-8,1,11:18.4
0,1,11:17.12
10,1,11:18.12
12,1,11:18.4
-8,2,11:18.4
0,2,11:17.12
3,2,11:18.12
4,2,11:17.12
-10,3,11:18.4
-5,3,11:18.4
-2,3,11:18.12
-1,3,11:18.12
2,3,11:17.12
8,3,11:18.12
-1,4,11:18.12
5,5,11:18.4
2,6,11:18.4
6,6,11:18.4
2,7,11:18.4
0,-12,12:18.4
1,-12,12:18.4
1,-11,12:18.4
4,-11,12:18.4
4,-10,12:18.4
5,-10,12:18.4
6,-10,12:18.4
7,-10,12:18.4
-2,-9,12:18.12
-1,-9,12:18.12
1,-9,12:17.12
5,-9,12:18.12
-5,-8,12:18.4
0,-8,12:17.12
2,-8,12:18.12
4,-8,12:18.12
5,-8,12:18.12
-7,-7,12:18.4
0,-7,12:18.12
1,-7,12:18.12
4,-7,12:18.12
6,-7,12:18.12
-4,-6,12:18.12
-3,-6,12:17.12
4,-6,12:17.12
7,-6,12:18.12
10,-6,12:18.12
-4,-5,12:18.12
3,-5,12:18.12
-5,-4,12:17.12
-6,-3,12:18.12
3,-3,12:17.12
7,-3,12:17.12
-4,-2,12:18.12
1,-2,12:17.12
8,-2,12:18.12
-3,-1,12:18.12
-2,-1,12:18.12
6,-1,12:18.12
-5,0,12:18.12
12,0,12:18.4
-4,1,12:18.12
-2,1,12:18.12
-6,2,12:18.12
-1,2,12:17.12
2,2,12:18.12
4,2,12:17.12
10,2,12:18.4
-2,3,12:18.12
-1,3,12:18.12
2,3,12:17.12
5,3,12:18.12
7,3,12:18.12
3,6,12:18.4
7,6,12:18.4
0,7,12:18.4
-4,-12,13:18.4
-2,-12,13:18.4
-1,-12,13:18.4
-2,-11,13:18.4
-1,-11,13:18.4
1,-11,13:18.4
4,-11,13:18.4
8,-11,13:18.4
-1,-10,13:18.4
1,-10,13:18.4
-5,-9,13:18.4
-4,-9,13:18.4
-1,-9,13:17.12
1,-9,13:18.12
3,-9,13:18.12
-4,-8,13:18.4
-3,-8,13:18.12
-1,-8,13:18.12
5,-8,13:18.12
-3,-7,13:18.12
1,-7,13:18.12
2,-7,13:18.12
4,-7,13:18.12
5,-7,13:17.12
6,-7,13:18.12
10,-7,13:18.4
-4,-6,13:18.12
-3,-6,13:17.12
6,-6,13:18.12
9,-6,13:18.4
-2,-5,13:18.12
-1,-5,13:18.12
0,-5,13:18.12
11,-5,13:18.4
2,-4,13:18.12
7,-4,13:17.12
10,-4,13:18.4
11,-4,13:18.4
-4,-3,13:18.12
3,-3,13:17.12
7,-3,13:18.12
11,-3,13:18.4
1,-2,13:17.12
8,-2,13:17.12
-8,-1,13:18.4
-3,-1,13:18.12
-1,-1,13:18.12
5,-1,13:18.12
9,-1,13:18.12
5,0,13:18.12
9,0,13:18.12
-1,1,13:18.12
9,1,13:18.12
10,1,13:18.4
-8,2,13:18.4
-1,2,13:18.12
5,2,13:18.12
-1,3,13:17.12
2,3,13:18.12
5,3,13:17.12
-2,5,13:18.4
0,5,13:18.4
1,6,13:18.4
5,6,13:18.4
0,-12,14:18.4
3,-11,14:18.4
-4,-9,14:18.4
-2,-9,14:18.12
0,-9,14:18.12
2,-9,14:18.12
-5,-8,14:18.4
-3,-8,14:18.12
0,-8,14:18.12
5,-8,14:17.12
-5,-7,14:18.4
-4,-7,14:17.12
-3,-7,14:18.12
-1,-7,14:18.12
0,-7,14:18.12
8,-7,14:18.12
10,-7,14:18.4
-8,-6,14:18.4
5,-6,14:18.12
8,-6,14:18.12
6,-5,14:17.12
-5,-4,14:18.4
-4,-4,14:18.4
-1,-4,14:18.12
0,-4,14:18.12
3,-4,14:18.12
5,-4,14:18.12
8,-4,14:17.12
-3,-3,14:18.12
0,-3,14:17.12
11,-3,14:18.4
3,-2,14:17.12
12,-2,14:18.4
-5,-1,14:18.4
-1,-1,14:18.12
1,-1,14:18.12
7,-1,14:18.12
8,-1,14:17.12
10,-1,14:18.4
-5,0,14:18.4
-2,0,14:18.12
7,0,14:18.12
9,0,14:18.12
10,0,14:18.4
-2,1,14:18.12
-1,1,14:18.12
4,2,14:18.12
-2,3,14:17.12
2,3,14:18.12
3,3,14:18.12
5,3,14:18.12
1,4,14:18.12
5,6,14:18.4
-1,7,14:18.4
0,7,14:18.4
-3,-12,15:18.4
1,-12,15:18.4
4,-12,15:18.4
-4,-11,15:18.4
-1,-11,15:18.4
-3,-10,15:18.4
-4,-9,15:18.4
-4,-8,15:18.4
0,-8,15:18.4
0,-7,15:18.12
2,-7,15:18.12
5,-7,15:18.12
-8,-6,15:18.4
-7,-6,15:18.4
7,-6,15:18.4
-8,-5,15:18.4
-5,-5,15:18.4
-2,-5,15:18.12
8,-5,15:18.4
9,-5,15:18.4
6,-4,15:18.12
9,-4,15:18.4
0,-3,15:17.12
-2,-2,15:18.12
4,-2,15:17.12
-4,-1,15:18.4
1,-1,15:18.12
9,-1,15:17.12
5,0,15:18.12
6,0,15:18.12
11,0,15:18.4
3,1,15:18.12
5,1,15:18.12
7,1,15:18.4
-3,3,15:18.4
5,3,15:18.4
4,4,15:18.4
3,5,15:18.4
1,-11,16:18.4
-4,-10,16:18.4
5,-10,16:18.4
-4,-9,16:18.4
-3,-9,16:18.4
-1,-9,16:18.4
3,-9,16:18.4
6,-9,16:18.4
-2,-8,16:18.4
2,-8,16:18.4
5,-8,16:18.4
7,-8,16:18.4
5,-7,16:18.4
-1,-5,16:18.4
1,-5,16:18.4
10,-5,16:18.4
-5,-4,16:18.4
0,-4,16:17.12
1,-4,16:18.4
-4,-3,16:18.4
3,-3,16:18.4
-5,-2,16:18.4
-1,-2,16:17.12
1,-2,16:18.4
-5,-1,16:18.4
-2,-1,16:18.4
4,-1,16:17.12
8,-1,16:18.4
10,-1,16:18.4
-2,0,16:18.4
5,0,16:18.4
-5,1,16:18.4
-4,1,16:18.4
3,1,16:18.4
7,1,16:18.4
-3,2,16:18.4
-2,2,16:18.4
2,2,16:18.4
5,2,16:18.4
-4,3,16:18.4
2,3,16:18.4
5,3,16:18.4
6,3,16:18.4
2,4,16:18.4
5,4,16:18.4
4,5,16:18.4
5,5,16:18.4
4,6,16:18.4
-4,-10,17:18.4
-2,-9,17:18.4
-1,-8,17:18.4
0,-7,17:18.4
1,-7,17:18.4
-4,-6,17:18.4
-1,-6,17:18.4
-2,-5,17:18.4
-1,-5,17:18.4
3,-5,17:18.4
4,-5,17:18.4
0,-4,17:17.12
2,-4,17:18.4
5,-4,17:18.4
0,-3,17:18.4
1,-3,17:18.4
11,-3,17:18.4
-2,-2,17:18.4
-1,-2,17:18.4
2,-2,17:18.4
4,-2,17:18.4
-2,-1,17:17.12
-1,-1,17:18.4
4,-1,17:17.12
-4,0,17:18.4
-2,0,17:18.4
1,0,17:18.4
2,1,17:18.4
-2,2,17:18.4
6,2,17:18.4
-2,3,17:18.4
5,3,17:18.4
5,4,17:18.4
-3,5,17:18.4
0,-8,18:18.4
-3,-7,18:18.4
5,-6,18:18.4
-2,-5,18:18.4
3,-5,18:18.4
-4,-4,18:18.4
-3,-4,18:18.4
-2,-4,18:18.4
-1,-3,18:18.4
3,-3,18:18.4
1,-2,18:18.4
6,-2,18:18.4
1,-1,18:18.4
3,-1,18:17.12
5,-1,18:18.4
-6,0,18:18.4
5,0,18:17.12
9,0,18:18.4
12,0,18:18.4
0,1,18:18.4
4,1,18:18.4
-1,2,18:18.4
8,2,18:18.4
-2,4,18:18.4
-2,-5,19:18.4
-3,-4,19:18.4
-1,-4,19:18.4
4,-4,19:18.4
0,-3,19:18.4
6,-3,19:18.4
7,-3,19:18.4
0,-2,19:18.4
1,-2,19:18.4
3,-2,19:18.4
-5,-1,19:18.4
-4,-1,19:18.4
-2,-1,19:18.4
0,-1,19:18.4
1,-1,19:18.4
3,-1,19:17.12
8,-1,19:18.4
9,-1,19:18.4
-2,0,19:18.4
-1,0,19:18.4
5,0,19:18.4
9,0,19:18.4
5,1,19:17.12
4,2,19:18.4
1,3,19:18.4
5,3,19:18.4
4,5,19:18.4
3,-6,20:18.4
3,-5,20:18.4
-1,-4,20:18.4
-3,-2,20:18.4
3,-2,20:17.12
4,-2,20:18.4
7,-2,20:18.4
-3,-1,20:18.4
1,1,20:18.4
3,1,20:18.4
5,1,20:18.4
6,1,20:18.4
4,4,20:18.4
-2,-3,21:18.4
6,-3,21:18.4
3,-2,21:18.4
-1,-1,21:18.4
7,0,21:18.4
0,1,21:18.4
7,1,21:18.4
3,0,22:18.4
4,1,22:18.4
6,4,22:18.4
1,-2,23:18.4
4,-2,23:18.4
2,-1,23:18.4
4,-1,23:18.4
3,-4,24:18.4
2,-1,24:18.4
