[META]
version=2.0
spawnOnBlockType=2
spawnSunlight=True
spawnDarkness=True
spawnWater=False
spawnLava=False
underFill=False
randomRotation=True
dig=True
tree=False
branch=False
needsFoundation=True
rarity=100
collisionPercentage=20
spawnElevationMin=0
spawnElevationMax=200
spawnInBiome=Custom
[DATA]
1,-2,0:17.12
1,-2,1:17.12
1,-2,2:17.12
3,-5,3:18.4
1,-4,3:18.4
-2,-2,3:18.4
1,-2,3:17.12
-3,-1,3:18.4
-1,-1,3:18.4
2,-5,4:18.4
0,-4,4:18.4
2,-3,4:17.12
-1,-2,4:18.4
0,-2,4:17.12
-6,-1,4:18.4
-5,-1,4:18.4
-3,-1,4:18.4
2,-1,4:17.12
-5,0,4:18.4
3,0,4:18.4
-3,1,4:18.4
-3,2,4:18.4
-2,-5,5:18.4
2,-5,5:18.4
-6,-3,5:18.4
-2,-3,5:17.12
-1,-3,5:17.12
2,-3,5:17.12
3,-3,5:18.4
-4,-1,5:18.4
-1,-1,5:17.12
2,-1,5:17.12
2,0,5:18.4
-2,4,5:18.4
-1,-7,6:18.4
3,-7,6:18.4
-3,-4,6:17.12
1,-4,6:17.12
3,-3,6:17.12
-4,-2,6:18.4
-2,-2,6:18.4
-5,-1,6:18.4
-2,-1,6:18.4
5,-1,6:18.4
-4,0,6:18.4
-2,0,6:17.12
1,0,6:17.12
2,0,6:18.4
-2,1,6:18.4
4,-7,7:18.4
4,-6,7:18.4
-5,-5,7:18.4
-1,-5,7:18.4
0,-5,7:17.12
-3,-4,7:18.4
-1,-4,7:18.4
1,-4,7:17.12
4,-4,7:18.4
5,-4,7:18.4
6,-4,7:18.4
0,-3,7:18.4
1,-3,7:18.4
3,-3,7:17.12
4,-3,7:18.4
5,-3,7:18.4
6,-3,7:18.4
-2,-2,7:18.4
1,-2,7:18.4
2,-2,7:18.4
3,-2,7:18.4
5,-2,7:18.4
7,-2,7:18.4
-4,-1,7:18.4
-3,-1,7:17.12
-2,-1,7:18.4
-1,-1,7:18.4
1,-1,7:18.4
3,-1,7:18.4
5,-1,7:18.4
7,-1,7:18.4
-2,0,7:17.12
0,0,7:18.4
1,0,7:18.4
-6,1,7:18.4
-4,1,7:18.4
1,1,7:17.12
-5,2,7:18.4
-4,2,7:18.4
-4,3,7:18.4
-2,4,7:18.4
2,-7,8:18.4
-1,-6,8:17.12
1,-6,8:18.4
-2,-5,8:18.4
2,-5,8:17.12
-3,-4,8:18.4
5,-4,8:18.4
-1,-3,8:18.4
1,-3,8:18.4
1,-2,8:18.4
4,-2,8:17.12
-3,-1,8:18.4
-1,0,8:18.4
-3,1,8:17.12
3,1,8:18.4
2,-5,9:17.12
3,-5,9:18.4
-1,-3,9:18.4
0,-3,9:18.4
4,-3,9:18.4
-3,-2,9:18.4
3,-2,9:18.4
4,-2,9:17.12
-2,-1,9:18.4
0,-1,9:18.4
1,-1,9:18.4
2,-1,9:18.4
0,0,9:18.4
1,0,9:18.4
-2,1,9:18.4
0,-5,10:18.4
3,-5,10:18.4
4,-5,10:18.4
1,-4,10:18.4
-1,-2,10:18.4
0,-2,10:18.4
0,-1,10:18.4
-5,0,10:18.4
-1,0,10:18.4
-2,1,10:18.4
1,-5,11:18.4
-1,-4,11:18.4
2,-4,11:18.4
2,-2,11:18.4
