[META]
version=2.0
spawnOnBlockType=2
spawnSunlight=True
spawnDarkness=True
spawnWater=False
spawnLava=False
underFill=False
randomRotation=True
dig=True
tree=False
branch=False
needsFoundation=True
rarity=100
collisionPercentage=20
spawnElevationMin=0
spawnElevationMax=200
spawnInBiome=Custom
[DATA]
5,-6,-3:17.14
1,-4,-3:17.14
3,-4,-3:17.14
4,-3,-3:17.14
3,-2,-3:17.14
1,-1,-3:17.14
4,-5,-2:17.14
5,-5,-2:17.14
1,-4,-2:17.14
3,-4,-2:17.14
3,-3,-2:17.14
2,-2,-2:17.14
4,-5,-1:17.14
1,-4,-1:17.14
2,-4,-1:17.14
3,-4,-1:17.14
3,-3,-1:17.14
2,-2,-1:17.14
4,-5,0:17.14
1,-4,0:17.14
2,-4,0:17.14
3,-4,0:17.14
3,-3,0:17.14
2,-2,0:17.14
2,-4,1:17.14
3,-4,1:17.14
3,-3,1:17.14
2,-4,2:17.14
3,-4,2:17.14
3,-3,2:17.14
3,-4,3:17.14
3,-3,3:17.14
3,-4,4:17.14
3,-3,4:17.14
3,-4,5:17.14
3,-3,5:17.14
3,-4,6:17.14
3,-4,7:17.14
3,-4,8:17.14
4,-4,9:17.14
4,-4,10:17.14
4,-4,11:17.14
5,-5,12:17.14
11,-6,13:18.4
5,-5,13:17.14
6,-5,13:17.14
10,-5,13:18.4
11,-7,14:18.4
5,-5,14:17.14
7,-4,14:17.14
10,-3,14:18.4
13,-2,14:18.4
8,-7,15:18.4
6,-6,15:17.14
13,-5,15:18.4
8,-4,15:17.14
9,-4,15:17.14
10,-3,15:18.4
12,-3,15:18.4
12,-2,15:18.4
11,0,15:18.4
9,-7,16:18.4
11,-7,16:18.4
6,-6,16:17.14
10,-6,16:18.4
11,-6,16:18.4
9,-5,16:18.4
10,-5,16:17.14
11,-5,16:18.4
12,-5,16:18.4
13,-5,16:18.4
11,-4,16:18.4
10,-3,16:17.14
11,-3,16:17.14
15,-3,16:18.4
10,-2,16:18.4
12,0,16:18.4
9,-8,17:18.4
11,-8,17:18.4
7,-7,17:17.14
5,-6,17:17.14
11,-6,17:18.4
6,-5,17:17.14
9,-5,17:18.4
10,-5,17:18.4
12,-5,17:18.4
13,-5,17:18.4
8,-4,17:18.4
12,-4,17:18.4
10,-3,17:18.4
10,-2,17:18.4
12,-2,17:17.14
14,-2,17:18.4
15,-2,17:18.4
9,-1,17:18.4
10,-1,17:18.4
14,0,17:18.4
6,-10,18:18.4
8,-10,18:18.4
6,-8,18:18.4
9,-8,18:18.4
5,-7,18:18.4
7,-7,18:17.14
9,-7,18:18.4
12,-7,18:18.4
-4,-5,18:18.4
-3,-5,18:18.4
-1,-5,18:18.4
1,-5,18:18.4
4,-5,18:17.14
12,-5,18:18.4
7,-4,18:17.14
10,-4,18:18.4
12,-2,18:18.4
13,-2,18:18.4
10,-1,18:18.4
12,-1,18:18.4
13,0,18:18.4
6,-11,19:18.4
6,-10,19:18.4
8,-10,19:18.4
9,-10,19:18.4
11,-10,19:18.4
6,-9,19:18.4
8,-9,19:18.4
3,-8,19:18.4
6,-8,19:17.14
9,-8,19:18.4
11,-8,19:18.4
2,-7,19:18.4
8,-7,19:17.14
-3,-6,19:18.4
-1,-6,19:18.4
8,-6,19:18.4
-3,-5,19:18.4
-2,-5,19:18.4
-1,-5,19:18.4
3,-5,19:17.14
10,-5,19:18.4
-5,-4,19:18.4
-3,-4,19:18.4
4,-4,19:18.4
6,-4,19:18.4
7,-4,19:17.14
9,-4,19:18.4
-4,-3,19:18.4
14,-3,19:18.4
6,-2,19:18.4
12,-1,19:18.4
13,0,19:18.4
4,-10,20:18.4
6,-9,20:18.4
11,-9,20:18.4
1,-8,20:18.4
2,-8,20:18.4
3,-8,20:18.4
6,-8,20:17.14
7,-8,20:18.4
9,-8,20:17.14
11,-8,20:18.4
3,-7,20:18.4
5,-7,20:18.4
-5,-6,20:18.4
1,-6,20:18.4
8,-6,20:18.4
9,-6,20:17.14
-2,-5,20:18.4
0,-5,20:18.4
1,-5,20:17.14
2,-5,20:17.14
10,-5,20:18.4
-3,-4,20:18.4
-1,-4,20:18.4
1,-4,20:18.4
4,-4,20:18.4
6,-4,20:18.4
8,-4,20:17.14
10,-4,20:18.4
-3,-3,20:18.4
6,-3,20:17.14
-2,-2,20:18.4
2,-2,20:18.4
4,-2,20:18.4
8,-2,20:18.4
12,-2,20:18.4
13,-1,20:18.4
7,-11,21:18.4
9,-11,21:18.4
4,-10,21:18.4
7,-10,21:18.4
7,-9,21:18.4
11,-9,21:18.4
6,-8,21:18.4
8,-8,21:18.4
9,-8,21:17.14
10,-8,21:18.4
-4,-7,21:18.4
-1,-7,21:18.4
1,-7,21:18.4
2,-7,21:18.4
7,-7,21:18.4
-2,-6,21:18.4
0,-6,21:18.4
8,-6,21:18.4
10,-6,21:17.14
11,-6,21:18.4
-6,-5,21:18.4
-3,-5,21:17.14
0,-5,21:18.4
3,-5,21:18.4
4,-5,21:18.4
5,-5,21:18.4
13,-5,21:18.4
-6,-4,21:18.4
0,-4,21:17.14
2,-4,21:18.4
3,-4,21:18.4
6,-4,21:18.4
7,-4,21:18.4
10,-4,21:18.4
-3,-3,21:18.4
0,-3,21:18.4
2,-3,21:18.4
4,-3,21:18.4
-3,-2,21:18.4
-1,-2,21:18.4
0,-2,21:18.4
3,-2,21:18.4
5,-2,21:17.14
6,-1,21:18.4
7,0,21:18.4
6,1,21:18.4
10,-11,22:18.4
11,-10,22:18.4
5,-9,22:18.4
6,-9,22:18.4
-2,-8,22:18.4
6,-8,22:18.4
-2,-7,22:18.4
1,-7,22:18.4
6,-7,22:18.4
8,-7,22:18.4
10,-7,22:18.4
11,-7,22:18.4
-3,-6,22:18.4
-2,-6,22:18.4
-1,-6,22:18.4
3,-6,22:18.4
5,-6,22:18.4
6,-6,22:18.4
8,-6,22:18.4
9,-6,22:18.4
10,-6,22:18.4
11,-6,22:18.4
-3,-5,22:18.4
-2,-5,22:18.4
1,-5,22:18.4
2,-5,22:18.4
12,-5,22:18.4
13,-5,22:18.4
-3,-4,22:18.4
-2,-4,22:17.14
-1,-4,22:17.14
0,-4,22:18.4
3,-4,22:18.4
10,-4,22:18.4
-5,-3,22:18.4
-3,-3,22:17.14
-2,-3,22:18.4
3,-3,22:18.4
-3,-2,22:18.4
6,-2,22:18.4
7,-2,22:18.4
4,-1,22:18.4
7,-1,22:18.4
-4,0,22:18.4
4,0,22:18.4
5,0,22:18.4
11,-10,23:18.4
5,-8,23:18.4
7,-8,23:18.4
9,-8,23:18.4
10,-8,23:18.4
-3,-7,23:18.4
-2,-6,23:18.4
1,-6,23:18.4
3,-6,23:18.4
9,-6,23:18.4
-2,-5,23:18.4
0,-5,23:18.4
5,-5,23:18.4
3,-4,23:18.4
4,-4,23:18.4
5,-4,23:18.4
-2,-3,23:18.4
0,-3,23:18.4
7,-3,23:18.4
3,-2,23:18.4
5,-2,23:18.4
7,-2,23:18.4
-4,-1,23:18.4
4,-1,23:18.4
-4,0,23:18.4
9,-9,24:18.4
2,-7,24:18.4
4,-7,24:18.4
9,-7,24:18.4
10,-6,24:18.4
11,-6,24:18.4
-4,-5,24:18.4
1,-4,24:18.4
3,-4,24:17.14
5,-4,24:18.4
6,-4,24:18.4
-3,-3,24:18.4
1,-3,24:18.4
3,-3,24:18.4
6,-3,24:18.4
-5,-2,24:18.4
-2,-2,24:18.4
2,-2,24:18.4
5,-6,25:18.4
6,-5,25:18.4
-4,-4,25:18.4
-3,-3,25:18.4
3,-3,25:18.4
5,-5,26:18.4
3,-4,26:18.4
5,-4,26:18.4
1,-2,26:18.4
2,-5,27:18.4
4,-5,27:18.4
3,-3,27:18.4
