[META]
version=2.0
spawnOnBlockType=2
spawnSunlight=True
spawnDarkness=True
spawnWater=False
spawnLava=False
underFill=False
randomRotation=True
dig=True
tree=False
branch=False
needsFoundation=True
rarity=100
collisionPercentage=20
spawnElevationMin=0
spawnElevationMax=200
spawnInBiome=Custom
[DATA]
-1,-4,-3:17.14
2,-3,-3:17.14
1,-2,-3:17.14
4,-2,-3:17.14
-1,-1,-3:17.14
1,-1,-3:17.14
2,-1,-3:17.14
4,0,-3:17.14
1,1,-3:17.14
-1,-4,-2:17.14
0,-3,-2:17.14
2,-3,-2:17.14
1,-2,-2:17.14
4,-2,-2:17.14
0,-1,-2:17.14
1,-1,-2:17.14
2,-1,-2:17.14
3,-1,-2:17.14
1,0,-2:17.14
4,0,-2:17.14
0,-3,-1:17.14
2,-3,-1:17.14
1,-2,-1:17.14
2,-2,-1:17.14
1,-1,-1:17.14
2,-1,-1:17.14
3,-1,-1:17.14
0,-3,0:17.14
2,-3,0:17.14
1,-2,0:17.14
2,-2,0:17.14
1,-1,0:17.14
2,-1,0:17.14
3,-1,0:17.14
1,-2,1:17.14
2,-2,1:17.14
1,-1,1:17.14
2,-1,1:17.14
1,-2,2:17.14
2,-2,2:17.14
1,-1,2:17.14
2,-1,2:17.14
1,-2,3:17.14
2,-2,3:17.14
1,-1,3:17.14
2,-1,3:17.14
1,-2,4:17.14
2,-2,4:17.14
1,-1,4:17.14
2,-1,4:17.14
1,-2,5:17.14
2,-2,5:17.14
1,-1,5:17.14
2,-1,5:17.14
1,-2,6:17.14
2,-2,6:17.14
1,-1,6:17.14
2,-1,6:17.14
1,-2,7:17.14
2,-2,7:17.14
1,-1,7:17.14
2,-1,7:17.14
1,-2,8:17.14
2,-2,8:17.14
1,-1,8:17.14
2,-1,8:17.14
1,-2,9:17.14
2,-2,9:17.14
1,-1,9:17.14
2,-1,9:17.14
1,-2,10:17.14
2,-2,10:17.14
1,-1,10:17.14
2,-1,10:17.14
1,-2,11:17.14
2,-2,11:17.14
1,-1,11:17.14
2,-1,11:17.14
1,-2,12:17.14
2,-2,12:17.14
1,-1,12:17.14
2,-1,12:17.14
1,-2,13:17.14
2,-2,13:17.14
1,-1,13:17.14
2,-1,13:17.14
1,-2,14:17.14
2,-2,14:17.14
1,-1,14:17.14
2,-1,14:17.14
1,-2,15:17.14
2,-2,15:17.14
1,-1,15:17.14
2,-1,15:17.14
1,-2,16:17.14
2,-2,16:17.14
1,-1,16:17.14
2,-1,16:17.14
1,-2,17:17.14
2,-2,17:17.14
1,-1,17:17.14
2,-1,17:17.14
1,-2,18:17.14
2,-2,18:17.14
1,-1,18:17.14
2,-1,18:17.14
1,-2,19:17.14
2,-2,19:17.14
1,-1,19:17.14
2,-1,19:17.14
1,-2,20:17.14
2,-2,20:17.14
1,-1,20:17.14
2,-1,20:17.14
1,-2,21:17.14
2,-2,21:17.14
1,-1,21:17.14
2,-1,21:17.14
1,-2,22:17.14
2,-2,22:17.14
1,-1,22:17.14
2,-1,22:17.14
1,-2,23:17.14
2,-2,23:17.14
2,-1,23:17.14
1,-2,24:17.14
2,-2,24:17.14
2,-1,24:17.14
1,-2,25:17.14
2,-2,25:17.14
2,-1,25:17.14
1,-2,26:17.14
2,-2,26:17.14
2,-1,26:17.14
1,-2,27:17.14
2,-2,27:17.14
2,-1,27:17.14
1,-2,28:17.14
2,-2,28:17.14
2,-1,28:17.14
1,-2,29:17.14
2,-2,29:17.14
2,-1,29:17.14
1,-2,30:17.14
2,-2,30:17.14
2,-1,30:17.14
1,-2,31:17.14
2,-1,31:17.14
1,-2,32:17.14
2,-1,32:17.14
1,-2,33:17.14
2,-1,33:17.14
1,-2,34:17.14
2,-1,34:17.14
1,-2,35:17.14
2,-1,35:17.14
-2,-5,36:18.4
-2,-4,36:18.4
0,-3,36:17.14
-4,-2,36:18.4
-3,-2,36:18.4
1,-2,36:17.14
2,-1,36:17.14
3,0,36:18.4
2,1,36:18.4
3,1,36:18.4
0,-7,37:18.4
-2,-6,37:18.4
-2,-5,37:18.4
0,-5,37:18.4
-3,-3,37:18.4
-1,-3,37:17.14
-5,-2,37:18.4
1,-2,37:17.14
2,-1,37:17.14
-5,0,37:18.4
1,0,37:18.4
2,0,37:18.4
0,3,37:18.4
1,3,37:18.4
5,3,37:18.4
-2,-7,38:18.4
-1,-7,38:18.4
-1,-6,38:18.4
0,-6,38:18.4
1,-6,38:18.4
-5,-5,38:18.4
-4,-5,38:18.4
-2,-5,38:18.4
-4,-4,38:18.4
-2,-4,38:17.14
-1,-4,38:18.4
-5,-3,38:18.4
-6,-2,38:18.4
-4,-2,38:18.4
-3,-2,38:18.4
-2,-2,38:17.14
1,-2,38:17.14
3,-1,38:18.4
2,0,38:17.14
3,0,38:18.4
-4,1,38:18.4
3,1,38:18.4
5,2,38:18.4
-2,3,38:18.4
0,3,38:18.4
1,3,38:18.4
2,3,38:18.4
3,3,38:18.4
0,4,38:18.4
-2,5,38:18.4
3,-9,39:18.4
-2,-8,39:18.4
-1,-8,39:18.4
2,-8,39:18.4
-3,-7,39:18.4
-1,-7,39:18.4
-2,-6,39:18.4
-1,-6,39:18.4
-5,-5,39:18.4
-4,-5,39:18.4
-3,-5,39:18.4
-2,-5,39:17.14
-1,-5,39:18.4
-4,-4,39:18.4
-3,-4,39:18.4
-2,-4,39:18.4
-1,-4,39:18.4
-4,-3,39:18.4
-2,-3,39:18.4
-1,-3,39:18.4
1,-3,39:17.14
-5,-2,39:18.4
-3,-2,39:17.14
-2,-2,39:18.4
-1,-2,39:18.4
1,-2,39:17.14
2,-2,39:17.14
-6,-1,39:18.4
-5,-1,39:18.4
-3,-1,39:18.4
-1,-1,39:18.4
2,-1,39:18.4
-4,0,39:18.4
-3,0,39:18.4
-2,0,39:18.4
-1,0,39:18.4
3,0,39:18.4
4,0,39:18.4
5,0,39:18.4
-1,1,39:18.4
0,1,39:18.4
1,1,39:17.14
2,1,39:18.4
3,1,39:17.14
4,1,39:18.4
6,1,39:18.4
0,2,39:18.4
1,2,39:17.14
3,2,39:18.4
6,2,39:18.4
0,3,39:18.4
1,3,39:18.4
3,3,39:18.4
4,3,39:18.4
-1,4,39:18.4
2,4,39:18.4
3,4,39:18.4
0,5,39:18.4
1,-8,40:18.4
-4,-5,40:18.4
-5,-4,40:18.4
-4,-4,40:18.4
-3,-4,40:18.4
2,-4,40:17.14
-3,-3,40:18.4
-2,-3,40:18.4
-1,-3,40:18.4
0,-3,40:18.4
-2,-2,40:18.4
1,-2,40:17.14
2,-2,40:17.14
3,-1,40:18.4
5,-1,40:18.4
-3,0,40:18.4
-1,0,40:18.4
-1,1,40:18.4
0,1,40:18.4
1,1,40:18.4
2,2,40:18.4
3,2,40:18.4
-1,3,40:18.4
0,3,40:17.14
1,3,40:18.4
3,3,40:18.4
5,3,40:18.4
0,4,40:18.4
3,4,40:18.4
0,5,40:18.4
0,-9,41:18.4
-1,-8,41:18.4
1,-8,41:18.4
2,-8,41:18.4
4,-8,41:18.4
5,-8,41:18.4
-1,-7,41:18.4
0,-7,41:18.4
4,-7,41:18.4
-1,-6,41:18.4
2,-6,41:18.4
4,-6,41:18.4
-1,-5,41:18.4
-2,-4,41:18.4
2,-4,41:17.14
-1,-3,41:18.4
1,-2,41:17.14
3,-2,41:17.14
-2,-1,41:18.4
1,-1,41:18.4
-2,0,41:18.4
0,0,41:18.4
1,0,41:18.4
4,0,41:18.4
-2,1,41:18.4
0,1,41:18.4
4,1,41:18.4
0,2,41:18.4
3,2,41:18.4
0,3,41:18.4
1,3,41:18.4
2,3,41:18.4
3,3,41:18.4
-3,4,41:18.4
-2,4,41:18.4
1,4,41:18.4
3,4,41:18.4
-2,5,41:18.4
-1,6,41:18.4
1,-11,42:18.4
2,-11,42:18.4
1,-10,42:18.4
2,-10,42:18.4
7,-10,42:18.4
0,-9,42:18.4
4,-9,42:18.4
-1,-8,42:18.4
0,-8,42:18.4
2,-8,42:17.14
3,-8,42:18.4
5,-8,42:18.4
1,-7,42:18.4
2,-7,42:17.14
3,-7,42:18.4
7,-7,42:18.4
3,-6,42:18.4
6,-6,42:18.4
-2,-5,42:18.4
2,-5,42:18.4
3,-5,42:17.14
8,-4,42:18.4
9,-4,42:18.4
10,-4,42:18.4
9,-3,42:18.4
1,-2,42:17.14
4,-2,42:17.14
5,-1,42:17.14
3,0,42:18.4
11,0,42:18.4
3,1,42:18.4
9,1,42:18.4
10,1,42:18.4
11,1,42:18.4
-1,2,42:18.4
10,2,42:18.4
11,2,42:18.4
-2,4,42:18.4
0,4,42:18.4
-2,5,42:18.4
1,-11,43:18.4
2,-11,43:18.4
7,-10,43:18.4
1,-9,43:18.4
0,-8,43:18.4
2,-8,43:18.4
5,-8,43:18.4
7,-8,43:18.4
4,-7,43:17.14
7,-7,43:18.4
-2,-6,43:18.4
2,-6,43:18.4
3,-6,43:17.14
5,-6,43:18.4
8,-6,43:18.4
11,-6,43:18.4
-3,-5,43:18.4
6,-5,43:18.4
9,-5,43:18.4
11,-5,43:18.4
5,-4,43:18.4
7,-4,43:18.4
9,-4,43:18.4
10,-4,43:18.4
0,-3,43:17.14
2,-3,43:17.14
5,-3,43:17.14
7,-3,43:18.4
11,-3,43:18.4
8,-2,43:17.14
10,-2,43:18.4
-8,-1,43:18.12
2,-1,43:17.14
6,-1,43:17.14
7,-1,43:17.14
9,-1,43:18.4
11,-1,43:18.4
-7,0,43:18.12
8,0,43:17.14
11,0,43:18.4
6,1,43:18.4
8,1,43:18.4
12,1,43:18.4
8,2,43:18.4
9,2,43:18.4
-1,3,43:18.4
0,3,43:18.4
7,3,43:18.4
4,-11,44:18.4
5,-10,44:18.4
6,-10,44:18.4
2,-9,44:18.4
3,-9,44:18.4
4,-9,44:18.4
6,-9,44:18.4
7,-9,44:18.4
2,-8,44:18.4
3,-8,44:18.4
5,-8,44:17.14
7,-8,44:18.4
2,-7,44:18.4
5,-7,44:18.4
8,-7,44:18.4
-4,-6,44:18.4
0,-6,44:18.4
2,-6,44:18.4
8,-6,44:18.4
11,-6,44:18.4
-3,-5,44:18.4
-2,-5,44:18.4
4,-5,44:18.4
5,-5,44:18.4
6,-5,44:18.4
-4,-4,44:18.4
-1,-4,44:18.4
2,-4,44:17.14
6,-4,44:17.14
8,-4,44:18.4
9,-4,44:18.4
10,-4,44:18.4
11,-4,44:18.4
12,-4,44:18.4
13,-4,44:18.4
-8,-3,44:18.12
-1,-3,44:17.14
0,-3,44:18.4
6,-3,44:18.4
7,-3,44:18.4
8,-3,44:18.4
9,-3,44:17.14
10,-3,44:18.4
-9,-2,44:18.4
-7,-1,44:18.12
1,-1,44:17.14
-7,0,44:18.12
-6,0,44:18.12
3,0,44:17.14
6,0,44:17.14
9,0,44:17.14
11,0,44:18.4
-8,1,44:18.12
-6,1,44:18.12
7,1,44:18.4
10,1,44:18.4
13,1,44:18.4
6,2,44:18.4
7,2,44:18.4
8,2,44:18.4
10,2,44:18.4
5,3,44:18.4
5,4,44:18.4
3,-10,45:18.4
3,-9,45:18.4
1,-8,45:18.4
2,-8,45:18.4
3,-8,45:18.4
5,-8,45:18.4
6,-8,45:18.4
7,-8,45:18.4
-3,-7,45:18.4
2,-7,45:18.4
5,-7,45:18.4
7,-7,45:18.4
9,-7,45:18.4
-2,-6,45:18.4
5,-6,45:18.4
7,-6,45:18.4
8,-6,45:18.4
11,-6,45:18.4
-4,-5,45:18.4
-3,-5,45:18.4
1,-5,45:18.4
7,-5,45:17.14
8,-5,45:18.4
9,-5,45:18.4
10,-5,45:18.4
13,-5,45:18.4
-1,-4,45:17.14
0,-4,45:18.4
3,-4,45:17.14
5,-4,45:18.4
6,-4,45:18.4
8,-4,45:18.4
9,-4,45:18.4
10,-4,45:17.14
13,-4,45:18.4
-3,-3,45:18.4
7,-3,45:18.4
10,-3,45:18.4
11,-3,45:18.4
12,-3,45:18.4
13,-3,45:18.4
-9,-2,45:18.4
-7,-2,45:18.12
-6,-2,45:18.12
-2,-2,45:17.14
8,-2,45:18.4
10,-2,45:18.4
11,-2,45:18.4
-9,-1,45:18.4
-7,-1,45:17.14
-6,-1,45:18.12
-4,-1,45:17.14
-3,-1,45:17.14
1,-1,45:17.14
6,-1,45:18.4
7,-1,45:18.4
9,-1,45:18.4
10,-1,45:18.4
-6,0,45:18.12
0,0,45:17.14
3,0,45:17.14
8,0,45:18.4
10,0,45:18.4
-8,1,45:18.12
6,1,45:18.4
7,1,45:17.14
8,1,45:18.4
10,1,45:17.14
5,2,45:18.4
7,2,45:18.4
10,2,45:18.4
6,3,45:18.4
8,3,45:18.4
9,3,45:18.4
10,3,45:18.4
7,4,45:18.4
9,4,45:18.4
10,4,45:18.4
6,5,45:18.4
6,-10,46:18.4
3,-9,46:18.4
4,-9,46:18.4
-2,-7,46:18.4
-1,-7,46:18.4
6,-7,46:18.4
-5,-6,46:18.4
-4,-6,46:18.4
-3,-6,46:18.4
0,-6,46:18.4
7,-6,46:18.4
12,-6,46:18.4
-4,-5,46:18.4
-2,-5,46:17.14
3,-5,46:17.14
4,-5,46:18.4
7,-5,46:18.4
10,-5,46:18.4
-4,-4,46:18.4
0,-4,46:18.4
9,-4,46:18.4
10,-4,46:18.4
-6,-3,46:18.12
13,-3,46:18.4
-7,-2,46:18.12
-6,-2,46:18.12
-5,-2,46:18.12
-1,-2,46:18.4
7,-2,46:18.4
10,-2,46:18.4
11,-2,46:18.4
-8,-1,46:18.12
-6,-1,46:17.14
-5,-1,46:17.14
-4,-1,46:18.12
7,-1,46:18.4
9,-1,46:18.4
10,-1,46:18.4
11,-1,46:18.4
-7,0,46:18.12
0,0,46:17.14
5,0,46:18.4
9,0,46:18.4
11,0,46:18.4
-6,1,46:18.12
4,1,46:17.14
8,1,46:18.4
9,1,46:18.4
4,2,46:18.4
6,2,46:18.4
7,2,46:17.14
4,3,46:18.4
8,3,46:18.4
9,3,46:18.4
10,3,46:18.4
6,4,46:18.4
6,5,46:18.4
7,5,46:18.4
8,5,46:18.4
6,-9,47:18.4
-2,-8,47:18.4
5,-8,47:18.4
7,-7,47:18.4
8,-7,47:18.4
10,-6,47:18.4
11,-6,47:18.4
-3,-5,47:17.14
-2,-5,47:18.4
-1,-5,47:17.14
1,-5,47:18.4
4,-5,47:17.14
7,-5,47:18.4
10,-5,47:18.4
-5,-4,47:18.12
-2,-4,47:18.4
7,-4,47:18.4
8,-4,47:18.4
11,-4,47:18.4
12,-4,47:18.4
-7,-3,47:18.12
-6,-3,47:18.12
-4,-3,47:18.12
5,-3,47:18.4
10,-3,47:18.4
-8,-2,47:18.12
-7,-2,47:18.12
-6,-2,47:17.14
-5,-2,47:18.12
-8,-1,47:18.12
-7,-1,47:18.12
-6,-1,47:18.12
-4,-1,47:18.12
-1,-1,47:17.14
7,-1,47:18.4
8,-1,47:18.4
-7,0,47:18.12
-6,0,47:18.12
10,0,47:18.4
0,1,47:17.14
4,1,47:17.14
8,1,47:18.4
10,1,47:18.4
12,1,47:18.4
4,2,47:18.4
7,2,47:18.4
10,2,47:18.4
4,3,47:18.4
6,3,47:18.4
9,3,47:18.4
12,3,47:18.4
5,4,47:18.4
8,5,47:18.4
-2,-7,48:18.4
-3,-6,48:17.14
-1,-6,48:17.14
5,-6,48:17.14
-2,-5,48:18.4
7,-5,48:18.4
8,-5,48:18.4
9,-5,48:18.4
-2,-4,48:18.4
4,-4,48:17.14
7,-4,48:18.4
-8,-2,48:18.12
-7,-2,48:18.12
-6,-2,48:18.12
-4,-1,48:18.12
-2,-1,48:17.14
-7,0,48:18.12
-6,0,48:18.12
5,0,48:17.14
1,1,48:17.14
10,1,48:18.4
11,1,48:18.4
5,2,48:17.14
6,2,48:18.4
8,2,48:18.4
5,3,48:18.4
7,3,48:18.12
9,3,48:18.4
5,4,48:18.4
6,5,48:18.12
4,-7,49:17.14
-4,-6,49:17.14
-2,-6,49:18.4
0,-6,49:17.14
6,-6,49:17.14
-1,-5,49:18.12
-2,-4,49:18.12
-1,-4,49:18.12
0,-4,49:18.12
4,-4,49:17.14
0,-3,49:18.12
-6,-2,49:18.12
-5,-2,49:18.12
-3,-2,49:17.14
0,-2,49:18.12
1,-2,49:18.12
-7,-1,49:18.12
-5,-1,49:18.12
1,-1,49:18.12
-2,0,49:17.14
2,0,49:17.14
6,0,49:17.14
7,0,49:17.14
7,1,49:18.4
1,2,49:17.14
6,2,49:18.12
7,2,49:18.12
6,3,49:17.14
7,3,49:18.4
6,4,49:18.12
7,4,49:18.12
5,5,49:18.12
6,-10,50:18.12
4,-9,50:18.12
5,-9,50:18.12
4,-8,50:17.14
-5,-7,50:18.12
-4,-7,50:17.14
0,-7,50:17.14
7,-6,50:17.14
0,-5,50:17.14
1,-5,50:18.12
-6,-4,50:18.12
-4,-4,50:18.12
-2,-4,50:18.12
-1,-4,50:18.12
0,-4,50:18.12
1,-4,50:18.12
4,-4,50:18.12
-5,-3,50:18.12
-4,-3,50:17.14
2,-3,50:18.12
4,-3,50:18.12
5,-3,50:17.14
-5,-2,50:18.12
-1,-2,50:18.12
0,-2,50:18.12
2,-2,50:17.14
3,-2,50:18.12
8,-2,50:18.12
9,-2,50:18.12
0,-1,50:18.12
1,-1,50:18.12
2,-1,50:17.14
3,-1,50:18.12
7,-1,50:17.14
9,-1,50:18.12
-5,0,50:18.12
-4,0,50:18.12
-3,0,50:17.14
8,0,50:18.12
-3,1,50:18.12
1,2,50:17.14
2,2,50:18.12
7,2,50:18.12
-1,3,50:18.12
0,3,50:18.12
1,3,50:18.12
2,3,50:18.12
6,3,50:18.12
0,4,50:18.12
1,4,50:18.12
2,4,50:18.12
6,4,50:18.12
7,4,50:17.14
8,4,50:18.12
9,4,50:18.12
-1,5,50:18.12
8,5,50:18.12
6,-11,51:18.4
-5,-10,51:18.4
3,-10,51:18.12
4,-10,51:18.12
-7,-9,51:18.4
-5,-9,51:18.12
-4,-9,51:18.12
1,-9,51:18.12
3,-9,51:18.12
4,-9,51:18.12
5,-9,51:18.12
-7,-8,51:18.4
1,-8,51:18.12
2,-8,51:18.12
4,-8,51:17.14
5,-8,51:18.12
-5,-7,51:17.14
-3,-7,51:18.12
1,-7,51:17.14
2,-7,51:18.12
3,-7,51:18.12
8,-7,51:17.14
-6,-6,51:18.4
-1,-6,51:18.12
0,-6,51:18.12
-6,-5,51:18.12
-5,-5,51:18.12
-1,-5,51:18.12
2,-5,51:18.12
3,-5,51:18.12
-7,-4,51:18.4
-6,-4,51:18.12
-5,-4,51:18.12
-2,-4,51:18.12
-1,-4,51:17.14
0,-4,51:18.12
1,-4,51:18.12
3,-4,51:18.12
-7,-3,51:18.4
-4,-3,51:17.14
-1,-3,51:18.12
0,-3,51:18.12
1,-3,51:18.12
3,-3,51:17.14
4,-3,51:18.12
5,-3,51:17.14
7,-3,51:18.12
-3,-2,51:18.12
-2,-2,51:18.12
-1,-2,51:18.12
0,-2,51:18.12
1,-2,51:17.14
3,-2,51:18.12
-6,-1,51:18.12
-4,-1,51:18.12
-3,-1,51:18.12
0,-1,51:18.12
1,-1,51:18.12
2,-1,51:18.12
3,-1,51:18.12
4,-1,51:18.12
6,-1,51:18.12
7,-1,51:17.14
8,-1,51:18.12
9,-1,51:18.12
10,-1,51:18.4
10,0,51:18.4
-4,1,51:18.12
-3,1,51:17.14
0,1,51:18.12
2,1,51:18.12
-4,2,51:18.12
-1,2,51:18.12
0,2,51:18.12
1,2,51:18.12
2,2,51:18.12
-4,3,51:18.12
-3,3,51:18.12
-1,3,51:18.12
0,3,51:17.14
-1,4,51:18.12
1,4,51:18.12
3,4,51:18.12
5,4,51:18.12
6,4,51:18.12
8,4,51:18.12
-1,5,51:18.12
0,5,51:18.12
8,5,51:18.12
-2,6,51:18.12
-1,6,51:18.12
6,6,51:18.4
5,-11,52:18.4
9,-11,52:18.4
10,-11,52:18.4
-5,-10,52:18.4
-4,-10,52:18.4
3,-10,52:18.12
4,-10,52:18.12
5,-10,52:18.12
-7,-9,52:18.4
-3,-9,52:18.4
3,-9,52:18.12
5,-9,52:17.14
6,-9,52:18.12
7,-9,52:18.12
8,-9,52:18.12
9,-9,52:18.12
10,-9,52:18.4
-7,-8,52:18.4
-6,-8,52:18.4
-5,-8,52:17.14
-4,-8,52:18.4
0,-8,52:18.12
1,-8,52:17.14
2,-8,52:18.12
3,-8,52:18.12
4,-8,52:18.12
5,-8,52:18.12
6,-8,52:18.12
7,-8,52:18.12
8,-8,52:18.12
9,-8,52:17.14
11,-8,52:18.4
-5,-7,52:18.4
-3,-7,52:18.4
3,-7,52:18.12
4,-7,52:18.12
5,-7,52:18.12
6,-7,52:18.12
-6,-6,52:18.4
-4,-6,52:18.4
2,-6,52:18.12
3,-6,52:18.12
8,-6,52:17.14
-5,-5,52:18.12
-1,-5,52:18.12
0,-5,52:18.12
4,-5,52:18.12
-6,-4,52:18.12
-4,-4,52:18.12
-3,-4,52:18.12
-2,-4,52:18.12
1,-4,52:18.12
2,-4,52:18.12
5,-4,52:18.12
-7,-3,52:18.4
-6,-3,52:18.12
-5,-3,52:17.14
-4,-3,52:18.12
-3,-3,52:18.12
0,-3,52:18.12
1,-3,52:18.12
2,-3,52:18.12
3,-3,52:17.14
5,-3,52:18.12
7,-3,52:18.12
8,-3,52:18.12
-6,-2,52:18.12
-1,-2,52:18.12
1,-2,52:18.12
2,-2,52:18.12
3,-2,52:18.12
-6,-1,52:18.12
-4,-1,52:18.12
0,-1,52:18.12
1,-1,52:18.12
2,-1,52:18.12
3,-1,52:18.12
6,-1,52:18.12
7,-1,52:18.12
8,-1,52:17.14
10,-1,52:18.4
-6,0,52:18.12
-2,0,52:18.12
2,0,52:18.12
6,0,52:18.12
8,0,52:18.12
-4,1,52:17.14
-3,1,52:18.12
-2,1,52:18.12
1,1,52:18.12
9,1,52:18.12
-2,2,52:18.12
1,2,52:18.12
-3,3,52:18.12
0,3,52:18.12
1,3,52:17.14
2,3,52:18.12
-1,4,52:17.14
0,4,52:18.12
1,4,52:18.12
7,4,52:18.12
8,4,52:18.12
-1,5,52:18.12
0,5,52:18.12
1,5,52:18.12
2,5,52:18.12
7,5,52:18.4
8,5,52:18.4
-1,6,52:18.12
5,-11,53:18.4
9,-11,53:18.4
-6,-10,53:18.4
1,-10,53:18.4
3,-10,53:18.4
7,-10,53:18.4
8,-10,53:18.4
10,-10,53:18.4
2,-9,53:18.4
3,-9,53:18.4
5,-9,53:18.4
9,-9,53:17.14
10,-9,53:18.4
-7,-8,53:18.4
-5,-8,53:18.4
-3,-8,53:18.4
0,-8,53:18.4
1,-8,53:18.4
2,-8,53:17.14
3,-8,53:18.4
4,-8,53:18.4
-3,-7,53:18.4
2,-7,53:18.4
3,-7,53:18.4
4,-7,53:18.4
5,-7,53:18.4
6,-7,53:18.4
9,-7,53:18.4
10,-7,53:18.4
-6,-6,53:18.4
-5,-6,53:18.4
-4,-6,53:18.4
2,-6,53:18.12
3,-6,53:18.12
-5,-5,53:18.4
-2,-5,53:18.12
-1,-5,53:18.12
0,-5,53:18.12
3,-5,53:18.12
4,-5,53:18.12
8,-5,53:17.14
-6,-4,53:18.12
-4,-4,53:18.12
-3,-4,53:18.12
-2,-4,53:18.12
-1,-4,53:18.12
8,-4,53:18.4
10,-4,53:18.4
-6,-3,53:18.12
-5,-3,53:18.12
-4,-3,53:18.12
-3,-3,53:18.12
1,-3,53:18.12
3,-3,53:18.12
5,-3,53:18.12
7,-3,53:18.4
8,-3,53:18.4
9,-3,53:18.4
-5,-2,53:18.12
-3,-2,53:18.12
1,-2,53:18.12
2,-2,53:18.12
3,-2,53:18.12
5,-2,53:18.12
6,-2,53:18.12
7,-2,53:18.4
8,-2,53:18.4
-4,-1,53:18.12
1,-1,53:18.12
7,-1,53:18.4
8,-1,53:18.4
-4,0,53:18.12
8,0,53:18.4
-4,1,53:18.12
-3,1,53:18.12
1,1,53:18.12
7,1,53:18.4
-6,2,53:18.12
-4,2,53:18.12
-3,2,53:18.12
-1,2,53:18.12
1,2,53:18.12
-1,3,53:18.12
1,3,53:18.12
3,3,53:18.12
-1,4,53:18.12
1,4,53:18.12
1,5,53:18.12
-1,6,53:18.12
10,-10,54:18.4
11,-10,54:18.4
4,-9,54:18.4
5,-9,54:18.4
8,-9,54:18.4
9,-9,54:18.4
-6,-8,54:18.4
-4,-8,54:18.4
2,-8,54:18.4
4,-8,54:18.4
5,-8,54:18.4
11,-8,54:18.4
3,-7,54:18.4
8,-7,54:18.4
9,-7,54:18.4
2,-6,54:18.12
8,-5,54:18.4
10,-5,54:18.4
-5,-4,54:18.4
3,-4,54:18.12
4,-4,54:18.12
9,-4,54:17.14
-5,-3,54:18.4
-4,-3,54:18.4
3,-3,54:18.12
4,-3,54:18.12
9,-3,54:18.4
10,-3,54:18.4
-5,-2,54:18.4
-4,-2,54:18.4
4,-2,54:18.12
9,-2,54:18.4
10,-2,54:18.4
7,-1,54:18.4
8,-1,54:18.4
9,-1,54:18.4
10,-1,54:18.4
-3,0,54:18.12
8,0,54:18.4
-5,1,54:18.4
-3,1,54:18.12
-5,2,54:18.4
0,4,54:18.4
-1,5,54:18.4
10,-10,55:18.4
1,-9,55:18.4
2,-9,55:18.4
10,-9,55:18.4
3,-8,55:18.4
9,-8,55:18.4
2,-7,55:18.4
8,-5,55:18.4
10,-5,55:18.4
7,-3,55:18.4
9,-3,55:17.14
11,-3,55:18.4
8,-2,55:18.4
9,-2,55:18.4
10,-2,55:18.4
8,-1,55:18.4
9,-1,55:18.4
10,-1,55:18.4
9,-5,56:18.4
10,-5,56:18.4
9,-4,56:18.4
9,-3,56:18.4
11,-3,56:18.4
8,-2,56:18.4
8,-1,56:18.4
9,-1,56:18.4
