[META]
version=2.0
spawnOnBlockType=2
spawnSunlight=True
spawnDarkness=True
spawnWater=False
spawnLava=False
underFill=False
randomRotation=True
dig=True
tree=False
branch=False
needsFoundation=True
rarity=100
collisionPercentage=20
spawnElevationMin=0
spawnElevationMax=200
spawnInBiome=Custom
[DATA]
1,-1,0:17.3
1,-1,1:17.3
1,-1,2:17.3
1,-1,3:17.3
1,-1,4:17.3
1,-1,5:17.3
1,-1,6:17.3
1,-1,7:17.3
1,-1,8:17.3
1,-1,9:17.3
1,-1,10:17.3
1,-1,11:17.3
1,-1,12:17.3
1,-1,13:17.3
1,-1,14:17.3
1,-1,15:17.3
1,-1,16:17.3
1,-1,17:17.3
1,-1,18:17.3
1,-1,19:17.3
1,-1,20:17.3
1,-1,21:17.3
1,-1,22:17.3
1,-2,23:127.8
1,-1,23:17.3
1,0,23:127.10
4,-4,24:18.12
1,-2,24:127.8
0,-1,24:127.11
1,-1,24:17.3
2,-1,24:127.9
1,0,24:127.10
5,0,24:18.12
-2,-4,25:18.12
3,-3,25:18.12
2,-2,25:18.12
0,-1,25:127.11
1,-1,25:17.3
3,-1,25:18.4
4,0,25:18.12
-2,2,25:18.12
1,-6,26:18.12
-1,-3,26:18.12
1,-3,26:18.12
0,-2,26:18.12
1,-1,26:17.3
2,-1,26:18.12
0,0,26:18.12
2,0,26:18.12
-1,1,26:18.12
1,2,26:18.12
5,3,26:18.12
1,-5,27:18.12
6,-5,27:18.12
1,-4,27:18.12
-4,-3,27:18.12
1,-2,27:18.12
3,-2,27:18.12
-1,-1,27:18.12
0,-1,27:18.12
1,-1,27:17.3
2,-1,27:18.12
1,0,27:18.12
1,1,27:18.12
3,1,27:18.12
4,2,27:18.12
5,-4,28:18.12
4,-3,28:18.12
-3,-2,28:18.12
-2,-2,28:18.12
1,-2,28:18.12
0,-1,28:18.12
1,-1,28:17.3
2,-1,28:18.12
1,0,28:18.12
1,-3,29:18.12
-1,-1,29:18.12
3,-1,29:18.12
2,0,29:18.12
1,1,29:18.12
1,-3,30:18.12
0,-2,30:18.12
2,-2,30:18.12
-1,-1,30:18.12
3,-1,30:18.12
0,0,30:18.12
2,0,30:18.12
1,1,30:18.12
1,-4,31:18.12
-1,-3,31:18.12
3,-3,31:18.12
-2,-1,31:18.12
4,-1,31:18.12
-1,1,31:18.12
3,1,31:18.12
1,2,31:18.12
1,-6,32:18.4
-3,-5,32:18.12
1,-5,32:18.12
5,-5,32:18.12
-2,-4,32:18.12
4,-4,32:18.12
-4,-1,32:18.4
-3,-1,32:18.12
5,-1,32:18.12
6,-1,32:18.12
-2,2,32:18.12
4,2,32:18.12
-3,3,32:18.12
1,3,32:18.12
5,3,32:18.12
0,4,32:18.12
1,0,26:85.0
0,-1,26:85.0
2,-2,26:85.0
1,-2,26:85.0
2,0,25:85.0
1,0,25:85.0
2,-1,25:85.0
1,-2,25:85.0
0,-2,25:85.0
