[META]
version=2.0
spawnOnBlockType=2
spawnSunlight=True
spawnDarkness=True
spawnWater=False
spawnLava=False
underFill=False
randomRotation=True
dig=True
tree=False
branch=False
needsFoundation=True
rarity=100
collisionPercentage=20
spawnElevationMin=0
spawnElevationMax=200
spawnInBiome=Custom
[DATA]
0,0,0:17.3
0,0,1:17.3
0,0,2:17.3
0,0,3:17.3
1,0,3:127.9
-2,-2,4:18.12
0,-1,4:127.8
0,0,4:17.3
-1,-1,5:18.12
-1,0,5:18.12
1,0,5:18.12
0,-2,6:18.12
1,-1,6:18.12
-2,0,6:18.12
-1,1,6:18.12
1,1,6:18.12
0,2,6:18.12
-1,-5,7:18.12
2,-5,7:18.12
-3,-3,7:18.12
0,-3,7:18.12
3,-3,7:18.12
-2,-1,7:18.12
1,-1,7:18.12
-3,0,7:18.12
0,0,7:18.12
2,0,7:18.12
2,2,7:18.12
0,3,7:18.12
-1,-4,8:18.12
1,-4,8:18.12
-3,-2,8:18.12
2,-2,8:18.12
0,-1,8:18.12
-5,0,8:18.12
-4,0,8:18.12
3,0,8:18.12
4,0,8:18.4
-1,1,8:18.12
1,1,8:18.12
3,3,8:18.12
0,4,8:18.12
4,4,8:18.12
0,5,8:18.4
0,-1,9:18.12
-1,1,9:18.12
1,1,9:18.12
0,2,5:85.0
1,1,5:85.0
-1,1,5:85.0
-2,0,5:85.0
1,-1,5:85.0
0,-2,5:85.0
0,1,4:85.0
1,0,4:85.0
-1,0,4:85.0
0,1,3:85.0
-1,0,3:85.0
0,-1,3:85.0
