[META]
version=2.0
spawnOnBlockType=2
spawnSunlight=True
spawnDarkness=True
spawnWater=False
spawnLava=False
underFill=False
randomRotation=True
dig=True
tree=False
branch=False
needsFoundation=True
rarity=100
collisionPercentage=20
spawnElevationMin=0
spawnElevationMax=200
spawnInBiome=Custom
[DATA]
2,-7,-3:17.12
1,-6,-3:17.12
2,-4,-3:17.12
4,-4,-3:17.12
3,-2,-3:17.12
1,-6,-2:17.12
2,-4,-2:17.12
4,-4,-2:17.12
3,-2,-2:17.12
2,-6,-1:17.12
3,-5,-1:17.12
2,-4,-1:17.12
4,-4,-1:17.12
3,-3,-1:17.12
2,-6,0:17.12
3,-5,0:17.12
2,-4,0:17.12
3,-4,0:17.12
4,-4,0:17.12
3,-3,0:17.12
3,-5,1:17.12
3,-4,1:17.12
3,-4,2:17.12
3,-4,3:17.12
4,-4,4:17.12
4,-4,5:17.12
4,-4,6:17.12
5,-5,7:17.12
4,-6,8:17.12
11,-6,8:18.12
5,-5,8:17.12
6,-5,8:17.12
10,-5,8:18.12
3,-7,9:17.12
11,-7,9:18.12
5,-5,9:17.12
7,-4,9:17.12
10,-3,9:18.12
13,-2,9:18.12
3,-7,10:17.12
8,-7,10:18.12
6,-6,10:17.12
13,-5,10:18.12
8,-4,10:17.12
9,-4,10:17.12
10,-3,10:18.12
12,-3,10:18.12
12,-2,10:18.12
11,0,10:18.12
3,-8,11:17.12
9,-7,11:18.12
11,-7,11:18.12
2,-6,11:17.12
6,-6,11:17.12
10,-6,11:18.12
11,-6,11:18.12
9,-5,11:18.12
10,-5,11:17.12
11,-5,11:18.12
12,-5,11:18.12
13,-5,11:18.12
11,-4,11:18.12
10,-3,11:17.12
11,-3,11:17.4
15,-3,11:18.12
10,-2,11:18.12
12,0,11:18.12
3,-8,12:17.12
9,-8,12:18.12
11,-8,12:18.12
7,-7,12:17.12
2,-6,12:17.12
5,-6,12:17.12
11,-6,12:18.12
6,-5,12:17.12
9,-5,12:18.12
10,-5,12:18.12
12,-5,12:18.12
13,-5,12:18.12
8,-4,12:18.12
12,-4,12:18.12
10,-3,12:18.12
10,-2,12:18.12
12,-2,12:17.4
14,-2,12:18.12
15,-2,12:18.12
9,-1,12:18.12
10,-1,12:18.12
14,0,12:18.12
6,-10,13:18.12
8,-10,13:18.12
4,-9,13:17.12
6,-8,13:18.12
9,-8,13:18.12
5,-7,13:18.12
7,-7,13:17.12
9,-7,13:18.12
12,-7,13:18.12
1,-6,13:17.12
-4,-5,13:18.12
-3,-5,13:18.12
-1,-5,13:18.12
1,-5,13:18.12
4,-5,13:17.12
12,-5,13:18.12
7,-4,13:17.12
10,-4,13:18.12
12,-2,13:18.12
13,-2,13:18.12
10,-1,13:18.12
12,-1,13:18.12
13,0,13:18.12
6,-11,14:18.12
4,-10,14:17.12
6,-10,14:18.12
8,-10,14:18.12
9,-10,14:18.12
11,-10,14:18.12
6,-9,14:18.12
8,-9,14:18.12
3,-8,14:18.12
6,-8,14:17.12
9,-8,14:18.12
11,-8,14:18.12
0,-7,14:17.12
2,-7,14:18.12
8,-7,14:17.12
-3,-6,14:18.12
-1,-6,14:18.12
8,-6,14:18.12
-3,-5,14:18.12
-2,-5,14:18.12
-1,-5,14:18.12
3,-5,14:17.12
10,-5,14:18.12
-5,-4,14:18.12
-3,-4,14:18.12
4,-4,14:18.12
6,-4,14:18.12
7,-4,14:17.12
9,-4,14:18.12
-4,-3,14:18.12
14,-3,14:18.12
6,-2,14:18.12
12,-1,14:18.12
13,0,14:18.12
4,-10,15:18.12
6,-9,15:18.12
11,-9,15:18.12
1,-8,15:18.12
2,-8,15:18.12
3,-8,15:18.12
6,-8,15:17.12
7,-8,15:18.12
9,-8,15:17.12
11,-8,15:18.12
3,-7,15:18.12
5,-7,15:18.12
-5,-6,15:18.12
1,-6,15:18.12
8,-6,15:18.12
9,-6,15:17.12
-2,-5,15:18.12
0,-5,15:18.12
1,-5,15:17.12
2,-5,15:17.12
10,-5,15:18.12
-3,-4,15:18.12
-1,-4,15:18.12
1,-4,15:18.12
4,-4,15:18.12
6,-4,15:18.12
8,-4,15:17.12
10,-4,15:18.12
-3,-3,15:18.12
6,-3,15:17.12
-2,-2,15:18.12
2,-2,15:18.12
4,-2,15:18.12
8,-2,15:18.12
12,-2,15:18.12
13,-1,15:18.12
7,-11,16:18.12
9,-11,16:18.12
4,-10,16:18.12
7,-10,16:18.12
7,-9,16:18.12
11,-9,16:18.12
6,-8,16:18.12
8,-8,16:18.12
9,-8,16:17.12
10,-8,16:18.12
-4,-7,16:18.12
-1,-7,16:18.12
1,-7,16:18.12
2,-7,16:18.12
7,-7,16:18.12
-2,-6,16:18.12
0,-6,16:18.12
8,-6,16:18.12
10,-6,16:17.12
11,-6,16:18.12
-6,-5,16:18.12
-3,-5,16:17.12
0,-5,16:18.12
3,-5,16:18.12
4,-5,16:18.12
5,-5,16:18.12
13,-5,16:18.12
-6,-4,16:18.12
0,-4,16:17.12
2,-4,16:18.12
3,-4,16:18.12
6,-4,16:18.12
7,-4,16:18.12
10,-4,16:18.12
-3,-3,16:18.12
0,-3,16:18.12
2,-3,16:18.12
4,-3,16:18.12
-3,-2,16:18.12
-1,-2,16:18.12
0,-2,16:18.12
3,-2,16:18.12
5,-2,16:17.12
6,-1,16:18.12
7,0,16:18.12
6,1,16:18.12
10,-11,17:18.12
11,-10,17:18.12
5,-9,17:18.12
6,-9,17:18.12
-2,-8,17:18.12
6,-8,17:18.12
-2,-7,17:18.12
1,-7,17:18.12
6,-7,17:18.12
8,-7,17:18.12
10,-7,17:18.12
11,-7,17:18.12
-3,-6,17:18.12
-2,-6,17:18.12
-1,-6,17:18.12
3,-6,17:18.12
5,-6,17:18.12
6,-6,17:18.12
8,-6,17:18.12
9,-6,17:18.12
10,-6,17:18.12
11,-6,17:18.12
-3,-5,17:18.12
-2,-5,17:18.12
1,-5,17:18.12
2,-5,17:18.12
12,-5,17:18.12
13,-5,17:18.12
-3,-4,17:18.12
-2,-4,17:17.12
-1,-4,17:17.12
0,-4,17:18.12
3,-4,17:18.12
10,-4,17:18.12
-5,-3,17:18.12
-3,-3,17:17.12
-2,-3,17:18.12
3,-3,17:18.12
-3,-2,17:18.12
6,-2,17:18.12
7,-2,17:18.12
4,-1,17:18.12
7,-1,17:18.12
-4,0,17:18.12
4,0,17:18.12
5,0,17:18.12
11,-10,18:18.12
5,-8,18:18.12
7,-8,18:18.12
9,-8,18:18.12
10,-8,18:18.12
-3,-7,18:18.12
-2,-6,18:18.12
1,-6,18:18.12
3,-6,18:18.12
9,-6,18:18.12
-2,-5,18:18.12
0,-5,18:18.12
5,-5,18:18.12
3,-4,18:18.12
4,-4,18:18.12
5,-4,18:18.12
-2,-3,18:18.12
0,-3,18:18.12
7,-3,18:18.12
3,-2,18:18.12
5,-2,18:18.12
7,-2,18:18.12
-4,-1,18:18.12
4,-1,18:18.12
-4,0,18:18.12
9,-9,19:18.12
2,-7,19:18.12
4,-7,19:18.12
9,-7,19:18.12
10,-6,19:18.12
11,-6,19:18.12
-4,-5,19:18.12
1,-4,19:18.12
5,-4,19:18.12
6,-4,19:18.12
-3,-3,19:18.12
1,-3,19:18.12
3,-3,19:18.12
6,-3,19:18.12
-5,-2,19:18.12
-2,-2,19:18.12
2,-2,19:18.12
5,-6,20:18.12
6,-5,20:18.12
-4,-4,20:18.12
-3,-3,20:18.12
3,-3,20:18.12
5,-5,21:18.12
3,-4,21:18.12
5,-4,21:18.12
1,-2,21:18.12
2,-5,22:18.12
4,-5,22:18.12
3,-3,22:18.12
