[META]
version=2.0
spawnOnBlockType=2
spawnSunlight=True
spawnDarkness=True
spawnWater=False
spawnLava=False
underFill=False
randomRotation=True
dig=True
tree=False
branch=False
needsFoundation=True
rarity=100
collisionPercentage=20
spawnElevationMin=0
spawnElevationMax=200
spawnInBiome=Custom
[DATA]
1,-3,-3:17.12
2,-3,-3:17.12
0,-2,-3:17.12
3,-2,-3:17.12
2,0,-3:17.12
-1,1,-3:17.12
1,1,-3:17.12
2,-3,-2:17.12
1,-2,-2:17.12
2,-1,-2:17.12
0,1,-2:17.12
2,-3,-1:17.12
1,-2,-1:17.12
2,-1,-1:17.12
0,0,-1:17.12
2,-3,0:17.12
1,-2,0:17.12
1,-1,0:17.12
2,-1,0:17.12
0,0,0:17.12
1,-2,1:17.12
1,-1,1:17.12
1,-1,2:17.12
1,-1,3:17.12
1,-1,4:17.12
1,-1,5:17.12
1,-1,6:17.12
1,-1,7:17.12
1,-1,8:17.12
1,-1,9:17.12
1,-1,10:17.12
2,-1,10:17.12
0,-2,11:17.12
2,-2,11:18.4
3,-2,11:18.4
2,-1,11:17.12
1,-4,12:18.4
0,-2,12:17.12
2,-2,12:18.4
2,-1,12:17.12
8,-8,13:18.12
9,-7,13:18.12
1,-3,13:18.4
0,-2,13:17.12
3,-2,13:18.4
4,-2,13:18.4
2,-1,13:17.12
7,-7,14:18.12
9,-7,14:18.12
10,-7,14:18.12
11,-7,14:18.12
11,-6,14:18.12
-3,-5,14:18.12
-2,-5,14:18.12
1,-5,14:18.4
3,-5,14:18.4
8,-5,14:18.12
9,-5,14:18.12
1,-4,14:18.4
-1,-3,14:17.12
1,-3,14:18.4
7,-3,14:18.12
0,-2,14:17.12
2,-2,14:17.12
3,-2,14:18.4
2,-1,14:17.12
5,-1,14:18.4
0,0,14:18.4
1,0,14:18.4
3,0,14:18.4
1,1,14:18.4
8,-10,15:18.4
9,-10,15:18.4
9,-8,15:18.12
-1,-7,15:18.12
0,-7,15:18.12
1,-7,15:18.12
8,-7,15:18.12
-2,-4,15:17.12
1,-4,15:18.4
4,-4,15:18.4
-1,-3,15:18.12
3,-3,15:18.4
7,-3,15:18.12
0,-2,15:17.12
3,-2,15:17.12
5,-2,15:18.4
2,0,15:17.12
3,0,15:18.4
10,0,15:18.12
2,1,15:18.4
0,-10,16:18.12
0,-9,16:18.12
7,-9,16:18.12
9,-9,16:18.12
11,-9,16:18.12
7,-8,16:18.12
8,-8,16:18.12
-2,-7,16:18.12
6,-7,16:18.12
8,-7,16:18.12
9,-7,16:17.12
10,-7,16:18.12
11,-7,16:18.12
7,-6,16:18.12
8,-6,16:17.12
-1,-5,16:18.12
6,-5,16:18.12
10,-5,16:18.12
-5,-4,16:18.12
-3,-4,16:18.12
-2,-4,16:17.12
3,-4,16:18.12
4,-4,16:18.12
-6,-3,16:18.12
-4,-3,16:18.12
-3,-3,16:18.12
-4,-2,16:18.12
0,-2,16:17.12
3,-2,16:17.12
4,-2,16:18.4
-3,-1,16:18.12
2,-1,16:18.4
2,0,16:17.12
8,-10,17:18.4
3,-9,17:18.12
8,-9,17:18.12
1,-8,17:18.12
8,-8,17:18.12
9,-8,17:18.12
10,-8,17:18.12
-2,-7,17:18.12
6,-7,17:18.12
7,-7,17:18.12
-4,-6,17:18.12
6,-6,17:18.12
-4,-5,17:18.12
0,-5,17:18.12
7,-5,17:17.12
-6,-4,17:18.12
-5,-4,17:18.12
-3,-4,17:17.12
6,-4,17:17.12
8,-4,17:18.12
-5,-3,17:18.12
-3,-3,17:18.12
-2,-2,17:18.12
0,-2,17:17.12
2,-2,17:17.12
3,-2,17:17.12
6,-2,17:18.12
-4,-1,17:18.12
5,-1,17:18.12
-8,0,17:18.12
1,0,17:17.12
8,0,17:18.12
9,0,17:18.12
-7,1,17:18.12
3,1,17:17.12
8,1,17:18.12
11,1,17:18.12
13,1,17:18.4
9,2,17:18.12
9,3,17:18.12
9,4,17:18.12
9,-9,18:18.12
0,-8,18:17.12
11,-8,18:18.12
-2,-7,18:18.12
9,-7,18:18.12
-3,-6,18:18.12
1,-6,18:18.12
4,-6,18:18.12
5,-6,18:18.12
11,-6,18:18.12
-3,-5,18:17.12
0,-5,18:18.12
3,-5,18:18.12
5,-5,18:18.12
8,-5,18:18.12
-6,-4,18:18.12
6,-4,18:18.12
8,-4,18:18.12
-5,-3,18:18.12
-4,-3,18:17.12
2,-3,18:17.12
5,-3,18:17.12
-8,-2,18:18.12
-4,-2,18:18.12
-1,-2,18:17.12
4,-2,18:17.12
5,-2,18:18.12
7,-2,18:18.12
8,-2,18:18.12
10,-2,18:18.12
-9,-1,18:18.12
7,-1,18:18.12
11,-1,18:18.12
-7,0,18:18.12
1,0,18:17.12
8,0,18:18.12
9,0,18:18.12
10,0,18:18.12
13,0,18:18.4
-7,1,18:18.12
-6,1,18:18.12
3,1,18:17.12
7,1,18:18.12
9,1,18:18.12
10,1,18:17.12
13,1,18:18.4
-8,2,18:18.12
-6,2,18:18.12
9,2,18:18.12
10,2,18:18.12
9,4,18:18.12
-1,-11,19:18.12
2,-10,19:18.12
0,-8,19:18.12
-2,-7,19:18.12
0,-7,19:17.12
8,-7,19:18.12
9,-7,19:18.12
-4,-6,19:18.12
-2,-6,19:18.12
-1,-5,19:18.12
0,-5,19:18.12
1,-5,19:17.12
-4,-4,19:18.12
-3,-4,19:18.12
-2,-4,19:18.12
1,-4,19:17.12
-5,-3,19:17.12
-1,-3,19:17.12
3,-3,19:17.12
7,-3,19:18.12
8,-3,19:18.12
9,-3,19:18.12
7,-2,19:18.12
9,-2,19:18.12
-9,-1,19:18.12
-7,-1,19:18.12
-6,-1,19:18.12
-2,-1,19:17.12
9,-1,19:18.12
12,-1,19:18.4
-9,0,19:18.12
-7,0,19:17.0
-6,0,19:18.12
-4,0,19:17.12
-3,0,19:17.12
1,0,19:17.12
4,0,19:17.12
9,0,19:18.12
10,0,19:18.12
11,0,19:18.12
-6,1,19:18.12
0,1,19:17.12
3,1,19:17.12
8,1,19:18.12
9,1,19:17.12
10,1,19:18.12
11,1,19:18.12
13,1,19:18.4
-8,2,19:18.12
10,2,19:18.12
12,2,19:18.4
13,2,19:18.4
6,3,19:18.12
12,3,19:18.4
9,4,19:18.12
10,4,19:18.12
-1,-10,20:18.12
-1,-9,20:18.12
0,-8,20:18.12
1,-8,20:18.12
0,-7,20:18.12
1,-7,20:18.12
4,-7,20:18.12
1,-6,20:17.12
2,-6,20:18.12
4,-6,20:18.12
2,-5,20:18.12
9,-5,20:18.12
-3,-4,20:18.12
-2,-4,20:17.12
3,-4,20:17.12
5,-4,20:18.12
6,-4,20:18.12
8,-4,20:18.12
9,-4,20:18.12
1,-3,20:18.12
5,-3,20:18.12
9,-3,20:18.12
-6,-2,20:18.12
8,-2,20:18.12
9,-2,20:18.12
11,-2,20:18.12
12,-2,20:18.4
-7,-1,20:18.12
-6,-1,20:18.12
-5,-1,20:18.12
8,-1,20:18.12
10,-1,20:18.12
-8,0,20:18.12
-6,0,20:17.0
-5,0,20:17.12
-4,0,20:18.12
5,0,20:17.12
6,0,20:17.12
11,0,20:18.12
-7,1,20:18.12
0,1,20:17.12
7,1,20:17.12
8,1,20:17.12
9,1,20:18.12
11,1,20:18.12
-6,2,20:18.12
4,2,20:17.12
6,2,20:18.12
8,2,20:18.12
6,3,20:18.12
7,4,20:18.12
0,-8,21:18.12
1,-8,21:18.12
3,-8,21:18.12
6,-6,21:18.12
6,-5,21:18.12
8,-5,21:18.12
-3,-4,21:17.12
-1,-4,21:17.12
2,-4,21:18.12
4,-4,21:17.12
8,-4,21:18.12
9,-4,21:18.12
-5,-3,21:18.12
-7,-2,21:18.12
-6,-2,21:18.12
-4,-2,21:18.12
8,-2,21:18.12
9,-2,21:18.12
-8,-1,21:18.12
-7,-1,21:18.12
-6,-1,21:17.12
-5,-1,21:18.12
9,-1,21:18.12
12,-1,21:18.4
-8,0,21:18.12
-7,0,21:18.12
-6,0,21:18.12
-4,0,21:18.12
-1,0,21:17.12
8,0,21:18.12
10,0,21:18.12
-7,1,21:18.12
-6,1,21:18.12
9,1,21:18.12
0,2,21:17.12
4,2,21:17.12
10,2,21:18.12
7,-7,22:18.12
8,-7,22:18.12
1,-6,22:18.12
9,-6,22:18.12
-3,-5,22:17.12
-1,-5,22:17.12
1,-5,22:18.12
5,-5,22:17.12
6,-5,22:18.12
7,-5,22:18.12
11,-4,22:18.4
4,-3,22:17.12
10,-2,22:18.12
-8,-1,22:18.12
-7,-1,22:18.12
-6,-1,22:18.12
-4,0,22:18.12
-2,0,22:17.12
9,0,22:18.12
-7,1,22:18.12
-6,1,22:18.12
5,1,22:17.12
9,1,22:18.12
1,2,22:17.12
5,3,22:17.12
7,4,22:18.12
6,6,22:18.12
8,-8,23:18.12
8,-7,23:18.12
1,-6,23:18.12
4,-6,23:17.12
8,-6,23:18.12
-4,-5,23:17.12
0,-5,23:17.12
5,-5,23:18.12
6,-5,23:17.12
-1,-4,23:18.12
9,-4,23:18.12
-2,-3,23:18.12
-1,-3,23:18.12
0,-3,23:18.12
4,-3,23:17.12
0,-2,23:18.12
-6,-1,23:18.12
-5,-1,23:18.12
-3,-1,23:17.12
0,-1,23:18.12
1,-1,23:18.12
8,-1,23:18.12
-7,0,23:18.12
-5,0,23:18.12
1,0,23:18.12
-2,1,23:17.12
2,1,23:17.12
6,1,23:17.12
7,1,23:17.12
1,3,23:17.12
6,3,23:18.12
7,3,23:18.12
6,4,23:17.12
6,5,23:18.12
7,5,23:18.12
5,6,23:18.12
6,-9,24:18.12
4,-8,24:18.12
5,-8,24:18.12
4,-7,24:17.12
-5,-6,24:18.12
-4,-6,24:17.12
0,-6,24:17.12
9,-6,24:18.4
4,-5,24:18.12
5,-5,24:18.12
7,-5,24:17.12
9,-5,24:18.4
0,-4,24:17.12
1,-4,24:18.12
-6,-3,24:18.12
-4,-3,24:18.12
-2,-3,24:18.12
-1,-3,24:18.12
0,-3,24:18.12
1,-3,24:18.12
4,-3,24:18.12
7,-3,24:18.12
-5,-2,24:18.12
-4,-2,24:17.12
2,-2,24:18.12
4,-2,24:18.12
5,-2,24:17.12
7,-2,24:18.12
9,-2,24:18.12
10,-2,24:18.12
-5,-1,24:18.12
-1,-1,24:18.12
0,-1,24:18.12
2,-1,24:17.12
3,-1,24:18.12
8,-1,24:18.12
9,-1,24:18.12
0,0,24:18.12
1,0,24:18.12
2,0,24:17.12
3,0,24:18.12
7,0,24:17.12
9,0,24:18.12
-5,1,24:18.12
-4,1,24:18.12
-3,1,24:17.12
8,1,24:18.12
-3,2,24:18.12
1,3,24:17.12
2,3,24:18.12
7,3,24:18.12
-1,4,24:18.12
0,4,24:18.12
1,4,24:18.12
2,4,24:18.12
6,4,24:18.12
0,5,24:18.12
1,5,24:18.12
2,5,24:18.12
6,5,24:18.12
7,5,24:17.12
8,5,24:18.12
9,5,24:18.12
-1,6,24:18.12
8,6,24:18.12
6,-10,25:18.12
-5,-9,25:18.12
3,-9,25:18.12
4,-9,25:18.12
-7,-8,25:18.12
-5,-8,25:18.12
-4,-8,25:18.12
1,-8,25:18.12
3,-8,25:18.12
4,-8,25:18.12
5,-8,25:18.12
7,-8,25:18.12
8,-8,25:18.12
-7,-7,25:18.12
1,-7,25:18.12
2,-7,25:18.12
4,-7,25:17.12
5,-7,25:18.12
9,-7,25:18.4
-5,-6,25:17.12
-3,-6,25:18.12
1,-6,25:17.12
2,-6,25:18.12
3,-6,25:18.12
8,-6,25:17.12
-6,-5,25:18.12
-1,-5,25:18.12
0,-5,25:18.12
7,-5,25:18.12
8,-5,25:18.12
10,-5,25:18.4
-6,-4,25:18.12
-5,-4,25:18.12
-1,-4,25:18.12
2,-4,25:18.12
3,-4,25:18.12
-7,-3,25:18.12
-6,-3,25:18.12
-5,-3,25:18.12
-2,-3,25:18.12
-1,-3,25:17.12
0,-3,25:18.12
1,-3,25:18.12
3,-3,25:18.12
8,-3,25:18.12
-7,-2,25:18.12
-4,-2,25:17.12
-1,-2,25:18.12
0,-2,25:18.12
1,-2,25:18.12
3,-2,25:17.12
4,-2,25:18.12
5,-2,25:17.12
7,-2,25:18.12
8,-2,25:18.12
-3,-1,25:18.12
-2,-1,25:18.12
-1,-1,25:18.12
0,-1,25:18.12
1,-1,25:17.12
3,-1,25:18.12
-6,0,25:18.12
-4,0,25:18.12
-3,0,25:18.12
0,0,25:18.12
1,0,25:18.12
2,0,25:18.12
3,0,25:18.12
4,0,25:18.12
6,0,25:18.12
7,0,25:17.12
8,0,25:18.12
9,0,25:18.12
10,0,25:18.12
10,1,25:18.12
-4,2,25:18.12
-3,2,25:17.12
0,2,25:18.12
2,2,25:18.12
-4,3,25:18.12
-1,3,25:18.12
0,3,25:18.12
1,3,25:18.12
2,3,25:18.12
-4,4,25:18.12
-3,4,25:18.12
-1,4,25:18.12
0,4,25:17.12
-1,5,25:18.12
1,5,25:18.12
3,5,25:18.12
5,5,25:18.12
6,5,25:18.12
8,5,25:18.12
-1,6,25:18.12
0,6,25:18.12
8,6,25:18.12
-2,7,25:18.12
-1,7,25:18.12
6,7,25:18.12
5,-10,26:18.12
9,-10,26:18.12
10,-10,26:18.12
-5,-9,26:18.12
-4,-9,26:18.12
3,-9,26:18.12
4,-9,26:18.12
5,-9,26:18.12
-7,-8,26:18.12
-3,-8,26:18.12
3,-8,26:18.12
5,-8,26:17.12
6,-8,26:18.12
7,-8,26:18.12
8,-8,26:18.12
9,-8,26:18.12
10,-8,26:18.12
-7,-7,26:18.12
-6,-7,26:18.12
-5,-7,26:17.12
-4,-7,26:18.12
0,-7,26:18.12
1,-7,26:17.12
2,-7,26:18.12
3,-7,26:18.12
4,-7,26:18.12
5,-7,26:18.12
6,-7,26:18.12
7,-7,26:18.12
8,-7,26:18.12
9,-7,26:17.12
11,-7,26:18.12
-5,-6,26:18.12
-3,-6,26:18.12
3,-6,26:18.12
4,-6,26:18.12
5,-6,26:18.12
6,-6,26:18.12
-6,-5,26:18.12
-4,-5,26:18.12
2,-5,26:18.12
3,-5,26:18.12
6,-5,26:18.4
7,-5,26:18.4
8,-5,26:17.12
9,-5,26:18.4
-5,-4,26:18.12
-1,-4,26:18.12
0,-4,26:18.12
4,-4,26:18.12
-6,-3,26:18.12
-4,-3,26:18.12
-3,-3,26:18.12
-2,-3,26:18.12
1,-3,26:18.12
2,-3,26:18.12
5,-3,26:18.12
-7,-2,26:18.12
-6,-2,26:18.12
-5,-2,26:17.12
-4,-2,26:18.12
-3,-2,26:18.12
0,-2,26:18.12
1,-2,26:18.12
2,-2,26:18.12
3,-2,26:17.12
5,-2,26:18.12
7,-2,26:18.12
8,-2,26:18.12
-6,-1,26:18.12
-1,-1,26:18.12
1,-1,26:18.12
2,-1,26:18.12
3,-1,26:18.12
-6,0,26:18.12
-4,0,26:18.12
0,0,26:18.12
1,0,26:18.12
2,0,26:18.12
3,0,26:18.12
6,0,26:18.12
7,0,26:18.12
8,0,26:17.12
10,0,26:18.12
-6,1,26:18.12
-2,1,26:18.12
2,1,26:18.12
6,1,26:18.12
8,1,26:18.12
-4,2,26:17.12
-3,2,26:18.12
-2,2,26:18.12
1,2,26:18.12
9,2,26:18.12
-2,3,26:18.12
1,3,26:18.12
-3,4,26:18.12
0,4,26:18.12
1,4,26:17.12
2,4,26:18.12
-1,5,26:17.12
0,5,26:18.12
1,5,26:18.12
7,5,26:18.12
8,5,26:18.12
-1,6,26:18.12
0,6,26:18.12
1,6,26:18.12
2,6,26:18.12
7,6,26:18.12
8,6,26:18.12
-1,7,26:18.12
5,-10,27:18.12
9,-10,27:18.12
-6,-9,27:18.12
1,-9,27:18.12
3,-9,27:18.12
7,-9,27:18.12
8,-9,27:18.12
10,-9,27:18.12
2,-8,27:18.12
3,-8,27:18.12
5,-8,27:18.12
9,-8,27:17.12
10,-8,27:18.12
-7,-7,27:18.12
-5,-7,27:18.12
-3,-7,27:18.12
0,-7,27:18.12
1,-7,27:18.12
2,-7,27:17.12
3,-7,27:18.12
4,-7,27:18.12
-3,-6,27:18.12
2,-6,27:18.12
3,-6,27:18.12
4,-6,27:18.12
5,-6,27:18.12
6,-6,27:18.12
8,-6,27:18.4
9,-6,27:18.12
10,-6,27:18.12
-6,-5,27:18.12
-5,-5,27:18.12
-4,-5,27:18.12
2,-5,27:18.12
3,-5,27:18.12
7,-5,27:18.4
-5,-4,27:18.12
-2,-4,27:18.12
-1,-4,27:18.12
0,-4,27:18.12
3,-4,27:18.12
4,-4,27:18.12
7,-4,27:18.4
8,-4,27:17.12
-6,-3,27:18.12
-4,-3,27:18.12
-3,-3,27:18.12
-2,-3,27:18.12
-1,-3,27:18.12
8,-3,27:18.12
10,-3,27:18.12
-6,-2,27:18.12
-5,-2,27:18.12
-4,-2,27:18.12
-3,-2,27:18.12
1,-2,27:18.12
3,-2,27:18.12
5,-2,27:18.12
7,-2,27:18.12
8,-2,27:18.12
9,-2,27:18.12
-5,-1,27:18.12
-3,-1,27:18.12
1,-1,27:18.12
2,-1,27:18.12
3,-1,27:18.12
5,-1,27:18.12
6,-1,27:18.12
7,-1,27:18.12
8,-1,27:18.12
-4,0,27:18.12
1,0,27:18.12
7,0,27:18.12
8,0,27:18.12
-4,1,27:18.12
8,1,27:18.12
-4,2,27:18.12
-3,2,27:18.12
1,2,27:18.12
7,2,27:18.12
-6,3,27:18.12
-4,3,27:18.12
-3,3,27:18.12
-1,3,27:18.12
1,3,27:18.12
-1,4,27:18.12
1,4,27:18.12
3,4,27:18.12
-1,5,27:18.12
1,5,27:18.12
1,6,27:18.12
-1,7,27:18.12
10,-9,28:18.12
11,-9,28:18.12
4,-8,28:18.12
5,-8,28:18.12
8,-8,28:18.12
9,-8,28:18.12
-6,-7,28:18.12
-4,-7,28:18.12
2,-7,28:18.12
4,-7,28:18.12
5,-7,28:18.12
11,-7,28:18.12
3,-6,28:18.12
8,-6,28:18.12
9,-6,28:18.12
2,-5,28:18.12
8,-4,28:18.12
10,-4,28:18.12
-5,-3,28:18.12
3,-3,28:18.12
4,-3,28:18.12
9,-3,28:17.12
-5,-2,28:18.12
-4,-2,28:18.12
3,-2,28:18.12
4,-2,28:18.12
9,-2,28:18.12
10,-2,28:18.12
-5,-1,28:18.12
-4,-1,28:18.12
4,-1,28:18.12
9,-1,28:18.12
10,-1,28:18.12
7,0,28:18.12
8,0,28:18.12
9,0,28:18.12
10,0,28:18.12
-3,1,28:18.12
8,1,28:18.12
-5,2,28:18.12
-3,2,28:18.12
-5,3,28:18.12
0,5,28:18.12
-1,6,28:18.12
10,-9,29:18.12
1,-8,29:18.12
2,-8,29:18.12
10,-8,29:18.12
3,-7,29:18.12
9,-7,29:18.12
2,-6,29:18.12
8,-4,29:18.12
10,-4,29:18.12
7,-2,29:18.12
9,-2,29:17.12
11,-2,29:18.12
8,-1,29:18.12
9,-1,29:18.12
10,-1,29:18.12
8,0,29:18.12
9,0,29:18.12
10,0,29:18.12
9,-4,30:18.12
10,-4,30:18.12
9,-3,30:18.12
9,-2,30:18.12
11,-2,30:18.12
8,-1,30:18.12
8,0,30:18.12
9,0,30:18.12
