[META]
version=2.0
spawnOnBlockType=2
spawnSunlight=True
spawnDarkness=True
spawnWater=False
spawnLava=False
underFill=False
randomRotation=True
dig=True
tree=False
branch=False
needsFoundation=True
rarity=100
collisionPercentage=20
spawnElevationMin=0
spawnElevationMax=200
spawnInBiome=Custom
[DATA]
5,-6,-3:17.14
5,-4,-3:17.14
3,-2,-3:17.14
2,-6,-2:17.14
-1,-5,-2:17.14
4,-5,-2:17.14
0,-4,-2:17.14
2,-2,-2:17.14
1,-1,-2:17.14
2,-5,-1:17.14
1,-4,-1:17.14
3,-4,-1:17.14
2,-3,-1:17.14
2,-5,0:17.14
1,-4,0:17.14
2,-4,0:17.14
3,-4,0:17.14
2,-3,0:17.14
2,-4,1:17.14
3,-4,1:17.14
2,-4,2:17.14
2,-4,3:17.14
2,-4,4:17.14
2,-4,5:17.14
2,-4,6:17.14
2,-4,7:17.14
2,-4,8:17.14
2,-4,9:17.14
3,-4,10:17.14
1,-3,10:17.14
3,-5,11:17.14
1,-3,11:17.14
3,-5,12:17.14
1,-3,12:17.14
4,-5,13:17.14
0,-2,13:17.14
-4,-7,14:18.4
4,-5,14:17.14
0,-2,14:17.14
-1,-8,15:18.4
-2,-7,15:18.4
2,-7,15:18.4
-3,-6,15:18.4
-4,-5,15:18.4
4,-5,15:17.14
-4,-4,15:18.4
-2,-4,15:18.4
-1,-3,15:17.14
0,-2,15:17.14
-3,-9,16:18.4
3,-9,16:18.4
-5,-8,16:18.4
-4,-8,16:18.4
-3,-8,16:18.4
2,-8,16:18.4
-2,-7,16:18.4
3,-7,16:18.4
5,-7,16:18.4
-1,-6,16:18.4
3,-6,16:17.14
-3,-5,16:17.14
5,-5,16:17.14
-3,-4,16:18.4
-2,-4,16:17.14
0,-2,16:17.14
-5,-10,17:18.4
-4,-9,17:18.4
-5,-8,17:18.4
-4,-8,17:18.4
-3,-8,17:18.4
-5,-7,17:18.4
-3,-7,17:18.4
-2,-7,17:18.4
1,-7,17:18.4
-6,-6,17:18.4
-3,-6,17:17.14
3,-6,17:17.14
-6,-5,17:18.4
-4,-5,17:18.4
-3,-5,17:18.4
-1,-5,17:18.4
0,-5,17:18.4
5,-5,17:17.14
-5,-4,17:18.4
-4,-4,17:18.4
-1,-2,17:17.14
-5,-11,18:18.4
-4,-11,18:18.4
-4,-10,18:18.4
2,-9,18:18.4
-3,-8,18:18.4
1,-8,18:18.4
3,-8,18:18.4
5,-8,18:18.4
-4,-7,18:18.4
-2,-7,18:18.4
2,-7,18:18.4
3,-7,18:17.14
-2,-6,18:18.4
0,-6,18:18.4
2,-5,18:17.14
5,-5,18:17.14
4,-4,18:18.4
-2,-3,18:17.14
-1,-2,18:17.14
2,-10,19:18.4
-6,-9,19:18.4
-1,-9,19:18.4
-6,-8,19:18.4
-4,-8,19:18.4
-2,-8,19:18.4
-7,-7,19:18.4
-5,-7,19:18.4
-3,-7,19:18.4
1,-7,19:18.4
2,-7,19:18.4
3,-7,19:18.4
-5,-6,19:18.4
-3,-6,19:18.4
-2,-6,19:18.4
-5,-5,19:18.4
-4,-5,19:18.4
-3,-5,19:18.4
-2,-5,19:18.4
5,-5,19:17.14
-4,-4,19:17.14
-3,-4,19:17.14
-1,-2,19:17.14
-3,-11,20:18.4
-2,-10,20:18.4
4,-9,20:18.4
-7,-8,20:18.4
-5,-8,20:18.4
-4,-8,20:18.4
-3,-8,20:18.4
-2,-8,20:18.4
1,-8,20:18.4
5,-8,20:18.4
-6,-7,20:18.4
-3,-7,20:18.4
4,-7,20:18.4
-6,-6,20:18.4
-5,-6,20:18.4
-5,-5,20:17.14
-2,-5,20:18.4
6,-5,20:17.14
-7,-4,20:18.4
-6,-4,20:18.4
-2,-4,20:18.4
-6,-3,20:18.4
-4,-3,20:18.4
-1,-2,20:17.14
-4,-10,21:18.4
-5,-9,21:18.4
-3,-9,21:18.4
-2,-9,21:18.4
2,-7,21:18.4
-2,-6,21:18.4
7,-6,21:17.14
8,-6,21:17.14
-8,-5,21:18.4
-5,-5,21:18.4
-4,-5,21:18.4
-6,-4,21:18.4
-2,-4,21:18.4
6,-4,21:17.14
-5,-3,21:18.4
-2,-3,21:17.14
-4,-2,21:18.4
-1,-1,21:17.14
-5,-7,22:18.4
9,-7,22:17.14
-3,-5,22:18.4
-3,-4,22:18.4
1,-4,22:18.4
6,-4,22:17.14
-5,-3,22:18.4
-2,-3,22:17.14
0,-3,22:18.4
-1,0,22:18.4
0,0,22:17.14
-1,2,22:18.4
10,-9,23:18.4
8,-8,23:18.4
10,-8,23:17.14
11,-8,23:18.4
-3,-7,23:18.4
-6,-6,23:18.4
-4,-6,23:18.4
-3,-6,23:18.4
0,-6,23:18.4
8,-6,23:18.4
10,-6,23:18.4
1,-5,23:18.4
-4,-4,23:18.4
-3,-4,23:17.14
-2,-4,23:18.4
-2,-3,23:18.4
-1,-3,23:17.14
6,-3,23:17.14
-4,-2,23:18.4
0,-2,23:18.4
1,-2,23:18.4
6,-2,23:18.4
5,-1,23:18.4
0,0,23:17.14
7,0,23:18.4
7,-9,24:18.4
9,-9,24:18.4
10,-9,24:18.4
10,-8,24:17.14
11,-8,24:18.4
-3,-7,24:18.4
-1,-7,24:18.4
9,-7,24:18.4
10,-7,24:18.4
12,-7,24:18.4
-4,-6,24:18.4
-3,-6,24:18.4
7,-6,24:18.4
-2,-5,24:18.4
2,-5,24:18.4
8,-5,24:18.4
-6,-4,24:18.4
-5,-4,24:18.4
-3,-4,24:17.14
-2,-4,24:18.4
0,-4,24:17.14
2,-4,24:18.4
9,-4,24:18.4
-4,-3,24:18.4
-3,-3,24:18.4
0,-3,24:18.4
6,-3,24:17.14
-5,-2,24:18.4
3,-2,24:18.4
5,-2,24:17.14
-1,-1,24:18.4
2,-1,24:18.4
4,-1,24:18.4
9,0,24:18.4
-3,1,24:18.4
-1,1,24:17.14
1,1,24:17.14
2,1,24:18.4
-2,4,24:18.4
11,-11,25:18.4
9,-10,25:18.4
8,-9,25:18.4
11,-9,25:18.4
13,-9,25:18.4
14,-9,25:18.4
8,-8,25:18.4
11,-8,25:17.14
0,-7,25:18.4
1,-7,25:18.4
6,-7,25:18.4
8,-7,25:18.4
9,-7,25:17.14
12,-7,25:18.4
-1,-6,25:18.4
1,-6,25:18.4
9,-6,25:18.4
-2,-5,25:18.4
2,-5,25:18.4
8,-5,25:18.4
9,-5,25:18.4
10,-5,25:18.4
-6,-4,25:18.4
-3,-4,25:18.4
-1,-4,25:18.4
0,-4,25:17.14
7,-4,25:18.4
9,-4,25:18.4
-3,-3,25:18.4
-2,-3,25:18.4
1,-3,25:18.4
6,-3,25:18.4
0,-2,25:18.4
2,-2,25:18.4
7,-2,25:17.14
9,-2,25:18.4
10,-2,25:18.4
0,-1,25:18.4
1,-1,25:18.4
4,-1,25:17.14
5,-1,25:18.4
7,-1,25:18.4
8,-1,25:18.4
2,0,25:18.4
9,0,25:18.4
-2,1,25:18.4
-1,1,25:17.14
1,1,25:18.4
-4,2,25:18.4
-1,4,25:18.4
11,-11,26:18.4
10,-10,26:18.4
14,-10,26:18.4
11,-9,26:17.14
12,-9,26:18.4
13,-9,26:18.4
11,-8,26:18.4
0,-7,26:18.4
1,-7,26:18.4
6,-7,26:18.4
7,-7,26:18.4
8,-7,26:18.4
9,-7,26:17.14
-1,-6,26:18.4
0,-6,26:18.4
9,-6,26:18.4
12,-6,26:18.4
0,-5,26:18.4
-3,-4,26:18.4
1,-4,26:18.4
3,-4,26:18.4
5,-4,26:18.4
-5,-3,26:18.4
-3,-3,26:18.4
-2,-3,26:18.4
1,-3,26:18.4
3,-3,26:18.4
4,-3,26:18.4
6,-3,26:18.4
-3,-2,26:18.4
-1,-2,26:18.4
0,-2,26:18.4
2,-2,26:18.4
4,-2,26:18.4
5,-2,26:18.4
9,-2,26:18.4
-1,-1,26:18.4
4,-1,26:17.14
1,0,26:18.4
4,0,26:18.4
6,0,26:18.4
7,0,26:18.4
-1,1,26:18.4
2,1,26:18.4
1,2,26:18.4
-1,4,26:18.4
11,-11,27:18.4
8,-10,27:18.4
9,-10,27:18.4
11,-10,27:18.4
2,-5,27:18.4
8,-5,27:18.4
-3,-4,27:18.4
-1,-4,27:18.4
0,-4,27:18.4
1,-3,27:18.4
5,-3,27:18.4
7,-3,27:18.4
0,-2,27:18.4
7,-2,27:18.4
9,-2,27:18.4
1,-1,27:18.4
4,-1,27:18.4
7,-1,27:18.4
9,-1,27:18.4
5,0,27:18.4
-2,1,27:18.4
-1,1,27:18.4
1,1,27:18.4
4,1,27:18.4
-3,2,27:18.4
0,3,27:18.4
11,-9,28:18.4
9,-8,28:18.4
10,-8,28:18.4
13,-8,28:18.4
9,-7,28:18.4
9,-5,28:18.4
1,-4,28:18.4
-1,-3,28:18.4
4,-3,28:18.4
6,-2,28:18.4
-1,1,28:18.4
0,1,28:18.4
5,1,28:18.4
-2,2,28:18.4
8,-8,29:18.4
9,-6,29:18.4
10,-6,29:18.4
4,-1,29:18.4
5,-1,29:18.4
