[META]
version=2.0
spawnOnBlockType=2
spawnSunlight=True
spawnDarkness=True
spawnWater=False
spawnLava=False
underFill=False
randomRotation=True
dig=True
tree=False
branch=False
needsFoundation=True
rarity=100
collisionPercentage=20
spawnElevationMin=0
spawnElevationMax=200
spawnInBiome=Custom
[DATA]
0,0,0:17.12
0,0,1:17.12
1,-4,2:18.4
-2,-2,2:18.4
0,-1,2:18.4
2,-1,2:18.4
-3,0,2:18.4
0,0,2:17.12
0,1,2:18.4
2,1,2:18.12
-3,-5,3:18.4
-4,-4,3:18.4
-3,-4,3:18.4
-1,-4,3:18.4
1,-4,3:18.4
-4,-3,3:18.4
0,-3,3:18.4
-7,-2,3:18.4
-6,-2,3:18.4
-5,-2,3:18.4
-4,-2,3:17.12
-3,-2,3:18.4
-2,-2,3:18.4
1,-2,3:18.4
-7,-1,3:18.4
-6,-1,3:18.4
-5,-1,3:18.4
-4,-1,3:18.4
-3,-1,3:17.12
-2,-1,3:17.12
1,-1,3:18.4
2,-1,3:18.4
3,-1,3:18.4
4,-1,3:18.4
-5,0,3:18.4
-4,0,3:18.4
-3,0,3:18.4
-2,0,3:18.4
0,0,3:17.12
1,0,3:17.12
2,0,3:17.12
3,0,3:18.12
-2,1,3:18.4
-1,1,3:18.4
0,1,3:18.4
-3,3,3:18.4
0,3,3:18.4
-6,-5,4:18.4
-5,-5,4:18.4
0,-5,4:18.4
1,-5,4:18.4
-5,-4,4:18.4
-4,-4,4:18.4
-3,-4,4:18.12
-7,-3,4:18.4
-6,-3,4:18.4
-5,-3,4:17.12
-4,-3,4:18.4
-3,-3,4:18.4
4,-3,4:18.12
-5,-2,4:18.4
-3,-2,4:18.4
-2,-2,4:18.4
0,-2,4:18.4
2,-2,4:18.4
3,-2,4:18.4
4,-2,4:18.12
6,-2,4:18.12
-6,-1,4:18.4
-4,-1,4:18.4
-3,-1,4:18.4
-1,-1,4:18.4
1,-1,4:18.4
2,-1,4:18.4
3,-1,4:17.12
4,-1,4:17.12
5,-1,4:18.4
6,-1,4:18.4
-5,0,4:18.12
-4,0,4:18.4
-3,0,4:18.4
-2,0,4:18.4
-1,0,4:17.12
0,0,4:17.12
1,0,4:18.12
2,0,4:18.12
3,0,4:18.12
4,0,4:18.4
5,0,4:18.4
-1,1,4:18.4
3,1,4:18.12
4,1,4:18.4
5,1,4:18.4
-2,2,4:18.4
-4,3,4:18.4
1,3,4:18.4
0,4,4:18.4
-4,-7,5:18.4
1,-7,5:18.12
-4,-6,5:18.4
-3,-6,5:18.12
-2,-6,5:18.12
0,-6,5:18.12
-4,-5,5:18.4
-1,-5,5:18.12
0,-5,5:18.12
1,-5,5:18.4
2,-5,5:18.12
-2,-4,5:18.12
0,-4,5:18.4
1,-4,5:18.4
2,-4,5:18.12
-5,-3,5:18.4
-4,-3,5:18.4
0,-3,5:18.4
1,-3,5:17.12
4,-3,5:18.4
-4,-2,5:18.4
-2,-2,5:18.4
-1,-2,5:18.4
0,-2,5:17.12
1,-2,5:18.4
3,-2,5:18.4
-2,-1,5:18.4
0,-1,5:18.4
1,-1,5:18.4
2,-1,5:18.4
3,-1,5:18.4
5,-1,5:18.4
-6,0,5:18.12
-4,0,5:18.4
-3,0,5:18.4
-2,0,5:18.4
-1,0,5:18.4
0,0,5:17.12
3,0,5:18.4
4,0,5:18.4
-5,1,5:18.12
-2,1,5:18.4
0,1,5:18.4
1,1,5:17.12
3,1,5:18.4
-6,2,5:18.12
-5,2,5:18.12
-4,2,5:18.4
-3,2,5:18.4
-2,2,5:18.4
0,2,5:18.4
1,2,5:18.4
2,2,5:17.12
3,2,5:18.4
4,2,5:18.4
-5,3,5:18.4
-2,4,5:18.4
1,4,5:18.4
2,4,5:18.4
3,4,5:18.4
-4,5,5:18.4
-2,6,5:18.4
-4,-6,6:18.4
1,-6,6:18.12
-3,-5,6:18.12
0,-5,6:18.12
1,-5,6:18.4
4,-5,6:18.12
-3,-4,6:18.12
0,-4,6:18.4
1,-4,6:17.12
3,-4,6:18.12
5,-4,6:18.4
-5,-3,6:18.4
-3,-3,6:18.4
0,-3,6:18.4
3,-3,6:18.4
5,-3,6:18.4
-6,-2,6:18.4
-3,-2,6:18.4
0,-2,6:18.4
1,-2,6:18.4
3,-2,6:18.4
5,-2,6:18.4
6,-2,6:18.4
-5,-1,6:18.4
-1,-1,6:18.4
0,-1,6:17.12
1,-1,6:18.4
5,-1,6:18.4
6,-1,6:18.4
7,-1,6:18.4
-6,0,6:18.12
-5,0,6:18.12
-4,0,6:18.4
-3,0,6:18.4
-2,0,6:18.4
-1,0,6:18.4
0,0,6:17.12
1,0,6:18.4
2,0,6:18.4
3,0,6:18.4
4,0,6:18.4
5,0,6:18.4
6,0,6:18.4
-6,1,6:18.12
-4,1,6:18.4
-3,1,6:18.4
-2,1,6:18.4
1,1,6:18.4
2,1,6:18.4
3,1,6:18.4
4,1,6:18.4
5,1,6:18.4
6,1,6:18.4
-6,2,6:18.12
-5,2,6:18.12
-4,2,6:18.4
-2,2,6:18.4
1,2,6:18.4
2,2,6:18.4
3,2,6:18.4
5,2,6:18.4
-6,3,6:18.4
-2,3,6:18.4
1,3,6:18.4
3,3,6:17.12
4,3,6:18.4
5,3,6:18.4
-2,4,6:18.4
1,4,6:18.4
2,4,6:18.4
5,4,6:18.4
3,5,6:18.4
4,5,6:18.4
-4,6,6:18.4
-2,6,6:18.4
-1,6,6:18.4
-3,-5,7:18.4
-5,-4,7:18.4
2,-4,7:18.12
3,-4,7:18.12
0,-3,7:18.4
1,-3,7:18.4
2,-3,7:18.4
3,-3,7:18.4
5,-3,7:18.4
6,-3,7:18.4
-2,-2,7:18.4
-1,-2,7:18.4
3,-2,7:18.4
-5,-1,7:18.4
-3,-1,7:18.4
-1,-1,7:18.4
0,-1,7:18.4
2,-1,7:18.4
3,-1,7:18.4
-7,0,7:18.4
-4,0,7:18.4
-2,0,7:18.4
-1,0,7:18.4
0,0,7:17.12
1,0,7:18.4
2,0,7:18.4
3,0,7:18.4
4,0,7:18.4
6,0,7:18.4
-5,1,7:18.4
-4,1,7:18.4
-2,1,7:18.4
-1,1,7:17.12
0,1,7:18.4
3,1,7:18.4
7,1,7:18.4
-6,2,7:18.4
-4,2,7:18.4
-3,2,7:18.4
-2,2,7:17.12
-1,2,7:18.4
0,2,7:18.4
1,2,7:18.4
3,2,7:18.4
4,2,7:18.4
-2,3,7:18.4
-1,3,7:18.4
0,3,7:18.4
1,3,7:18.4
3,3,7:18.4
4,3,7:18.4
-3,4,7:18.4
-1,4,7:18.4
0,4,7:18.4
3,4,7:18.4
5,4,7:18.4
1,-4,8:18.4
0,-3,8:18.4
0,-1,8:18.4
1,-1,8:18.4
3,-1,8:18.4
-4,0,8:18.4
-3,0,8:18.4
-2,0,8:18.4
-1,0,8:18.4
0,0,8:17.12
2,0,8:18.4
3,0,8:18.4
-4,1,8:18.4
-3,1,8:18.4
-2,1,8:18.4
-4,2,8:18.4
0,2,8:18.4
1,2,8:18.4
-3,3,8:18.4
-2,3,8:18.4
-1,3,8:18.4
1,3,8:18.4
2,3,8:18.4
3,3,8:18.4
2,-4,9:18.4
2,-3,9:18.4
-4,-2,9:18.4
-3,-2,9:18.4
-4,-1,9:18.4
-2,-1,9:18.4
-1,-1,9:18.4
0,-1,9:18.4
-3,0,9:18.4
0,0,9:17.12
1,0,9:18.4
4,0,9:18.4
0,1,9:18.4
1,1,9:18.4
-2,2,9:18.4
-1,3,9:18.4
2,3,9:18.4
3,3,9:18.4
-1,4,9:18.4
