[META]
version=2.0
spawnOnBlockType=2
spawnSunlight=True
spawnDarkness=True
spawnWater=False
spawnLava=False
underFill=False
randomRotation=True
dig=True
tree=False
branch=False
needsFoundation=True
rarity=100
collisionPercentage=20
spawnElevationMin=0
spawnElevationMax=200
spawnInBiome=Custom
[DATA]
-1,-3,-3:17.15
3,1,-3:17.15
-1,3,-3:17.15
0,-3,-2:17.15
-2,-2,-2:17.15
0,-2,-2:17.15
2,-2,-2:17.15
-3,0,-2:17.15
2,0,-2:17.15
-2,2,-2:17.15
0,2,-2:17.15
0,-2,-1:17.15
-2,-1,-1:17.15
-1,-1,-1:17.15
1,-1,-1:17.15
-1,0,-1:17.15
1,0,-1:17.15
-1,1,-1:17.15
0,1,-1:17.15
1,1,-1:17.15
0,2,-1:17.15
-1,-1,0:17.15
1,-1,0:17.15
0,0,0:17.15
0,1,0:17.15
0,0,1:17.15
0,0,2:17.15
0,0,3:17.15
0,0,4:17.15
0,0,5:17.15
0,0,6:17.15
0,0,7:17.15
0,0,8:17.15
0,0,9:17.15
0,0,10:17.15
0,0,11:17.15
0,0,12:17.15
0,0,13:17.15
0,0,14:17.15
0,0,15:17.15
0,0,16:17.15
0,0,17:17.15
0,0,18:17.15
0,0,19:17.15
0,0,20:17.15
0,0,21:17.15
0,0,22:17.15
0,0,23:17.15
0,0,24:17.15
0,0,25:17.15
0,0,26:17.15
0,0,27:17.15
0,0,28:17.3
0,0,29:17.3
1,0,29:18.12
2,0,29:18.12
1,1,29:18.12
0,-1,30:18.12
2,-1,30:18.12
-2,0,30:18.12
-1,0,30:18.12
0,0,30:17.13
1,0,30:18.12
3,0,30:18.12
4,0,30:18.12
-1,1,30:18.12
0,1,30:18.12
2,2,30:18.12
3,3,30:18.12
4,-3,31:18.12
3,-2,31:18.12
-4,-1,31:18.12
-3,-1,31:18.12
0,-1,31:18.12
-1,0,31:18.12
0,0,31:17.13
1,0,31:18.12
5,0,31:18.12
0,1,31:18.12
-2,2,31:18.12
-3,3,31:18.12
4,4,31:18.12
5,-4,32:18.12
-5,-2,32:18.12
0,-2,32:18.12
-2,0,32:18.12
0,0,32:18.12
2,0,32:18.12
1,1,32:18.12
0,2,32:18.12
0,-2,33:18.12
-1,-1,33:18.12
1,-1,33:18.12
-2,0,33:18.12
2,0,33:18.12
-1,1,33:18.12
1,1,33:18.12
0,2,33:18.12
0,-3,34:18.12
-2,-2,34:18.12
2,-2,34:18.12
-3,0,34:18.12
3,0,34:18.12
-2,2,34:18.12
2,2,34:18.12
0,3,34:18.12
0,-5,35:18.4
-4,-4,35:18.12
0,-4,35:18.12
4,-4,35:18.12
-3,-3,35:18.12
3,-3,35:18.12
-5,0,35:18.4
-4,0,35:18.12
4,0,35:18.12
5,0,35:18.12
-3,3,35:18.12
3,3,35:18.12
-4,4,35:18.12
0,4,35:18.12
4,4,35:18.12
-1,5,35:18.12
0,1,29:85.0
-1,0,29:85.0
2,-1,29:85.0
0,-1,29:85.0
0,1,28:85.0
1,0,28:85.0
0,-1,3:85.0
1,0,2:85.0
0,-1,2:85.0
0,1,1:85.0
1,0,1:85.0
-1,0,1:85.0
0,-1,1:85.0
-1,-1,1:85.0
0,2,0:85.0
1,1,0:85.0
-1,1,0:85.0
1,0,0:85.0
-1,0,0:85.0
0,-1,0:85.0
-2,-1,0:85.0
0,-2,0:85.0
