[META]
version=2.0
spawnOnBlockType=2
spawnSunlight=True
spawnDarkness=True
spawnWater=False
spawnLava=False
underFill=False
randomRotation=True
dig=True
tree=False
branch=False
needsFoundation=True
rarity=100
collisionPercentage=20
spawnElevationMin=0
spawnElevationMax=200
spawnInBiome=Custom
[DATA]
1,-4,-3:17.15
0,1,-3:17.15
-1,-3,-2:17.15
1,-3,-2:17.15
0,-2,-2:17.15
-1,-1,-2:17.15
0,-1,-2:17.15
2,-1,-2:17.15
1,0,-2:17.15
3,0,-2:17.15
0,-2,-1:17.15
1,-2,-1:17.15
0,-1,-1:17.15
1,-1,-1:17.15
2,-1,-1:17.15
1,0,-1:17.15
0,-2,0:17.15
1,-1,0:17.15
2,-1,0:17.15
1,-1,1:17.15
1,-1,2:17.15
1,-1,3:17.15
1,-1,4:17.15
1,-1,5:17.15
1,-1,6:17.3
1,-1,7:17.3
1,-1,8:17.3
1,-1,9:17.3
1,-1,10:17.3
2,-1,10:18.12
2,0,10:18.12
1,-2,11:18.12
3,-2,11:18.12
-1,-1,11:18.12
0,-1,11:18.12
1,-1,11:17.13
2,-1,11:18.12
1,0,11:18.12
3,1,11:18.12
4,2,11:18.12
4,-3,12:18.12
-3,-2,12:18.12
-2,-2,12:18.12
1,-2,12:18.12
0,-1,12:18.12
1,-1,12:17.13
2,-1,12:18.12
1,0,12:18.12
1,-3,13:18.12
-1,-1,13:18.12
1,-1,13:18.12
3,-1,13:18.12
2,0,13:18.12
1,1,13:18.12
1,-3,14:18.12
0,-2,14:18.12
2,-2,14:18.12
-1,-1,14:18.12
3,-1,14:18.12
0,0,14:18.12
2,0,14:18.12
1,1,14:18.12
1,-4,15:18.12
-1,-3,15:18.12
3,-3,15:18.12
-2,-1,15:18.12
4,-1,15:18.12
-1,1,15:18.12
3,1,15:18.12
1,2,15:18.12
1,0,10:85.0
0,-1,10:85.0
3,-2,10:85.0
1,-2,10:85.0
1,0,9:85.0
2,-1,9:85.0
2,-1,1:85.0
1,0,0:85.0
0,-1,0:85.0
1,-2,0:85.0
