[META]
version=2.0
spawnOnBlockType=2
spawnSunlight=True
spawnDarkness=True
spawnWater=False
spawnLava=False
underFill=False
randomRotation=True
dig=True
tree=False
branch=False
needsFoundation=True
rarity=100
collisionPercentage=20
spawnElevationMin=0
spawnElevationMax=200
spawnInBiome=Custom
[DATA]
0,-1,0:17.15
0,-1,1:17.15
0,-2,2:127.8
1,-2,2:18.12
-2,-1,2:18.12
-1,-1,2:127.11
0,-1,2:17.15
1,-1,2:127.9
0,0,2:127.10
1,0,2:17.15
2,0,2:127.9
5,0,2:18.12
-3,1,2:18.12
1,1,2:127.10
6,1,2:18.12
5,2,2:18.12
0,-4,3:18.12
-1,-3,3:127.8
3,-3,3:18.12
-4,-2,3:18.12
-2,-2,3:127.11
-1,-2,3:17.15
2,-2,3:18.12
-1,-1,3:18.12
0,-1,3:18.12
1,-1,3:18.12
3,-1,3:18.12
4,-1,3:18.12
5,-1,3:18.12
-3,0,3:18.12
-2,0,3:127.11
-1,0,3:17.15
0,0,3:18.12
2,0,3:17.15
3,0,3:17.15
4,0,3:18.12
-1,1,3:127.10
0,1,3:18.12
3,1,3:18.12
5,1,3:18.12
3,3,3:18.12
-1,-6,4:18.12
0,-4,4:18.12
1,-4,4:18.12
-3,-3,4:18.12
-2,-3,4:18.12
0,-3,4:17.15
2,-3,4:18.12
-1,-2,4:18.12
3,-2,4:18.12
-2,-1,4:18.12
0,-1,4:18.12
1,-1,4:18.12
2,-1,4:18.12
-5,0,4:18.12
-2,0,4:17.15
0,0,4:18.12
4,0,4:18.12
0,1,4:17.15
4,1,4:17.15
5,1,4:18.12
-3,2,4:18.12
0,2,4:18.12
2,3,4:18.12
2,-5,5:18.12
-1,-4,5:18.12
-2,-3,5:18.12
0,-3,5:17.15
3,-3,5:18.12
-3,-2,5:18.12
0,-2,5:18.12
2,-2,5:18.12
5,-2,5:18.12
-3,-1,5:18.12
0,-1,5:18.12
1,-1,5:18.12
2,-1,5:18.12
-3,0,5:17.15
0,0,5:18.12
1,0,5:18.12
4,0,5:18.12
-3,1,5:18.12
-2,1,5:18.12
0,1,5:17.15
3,1,5:18.12
-4,2,5:18.12
-3,2,5:18.12
0,2,5:18.12
2,2,5:18.12
-3,3,5:18.12
-1,4,5:18.12
-2,-4,6:18.12
1,-4,6:18.12
-1,-3,6:18.12
0,-3,6:18.12
2,-3,6:18.12
3,-3,6:18.12
-2,-2,6:18.12
-1,-2,6:18.12
0,-2,6:18.12
2,-2,6:18.12
0,-1,6:18.12
4,-1,6:18.12
-2,0,6:18.12
0,0,6:18.12
0,1,6:18.12
3,1,6:18.12
-1,2,6:18.12
-3,3,6:18.12
1,3,6:18.12
-1,-3,7:18.12
-1,-1,7:18.12
-2,0,7:18.12
0,1,7:18.12
-1,3,7:18.12
0,2,8:18.12
1,2,8:18.12
