[META]
version=2.0
spawnOnBlockType=2
spawnSunlight=True
spawnDarkness=True
spawnWater=False
spawnLava=False
underFill=False
randomRotation=True
dig=True
tree=False
branch=False
needsFoundation=True
rarity=100
collisionPercentage=20
spawnElevationMin=0
spawnElevationMax=200
spawnInBiome=Custom
[DATA]
0,-4,-3:17.14
3,-3,-3:17.14
-1,-1,-3:17.14
3,0,-3:17.14
0,1,-3:17.14
1,-4,-2:17.14
2,-3,-2:17.14
3,-1,-2:17.14
0,0,-2:17.14
0,1,-2:17.14
2,-3,-1:17.14
2,-1,-1:17.14
0,0,-1:17.14
2,-3,0:17.14
1,-2,0:17.14
1,-1,0:17.14
2,-1,0:17.14
0,0,0:17.14
1,-1,1:17.14
1,-1,2:17.14
1,-1,3:17.14
1,-1,4:17.14
1,-1,5:17.14
1,-1,6:17.14
1,-1,7:17.14
1,-1,8:17.14
1,-1,9:17.14
1,-1,10:17.14
1,-1,11:17.14
1,-1,12:17.14
1,-1,13:17.14
1,-1,14:17.14
1,-1,15:17.14
0,-1,16:17.14
1,-1,16:17.2
2,-1,16:17.14
0,-2,17:17.14
2,-2,17:17.14
-8,0,17:18.12
2,0,17:17.14
-7,1,17:18.12
2,-3,18:17.14
-8,-2,18:18.12
-1,-2,18:17.14
-9,-1,18:18.4
-7,0,18:18.12
1,0,18:17.14
-7,1,18:18.12
-6,1,18:18.12
3,1,18:17.14
-8,2,18:18.4
-6,2,18:18.12
-1,-3,19:17.14
3,-3,19:17.14
-9,-1,19:18.4
-7,-1,19:18.12
-6,-1,19:18.12
-2,-1,19:17.14
-9,0,19:18.4
-7,0,19:17.14
-6,0,19:18.12
-4,0,19:17.14
-3,0,19:17.14
1,0,19:17.14
-6,1,19:18.12
0,1,19:17.14
3,1,19:17.14
-8,2,19:18.4
-2,-4,20:17.14
3,-4,20:17.14
-6,-2,20:18.12
-7,-1,20:18.4
-6,-1,20:18.12
-5,-1,20:18.12
-8,0,20:18.4
-6,0,20:17.14
-5,0,20:17.14
-4,0,20:18.12
-7,1,20:18.4
0,1,20:17.14
-6,2,20:18.4
4,2,20:17.14
-3,-4,21:17.14
-1,-4,21:17.14
4,-4,21:17.14
-5,-3,21:18.4
-7,-2,21:18.4
-6,-2,21:18.4
-4,-2,21:18.4
-8,-1,21:18.4
-7,-1,21:18.4
-6,-1,21:17.14
-5,-1,21:18.4
-8,0,21:18.4
-7,0,21:18.4
-6,0,21:18.4
-4,0,21:18.4
-1,0,21:17.14
-7,1,21:18.4
-6,1,21:18.4
0,2,21:17.14
4,2,21:17.14
-3,-5,22:17.14
-1,-5,22:17.14
5,-5,22:17.14
4,-3,22:17.14
-8,-1,22:18.4
-7,-1,22:18.4
-6,-1,22:18.4
-4,0,22:18.4
-2,0,22:17.14
-7,1,22:18.4
-6,1,22:18.4
5,1,22:17.14
1,2,22:17.14
5,3,22:17.14
7,4,22:18.4
6,6,22:18.4
4,-6,23:17.14
-4,-5,23:17.14
0,-5,23:17.14
6,-5,23:17.14
-1,-4,23:18.4
-2,-3,23:18.4
-1,-3,23:18.4
0,-3,23:18.4
4,-3,23:17.14
0,-2,23:18.4
-6,-1,23:18.4
-5,-1,23:18.4
-3,-1,23:17.14
0,-1,23:18.4
1,-1,23:18.4
-7,0,23:18.4
-5,0,23:18.4
1,0,23:18.4
-2,1,23:17.14
2,1,23:17.14
6,1,23:17.14
7,1,23:17.14
1,3,23:17.14
6,3,23:18.4
7,3,23:18.4
6,4,23:17.14
6,5,23:18.4
7,5,23:18.4
5,6,23:18.4
6,-9,24:18.4
4,-8,24:18.4
5,-8,24:18.4
4,-7,24:17.14
-5,-6,24:18.4
-4,-6,24:17.14
0,-6,24:17.14
7,-5,24:17.14
0,-4,24:17.14
1,-4,24:18.4
-6,-3,24:18.4
-4,-3,24:18.4
-2,-3,24:18.4
-1,-3,24:18.4
0,-3,24:18.4
1,-3,24:18.4
4,-3,24:18.4
-5,-2,24:18.4
-4,-2,24:17.14
2,-2,24:18.4
4,-2,24:18.4
5,-2,24:17.14
-5,-1,24:18.4
-1,-1,24:18.4
0,-1,24:18.4
2,-1,24:17.14
3,-1,24:18.4
8,-1,24:18.4
9,-1,24:18.4
0,0,24:18.4
1,0,24:18.4
2,0,24:17.14
3,0,24:18.4
7,0,24:17.14
9,0,24:18.4
-5,1,24:18.4
-4,1,24:18.4
-3,1,24:17.14
8,1,24:18.4
-3,2,24:18.4
1,3,24:17.14
2,3,24:18.4
7,3,24:18.4
-1,4,24:18.4
0,4,24:18.4
1,4,24:18.4
2,4,24:18.4
6,4,24:18.4
0,5,24:18.4
1,5,24:18.4
2,5,24:18.4
6,5,24:18.4
7,5,24:17.14
8,5,24:18.4
9,5,24:18.4
-1,6,24:18.4
8,6,24:18.4
6,-10,25:18.4
-5,-9,25:18.4
3,-9,25:18.4
4,-9,25:18.4
-7,-8,25:18.4
-5,-8,25:18.4
-4,-8,25:18.4
1,-8,25:18.4
3,-8,25:18.4
4,-8,25:18.4
5,-8,25:18.4
-7,-7,25:18.4
1,-7,25:18.4
2,-7,25:18.4
4,-7,25:17.14
5,-7,25:18.4
-5,-6,25:17.14
-3,-6,25:18.4
1,-6,25:17.14
2,-6,25:18.4
3,-6,25:18.4
8,-6,25:17.14
-6,-5,25:18.4
-1,-5,25:18.4
0,-5,25:18.4
-6,-4,25:18.4
-5,-4,25:18.4
-1,-4,25:18.4
2,-4,25:18.4
3,-4,25:18.4
-7,-3,25:18.4
-6,-3,25:18.4
-5,-3,25:18.4
-2,-3,25:18.4
-1,-3,25:17.14
0,-3,25:18.4
1,-3,25:18.4
3,-3,25:18.4
-7,-2,25:18.4
-4,-2,25:17.14
-1,-2,25:18.4
0,-2,25:18.4
1,-2,25:18.4
3,-2,25:17.14
4,-2,25:18.4
5,-2,25:17.14
7,-2,25:18.4
-3,-1,25:18.4
-2,-1,25:18.4
-1,-1,25:18.4
0,-1,25:18.4
1,-1,25:17.14
3,-1,25:18.4
-6,0,25:18.4
-4,0,25:18.4
-3,0,25:18.4
0,0,25:18.4
1,0,25:18.4
2,0,25:18.4
3,0,25:18.4
4,0,25:18.4
6,0,25:18.4
7,0,25:17.14
8,0,25:18.4
9,0,25:18.4
10,0,25:18.4
10,1,25:18.4
-4,2,25:18.4
-3,2,25:17.14
0,2,25:18.4
2,2,25:18.4
-4,3,25:18.4
-1,3,25:18.4
0,3,25:18.4
1,3,25:18.4
2,3,25:18.4
-4,4,25:18.4
-3,4,25:18.4
-1,4,25:18.4
0,4,25:17.14
-1,5,25:18.4
1,5,25:18.4
3,5,25:18.4
5,5,25:18.4
6,5,25:18.4
8,5,25:18.4
-1,6,25:18.4
0,6,25:18.4
8,6,25:18.4
-2,7,25:18.4
-1,7,25:18.4
6,7,25:18.4
5,-10,26:18.4
9,-10,26:18.4
10,-10,26:18.4
-5,-9,26:18.4
-4,-9,26:18.4
3,-9,26:18.4
4,-9,26:18.4
5,-9,26:18.4
-7,-8,26:18.4
-3,-8,26:18.4
3,-8,26:18.4
5,-8,26:17.14
6,-8,26:18.4
7,-8,26:18.4
8,-8,26:18.4
9,-8,26:18.4
10,-8,26:18.4
-7,-7,26:18.4
-6,-7,26:18.4
-5,-7,26:17.14
-4,-7,26:18.4
0,-7,26:18.4
1,-7,26:17.14
2,-7,26:18.4
3,-7,26:18.4
4,-7,26:18.4
5,-7,26:18.4
6,-7,26:18.4
7,-7,26:18.4
8,-7,26:18.4
9,-7,26:17.14
11,-7,26:18.4
-5,-6,26:18.4
-3,-6,26:18.4
3,-6,26:18.4
4,-6,26:18.4
5,-6,26:18.4
6,-6,26:18.4
-6,-5,26:18.4
-4,-5,26:18.4
2,-5,26:18.4
3,-5,26:18.4
8,-5,26:17.14
-5,-4,26:18.4
-1,-4,26:18.4
0,-4,26:18.4
4,-4,26:18.4
-6,-3,26:18.4
-4,-3,26:18.4
-3,-3,26:18.4
-2,-3,26:18.4
1,-3,26:18.4
2,-3,26:18.4
5,-3,26:18.4
-7,-2,26:18.4
-6,-2,26:18.4
-5,-2,26:17.14
-4,-2,26:18.4
-3,-2,26:18.4
0,-2,26:18.4
1,-2,26:18.4
2,-2,26:18.4
3,-2,26:17.14
5,-2,26:18.4
7,-2,26:18.4
8,-2,26:18.4
-6,-1,26:18.4
-1,-1,26:18.4
1,-1,26:18.4
2,-1,26:18.4
3,-1,26:18.4
-6,0,26:18.4
-4,0,26:18.4
0,0,26:18.4
1,0,26:18.4
2,0,26:18.4
3,0,26:18.4
6,0,26:18.4
7,0,26:18.4
8,0,26:17.14
10,0,26:18.4
-6,1,26:18.4
-2,1,26:18.4
2,1,26:18.4
6,1,26:18.4
8,1,26:18.4
-4,2,26:17.14
-3,2,26:18.4
-2,2,26:18.4
1,2,26:18.4
9,2,26:18.4
-2,3,26:18.4
1,3,26:18.4
-3,4,26:18.4
0,4,26:18.4
1,4,26:17.14
2,4,26:18.4
-1,5,26:17.14
0,5,26:18.4
1,5,26:18.4
7,5,26:18.4
8,5,26:18.4
-1,6,26:18.4
0,6,26:18.4
1,6,26:18.4
2,6,26:18.4
7,6,26:18.4
8,6,26:18.4
-1,7,26:18.4
5,-10,27:18.4
9,-10,27:18.4
-6,-9,27:18.4
1,-9,27:18.4
3,-9,27:18.4
7,-9,27:18.4
8,-9,27:18.4
10,-9,27:18.4
2,-8,27:18.4
3,-8,27:18.4
5,-8,27:18.4
9,-8,27:17.14
10,-8,27:18.4
-7,-7,27:18.4
-5,-7,27:18.4
-3,-7,27:18.4
0,-7,27:18.4
1,-7,27:18.4
2,-7,27:17.14
3,-7,27:18.4
4,-7,27:18.4
-3,-6,27:18.4
2,-6,27:18.4
3,-6,27:18.4
4,-6,27:18.4
5,-6,27:18.4
6,-6,27:18.4
9,-6,27:18.4
10,-6,27:18.4
-6,-5,27:18.4
-5,-5,27:18.4
-4,-5,27:18.4
2,-5,27:18.4
3,-5,27:18.4
-5,-4,27:18.4
-2,-4,27:18.4
-1,-4,27:18.4
0,-4,27:18.4
3,-4,27:18.4
4,-4,27:18.4
8,-4,27:17.14
-6,-3,27:18.4
-4,-3,27:18.4
-3,-3,27:18.4
-2,-3,27:18.4
-1,-3,27:18.4
8,-3,27:18.4
10,-3,27:18.4
-6,-2,27:18.4
-5,-2,27:18.4
-4,-2,27:18.4
-3,-2,27:18.4
1,-2,27:18.4
3,-2,27:18.4
5,-2,27:18.4
7,-2,27:18.4
8,-2,27:18.4
9,-2,27:18.4
-5,-1,27:18.4
-3,-1,27:18.4
1,-1,27:18.4
2,-1,27:18.4
3,-1,27:18.4
5,-1,27:18.4
6,-1,27:18.4
7,-1,27:18.4
8,-1,27:18.4
-4,0,27:18.4
1,0,27:18.4
7,0,27:18.4
8,0,27:18.4
-4,1,27:18.4
8,1,27:18.4
-4,2,27:18.4
-3,2,27:18.4
1,2,27:18.4
7,2,27:18.4
-6,3,27:18.4
-4,3,27:18.4
-3,3,27:18.4
-1,3,27:18.4
1,3,27:18.4
-1,4,27:18.4
1,4,27:18.4
3,4,27:18.4
-1,5,27:18.4
1,5,27:18.4
1,6,27:18.4
-1,7,27:18.4
10,-9,28:18.4
11,-9,28:18.4
4,-8,28:18.4
5,-8,28:18.4
8,-8,28:18.4
9,-8,28:18.4
-6,-7,28:18.4
-4,-7,28:18.4
2,-7,28:18.4
4,-7,28:18.4
5,-7,28:18.4
11,-7,28:18.4
3,-6,28:18.4
8,-6,28:18.4
9,-6,28:18.4
2,-5,28:18.4
8,-4,28:18.4
10,-4,28:18.4
-5,-3,28:18.4
3,-3,28:18.4
4,-3,28:18.4
9,-3,28:17.14
-5,-2,28:18.4
-4,-2,28:18.4
3,-2,28:18.4
4,-2,28:18.4
9,-2,28:18.4
10,-2,28:18.4
-5,-1,28:18.4
-4,-1,28:18.4
4,-1,28:18.4
9,-1,28:18.4
10,-1,28:18.4
7,0,28:18.4
8,0,28:18.4
9,0,28:18.4
10,0,28:18.4
-3,1,28:18.4
8,1,28:18.4
-5,2,28:18.4
-3,2,28:18.4
-5,3,28:18.4
0,5,28:18.4
-1,6,28:18.4
10,-9,29:18.4
1,-8,29:18.4
2,-8,29:18.4
10,-8,29:18.4
3,-7,29:18.4
9,-7,29:18.4
2,-6,29:18.4
8,-4,29:18.4
10,-4,29:18.4
7,-2,29:18.4
9,-2,29:17.14
11,-2,29:18.4
8,-1,29:18.4
9,-1,29:18.4
10,-1,29:18.4
8,0,29:18.4
9,0,29:18.4
10,0,29:18.4
9,-4,30:18.4
10,-4,30:18.4
9,-3,30:18.4
9,-2,30:18.4
11,-2,30:18.4
8,-1,30:18.4
8,0,30:18.4
9,0,30:18.4
