[META]
version=2.0
spawnOnBlockType=2
spawnSunlight=True
spawnDarkness=True
spawnWater=False
spawnLava=False
underFill=False
randomRotation=True
dig=True
tree=False
branch=False
needsFoundation=True
rarity=100
collisionPercentage=20
spawnElevationMin=0
spawnElevationMax=200
spawnInBiome=Custom
[DATA]
0,-1,-3:17.14
-2,2,-3:17.14
0,0,-2:17.14
-2,1,-2:17.14
0,0,-1:17.14
-1,1,-1:17.14
0,0,0:17.14
-1,1,0:17.14
0,0,1:17.14
0,0,2:17.14
0,0,3:17.14
0,0,4:17.14
0,0,5:17.14
0,0,6:17.14
0,0,7:17.14
0,0,8:17.14
0,0,9:17.14
1,0,9:17.14
2,-1,10:17.14
-1,0,10:17.14
1,1,10:17.14
-1,-4,11:18.4
3,-4,11:18.4
-3,-2,11:18.4
-2,-2,11:18.4
5,-2,11:18.4
-3,-1,11:18.4
-1,-1,11:17.14
1,-1,11:18.4
2,-1,11:17.14
1,0,11:18.4
4,0,11:18.4
-3,1,11:18.4
-2,1,11:17.14
3,1,11:18.4
-3,2,11:18.4
1,2,11:17.14
0,3,11:18.4
2,3,11:18.4
4,3,11:18.4
0,4,11:18.4
1,-3,12:18.4
-2,-2,12:18.4
-1,-2,12:17.14
2,-2,12:18.4
3,-2,12:17.14
-4,-1,12:18.4
-1,-1,12:18.4
1,-1,12:18.4
3,-1,12:18.4
-2,0,12:18.4
0,0,12:18.4
1,0,12:17.14
3,0,12:18.4
4,0,12:18.4
-5,1,12:18.4
-4,1,12:18.4
-3,1,12:17.14
3,1,12:18.4
0,2,12:18.4
2,2,12:17.14
3,2,12:18.4
5,2,12:18.4
0,3,12:17.14
2,3,12:18.4
3,3,12:18.4
4,3,12:18.4
1,4,12:18.4
-1,5,12:18.4
3,5,12:18.4
0,-5,13:18.4
-2,-4,13:18.4
0,-4,13:18.4
-2,-3,13:18.4
3,-3,13:18.4
-3,-2,13:18.4
0,-2,13:17.14
1,-2,13:18.4
2,-2,13:18.4
-3,-1,13:18.4
-2,-1,13:17.14
0,-1,13:18.4
2,-1,13:18.4
-3,0,13:18.4
-1,0,13:18.4
0,0,13:17.14
1,0,13:18.4
2,0,13:18.4
-3,1,13:18.4
0,1,13:18.4
1,1,13:18.4
2,1,13:18.4
3,1,13:17.14
4,1,13:18.4
5,1,13:18.4
-3,2,13:17.14
-2,2,13:18.4
1,2,13:18.4
2,2,13:18.4
0,3,13:18.4
3,3,13:17.14
4,3,13:18.4
-3,4,13:18.4
2,4,13:18.4
0,-5,14:18.4
-2,-4,14:18.4
1,-4,14:18.4
-2,-3,14:18.4
0,-3,14:17.14
2,-3,14:18.4
-1,-2,14:18.4
2,-1,14:18.4
-2,0,14:18.4
2,1,14:18.4
3,1,14:18.4
-5,2,14:18.4
-3,2,14:18.4
-2,2,14:18.4
0,2,14:18.4
3,2,14:18.4
-1,3,14:18.4
3,3,14:18.4
2,4,14:18.4
-2,-3,15:18.4
0,-2,15:18.4
1,-2,15:18.4
2,-2,15:18.4
-2,-1,15:18.4
-1,-1,15:18.4
0,0,15:18.4
3,1,15:18.4
1,-3,16:18.4
0,-2,16:18.4
