[META]
version=2.0
spawnOnBlockType=2
spawnSunlight=True
spawnDarkness=True
spawnWater=False
spawnLava=False
underFill=False
randomRotation=True
dig=True
tree=False
branch=False
needsFoundation=True
rarity=100
collisionPercentage=20
spawnElevationMin=0
spawnElevationMax=200
spawnInBiome=Custom
[DATA]
0,0,0:17.3
0,0,1:17.3
0,0,2:17.3
0,0,3:17.3
0,0,4:17.3
0,0,5:17.3
0,0,6:17.3
0,0,7:17.3
0,0,8:17.3
0,0,9:17.3
0,0,10:17.3
0,0,11:17.3
0,0,12:17.3
0,0,13:17.3
0,-1,14:127.8
0,0,14:17.3
1,0,14:127.9
0,1,14:127.10
0,-1,15:127.8
-1,0,15:127.11
0,0,15:17.3
0,0,16:17.3
1,0,16:18.12
1,1,16:18.12
4,4,16:18.12
5,-4,17:18.12
-5,-2,17:18.12
0,-1,17:18.12
2,-1,17:18.12
-2,0,17:18.12
-1,0,17:18.12
0,0,17:17.13
1,0,17:18.12
0,1,17:18.12
2,2,17:18.12
3,3,17:18.12
4,-3,18:18.12
3,-2,18:18.12
-4,-1,18:18.12
-3,-1,18:18.12
0,-1,18:18.12
-1,0,18:18.12
0,0,18:17.13
1,0,18:18.12
0,1,18:18.12
0,-2,19:18.12
-2,0,19:18.12
0,0,19:18.12
2,0,19:18.12
1,1,19:18.12
0,2,19:18.12
0,-2,20:18.12
-1,-1,20:18.12
1,-1,20:18.12
-2,0,20:18.12
2,0,20:18.12
-1,1,20:18.12
1,1,20:18.12
0,2,20:18.12
0,-3,21:18.12
-2,-2,21:18.12
2,-2,21:18.12
-3,0,21:18.12
3,0,21:18.12
-2,2,21:18.12
2,2,21:18.12
0,3,21:18.12
0,-5,22:18.4
-4,-4,22:18.12
0,-4,22:18.12
4,-4,22:18.12
-3,-3,22:18.12
3,-3,22:18.12
-5,0,22:18.4
-4,0,22:18.12
4,0,22:18.12
5,0,22:18.12
-3,3,22:18.12
3,3,22:18.12
-4,4,22:18.12
0,4,22:18.12
4,4,22:18.12
-1,5,22:18.12
0,1,16:85.0
-1,0,16:85.0
2,-1,16:85.0
0,-1,16:85.0
0,1,15:85.0
1,0,15:85.0
