[META]
version=2.0
spawnOnBlockType=2
spawnSunlight=True
spawnDarkness=True
spawnWater=False
spawnLava=False
underFill=False
randomRotation=True
dig=True
tree=False
branch=False
needsFoundation=True
rarity=100
collisionPercentage=20
spawnElevationMin=0
spawnElevationMax=200
spawnInBiome=Custom
[DATA]
0,0,0:17.3
0,0,1:17.3
0,0,2:17.3
0,0,3:17.3
0,0,4:17.3
0,0,5:17.3
0,0,6:17.3
0,0,7:17.3
0,1,7:127.10
0,-1,8:127.8
-1,0,8:127.11
0,0,8:17.3
0,0,9:17.3
1,0,9:18.12
1,1,9:18.12
4,4,9:18.12
5,-4,10:18.12
-5,-2,10:18.12
0,-1,10:18.12
2,-1,10:18.12
-2,0,10:18.12
-1,0,10:18.12
0,0,10:17.13
1,0,10:18.12
0,1,10:18.12
2,2,10:18.12
3,3,10:18.12
4,-3,11:18.12
3,-2,11:18.12
-4,-1,11:18.12
-3,-1,11:18.12
0,-1,11:18.12
-1,0,11:18.12
0,0,11:17.13
1,0,11:18.12
0,1,11:18.12
0,-2,12:18.12
-2,0,12:18.12
0,0,12:18.12
2,0,12:18.12
1,1,12:18.12
0,2,12:18.12
0,-2,13:18.12
-1,-1,13:18.12
1,-1,13:18.12
-2,0,13:18.12
2,0,13:18.12
-1,1,13:18.12
1,1,13:18.12
0,2,13:18.12
0,-3,14:18.12
-2,-2,14:18.12
2,-2,14:18.12
-3,0,14:18.12
3,0,14:18.12
-2,2,14:18.12
2,2,14:18.12
0,3,14:18.12
0,-5,15:18.12
-4,-4,15:18.12
0,-4,15:18.12
4,-4,15:18.12
-3,-3,15:18.12
3,-3,15:18.12
-5,0,15:18.12
-4,0,15:18.12
4,0,15:18.12
5,0,15:18.12
-3,3,15:18.12
3,3,15:18.12
-4,4,15:18.12
0,4,15:18.12
4,4,15:18.12
-1,5,15:18.12
0,1,9:85.0
-1,0,9:85.0
2,-1,9:85.0
0,-1,9:85.0
0,1,8:85.0
1,0,8:85.0
