[META]
version=2.0
spawnOnBlockType=2
spawnSunlight=True
spawnDarkness=True
spawnWater=False
spawnLava=False
underFill=False
randomRotation=True
dig=True
tree=False
branch=False
needsFoundation=True
rarity=100
collisionPercentage=20
spawnElevationMin=0
spawnElevationMax=200
spawnInBiome=Custom
[DATA]
0,0,0:17.12
0,0,1:17.12
0,0,2:17.12
0,0,3:17.12
0,0,4:17.12
0,0,5:17.12
0,0,6:17.12
0,0,7:17.12
0,0,8:17.12
-1,-1,9:86.3
0,0,9:17.12
1,1,9:86.2
1,-1,10:86.0
0,0,10:17.0
0,0,11:17.0
1,0,11:18.12
-1,1,11:86.3
1,1,11:18.12
4,4,11:18.12
5,-4,12:18.12
-5,-2,12:18.12
0,-1,12:18.12
2,-1,12:18.12
-2,0,12:18.12
-1,0,12:18.12
0,0,12:17.0
1,0,12:18.12
0,1,12:18.12
2,2,12:18.12
3,3,12:18.12
4,-3,13:18.12
3,-2,13:18.12
-4,-1,13:18.12
-3,-1,13:18.12
0,-1,13:18.12
-1,0,13:18.12
0,0,13:17.0
1,0,13:18.12
0,1,13:18.12
0,-2,14:18.12
-2,0,14:18.12
0,0,14:18.12
2,0,14:18.12
1,1,14:18.12
0,2,14:18.12
0,-2,15:18.12
-1,-1,15:18.12
1,-1,15:18.12
-2,0,15:18.12
2,0,15:18.12
-1,1,15:18.12
1,1,15:18.12
0,2,15:18.12
0,-3,16:18.12
-2,-2,16:18.12
2,-2,16:18.12
-3,0,16:18.12
3,0,16:18.12
-2,2,16:18.12
2,2,16:18.12
0,3,16:18.12
0,-5,17:18.4
-4,-4,17:18.12
0,-4,17:18.12
4,-4,17:18.12
-3,-3,17:18.12
3,-3,17:18.12
-5,0,17:18.4
-4,0,17:18.12
4,0,17:18.12
5,0,17:18.12
-3,3,17:18.12
3,3,17:18.12
-4,4,17:18.12
0,4,17:18.12
4,4,17:18.12
-1,5,17:18.12
0,1,11:85.0
-1,0,11:85.0
1,-1,11:85.0
0,-1,11:85.0
1,1,10:85.0
0,1,10:85.0
1,0,10:85.0
0,-1,10:85.0
-1,-1,10:85.0
