[META]
version=2.0
spawnOnBlockType=2
spawnSunlight=True
spawnDarkness=True
spawnWater=False
spawnLava=False
underFill=False
randomRotation=True
dig=True
tree=False
branch=False
needsFoundation=True
rarity=100
collisionPercentage=20
spawnElevationMin=0
spawnElevationMax=200
spawnInBiome=Custom
[DATA]
0,0,0:17.12
0,0,1:17.12
0,0,2:17.12
0,0,3:17.0
0,0,4:17.0
1,-1,5:86.0
0,0,5:17.0
1,0,5:18.12
0,-1,6:18.12
-1,0,6:18.12
0,0,6:17.0
1,0,6:18.12
-1,1,6:86.3
0,1,6:18.12
0,-2,7:18.12
-2,0,7:18.12
0,0,7:18.12
2,0,7:18.12
1,1,7:18.12
0,2,7:18.12
0,-2,8:18.12
-1,-1,8:18.12
1,-1,8:18.12
-2,0,8:18.12
2,0,8:18.12
-1,1,8:18.12
1,1,8:18.12
0,2,8:18.12
0,-3,9:18.12
-2,-2,9:18.12
2,-2,9:18.12
-3,0,9:18.12
3,0,9:18.12
-2,2,9:18.12
2,2,9:18.12
0,3,9:18.12
0,-4,10:18.12
-3,-3,10:18.12
3,-3,10:18.12
-4,0,10:18.12
4,0,10:18.12
-3,3,10:18.12
3,3,10:18.12
0,4,10:18.12
-1,1,7:85.0
1,-1,6:85.0
0,1,5:85.0
-1,0,5:85.0
0,-1,5:85.0
1,0,4:85.0
