[META]
version=2.0
spawnOnBlockType=2
spawnSunlight=True
spawnDarkness=True
spawnWater=False
spawnLava=False
underFill=False
randomRotation=True
dig=True
tree=False
branch=False
needsFoundation=True
rarity=100
collisionPercentage=20
spawnElevationMin=0
spawnElevationMax=200
spawnInBiome=Custom
[DATA]
-1,-2,-3:17.12
2,-2,-3:17.12
0,1,-3:17.12
2,1,-3:17.12
-1,-2,-2:17.12
2,-1,-2:17.12
1,1,-2:17.12
0,-1,-1:17.12
1,-1,-1:17.12
1,0,-1:17.12
0,-1,0:17.12
1,-1,0:17.12
1,0,0:17.12
1,-1,1:17.12
1,-1,2:17.12
1,-1,3:17.12
4,-1,3:18.12
1,-1,4:17.12
2,-1,4:17.12
3,-1,4:18.12
5,-1,4:18.12
4,0,4:18.12
4,1,4:18.12
2,-2,5:18.12
1,-1,5:17.12
3,-1,5:18.12
4,-1,5:18.12
2,0,5:18.12
3,0,5:17.12
1,1,5:18.12
3,1,5:18.12
4,1,5:18.12
-3,2,5:18.12
-2,2,5:18.12
-2,3,5:18.12
1,-1,6:17.12
3,-1,6:18.12
0,0,6:17.12
3,0,6:18.12
5,0,6:18.12
-2,1,6:18.12
-1,2,6:18.12
1,-1,7:17.12
-2,0,7:18.12
2,0,7:18.12
-1,1,7:17.12
-3,2,7:18.12
-2,2,7:17.12
1,2,7:18.12
-1,3,7:18.12
1,3,7:18.12
-3,4,7:18.12
-1,4,7:18.12
1,4,7:18.12
3,-4,8:18.12
0,-2,8:17.12
1,-1,8:17.12
-3,0,8:18.12
2,0,8:18.12
0,2,8:18.12
3,2,8:18.12
4,2,8:18.12
-5,3,8:18.12
-2,3,8:18.12
2,3,8:18.12
-2,4,8:18.12
-1,5,8:18.12
5,-6,9:18.12
0,-4,9:18.12
1,-4,9:18.12
2,-4,9:18.12
3,-3,9:18.12
0,-2,9:17.12
1,-1,9:18.12
2,-1,9:18.12
5,-1,9:18.12
0,0,9:18.12
1,0,9:18.12
2,0,9:17.12
3,0,9:18.12
4,0,9:18.12
-3,1,9:18.12
-2,1,9:18.12
2,1,9:18.12
-2,2,9:18.12
-1,2,9:18.12
1,2,9:18.12
0,3,9:18.12
1,4,9:18.12
0,5,9:18.12
2,-5,10:18.12
3,-5,10:18.12
0,-4,10:18.12
4,-4,10:18.12
-1,-3,10:17.12
1,-3,10:18.12
2,-3,10:17.12
3,-3,10:18.12
4,-3,10:18.12
1,-2,10:17.12
6,-2,10:18.12
2,-1,10:18.12
3,-1,10:18.12
-4,0,10:18.12
1,0,10:18.12
2,0,10:17.12
4,0,10:18.12
0,1,10:18.12
3,1,10:18.12
4,1,10:18.12
-4,2,10:18.12
-3,2,10:18.12
2,2,10:18.12
4,2,10:18.12
-4,3,10:18.12
2,3,10:18.12
4,-6,11:18.12
-3,-4,11:18.12
1,-4,11:18.12
4,-4,11:18.12
-1,-3,11:17.12
3,-2,11:18.12
6,-2,11:18.12
7,-2,11:18.12
8,-2,11:18.12
7,-1,11:18.12
2,0,11:17.12
3,0,11:18.12
-2,1,11:18.12
4,1,11:18.12
-1,2,11:18.12
3,2,11:18.12
5,2,11:18.12
-6,3,11:18.12
-1,3,11:18.12
-4,4,11:18.12
-3,4,11:18.12
1,-6,12:18.12
0,-5,12:18.12
-4,-4,12:18.12
4,-4,12:18.12
5,-4,12:18.12
-1,-3,12:17.12
2,-3,12:18.12
-4,-2,12:18.12
1,-2,12:18.12
5,-2,12:18.12
7,-2,12:18.12
2,-1,12:17.12
-1,0,12:18.12
1,1,12:17.12
3,1,12:18.12
-2,3,12:18.12
-1,-6,13:18.12
1,-6,13:18.12
-2,-5,13:18.12
1,-5,13:18.12
-3,-4,13:18.12
0,-4,13:17.12
-2,-3,13:17.12
-1,-3,13:18.12
3,-3,13:18.12
-3,-2,13:18.12
0,-2,13:18.12
3,-2,13:17.12
5,-2,13:18.12
-3,-1,13:18.12
4,-1,13:18.12
5,-1,13:18.12
6,-1,13:18.12
3,0,13:17.12
5,0,13:18.12
1,1,13:17.12
2,1,13:18.12
5,1,13:18.12
7,1,13:18.12
-4,2,13:18.12
-3,2,13:18.12
0,2,13:18.12
-3,3,13:18.12
0,3,13:18.12
4,3,13:18.12
1,-5,14:18.12
-2,-4,14:18.12
0,-4,14:17.12
1,-4,14:18.12
4,-4,14:18.12
5,-4,14:18.12
-4,-3,14:18.12
-3,-3,14:17.12
3,-3,14:18.12
4,-3,14:18.12
-4,-2,14:18.12
-3,-2,14:18.12
-2,-2,14:18.12
2,-2,14:18.12
3,-2,14:17.12
5,-2,14:18.12
0,-1,14:18.12
-1,0,14:18.12
0,0,14:18.12
4,0,14:18.12
-1,1,14:18.12
1,1,14:18.12
2,1,14:18.12
4,1,14:17.12
5,1,14:18.12
-2,2,14:18.12
-1,2,14:18.12
0,2,14:17.12
1,2,14:18.12
3,2,14:18.12
1,3,14:18.12
2,3,14:18.12
0,4,14:18.12
1,4,14:18.12
1,-7,15:18.12
1,-6,15:18.12
-1,-5,15:18.12
1,-5,15:17.12
3,-5,15:18.12
-4,-4,15:18.12
-3,-4,15:18.12
1,-4,15:18.12
-5,-3,15:18.12
-3,-3,15:18.12
-2,-3,15:18.12
-4,-2,15:18.12
-3,-2,15:17.12
-2,-2,15:18.12
2,-2,15:18.12
3,-2,15:18.12
4,-2,15:18.12
-4,-1,15:18.12
-3,-1,15:18.12
-1,-1,15:18.12
5,-1,15:18.12
-2,1,15:18.12
-1,1,15:18.12
0,1,15:18.12
2,1,15:18.12
6,1,15:18.12
-2,2,15:18.12
-1,2,15:18.12
0,2,15:17.12
2,2,15:18.12
5,2,15:18.12
6,2,15:18.12
-1,3,15:18.12
0,3,15:18.12
2,3,15:18.12
3,3,15:18.12
0,-7,16:18.12
1,-6,16:18.12
1,-5,16:18.12
-4,-4,16:18.12
-3,-4,16:18.12
-1,-4,16:18.12
1,-4,16:18.12
3,-4,16:18.12
-2,-3,16:18.12
3,-3,16:18.12
-5,-1,16:18.12
-2,-1,16:18.12
3,-1,16:18.12
1,0,16:18.12
3,1,16:18.12
-1,2,16:18.12
0,2,16:18.12
1,2,16:18.12
2,2,16:18.12
4,2,16:18.12
1,3,16:18.12
0,-6,17:18.12
-2,-5,17:18.12
1,-5,17:18.12
-1,-4,17:18.12
0,-4,17:18.12
1,-4,17:18.12
-1,-3,17:18.12
0,-3,17:18.12
-4,-2,17:18.12
2,-2,17:18.12
1,-5,18:18.12
-1,-4,18:18.12
0,-1,18:18.12
2,-1,18:18.12
1,-4,19:18.12
2,-3,19:18.12
