[META]
version=2.0
spawnOnBlockType=2
spawnSunlight=True
spawnDarkness=True
spawnWater=False
spawnLava=False
underFill=False
randomRotation=True
dig=True
tree=False
branch=False
needsFoundation=True
rarity=100
collisionPercentage=20
spawnElevationMin=0
spawnElevationMax=200
spawnInBiome=Custom
[DATA]
1,0,0:17.12
1,0,1:17.12
1,0,2:17.12
1,0,3:17.12
1,0,4:17.12
1,0,5:17.12
1,0,6:17.12
1,0,7:17.12
1,0,8:17.12
1,0,9:17.12
1,0,10:17.12
1,0,11:17.12
1,0,12:17.12
-1,-2,13:18.4
1,0,13:17.12
2,0,13:18.4
1,-2,14:18.4
-2,0,14:18.4
1,0,14:17.12
-1,-2,15:18.4
-1,-1,15:18.4
0,0,15:18.4
1,0,15:17.12
4,0,15:18.4
-1,1,15:18.4
1,1,15:18.4
1,3,15:18.4
2,-4,16:18.4
4,-4,16:18.4
1,-3,16:18.4
2,-1,16:17.12
4,-1,16:18.4
0,0,16:17.12
1,0,16:18.4
2,-3,17:18.4
0,-2,17:18.4
2,-2,17:18.4
-2,-1,17:18.4
2,-1,17:17.12
-1,0,17:17.12
1,0,17:18.4
4,0,17:18.4
3,1,17:18.4
1,2,17:18.4
1,-4,18:18.4
4,-4,18:18.4
1,-3,18:18.4
0,-2,18:18.4
2,-2,18:17.12
3,-2,18:18.4
-2,-1,18:17.12
5,-1,18:18.4
1,0,18:17.12
3,0,18:17.12
5,0,18:18.4
1,1,18:18.4
2,1,18:18.4
3,1,18:18.4
-3,2,18:18.4
1,2,18:18.4
5,2,18:18.4
6,2,18:18.4
6,3,18:18.4
-2,-5,19:18.4
3,-5,19:18.4
-2,-3,19:18.4
-1,-3,19:18.4
0,-3,19:18.4
3,-3,19:18.4
2,-2,19:17.12
3,-2,19:18.4
4,-2,19:18.4
-5,-1,19:18.4
-3,-1,19:18.4
-2,-1,19:17.12
3,-1,19:18.4
-5,0,19:18.4
0,0,19:18.4
3,0,19:18.4
4,0,19:18.4
0,1,19:17.12
4,1,19:17.12
-4,2,19:18.4
0,3,19:18.4
1,3,19:18.4
2,3,19:18.4
3,3,19:18.4
-1,4,19:18.4
4,4,19:18.4
5,-5,20:18.4
-2,-4,20:18.4
0,-4,20:18.4
-3,-3,20:18.4
-2,-3,20:18.4
1,-3,20:17.12
3,-3,20:17.12
4,-3,20:18.4
0,-2,20:18.4
3,-2,20:18.4
4,-2,20:18.4
-2,-1,20:18.4
0,-1,20:18.4
2,-1,20:18.4
4,-1,20:18.4
5,-1,20:18.4
-4,0,20:18.4
-3,0,20:17.12
-1,0,20:18.4
1,0,20:18.4
2,0,20:18.4
4,0,20:18.4
1,1,20:18.4
4,1,20:17.12
6,1,20:18.4
7,1,20:18.4
-2,2,20:18.4
1,2,20:17.12
3,2,20:18.4
-2,3,20:18.4
1,5,20:18.4
-2,-5,21:18.4
1,-4,21:18.4
2,-4,21:18.4
3,-4,21:17.12
7,-4,21:18.4
-1,-3,21:18.4
0,-3,21:17.12
1,-3,21:18.4
7,-3,21:18.4
-5,-2,21:18.4
0,-2,21:18.4
-2,-1,21:18.4
-1,-1,21:18.4
2,-1,21:18.4
3,-1,21:18.4
4,-1,21:18.4
-6,0,21:18.4
-3,0,21:18.4
2,1,21:18.4
4,1,21:18.4
5,1,21:18.4
-2,2,21:18.4
4,2,21:18.4
-3,3,21:18.4
3,-7,22:18.4
5,-7,22:18.4
7,-5,22:18.4
3,-4,22:18.4
4,-4,22:17.12
6,-4,22:18.4
-2,-3,22:18.4
-1,-3,22:18.4
0,-3,22:18.4
2,-3,22:18.4
7,-3,22:18.4
4,-2,22:18.4
-5,-1,22:18.4
3,-1,22:18.4
4,-1,22:18.4
6,0,22:18.4
4,2,22:18.4
1,3,22:18.4
0,-5,23:18.4
6,-5,23:18.4
2,-4,23:18.4
5,-1,23:18.4
-4,0,23:18.4
2,1,23:18.4
3,2,23:18.4
4,2,23:18.4
2,-6,24:18.4
3,-5,24:18.4
6,-5,24:18.4
0,-3,24:18.4
5,-4,25:18.4
