[META]
version=2.0
spawnOnBlockType=2
spawnSunlight=True
spawnDarkness=True
spawnWater=False
spawnLava=False
underFill=False
randomRotation=True
dig=True
tree=False
branch=False
needsFoundation=True
rarity=100
collisionPercentage=20
spawnElevationMin=0
spawnElevationMax=200
spawnInBiome=Custom
[DATA]
-1,0,0:17.0
-1,0,1:17.0
-1,0,2:17.12
-1,0,3:17.12
-2,2,3:18.12
-3,-2,4:18.12
-1,0,4:17.12
-2,1,4:18.12
0,-4,5:18.12
-2,-1,5:18.12
-1,-1,5:18.12
0,-1,5:17.12
-2,0,5:17.12
-3,1,5:18.12
-2,1,5:18.12
-2,-4,6:18.4
-2,-3,6:18.4
1,-2,6:18.12
2,-2,6:18.12
-3,-1,6:18.12
-2,-1,6:17.12
0,-1,6:17.12
-1,0,6:18.12
1,0,6:18.12
-2,1,6:17.12
-3,2,6:18.4
-2,2,6:18.12
-1,3,6:18.12
-1,-3,7:18.12
0,-3,7:18.4
0,-2,7:18.12
1,-2,7:17.12
-3,-1,7:17.12
0,-1,7:18.12
-1,0,7:18.12
0,0,7:18.12
-2,1,7:18.12
-1,1,7:18.12
-3,2,7:18.4
-2,2,7:18.12
-1,2,7:17.12
1,2,7:18.12
0,3,7:18.12
-1,-3,8:18.4
-3,-2,8:18.4
-1,-2,8:18.12
0,-2,8:18.12
1,-2,8:18.12
-4,-1,8:18.4
-3,-1,8:18.4
-3,0,8:18.4
-2,0,8:18.12
-1,0,8:18.12
0,0,8:18.12
3,0,8:18.12
-2,1,8:18.12
-1,1,8:18.12
0,1,8:18.12
-2,2,8:18.12
0,-3,9:18.12
0,-2,9:18.12
1,-2,9:18.12
-2,-1,9:18.12
0,-1,9:18.12
1,0,9:18.12
-3,1,9:18.12
-1,2,9:18.12
0,3,9:18.12
2,0,10:18.12
1,0,11:18.12
