[META]
version=2.0
spawnOnBlockType=2
spawnSunlight=True
spawnDarkness=True
spawnWater=False
spawnLava=False
underFill=False
randomRotation=True
dig=True
tree=False
branch=False
needsFoundation=True
rarity=100
collisionPercentage=20
spawnElevationMin=0
spawnElevationMax=200
spawnInBiome=Custom
[DATA]
0,0,0:17.3
0,0,1:17.3
0,0,2:17.3
0,0,3:17.3
0,0,4:17.3
0,0,5:17.3
0,0,6:17.3
1,0,6:18.12
-2,-1,7:18.4
0,-1,7:18.12
-1,0,7:18.12
0,0,7:17.3
1,0,7:18.12
0,1,7:18.12
2,2,7:18.4
0,-3,8:18.12
-2,-1,8:18.12
0,-1,8:18.12
-3,0,8:18.12
-1,0,8:18.12
0,0,8:17.3
1,0,8:18.12
3,0,8:18.12
0,1,8:18.12
2,2,8:18.12
0,3,8:18.12
0,-2,9:18.12
-2,0,9:18.12
0,0,9:18.12
2,0,9:18.12
1,1,9:18.12
0,2,9:18.12
0,-2,10:18.12
-1,-1,10:18.12
1,-1,10:18.12
-2,0,10:18.12
2,0,10:18.12
-1,1,10:18.12
1,1,10:18.12
0,2,10:18.12
0,-3,11:18.12
-2,-2,11:18.12
2,-2,11:18.12
-3,0,11:18.12
3,0,11:18.12
-2,2,11:18.12
2,2,11:18.12
0,3,11:18.12
0,1,6:85.0
-1,0,6:85.0
0,-1,6:85.0
1,0,5:85.0
