[META]
version=2.0
spawnOnBlockType=2
spawnSunlight=True
spawnDarkness=True
spawnWater=False
spawnLava=False
underFill=False
randomRotation=True
dig=True
tree=False
branch=False
needsFoundation=True
rarity=100
collisionPercentage=20
spawnElevationMin=0
spawnElevationMax=200
spawnInBiome=Custom
[DATA]
0,0,0:17.15
0,0,1:17.15
0,0,2:17.15
0,0,3:17.15
0,0,4:17.15
0,0,5:17.15
0,0,6:17.15
0,0,7:17.15
0,0,8:17.15
0,0,9:17.15
0,0,10:17.15
0,0,11:17.15
0,0,12:17.15
2,-1,13:18.12
0,0,13:17.15
-2,-2,14:18.12
0,-1,14:86.0
2,-1,14:18.12
-1,0,14:86.3
0,0,14:17.15
-2,1,14:18.12
0,1,14:86.2
2,1,14:18.12
-1,2,14:18.12
-2,-2,15:18.12
1,-1,15:18.12
0,0,15:17.15
-2,1,15:18.12
2,1,15:18.12
0,2,15:18.12
0,-4,16:18.12
-1,-1,16:18.12
0,-1,16:18.12
-4,0,16:18.12
-1,0,16:18.12
0,0,16:17.15
1,0,16:18.12
4,0,16:18.12
0,1,16:18.12
1,1,16:18.12
0,4,16:18.12
0,-3,17:18.12
0,-2,17:18.12
0,-1,17:18.12
-3,0,17:18.12
-2,0,17:18.12
-1,0,17:18.12
0,0,17:18.12
1,0,17:18.12
2,0,17:18.12
3,0,17:18.12
0,1,17:18.12
0,2,17:18.12
0,3,17:18.12
-3,-3,18:18.12
3,-3,18:18.12
-1,-1,18:18.4
1,-1,18:18.4
0,0,18:18.12
-1,1,18:18.4
1,1,18:18.4
-3,3,18:18.12
3,3,18:18.12
-2,-2,19:18.12
2,-2,19:18.12
-1,-1,19:18.12
1,-1,19:18.12
-1,1,19:18.12
1,1,19:18.12
-2,2,19:18.12
2,2,19:18.12
0,1,15:85.0
-1,0,15:85.0
0,-1,15:85.0
