[META]
version=2.0
spawnOnBlockType=2
spawnSunlight=True
spawnDarkness=True
spawnWater=False
spawnLava=False
underFill=False
randomRotation=True
dig=True
tree=False
branch=False
needsFoundation=True
rarity=100
collisionPercentage=20
spawnElevationMin=0
spawnElevationMax=200
spawnInBiome=Custom
[DATA]
0,0,0:17.15
0,0,1:17.15
0,0,2:17.15
0,0,3:17.15
0,0,4:17.15
0,0,5:17.15
2,-1,6:18.12
0,0,6:17.15
-2,-2,7:18.12
0,-1,7:86.0
2,-1,7:18.12
-1,0,7:86.3
0,0,7:17.15
-2,1,7:18.12
0,1,7:86.2
2,1,7:18.12
-1,2,7:18.12
-2,-2,8:18.12
1,-1,8:18.12
0,0,8:17.15
-2,1,8:18.12
2,1,8:18.12
0,2,8:18.12
0,-4,9:18.12
-1,-1,9:18.12
0,-1,9:18.12
-4,0,9:18.12
-1,0,9:18.12
0,0,9:17.15
1,0,9:18.12
4,0,9:18.12
0,1,9:18.12
1,1,9:18.12
0,4,9:18.12
0,-3,10:18.12
0,-2,10:18.12
0,-1,10:18.12
-3,0,10:18.12
-2,0,10:18.12
-1,0,10:18.12
0,0,10:18.12
1,0,10:18.12
2,0,10:18.12
3,0,10:18.12
0,1,10:18.12
0,2,10:18.12
0,3,10:18.12
-3,-3,11:18.12
3,-3,11:18.12
-1,-1,11:18.4
1,-1,11:18.4
0,0,11:18.12
-1,1,11:18.4
1,1,11:18.4
-3,3,11:18.12
3,3,11:18.12
-2,-2,12:18.12
2,-2,12:18.12
-1,-1,12:18.12
1,-1,12:18.12
-1,1,12:18.12
1,1,12:18.12
-2,2,12:18.12
2,2,12:18.12
0,1,8:85.0
-1,0,8:85.0
0,-1,8:85.0
